Qubicle Exchange Format
Version 0.2
www.minddesk.com
11 11 21
1
1.000000 1.000000 1.000000
1 5 19 0 52
1 5 18 0 20
1 5 17 0 20
1 5 16 0 20
1 5 15 0 20
1 5 14 0 20
1 5 13 0 20
1 5 12 0 20
1 5 11 0 20
1 5 10 0 20
1 5 9 0 20
1 5 8 0 20
1 5 7 0 20
1 5 6 0 20
1 5 5 0 20
1 5 4 0 20
1 5 3 0 20
1 5 2 0 20
1 5 1 0 20
1 5 0 0 84
1 6 19 0 44
1 6 18 0 12
1 6 17 0 12
1 6 16 0 12
1 6 15 0 12
1 6 14 0 12
1 6 13 0 12
1 6 12 0 12
1 6 11 0 12
1 6 10 0 12
1 6 9 0 12
1 6 8 0 12
1 6 7 0 12
1 6 6 0 12
1 6 5 0 12
1 6 4 0 12
1 6 3 0 12
1 6 2 0 12
1 6 1 0 12
1 6 0 0 76
2 3 19 0 52
2 3 18 0 20
2 3 17 0 20
2 3 16 0 20
2 3 15 0 20
2 3 14 0 20
2 3 13 0 20
2 3 12 0 20
2 3 11 0 20
2 3 10 0 20
2 3 9 0 20
2 3 8 0 20
2 3 7 0 20
2 3 6 0 20
2 3 5 0 20
2 3 4 0 20
2 3 3 0 20
2 3 2 0 20
2 3 1 0 20
2 3 0 0 84
2 4 19 0 36
2 4 18 0 4
2 4 17 0 4
2 4 16 0 4
2 4 15 0 4
2 4 14 0 4
2 4 13 0 4
2 4 12 0 4
2 4 11 0 4
2 4 10 0 4
2 4 9 0 4
2 4 8 0 4
2 4 7 0 4
2 4 6 0 4
2 4 5 0 4
2 4 4 0 4
2 4 3 0 4
2 4 2 0 4
2 4 1 0 4
2 4 0 0 68
2 5 19 0 32
2 5 18 0 0
2 5 17 0 0
2 5 16 0 0
2 5 15 0 0
2 5 14 0 0
2 5 13 0 0
2 5 12 0 0
2 5 11 0 0
2 5 10 0 0
2 5 9 0 0
2 5 8 0 0
2 5 7 0 0
2 5 6 0 0
2 5 5 0 0
2 5 4 0 0
2 5 3 0 0
2 5 2 0 0
2 5 1 0 0
2 5 0 0 64
2 6 19 0 32
2 6 18 0 0
2 6 17 0 0
2 6 16 0 0
2 6 15 0 0
2 6 14 0 0
2 6 13 0 0
2 6 12 0 0
2 6 11 0 0
2 6 10 0 0
2 6 9 0 0
2 6 8 0 0
2 6 7 0 0
2 6 6 0 0
2 6 5 0 0
2 6 4 0 0
2 6 3 0 0
2 6 2 0 0
2 6 1 0 0
2 6 0 0 64
2 7 19 0 36
2 7 18 0 4
2 7 17 0 4
2 7 16 0 4
2 7 15 0 4
2 7 14 0 4
2 7 13 0 4
2 7 12 0 4
2 7 11 0 4
2 7 10 0 4
2 7 9 0 4
2 7 8 0 4
2 7 7 0 4
2 7 6 0 4
2 7 5 0 4
2 7 4 0 4
2 7 3 0 4
2 7 2 0 4
2 7 1 0 4
2 7 0 0 68
2 8 19 0 44
2 8 18 0 12
2 8 17 0 12
2 8 16 0 12
2 8 15 0 12
2 8 14 0 12
2 8 13 0 12
2 8 12 0 12
2 8 11 0 12
2 8 10 0 12
2 8 9 0 12
2 8 8 0 12
2 8 7 0 12
2 8 6 0 12
2 8 5 0 12
2 8 4 0 12
2 8 3 0 12
2 8 2 0 12
2 8 1 0 12
2 8 0 0 76
3 2 19 0 52
3 2 18 0 20
3 2 17 0 20
3 2 16 0 20
3 2 15 0 20
3 2 14 0 20
3 2 13 0 20
3 2 12 0 20
3 2 11 0 20
3 2 10 0 20
3 2 9 0 20
3 2 8 0 20
3 2 7 0 20
3 2 6 0 20
3 2 5 0 20
3 2 4 0 20
3 2 3 0 20
3 2 2 0 20
3 2 1 0 20
3 2 0 0 84
3 3 19 0 32
3 3 18 0 0
3 3 17 0 0
3 3 16 0 0
3 3 15 0 0
3 3 14 0 0
3 3 13 0 0
3 3 12 0 0
3 3 11 0 0
3 3 10 0 0
3 3 9 0 0
3 3 8 0 0
3 3 7 0 0
3 3 6 0 0
3 3 5 0 0
3 3 4 0 0
3 3 3 0 0
3 3 2 0 0
3 3 1 0 0
3 3 0 0 64
3 4 19 0 32
3 4 18 0 0
3 4 17 0 0
3 4 16 0 0
3 4 15 0 0
3 4 14 0 0
3 4 13 0 0
3 4 12 0 0
3 4 11 0 0
3 4 10 0 0
3 4 9 0 0
3 4 8 0 0
3 4 7 0 0
3 4 6 0 0
3 4 5 0 0
3 4 4 0 0
3 4 3 0 0
3 4 2 0 0
3 4 1 0 0
3 4 0 0 64
3 5 19 0 32
3 5 18 0 0
3 5 17 0 0
3 5 16 0 0
3 5 15 0 0
3 5 14 0 0
3 5 13 0 0
3 5 12 0 0
3 5 11 0 0
3 5 10 0 0
3 5 9 0 0
3 5 8 0 0
3 5 7 0 0
3 5 6 0 0
3 5 5 0 0
3 5 4 0 0
3 5 3 0 0
3 5 2 0 0
3 5 1 0 0
3 5 0 0 64
3 6 19 0 32
3 6 18 0 0
3 6 17 0 0
3 6 16 0 0
3 6 15 0 0
3 6 14 0 0
3 6 13 0 0
3 6 12 0 0
3 6 11 0 0
3 6 10 0 0
3 6 9 0 0
3 6 8 0 0
3 6 7 0 0
3 6 6 0 0
3 6 5 0 0
3 6 4 0 0
3 6 3 0 0
3 6 2 0 0
3 6 1 0 0
3 6 0 0 64
3 7 19 0 32
3 7 18 0 0
3 7 17 0 0
3 7 16 0 0
3 7 15 0 0
3 7 14 0 0
3 7 13 0 0
3 7 12 0 0
3 7 11 0 0
3 7 10 0 0
3 7 9 0 0
3 7 8 0 0
3 7 7 0 0
3 7 6 0 0
3 7 5 0 0
3 7 4 0 0
3 7 3 0 0
3 7 2 0 0
3 7 1 0 0
3 7 0 0 64
3 8 19 0 32
3 8 18 0 0
3 8 17 0 0
3 8 16 0 0
3 8 15 0 0
3 8 14 0 0
3 8 13 0 0
3 8 12 0 0
3 8 11 0 0
3 8 10 0 0
3 8 9 0 0
3 8 8 0 0
3 8 7 0 0
3 8 6 0 0
3 8 5 0 0
3 8 4 0 0
3 8 3 0 0
3 8 2 0 0
3 8 1 0 0
3 8 0 0 64
3 9 19 0 44
3 9 18 0 12
3 9 17 0 12
3 9 16 0 12
3 9 15 0 12
3 9 14 0 12
3 9 13 0 12
3 9 12 0 12
3 9 11 0 12
3 9 10 0 12
3 9 9 0 12
3 9 8 0 12
3 9 7 0 12
3 9 6 0 12
3 9 5 0 12
3 9 4 0 12
3 9 3 0 12
3 9 2 0 12
3 9 1 0 12
3 9 0 0 76
4 2 19 0 48
4 2 18 0 16
4 2 17 0 16
4 2 16 0 16
4 2 15 0 16
4 2 14 0 16
4 2 13 0 16
4 2 12 0 16
4 2 11 0 16
4 2 10 0 16
4 2 9 0 16
4 2 8 0 16
4 2 7 0 16
4 2 6 0 16
4 2 5 0 16
4 2 4 0 16
4 2 3 0 16
4 2 2 0 16
4 2 1 0 16
4 2 0 0 80
4 3 19 0 32
4 3 18 0 0
4 3 17 0 0
4 3 16 0 0
4 3 15 0 0
4 3 14 0 0
4 3 13 0 0
4 3 12 0 0
4 3 11 0 0
4 3 10 0 0
4 3 9 0 0
4 3 8 0 0
4 3 7 0 0
4 3 6 0 0
4 3 5 0 0
4 3 4 0 0
4 3 3 0 0
4 3 2 0 0
4 3 1 0 0
4 3 0 0 64
4 4 19 0 32
4 4 18 0 0
4 4 17 0 0
4 4 16 0 0
4 4 15 0 0
4 4 14 0 0
4 4 13 0 0
4 4 12 0 0
4 4 11 0 0
4 4 10 0 0
4 4 9 0 0
4 4 8 0 0
4 4 7 0 0
4 4 6 0 0
4 4 5 0 0
4 4 4 0 0
4 4 3 0 0
4 4 2 0 0
4 4 1 0 0
4 4 0 0 64
4 5 19 0 32
4 5 18 0 0
4 5 17 0 0
4 5 16 0 0
4 5 15 0 0
4 5 14 0 0
4 5 13 0 0
4 5 12 0 0
4 5 11 0 0
4 5 10 0 0
4 5 9 0 0
4 5 8 0 0
4 5 7 0 0
4 5 6 0 0
4 5 5 0 0
4 5 4 0 0
4 5 3 0 0
4 5 2 0 0
4 5 1 0 0
4 5 0 0 64
4 6 19 0 32
4 6 18 0 0
4 6 17 0 0
4 6 16 0 0
4 6 15 0 0
4 6 14 0 0
4 6 13 0 0
4 6 12 0 0
4 6 11 0 0
4 6 10 0 0
4 6 9 0 0
4 6 8 0 0
4 6 7 0 0
4 6 6 0 0
4 6 5 0 0
4 6 4 0 0
4 6 3 0 0
4 6 2 0 0
4 6 1 0 0
4 6 0 0 64
4 7 19 0 32
4 7 18 0 0
4 7 17 0 0
4 7 16 0 0
4 7 15 0 0
4 7 14 0 0
4 7 13 0 0
4 7 12 0 0
4 7 11 0 0
4 7 10 0 0
4 7 9 0 0
4 7 8 0 0
4 7 7 0 0
4 7 6 0 0
4 7 5 0 0
4 7 4 0 0
4 7 3 0 0
4 7 2 0 0
4 7 1 0 0
4 7 0 0 64
4 8 19 0 32
4 8 18 0 0
4 8 17 0 0
4 8 16 0 0
4 8 15 0 0
4 8 14 0 0
4 8 13 0 0
4 8 12 0 0
4 8 11 0 0
4 8 10 0 0
4 8 9 0 0
4 8 8 0 0
4 8 7 0 0
4 8 6 0 0
4 8 5 0 0
4 8 4 0 0
4 8 3 0 0
4 8 2 0 0
4 8 1 0 0
4 8 0 0 64
4 9 19 0 40
4 9 18 0 8
4 9 17 0 8
4 9 16 0 8
4 9 15 0 8
4 9 14 0 8
4 9 13 0 8
4 9 12 0 8
4 9 11 0 8
4 9 10 0 8
4 9 9 0 8
4 9 8 0 8
4 9 7 0 8
4 9 6 0 8
4 9 5 0 8
4 9 4 0 8
4 9 3 0 8
4 9 2 0 8
4 9 1 0 8
4 9 0 0 72
5 1 19 0 52
5 1 18 0 20
5 1 17 0 20
5 1 16 0 20
5 1 15 0 20
5 1 14 0 20
5 1 13 0 20
5 1 12 0 20
5 1 11 0 20
5 1 10 0 20
5 1 9 0 20
5 1 8 0 20
5 1 7 0 20
5 1 6 0 20
5 1 5 0 20
5 1 4 0 20
5 1 3 0 20
5 1 2 0 20
5 1 1 0 20
5 1 0 0 84
5 2 19 0 32
5 2 18 0 0
5 2 17 0 0
5 2 16 0 0
5 2 15 0 0
5 2 14 0 0
5 2 13 0 0
5 2 12 0 0
5 2 11 0 0
5 2 10 0 0
5 2 9 0 0
5 2 8 0 0
5 2 7 0 0
5 2 6 0 0
5 2 5 0 0
5 2 4 0 0
5 2 3 0 0
5 2 2 0 0
5 2 1 0 0
5 2 0 0 64
5 3 19 0 32
5 3 18 0 0
5 3 17 0 0
5 3 16 0 0
5 3 15 0 0
5 3 14 0 0
5 3 13 0 0
5 3 12 0 0
5 3 11 0 0
5 3 10 0 0
5 3 9 0 0
5 3 8 0 0
5 3 7 0 0
5 3 6 0 0
5 3 5 0 0
5 3 4 0 0
5 3 3 0 0
5 3 2 0 0
5 3 1 0 0
5 3 0 0 64
5 4 19 0 32
5 4 18 0 0
5 4 17 0 0
5 4 16 0 0
5 4 15 0 0
5 4 14 0 0
5 4 13 0 0
5 4 12 0 0
5 4 11 0 0
5 4 10 0 0
5 4 9 0 0
5 4 8 0 0
5 4 7 0 0
5 4 6 0 0
5 4 5 0 0
5 4 4 0 0
5 4 3 0 0
5 4 2 0 0
5 4 1 0 0
5 4 0 0 64
5 5 19 0 32
5 5 18 0 0
5 5 17 0 0
5 5 16 0 0
5 5 15 0 0
5 5 14 0 0
5 5 13 0 0
5 5 12 0 0
5 5 11 0 0
5 5 10 0 0
5 5 9 0 0
5 5 8 0 0
5 5 7 0 0
5 5 6 0 0
5 5 5 0 0
5 5 4 0 0
5 5 3 0 0
5 5 2 0 0
5 5 1 0 0
5 5 0 0 64
5 6 19 0 32
5 6 18 0 0
5 6 17 0 0
5 6 16 0 0
5 6 15 0 0
5 6 14 0 0
5 6 13 0 0
5 6 12 0 0
5 6 11 0 0
5 6 10 0 0
5 6 9 0 0
5 6 8 0 0
5 6 7 0 0
5 6 6 0 0
5 6 5 0 0
5 6 4 0 0
5 6 3 0 0
5 6 2 0 0
5 6 1 0 0
5 6 0 0 64
5 7 19 0 32
5 7 18 0 0
5 7 17 0 0
5 7 16 0 0
5 7 15 0 0
5 7 14 0 0
5 7 13 0 0
5 7 12 0 0
5 7 11 0 0
5 7 10 0 0
5 7 9 0 0
5 7 8 0 0
5 7 7 0 0
5 7 6 0 0
5 7 5 0 0
5 7 4 0 0
5 7 3 0 0
5 7 2 0 0
5 7 1 0 0
5 7 0 0 64
5 8 19 0 32
5 8 18 0 0
5 8 17 0 0
5 8 16 0 0
5 8 15 0 0
5 8 14 0 0
5 8 13 0 0
5 8 12 0 0
5 8 11 0 0
5 8 10 0 0
5 8 9 0 0
5 8 8 0 0
5 8 7 0 0
5 8 6 0 0
5 8 5 0 0
5 8 4 0 0
5 8 3 0 0
5 8 2 0 0
5 8 1 0 0
5 8 0 0 64
5 9 19 0 32
5 9 18 0 0
5 9 17 0 0
5 9 16 0 0
5 9 15 0 0
5 9 14 0 0
5 9 13 0 0
5 9 12 0 0
5 9 11 0 0
5 9 10 0 0
5 9 9 0 0
5 9 8 0 0
5 9 7 0 0
5 9 6 0 0
5 9 5 0 0
5 9 4 0 0
5 9 3 0 0
5 9 2 0 0
5 9 1 0 0
5 9 0 0 64
5 10 19 0 44
5 10 18 0 12
5 10 17 0 12
5 10 16 0 12
5 10 15 0 12
5 10 14 0 12
5 10 13 0 12
5 10 12 0 12
5 10 11 0 12
5 10 10 0 12
5 10 9 0 12
5 10 8 0 12
5 10 7 0 12
5 10 6 0 12
5 10 5 0 12
5 10 4 0 12
5 10 3 0 12
5 10 2 0 12
5 10 1 0 12
5 10 0 0 76
6 1 19 0 50
6 1 18 0 18
6 1 17 0 18
6 1 16 0 18
6 1 15 0 18
6 1 14 0 18
6 1 13 0 18
6 1 12 0 18
6 1 11 0 18
6 1 10 0 18
6 1 9 0 18
6 1 8 0 18
6 1 7 0 18
6 1 6 0 18
6 1 5 0 18
6 1 4 0 18
6 1 3 0 18
6 1 2 0 18
6 1 1 0 18
6 1 0 0 82
6 2 19 0 32
6 2 18 0 0
6 2 17 0 0
6 2 16 0 0
6 2 15 0 0
6 2 14 0 0
6 2 13 0 0
6 2 12 0 0
6 2 11 0 0
6 2 10 0 0
6 2 9 0 0
6 2 8 0 0
6 2 7 0 0
6 2 6 0 0
6 2 5 0 0
6 2 4 0 0
6 2 3 0 0
6 2 2 0 0
6 2 1 0 0
6 2 0 0 64
6 3 19 0 32
6 3 18 0 0
6 3 17 0 0
6 3 16 0 0
6 3 15 0 0
6 3 14 0 0
6 3 13 0 0
6 3 12 0 0
6 3 11 0 0
6 3 10 0 0
6 3 9 0 0
6 3 8 0 0
6 3 7 0 0
6 3 6 0 0
6 3 5 0 0
6 3 4 0 0
6 3 3 0 0
6 3 2 0 0
6 3 1 0 0
6 3 0 0 64
6 4 19 0 32
6 4 18 0 0
6 4 17 0 0
6 4 16 0 0
6 4 15 0 0
6 4 14 0 0
6 4 13 0 0
6 4 12 0 0
6 4 11 0 0
6 4 10 0 0
6 4 9 0 0
6 4 8 0 0
6 4 7 0 0
6 4 6 0 0
6 4 5 0 0
6 4 4 0 0
6 4 3 0 0
6 4 2 0 0
6 4 1 0 0
6 4 0 0 64
6 5 19 0 32
6 5 18 0 0
6 5 17 0 0
6 5 16 0 0
6 5 15 0 0
6 5 14 0 0
6 5 13 0 0
6 5 12 0 0
6 5 11 0 0
6 5 10 0 0
6 5 9 0 0
6 5 8 0 0
6 5 7 0 0
6 5 6 0 0
6 5 5 0 0
6 5 4 0 0
6 5 3 0 0
6 5 2 0 0
6 5 1 0 0
6 5 0 0 64
6 6 19 0 32
6 6 18 0 0
6 6 17 0 0
6 6 16 0 0
6 6 15 0 0
6 6 14 0 0
6 6 13 0 0
6 6 12 0 0
6 6 11 0 0
6 6 10 0 0
6 6 9 0 0
6 6 8 0 0
6 6 7 0 0
6 6 6 0 0
6 6 5 0 0
6 6 4 0 0
6 6 3 0 0
6 6 2 0 0
6 6 1 0 0
6 6 0 0 64
6 7 19 0 32
6 7 18 0 0
6 7 17 0 0
6 7 16 0 0
6 7 15 0 0
6 7 14 0 0
6 7 13 0 0
6 7 12 0 0
6 7 11 0 0
6 7 10 0 0
6 7 9 0 0
6 7 8 0 0
6 7 7 0 0
6 7 6 0 0
6 7 5 0 0
6 7 4 0 0
6 7 3 0 0
6 7 2 0 0
6 7 1 0 0
6 7 0 0 64
6 8 19 0 32
6 8 18 0 0
6 8 17 0 0
6 8 16 0 0
6 8 15 0 0
6 8 14 0 0
6 8 13 0 0
6 8 12 0 0
6 8 11 0 0
6 8 10 0 0
6 8 9 0 0
6 8 8 0 0
6 8 7 0 0
6 8 6 0 0
6 8 5 0 0
6 8 4 0 0
6 8 3 0 0
6 8 2 0 0
6 8 1 0 0
6 8 0 0 64
6 9 19 0 32
6 9 18 0 0
6 9 17 0 0
6 9 16 0 0
6 9 15 0 0
6 9 14 0 0
6 9 13 0 0
6 9 12 0 0
6 9 11 0 0
6 9 10 0 0
6 9 9 0 0
6 9 8 0 0
6 9 7 0 0
6 9 6 0 0
6 9 5 0 0
6 9 4 0 0
6 9 3 0 0
6 9 2 0 0
6 9 1 0 0
6 9 0 0 64
6 10 19 0 42
6 10 18 0 10
6 10 17 0 10
6 10 16 0 10
6 10 15 0 10
6 10 14 0 10
6 10 13 0 10
6 10 12 0 10
6 10 11 0 10
6 10 10 0 10
6 10 9 0 10
6 10 8 0 10
6 10 7 0 10
6 10 6 0 10
6 10 5 0 10
6 10 4 0 10
6 10 3 0 10
6 10 2 0 10
6 10 1 0 10
6 10 0 0 74
7 2 19 0 48
7 2 18 0 16
7 2 17 0 16
7 2 16 0 16
7 2 15 0 16
7 2 14 0 16
7 2 13 0 16
7 2 12 0 16
7 2 11 0 16
7 2 10 0 16
7 2 9 0 16
7 2 8 0 16
7 2 7 0 16
7 2 6 0 16
7 2 5 0 16
7 2 4 0 16
7 2 3 0 16
7 2 2 0 16
7 2 1 0 16
7 2 0 0 80
7 3 19 0 32
7 3 18 0 0
7 3 17 0 0
7 3 16 0 0
7 3 15 0 0
7 3 14 0 0
7 3 13 0 0
7 3 12 0 0
7 3 11 0 0
7 3 10 0 0
7 3 9 0 0
7 3 8 0 0
7 3 7 0 0
7 3 6 0 0
7 3 5 0 0
7 3 4 0 0
7 3 3 0 0
7 3 2 0 0
7 3 1 0 0
7 3 0 0 64
7 4 19 0 32
7 4 18 0 0
7 4 17 0 0
7 4 16 0 0
7 4 15 0 0
7 4 14 0 0
7 4 13 0 0
7 4 12 0 0
7 4 11 0 0
7 4 10 0 0
7 4 9 0 0
7 4 8 0 0
7 4 7 0 0
7 4 6 0 0
7 4 5 0 0
7 4 4 0 0
7 4 3 0 0
7 4 2 0 0
7 4 1 0 0
7 4 0 0 64
7 5 19 0 32
7 5 18 0 0
7 5 17 0 0
7 5 16 0 0
7 5 15 0 0
7 5 14 0 0
7 5 13 0 0
7 5 12 0 0
7 5 11 0 0
7 5 10 0 0
7 5 9 0 0
7 5 8 0 0
7 5 7 0 0
7 5 6 0 0
7 5 5 0 0
7 5 4 0 0
7 5 3 0 0
7 5 2 0 0
7 5 1 0 0
7 5 0 0 64
7 6 19 0 32
7 6 18 0 0
7 6 17 0 0
7 6 16 0 0
7 6 15 0 0
7 6 14 0 0
7 6 13 0 0
7 6 12 0 0
7 6 11 0 0
7 6 10 0 0
7 6 9 0 0
7 6 8 0 0
7 6 7 0 0
7 6 6 0 0
7 6 5 0 0
7 6 4 0 0
7 6 3 0 0
7 6 2 0 0
7 6 1 0 0
7 6 0 0 64
7 7 19 0 32
7 7 18 0 0
7 7 17 0 0
7 7 16 0 0
7 7 15 0 0
7 7 14 0 0
7 7 13 0 0
7 7 12 0 0
7 7 11 0 0
7 7 10 0 0
7 7 9 0 0
7 7 8 0 0
7 7 7 0 0
7 7 6 0 0
7 7 5 0 0
7 7 4 0 0
7 7 3 0 0
7 7 2 0 0
7 7 1 0 0
7 7 0 0 64
7 8 19 0 32
7 8 18 0 0
7 8 17 0 0
7 8 16 0 0
7 8 15 0 0
7 8 14 0 0
7 8 13 0 0
7 8 12 0 0
7 8 11 0 0
7 8 10 0 0
7 8 9 0 0
7 8 8 0 0
7 8 7 0 0
7 8 6 0 0
7 8 5 0 0
7 8 4 0 0
7 8 3 0 0
7 8 2 0 0
7 8 1 0 0
7 8 0 0 64
7 9 19 0 40
7 9 18 0 8
7 9 17 0 8
7 9 16 0 8
7 9 15 0 8
7 9 14 0 8
7 9 13 0 8
7 9 12 0 8
7 9 11 0 8
7 9 10 0 8
7 9 9 0 8
7 9 8 0 8
7 9 7 0 8
7 9 6 0 8
7 9 5 0 8
7 9 4 0 8
7 9 3 0 8
7 9 2 0 8
7 9 1 0 8
7 9 0 0 72
8 2 19 0 50
8 2 18 0 18
8 2 17 0 18
8 2 16 0 18
8 2 15 0 18
8 2 14 0 18
8 2 13 0 18
8 2 12 0 18
8 2 11 0 18
8 2 10 0 18
8 2 9 0 18
8 2 8 0 18
8 2 7 0 18
8 2 6 0 18
8 2 5 0 18
8 2 4 0 18
8 2 3 0 18
8 2 2 0 18
8 2 1 0 18
8 2 0 0 82
8 3 19 0 32
8 3 18 0 0
8 3 17 0 0
8 3 16 0 0
8 3 15 0 0
8 3 14 0 0
8 3 13 0 0
8 3 12 0 0
8 3 11 0 0
8 3 10 0 0
8 3 9 0 0
8 3 8 0 0
8 3 7 0 0
8 3 6 0 0
8 3 5 0 0
8 3 4 0 0
8 3 3 0 0
8 3 2 0 0
8 3 1 0 0
8 3 0 0 64
8 4 19 0 32
8 4 18 0 0
8 4 17 0 0
8 4 16 0 0
8 4 15 0 0
8 4 14 0 0
8 4 13 0 0
8 4 12 0 0
8 4 11 0 0
8 4 10 0 0
8 4 9 0 0
8 4 8 0 0
8 4 7 0 0
8 4 6 0 0
8 4 5 0 0
8 4 4 0 0
8 4 3 0 0
8 4 2 0 0
8 4 1 0 0
8 4 0 0 64
8 5 19 0 32
8 5 18 0 0
8 5 17 0 0
8 5 16 0 0
8 5 15 0 0
8 5 14 0 0
8 5 13 0 0
8 5 12 0 0
8 5 11 0 0
8 5 10 0 0
8 5 9 0 0
8 5 8 0 0
8 5 7 0 0
8 5 6 0 0
8 5 5 0 0
8 5 4 0 0
8 5 3 0 0
8 5 2 0 0
8 5 1 0 0
8 5 0 0 64
8 6 19 0 32
8 6 18 0 0
8 6 17 0 0
8 6 16 0 0
8 6 15 0 0
8 6 14 0 0
8 6 13 0 0
8 6 12 0 0
8 6 11 0 0
8 6 10 0 0
8 6 9 0 0
8 6 8 0 0
8 6 7 0 0
8 6 6 0 0
8 6 5 0 0
8 6 4 0 0
8 6 3 0 0
8 6 2 0 0
8 6 1 0 0
8 6 0 0 64
8 7 19 0 32
8 7 18 0 0
8 7 17 0 0
8 7 16 0 0
8 7 15 0 0
8 7 14 0 0
8 7 13 0 0
8 7 12 0 0
8 7 11 0 0
8 7 10 0 0
8 7 9 0 0
8 7 8 0 0
8 7 7 0 0
8 7 6 0 0
8 7 5 0 0
8 7 4 0 0
8 7 3 0 0
8 7 2 0 0
8 7 1 0 0
8 7 0 0 64
8 8 19 0 32
8 8 18 0 0
8 8 17 0 0
8 8 16 0 0
8 8 15 0 0
8 8 14 0 0
8 8 13 0 0
8 8 12 0 0
8 8 11 0 0
8 8 10 0 0
8 8 9 0 0
8 8 8 0 0
8 8 7 0 0
8 8 6 0 0
8 8 5 0 0
8 8 4 0 0
8 8 3 0 0
8 8 2 0 0
8 8 1 0 0
8 8 0 0 64
8 9 19 0 42
8 9 18 0 10
8 9 17 0 10
8 9 16 0 10
8 9 15 0 10
8 9 14 0 10
8 9 13 0 10
8 9 12 0 10
8 9 11 0 10
8 9 10 0 10
8 9 9 0 10
8 9 8 0 10
8 9 7 0 10
8 9 6 0 10
8 9 5 0 10
8 9 4 0 10
8 9 3 0 10
8 9 2 0 10
8 9 1 0 10
8 9 0 0 74
9 3 19 0 50
9 3 18 0 18
9 3 17 0 18
9 3 16 0 18
9 3 15 0 18
9 3 14 0 18
9 3 13 0 18
9 3 12 0 18
9 3 11 0 18
9 3 10 0 18
9 3 9 0 18
9 3 8 0 18
9 3 7 0 18
9 3 6 0 18
9 3 5 0 18
9 3 4 0 18
9 3 3 0 18
9 3 2 0 18
9 3 1 0 18
9 3 0 0 82
9 4 19 0 34
9 4 18 0 2
9 4 17 0 2
9 4 16 0 2
9 4 15 0 2
9 4 14 0 2
9 4 13 0 2
9 4 12 0 2
9 4 11 0 2
9 4 10 0 2
9 4 9 0 2
9 4 8 0 2
9 4 7 0 2
9 4 6 0 2
9 4 5 0 2
9 4 4 0 2
9 4 3 0 2
9 4 2 0 2
9 4 1 0 2
9 4 0 0 66
9 5 19 0 32
9 5 18 0 0
9 5 17 0 0
9 5 16 0 0
9 5 15 0 0
9 5 14 0 0
9 5 13 0 0
9 5 12 0 0
9 5 11 0 0
9 5 10 0 0
9 5 9 0 0
9 5 8 0 0
9 5 7 0 0
9 5 6 0 0
9 5 5 0 0
9 5 4 0 0
9 5 3 0 0
9 5 2 0 0
9 5 1 0 0
9 5 0 0 64
9 6 19 0 32
9 6 18 0 0
9 6 17 0 0
9 6 16 0 0
9 6 15 0 0
9 6 14 0 0
9 6 13 0 0
9 6 12 0 0
9 6 11 0 0
9 6 10 0 0
9 6 9 0 0
9 6 8 0 0
9 6 7 0 0
9 6 6 0 0
9 6 5 0 0
9 6 4 0 0
9 6 3 0 0
9 6 2 0 0
9 6 1 0 0
9 6 0 0 64
9 7 19 0 34
9 7 18 0 2
9 7 17 0 2
9 7 16 0 2
9 7 15 0 2
9 7 14 0 2
9 7 13 0 2
9 7 12 0 2
9 7 11 0 2
9 7 10 0 2
9 7 9 0 2
9 7 8 0 2
9 7 7 0 2
9 7 6 0 2
9 7 5 0 2
9 7 4 0 2
9 7 3 0 2
9 7 2 0 2
9 7 1 0 2
9 7 0 0 66
9 8 19 0 42
9 8 18 0 10
9 8 17 0 10
9 8 16 0 10
9 8 15 0 10
9 8 14 0 10
9 8 13 0 10
9 8 12 0 10
9 8 11 0 10
9 8 10 0 10
9 8 9 0 10
9 8 8 0 10
9 8 7 0 10
9 8 6 0 10
9 8 5 0 10
9 8 4 0 10
9 8 3 0 10
9 8 2 0 10
9 8 1 0 10
9 8 0 0 74
10 5 19 0 50
10 5 18 0 18
10 5 17 0 18
10 5 16 0 18
10 5 15 0 18
10 5 14 0 18
10 5 13 0 18
10 5 12 0 18
10 5 11 0 18
10 5 10 0 18
10 5 9 0 18
10 5 8 0 18
10 5 7 0 18
10 5 6 0 18
10 5 5 0 18
10 5 4 0 18
10 5 3 0 18
10 5 2 0 18
10 5 1 0 18
10 5 0 0 82
10 6 19 0 42
10 6 18 0 10
10 6 17 0 10
10 6 16 0 10
10 6 15 0 10
10 6 14 0 10
10 6 13 0 10
10 6 12 0 10
10 6 11 0 10
10 6 10 0 10
10 6 9 0 10
10 6 8 0 10
10 6 7 0 10
10 6 6 0 10
10 6 5 0 10
10 6 4 0 10
10 6 3 0 10
10 6 2 0 10
10 6 1 0 10
10 6 0 0 74
