Qubicle Exchange Format
Version 0.2
www.minddesk.com
9 9 9
1
0.152941 0.152941 0.152941
1 2 4 0 52
1 2 3 0 84
1 3 5 0 52
1 3 4 0 4
1 3 3 0 4
1 3 2 0 84
1 4 6 0 52
1 4 5 0 4
1 4 4 0 4
1 4 3 0 4
1 4 2 0 4
1 4 1 0 84
1 5 6 0 44
1 5 5 0 4
1 5 4 0 4
1 5 3 0 4
1 5 2 0 4
1 5 1 0 76
1 6 5 0 44
1 6 4 0 4
1 6 3 0 4
1 6 2 0 76
1 7 4 0 44
1 7 3 0 76
2 1 4 0 52
2 1 3 0 84
2 2 6 0 52
2 2 5 0 20
2 2 4 0 0
2 2 3 0 0
2 2 2 0 20
2 2 1 0 84
2 3 6 0 36
2 3 5 0 0
2 3 4 0 0
2 3 3 0 0
2 3 2 0 0
2 3 1 0 68
2 4 7 0 52
2 4 6 0 0
2 4 5 0 0
2 4 4 0 0
2 4 3 0 0
2 4 2 0 0
2 4 1 0 0
2 4 0 0 84
2 5 7 0 44
2 5 6 0 0
2 5 5 0 0
2 5 4 0 0
2 5 3 0 0
2 5 2 0 0
2 5 1 0 0
2 5 0 0 76
2 6 6 0 36
2 6 5 0 0
2 6 4 0 0
2 6 3 0 0
2 6 2 0 0
2 6 1 0 68
2 7 6 0 44
2 7 5 0 12
2 7 4 0 0
2 7 3 0 0
2 7 2 0 12
2 7 1 0 76
2 8 4 0 44
2 8 3 0 76
3 1 5 0 52
3 1 4 0 16
3 1 3 0 16
3 1 2 0 84
3 2 6 0 48
3 2 5 0 0
3 2 4 0 0
3 2 3 0 0
3 2 2 0 0
3 2 1 0 80
3 3 7 0 52
3 3 6 0 0
3 3 5 0 0
3 3 4 0 0
3 3 3 0 0
3 3 2 0 0
3 3 1 0 0
3 3 0 0 84
3 4 7 0 32
3 4 6 0 0
3 4 5 0 0
3 4 4 0 0
3 4 3 0 0
3 4 2 0 0
3 4 1 0 0
3 4 0 0 64
3 5 7 0 32
3 5 6 0 0
3 5 5 0 0
3 5 4 0 0
3 5 3 0 0
3 5 2 0 0
3 5 1 0 0
3 5 0 0 64
3 6 7 0 44
3 6 6 0 0
3 6 5 0 0
3 6 4 0 0
3 6 3 0 0
3 6 2 0 0
3 6 1 0 0
3 6 0 0 76
3 7 6 0 40
3 7 5 0 0
3 7 4 0 0
3 7 3 0 0
3 7 2 0 0
3 7 1 0 72
3 8 5 0 44
3 8 4 0 8
3 8 3 0 8
3 8 2 0 76
4 1 6 0 52
4 1 5 0 16
4 1 4 0 16
4 1 3 0 16
4 1 2 0 16
4 1 1 0 84
4 2 7 0 52
4 2 6 0 0
4 2 5 0 0
4 2 4 0 0
4 2 3 0 0
4 2 2 0 0
4 2 1 0 0
4 2 0 0 84
4 3 7 0 32
4 3 6 0 0
4 3 5 0 0
4 3 4 0 0
4 3 3 0 0
4 3 2 0 0
4 3 1 0 0
4 3 0 0 64
4 4 7 0 32
4 4 6 0 0
4 4 5 0 0
4 4 4 0 0
4 4 3 0 0
4 4 2 0 0
4 4 1 0 0
4 4 0 0 64
4 5 7 0 32
4 5 6 0 0
4 5 5 0 0
4 5 4 0 0
4 5 3 0 0
4 5 2 0 0
4 5 1 0 0
4 5 0 0 64
4 6 7 0 32
4 6 6 0 0
4 6 5 0 0
4 6 4 0 0
4 6 3 0 0
4 6 2 0 0
4 6 1 0 0
4 6 0 0 64
4 7 7 0 44
4 7 6 0 0
4 7 5 0 0
4 7 4 0 0
4 7 3 0 0
4 7 2 0 0
4 7 1 0 0
4 7 0 0 76
4 8 6 0 44
4 8 5 0 8
4 8 4 0 8
4 8 3 0 8
4 8 2 0 8
4 8 1 0 76
5 1 6 0 50
5 1 5 0 16
5 1 4 0 16
5 1 3 0 16
5 1 2 0 16
5 1 1 0 82
5 2 7 0 50
5 2 6 0 0
5 2 5 0 0
5 2 4 0 0
5 2 3 0 0
5 2 2 0 0
5 2 1 0 0
5 2 0 0 82
5 3 7 0 32
5 3 6 0 0
5 3 5 0 0
5 3 4 0 0
5 3 3 0 0
5 3 2 0 0
5 3 1 0 0
5 3 0 0 64
5 4 7 0 32
5 4 6 0 0
5 4 5 0 0
5 4 4 0 0
5 4 3 0 0
5 4 2 0 0
5 4 1 0 0
5 4 0 0 64
5 5 7 0 32
5 5 6 0 0
5 5 5 0 0
5 5 4 0 0
5 5 3 0 0
5 5 2 0 0
5 5 1 0 0
5 5 0 0 64
5 6 7 0 32
5 6 6 0 0
5 6 5 0 0
5 6 4 0 0
5 6 3 0 0
5 6 2 0 0
5 6 1 0 0
5 6 0 0 64
5 7 7 0 42
5 7 6 0 0
5 7 5 0 0
5 7 4 0 0
5 7 3 0 0
5 7 2 0 0
5 7 1 0 0
5 7 0 0 74
5 8 6 0 42
5 8 5 0 8
5 8 4 0 8
5 8 3 0 8
5 8 2 0 8
5 8 1 0 74
6 1 5 0 50
6 1 4 0 16
6 1 3 0 16
6 1 2 0 82
6 2 6 0 48
6 2 5 0 0
6 2 4 0 0
6 2 3 0 0
6 2 2 0 0
6 2 1 0 80
6 3 7 0 50
6 3 6 0 0
6 3 5 0 0
6 3 4 0 0
6 3 3 0 0
6 3 2 0 0
6 3 1 0 0
6 3 0 0 82
6 4 7 0 32
6 4 6 0 0
6 4 5 0 0
6 4 4 0 0
6 4 3 0 0
6 4 2 0 0
6 4 1 0 0
6 4 0 0 64
6 5 7 0 32
6 5 6 0 0
6 5 5 0 0
6 5 4 0 0
6 5 3 0 0
6 5 2 0 0
6 5 1 0 0
6 5 0 0 64
6 6 7 0 42
6 6 6 0 0
6 6 5 0 0
6 6 4 0 0
6 6 3 0 0
6 6 2 0 0
6 6 1 0 0
6 6 0 0 74
6 7 6 0 40
6 7 5 0 0
6 7 4 0 0
6 7 3 0 0
6 7 2 0 0
6 7 1 0 72
6 8 5 0 42
6 8 4 0 8
6 8 3 0 8
6 8 2 0 74
7 1 4 0 50
7 1 3 0 82
7 2 6 0 50
7 2 5 0 18
7 2 4 0 0
7 2 3 0 0
7 2 2 0 18
7 2 1 0 82
7 3 6 0 34
7 3 5 0 0
7 3 4 0 0
7 3 3 0 0
7 3 2 0 0
7 3 1 0 66
7 4 7 0 50
7 4 6 0 0
7 4 5 0 0
7 4 4 0 0
7 4 3 0 0
7 4 2 0 0
7 4 1 0 0
7 4 0 0 82
7 5 7 0 42
7 5 6 0 0
7 5 5 0 0
7 5 4 0 0
7 5 3 0 0
7 5 2 0 0
7 5 1 0 0
7 5 0 0 74
7 6 6 0 34
7 6 5 0 0
7 6 4 0 0
7 6 3 0 0
7 6 2 0 0
7 6 1 0 66
7 7 6 0 42
7 7 5 0 10
7 7 4 0 0
7 7 3 0 0
7 7 2 0 10
7 7 1 0 74
7 8 4 0 42
7 8 3 0 74
8 2 4 0 50
8 2 3 0 82
8 3 5 0 50
8 3 4 0 2
8 3 3 0 2
8 3 2 0 82
8 4 6 0 50
8 4 5 0 2
8 4 4 0 2
8 4 3 0 2
8 4 2 0 2
8 4 1 0 82
8 5 6 0 42
8 5 5 0 2
8 5 4 0 2
8 5 3 0 2
8 5 2 0 2
8 5 1 0 74
8 6 5 0 42
8 6 4 0 2
8 6 3 0 2
8 6 2 0 74
8 7 4 0 42
8 7 3 0 74
