Qubicle Exchange Format
Version 0.2
www.minddesk.com
12 12 27
5
0.180392 0.117647 0.047059
0.180392 0.145098 0.098039
0.188235 0.192157 0.196078
0.368627 0.160784 0.121569
0.745098 0.635294 0.003922
2 6 25 1 52
2 6 24 0 20
2 6 23 0 84
2 6 12 2 52
2 6 11 2 20
2 6 10 2 20
2 6 9 2 20
2 6 8 2 84
2 7 25 1 44
2 7 24 0 12
2 7 23 0 76
2 7 12 2 44
2 7 11 2 12
2 7 10 2 12
2 7 9 2 12
2 7 8 2 76
3 4 25 1 52
3 4 24 0 20
3 4 23 0 84
3 4 12 2 52
3 4 11 2 20
3 4 10 2 20
3 4 9 2 20
3 4 8 2 84
3 5 25 1 36
3 5 24 0 4
3 5 23 0 70
3 5 12 2 36
3 5 11 2 4
3 5 10 2 4
3 5 9 2 4
3 5 8 2 68
3 6 25 1 34
3 6 24 0 2
3 6 23 0 2
3 6 22 4 22
3 6 21 3 22
3 6 20 3 22
3 6 19 2 22
3 6 18 2 22
3 6 17 2 20
3 6 16 3 20
3 6 15 3 20
3 6 14 3 20
3 6 13 3 20
3 6 12 2 0
3 6 11 2 0
3 6 10 2 0
3 6 9 2 0
3 6 8 2 64
3 7 25 1 34
3 7 24 0 2
3 7 23 0 2
3 7 22 4 14
3 7 21 3 14
3 7 20 3 14
3 7 19 2 12
3 7 18 2 14
3 7 17 2 12
3 7 16 3 12
3 7 15 3 12
3 7 14 3 12
3 7 13 3 12
3 7 12 2 0
3 7 11 2 0
3 7 10 2 0
3 7 9 2 0
3 7 8 2 64
3 8 25 1 36
3 8 24 0 4
3 8 23 0 68
3 8 12 2 36
3 8 11 2 4
3 8 10 2 4
3 8 9 2 4
3 8 8 2 68
3 9 25 1 44
3 9 24 0 12
3 9 23 0 76
3 9 12 2 44
3 9 11 2 12
3 9 10 2 12
3 9 9 2 12
3 9 8 2 76
4 3 25 1 52
4 3 24 0 20
4 3 23 0 84
4 3 12 2 52
4 3 11 2 20
4 3 10 2 20
4 3 9 2 20
4 3 8 2 84
4 4 25 0 32
4 4 24 0 0
4 4 23 0 8
4 4 22 4 20
4 4 21 2 20
4 4 20 2 20
4 4 19 2 20
4 4 18 2 20
4 4 17 2 20
4 4 16 2 20
4 4 15 2 20
4 4 14 2 20
4 4 13 2 20
4 4 12 2 0
4 4 11 2 0
4 4 10 2 0
4 4 9 2 0
4 4 8 2 64
4 5 25 0 42
4 5 24 0 74
4 5 22 4 46
4 5 21 2 14
4 5 20 2 14
4 5 19 2 14
4 5 18 2 14
4 5 17 2 4
4 5 16 2 4
4 5 15 2 4
4 5 14 2 4
4 5 13 2 4
4 5 12 2 0
4 5 11 2 0
4 5 10 2 0
4 5 9 2 0
4 5 8 2 64
4 6 17 2 32
4 6 16 2 0
4 6 15 2 0
4 6 14 2 0
4 6 13 2 0
4 6 12 2 0
4 6 11 2 0
4 6 10 2 0
4 6 9 2 0
4 6 8 2 64
4 7 19 2 114
4 7 17 2 32
4 7 16 2 0
4 7 15 2 0
4 7 14 2 0
4 7 13 2 0
4 7 12 2 0
4 7 11 2 0
4 7 10 2 0
4 7 9 2 0
4 7 8 2 64
4 8 25 0 50
4 8 24 0 18
4 8 23 0 18
4 8 22 4 22
4 8 21 2 22
4 8 20 2 22
4 8 19 2 4
4 8 18 2 22
4 8 17 2 4
4 8 16 2 4
4 8 15 2 4
4 8 14 2 4
4 8 13 2 4
4 8 12 2 0
4 8 11 2 0
4 8 10 2 0
4 8 9 2 0
4 8 8 2 64
4 9 25 1 32
4 9 24 0 0
4 9 23 0 0
4 9 22 4 12
4 9 21 2 12
4 9 20 2 12
4 9 19 2 12
4 9 18 2 12
4 9 17 2 12
4 9 16 2 12
4 9 15 2 12
4 9 14 2 12
4 9 13 2 12
4 9 12 2 0
4 9 11 2 0
4 9 10 2 0
4 9 9 2 0
4 9 8 2 64
4 10 25 1 44
4 10 24 0 12
4 10 23 0 76
4 10 12 2 44
4 10 11 2 12
4 10 10 2 12
4 10 9 2 12
4 10 8 2 76
5 3 25 1 48
5 3 24 0 16
5 3 23 0 80
5 3 12 2 48
5 3 11 2 16
5 3 10 2 16
5 3 9 2 16
5 3 8 2 80
5 4 25 0 42
5 4 24 0 10
5 4 23 0 10
5 4 22 4 26
5 4 21 2 26
5 4 20 2 26
5 4 19 2 24
5 4 18 2 26
5 4 17 2 16
5 4 16 2 16
5 4 15 2 16
5 4 14 2 16
5 4 13 2 16
5 4 12 2 0
5 4 11 2 0
5 4 10 2 0
5 4 9 2 0
5 4 8 2 64
5 5 17 2 32
5 5 16 2 0
5 5 15 2 0
5 5 14 2 0
5 5 13 2 0
5 5 12 2 0
5 5 11 2 0
5 5 10 2 0
5 5 9 2 0
5 5 8 2 64
5 6 17 2 32
5 6 16 2 0
5 6 15 2 0
5 6 14 2 0
5 6 13 2 0
5 6 12 2 0
5 6 11 2 0
5 6 10 2 0
5 6 9 2 0
5 6 8 2 64
5 7 17 2 32
5 7 16 2 0
5 7 15 2 0
5 7 14 2 0
5 7 13 2 0
5 7 12 2 0
5 7 11 2 0
5 7 10 2 0
5 7 9 2 0
5 7 8 2 64
5 8 19 2 114
5 8 17 2 32
5 8 16 2 0
5 8 15 2 0
5 8 14 2 0
5 8 13 2 0
5 8 12 2 0
5 8 11 2 0
5 8 10 2 0
5 8 9 2 0
5 8 8 2 64
5 9 25 0 50
5 9 24 0 18
5 9 23 0 18
5 9 22 4 26
5 9 21 2 26
5 9 20 2 26
5 9 19 2 10
5 9 18 2 26
5 9 17 2 8
5 9 16 2 8
5 9 15 2 8
5 9 14 2 8
5 9 13 2 8
5 9 12 2 0
5 9 11 2 0
5 9 10 2 0
5 9 9 2 0
5 9 8 2 64
5 10 25 1 40
5 10 24 0 8
5 10 23 0 72
5 10 12 2 40
5 10 11 2 8
5 10 10 2 8
5 10 9 2 8
5 10 8 2 72
6 2 25 1 52
6 2 24 0 20
6 2 23 0 84
6 2 11 2 52
6 2 10 2 20
6 2 9 2 20
6 2 8 2 84
6 3 25 1 40
6 3 24 0 8
6 3 23 0 8
6 3 22 4 28
6 3 21 3 28
6 3 20 3 28
6 3 19 2 20
6 3 18 2 28
6 3 17 2 20
6 3 16 3 20
6 3 15 3 20
6 3 14 3 20
6 3 13 3 20
6 3 12 2 16
6 3 11 2 0
6 3 10 2 0
6 3 9 2 0
6 3 8 2 64
6 4 19 2 104
6 4 17 2 34
6 4 16 2 0
6 4 15 2 0
6 4 14 2 0
6 4 13 2 0
6 4 12 2 0
6 4 11 2 0
6 4 10 2 0
6 4 9 2 0
6 4 8 2 64
6 5 17 2 32
6 5 16 2 0
6 5 15 2 0
6 5 14 2 0
6 5 13 2 0
6 5 12 2 0
6 5 11 2 0
6 5 10 2 0
6 5 9 2 0
6 5 8 2 64
6 6 17 2 32
6 6 16 2 0
6 6 15 2 0
6 6 14 2 0
6 6 13 2 0
6 6 12 2 0
6 6 11 2 0
6 6 10 2 0
6 6 9 2 0
6 6 8 2 64
6 7 17 2 32
6 7 16 2 0
6 7 15 2 0
6 7 14 2 0
6 7 13 2 0
6 7 12 2 0
6 7 11 2 0
6 7 10 2 0
6 7 9 2 0
6 7 8 2 64
6 8 17 2 32
6 8 16 2 0
6 8 15 2 0
6 8 14 2 0
6 8 13 2 0
6 8 12 2 0
6 8 11 2 0
6 8 10 2 0
6 8 9 2 0
6 8 8 2 64
6 9 17 2 32
6 9 16 2 0
6 9 15 2 0
6 9 14 2 0
6 9 13 2 0
6 9 12 2 0
6 9 11 2 0
6 9 10 2 0
6 9 9 2 0
6 9 8 2 64
6 10 25 0 48
6 10 24 0 16
6 10 23 0 16
6 10 22 4 28
6 10 21 3 28
6 10 20 3 28
6 10 19 2 28
6 10 18 2 28
6 10 17 2 12
6 10 16 3 12
6 10 15 3 12
6 10 14 3 12
6 10 13 3 12
6 10 12 2 8
6 10 11 2 0
6 10 10 2 0
6 10 9 2 0
6 10 8 2 64
6 11 25 1 44
6 11 24 0 12
6 11 23 0 76
6 11 11 2 44
6 11 10 2 12
6 11 9 2 12
6 11 8 2 76
7 2 25 1 50
7 2 24 0 18
7 2 23 0 82
7 2 11 2 50
7 2 10 2 18
7 2 9 2 18
7 2 8 2 82
7 3 25 1 40
7 3 24 0 8
7 3 23 0 8
7 3 22 4 26
7 3 21 3 26
7 3 20 3 26
7 3 19 2 18
7 3 18 2 26
7 3 17 2 26
7 3 16 3 18
7 3 15 3 18
7 3 14 3 18
7 3 13 3 18
7 3 12 2 16
7 3 11 2 0
7 3 10 2 0
7 3 9 2 0
7 3 8 2 64
7 4 19 2 104
7 4 16 2 32
7 4 15 2 0
7 4 14 2 0
7 4 13 2 0
7 4 12 2 0
7 4 11 2 0
7 4 10 2 0
7 4 9 2 0
7 4 8 2 64
7 5 17 2 48
7 5 16 2 0
7 5 15 2 0
7 5 14 2 0
7 5 13 2 0
7 5 12 2 0
7 5 11 2 0
7 5 10 2 0
7 5 9 2 0
7 5 8 2 64
7 6 17 2 32
7 6 16 2 0
7 6 15 2 0
7 6 14 2 0
7 6 13 2 0
7 6 12 2 0
7 6 11 2 0
7 6 10 2 0
7 6 9 2 0
7 6 8 2 64
7 7 17 2 32
7 7 16 2 0
7 7 15 2 0
7 7 14 2 0
7 7 13 2 0
7 7 12 2 0
7 7 11 2 0
7 7 10 2 0
7 7 9 2 0
7 7 8 2 64
7 8 17 2 32
7 8 16 2 0
7 8 15 2 0
7 8 14 2 0
7 8 13 2 0
7 8 12 2 0
7 8 11 2 0
7 8 10 2 0
7 8 9 2 0
7 8 8 2 64
7 9 17 2 32
7 9 16 2 0
7 9 15 2 0
7 9 14 2 0
7 9 13 2 0
7 9 12 2 0
7 9 11 2 0
7 9 10 2 0
7 9 9 2 0
7 9 8 2 64
7 10 25 0 48
7 10 24 0 16
7 10 23 0 16
7 10 22 4 26
7 10 21 3 26
7 10 20 3 26
7 10 19 2 26
7 10 18 2 26
7 10 17 2 10
7 10 16 3 10
7 10 15 3 10
7 10 14 3 10
7 10 13 3 10
7 10 12 2 8
7 10 11 2 0
7 10 10 2 0
7 10 9 2 0
7 10 8 2 64
7 11 25 1 42
7 11 24 0 10
7 11 23 0 74
7 11 11 2 42
7 11 10 2 10
7 11 9 2 10
7 11 8 2 74
8 3 25 1 48
8 3 24 0 16
8 3 23 0 80
8 3 12 2 48
8 3 11 2 16
8 3 10 2 16
8 3 9 2 16
8 3 8 2 80
8 4 25 0 44
8 4 24 0 12
8 4 23 0 12
8 4 22 4 28
8 4 21 2 28
8 4 20 2 28
8 4 19 2 24
8 4 18 2 28
8 4 17 2 20
8 4 16 2 16
8 4 15 2 16
8 4 14 2 16
8 4 13 2 16
8 4 12 2 0
8 4 11 2 0
8 4 10 2 0
8 4 9 2 0
8 4 8 2 64
8 5 17 2 32
8 5 16 2 0
8 5 15 2 0
8 5 14 2 0
8 5 13 2 0
8 5 12 2 0
8 5 11 2 0
8 5 10 2 0
8 5 9 2 0
8 5 8 2 64
8 6 17 2 32
8 6 16 2 0
8 6 15 2 0
8 6 14 2 0
8 6 13 2 0
8 6 12 2 0
8 6 11 2 0
8 6 10 2 0
8 6 9 2 0
8 6 8 2 64
8 7 17 2 32
8 7 16 2 0
8 7 15 2 0
8 7 14 2 0
8 7 13 2 0
8 7 12 2 0
8 7 11 2 0
8 7 10 2 0
8 7 9 2 0
8 7 8 2 64
8 8 17 2 32
8 8 16 2 0
8 8 15 2 0
8 8 14 2 0
8 8 13 2 0
8 8 12 2 0
8 8 11 2 0
8 8 10 2 0
8 8 9 2 0
8 8 8 2 64
8 9 25 0 52
8 9 24 0 20
8 9 23 0 20
8 9 22 4 28
8 9 21 2 28
8 9 20 2 28
8 9 19 2 28
8 9 18 2 28
8 9 17 2 8
8 9 16 2 8
8 9 15 2 8
8 9 14 2 8
8 9 13 2 8
8 9 12 2 0
8 9 11 2 0
8 9 10 2 0
8 9 9 2 0
8 9 8 2 64
8 10 25 1 40
8 10 24 0 8
8 10 23 0 72
8 10 12 2 40
8 10 11 2 8
8 10 10 2 8
8 10 9 2 8
8 10 8 2 72
9 3 25 1 50
9 3 24 0 18
9 3 23 0 82
9 3 12 2 50
9 3 11 2 18
9 3 10 2 18
9 3 9 2 18
9 3 8 2 82
9 4 25 1 32
9 4 24 0 0
9 4 23 0 0
9 4 22 4 18
9 4 21 2 18
9 4 20 2 18
9 4 19 2 18
9 4 18 2 18
9 4 17 2 18
9 4 16 2 18
9 4 15 2 18
9 4 14 2 18
9 4 13 2 18
9 4 12 2 0
9 4 11 2 0
9 4 10 2 0
9 4 9 2 0
9 4 8 2 64
9 5 25 0 44
9 5 24 0 12
9 5 23 0 12
9 5 22 4 14
9 5 21 2 14
9 5 20 2 14
9 5 19 2 14
9 5 18 2 14
9 5 17 2 2
9 5 16 2 2
9 5 15 2 2
9 5 14 2 2
9 5 13 2 2
9 5 12 2 0
9 5 11 2 0
9 5 10 2 0
9 5 9 2 0
9 5 8 2 64
9 6 17 2 32
9 6 16 2 0
9 6 15 2 0
9 6 14 2 0
9 6 13 2 0
9 6 12 2 0
9 6 11 2 0
9 6 10 2 0
9 6 9 2 0
9 6 8 2 64
9 7 17 2 32
9 7 16 2 0
9 7 15 2 0
9 7 14 2 0
9 7 13 2 0
9 7 12 2 0
9 7 11 2 0
9 7 10 2 0
9 7 9 2 0
9 7 8 2 64
9 8 25 0 52
9 8 24 0 20
9 8 23 0 20
9 8 22 4 22
9 8 21 2 22
9 8 20 2 22
9 8 19 2 22
9 8 18 2 22
9 8 17 2 2
9 8 16 2 2
9 8 15 2 2
9 8 14 2 2
9 8 13 2 2
9 8 12 2 0
9 8 11 2 0
9 8 10 2 0
9 8 9 2 0
9 8 8 2 64
9 9 25 1 32
9 9 24 0 0
9 9 23 0 0
9 9 22 4 10
9 9 21 2 10
9 9 20 2 10
9 9 19 2 10
9 9 18 2 10
9 9 17 2 10
9 9 16 2 10
9 9 15 2 10
9 9 14 2 10
9 9 13 2 10
9 9 12 2 0
9 9 11 2 0
9 9 10 2 0
9 9 9 2 0
9 9 8 2 64
9 10 25 1 42
9 10 24 0 10
9 10 23 0 74
9 10 12 2 42
9 10 11 2 10
9 10 10 2 10
9 10 9 2 10
9 10 8 2 74
10 4 25 1 50
10 4 24 0 18
10 4 23 0 82
10 4 12 2 50
10 4 11 2 18
10 4 10 2 18
10 4 9 2 18
10 4 8 2 82
10 5 25 1 34
10 5 24 0 2
10 5 23 0 66
10 5 12 2 34
10 5 11 2 2
10 5 10 2 2
10 5 9 2 2
10 5 8 2 66
10 6 25 1 36
10 6 24 0 4
10 6 23 0 4
10 6 22 4 22
10 6 21 3 22
10 6 20 3 22
10 6 19 2 22
10 6 18 2 22
10 6 17 2 18
10 6 16 3 18
10 6 15 3 18
10 6 14 3 18
10 6 13 3 18
10 6 12 2 2
10 6 11 2 2
10 6 10 2 2
10 6 9 2 2
10 6 8 2 64
10 7 25 1 36
10 7 24 0 4
10 7 23 0 4
10 7 22 4 14
10 7 21 3 14
10 7 20 3 14
10 7 19 2 14
10 7 18 2 14
10 7 17 2 10
10 7 16 3 10
10 7 15 3 10
10 7 14 3 10
10 7 13 3 10
10 7 12 2 2
10 7 11 2 2
10 7 10 2 2
10 7 9 2 2
10 7 8 2 64
10 8 25 1 34
10 8 24 0 2
10 8 23 0 66
10 8 12 2 34
10 8 11 2 2
10 8 10 2 2
10 8 9 2 2
10 8 8 2 66
10 9 25 1 42
10 9 24 0 10
10 9 23 0 74
10 9 12 2 42
10 9 11 2 10
10 9 10 2 10
10 9 9 2 10
10 9 8 2 74
11 6 25 1 50
11 6 24 0 18
11 6 23 1 82
11 6 8 2 114
11 7 25 1 42
11 7 24 0 10
11 7 23 0 74
11 7 8 2 106
