Qubicle Exchange Format
Version 0.2
www.minddesk.com
11 26 11
5
0.180392 0.117647 0.047059
0.180392 0.145098 0.098039
0.188235 0.192157 0.196078
0.368627 0.160784 0.121569
0.745098 0.635294 0.003922
1 8 5 2 52
1 8 4 2 84
1 9 5 2 36
1 9 4 2 68
1 10 5 2 36
1 10 4 2 68
1 11 5 2 44
1 11 4 2 76
1 23 5 0 52
1 23 4 0 84
1 24 5 0 36
1 24 4 0 68
1 25 5 1 44
1 25 4 1 76
2 8 7 2 52
2 8 6 2 20
2 8 5 2 16
2 8 4 2 16
2 8 3 2 20
2 8 2 2 84
2 9 7 2 36
2 9 6 2 4
2 9 5 2 0
2 9 4 2 0
2 9 3 2 4
2 9 2 2 68
2 10 7 2 36
2 10 6 2 4
2 10 5 2 0
2 10 4 2 0
2 10 3 2 4
2 10 2 2 68
2 11 7 2 36
2 11 6 2 4
2 11 5 2 0
2 11 4 2 0
2 11 3 2 4
2 11 2 2 68
2 12 7 2 44
2 12 6 2 12
2 12 5 2 4
2 12 4 2 4
2 12 3 2 12
2 12 2 2 76
2 13 5 3 36
2 13 4 3 68
2 14 5 3 36
2 14 4 3 68
2 15 5 3 36
2 15 4 3 68
2 16 5 3 36
2 16 4 3 68
2 17 5 2 36
2 17 4 2 68
2 18 5 2 38
2 18 4 2 70
2 19 5 2 38
2 19 4 2 70
2 20 5 3 38
2 20 4 3 70
2 21 5 3 38
2 21 4 3 70
2 22 5 4 38
2 22 4 4 70
2 23 7 0 52
2 23 6 0 20
2 23 5 0 2
2 23 4 0 2
2 23 3 0 20
2 23 2 0 84
2 24 7 0 36
2 24 6 0 4
2 24 5 0 2
2 24 4 0 2
2 24 3 0 4
2 24 2 0 68
2 25 7 1 44
2 25 6 1 12
2 25 5 0 10
2 25 4 0 10
2 25 3 1 12
2 25 2 1 76
3 8 8 2 52
3 8 7 2 16
3 8 6 2 16
3 8 5 2 16
3 8 4 2 16
3 8 3 2 16
3 8 2 2 16
3 8 1 2 84
3 9 8 2 36
3 9 7 2 0
3 9 6 2 0
3 9 5 2 0
3 9 4 2 0
3 9 3 2 0
3 9 2 2 0
3 9 1 2 68
3 10 8 2 36
3 10 7 2 0
3 10 6 2 0
3 10 5 2 0
3 10 4 2 0
3 10 3 2 0
3 10 2 2 0
3 10 1 2 68
3 11 8 2 36
3 11 7 2 0
3 11 6 2 0
3 11 5 2 0
3 11 4 2 0
3 11 3 2 0
3 11 2 2 0
3 11 1 2 68
3 12 8 2 44
3 12 7 2 0
3 12 6 2 0
3 12 5 2 0
3 12 4 2 0
3 12 3 2 0
3 12 2 2 0
3 12 1 2 76
3 13 7 2 36
3 13 6 2 4
3 13 5 2 0
3 13 4 2 0
3 13 3 2 4
3 13 2 2 68
3 14 7 2 36
3 14 6 2 4
3 14 5 2 0
3 14 4 2 0
3 14 3 2 4
3 14 2 2 68
3 15 7 2 36
3 15 6 2 4
3 15 5 2 0
3 15 4 2 0
3 15 3 2 4
3 15 2 2 68
3 16 7 2 36
3 16 6 2 4
3 16 5 2 0
3 16 4 2 0
3 16 3 2 4
3 16 2 2 68
3 17 7 2 36
3 17 6 2 4
3 17 5 2 8
3 17 4 2 8
3 17 3 2 4
3 17 2 2 68
3 18 7 2 36
3 18 6 2 70
3 18 3 2 38
3 18 2 2 68
3 19 7 2 36
3 19 6 2 68
3 19 3 2 38
3 19 2 2 68
3 20 7 2 36
3 20 6 2 70
3 20 3 2 38
3 20 2 2 68
3 21 7 2 36
3 21 6 2 70
3 21 3 2 38
3 21 2 2 68
3 22 7 4 36
3 22 6 4 70
3 22 3 4 38
3 22 2 4 68
3 23 8 0 52
3 23 7 0 0
3 23 6 0 66
3 23 3 0 34
3 23 2 0 0
3 23 1 0 84
3 24 8 0 36
3 24 7 0 0
3 24 6 0 66
3 24 3 0 34
3 24 2 0 0
3 24 1 0 68
3 25 8 1 44
3 25 7 1 8
3 25 6 0 74
3 25 3 0 42
3 25 2 1 8
3 25 1 1 76
4 8 8 2 48
4 8 7 2 16
4 8 6 2 16
4 8 5 2 16
4 8 4 2 16
4 8 3 2 16
4 8 2 2 16
4 8 1 2 80
4 9 8 2 32
4 9 7 2 0
4 9 6 2 0
4 9 5 2 0
4 9 4 2 0
4 9 3 2 0
4 9 2 2 0
4 9 1 2 64
4 10 8 2 32
4 10 7 2 0
4 10 6 2 0
4 10 5 2 0
4 10 4 2 0
4 10 3 2 0
4 10 2 2 0
4 10 1 2 64
4 11 8 2 32
4 11 7 2 0
4 11 6 2 0
4 11 5 2 0
4 11 4 2 0
4 11 3 2 0
4 11 2 2 0
4 11 1 2 64
4 12 8 2 40
4 12 7 2 0
4 12 6 2 0
4 12 5 2 0
4 12 4 2 0
4 12 3 2 0
4 12 2 2 0
4 12 1 2 72
4 13 7 2 32
4 13 6 2 0
4 13 5 2 0
4 13 4 2 0
4 13 3 2 0
4 13 2 2 64
4 14 7 2 32
4 14 6 2 0
4 14 5 2 0
4 14 4 2 0
4 14 3 2 0
4 14 2 2 64
4 15 7 2 32
4 15 6 2 0
4 15 5 2 0
4 15 4 2 0
4 15 3 2 0
4 15 2 2 64
4 16 7 2 32
4 16 6 2 0
4 16 5 2 0
4 16 4 2 0
4 16 3 2 0
4 16 2 2 64
4 17 7 2 32
4 17 6 2 8
4 17 5 2 8
4 17 4 2 8
4 17 3 2 8
4 17 2 2 64
4 18 7 2 98
4 18 2 2 98
4 19 7 2 32
4 19 6 2 90
4 19 2 2 98
4 20 7 2 98
4 20 2 2 98
4 21 7 2 98
4 21 2 2 98
4 22 7 4 98
4 22 2 4 98
4 23 8 0 48
4 23 7 0 66
4 23 2 0 34
4 23 1 0 80
4 24 8 0 32
4 24 7 0 66
4 24 2 0 34
4 24 1 0 64
4 25 8 1 40
4 25 7 0 74
4 25 2 0 42
4 25 1 1 72
5 8 9 2 52
5 8 8 2 16
5 8 7 2 16
5 8 6 2 16
5 8 5 2 16
5 8 4 2 16
5 8 3 2 16
5 8 2 2 16
5 8 1 2 16
5 8 0 2 92
5 9 9 2 36
5 9 8 2 0
5 9 7 2 0
5 9 6 2 0
5 9 5 2 0
5 9 4 2 0
5 9 3 2 0
5 9 2 2 0
5 9 1 2 64
5 10 9 2 36
5 10 8 2 0
5 10 7 2 0
5 10 6 2 0
5 10 5 2 0
5 10 4 2 0
5 10 3 2 0
5 10 2 2 0
5 10 1 2 64
5 11 9 2 36
5 11 8 2 0
5 11 7 2 0
5 11 6 2 0
5 11 5 2 0
5 11 4 2 0
5 11 3 2 0
5 11 2 2 0
5 11 1 2 64
5 12 9 2 44
5 12 8 2 0
5 12 7 2 0
5 12 6 2 0
5 12 5 2 0
5 12 4 2 0
5 12 3 2 0
5 12 2 2 0
5 12 1 2 64
5 13 8 3 36
5 13 7 2 0
5 13 6 2 0
5 13 5 2 0
5 13 4 2 0
5 13 3 2 0
5 13 2 2 0
5 13 1 3 68
5 14 8 3 36
5 14 7 2 0
5 14 6 2 0
5 14 5 2 0
5 14 4 2 0
5 14 3 2 0
5 14 2 2 0
5 14 1 3 68
5 15 8 3 36
5 15 7 2 0
5 15 6 2 0
5 15 5 2 0
5 15 4 2 0
5 15 3 2 0
5 15 2 2 0
5 15 1 3 68
5 16 8 3 36
5 16 7 2 0
5 16 6 2 0
5 16 5 2 0
5 16 4 2 0
5 16 3 2 0
5 16 2 2 0
5 16 1 3 68
5 17 8 2 36
5 17 7 2 8
5 17 6 2 8
5 17 5 2 8
5 17 4 2 8
5 17 3 2 8
5 17 2 2 8
5 17 1 2 68
5 18 8 2 100
5 18 1 2 100
5 19 8 2 36
5 19 7 2 90
5 19 1 2 100
5 20 8 3 100
5 20 1 3 100
5 21 8 3 100
5 21 1 3 100
5 22 8 4 100
5 22 1 4 100
5 23 9 0 52
5 23 8 0 64
5 23 1 0 32
5 23 0 0 84
5 24 9 0 36
5 24 8 0 64
5 24 1 0 32
5 24 0 0 68
5 25 9 1 44
5 25 8 1 72
5 25 1 1 40
5 25 0 1 76
6 8 9 2 50
6 8 8 2 16
6 8 7 2 16
6 8 6 2 16
6 8 5 2 16
6 8 4 2 16
6 8 3 2 16
6 8 2 2 16
6 8 1 2 16
6 8 0 2 90
6 9 9 2 34
6 9 8 2 0
6 9 7 2 0
6 9 6 2 0
6 9 5 2 0
6 9 4 2 0
6 9 3 2 0
6 9 2 2 0
6 9 1 2 64
6 10 9 2 34
6 10 8 2 0
6 10 7 2 0
6 10 6 2 0
6 10 5 2 0
6 10 4 2 0
6 10 3 2 0
6 10 2 2 0
6 10 1 2 64
6 11 9 2 34
6 11 8 2 0
6 11 7 2 0
6 11 6 2 0
6 11 5 2 0
6 11 4 2 0
6 11 3 2 0
6 11 2 2 0
6 11 1 2 64
6 12 9 2 42
6 12 8 2 0
6 12 7 2 0
6 12 6 2 0
6 12 5 2 0
6 12 4 2 0
6 12 3 2 0
6 12 2 2 0
6 12 1 2 64
6 13 8 3 34
6 13 7 2 0
6 13 6 2 0
6 13 5 2 0
6 13 4 2 0
6 13 3 2 0
6 13 2 2 0
6 13 1 3 66
6 14 8 3 34
6 14 7 2 0
6 14 6 2 0
6 14 5 2 0
6 14 4 2 0
6 14 3 2 0
6 14 2 2 0
6 14 1 3 66
6 15 8 3 34
6 15 7 2 0
6 15 6 2 0
6 15 5 2 0
6 15 4 2 0
6 15 3 2 0
6 15 2 2 0
6 15 1 3 66
6 16 8 3 34
6 16 7 2 0
6 16 6 2 0
6 16 5 2 0
6 16 4 2 0
6 16 3 2 0
6 16 2 2 0
6 16 1 3 66
6 17 8 2 34
6 17 7 2 8
6 17 6 2 8
6 17 5 2 8
6 17 4 2 8
6 17 3 2 8
6 17 2 2 8
6 17 1 2 66
6 18 8 2 98
6 18 1 2 98
6 19 8 2 98
6 19 1 2 98
6 20 8 3 98
6 20 1 3 98
6 21 8 3 98
6 21 1 3 98
6 22 8 4 98
6 22 1 4 98
6 23 9 0 50
6 23 8 0 64
6 23 1 0 32
6 23 0 1 82
6 24 9 0 34
6 24 8 0 64
6 24 1 0 32
6 24 0 0 66
6 25 9 1 42
6 25 8 1 72
6 25 1 1 40
6 25 0 1 74
7 8 8 2 48
7 8 7 2 16
7 8 6 2 16
7 8 5 2 16
7 8 4 2 16
7 8 3 2 16
7 8 2 2 16
7 8 1 2 80
7 9 8 2 32
7 9 7 2 0
7 9 6 2 0
7 9 5 2 0
7 9 4 2 0
7 9 3 2 0
7 9 2 2 0
7 9 1 2 64
7 10 8 2 32
7 10 7 2 0
7 10 6 2 0
7 10 5 2 0
7 10 4 2 0
7 10 3 2 0
7 10 2 2 0
7 10 1 2 64
7 11 8 2 32
7 11 7 2 0
7 11 6 2 0
7 11 5 2 0
7 11 4 2 0
7 11 3 2 0
7 11 2 2 0
7 11 1 2 64
7 12 8 2 40
7 12 7 2 0
7 12 6 2 0
7 12 5 2 0
7 12 4 2 0
7 12 3 2 0
7 12 2 2 0
7 12 1 2 72
7 13 7 2 32
7 13 6 2 0
7 13 5 2 0
7 13 4 2 0
7 13 3 2 0
7 13 2 2 64
7 14 7 2 32
7 14 6 2 0
7 14 5 2 0
7 14 4 2 0
7 14 3 2 0
7 14 2 2 64
7 15 7 2 32
7 15 6 2 0
7 15 5 2 0
7 15 4 2 0
7 15 3 2 0
7 15 2 2 64
7 16 7 2 32
7 16 6 2 0
7 16 5 2 0
7 16 4 2 0
7 16 3 2 0
7 16 2 2 64
7 17 7 2 32
7 17 6 2 8
7 17 5 2 8
7 17 4 2 10
7 17 3 2 8
7 17 2 2 64
7 18 7 2 100
7 18 2 2 100
7 19 7 2 100
7 19 2 2 100
7 20 7 2 100
7 20 2 2 100
7 21 7 2 100
7 21 2 2 100
7 22 7 4 108
7 22 2 4 100
7 23 8 0 112
7 23 2 0 36
7 23 1 0 80
7 24 8 0 32
7 24 7 0 84
7 24 2 0 36
7 24 1 0 64
7 25 8 1 40
7 25 7 0 76
7 25 2 0 44
7 25 1 1 72
8 8 8 2 50
8 8 7 2 16
8 8 6 2 16
8 8 5 2 16
8 8 4 2 16
8 8 3 2 16
8 8 2 2 16
8 8 1 2 82
8 9 8 2 34
8 9 7 2 0
8 9 6 2 0
8 9 5 2 0
8 9 4 2 0
8 9 3 2 0
8 9 2 2 0
8 9 1 2 66
8 10 8 2 34
8 10 7 2 0
8 10 6 2 0
8 10 5 2 0
8 10 4 2 0
8 10 3 2 0
8 10 2 2 0
8 10 1 2 66
8 11 8 2 34
8 11 7 2 0
8 11 6 2 0
8 11 5 2 0
8 11 4 2 0
8 11 3 2 0
8 11 2 2 0
8 11 1 2 66
8 12 8 2 42
8 12 7 2 0
8 12 6 2 0
8 12 5 2 0
8 12 4 2 0
8 12 3 2 0
8 12 2 2 0
8 12 1 2 74
8 13 7 2 34
8 13 6 2 2
8 13 5 2 0
8 13 4 2 0
8 13 3 2 2
8 13 2 2 66
8 14 7 2 34
8 14 6 2 2
8 14 5 2 0
8 14 4 2 0
8 14 3 2 2
8 14 2 2 66
8 15 7 2 34
8 15 6 2 2
8 15 5 2 0
8 15 4 2 0
8 15 3 2 2
8 15 2 2 66
8 16 7 2 34
8 16 6 2 2
8 16 5 2 0
8 16 4 2 8
8 16 3 2 2
8 16 2 2 66
8 17 7 2 34
8 17 6 2 2
8 17 5 2 72
8 17 3 2 34
8 17 2 2 66
8 18 7 2 34
8 18 6 2 70
8 18 3 2 38
8 18 2 2 66
8 19 7 2 34
8 19 6 2 6
8 19 5 2 28
8 19 4 2 28
8 19 3 2 6
8 19 2 2 66
8 20 7 2 34
8 20 6 2 70
8 20 3 2 38
8 20 2 2 66
8 21 7 2 34
8 21 6 2 70
8 21 3 2 38
8 21 2 2 66
8 22 7 4 34
8 22 6 4 70
8 22 3 4 38
8 22 2 4 66
8 23 8 0 50
8 23 7 0 4
8 23 6 0 68
8 23 3 0 36
8 23 2 0 0
8 23 1 0 82
8 24 8 0 34
8 24 7 0 0
8 24 6 0 68
8 24 3 0 36
8 24 2 0 0
8 24 1 0 66
8 25 8 1 42
8 25 7 0 8
8 25 6 0 76
8 25 3 0 44
8 25 2 1 8
8 25 1 1 74
9 8 7 2 50
9 8 6 2 18
9 8 5 2 16
9 8 4 2 16
9 8 3 2 18
9 8 2 2 82
9 9 7 2 34
9 9 6 2 2
9 9 5 2 0
9 9 4 2 0
9 9 3 2 2
9 9 2 2 66
9 10 7 2 34
9 10 6 2 2
9 10 5 2 0
9 10 4 2 0
9 10 3 2 2
9 10 2 2 66
9 11 7 2 34
9 11 6 2 2
9 11 5 2 0
9 11 4 2 0
9 11 3 2 2
9 11 2 2 66
9 12 7 2 42
9 12 6 2 10
9 12 5 2 2
9 12 4 2 2
9 12 3 2 10
9 12 2 2 74
9 13 5 3 34
9 13 4 3 66
9 14 5 3 34
9 14 4 3 66
9 15 5 3 34
9 15 4 3 66
9 16 5 3 34
9 16 4 3 66
9 17 5 2 34
9 17 4 2 70
9 18 5 2 38
9 18 4 2 70
9 19 5 2 34
9 19 4 2 66
9 20 5 3 38
9 20 4 3 70
9 21 5 3 38
9 21 4 3 70
9 22 5 4 38
9 22 4 4 70
9 23 7 0 50
9 23 6 0 18
9 23 5 0 4
9 23 4 0 4
9 23 3 0 18
9 23 2 0 82
9 24 7 0 34
9 24 6 0 2
9 24 5 0 4
9 24 4 0 4
9 24 3 0 2
9 24 2 0 66
9 25 7 1 42
9 25 6 1 10
9 25 5 1 12
9 25 4 1 12
9 25 3 1 10
9 25 2 1 74
10 8 5 2 50
10 8 4 2 82
10 9 5 2 34
10 9 4 2 66
10 10 5 2 34
10 10 4 2 66
10 11 5 2 42
10 11 4 2 74
10 23 5 0 50
10 23 4 0 82
10 24 5 0 34
10 24 4 0 66
10 25 5 1 42
10 25 4 1 74
