Qubicle Exchange Format
Version 0.2
www.minddesk.com
26 11 11
5
0.180392 0.117647 0.047059
0.180392 0.145098 0.098039
0.188235 0.192157 0.196078
0.368627 0.160784 0.121569
0.745098 0.635294 0.003922
8 1 5 2 52
8 1 4 2 84
8 2 7 2 52
8 2 6 2 20
8 2 5 2 4
8 2 4 2 4
8 2 3 2 20
8 2 2 2 84
8 3 8 2 52
8 3 7 2 4
8 3 6 2 4
8 3 5 2 4
8 3 4 2 4
8 3 3 2 4
8 3 2 2 4
8 3 1 2 84
8 4 8 2 36
8 4 7 2 4
8 4 6 2 4
8 4 5 2 4
8 4 4 2 4
8 4 3 2 4
8 4 2 2 4
8 4 1 2 68
8 5 9 2 52
8 5 8 2 4
8 5 7 2 4
8 5 6 2 4
8 5 5 2 4
8 5 4 2 4
8 5 3 2 4
8 5 2 2 4
8 5 1 2 4
8 5 0 2 86
8 6 9 2 44
8 6 8 2 4
8 6 7 2 4
8 6 6 2 4
8 6 5 2 4
8 6 4 2 4
8 6 3 2 4
8 6 2 2 4
8 6 1 2 4
8 6 0 2 78
8 7 8 2 36
8 7 7 2 4
8 7 6 2 4
8 7 5 2 4
8 7 4 2 4
8 7 3 2 4
8 7 2 2 4
8 7 1 2 68
8 8 8 2 44
8 8 7 2 4
8 8 6 2 4
8 8 5 2 4
8 8 4 2 4
8 8 3 2 4
8 8 2 2 4
8 8 1 2 76
8 9 7 2 44
8 9 6 2 12
8 9 5 2 4
8 9 4 2 4
8 9 3 2 12
8 9 2 2 76
8 10 5 2 44
8 10 4 2 76
9 1 5 2 48
9 1 4 2 80
9 2 7 2 48
9 2 6 2 16
9 2 5 2 0
9 2 4 2 0
9 2 3 2 16
9 2 2 2 80
9 3 8 2 48
9 3 7 2 0
9 3 6 2 0
9 3 5 2 0
9 3 4 2 0
9 3 3 2 0
9 3 2 2 0
9 3 1 2 80
9 4 8 2 32
9 4 7 2 0
9 4 6 2 0
9 4 5 2 0
9 4 4 2 0
9 4 3 2 0
9 4 2 2 0
9 4 1 2 64
9 5 9 2 48
9 5 8 2 0
9 5 7 2 0
9 5 6 2 0
9 5 5 2 0
9 5 4 2 0
9 5 3 2 0
9 5 2 2 0
9 5 1 2 64
9 6 9 2 40
9 6 8 2 0
9 6 7 2 0
9 6 6 2 0
9 6 5 2 0
9 6 4 2 0
9 6 3 2 0
9 6 2 2 0
9 6 1 2 64
9 7 8 2 32
9 7 7 2 0
9 7 6 2 0
9 7 5 2 0
9 7 4 2 0
9 7 3 2 0
9 7 2 2 0
9 7 1 2 64
9 8 8 2 40
9 8 7 2 0
9 8 6 2 0
9 8 5 2 0
9 8 4 2 0
9 8 3 2 0
9 8 2 2 0
9 8 1 2 72
9 9 7 2 40
9 9 6 2 8
9 9 5 2 0
9 9 4 2 0
9 9 3 2 8
9 9 2 2 72
9 10 5 2 40
9 10 4 2 72
10 1 5 2 48
10 1 4 2 80
10 2 7 2 48
10 2 6 2 16
10 2 5 2 0
10 2 4 2 0
10 2 3 2 16
10 2 2 2 80
10 3 8 2 48
10 3 7 2 0
10 3 6 2 0
10 3 5 2 0
10 3 4 2 0
10 3 3 2 0
10 3 2 2 0
10 3 1 2 80
10 4 8 2 32
10 4 7 2 0
10 4 6 2 0
10 4 5 2 0
10 4 4 2 0
10 4 3 2 0
10 4 2 2 0
10 4 1 2 64
10 5 9 2 48
10 5 8 2 0
10 5 7 2 0
10 5 6 2 0
10 5 5 2 0
10 5 4 2 0
10 5 3 2 0
10 5 2 2 0
10 5 1 2 64
10 6 9 2 40
10 6 8 2 0
10 6 7 2 0
10 6 6 2 0
10 6 5 2 0
10 6 4 2 0
10 6 3 2 0
10 6 2 2 0
10 6 1 2 64
10 7 8 2 32
10 7 7 2 0
10 7 6 2 0
10 7 5 2 0
10 7 4 2 0
10 7 3 2 0
10 7 2 2 0
10 7 1 2 64
10 8 8 2 40
10 8 7 2 0
10 8 6 2 0
10 8 5 2 0
10 8 4 2 0
10 8 3 2 0
10 8 2 2 0
10 8 1 2 72
10 9 7 2 40
10 9 6 2 8
10 9 5 2 0
10 9 4 2 0
10 9 3 2 8
10 9 2 2 72
10 10 5 2 40
10 10 4 2 72
11 1 5 2 50
11 1 4 2 82
11 2 7 2 48
11 2 6 2 16
11 2 5 2 0
11 2 4 2 0
11 2 3 2 16
11 2 2 2 80
11 3 8 2 48
11 3 7 2 0
11 3 6 2 0
11 3 5 2 0
11 3 4 2 0
11 3 3 2 0
11 3 2 2 0
11 3 1 2 80
11 4 8 2 32
11 4 7 2 0
11 4 6 2 0
11 4 5 2 0
11 4 4 2 0
11 4 3 2 0
11 4 2 2 0
11 4 1 2 64
11 5 9 2 48
11 5 8 2 0
11 5 7 2 0
11 5 6 2 0
11 5 5 2 0
11 5 4 2 0
11 5 3 2 0
11 5 2 2 0
11 5 1 2 64
11 6 9 2 40
11 6 8 2 0
11 6 7 2 0
11 6 6 2 0
11 6 5 2 0
11 6 4 2 0
11 6 3 2 0
11 6 2 2 0
11 6 1 2 64
11 7 8 2 32
11 7 7 2 0
11 7 6 2 0
11 7 5 2 0
11 7 4 2 0
11 7 3 2 0
11 7 2 2 0
11 7 1 2 64
11 8 8 2 40
11 8 7 2 0
11 8 6 2 0
11 8 5 2 0
11 8 4 2 0
11 8 3 2 0
11 8 2 2 0
11 8 1 2 72
11 9 7 2 40
11 9 6 2 8
11 9 5 2 0
11 9 4 2 0
11 9 3 2 8
11 9 2 2 72
11 10 5 2 42
11 10 4 2 74
12 2 7 2 50
12 2 6 2 18
12 2 5 2 16
12 2 4 2 16
12 2 3 2 18
12 2 2 2 82
12 3 8 2 50
12 3 7 2 0
12 3 6 2 0
12 3 5 2 0
12 3 4 2 0
12 3 3 2 0
12 3 2 2 0
12 3 1 2 82
12 4 8 2 34
12 4 7 2 0
12 4 6 2 0
12 4 5 2 0
12 4 4 2 0
12 4 3 2 0
12 4 2 2 0
12 4 1 2 66
12 5 9 2 50
12 5 8 2 0
12 5 7 2 0
12 5 6 2 0
12 5 5 2 0
12 5 4 2 0
12 5 3 2 0
12 5 2 2 0
12 5 1 2 64
12 6 9 2 42
12 6 8 2 0
12 6 7 2 0
12 6 6 2 0
12 6 5 2 0
12 6 4 2 0
12 6 3 2 0
12 6 2 2 0
12 6 1 2 64
12 7 8 2 34
12 7 7 2 0
12 7 6 2 0
12 7 5 2 0
12 7 4 2 0
12 7 3 2 0
12 7 2 2 0
12 7 1 2 66
12 8 8 2 42
12 8 7 2 0
12 8 6 2 0
12 8 5 2 0
12 8 4 2 0
12 8 3 2 0
12 8 2 2 0
12 8 1 2 74
12 9 7 2 42
12 9 6 2 10
12 9 5 2 8
12 9 4 2 8
12 9 3 2 10
12 9 2 2 74
13 2 5 3 48
13 2 4 3 80
13 3 7 2 48
13 3 6 2 16
13 3 5 2 0
13 3 4 2 0
13 3 3 2 16
13 3 2 2 80
13 4 7 2 32
13 4 6 2 0
13 4 5 2 0
13 4 4 2 0
13 4 3 2 0
13 4 2 2 64
13 5 8 3 48
13 5 7 2 0
13 5 6 2 0
13 5 5 2 0
13 5 4 2 0
13 5 3 2 0
13 5 2 2 0
13 5 1 3 80
13 6 8 3 40
13 6 7 2 0
13 6 6 2 0
13 6 5 2 0
13 6 4 2 0
13 6 3 2 0
13 6 2 2 0
13 6 1 3 72
13 7 7 2 32
13 7 6 2 0
13 7 5 2 0
13 7 4 2 0
13 7 3 2 0
13 7 2 2 64
13 8 7 2 40
13 8 6 2 8
13 8 5 2 0
13 8 4 2 0
13 8 3 2 8
13 8 2 2 72
13 9 5 3 40
13 9 4 3 72
14 2 5 3 48
14 2 4 3 80
14 3 7 2 48
14 3 6 2 16
14 3 5 2 0
14 3 4 2 0
14 3 3 2 16
14 3 2 2 80
14 4 7 2 32
14 4 6 2 0
14 4 5 2 0
14 4 4 2 0
14 4 3 2 0
14 4 2 2 64
14 5 8 3 48
14 5 7 2 0
14 5 6 2 0
14 5 5 2 0
14 5 4 2 0
14 5 3 2 0
14 5 2 2 0
14 5 1 3 80
14 6 8 3 40
14 6 7 2 0
14 6 6 2 0
14 6 5 2 0
14 6 4 2 0
14 6 3 2 0
14 6 2 2 0
14 6 1 3 72
14 7 7 2 32
14 7 6 2 0
14 7 5 2 0
14 7 4 2 0
14 7 3 2 0
14 7 2 2 64
14 8 7 2 40
14 8 6 2 8
14 8 5 2 0
14 8 4 2 0
14 8 3 2 8
14 8 2 2 72
14 9 5 3 40
14 9 4 3 72
15 2 5 3 48
15 2 4 3 80
15 3 7 2 48
15 3 6 2 16
15 3 5 2 0
15 3 4 2 0
15 3 3 2 16
15 3 2 2 80
15 4 7 2 32
15 4 6 2 0
15 4 5 2 0
15 4 4 2 0
15 4 3 2 0
15 4 2 2 64
15 5 8 3 48
15 5 7 2 0
15 5 6 2 0
15 5 5 2 0
15 5 4 2 0
15 5 3 2 0
15 5 2 2 0
15 5 1 3 80
15 6 8 3 40
15 6 7 2 0
15 6 6 2 0
15 6 5 2 0
15 6 4 2 0
15 6 3 2 0
15 6 2 2 0
15 6 1 3 72
15 7 7 2 32
15 7 6 2 0
15 7 5 2 0
15 7 4 2 0
15 7 3 2 0
15 7 2 2 64
15 8 7 2 40
15 8 6 2 8
15 8 5 2 0
15 8 4 2 0
15 8 3 2 8
15 8 2 2 72
15 9 5 3 40
15 9 4 3 72
16 2 5 3 48
16 2 4 3 80
16 3 7 2 48
16 3 6 2 16
16 3 5 2 0
16 3 4 2 2
16 3 3 2 16
16 3 2 2 80
16 4 7 2 32
16 4 6 2 0
16 4 5 2 0
16 4 4 2 0
16 4 3 2 0
16 4 2 2 64
16 5 8 3 48
16 5 7 2 0
16 5 6 2 0
16 5 5 2 0
16 5 4 2 0
16 5 3 2 0
16 5 2 2 0
16 5 1 3 80
16 6 8 3 40
16 6 7 2 0
16 6 6 2 0
16 6 5 2 0
16 6 4 2 0
16 6 3 2 0
16 6 2 2 0
16 6 1 3 72
16 7 7 2 32
16 7 6 2 0
16 7 5 2 0
16 7 4 2 0
16 7 3 2 0
16 7 2 2 64
16 8 7 2 40
16 8 6 2 8
16 8 5 2 0
16 8 4 2 0
16 8 3 2 8
16 8 2 2 72
16 9 5 3 40
16 9 4 3 72
17 2 5 2 48
17 2 4 2 88
17 3 7 2 48
17 3 6 2 16
17 3 5 2 66
17 3 3 2 48
17 3 2 2 80
17 4 7 2 32
17 4 6 2 2
17 4 5 2 2
17 4 4 2 18
17 4 3 2 2
17 4 2 2 64
17 5 8 2 48
17 5 7 2 2
17 5 6 2 2
17 5 5 2 2
17 5 4 2 2
17 5 3 2 2
17 5 2 2 2
17 5 1 2 80
17 6 8 2 40
17 6 7 2 2
17 6 6 2 2
17 6 5 2 2
17 6 4 2 2
17 6 3 2 2
17 6 2 2 2
17 6 1 2 72
17 7 7 2 32
17 7 6 2 2
17 7 5 2 2
17 7 4 2 2
17 7 3 2 2
17 7 2 2 64
17 8 7 2 40
17 8 6 2 8
17 8 5 2 2
17 8 4 2 2
17 8 3 2 8
17 8 2 2 72
17 9 5 2 40
17 9 4 2 72
18 2 5 2 56
18 2 4 2 88
18 3 7 2 48
18 3 6 2 88
18 3 3 2 56
18 3 2 2 80
18 4 7 2 104
18 4 2 2 104
18 5 8 2 112
18 5 1 2 112
18 6 8 2 104
18 6 1 2 104
18 7 7 2 112
18 7 2 2 112
18 8 7 2 40
18 8 6 2 88
18 8 3 2 56
18 8 2 2 72
18 9 5 2 56
18 9 4 2 88
19 2 5 2 48
19 2 4 2 80
19 3 7 2 48
19 3 6 2 24
19 3 5 2 14
19 3 4 2 14
19 3 3 2 24
19 3 2 2 80
19 4 7 2 104
19 4 2 2 104
19 5 8 2 112
19 5 1 2 112
19 6 8 2 40
19 6 7 2 86
19 6 1 2 104
19 7 7 2 32
19 7 6 2 86
19 7 2 2 112
19 8 7 2 40
19 8 6 2 72
19 8 3 2 56
19 8 2 2 72
19 9 5 2 56
19 9 4 2 88
20 2 5 3 56
20 2 4 3 88
20 3 7 2 48
20 3 6 2 88
20 3 3 2 56
20 3 2 2 80
20 4 7 2 104
20 4 2 2 104
20 5 8 3 112
20 5 1 3 112
20 6 8 3 104
20 6 1 3 104
20 7 7 2 112
20 7 2 2 112
20 8 7 2 40
20 8 6 2 88
20 8 3 2 56
20 8 2 2 72
20 9 5 3 56
20 9 4 3 88
21 2 5 3 56
21 2 4 3 88
21 3 7 2 48
21 3 6 2 88
21 3 3 2 56
21 3 2 2 80
21 4 7 2 104
21 4 2 2 104
21 5 8 3 112
21 5 1 3 112
21 6 8 3 104
21 6 1 3 104
21 7 7 2 112
21 7 2 2 112
21 8 7 2 40
21 8 6 2 88
21 8 3 2 56
21 8 2 2 72
21 9 5 3 56
21 9 4 3 88
22 2 5 4 56
22 2 4 4 88
22 3 7 4 48
22 3 6 4 88
22 3 3 4 56
22 3 2 4 80
22 4 7 4 106
22 4 2 4 104
22 5 8 4 112
22 5 1 4 112
22 6 8 4 104
22 6 1 4 104
22 7 7 4 112
22 7 2 4 112
22 8 7 4 40
22 8 6 4 88
22 8 3 4 56
22 8 2 4 72
22 9 5 4 56
22 9 4 4 88
23 1 5 0 52
23 1 4 0 84
23 2 7 0 52
23 2 6 0 20
23 2 5 0 8
23 2 4 0 8
23 2 3 0 20
23 2 2 0 84
23 3 8 0 52
23 3 7 0 8
23 3 6 0 72
23 3 3 0 40
23 3 2 0 0
23 3 1 0 84
23 4 8 0 100
23 4 2 0 40
23 4 1 0 68
23 5 9 0 52
23 5 8 0 64
23 5 1 0 32
23 5 0 1 84
23 6 9 0 44
23 6 8 0 64
23 6 1 0 32
23 6 0 0 76
23 7 8 0 36
23 7 7 0 80
23 7 2 0 48
23 7 1 0 68
23 8 8 0 44
23 8 7 0 0
23 8 6 0 80
23 8 3 0 48
23 8 2 0 0
23 8 1 0 76
23 9 7 0 44
23 9 6 0 12
23 9 5 0 16
23 9 4 0 16
23 9 3 0 12
23 9 2 0 76
23 10 5 0 44
23 10 4 0 76
24 1 5 0 48
24 1 4 0 80
24 2 7 0 48
24 2 6 0 16
24 2 5 0 8
24 2 4 0 8
24 2 3 0 16
24 2 2 0 80
24 3 8 0 48
24 3 7 0 0
24 3 6 0 72
24 3 3 0 40
24 3 2 0 0
24 3 1 0 80
24 4 8 0 32
24 4 7 0 76
24 4 2 0 40
24 4 1 0 64
24 5 9 0 48
24 5 8 0 64
24 5 1 0 32
24 5 0 0 80
24 6 9 0 40
24 6 8 0 64
24 6 1 0 32
24 6 0 0 72
24 7 8 0 32
24 7 7 0 80
24 7 2 0 48
24 7 1 0 64
24 8 8 0 40
24 8 7 0 0
24 8 6 0 80
24 8 3 0 48
24 8 2 0 0
24 8 1 0 72
24 9 7 0 40
24 9 6 0 8
24 9 5 0 16
24 9 4 0 16
24 9 3 0 8
24 9 2 0 72
24 10 5 0 40
24 10 4 0 72
25 1 5 1 50
25 1 4 1 82
25 2 7 1 50
25 2 6 1 18
25 2 5 1 10
25 2 4 1 10
25 2 3 1 18
25 2 2 1 82
25 3 8 1 50
25 3 7 0 2
25 3 6 0 74
25 3 3 0 42
25 3 2 1 2
25 3 1 1 82
25 4 8 1 34
25 4 7 0 74
25 4 2 0 42
25 4 1 1 66
25 5 9 1 50
25 5 8 1 66
25 5 1 1 34
25 5 0 1 82
25 6 9 1 42
25 6 8 1 66
25 6 1 1 34
25 6 0 1 74
25 7 8 1 34
25 7 7 0 82
25 7 2 0 50
25 7 1 1 66
25 8 8 1 42
25 8 7 1 2
25 8 6 0 82
25 8 3 0 50
25 8 2 1 2
25 8 1 1 74
25 9 7 1 42
25 9 6 1 10
25 9 5 0 18
25 9 4 0 18
25 9 3 1 10
25 9 2 1 74
25 10 5 1 42
25 10 4 1 74
