Qubicle Exchange Format
Version 0.2
www.minddesk.com
21 37 21
12
0.000000 0.000000 0.000000
0.141176 0.211765 0.392157
0.188235 0.192157 0.196078
0.368627 0.160784 0.121569
0.443137 0.388235 0.309804
0.678431 0.474510 0.301961
0.682353 0.466667 0.019608
0.843137 0.623529 0.184314
0.890196 0.890196 0.733333
0.894118 0.200000 0.203922
0.960784 0.533333 0.086275
0.988235 0.784314 0.031373
4 25 11 5 116
4 26 11 5 44
4 26 10 5 92
5 23 8 7 52
5 23 7 7 84
5 24 8 7 36
5 24 7 7 68
5 25 11 5 48
5 25 10 5 84
5 25 8 7 36
5 25 7 7 68
5 26 11 5 40
5 26 10 5 72
5 26 8 7 36
5 26 7 7 68
5 27 8 7 36
5 27 7 7 68
5 28 11 7 52
5 28 10 7 20
5 28 9 7 20
5 28 8 7 4
5 28 7 7 4
5 28 6 7 20
5 28 5 7 84
5 29 11 7 44
5 29 10 7 12
5 29 9 7 12
5 29 8 7 12
5 29 7 7 12
5 29 6 7 12
5 29 5 7 76
6 9 12 3 52
6 9 11 3 20
6 9 10 3 20
6 9 9 3 20
6 9 8 3 20
6 9 7 3 20
6 9 6 3 20
6 9 5 3 84
6 10 12 3 36
6 10 11 3 4
6 10 10 3 4
6 10 9 3 4
6 10 8 3 4
6 10 7 3 4
6 10 6 3 12
6 10 5 3 76
6 11 12 4 36
6 11 11 4 4
6 11 10 4 4
6 11 9 4 4
6 11 8 4 4
6 11 7 4 68
6 12 12 4 36
6 12 11 4 4
6 12 10 4 4
6 12 9 4 4
6 12 8 4 4
6 12 7 4 68
6 13 12 4 36
6 13 11 4 4
6 13 10 4 4
6 13 9 4 4
6 13 8 4 4
6 13 7 4 68
6 14 12 4 44
6 14 11 4 12
6 14 10 4 12
6 14 9 4 12
6 14 8 4 12
6 14 7 4 76
6 18 17 7 52
6 18 16 7 84
6 18 13 4 52
6 18 12 4 20
6 18 11 4 20
6 18 10 4 20
6 18 9 4 20
6 18 8 4 20
6 18 7 4 84
6 19 17 7 36
6 19 16 7 68
6 19 13 4 36
6 19 12 4 6
6 19 11 4 6
6 19 10 4 6
6 19 9 4 14
6 19 8 4 14
6 19 7 4 78
6 20 17 7 44
6 20 16 7 4
6 20 15 7 84
6 20 13 4 44
6 20 12 4 14
6 20 11 4 14
6 20 10 4 78
6 21 16 7 36
6 21 15 7 68
6 22 16 7 44
6 22 15 7 4
6 22 14 7 84
6 22 8 7 52
6 22 7 7 20
6 22 6 7 84
6 23 15 7 36
6 23 14 7 68
6 23 12 5 52
6 23 11 5 20
6 23 10 5 20
6 23 9 5 20
6 23 8 7 0
6 23 7 7 0
6 23 6 5 4
6 23 5 5 84
6 24 15 7 44
6 24 14 7 68
6 24 12 5 36
6 24 11 5 4
6 24 10 5 4
6 24 9 5 4
6 24 8 7 0
6 24 7 7 0
6 24 6 5 4
6 24 5 5 68
6 25 14 7 44
6 25 13 7 20
6 25 12 5 4
6 25 11 5 0
6 25 10 5 0
6 25 9 5 4
6 25 8 7 0
6 25 7 7 0
6 25 6 5 4
6 25 5 5 68
6 26 13 7 36
6 26 12 7 4
6 26 11 5 0
6 26 10 5 0
6 26 9 5 4
6 26 8 7 0
6 26 7 7 0
6 26 6 7 4
6 26 5 5 68
6 27 13 7 36
6 27 12 7 4
6 27 11 7 4
6 27 10 7 4
6 27 9 7 4
6 27 8 7 0
6 27 7 7 0
6 27 6 7 4
6 27 5 7 68
6 28 13 7 36
6 28 12 7 4
6 28 11 7 0
6 28 10 7 0
6 28 9 7 0
6 28 8 7 0
6 28 7 7 0
6 28 6 7 0
6 28 5 7 64
6 29 13 7 36
6 29 12 7 4
6 29 11 7 0
6 29 10 7 0
6 29 9 7 0
6 29 8 7 0
6 29 7 7 0
6 29 6 7 0
6 29 5 7 8
6 29 4 7 92
6 30 13 7 44
6 30 12 7 12
6 30 11 7 12
6 30 10 7 12
6 30 9 7 12
6 30 8 7 12
6 30 7 7 12
6 30 6 7 76
7 8 11 3 52
7 8 10 3 20
7 8 9 3 20
7 8 8 3 20
7 8 7 3 20
7 8 6 3 20
7 8 5 3 84
7 9 12 3 48
7 9 11 1 0
7 9 10 1 0
7 9 9 1 0
7 9 8 1 0
7 9 7 3 0
7 9 6 3 0
7 9 5 3 0
7 9 4 3 84
7 10 12 3 32
7 10 11 1 0
7 10 10 1 0
7 10 9 1 0
7 10 8 1 0
7 10 7 1 0
7 10 6 1 0
7 10 5 0 0
7 10 4 3 76
7 11 13 4 52
7 11 12 6 0
7 11 11 6 0
7 11 10 6 0
7 11 9 6 0
7 11 8 6 0
7 11 7 1 0
7 11 6 6 4
7 11 5 6 68
7 12 13 4 36
7 12 12 6 0
7 12 11 6 0
7 12 10 6 0
7 12 9 6 0
7 12 8 6 0
7 12 7 1 0
7 12 6 4 4
7 12 5 4 68
7 13 13 4 36
7 13 12 6 0
7 13 11 6 0
7 13 10 6 0
7 13 9 4 0
7 13 8 4 0
7 13 7 4 0
7 13 6 4 4
7 13 5 4 70
7 14 13 4 44
7 14 12 6 0
7 14 11 6 0
7 14 10 6 0
7 14 9 6 0
7 14 8 6 0
7 14 7 6 0
7 14 6 4 4
7 14 5 4 76
7 15 12 4 36
7 15 11 4 4
7 15 10 4 4
7 15 9 4 4
7 15 8 4 4
7 15 7 4 4
7 15 6 4 68
7 16 12 4 36
7 16 11 4 4
7 16 10 4 4
7 16 9 4 4
7 16 8 4 4
7 16 7 4 4
7 16 6 4 68
7 17 13 4 52
7 17 12 4 4
7 17 11 4 4
7 17 10 4 4
7 17 9 4 4
7 17 8 4 4
7 17 7 4 4
7 17 6 4 68
7 18 17 7 48
7 18 16 7 80
7 18 13 4 32
7 18 12 2 8
7 18 11 2 8
7 18 10 2 8
7 18 9 2 8
7 18 8 2 8
7 18 7 2 8
7 18 6 2 78
7 19 17 7 32
7 19 16 7 64
7 19 13 4 96
7 20 17 7 40
7 20 16 7 0
7 20 15 7 80
7 20 13 4 104
7 21 16 7 32
7 21 15 7 64
7 21 7 7 52
7 21 6 7 84
7 22 16 7 40
7 22 15 7 0
7 22 14 7 80
7 22 12 5 52
7 22 11 5 20
7 22 10 5 20
7 22 9 5 20
7 22 8 7 16
7 22 7 7 0
7 22 6 7 0
7 22 5 5 84
7 23 15 7 32
7 23 14 7 64
7 23 12 5 32
7 23 11 5 0
7 23 10 5 0
7 23 9 5 0
7 23 8 5 0
7 23 7 5 0
7 23 6 5 0
7 23 5 5 64
7 24 15 7 40
7 24 14 7 64
7 24 12 5 32
7 24 11 5 0
7 24 10 5 0
7 24 9 5 0
7 24 8 5 0
7 24 7 5 0
7 24 6 5 0
7 24 5 5 64
7 25 14 7 32
7 25 13 7 16
7 25 12 5 0
7 25 11 5 0
7 25 10 5 0
7 25 9 5 0
7 25 8 5 0
7 25 7 5 0
7 25 6 5 0
7 25 5 5 64
7 26 14 7 36
7 26 13 5 0
7 26 12 5 0
7 26 11 5 0
7 26 10 5 0
7 26 9 5 0
7 26 8 5 0
7 26 7 5 0
7 26 6 5 0
7 26 5 3 64
7 27 14 7 36
7 27 13 7 0
7 27 12 7 0
7 27 11 7 0
7 27 10 7 0
7 27 9 7 0
7 27 8 7 0
7 27 7 5 0
7 27 6 5 0
7 27 5 5 64
7 28 14 7 36
7 28 13 7 0
7 28 12 7 0
7 28 11 7 0
7 28 10 7 0
7 28 9 7 0
7 28 8 7 0
7 28 7 5 0
7 28 6 5 0
7 28 5 5 64
7 29 14 7 36
7 29 13 7 0
7 29 12 7 0
7 29 11 7 0
7 29 10 7 0
7 29 9 7 0
7 29 8 7 0
7 29 7 7 0
7 29 6 7 0
7 29 5 7 0
7 29 4 7 88
7 30 14 7 44
7 30 13 7 0
7 30 12 7 0
7 30 11 7 0
7 30 10 7 0
7 30 9 7 0
7 30 8 7 0
7 30 7 7 0
7 30 6 7 0
7 30 5 7 76
7 31 13 7 44
7 31 12 7 12
7 31 11 7 12
7 31 10 7 12
7 31 9 7 12
7 31 8 7 12
7 31 7 7 12
7 31 6 7 76
8 8 11 3 48
8 8 10 3 16
8 8 9 3 16
8 8 8 3 16
8 8 7 3 16
8 8 6 3 16
8 8 5 3 80
8 9 12 3 48
8 9 11 1 0
8 9 10 1 0
8 9 9 1 0
8 9 8 1 0
8 9 7 1 0
8 9 6 1 0
8 9 5 3 0
8 9 4 3 80
8 10 14 4 116
8 10 12 3 32
8 10 11 1 0
8 10 10 1 0
8 10 9 1 0
8 10 8 1 0
8 10 7 1 0
8 10 6 1 0
8 10 5 0 0
8 10 4 3 72
8 11 14 4 36
8 11 13 4 16
8 11 12 6 0
8 11 11 6 0
8 11 10 6 0
8 11 9 6 0
8 11 8 6 0
8 11 7 1 0
8 11 6 1 0
8 11 5 6 64
8 12 14 4 36
8 12 13 4 0
8 12 12 6 0
8 12 11 6 0
8 12 10 6 0
8 12 9 6 0
8 12 8 6 0
8 12 7 1 0
8 12 6 1 0
8 12 5 6 72
8 13 14 4 44
8 13 13 4 0
8 13 12 6 0
8 13 11 6 0
8 13 10 6 0
8 13 9 6 0
8 13 8 6 0
8 13 7 6 0
8 13 6 8 64
8 14 13 4 40
8 14 12 6 0
8 14 11 6 0
8 14 10 6 0
8 14 9 6 0
8 14 8 6 0
8 14 7 6 0
8 14 6 6 0
8 14 5 4 90
8 15 12 4 32
8 15 11 6 0
8 15 10 6 0
8 15 9 6 0
8 15 8 6 0
8 15 7 6 0
8 15 6 4 64
8 16 12 4 32
8 16 11 4 0
8 16 10 6 0
8 16 9 6 0
8 16 8 6 0
8 16 7 4 0
8 16 6 4 64
8 17 13 4 48
8 17 12 4 0
8 17 11 4 2
8 17 10 4 2
8 17 9 4 2
8 17 8 4 2
8 17 7 4 0
8 17 6 2 72
8 18 17 7 48
8 18 16 7 80
8 18 13 4 32
8 18 12 2 8
8 18 11 2 8
8 18 10 2 8
8 18 9 2 8
8 18 8 2 8
8 18 7 2 72
8 19 17 7 32
8 19 16 7 64
8 19 13 4 96
8 20 17 7 40
8 20 16 7 0
8 20 15 7 80
8 20 13 4 104
8 20 5 7 116
8 21 16 7 32
8 21 15 7 64
8 21 8 5 52
8 21 7 7 16
8 21 6 7 16
8 21 5 7 68
8 22 16 7 40
8 22 15 7 0
8 22 14 7 80
8 22 12 5 48
8 22 11 5 16
8 22 10 5 16
8 22 9 5 16
8 22 8 5 0
8 22 7 5 0
8 22 6 5 0
8 22 5 5 64
8 23 15 7 32
8 23 14 7 0
8 23 13 7 20
8 23 12 5 0
8 23 11 5 0
8 23 10 5 0
8 23 9 5 0
8 23 8 5 0
8 23 7 5 0
8 23 6 5 0
8 23 5 5 64
8 24 15 7 40
8 24 14 7 0
8 24 13 7 4
8 24 12 5 0
8 24 11 5 0
8 24 10 5 0
8 24 9 5 0
8 24 8 5 0
8 24 7 5 0
8 24 6 5 0
8 24 5 0 64
8 25 14 7 32
8 25 13 5 0
8 25 12 5 0
8 25 11 5 0
8 25 10 5 0
8 25 9 5 0
8 25 8 5 0
8 25 7 5 0
8 25 6 5 0
8 25 5 5 64
8 26 14 7 32
8 26 13 5 0
8 26 12 5 0
8 26 11 5 0
8 26 10 5 0
8 26 9 5 0
8 26 8 5 0
8 26 7 5 0
8 26 6 5 0
8 26 5 3 64
8 27 14 7 32
8 27 13 7 0
8 27 12 7 0
8 27 11 7 0
8 27 10 7 0
8 27 9 7 0
8 27 8 7 0
8 27 7 5 0
8 27 6 5 0
8 27 5 5 64
8 28 14 7 32
8 28 13 7 0
8 28 12 7 0
8 28 11 7 0
8 28 10 7 0
8 28 9 7 0
8 28 8 7 0
8 28 7 5 0
8 28 6 5 0
8 28 5 5 64
8 29 14 7 32
8 29 13 7 0
8 29 12 7 0
8 29 11 7 0
8 29 10 7 0
8 29 9 7 0
8 29 8 7 0
8 29 7 7 0
8 29 6 7 0
8 29 5 7 0
8 29 4 7 88
8 30 14 7 40
8 30 13 7 0
8 30 12 7 0
8 30 11 7 0
8 30 10 7 0
8 30 9 7 0
8 30 8 7 0
8 30 7 7 0
8 30 6 7 0
8 30 5 7 72
8 31 13 7 40
8 31 12 7 0
8 31 11 7 0
8 31 10 7 0
8 31 9 7 0
8 31 8 7 0
8 31 7 7 8
8 31 6 7 72
8 32 12 7 44
8 32 11 7 12
8 32 10 7 12
8 32 9 7 12
8 32 8 7 76
9 8 11 3 48
9 8 10 3 16
9 8 9 3 16
9 8 8 3 16
9 8 7 3 16
9 8 6 3 16
9 8 5 3 80
9 9 14 4 116
9 9 12 3 48
9 9 11 1 0
9 9 10 1 0
9 9 9 1 0
9 9 8 1 0
9 9 7 1 0
9 9 6 1 0
9 9 5 3 0
9 9 4 3 80
9 10 14 4 96
9 10 12 3 32
9 10 11 1 0
9 10 10 1 0
9 10 9 1 0
9 10 8 1 0
9 10 7 1 0
9 10 6 1 0
9 10 5 0 0
9 10 4 3 72
9 11 14 4 32
9 11 13 4 16
9 11 12 6 0
9 11 11 6 0
9 11 10 6 0
9 11 9 6 0
9 11 8 6 0
9 11 7 6 0
9 11 6 1 0
9 11 5 6 64
9 12 14 4 32
9 12 13 4 0
9 12 12 6 0
9 12 11 6 0
9 12 10 6 0
9 12 9 6 0
9 12 8 6 0
9 12 7 6 0
9 12 6 1 0
9 12 5 6 72
9 13 14 4 40
9 13 13 6 0
9 13 12 6 0
9 13 11 6 0
9 13 10 6 0
9 13 9 6 0
9 13 8 6 0
9 13 7 6 0
9 13 6 8 64
9 14 13 4 40
9 14 12 6 0
9 14 11 6 0
9 14 10 6 0
9 14 9 6 0
9 14 8 6 0
9 14 7 6 0
9 14 6 8 64
9 15 12 4 32
9 15 11 6 0
9 15 10 6 0
9 15 9 6 0
9 15 8 6 0
9 15 7 6 0
9 15 6 8 64
9 16 12 4 32
9 16 11 4 8
9 16 10 6 8
9 16 9 6 8
9 16 8 6 8
9 16 7 4 0
9 16 6 4 0
9 16 5 2 92
9 17 13 2 48
9 17 12 4 64
9 17 7 4 32
9 17 6 2 72
9 18 17 7 48
9 18 16 7 80
9 18 13 4 32
9 18 12 4 8
9 18 11 4 24
9 18 10 4 24
9 18 9 4 24
9 18 8 4 24
9 18 7 8 72
9 19 17 7 32
9 19 16 7 64
9 19 13 4 96
9 20 17 7 40
9 20 16 7 0
9 20 15 7 80
9 20 13 4 104
9 20 5 7 48
9 20 4 7 84
9 21 16 7 32
9 21 15 7 64
9 21 8 5 48
9 21 7 7 16
9 21 6 7 16
9 21 5 7 0
9 21 4 7 70
9 22 16 7 40
9 22 15 7 0
9 22 14 7 80
9 22 12 5 48
9 22 11 5 16
9 22 10 5 16
9 22 9 5 16
9 22 8 5 0
9 22 7 5 0
9 22 6 5 0
9 22 5 5 0
9 22 4 7 76
9 23 15 7 32
9 23 14 7 0
9 23 13 7 16
9 23 12 5 0
9 23 11 5 0
9 23 10 5 0
9 23 9 5 0
9 23 8 5 0
9 23 7 5 0
9 23 6 5 0
9 23 5 5 64
9 24 15 7 40
9 24 14 7 0
9 24 13 5 0
9 24 12 5 0
9 24 11 5 0
9 24 10 5 0
9 24 9 5 0
9 24 8 5 0
9 24 7 5 0
9 24 6 5 0
9 24 5 5 64
9 25 14 7 32
9 25 13 5 0
9 25 12 5 0
9 25 11 5 0
9 25 10 5 0
9 25 9 5 0
9 25 8 5 0
9 25 7 5 0
9 25 6 5 0
9 25 5 5 64
9 26 14 7 32
9 26 13 5 0
9 26 12 5 0
9 26 11 5 0
9 26 10 5 0
9 26 9 5 0
9 26 8 5 0
9 26 7 5 0
9 26 6 5 0
9 26 5 3 64
9 27 14 7 32
9 27 13 7 0
9 27 12 7 0
9 27 11 7 0
9 27 10 7 0
9 27 9 7 0
9 27 8 7 0
9 27 7 7 0
9 27 6 5 0
9 27 5 5 64
9 28 14 7 32
9 28 13 7 0
9 28 12 7 0
9 28 11 7 0
9 28 10 7 0
9 28 9 7 0
9 28 8 7 0
9 28 7 7 0
9 28 6 5 0
9 28 5 7 0
9 28 4 7 86
9 29 14 7 32
9 29 13 7 0
9 29 12 7 0
9 29 11 7 0
9 29 10 7 0
9 29 9 7 0
9 29 8 7 0
9 29 7 7 0
9 29 6 7 0
9 29 5 7 0
9 29 4 7 72
9 30 14 7 40
9 30 13 7 0
9 30 12 7 0
9 30 11 7 0
9 30 10 7 0
9 30 9 7 0
9 30 8 7 0
9 30 7 7 0
9 30 6 7 0
9 30 5 7 72
9 31 13 7 40
9 31 12 7 0
9 31 11 7 0
9 31 10 7 0
9 31 9 7 0
9 31 8 7 0
9 31 7 7 8
9 31 6 7 72
9 32 12 7 40
9 32 11 7 8
9 32 10 7 8
9 32 9 7 8
9 32 8 7 72
10 8 11 3 48
10 8 10 3 16
10 8 9 3 16
10 8 8 3 16
10 8 7 3 16
10 8 6 3 16
10 8 5 3 80
10 9 14 4 112
10 9 12 3 48
10 9 11 1 0
10 9 10 1 0
10 9 9 1 0
10 9 8 1 0
10 9 7 1 0
10 9 6 1 0
10 9 5 3 0
10 9 4 3 80
10 10 14 4 96
10 10 12 3 32
10 10 11 1 0
10 10 10 1 0
10 10 9 1 0
10 10 8 1 0
10 10 7 1 0
10 10 6 1 0
10 10 5 1 0
10 10 4 3 72
10 11 14 4 32
10 11 13 4 16
10 11 12 6 0
10 11 11 6 0
10 11 10 6 0
10 11 9 6 0
10 11 8 6 0
10 11 7 6 0
10 11 6 1 0
10 11 5 6 64
10 12 14 4 32
10 12 13 6 0
10 12 12 6 0
10 12 11 6 0
10 12 10 6 0
10 12 9 6 0
10 12 8 6 0
10 12 7 6 0
10 12 6 1 0
10 12 5 6 72
10 13 14 4 40
10 13 13 6 0
10 13 12 6 0
10 13 11 6 0
10 13 10 6 0
10 13 9 6 0
10 13 8 6 0
10 13 7 6 0
10 13 6 8 64
10 14 13 4 40
10 14 12 6 0
10 14 11 6 0
10 14 10 6 0
10 14 9 6 0
10 14 8 6 0
10 14 7 6 0
10 14 6 8 64
10 15 12 4 32
10 15 11 6 0
10 15 10 6 0
10 15 9 6 0
10 15 8 6 0
10 15 7 6 0
10 15 6 4 0
10 15 5 2 84
10 16 12 2 32
10 16 11 4 8
10 16 10 6 8
10 16 9 6 8
10 16 8 6 8
10 16 7 4 0
10 16 6 8 0
10 16 5 2 74
10 17 13 2 48
10 17 12 4 64
10 17 7 4 32
10 17 6 8 72
10 18 17 7 48
10 18 16 7 80
10 18 13 4 32
10 18 12 4 8
10 18 11 4 24
10 18 10 4 24
10 18 9 4 24
10 18 8 4 24
10 18 7 8 72
10 19 17 7 32
10 19 16 7 64
10 19 13 4 96
10 19 4 7 52
10 19 3 7 92
10 20 17 7 40
10 20 16 7 0
10 20 15 7 80
10 20 13 4 104
10 20 5 7 48
10 20 4 7 72
10 21 16 7 32
10 21 15 7 64
10 21 8 5 48
10 21 7 7 16
10 21 6 7 16
10 21 5 0 64
10 22 16 7 40
10 22 15 7 0
10 22 14 7 80
10 22 12 5 48
10 22 11 5 16
10 22 10 5 16
10 22 9 5 16
10 22 8 5 0
10 22 7 5 0
10 22 6 5 0
10 22 5 5 0
10 22 4 7 80
10 23 15 7 32
10 23 14 7 0
10 23 13 7 16
10 23 12 5 0
10 23 11 5 0
10 23 10 5 0
10 23 9 5 0
10 23 8 5 0
10 23 7 5 0
10 23 6 5 0
10 23 5 5 0
10 23 4 9 68
10 24 15 7 40
10 24 14 7 0
10 24 13 5 0
10 24 12 5 0
10 24 11 5 0
10 24 10 5 0
10 24 9 5 0
10 24 8 5 0
10 24 7 5 0
10 24 6 5 0
10 24 5 5 0
10 24 4 10 76
10 25 14 7 32
10 25 13 5 0
10 25 12 5 0
10 25 11 5 0
10 25 10 5 0
10 25 9 5 0
10 25 8 5 0
10 25 7 5 0
10 25 6 5 0
10 25 5 11 64
10 26 14 7 32
10 26 13 5 0
10 26 12 5 0
10 26 11 5 0
10 26 10 5 0
10 26 9 5 0
10 26 8 5 0
10 26 7 5 0
10 26 6 5 0
10 26 5 5 64
10 27 14 7 32
10 27 13 7 0
10 27 12 7 0
10 27 11 7 0
10 27 10 7 0
10 27 9 7 0
10 27 8 7 0
10 27 7 7 0
10 27 6 5 0
10 27 5 5 64
10 28 14 7 32
10 28 13 7 0
10 28 12 7 0
10 28 11 7 0
10 28 10 7 0
10 28 9 7 0
10 28 8 7 0
10 28 7 7 0
10 28 6 5 0
10 28 5 5 64
10 29 14 7 32
10 29 13 7 0
10 29 12 7 0
10 29 11 7 0
10 29 10 7 0
10 29 9 7 0
10 29 8 7 0
10 29 7 7 0
10 29 6 7 0
10 29 5 7 0
10 29 4 7 90
10 30 14 7 40
10 30 13 7 0
10 30 12 7 0
10 30 11 7 0
10 30 10 7 0
10 30 9 7 0
10 30 8 7 0
10 30 7 7 0
10 30 6 7 0
10 30 5 7 72
10 31 13 7 40
10 31 12 7 0
10 31 11 7 0
10 31 10 7 0
10 31 9 7 0
10 31 8 7 0
10 31 7 7 8
10 31 6 7 74
10 32 12 7 40
10 32 11 7 8
10 32 10 7 8
10 32 9 7 8
10 32 8 7 72
11 8 11 3 48
11 8 10 3 16
11 8 9 3 16
11 8 8 3 16
11 8 7 3 16
11 8 6 3 16
11 8 5 3 80
11 9 14 4 112
11 9 12 3 48
11 9 11 1 0
11 9 10 1 0
11 9 9 1 0
11 9 8 1 0
11 9 7 1 0
11 9 6 1 0
11 9 5 3 0
11 9 4 3 80
11 10 14 4 96
11 10 12 3 32
11 10 11 1 0
11 10 10 1 0
11 10 9 1 0
11 10 8 1 0
11 10 7 1 0
11 10 6 1 0
11 10 5 1 0
11 10 4 3 72
11 11 14 4 32
11 11 13 4 16
11 11 12 6 0
11 11 11 6 0
11 11 10 6 0
11 11 9 6 0
11 11 8 6 0
11 11 7 6 0
11 11 6 1 0
11 11 5 6 64
11 12 14 4 32
11 12 13 6 0
11 12 12 6 0
11 12 11 6 0
11 12 10 6 0
11 12 9 6 0
11 12 8 6 0
11 12 7 6 0
11 12 6 1 0
11 12 5 6 72
11 13 14 4 40
11 13 13 6 0
11 13 12 6 0
11 13 11 6 0
11 13 10 6 0
11 13 9 6 0
11 13 8 6 0
11 13 7 6 0
11 13 6 8 64
11 14 13 4 40
11 14 12 6 0
11 14 11 6 0
11 14 10 6 0
11 14 9 6 0
11 14 8 6 0
11 14 7 6 0
11 14 6 6 0
11 14 5 2 84
11 15 12 4 32
11 15 11 6 0
11 15 10 6 0
11 15 9 6 0
11 15 8 6 0
11 15 7 6 0
11 15 6 4 0
11 15 5 2 74
11 16 12 2 32
11 16 11 6 8
11 16 10 6 8
11 16 9 6 8
11 16 8 6 8
11 16 7 4 0
11 16 6 8 64
11 17 13 4 48
11 17 12 4 64
11 17 7 4 32
11 17 6 8 72
11 18 17 7 48
11 18 16 7 80
11 18 13 4 32
11 18 12 4 8
11 18 11 4 24
11 18 10 4 24
11 18 9 4 24
11 18 8 4 24
11 18 7 8 72
11 19 17 7 32
11 19 16 7 64
11 19 13 4 96
11 19 4 7 50
11 19 3 7 90
11 20 17 7 40
11 20 16 7 0
11 20 15 7 80
11 20 13 4 104
11 20 5 7 48
11 20 4 7 72
11 21 16 7 32
11 21 15 7 64
11 21 8 5 50
11 21 7 7 16
11 21 6 7 16
11 21 5 0 64
11 22 16 7 40
11 22 15 7 0
11 22 14 7 80
11 22 12 5 48
11 22 11 5 16
11 22 10 5 16
11 22 9 5 16
11 22 8 5 0
11 22 7 5 0
11 22 6 5 0
11 22 5 5 0
11 22 4 7 80
11 23 15 7 32
11 23 14 7 0
11 23 13 7 16
11 23 12 5 0
11 23 11 5 0
11 23 10 5 0
11 23 9 5 0
11 23 8 5 0
11 23 7 5 0
11 23 6 5 0
11 23 5 5 0
11 23 4 9 66
11 24 15 7 40
11 24 14 7 0
11 24 13 5 0
11 24 12 5 0
11 24 11 5 0
11 24 10 5 0
11 24 9 5 0
11 24 8 5 0
11 24 7 5 0
11 24 6 5 0
11 24 5 5 0
11 24 4 10 74
11 25 14 7 32
11 25 13 5 0
11 25 12 5 0
11 25 11 5 0
11 25 10 5 0
11 25 9 5 0
11 25 8 5 0
11 25 7 5 0
11 25 6 5 0
11 25 5 11 64
11 26 14 7 32
11 26 13 5 0
11 26 12 5 0
11 26 11 5 0
11 26 10 5 0
11 26 9 5 0
11 26 8 5 0
11 26 7 5 0
11 26 6 5 0
11 26 5 5 64
11 27 14 7 32
11 27 13 7 0
11 27 12 7 0
11 27 11 7 0
11 27 10 7 0
11 27 9 7 0
11 27 8 7 0
11 27 7 7 0
11 27 6 5 0
11 27 5 5 64
11 28 14 7 32
11 28 13 7 0
11 28 12 7 0
11 28 11 7 0
11 28 10 7 0
11 28 9 7 0
11 28 8 7 0
11 28 7 7 0
11 28 6 5 0
11 28 5 7 0
11 28 4 7 92
11 29 14 7 32
11 29 13 7 0
11 29 12 7 0
11 29 11 7 0
11 29 10 7 0
11 29 9 7 0
11 29 8 7 0
11 29 7 7 0
11 29 6 7 0
11 29 5 7 64
11 30 14 7 40
11 30 13 7 0
11 30 12 7 0
11 30 11 7 0
11 30 10 7 0
11 30 9 7 0
11 30 8 7 0
11 30 7 7 0
11 30 6 7 8
11 30 5 7 72
11 31 13 7 40
11 31 12 7 0
11 31 11 7 0
11 31 10 7 0
11 31 9 7 0
11 31 8 7 0
11 31 7 7 72
11 32 12 7 40
11 32 11 7 8
11 32 10 7 8
11 32 9 7 8
11 32 8 7 72
12 8 11 3 48
12 8 10 3 16
12 8 9 3 16
12 8 8 3 16
12 8 7 3 16
12 8 6 3 16
12 8 5 3 80
12 9 14 4 114
12 9 12 3 48
12 9 11 1 0
12 9 10 1 0
12 9 9 1 0
12 9 8 1 0
12 9 7 1 0
12 9 6 1 0
12 9 5 3 0
12 9 4 3 80
12 10 14 4 96
12 10 12 3 32
12 10 11 1 0
12 10 10 1 0
12 10 9 1 0
12 10 8 1 0
12 10 7 1 0
12 10 6 1 0
12 10 5 0 0
12 10 4 3 72
12 11 14 4 32
12 11 13 4 16
12 11 12 6 0
12 11 11 6 0
12 11 10 6 0
12 11 9 6 0
12 11 8 6 0
12 11 7 6 0
12 11 6 6 0
12 11 5 6 64
12 12 14 4 32
12 12 13 6 0
12 12 12 6 0
12 12 11 6 0
12 12 10 6 0
12 12 9 6 0
12 12 8 6 0
12 12 7 6 0
12 12 6 6 0
12 12 5 6 64
12 13 14 4 40
12 13 13 6 0
12 13 12 6 0
12 13 11 6 0
12 13 10 6 0
12 13 9 6 0
12 13 8 6 0
12 13 7 6 0
12 13 6 6 0
12 13 5 2 68
12 14 13 4 40
12 14 12 6 0
12 14 11 6 0
12 14 10 6 0
12 14 9 6 0
12 14 8 6 0
12 14 7 6 0
12 14 6 6 0
12 14 5 2 72
12 15 12 2 32
12 15 11 6 0
12 15 10 6 0
12 15 9 6 0
12 15 8 6 0
12 15 7 6 0
12 15 6 8 64
12 16 12 2 32
12 16 11 6 8
12 16 10 6 8
12 16 9 6 8
12 16 8 6 8
12 16 7 4 0
12 16 6 8 64
12 17 13 4 48
12 17 12 4 64
12 17 7 4 32
12 17 6 8 72
12 18 17 7 48
12 18 16 7 80
12 18 13 4 32
12 18 12 4 8
12 18 11 4 24
12 18 10 4 24
12 18 9 4 24
12 18 8 4 24
12 18 7 8 72
12 19 17 7 32
12 19 16 7 64
12 19 13 4 96
12 20 17 7 40
12 20 16 7 0
12 20 15 7 80
12 20 13 4 104
12 20 5 7 48
12 20 4 7 82
12 21 16 7 32
12 21 15 7 64
12 21 7 7 48
12 21 6 7 16
12 21 5 7 0
12 21 4 7 70
12 22 16 7 40
12 22 15 7 0
12 22 14 7 80
12 22 12 5 48
12 22 11 5 16
12 22 10 5 16
12 22 9 5 16
12 22 8 5 16
12 22 7 5 0
12 22 6 5 0
12 22 5 5 0
12 22 4 7 74
12 23 15 7 32
12 23 14 7 0
12 23 13 7 16
12 23 12 5 0
12 23 11 5 0
12 23 10 5 0
12 23 9 5 0
12 23 8 5 0
12 23 7 5 0
12 23 6 5 0
12 23 5 5 64
12 24 15 7 40
12 24 14 7 0
12 24 13 5 0
12 24 12 5 0
12 24 11 5 0
12 24 10 5 0
12 24 9 5 0
12 24 8 5 0
12 24 7 5 0
12 24 6 5 0
12 24 5 5 64
12 25 14 7 32
12 25 13 5 0
12 25 12 5 0
12 25 11 5 0
12 25 10 5 0
12 25 9 5 0
12 25 8 5 0
12 25 7 5 0
12 25 6 5 0
12 25 5 5 64
12 26 14 7 32
12 26 13 5 0
12 26 12 5 0
12 26 11 5 0
12 26 10 5 0
12 26 9 5 0
12 26 8 5 0
12 26 7 5 0
12 26 6 5 0
12 26 5 3 64
12 27 14 7 32
12 27 13 7 0
12 27 12 7 0
12 27 11 7 0
12 27 10 7 0
12 27 9 7 0
12 27 8 7 0
12 27 7 7 0
12 27 6 7 0
12 27 5 5 64
12 28 14 7 32
12 28 13 7 0
12 28 12 7 0
12 28 11 7 0
12 28 10 7 0
12 28 9 7 0
12 28 8 7 0
12 28 7 7 0
12 28 6 7 0
12 28 5 7 0
12 28 4 7 80
12 29 14 7 32
12 29 13 7 0
12 29 12 7 0
12 29 11 7 0
12 29 10 7 0
12 29 9 7 0
12 29 8 7 0
12 29 7 7 0
12 29 6 7 0
12 29 5 7 0
12 29 4 7 76
12 30 14 7 40
12 30 13 7 0
12 30 12 7 0
12 30 11 7 0
12 30 10 7 0
12 30 9 7 0
12 30 8 7 0
12 30 7 7 0
12 30 6 7 0
12 30 5 7 72
12 31 13 7 40
12 31 12 7 0
12 31 11 7 0
12 31 10 7 0
12 31 9 7 0
12 31 8 7 0
12 31 7 7 8
12 31 6 7 76
12 32 12 7 40
12 32 11 7 8
12 32 10 7 8
12 32 9 7 8
12 32 8 7 72
13 8 11 3 48
13 8 10 3 16
13 8 9 3 16
13 8 8 3 16
13 8 7 3 16
13 8 6 3 16
13 8 5 3 80
13 9 12 3 48
13 9 11 1 0
13 9 10 1 0
13 9 9 1 0
13 9 8 1 0
13 9 7 1 0
13 9 6 1 0
13 9 5 3 0
13 9 4 3 80
13 10 14 4 114
13 10 12 3 32
13 10 11 1 0
13 10 10 1 0
13 10 9 1 0
13 10 8 1 0
13 10 7 1 0
13 10 6 1 0
13 10 5 0 0
13 10 4 3 72
13 11 14 4 34
13 11 13 4 16
13 11 12 6 0
13 11 11 6 0
13 11 10 6 0
13 11 9 6 0
13 11 8 6 0
13 11 7 6 0
13 11 6 6 0
13 11 5 6 64
13 12 14 4 34
13 12 13 6 0
13 12 12 6 0
13 12 11 6 0
13 12 10 6 0
13 12 9 6 0
13 12 8 6 0
13 12 7 6 0
13 12 6 6 0
13 12 5 6 64
13 13 14 4 42
13 13 13 6 0
13 13 12 6 0
13 13 11 6 0
13 13 10 6 0
13 13 9 6 0
13 13 8 6 0
13 13 7 6 0
13 13 6 6 0
13 13 5 2 64
13 14 13 2 40
13 14 12 6 0
13 14 11 6 0
13 14 10 6 0
13 14 9 6 0
13 14 8 6 0
13 14 7 6 0
13 14 6 6 0
13 14 5 4 72
13 15 12 2 32
13 15 11 6 0
13 15 10 6 0
13 15 9 6 0
13 15 8 6 0
13 15 7 6 0
13 15 6 4 64
13 16 12 4 32
13 16 11 6 0
13 16 10 6 0
13 16 9 6 0
13 16 8 6 0
13 16 7 4 0
13 16 6 4 64
13 17 13 4 48
13 17 12 4 0
13 17 11 4 4
13 17 10 4 4
13 17 9 4 4
13 17 8 4 4
13 17 7 4 0
13 17 6 4 72
13 18 17 7 48
13 18 16 7 80
13 18 13 4 32
13 18 12 4 8
13 18 11 4 8
13 18 10 4 8
13 18 9 4 8
13 18 8 4 8
13 18 7 8 72
13 19 17 7 32
13 19 16 7 64
13 19 13 4 96
13 20 17 7 40
13 20 16 7 0
13 20 15 7 80
13 20 13 4 104
13 20 5 7 114
13 21 16 7 32
13 21 15 7 64
13 21 8 5 54
13 21 7 7 16
13 21 6 7 16
13 21 5 7 66
13 22 16 7 40
13 22 15 7 0
13 22 14 7 80
13 22 12 5 48
13 22 11 5 16
13 22 10 5 16
13 22 9 5 16
13 22 8 5 0
13 22 7 5 0
13 22 6 5 0
13 22 5 5 64
13 23 15 7 32
13 23 14 7 0
13 23 13 7 18
13 23 12 5 0
13 23 11 5 0
13 23 10 5 0
13 23 9 5 0
13 23 8 5 0
13 23 7 5 0
13 23 6 5 0
13 23 5 5 64
13 24 15 7 40
13 24 14 7 0
13 24 13 7 2
13 24 12 5 0
13 24 11 5 0
13 24 10 5 0
13 24 9 5 0
13 24 8 5 0
13 24 7 5 0
13 24 6 5 0
13 24 5 0 64
13 25 14 7 32
13 25 13 7 2
13 25 12 5 0
13 25 11 5 0
13 25 10 5 0
13 25 9 5 0
13 25 8 5 0
13 25 7 5 0
13 25 6 5 0
13 25 5 5 64
13 26 14 7 32
13 26 13 5 0
13 26 12 5 0
13 26 11 5 0
13 26 10 5 0
13 26 9 5 0
13 26 8 5 0
13 26 7 5 0
13 26 6 5 0
13 26 5 3 64
13 27 14 7 32
13 27 13 7 0
13 27 12 7 0
13 27 11 7 0
13 27 10 7 0
13 27 9 7 0
13 27 8 7 0
13 27 7 7 0
13 27 6 7 0
13 27 5 7 64
13 28 14 7 32
13 28 13 7 0
13 28 12 7 0
13 28 11 7 0
13 28 10 7 0
13 28 9 7 0
13 28 8 7 0
13 28 7 7 0
13 28 6 7 0
13 28 5 7 0
13 28 4 7 80
13 29 14 7 32
13 29 13 7 0
13 29 12 7 0
13 29 11 7 0
13 29 10 7 0
13 29 9 7 0
13 29 8 7 0
13 29 7 7 0
13 29 6 7 0
13 29 5 7 0
13 29 4 7 72
13 30 14 7 40
13 30 13 7 0
13 30 12 7 0
13 30 11 7 0
13 30 10 7 0
13 30 9 7 0
13 30 8 7 0
13 30 7 7 0
13 30 6 7 0
13 30 5 7 72
13 31 13 7 40
13 31 12 7 0
13 31 11 7 0
13 31 10 7 0
13 31 9 7 0
13 31 8 7 0
13 31 7 7 8
13 31 6 7 72
13 32 12 7 42
13 32 11 7 10
13 32 10 7 10
13 32 9 7 10
13 32 8 7 74
14 8 11 3 50
14 8 10 3 18
14 8 9 3 18
14 8 8 3 18
14 8 7 3 18
14 8 6 3 18
14 8 5 3 82
14 9 12 3 48
14 9 11 1 0
14 9 10 1 0
14 9 9 1 0
14 9 8 1 0
14 9 7 1 0
14 9 6 1 0
14 9 5 3 0
14 9 4 3 82
14 10 12 3 32
14 10 11 1 0
14 10 10 1 0
14 10 9 1 0
14 10 8 1 0
14 10 7 1 0
14 10 6 1 0
14 10 5 6 0
14 10 4 3 74
14 11 13 4 50
14 11 12 6 0
14 11 11 6 0
14 11 10 6 0
14 11 9 6 0
14 11 8 6 0
14 11 7 6 0
14 11 6 2 2
14 11 5 6 66
14 12 13 4 34
14 12 12 6 0
14 12 11 6 0
14 12 10 6 0
14 12 9 6 0
14 12 8 6 0
14 12 7 6 0
14 12 6 2 2
14 12 5 2 66
14 13 13 2 34
14 13 12 6 0
14 13 11 6 0
14 13 10 6 0
14 13 9 6 0
14 13 8 4 0
14 13 7 4 0
14 13 6 4 2
14 13 5 2 66
14 14 13 2 42
14 14 12 6 0
14 14 11 6 0
14 14 10 6 0
14 14 9 6 0
14 14 8 4 0
14 14 7 4 0
14 14 6 4 2
14 14 5 4 74
14 15 12 4 34
14 15 11 4 2
14 15 10 4 2
14 15 9 4 2
14 15 8 4 2
14 15 7 4 2
14 15 6 4 66
14 16 12 4 34
14 16 11 4 2
14 16 10 4 2
14 16 9 4 2
14 16 8 4 2
14 16 7 4 2
14 16 6 4 66
14 17 13 4 50
14 17 12 4 2
14 17 11 4 2
14 17 10 4 2
14 17 9 4 2
14 17 8 4 2
14 17 7 4 2
14 17 6 4 66
14 18 17 7 48
14 18 16 7 80
14 18 13 4 32
14 18 12 4 8
14 18 11 4 8
14 18 10 4 8
14 18 9 4 8
14 18 8 4 8
14 18 7 4 8
14 18 6 4 78
14 19 17 7 32
14 19 16 7 64
14 19 13 4 96
14 20 17 7 40
14 20 16 7 0
14 20 15 7 80
14 20 13 4 104
14 21 16 7 32
14 21 15 7 64
14 21 7 7 50
14 21 6 7 82
14 22 16 7 40
14 22 15 7 0
14 22 14 7 80
14 22 12 5 50
14 22 11 5 18
14 22 10 5 18
14 22 9 5 18
14 22 8 5 18
14 22 7 7 0
14 22 6 7 0
14 22 5 5 82
14 23 15 7 32
14 23 14 7 64
14 23 12 5 34
14 23 11 5 2
14 23 10 5 0
14 23 9 5 0
14 23 8 5 0
14 23 7 5 0
14 23 6 5 0
14 23 5 5 64
14 24 15 7 40
14 24 14 7 64
14 24 12 5 32
14 24 11 5 0
14 24 10 5 0
14 24 9 5 0
14 24 8 5 0
14 24 7 5 0
14 24 6 5 0
14 24 5 5 64
14 25 14 7 96
14 25 12 5 32
14 25 11 5 0
14 25 10 5 0
14 25 9 5 0
14 25 8 5 0
14 25 7 5 0
14 25 6 5 0
14 25 5 5 64
14 26 14 7 34
14 26 13 7 16
14 26 12 5 0
14 26 11 5 0
14 26 10 5 0
14 26 9 5 0
14 26 8 5 0
14 26 7 5 0
14 26 6 5 0
14 26 5 7 64
14 27 14 7 34
14 27 13 7 0
14 27 12 7 0
14 27 11 7 0
14 27 10 7 0
14 27 9 7 0
14 27 8 7 0
14 27 7 7 0
14 27 6 7 0
14 27 5 7 0
14 27 4 7 86
14 28 14 7 34
14 28 13 7 0
14 28 12 7 0
14 28 11 7 0
14 28 10 7 0
14 28 9 7 0
14 28 8 7 0
14 28 7 7 0
14 28 6 7 0
14 28 5 7 0
14 28 4 7 66
14 29 14 7 34
14 29 13 7 0
14 29 12 7 0
14 29 11 7 0
14 29 10 7 0
14 29 9 7 0
14 29 8 7 0
14 29 7 7 0
14 29 6 7 0
14 29 5 7 0
14 29 4 7 74
14 30 14 7 42
14 30 13 7 0
14 30 12 7 0
14 30 11 7 0
14 30 10 7 0
14 30 9 7 0
14 30 8 7 0
14 30 7 7 0
14 30 6 7 0
14 30 5 7 72
14 31 13 7 42
14 31 12 7 10
14 31 11 7 10
14 31 10 7 10
14 31 9 7 10
14 31 8 7 10
14 31 7 7 10
14 31 6 7 74
15 9 12 3 50
15 9 11 3 18
15 9 10 3 18
15 9 9 3 18
15 9 8 3 18
15 9 7 3 18
15 9 6 3 18
15 9 5 3 82
15 10 12 3 34
15 10 11 2 2
15 10 10 2 2
15 10 9 2 2
15 10 8 2 2
15 10 7 2 2
15 10 6 2 10
15 10 5 3 74
15 11 12 4 34
15 11 11 2 2
15 11 10 2 2
15 11 9 2 2
15 11 8 2 2
15 11 7 2 66
15 12 12 2 34
15 12 11 2 2
15 12 10 4 2
15 12 9 4 2
15 12 8 4 2
15 12 7 4 66
15 13 12 2 34
15 13 11 4 2
15 13 10 4 2
15 13 9 4 2
15 13 8 4 2
15 13 7 4 66
15 14 12 4 42
15 14 11 4 10
15 14 10 4 10
15 14 9 4 10
15 14 8 4 10
15 14 7 4 74
15 18 17 7 50
15 18 16 7 82
15 18 13 4 50
15 18 12 4 18
15 18 11 4 18
15 18 10 4 18
15 18 9 4 18
15 18 8 4 18
15 18 7 4 82
15 19 17 7 34
15 19 16 7 66
15 19 13 4 34
15 19 12 4 6
15 19 11 4 6
15 19 10 4 6
15 19 9 4 6
15 19 8 4 14
15 19 7 4 78
15 20 17 7 42
15 20 16 7 2
15 20 15 7 82
15 20 13 4 42
15 20 12 4 14
15 20 11 4 14
15 20 10 4 14
15 20 9 4 78
15 21 16 7 34
15 21 15 7 66
15 22 16 7 42
15 22 15 7 2
15 22 14 7 82
15 22 7 7 50
15 22 6 7 82
15 23 15 7 34
15 23 14 7 66
15 23 10 5 50
15 23 9 5 18
15 23 8 5 18
15 23 7 7 0
15 23 6 5 2
15 23 5 5 82
15 24 15 7 42
15 24 14 7 66
15 24 12 5 50
15 24 11 5 18
15 24 10 5 2
15 24 9 5 2
15 24 8 5 0
15 24 7 5 0
15 24 6 5 2
15 24 5 5 66
15 25 14 7 106
15 25 12 5 34
15 25 11 5 0
15 25 10 5 0
15 25 9 5 2
15 25 8 5 0
15 25 7 5 0
15 25 6 5 2
15 25 5 5 66
15 26 13 7 50
15 26 12 5 2
15 26 11 5 0
15 26 10 5 0
15 26 9 5 2
15 26 8 5 0
15 26 7 5 0
15 26 6 5 0
15 26 5 5 66
15 27 13 7 34
15 27 12 7 2
15 27 11 7 0
15 27 10 7 0
15 27 9 7 2
15 27 8 7 0
15 27 7 7 0
15 27 6 7 0
15 27 5 7 64
15 28 13 7 34
15 28 12 7 2
15 28 11 7 2
15 28 10 7 2
15 28 9 7 2
15 28 8 7 0
15 28 7 7 0
15 28 6 7 0
15 28 5 7 64
15 29 13 7 34
15 29 12 7 2
15 29 11 7 2
15 29 10 7 2
15 29 9 7 2
15 29 8 7 2
15 29 7 7 2
15 29 6 7 0
15 29 5 7 64
15 30 13 7 42
15 30 12 7 10
15 30 11 7 10
15 30 10 7 10
15 30 9 7 10
15 30 8 7 10
15 30 7 7 10
15 30 6 7 10
15 30 5 7 74
16 23 7 7 114
16 24 8 7 50
16 24 7 7 66
16 25 11 5 48
16 25 10 5 82
16 25 8 7 34
16 25 7 7 66
16 26 11 5 32
16 26 10 5 64
16 26 8 7 34
16 26 7 7 2
16 26 6 7 82
16 27 11 7 42
16 27 10 7 74
16 27 8 7 34
16 27 7 7 2
16 27 6 7 2
16 27 5 7 82
16 28 8 7 42
16 28 7 7 10
16 28 6 7 2
16 28 5 7 66
16 29 6 7 42
16 29 5 7 74
17 25 11 5 114
17 26 11 5 42
17 26 10 5 90
