Qubicle Exchange Format
Version 0.2
www.minddesk.com
15 26 17
12
0.000000 0.000000 0.000000
0.141176 0.211765 0.392157
0.188235 0.192157 0.196078
0.368627 0.160784 0.121569
0.443137 0.388235 0.309804
0.678431 0.474510 0.301961
0.682353 0.466667 0.019608
0.843137 0.623529 0.184314
0.890196 0.890196 0.733333
0.894118 0.200000 0.203922
0.960784 0.533333 0.086275
0.988235 0.784314 0.031373
1 18 9 5 116
1 19 9 5 44
1 19 8 5 92
2 16 6 7 52
2 16 5 7 84
2 17 6 7 36
2 17 5 7 68
2 18 9 5 48
2 18 8 5 84
2 18 6 7 36
2 18 5 7 68
2 19 9 5 40
2 19 8 5 72
2 19 6 7 36
2 19 5 7 68
2 20 6 7 36
2 20 5 7 68
2 21 9 7 52
2 21 8 7 20
2 21 7 7 20
2 21 6 7 4
2 21 5 7 4
2 21 4 7 20
2 21 3 7 84
2 22 9 7 44
2 22 8 7 12
2 22 7 7 12
2 22 6 7 12
2 22 5 7 12
2 22 4 7 12
2 22 3 7 76
3 2 10 3 52
3 2 9 3 20
3 2 8 3 20
3 2 7 3 20
3 2 6 3 20
3 2 5 3 20
3 2 4 3 20
3 2 3 3 84
3 3 10 3 36
3 3 9 3 4
3 3 8 3 4
3 3 7 3 4
3 3 6 3 4
3 3 5 3 4
3 3 4 3 12
3 3 3 3 76
3 4 10 4 36
3 4 9 4 4
3 4 8 4 4
3 4 7 4 4
3 4 6 4 4
3 4 5 4 68
3 5 10 4 36
3 5 9 4 4
3 5 8 4 4
3 5 7 4 4
3 5 6 4 4
3 5 5 4 68
3 6 10 4 36
3 6 9 4 4
3 6 8 4 4
3 6 7 4 4
3 6 6 4 4
3 6 5 4 68
3 7 10 4 44
3 7 9 4 12
3 7 8 4 12
3 7 7 4 12
3 7 6 4 12
3 7 5 4 76
3 11 15 7 52
3 11 14 7 84
3 11 11 4 52
3 11 10 4 20
3 11 9 4 20
3 11 8 4 20
3 11 7 4 20
3 11 6 4 20
3 11 5 4 84
3 12 15 7 36
3 12 14 7 68
3 12 11 4 36
3 12 10 4 6
3 12 9 4 6
3 12 8 4 6
3 12 7 4 14
3 12 6 4 14
3 12 5 4 78
3 13 15 7 44
3 13 14 7 4
3 13 13 7 84
3 13 11 4 44
3 13 10 4 14
3 13 9 4 14
3 13 8 4 78
3 14 14 7 36
3 14 13 7 68
3 15 14 7 44
3 15 13 7 4
3 15 12 7 84
3 15 6 7 52
3 15 5 7 20
3 15 4 7 84
3 16 13 7 36
3 16 12 7 68
3 16 10 5 52
3 16 9 5 20
3 16 8 5 20
3 16 7 5 20
3 16 6 7 0
3 16 5 7 0
3 16 4 5 4
3 16 3 5 84
3 17 13 7 44
3 17 12 7 68
3 17 10 5 36
3 17 9 5 4
3 17 8 5 4
3 17 7 5 4
3 17 6 7 0
3 17 5 7 0
3 17 4 5 4
3 17 3 5 68
3 18 12 7 44
3 18 11 7 20
3 18 10 5 4
3 18 9 5 0
3 18 8 5 0
3 18 7 5 4
3 18 6 7 0
3 18 5 7 0
3 18 4 5 4
3 18 3 5 68
3 19 11 7 36
3 19 10 7 4
3 19 9 5 0
3 19 8 5 0
3 19 7 5 4
3 19 6 7 0
3 19 5 7 0
3 19 4 7 4
3 19 3 5 68
3 20 11 7 36
3 20 10 7 4
3 20 9 7 4
3 20 8 7 4
3 20 7 7 4
3 20 6 7 0
3 20 5 7 0
3 20 4 7 4
3 20 3 7 68
3 21 11 7 36
3 21 10 7 4
3 21 9 7 0
3 21 8 7 0
3 21 7 7 0
3 21 6 7 0
3 21 5 7 0
3 21 4 7 0
3 21 3 7 64
3 22 11 7 36
3 22 10 7 4
3 22 9 7 0
3 22 8 7 0
3 22 7 7 0
3 22 6 7 0
3 22 5 7 0
3 22 4 7 0
3 22 3 7 8
3 22 2 7 92
3 23 11 7 44
3 23 10 7 12
3 23 9 7 12
3 23 8 7 12
3 23 7 7 12
3 23 6 7 12
3 23 5 7 12
3 23 4 7 76
4 1 9 3 52
4 1 8 3 20
4 1 7 3 20
4 1 6 3 20
4 1 5 3 20
4 1 4 3 20
4 1 3 3 84
4 2 10 3 48
4 2 9 1 0
4 2 8 1 0
4 2 7 1 0
4 2 6 1 0
4 2 5 3 0
4 2 4 3 0
4 2 3 3 0
4 2 2 3 84
4 3 10 3 32
4 3 9 1 0
4 3 8 1 0
4 3 7 1 0
4 3 6 1 0
4 3 5 1 0
4 3 4 1 0
4 3 3 0 0
4 3 2 3 76
4 4 11 4 52
4 4 10 6 0
4 4 9 6 0
4 4 8 6 0
4 4 7 6 0
4 4 6 6 0
4 4 5 1 0
4 4 4 6 4
4 4 3 6 68
4 5 11 4 36
4 5 10 6 0
4 5 9 6 0
4 5 8 6 0
4 5 7 6 0
4 5 6 6 0
4 5 5 1 0
4 5 4 4 4
4 5 3 4 68
4 6 11 4 36
4 6 10 6 0
4 6 9 6 0
4 6 8 6 0
4 6 7 4 0
4 6 6 4 0
4 6 5 4 0
4 6 4 4 4
4 6 3 4 70
4 7 11 4 44
4 7 10 6 0
4 7 9 6 0
4 7 8 6 0
4 7 7 6 0
4 7 6 6 0
4 7 5 6 0
4 7 4 4 4
4 7 3 4 76
4 8 10 4 36
4 8 9 4 4
4 8 8 4 4
4 8 7 4 4
4 8 6 4 4
4 8 5 4 4
4 8 4 4 68
4 9 10 4 36
4 9 9 4 4
4 9 8 4 4
4 9 7 4 4
4 9 6 4 4
4 9 5 4 4
4 9 4 4 68
4 10 11 4 52
4 10 10 4 4
4 10 9 4 4
4 10 8 4 4
4 10 7 4 4
4 10 6 4 4
4 10 5 4 4
4 10 4 4 68
4 11 15 7 48
4 11 14 7 80
4 11 11 4 32
4 11 10 2 8
4 11 9 2 8
4 11 8 2 8
4 11 7 2 8
4 11 6 2 8
4 11 5 2 8
4 11 4 2 78
4 12 15 7 32
4 12 14 7 64
4 12 11 4 96
4 13 15 7 40
4 13 14 7 0
4 13 13 7 80
4 13 11 4 104
4 14 14 7 32
4 14 13 7 64
4 14 5 7 52
4 14 4 7 84
4 15 14 7 40
4 15 13 7 0
4 15 12 7 80
4 15 10 5 52
4 15 9 5 20
4 15 8 5 20
4 15 7 5 20
4 15 6 7 16
4 15 5 7 0
4 15 4 7 0
4 15 3 5 84
4 16 13 7 32
4 16 12 7 64
4 16 10 5 32
4 16 9 5 0
4 16 8 5 0
4 16 7 5 0
4 16 6 5 0
4 16 5 5 0
4 16 4 5 0
4 16 3 5 64
4 17 13 7 40
4 17 12 7 64
4 17 10 5 32
4 17 9 5 0
4 17 8 5 0
4 17 7 5 0
4 17 6 5 0
4 17 5 5 0
4 17 4 5 0
4 17 3 5 64
4 18 12 7 32
4 18 11 7 16
4 18 10 5 0
4 18 9 5 0
4 18 8 5 0
4 18 7 5 0
4 18 6 5 0
4 18 5 5 0
4 18 4 5 0
4 18 3 5 64
4 19 12 7 36
4 19 11 5 0
4 19 10 5 0
4 19 9 5 0
4 19 8 5 0
4 19 7 5 0
4 19 6 5 0
4 19 5 5 0
4 19 4 5 0
4 19 3 3 64
4 20 12 7 36
4 20 11 7 0
4 20 10 7 0
4 20 9 7 0
4 20 8 7 0
4 20 7 7 0
4 20 6 7 0
4 20 5 5 0
4 20 4 5 0
4 20 3 5 64
4 21 12 7 36
4 21 11 7 0
4 21 10 7 0
4 21 9 7 0
4 21 8 7 0
4 21 7 7 0
4 21 6 7 0
4 21 5 5 0
4 21 4 5 0
4 21 3 5 64
4 22 12 7 36
4 22 11 7 0
4 22 10 7 0
4 22 9 7 0
4 22 8 7 0
4 22 7 7 0
4 22 6 7 0
4 22 5 7 0
4 22 4 7 0
4 22 3 7 0
4 22 2 7 88
4 23 12 7 44
4 23 11 7 0
4 23 10 7 0
4 23 9 7 0
4 23 8 7 0
4 23 7 7 0
4 23 6 7 0
4 23 5 7 0
4 23 4 7 0
4 23 3 7 76
4 24 11 7 44
4 24 10 7 12
4 24 9 7 12
4 24 8 7 12
4 24 7 7 12
4 24 6 7 12
4 24 5 7 12
4 24 4 7 76
5 1 9 3 48
5 1 8 3 16
5 1 7 3 16
5 1 6 3 16
5 1 5 3 16
5 1 4 3 16
5 1 3 3 80
5 2 10 3 48
5 2 9 1 0
5 2 8 1 0
5 2 7 1 0
5 2 6 1 0
5 2 5 1 0
5 2 4 1 0
5 2 3 3 0
5 2 2 3 80
5 3 12 4 116
5 3 10 3 32
5 3 9 1 0
5 3 8 1 0
5 3 7 1 0
5 3 6 1 0
5 3 5 1 0
5 3 4 1 0
5 3 3 0 0
5 3 2 3 72
5 4 12 4 36
5 4 11 4 16
5 4 10 6 0
5 4 9 6 0
5 4 8 6 0
5 4 7 6 0
5 4 6 6 0
5 4 5 1 0
5 4 4 1 0
5 4 3 6 64
5 5 12 4 36
5 5 11 4 0
5 5 10 6 0
5 5 9 6 0
5 5 8 6 0
5 5 7 6 0
5 5 6 6 0
5 5 5 1 0
5 5 4 1 0
5 5 3 6 72
5 6 12 4 44
5 6 11 4 0
5 6 10 6 0
5 6 9 6 0
5 6 8 6 0
5 6 7 6 0
5 6 6 6 0
5 6 5 6 0
5 6 4 8 64
5 7 11 4 40
5 7 10 6 0
5 7 9 6 0
5 7 8 6 0
5 7 7 6 0
5 7 6 6 0
5 7 5 6 0
5 7 4 6 0
5 7 3 4 90
5 8 10 4 32
5 8 9 6 0
5 8 8 6 0
5 8 7 6 0
5 8 6 6 0
5 8 5 6 0
5 8 4 4 64
5 9 10 4 32
5 9 9 4 0
5 9 8 6 0
5 9 7 6 0
5 9 6 6 0
5 9 5 4 0
5 9 4 4 64
5 10 11 4 48
5 10 10 4 0
5 10 9 4 2
5 10 8 4 2
5 10 7 4 2
5 10 6 4 2
5 10 5 4 0
5 10 4 2 72
5 11 15 7 48
5 11 14 7 80
5 11 11 4 32
5 11 10 2 8
5 11 9 2 8
5 11 8 2 8
5 11 7 2 8
5 11 6 2 8
5 11 5 2 72
5 12 15 7 32
5 12 14 7 64
5 12 11 4 96
5 13 15 7 40
5 13 14 7 0
5 13 13 7 80
5 13 11 4 104
5 13 3 7 116
5 14 14 7 32
5 14 13 7 64
5 14 6 5 52
5 14 5 7 16
5 14 4 7 16
5 14 3 7 68
5 15 14 7 40
5 15 13 7 0
5 15 12 7 80
5 15 10 5 48
5 15 9 5 16
5 15 8 5 16
5 15 7 5 16
5 15 6 5 0
5 15 5 5 0
5 15 4 5 0
5 15 3 5 64
5 16 13 7 32
5 16 12 7 0
5 16 11 7 20
5 16 10 5 0
5 16 9 5 0
5 16 8 5 0
5 16 7 5 0
5 16 6 5 0
5 16 5 5 0
5 16 4 5 0
5 16 3 5 64
5 17 13 7 40
5 17 12 7 0
5 17 11 7 4
5 17 10 5 0
5 17 9 5 0
5 17 8 5 0
5 17 7 5 0
5 17 6 5 0
5 17 5 5 0
5 17 4 5 0
5 17 3 0 64
5 18 12 7 32
5 18 11 5 0
5 18 10 5 0
5 18 9 5 0
5 18 8 5 0
5 18 7 5 0
5 18 6 5 0
5 18 5 5 0
5 18 4 5 0
5 18 3 5 64
5 19 12 7 32
5 19 11 5 0
5 19 10 5 0
5 19 9 5 0
5 19 8 5 0
5 19 7 5 0
5 19 6 5 0
5 19 5 5 0
5 19 4 5 0
5 19 3 3 64
5 20 12 7 32
5 20 11 7 0
5 20 10 7 0
5 20 9 7 0
5 20 8 7 0
5 20 7 7 0
5 20 6 7 0
5 20 5 5 0
5 20 4 5 0
5 20 3 5 64
5 21 12 7 32
5 21 11 7 0
5 21 10 7 0
5 21 9 7 0
5 21 8 7 0
5 21 7 7 0
5 21 6 7 0
5 21 5 5 0
5 21 4 5 0
5 21 3 5 64
5 22 12 7 32
5 22 11 7 0
5 22 10 7 0
5 22 9 7 0
5 22 8 7 0
5 22 7 7 0
5 22 6 7 0
5 22 5 7 0
5 22 4 7 0
5 22 3 7 0
5 22 2 7 88
5 23 12 7 40
5 23 11 7 0
5 23 10 7 0
5 23 9 7 0
5 23 8 7 0
5 23 7 7 0
5 23 6 7 0
5 23 5 7 0
5 23 4 7 0
5 23 3 7 72
5 24 11 7 40
5 24 10 7 0
5 24 9 7 0
5 24 8 7 0
5 24 7 7 0
5 24 6 7 0
5 24 5 7 8
5 24 4 7 72
5 25 10 7 44
5 25 9 7 12
5 25 8 7 12
5 25 7 7 12
5 25 6 7 76
6 1 9 3 48
6 1 8 3 16
6 1 7 3 16
6 1 6 3 16
6 1 5 3 16
6 1 4 3 16
6 1 3 3 80
6 2 12 4 116
6 2 10 3 48
6 2 9 1 0
6 2 8 1 0
6 2 7 1 0
6 2 6 1 0
6 2 5 1 0
6 2 4 1 0
6 2 3 3 0
6 2 2 3 80
6 3 12 4 96
6 3 10 3 32
6 3 9 1 0
6 3 8 1 0
6 3 7 1 0
6 3 6 1 0
6 3 5 1 0
6 3 4 1 0
6 3 3 0 0
6 3 2 3 72
6 4 12 4 32
6 4 11 4 16
6 4 10 6 0
6 4 9 6 0
6 4 8 6 0
6 4 7 6 0
6 4 6 6 0
6 4 5 6 0
6 4 4 1 0
6 4 3 6 64
6 5 12 4 32
6 5 11 4 0
6 5 10 6 0
6 5 9 6 0
6 5 8 6 0
6 5 7 6 0
6 5 6 6 0
6 5 5 6 0
6 5 4 1 0
6 5 3 6 72
6 6 12 4 40
6 6 11 6 0
6 6 10 6 0
6 6 9 6 0
6 6 8 6 0
6 6 7 6 0
6 6 6 6 0
6 6 5 6 0
6 6 4 8 64
6 7 11 4 40
6 7 10 6 0
6 7 9 6 0
6 7 8 6 0
6 7 7 6 0
6 7 6 6 0
6 7 5 6 0
6 7 4 8 64
6 8 10 4 32
6 8 9 6 0
6 8 8 6 0
6 8 7 6 0
6 8 6 6 0
6 8 5 6 0
6 8 4 8 64
6 9 10 4 32
6 9 9 4 8
6 9 8 6 8
6 9 7 6 8
6 9 6 6 8
6 9 5 4 0
6 9 4 4 0
6 9 3 2 92
6 10 11 2 48
6 10 10 4 64
6 10 5 4 32
6 10 4 2 72
6 11 15 7 48
6 11 14 7 80
6 11 11 4 32
6 11 10 4 8
6 11 9 4 24
6 11 8 4 24
6 11 7 4 24
6 11 6 4 24
6 11 5 8 72
6 12 15 7 32
6 12 14 7 64
6 12 11 4 96
6 13 15 7 40
6 13 14 7 0
6 13 13 7 80
6 13 11 4 104
6 13 3 7 48
6 13 2 7 84
6 14 14 7 32
6 14 13 7 64
6 14 6 5 48
6 14 5 7 16
6 14 4 7 16
6 14 3 7 0
6 14 2 7 70
6 15 14 7 40
6 15 13 7 0
6 15 12 7 80
6 15 10 5 48
6 15 9 5 16
6 15 8 5 16
6 15 7 5 16
6 15 6 5 0
6 15 5 5 0
6 15 4 5 0
6 15 3 5 0
6 15 2 7 76
6 16 13 7 32
6 16 12 7 0
6 16 11 7 16
6 16 10 5 0
6 16 9 5 0
6 16 8 5 0
6 16 7 5 0
6 16 6 5 0
6 16 5 5 0
6 16 4 5 0
6 16 3 5 64
6 17 13 7 40
6 17 12 7 0
6 17 11 5 0
6 17 10 5 0
6 17 9 5 0
6 17 8 5 0
6 17 7 5 0
6 17 6 5 0
6 17 5 5 0
6 17 4 5 0
6 17 3 5 64
6 18 12 7 32
6 18 11 5 0
6 18 10 5 0
6 18 9 5 0
6 18 8 5 0
6 18 7 5 0
6 18 6 5 0
6 18 5 5 0
6 18 4 5 0
6 18 3 5 64
6 19 12 7 32
6 19 11 5 0
6 19 10 5 0
6 19 9 5 0
6 19 8 5 0
6 19 7 5 0
6 19 6 5 0
6 19 5 5 0
6 19 4 5 0
6 19 3 3 64
6 20 12 7 32
6 20 11 7 0
6 20 10 7 0
6 20 9 7 0
6 20 8 7 0
6 20 7 7 0
6 20 6 7 0
6 20 5 7 0
6 20 4 5 0
6 20 3 5 64
6 21 12 7 32
6 21 11 7 0
6 21 10 7 0
6 21 9 7 0
6 21 8 7 0
6 21 7 7 0
6 21 6 7 0
6 21 5 7 0
6 21 4 5 0
6 21 3 7 0
6 21 2 7 86
6 22 12 7 32
6 22 11 7 0
6 22 10 7 0
6 22 9 7 0
6 22 8 7 0
6 22 7 7 0
6 22 6 7 0
6 22 5 7 0
6 22 4 7 0
6 22 3 7 0
6 22 2 7 72
6 23 12 7 40
6 23 11 7 0
6 23 10 7 0
6 23 9 7 0
6 23 8 7 0
6 23 7 7 0
6 23 6 7 0
6 23 5 7 0
6 23 4 7 0
6 23 3 7 72
6 24 11 7 40
6 24 10 7 0
6 24 9 7 0
6 24 8 7 0
6 24 7 7 0
6 24 6 7 0
6 24 5 7 8
6 24 4 7 72
6 25 10 7 40
6 25 9 7 8
6 25 8 7 8
6 25 7 7 8
6 25 6 7 72
7 1 9 3 48
7 1 8 3 16
7 1 7 3 16
7 1 6 3 16
7 1 5 3 16
7 1 4 3 16
7 1 3 3 80
7 2 12 4 112
7 2 10 3 48
7 2 9 1 0
7 2 8 1 0
7 2 7 1 0
7 2 6 1 0
7 2 5 1 0
7 2 4 1 0
7 2 3 3 0
7 2 2 3 80
7 3 12 4 96
7 3 10 3 32
7 3 9 1 0
7 3 8 1 0
7 3 7 1 0
7 3 6 1 0
7 3 5 1 0
7 3 4 1 0
7 3 3 1 0
7 3 2 3 72
7 4 12 4 32
7 4 11 4 16
7 4 10 6 0
7 4 9 6 0
7 4 8 6 0
7 4 7 6 0
7 4 6 6 0
7 4 5 6 0
7 4 4 1 0
7 4 3 6 64
7 5 12 4 32
7 5 11 6 0
7 5 10 6 0
7 5 9 6 0
7 5 8 6 0
7 5 7 6 0
7 5 6 6 0
7 5 5 6 0
7 5 4 1 0
7 5 3 6 72
7 6 12 4 40
7 6 11 6 0
7 6 10 6 0
7 6 9 6 0
7 6 8 6 0
7 6 7 6 0
7 6 6 6 0
7 6 5 6 0
7 6 4 8 64
7 7 11 4 40
7 7 10 6 0
7 7 9 6 0
7 7 8 6 0
7 7 7 6 0
7 7 6 6 0
7 7 5 6 0
7 7 4 8 64
7 8 10 4 32
7 8 9 6 0
7 8 8 6 0
7 8 7 6 0
7 8 6 6 0
7 8 5 6 0
7 8 4 4 0
7 8 3 2 84
7 9 10 2 32
7 9 9 4 8
7 9 8 6 8
7 9 7 6 8
7 9 6 6 8
7 9 5 4 0
7 9 4 8 0
7 9 3 2 74
7 10 11 2 48
7 10 10 4 64
7 10 5 4 32
7 10 4 8 72
7 11 15 7 48
7 11 14 7 80
7 11 11 4 32
7 11 10 4 8
7 11 9 4 24
7 11 8 4 24
7 11 7 4 24
7 11 6 4 24
7 11 5 8 72
7 12 15 7 32
7 12 14 7 64
7 12 11 4 96
7 12 2 7 52
7 12 1 7 92
7 13 15 7 40
7 13 14 7 0
7 13 13 7 80
7 13 11 4 104
7 13 3 7 48
7 13 2 7 72
7 14 14 7 32
7 14 13 7 64
7 14 6 5 48
7 14 5 7 16
7 14 4 7 16
7 14 3 0 64
7 15 14 7 40
7 15 13 7 0
7 15 12 7 80
7 15 10 5 48
7 15 9 5 16
7 15 8 5 16
7 15 7 5 16
7 15 6 5 0
7 15 5 5 0
7 15 4 5 0
7 15 3 5 0
7 15 2 7 80
7 16 13 7 32
7 16 12 7 0
7 16 11 7 16
7 16 10 5 0
7 16 9 5 0
7 16 8 5 0
7 16 7 5 0
7 16 6 5 0
7 16 5 5 0
7 16 4 5 0
7 16 3 5 0
7 16 2 9 68
7 17 13 7 40
7 17 12 7 0
7 17 11 5 0
7 17 10 5 0
7 17 9 5 0
7 17 8 5 0
7 17 7 5 0
7 17 6 5 0
7 17 5 5 0
7 17 4 5 0
7 17 3 5 0
7 17 2 10 76
7 18 12 7 32
7 18 11 5 0
7 18 10 5 0
7 18 9 5 0
7 18 8 5 0
7 18 7 5 0
7 18 6 5 0
7 18 5 5 0
7 18 4 5 0
7 18 3 11 64
7 19 12 7 32
7 19 11 5 0
7 19 10 5 0
7 19 9 5 0
7 19 8 5 0
7 19 7 5 0
7 19 6 5 0
7 19 5 5 0
7 19 4 5 0
7 19 3 5 64
7 20 12 7 32
7 20 11 7 0
7 20 10 7 0
7 20 9 7 0
7 20 8 7 0
7 20 7 7 0
7 20 6 7 0
7 20 5 7 0
7 20 4 5 0
7 20 3 5 64
7 21 12 7 32
7 21 11 7 0
7 21 10 7 0
7 21 9 7 0
7 21 8 7 0
7 21 7 7 0
7 21 6 7 0
7 21 5 7 0
7 21 4 5 0
7 21 3 5 64
7 22 12 7 32
7 22 11 7 0
7 22 10 7 0
7 22 9 7 0
7 22 8 7 0
7 22 7 7 0
7 22 6 7 0
7 22 5 7 0
7 22 4 7 0
7 22 3 7 0
7 22 2 7 90
7 23 12 7 40
7 23 11 7 0
7 23 10 7 0
7 23 9 7 0
7 23 8 7 0
7 23 7 7 0
7 23 6 7 0
7 23 5 7 0
7 23 4 7 0
7 23 3 7 72
7 24 11 7 40
7 24 10 7 0
7 24 9 7 0
7 24 8 7 0
7 24 7 7 0
7 24 6 7 0
7 24 5 7 8
7 24 4 7 74
7 25 10 7 40
7 25 9 7 8
7 25 8 7 8
7 25 7 7 8
7 25 6 7 72
8 1 9 3 48
8 1 8 3 16
8 1 7 3 16
8 1 6 3 16
8 1 5 3 16
8 1 4 3 16
8 1 3 3 80
8 2 12 4 112
8 2 10 3 48
8 2 9 1 0
8 2 8 1 0
8 2 7 1 0
8 2 6 1 0
8 2 5 1 0
8 2 4 1 0
8 2 3 3 0
8 2 2 3 80
8 3 12 4 96
8 3 10 3 32
8 3 9 1 0
8 3 8 1 0
8 3 7 1 0
8 3 6 1 0
8 3 5 1 0
8 3 4 1 0
8 3 3 1 0
8 3 2 3 72
8 4 12 4 32
8 4 11 4 16
8 4 10 6 0
8 4 9 6 0
8 4 8 6 0
8 4 7 6 0
8 4 6 6 0
8 4 5 6 0
8 4 4 1 0
8 4 3 6 64
8 5 12 4 32
8 5 11 6 0
8 5 10 6 0
8 5 9 6 0
8 5 8 6 0
8 5 7 6 0
8 5 6 6 0
8 5 5 6 0
8 5 4 1 0
8 5 3 6 72
8 6 12 4 40
8 6 11 6 0
8 6 10 6 0
8 6 9 6 0
8 6 8 6 0
8 6 7 6 0
8 6 6 6 0
8 6 5 6 0
8 6 4 8 64
8 7 11 4 40
8 7 10 6 0
8 7 9 6 0
8 7 8 6 0
8 7 7 6 0
8 7 6 6 0
8 7 5 6 0
8 7 4 6 0
8 7 3 2 84
8 8 10 4 32
8 8 9 6 0
8 8 8 6 0
8 8 7 6 0
8 8 6 6 0
8 8 5 6 0
8 8 4 4 0
8 8 3 2 74
8 9 10 2 32
8 9 9 6 8
8 9 8 6 8
8 9 7 6 8
8 9 6 6 8
8 9 5 4 0
8 9 4 8 64
8 10 11 4 48
8 10 10 4 64
8 10 5 4 32
8 10 4 8 72
8 11 15 7 48
8 11 14 7 80
8 11 11 4 32
8 11 10 4 8
8 11 9 4 24
8 11 8 4 24
8 11 7 4 24
8 11 6 4 24
8 11 5 8 72
8 12 15 7 32
8 12 14 7 64
8 12 11 4 96
8 12 2 7 50
8 12 1 7 90
8 13 15 7 40
8 13 14 7 0
8 13 13 7 80
8 13 11 4 104
8 13 3 7 48
8 13 2 7 72
8 14 14 7 32
8 14 13 7 64
8 14 6 5 50
8 14 5 7 16
8 14 4 7 16
8 14 3 0 64
8 15 14 7 40
8 15 13 7 0
8 15 12 7 80
8 15 10 5 48
8 15 9 5 16
8 15 8 5 16
8 15 7 5 16
8 15 6 5 0
8 15 5 5 0
8 15 4 5 0
8 15 3 5 0
8 15 2 7 80
8 16 13 7 32
8 16 12 7 0
8 16 11 7 16
8 16 10 5 0
8 16 9 5 0
8 16 8 5 0
8 16 7 5 0
8 16 6 5 0
8 16 5 5 0
8 16 4 5 0
8 16 3 5 0
8 16 2 9 66
8 17 13 7 40
8 17 12 7 0
8 17 11 5 0
8 17 10 5 0
8 17 9 5 0
8 17 8 5 0
8 17 7 5 0
8 17 6 5 0
8 17 5 5 0
8 17 4 5 0
8 17 3 5 0
8 17 2 10 74
8 18 12 7 32
8 18 11 5 0
8 18 10 5 0
8 18 9 5 0
8 18 8 5 0
8 18 7 5 0
8 18 6 5 0
8 18 5 5 0
8 18 4 5 0
8 18 3 11 64
8 19 12 7 32
8 19 11 5 0
8 19 10 5 0
8 19 9 5 0
8 19 8 5 0
8 19 7 5 0
8 19 6 5 0
8 19 5 5 0
8 19 4 5 0
8 19 3 5 64
8 20 12 7 32
8 20 11 7 0
8 20 10 7 0
8 20 9 7 0
8 20 8 7 0
8 20 7 7 0
8 20 6 7 0
8 20 5 7 0
8 20 4 5 0
8 20 3 5 64
8 21 12 7 32
8 21 11 7 0
8 21 10 7 0
8 21 9 7 0
8 21 8 7 0
8 21 7 7 0
8 21 6 7 0
8 21 5 7 0
8 21 4 5 0
8 21 3 7 0
8 21 2 7 92
8 22 12 7 32
8 22 11 7 0
8 22 10 7 0
8 22 9 7 0
8 22 8 7 0
8 22 7 7 0
8 22 6 7 0
8 22 5 7 0
8 22 4 7 0
8 22 3 7 64
8 23 12 7 40
8 23 11 7 0
8 23 10 7 0
8 23 9 7 0
8 23 8 7 0
8 23 7 7 0
8 23 6 7 0
8 23 5 7 0
8 23 4 7 8
8 23 3 7 72
8 24 11 7 40
8 24 10 7 0
8 24 9 7 0
8 24 8 7 0
8 24 7 7 0
8 24 6 7 0
8 24 5 7 72
8 25 10 7 40
8 25 9 7 8
8 25 8 7 8
8 25 7 7 8
8 25 6 7 72
9 1 9 3 48
9 1 8 3 16
9 1 7 3 16
9 1 6 3 16
9 1 5 3 16
9 1 4 3 16
9 1 3 3 80
9 2 12 4 114
9 2 10 3 48
9 2 9 1 0
9 2 8 1 0
9 2 7 1 0
9 2 6 1 0
9 2 5 1 0
9 2 4 1 0
9 2 3 3 0
9 2 2 3 80
9 3 12 4 96
9 3 10 3 32
9 3 9 1 0
9 3 8 1 0
9 3 7 1 0
9 3 6 1 0
9 3 5 1 0
9 3 4 1 0
9 3 3 0 0
9 3 2 3 72
9 4 12 4 32
9 4 11 4 16
9 4 10 6 0
9 4 9 6 0
9 4 8 6 0
9 4 7 6 0
9 4 6 6 0
9 4 5 6 0
9 4 4 6 0
9 4 3 6 64
9 5 12 4 32
9 5 11 6 0
9 5 10 6 0
9 5 9 6 0
9 5 8 6 0
9 5 7 6 0
9 5 6 6 0
9 5 5 6 0
9 5 4 6 0
9 5 3 6 64
9 6 12 4 40
9 6 11 6 0
9 6 10 6 0
9 6 9 6 0
9 6 8 6 0
9 6 7 6 0
9 6 6 6 0
9 6 5 6 0
9 6 4 6 0
9 6 3 2 68
9 7 11 4 40
9 7 10 6 0
9 7 9 6 0
9 7 8 6 0
9 7 7 6 0
9 7 6 6 0
9 7 5 6 0
9 7 4 6 0
9 7 3 2 72
9 8 10 2 32
9 8 9 6 0
9 8 8 6 0
9 8 7 6 0
9 8 6 6 0
9 8 5 6 0
9 8 4 8 64
9 9 10 2 32
9 9 9 6 8
9 9 8 6 8
9 9 7 6 8
9 9 6 6 8
9 9 5 4 0
9 9 4 8 64
9 10 11 4 48
9 10 10 4 64
9 10 5 4 32
9 10 4 8 72
9 11 15 7 48
9 11 14 7 80
9 11 11 4 32
9 11 10 4 8
9 11 9 4 24
9 11 8 4 24
9 11 7 4 24
9 11 6 4 24
9 11 5 8 72
9 12 15 7 32
9 12 14 7 64
9 12 11 4 96
9 13 15 7 40
9 13 14 7 0
9 13 13 7 80
9 13 11 4 104
9 13 3 7 48
9 13 2 7 82
9 14 14 7 32
9 14 13 7 64
9 14 5 7 48
9 14 4 7 16
9 14 3 7 0
9 14 2 7 70
9 15 14 7 40
9 15 13 7 0
9 15 12 7 80
9 15 10 5 48
9 15 9 5 16
9 15 8 5 16
9 15 7 5 16
9 15 6 5 16
9 15 5 5 0
9 15 4 5 0
9 15 3 5 0
9 15 2 7 74
9 16 13 7 32
9 16 12 7 0
9 16 11 7 16
9 16 10 5 0
9 16 9 5 0
9 16 8 5 0
9 16 7 5 0
9 16 6 5 0
9 16 5 5 0
9 16 4 5 0
9 16 3 5 64
9 17 13 7 40
9 17 12 7 0
9 17 11 5 0
9 17 10 5 0
9 17 9 5 0
9 17 8 5 0
9 17 7 5 0
9 17 6 5 0
9 17 5 5 0
9 17 4 5 0
9 17 3 5 64
9 18 12 7 32
9 18 11 5 0
9 18 10 5 0
9 18 9 5 0
9 18 8 5 0
9 18 7 5 0
9 18 6 5 0
9 18 5 5 0
9 18 4 5 0
9 18 3 5 64
9 19 12 7 32
9 19 11 5 0
9 19 10 5 0
9 19 9 5 0
9 19 8 5 0
9 19 7 5 0
9 19 6 5 0
9 19 5 5 0
9 19 4 5 0
9 19 3 3 64
9 20 12 7 32
9 20 11 7 0
9 20 10 7 0
9 20 9 7 0
9 20 8 7 0
9 20 7 7 0
9 20 6 7 0
9 20 5 7 0
9 20 4 7 0
9 20 3 5 64
9 21 12 7 32
9 21 11 7 0
9 21 10 7 0
9 21 9 7 0
9 21 8 7 0
9 21 7 7 0
9 21 6 7 0
9 21 5 7 0
9 21 4 7 0
9 21 3 7 0
9 21 2 7 80
9 22 12 7 32
9 22 11 7 0
9 22 10 7 0
9 22 9 7 0
9 22 8 7 0
9 22 7 7 0
9 22 6 7 0
9 22 5 7 0
9 22 4 7 0
9 22 3 7 0
9 22 2 7 76
9 23 12 7 40
9 23 11 7 0
9 23 10 7 0
9 23 9 7 0
9 23 8 7 0
9 23 7 7 0
9 23 6 7 0
9 23 5 7 0
9 23 4 7 0
9 23 3 7 72
9 24 11 7 40
9 24 10 7 0
9 24 9 7 0
9 24 8 7 0
9 24 7 7 0
9 24 6 7 0
9 24 5 7 8
9 24 4 7 76
9 25 10 7 40
9 25 9 7 8
9 25 8 7 8
9 25 7 7 8
9 25 6 7 72
10 1 9 3 48
10 1 8 3 16
10 1 7 3 16
10 1 6 3 16
10 1 5 3 16
10 1 4 3 16
10 1 3 3 80
10 2 10 3 48
10 2 9 1 0
10 2 8 1 0
10 2 7 1 0
10 2 6 1 0
10 2 5 1 0
10 2 4 1 0
10 2 3 3 0
10 2 2 3 80
10 3 12 4 114
10 3 10 3 32
10 3 9 1 0
10 3 8 1 0
10 3 7 1 0
10 3 6 1 0
10 3 5 1 0
10 3 4 1 0
10 3 3 0 0
10 3 2 3 72
10 4 12 4 34
10 4 11 4 16
10 4 10 6 0
10 4 9 6 0
10 4 8 6 0
10 4 7 6 0
10 4 6 6 0
10 4 5 6 0
10 4 4 6 0
10 4 3 6 64
10 5 12 4 34
10 5 11 6 0
10 5 10 6 0
10 5 9 6 0
10 5 8 6 0
10 5 7 6 0
10 5 6 6 0
10 5 5 6 0
10 5 4 6 0
10 5 3 6 64
10 6 12 4 42
10 6 11 6 0
10 6 10 6 0
10 6 9 6 0
10 6 8 6 0
10 6 7 6 0
10 6 6 6 0
10 6 5 6 0
10 6 4 6 0
10 6 3 2 64
10 7 11 2 40
10 7 10 6 0
10 7 9 6 0
10 7 8 6 0
10 7 7 6 0
10 7 6 6 0
10 7 5 6 0
10 7 4 6 0
10 7 3 4 72
10 8 10 2 32
10 8 9 6 0
10 8 8 6 0
10 8 7 6 0
10 8 6 6 0
10 8 5 6 0
10 8 4 4 64
10 9 10 4 32
10 9 9 6 0
10 9 8 6 0
10 9 7 6 0
10 9 6 6 0
10 9 5 4 0
10 9 4 4 64
10 10 11 4 48
10 10 10 4 0
10 10 9 4 4
10 10 8 4 4
10 10 7 4 4
10 10 6 4 4
10 10 5 4 0
10 10 4 4 72
10 11 15 7 48
10 11 14 7 80
10 11 11 4 32
10 11 10 4 8
10 11 9 4 8
10 11 8 4 8
10 11 7 4 8
10 11 6 4 8
10 11 5 8 72
10 12 15 7 32
10 12 14 7 64
10 12 11 4 96
10 13 15 7 40
10 13 14 7 0
10 13 13 7 80
10 13 11 4 104
10 13 3 7 114
10 14 14 7 32
10 14 13 7 64
10 14 6 5 54
10 14 5 7 16
10 14 4 7 16
10 14 3 7 66
10 15 14 7 40
10 15 13 7 0
10 15 12 7 80
10 15 10 5 48
10 15 9 5 16
10 15 8 5 16
10 15 7 5 16
10 15 6 5 0
10 15 5 5 0
10 15 4 5 0
10 15 3 5 64
10 16 13 7 32
10 16 12 7 0
10 16 11 7 18
10 16 10 5 0
10 16 9 5 0
10 16 8 5 0
10 16 7 5 0
10 16 6 5 0
10 16 5 5 0
10 16 4 5 0
10 16 3 5 64
10 17 13 7 40
10 17 12 7 0
10 17 11 7 2
10 17 10 5 0
10 17 9 5 0
10 17 8 5 0
10 17 7 5 0
10 17 6 5 0
10 17 5 5 0
10 17 4 5 0
10 17 3 0 64
10 18 12 7 32
10 18 11 7 2
10 18 10 5 0
10 18 9 5 0
10 18 8 5 0
10 18 7 5 0
10 18 6 5 0
10 18 5 5 0
10 18 4 5 0
10 18 3 5 64
10 19 12 7 32
10 19 11 5 0
10 19 10 5 0
10 19 9 5 0
10 19 8 5 0
10 19 7 5 0
10 19 6 5 0
10 19 5 5 0
10 19 4 5 0
10 19 3 3 64
10 20 12 7 32
10 20 11 7 0
10 20 10 7 0
10 20 9 7 0
10 20 8 7 0
10 20 7 7 0
10 20 6 7 0
10 20 5 7 0
10 20 4 7 0
10 20 3 7 64
10 21 12 7 32
10 21 11 7 0
10 21 10 7 0
10 21 9 7 0
10 21 8 7 0
10 21 7 7 0
10 21 6 7 0
10 21 5 7 0
10 21 4 7 0
10 21 3 7 0
10 21 2 7 80
10 22 12 7 32
10 22 11 7 0
10 22 10 7 0
10 22 9 7 0
10 22 8 7 0
10 22 7 7 0
10 22 6 7 0
10 22 5 7 0
10 22 4 7 0
10 22 3 7 0
10 22 2 7 72
10 23 12 7 40
10 23 11 7 0
10 23 10 7 0
10 23 9 7 0
10 23 8 7 0
10 23 7 7 0
10 23 6 7 0
10 23 5 7 0
10 23 4 7 0
10 23 3 7 72
10 24 11 7 40
10 24 10 7 0
10 24 9 7 0
10 24 8 7 0
10 24 7 7 0
10 24 6 7 0
10 24 5 7 8
10 24 4 7 72
10 25 10 7 42
10 25 9 7 10
10 25 8 7 10
10 25 7 7 10
10 25 6 7 74
11 1 9 3 50
11 1 8 3 18
11 1 7 3 18
11 1 6 3 18
11 1 5 3 18
11 1 4 3 18
11 1 3 3 82
11 2 10 3 48
11 2 9 1 0
11 2 8 1 0
11 2 7 1 0
11 2 6 1 0
11 2 5 1 0
11 2 4 1 0
11 2 3 3 0
11 2 2 3 82
11 3 10 3 32
11 3 9 1 0
11 3 8 1 0
11 3 7 1 0
11 3 6 1 0
11 3 5 1 0
11 3 4 1 0
11 3 3 6 0
11 3 2 3 74
11 4 11 4 50
11 4 10 6 0
11 4 9 6 0
11 4 8 6 0
11 4 7 6 0
11 4 6 6 0
11 4 5 6 0
11 4 4 2 2
11 4 3 6 66
11 5 11 4 34
11 5 10 6 0
11 5 9 6 0
11 5 8 6 0
11 5 7 6 0
11 5 6 6 0
11 5 5 6 0
11 5 4 2 2
11 5 3 2 66
11 6 11 2 34
11 6 10 6 0
11 6 9 6 0
11 6 8 6 0
11 6 7 6 0
11 6 6 4 0
11 6 5 4 0
11 6 4 4 2
11 6 3 2 66
11 7 11 2 42
11 7 10 6 0
11 7 9 6 0
11 7 8 6 0
11 7 7 6 0
11 7 6 4 0
11 7 5 4 0
11 7 4 4 2
11 7 3 4 74
11 8 10 4 34
11 8 9 4 2
11 8 8 4 2
11 8 7 4 2
11 8 6 4 2
11 8 5 4 2
11 8 4 4 66
11 9 10 4 34
11 9 9 4 2
11 9 8 4 2
11 9 7 4 2
11 9 6 4 2
11 9 5 4 2
11 9 4 4 66
11 10 11 4 50
11 10 10 4 2
11 10 9 4 2
11 10 8 4 2
11 10 7 4 2
11 10 6 4 2
11 10 5 4 2
11 10 4 4 66
11 11 15 7 48
11 11 14 7 80
11 11 11 4 32
11 11 10 4 8
11 11 9 4 8
11 11 8 4 8
11 11 7 4 8
11 11 6 4 8
11 11 5 4 8
11 11 4 4 78
11 12 15 7 32
11 12 14 7 64
11 12 11 4 96
11 13 15 7 40
11 13 14 7 0
11 13 13 7 80
11 13 11 4 104
11 14 14 7 32
11 14 13 7 64
11 14 5 7 50
11 14 4 7 82
11 15 14 7 40
11 15 13 7 0
11 15 12 7 80
11 15 10 5 50
11 15 9 5 18
11 15 8 5 18
11 15 7 5 18
11 15 6 5 18
11 15 5 7 0
11 15 4 7 0
11 15 3 5 82
11 16 13 7 32
11 16 12 7 64
11 16 10 5 34
11 16 9 5 2
11 16 8 5 0
11 16 7 5 0
11 16 6 5 0
11 16 5 5 0
11 16 4 5 0
11 16 3 5 64
11 17 13 7 40
11 17 12 7 64
11 17 10 5 32
11 17 9 5 0
11 17 8 5 0
11 17 7 5 0
11 17 6 5 0
11 17 5 5 0
11 17 4 5 0
11 17 3 5 64
11 18 12 7 96
11 18 10 5 32
11 18 9 5 0
11 18 8 5 0
11 18 7 5 0
11 18 6 5 0
11 18 5 5 0
11 18 4 5 0
11 18 3 5 64
11 19 12 7 34
11 19 11 7 16
11 19 10 5 0
11 19 9 5 0
11 19 8 5 0
11 19 7 5 0
11 19 6 5 0
11 19 5 5 0
11 19 4 5 0
11 19 3 7 64
11 20 12 7 34
11 20 11 7 0
11 20 10 7 0
11 20 9 7 0
11 20 8 7 0
11 20 7 7 0
11 20 6 7 0
11 20 5 7 0
11 20 4 7 0
11 20 3 7 0
11 20 2 7 86
11 21 12 7 34
11 21 11 7 0
11 21 10 7 0
11 21 9 7 0
11 21 8 7 0
11 21 7 7 0
11 21 6 7 0
11 21 5 7 0
11 21 4 7 0
11 21 3 7 0
11 21 2 7 66
11 22 12 7 34
11 22 11 7 0
11 22 10 7 0
11 22 9 7 0
11 22 8 7 0
11 22 7 7 0
11 22 6 7 0
11 22 5 7 0
11 22 4 7 0
11 22 3 7 0
11 22 2 7 74
11 23 12 7 42
11 23 11 7 0
11 23 10 7 0
11 23 9 7 0
11 23 8 7 0
11 23 7 7 0
11 23 6 7 0
11 23 5 7 0
11 23 4 7 0
11 23 3 7 72
11 24 11 7 42
11 24 10 7 10
11 24 9 7 10
11 24 8 7 10
11 24 7 7 10
11 24 6 7 10
11 24 5 7 10
11 24 4 7 74
12 2 10 3 50
12 2 9 3 18
12 2 8 3 18
12 2 7 3 18
12 2 6 3 18
12 2 5 3 18
12 2 4 3 18
12 2 3 3 82
12 3 10 3 34
12 3 9 2 2
12 3 8 2 2
12 3 7 2 2
12 3 6 2 2
12 3 5 2 2
12 3 4 2 10
12 3 3 3 74
12 4 10 4 34
12 4 9 2 2
12 4 8 2 2
12 4 7 2 2
12 4 6 2 2
12 4 5 2 66
12 5 10 2 34
12 5 9 2 2
12 5 8 4 2
12 5 7 4 2
12 5 6 4 2
12 5 5 4 66
12 6 10 2 34
12 6 9 4 2
12 6 8 4 2
12 6 7 4 2
12 6 6 4 2
12 6 5 4 66
12 7 10 4 42
12 7 9 4 10
12 7 8 4 10
12 7 7 4 10
12 7 6 4 10
12 7 5 4 74
12 11 15 7 50
12 11 14 7 82
12 11 11 4 50
12 11 10 4 18
12 11 9 4 18
12 11 8 4 18
12 11 7 4 18
12 11 6 4 18
12 11 5 4 82
12 12 15 7 34
12 12 14 7 66
12 12 11 4 34
12 12 10 4 6
12 12 9 4 6
12 12 8 4 6
12 12 7 4 6
12 12 6 4 14
12 12 5 4 78
12 13 15 7 42
12 13 14 7 2
12 13 13 7 82
12 13 11 4 42
12 13 10 4 14
12 13 9 4 14
12 13 8 4 14
12 13 7 4 78
12 14 14 7 34
12 14 13 7 66
12 15 14 7 42
12 15 13 7 2
12 15 12 7 82
12 15 5 7 50
12 15 4 7 82
12 16 13 7 34
12 16 12 7 66
12 16 8 5 50
12 16 7 5 18
12 16 6 5 18
12 16 5 7 0
12 16 4 5 2
12 16 3 5 82
12 17 13 7 42
12 17 12 7 66
12 17 10 5 50
12 17 9 5 18
12 17 8 5 2
12 17 7 5 2
12 17 6 5 0
12 17 5 5 0
12 17 4 5 2
12 17 3 5 66
12 18 12 7 106
12 18 10 5 34
12 18 9 5 0
12 18 8 5 0
12 18 7 5 2
12 18 6 5 0
12 18 5 5 0
12 18 4 5 2
12 18 3 5 66
12 19 11 7 50
12 19 10 5 2
12 19 9 5 0
12 19 8 5 0
12 19 7 5 2
12 19 6 5 0
12 19 5 5 0
12 19 4 5 0
12 19 3 5 66
12 20 11 7 34
12 20 10 7 2
12 20 9 7 0
12 20 8 7 0
12 20 7 7 2
12 20 6 7 0
12 20 5 7 0
12 20 4 7 0
12 20 3 7 64
12 21 11 7 34
12 21 10 7 2
12 21 9 7 2
12 21 8 7 2
12 21 7 7 2
12 21 6 7 0
12 21 5 7 0
12 21 4 7 0
12 21 3 7 64
12 22 11 7 34
12 22 10 7 2
12 22 9 7 2
12 22 8 7 2
12 22 7 7 2
12 22 6 7 2
12 22 5 7 2
12 22 4 7 0
12 22 3 7 64
12 23 11 7 42
12 23 10 7 10
12 23 9 7 10
12 23 8 7 10
12 23 7 7 10
12 23 6 7 10
12 23 5 7 10
12 23 4 7 10
12 23 3 7 74
13 16 5 7 114
13 17 6 7 50
13 17 5 7 66
13 18 9 5 48
13 18 8 5 82
13 18 6 7 34
13 18 5 7 66
13 19 9 5 32
13 19 8 5 64
13 19 6 7 34
13 19 5 7 2
13 19 4 7 82
13 20 9 7 42
13 20 8 7 74
13 20 6 7 34
13 20 5 7 2
13 20 4 7 2
13 20 3 7 82
13 21 6 7 42
13 21 5 7 10
13 21 4 7 2
13 21 3 7 66
13 22 4 7 42
13 22 3 7 74
14 18 9 5 114
14 19 9 5 42
14 19 8 5 90
