Qubicle Exchange Format
Version 0.2
www.minddesk.com
15 26 26
12
0.000000 0.000000 0.000000
0.141176 0.211765 0.392157
0.188235 0.192157 0.196078
0.266667 0.156863 0.000000
0.368627 0.160784 0.121569
0.443137 0.388235 0.309804
0.682353 0.466667 0.019608
0.890196 0.890196 0.733333
0.894118 0.200000 0.203922
0.905882 0.752941 0.388235
0.960784 0.533333 0.086275
0.988235 0.784314 0.031373
1 18 14 9 116
1 19 14 9 44
1 19 13 9 92
2 16 10 3 116
2 17 11 3 52
2 17 10 3 68
2 18 14 9 48
2 18 13 9 84
2 18 11 3 36
2 18 10 3 68
2 19 15 3 60
2 19 14 9 0
2 19 13 9 64
2 19 11 3 36
2 19 10 3 4
2 19 9 3 84
2 20 14 3 44
2 20 13 3 76
2 20 11 3 36
2 20 10 3 4
2 20 9 3 4
2 20 8 3 84
2 21 11 3 44
2 21 10 3 12
2 21 9 3 4
2 21 8 3 68
2 22 9 3 44
2 22 8 3 76
3 2 15 4 52
3 2 14 4 20
3 2 13 4 20
3 2 12 4 20
3 2 11 4 20
3 2 10 4 20
3 2 9 4 20
3 2 8 4 84
3 3 15 4 36
3 3 14 2 4
3 3 13 2 4
3 3 12 2 4
3 3 11 2 4
3 3 10 2 4
3 3 9 2 12
3 3 8 4 76
3 4 15 5 36
3 4 14 2 4
3 4 13 2 4
3 4 12 2 4
3 4 11 2 4
3 4 10 2 68
3 5 15 2 36
3 5 14 2 4
3 5 13 5 4
3 5 12 5 4
3 5 11 5 4
3 5 10 5 68
3 6 15 2 36
3 6 14 5 4
3 6 13 5 4
3 6 12 5 4
3 6 11 5 4
3 6 10 5 68
3 7 15 5 44
3 7 14 5 12
3 7 13 5 12
3 7 12 5 12
3 7 11 5 12
3 7 10 5 76
3 11 20 3 52
3 11 19 3 84
3 11 16 5 52
3 11 15 5 20
3 11 14 5 20
3 11 13 5 20
3 11 12 5 20
3 11 11 5 20
3 11 10 5 84
3 12 20 3 36
3 12 19 3 68
3 12 16 5 36
3 12 15 5 6
3 12 14 5 6
3 12 13 5 6
3 12 12 5 6
3 12 11 5 14
3 12 10 5 78
3 13 20 3 44
3 13 19 3 4
3 13 18 3 84
3 13 16 5 44
3 13 15 5 14
3 13 14 5 14
3 13 13 5 14
3 13 12 5 78
3 14 19 3 36
3 14 18 3 68
3 15 19 3 44
3 15 18 3 4
3 15 17 3 84
3 15 10 3 52
3 15 9 3 84
3 16 18 3 36
3 16 17 3 68
3 16 13 9 52
3 16 12 9 20
3 16 11 9 20
3 16 10 3 0
3 16 9 9 4
3 16 8 9 84
3 17 18 3 44
3 17 17 3 68
3 17 15 9 52
3 17 14 9 20
3 17 13 9 4
3 17 12 9 4
3 17 11 9 0
3 17 10 9 0
3 17 9 9 4
3 17 8 9 68
3 18 17 3 108
3 18 15 9 36
3 18 14 9 0
3 18 13 9 0
3 18 12 9 4
3 18 11 9 0
3 18 10 9 0
3 18 9 9 4
3 18 8 9 68
3 19 16 3 52
3 19 15 9 0
3 19 14 9 0
3 19 13 9 0
3 19 12 9 4
3 19 11 9 0
3 19 10 9 0
3 19 9 9 0
3 19 8 9 68
3 20 16 3 36
3 20 15 3 4
3 20 14 3 0
3 20 13 3 0
3 20 12 3 4
3 20 11 3 0
3 20 10 3 0
3 20 9 3 0
3 20 8 3 64
3 21 16 3 36
3 21 15 3 4
3 21 14 3 4
3 21 13 3 4
3 21 12 3 4
3 21 11 3 0
3 21 10 3 0
3 21 9 3 0
3 21 8 3 64
3 22 16 3 36
3 22 15 3 4
3 22 14 3 4
3 22 13 3 4
3 22 12 3 4
3 22 11 3 4
3 22 10 3 4
3 22 9 3 0
3 22 8 3 64
3 23 16 3 44
3 23 15 3 12
3 23 14 3 12
3 23 13 3 12
3 23 12 3 12
3 23 11 3 12
3 23 10 3 12
3 23 9 3 12
3 23 8 3 76
4 1 14 4 52
4 1 13 4 20
4 1 12 4 20
4 1 11 4 20
4 1 10 4 20
4 1 9 4 20
4 1 8 4 84
4 2 15 4 48
4 2 14 1 0
4 2 13 1 0
4 2 12 1 0
4 2 11 1 0
4 2 10 1 0
4 2 9 1 0
4 2 8 4 0
4 2 7 4 84
4 3 15 4 32
4 3 14 1 0
4 3 13 1 0
4 3 12 1 0
4 3 11 1 0
4 3 10 1 0
4 3 9 1 0
4 3 8 6 0
4 3 7 4 76
4 4 16 5 52
4 4 15 6 0
4 4 14 6 0
4 4 13 6 0
4 4 12 6 0
4 4 11 6 0
4 4 10 6 0
4 4 9 2 4
4 4 8 6 68
4 5 16 5 36
4 5 15 6 0
4 5 14 6 0
4 5 13 6 0
4 5 12 6 0
4 5 11 6 0
4 5 10 6 0
4 5 9 2 4
4 5 8 2 68
4 6 16 2 36
4 6 15 6 0
4 6 14 6 0
4 6 13 6 0
4 6 12 6 0
4 6 11 5 0
4 6 10 5 0
4 6 9 5 4
4 6 8 2 68
4 7 16 2 44
4 7 15 6 0
4 7 14 6 0
4 7 13 6 0
4 7 12 6 0
4 7 11 5 0
4 7 10 5 0
4 7 9 5 4
4 7 8 5 76
4 8 15 5 36
4 8 14 5 4
4 8 13 5 4
4 8 12 5 4
4 8 11 5 4
4 8 10 5 4
4 8 9 5 68
4 9 15 5 36
4 9 14 5 4
4 9 13 5 4
4 9 12 5 4
4 9 11 5 4
4 9 10 5 4
4 9 9 5 68
4 10 16 5 52
4 10 15 5 4
4 10 14 5 4
4 10 13 5 4
4 10 12 5 4
4 10 11 5 4
4 10 10 5 4
4 10 9 5 68
4 11 20 3 48
4 11 19 3 80
4 11 16 5 32
4 11 15 5 8
4 11 14 5 8
4 11 13 5 8
4 11 12 5 8
4 11 11 5 8
4 11 10 5 8
4 11 9 5 78
4 12 20 3 32
4 12 19 3 64
4 12 16 5 96
4 13 20 3 40
4 13 19 3 0
4 13 18 3 80
4 13 16 5 104
4 14 19 3 32
4 14 18 3 64
4 14 10 3 52
4 14 9 3 84
4 15 19 3 40
4 15 18 3 0
4 15 17 3 80
4 15 15 9 52
4 15 14 9 20
4 15 13 9 20
4 15 12 9 20
4 15 11 9 20
4 15 10 3 0
4 15 9 3 0
4 15 8 9 84
4 16 18 3 32
4 16 17 3 64
4 16 15 9 36
4 16 14 9 4
4 16 13 9 0
4 16 12 9 0
4 16 11 9 0
4 16 10 9 0
4 16 9 9 0
4 16 8 9 64
4 17 18 3 40
4 17 17 3 64
4 17 15 9 32
4 17 14 9 0
4 17 13 9 0
4 17 12 9 0
4 17 11 9 0
4 17 10 9 0
4 17 9 9 0
4 17 8 9 64
4 18 17 3 96
4 18 15 9 32
4 18 14 9 0
4 18 13 9 0
4 18 12 9 0
4 18 11 9 0
4 18 10 9 0
4 18 9 9 0
4 18 8 9 64
4 19 17 3 36
4 19 16 3 16
4 19 15 9 0
4 19 14 9 0
4 19 13 9 0
4 19 12 9 0
4 19 11 9 0
4 19 10 9 0
4 19 9 9 0
4 19 8 3 64
4 20 17 3 36
4 20 16 3 0
4 20 15 3 0
4 20 14 3 0
4 20 13 3 0
4 20 12 3 0
4 20 11 3 0
4 20 10 3 0
4 20 9 3 0
4 20 8 3 0
4 20 7 3 86
4 21 17 3 36
4 21 16 3 0
4 21 15 3 0
4 21 14 3 0
4 21 13 3 0
4 21 12 3 0
4 21 11 3 0
4 21 10 3 0
4 21 9 3 0
4 21 8 3 0
4 21 7 3 68
4 22 17 3 36
4 22 16 3 0
4 22 15 3 0
4 22 14 3 0
4 22 13 3 0
4 22 12 3 0
4 22 11 3 0
4 22 10 3 0
4 22 9 3 0
4 22 8 3 0
4 22 7 3 76
4 23 17 3 44
4 23 16 3 0
4 23 15 3 0
4 23 14 3 0
4 23 13 3 0
4 23 12 3 0
4 23 11 3 0
4 23 10 3 0
4 23 9 3 0
4 23 8 3 72
4 24 16 3 44
4 24 15 3 12
4 24 14 3 12
4 24 13 3 12
4 24 12 3 12
4 24 11 3 12
4 24 10 3 12
4 24 9 3 76
5 1 14 4 48
5 1 13 4 16
5 1 12 4 16
5 1 11 4 16
5 1 10 4 16
5 1 9 4 16
5 1 8 4 80
5 2 15 4 48
5 2 14 1 0
5 2 13 1 0
5 2 12 1 0
5 2 11 1 0
5 2 10 1 0
5 2 9 1 0
5 2 8 4 0
5 2 7 4 80
5 3 17 5 116
5 3 15 4 32
5 3 14 1 0
5 3 13 1 0
5 3 12 1 0
5 3 11 1 0
5 3 10 1 0
5 3 9 1 0
5 3 8 0 0
5 3 7 4 72
5 4 17 5 36
5 4 16 5 16
5 4 15 6 0
5 4 14 6 0
5 4 13 6 0
5 4 12 6 0
5 4 11 6 0
5 4 10 6 0
5 4 9 6 0
5 4 8 6 64
5 5 17 5 36
5 5 16 6 0
5 5 15 6 0
5 5 14 6 0
5 5 13 6 0
5 5 12 6 0
5 5 11 6 0
5 5 10 6 0
5 5 9 6 0
5 5 8 6 64
5 6 17 5 44
5 6 16 6 0
5 6 15 6 0
5 6 14 6 0
5 6 13 6 0
5 6 12 6 0
5 6 11 6 0
5 6 10 6 0
5 6 9 6 0
5 6 8 2 64
5 7 16 2 40
5 7 15 6 0
5 7 14 6 0
5 7 13 6 0
5 7 12 6 0
5 7 11 6 0
5 7 10 6 0
5 7 9 6 0
5 7 8 5 72
5 8 15 2 32
5 8 14 6 0
5 8 13 6 0
5 8 12 6 0
5 8 11 6 0
5 8 10 6 0
5 8 9 5 64
5 9 15 5 32
5 9 14 6 0
5 9 13 6 0
5 9 12 6 0
5 9 11 6 0
5 9 10 5 0
5 9 9 5 64
5 10 16 5 48
5 10 15 5 0
5 10 14 5 2
5 10 13 5 2
5 10 12 5 2
5 10 11 5 2
5 10 10 5 0
5 10 9 5 72
5 11 20 3 48
5 11 19 3 80
5 11 16 5 32
5 11 15 5 8
5 11 14 5 8
5 11 13 5 8
5 11 12 5 8
5 11 11 5 8
5 11 10 7 72
5 12 20 3 32
5 12 19 3 64
5 12 16 5 96
5 13 20 3 40
5 13 19 3 0
5 13 18 3 80
5 13 16 5 104
5 13 8 3 116
5 14 19 3 32
5 14 18 3 64
5 14 11 9 54
5 14 10 3 16
5 14 9 3 16
5 14 8 3 68
5 15 19 3 40
5 15 18 3 0
5 15 17 3 80
5 15 15 9 48
5 15 14 9 16
5 15 13 9 16
5 15 12 9 16
5 15 11 9 0
5 15 10 9 0
5 15 9 9 0
5 15 8 9 64
5 16 18 3 32
5 16 17 3 0
5 16 16 3 20
5 16 15 9 0
5 16 14 9 0
5 16 13 9 0
5 16 12 9 0
5 16 11 9 0
5 16 10 9 0
5 16 9 9 0
5 16 8 9 64
5 17 18 3 40
5 17 17 3 0
5 17 16 3 4
5 17 15 9 0
5 17 14 9 0
5 17 13 9 0
5 17 12 9 0
5 17 11 9 0
5 17 10 9 0
5 17 9 9 0
5 17 8 0 64
5 18 17 3 32
5 18 16 3 4
5 18 15 9 0
5 18 14 9 0
5 18 13 9 0
5 18 12 9 0
5 18 11 9 0
5 18 10 9 0
5 18 9 9 0
5 18 8 9 64
5 19 17 3 32
5 19 16 9 0
5 19 15 9 0
5 19 14 9 0
5 19 13 9 0
5 19 12 9 0
5 19 11 9 0
5 19 10 9 0
5 19 9 9 0
5 19 8 0 64
5 20 17 3 32
5 20 16 3 0
5 20 15 3 0
5 20 14 3 0
5 20 13 3 0
5 20 12 3 0
5 20 11 3 0
5 20 10 3 0
5 20 9 3 0
5 20 8 3 64
5 21 17 3 32
5 21 16 3 0
5 21 15 3 0
5 21 14 3 0
5 21 13 3 0
5 21 12 3 0
5 21 11 3 0
5 21 10 3 0
5 21 9 3 0
5 21 8 3 0
5 21 7 3 80
5 22 17 3 32
5 22 16 3 0
5 22 15 3 0
5 22 14 3 0
5 22 13 3 0
5 22 12 3 0
5 22 11 3 0
5 22 10 3 0
5 22 9 3 0
5 22 8 3 0
5 22 7 3 72
5 23 17 3 40
5 23 16 3 0
5 23 15 3 0
5 23 14 3 0
5 23 13 3 0
5 23 12 3 0
5 23 11 3 0
5 23 10 3 0
5 23 9 3 0
5 23 8 3 72
5 24 16 3 40
5 24 15 3 0
5 24 14 3 0
5 24 13 3 0
5 24 12 3 0
5 24 11 3 0
5 24 10 3 8
5 24 9 3 72
5 25 15 3 44
5 25 14 3 12
5 25 13 3 12
5 25 12 3 12
5 25 11 3 76
6 1 14 4 48
6 1 13 4 16
6 1 12 4 16
6 1 11 4 16
6 1 10 4 16
6 1 9 4 16
6 1 8 4 80
6 2 17 5 116
6 2 15 4 48
6 2 14 1 0
6 2 13 1 0
6 2 12 1 0
6 2 11 1 0
6 2 10 1 0
6 2 9 1 0
6 2 8 4 0
6 2 7 4 80
6 3 17 5 96
6 3 15 4 32
6 3 14 1 0
6 3 13 1 0
6 3 12 1 0
6 3 11 1 0
6 3 10 1 0
6 3 9 1 0
6 3 8 0 0
6 3 7 4 72
6 4 17 5 32
6 4 16 5 16
6 4 15 6 0
6 4 14 6 0
6 4 13 6 0
6 4 12 6 0
6 4 11 6 0
6 4 10 6 0
6 4 9 6 0
6 4 8 6 64
6 5 17 5 32
6 5 16 6 0
6 5 15 6 0
6 5 14 6 0
6 5 13 6 0
6 5 12 6 0
6 5 11 6 0
6 5 10 6 0
6 5 9 6 0
6 5 8 6 64
6 6 17 5 40
6 6 16 6 0
6 6 15 6 0
6 6 14 6 0
6 6 13 6 0
6 6 12 6 0
6 6 11 6 0
6 6 10 6 0
6 6 9 6 0
6 6 8 2 66
6 7 16 5 40
6 7 15 6 0
6 7 14 6 0
6 7 13 6 0
6 7 12 6 0
6 7 11 6 0
6 7 10 6 0
6 7 9 6 0
6 7 8 2 72
6 8 15 2 32
6 8 14 6 0
6 8 13 6 0
6 8 12 6 0
6 8 11 6 0
6 8 10 6 0
6 8 9 7 64
6 9 15 2 32
6 9 14 6 8
6 9 13 6 8
6 9 12 6 8
6 9 11 6 8
6 9 10 5 0
6 9 9 7 64
6 10 16 5 48
6 10 15 5 64
6 10 10 5 32
6 10 9 7 72
6 11 20 3 48
6 11 19 3 80
6 11 16 5 32
6 11 15 5 8
6 11 14 5 24
6 11 13 5 24
6 11 12 5 24
6 11 11 5 24
6 11 10 7 72
6 12 20 3 32
6 12 19 3 64
6 12 16 5 96
6 13 20 3 40
6 13 19 3 0
6 13 18 3 80
6 13 16 5 104
6 13 8 3 48
6 13 7 3 84
6 14 19 3 32
6 14 18 3 64
6 14 10 3 48
6 14 9 3 16
6 14 8 3 0
6 14 7 3 70
6 15 19 3 40
6 15 18 3 0
6 15 17 3 80
6 15 15 9 48
6 15 14 9 16
6 15 13 9 16
6 15 12 9 16
6 15 11 9 16
6 15 10 9 0
6 15 9 9 0
6 15 8 9 0
6 15 7 3 76
6 16 18 3 32
6 16 17 3 0
6 16 16 3 16
6 16 15 9 0
6 16 14 9 0
6 16 13 9 0
6 16 12 9 0
6 16 11 9 0
6 16 10 9 0
6 16 9 9 0
6 16 8 9 64
6 17 18 3 40
6 17 17 3 0
6 17 16 9 0
6 17 15 9 0
6 17 14 9 0
6 17 13 9 0
6 17 12 9 0
6 17 11 9 0
6 17 10 9 0
6 17 9 9 0
6 17 8 9 64
6 18 17 3 32
6 18 16 9 0
6 18 15 9 0
6 18 14 9 0
6 18 13 9 0
6 18 12 9 0
6 18 11 9 0
6 18 10 9 0
6 18 9 9 0
6 18 8 9 64
6 19 17 3 32
6 19 16 9 0
6 19 15 9 0
6 19 14 9 0
6 19 13 9 0
6 19 12 9 0
6 19 11 9 0
6 19 10 9 0
6 19 9 9 0
6 19 8 0 64
6 20 17 3 32
6 20 16 3 0
6 20 15 3 0
6 20 14 3 0
6 20 13 3 0
6 20 12 3 0
6 20 11 3 0
6 20 10 3 0
6 20 9 3 0
6 20 8 9 64
6 21 17 3 32
6 21 16 3 0
6 21 15 3 0
6 21 14 3 0
6 21 13 3 0
6 21 12 3 0
6 21 11 3 0
6 21 10 3 0
6 21 9 3 0
6 21 8 3 0
6 21 7 3 80
6 22 17 3 32
6 22 16 3 0
6 22 15 3 0
6 22 14 3 0
6 22 13 3 0
6 22 12 3 0
6 22 11 3 0
6 22 10 3 0
6 22 9 3 0
6 22 8 3 0
6 22 7 3 72
6 23 17 3 40
6 23 16 3 0
6 23 15 3 0
6 23 14 3 0
6 23 13 3 0
6 23 12 3 0
6 23 11 3 0
6 23 10 3 0
6 23 9 3 0
6 23 8 3 72
6 24 16 3 40
6 24 15 3 0
6 24 14 3 0
6 24 13 3 0
6 24 12 3 0
6 24 11 3 0
6 24 10 3 8
6 24 9 3 74
6 25 15 3 40
6 25 14 3 8
6 25 13 3 8
6 25 12 3 8
6 25 11 3 72
7 1 14 4 48
7 1 13 4 16
7 1 12 4 16
7 1 11 4 16
7 1 10 4 16
7 1 9 4 16
7 1 8 4 80
7 2 17 5 112
7 2 15 4 48
7 2 14 1 0
7 2 13 1 0
7 2 12 1 0
7 2 11 1 0
7 2 10 1 0
7 2 9 1 0
7 2 8 4 0
7 2 7 4 80
7 3 17 5 96
7 3 15 4 32
7 3 14 1 0
7 3 13 1 0
7 3 12 1 0
7 3 11 1 0
7 3 10 1 0
7 3 9 1 0
7 3 8 1 0
7 3 7 4 72
7 4 17 5 32
7 4 16 5 16
7 4 15 6 0
7 4 14 6 0
7 4 13 6 0
7 4 12 6 0
7 4 11 6 0
7 4 10 6 0
7 4 9 1 0
7 4 8 6 64
7 5 17 5 32
7 5 16 6 0
7 5 15 6 0
7 5 14 6 0
7 5 13 6 0
7 5 12 6 0
7 5 11 6 0
7 5 10 6 0
7 5 9 1 0
7 5 8 6 72
7 6 17 5 40
7 6 16 6 0
7 6 15 6 0
7 6 14 6 0
7 6 13 6 0
7 6 12 6 0
7 6 11 6 0
7 6 10 6 0
7 6 9 7 64
7 7 16 5 40
7 7 15 6 0
7 7 14 6 0
7 7 13 6 0
7 7 12 6 0
7 7 11 6 0
7 7 10 6 0
7 7 9 6 0
7 7 8 2 82
7 8 15 5 32
7 8 14 6 0
7 8 13 6 0
7 8 12 6 0
7 8 11 6 0
7 8 10 6 0
7 8 9 5 0
7 8 8 2 76
7 9 15 2 32
7 9 14 6 8
7 9 13 6 8
7 9 12 6 8
7 9 11 6 8
7 9 10 5 0
7 9 9 7 64
7 10 16 5 48
7 10 15 5 64
7 10 10 5 32
7 10 9 7 72
7 11 20 3 48
7 11 19 3 80
7 11 16 5 32
7 11 15 5 8
7 11 14 5 24
7 11 13 5 24
7 11 12 5 24
7 11 11 5 24
7 11 10 7 72
7 12 20 3 32
7 12 19 3 64
7 12 16 5 96
7 12 7 3 52
7 12 6 3 92
7 13 20 3 40
7 13 19 3 0
7 13 18 3 80
7 13 16 5 104
7 13 8 3 48
7 13 7 3 72
7 14 19 3 32
7 14 18 3 64
7 14 11 9 52
7 14 10 3 16
7 14 9 3 16
7 14 8 0 64
7 15 19 3 40
7 15 18 3 0
7 15 17 3 80
7 15 15 9 48
7 15 14 9 16
7 15 13 9 16
7 15 12 9 16
7 15 11 9 0
7 15 10 9 0
7 15 9 9 0
7 15 8 9 0
7 15 7 3 80
7 16 18 3 32
7 16 17 3 0
7 16 16 3 16
7 16 15 9 0
7 16 14 9 0
7 16 13 9 0
7 16 12 9 0
7 16 11 9 0
7 16 10 9 0
7 16 9 9 0
7 16 8 9 0
7 16 7 8 68
7 17 18 3 40
7 17 17 3 0
7 17 16 9 0
7 17 15 9 0
7 17 14 9 0
7 17 13 9 0
7 17 12 9 0
7 17 11 9 0
7 17 10 9 0
7 17 9 9 0
7 17 8 9 0
7 17 7 10 76
7 18 17 3 32
7 18 16 9 0
7 18 15 9 0
7 18 14 9 0
7 18 13 9 0
7 18 12 9 0
7 18 11 9 0
7 18 10 9 0
7 18 9 9 0
7 18 8 11 64
7 19 17 3 32
7 19 16 9 0
7 19 15 9 0
7 19 14 9 0
7 19 13 9 0
7 19 12 9 0
7 19 11 9 0
7 19 10 9 0
7 19 9 9 0
7 19 8 9 64
7 20 17 3 32
7 20 16 3 0
7 20 15 3 0
7 20 14 3 0
7 20 13 3 0
7 20 12 3 0
7 20 11 3 0
7 20 10 3 0
7 20 9 9 0
7 20 8 9 64
7 21 17 3 32
7 21 16 3 0
7 21 15 3 0
7 21 14 3 0
7 21 13 3 0
7 21 12 3 0
7 21 11 3 0
7 21 10 3 0
7 21 9 9 0
7 21 8 3 0
7 21 7 3 82
7 22 17 3 32
7 22 16 3 0
7 22 15 3 0
7 22 14 3 0
7 22 13 3 0
7 22 12 3 0
7 22 11 3 0
7 22 10 3 0
7 22 9 3 0
7 22 8 3 0
7 22 7 3 72
7 23 17 3 40
7 23 16 3 0
7 23 15 3 0
7 23 14 3 0
7 23 13 3 0
7 23 12 3 0
7 23 11 3 0
7 23 10 3 0
7 23 9 3 8
7 23 8 3 72
7 24 16 3 40
7 24 15 3 0
7 24 14 3 0
7 24 13 3 0
7 24 12 3 0
7 24 11 3 0
7 24 10 3 72
7 25 15 3 40
7 25 14 3 8
7 25 13 3 8
7 25 12 3 8
7 25 11 3 72
8 1 14 4 48
8 1 13 4 16
8 1 12 4 16
8 1 11 4 16
8 1 10 4 16
8 1 9 4 16
8 1 8 4 80
8 2 17 5 112
8 2 15 4 48
8 2 14 1 0
8 2 13 1 0
8 2 12 1 0
8 2 11 1 0
8 2 10 1 0
8 2 9 1 0
8 2 8 4 0
8 2 7 4 80
8 3 17 5 96
8 3 15 4 32
8 3 14 1 0
8 3 13 1 0
8 3 12 1 0
8 3 11 1 0
8 3 10 1 0
8 3 9 1 0
8 3 8 1 0
8 3 7 4 72
8 4 17 5 32
8 4 16 5 16
8 4 15 6 0
8 4 14 6 0
8 4 13 6 0
8 4 12 6 0
8 4 11 6 0
8 4 10 6 0
8 4 9 1 0
8 4 8 6 64
8 5 17 5 32
8 5 16 6 0
8 5 15 6 0
8 5 14 6 0
8 5 13 6 0
8 5 12 6 0
8 5 11 6 0
8 5 10 6 0
8 5 9 1 0
8 5 8 6 72
8 6 17 5 40
8 6 16 6 0
8 6 15 6 0
8 6 14 6 0
8 6 13 6 0
8 6 12 6 0
8 6 11 6 0
8 6 10 6 0
8 6 9 7 64
8 7 16 5 40
8 7 15 6 0
8 7 14 6 0
8 7 13 6 0
8 7 12 6 0
8 7 11 6 0
8 7 10 6 0
8 7 9 7 64
8 8 15 5 32
8 8 14 6 0
8 8 13 6 0
8 8 12 6 0
8 8 11 6 0
8 8 10 6 0
8 8 9 5 0
8 8 8 2 82
8 9 15 2 32
8 9 14 5 8
8 9 13 6 8
8 9 12 6 8
8 9 11 6 8
8 9 10 5 0
8 9 9 7 0
8 9 8 2 76
8 10 16 2 48
8 10 15 5 64
8 10 10 5 32
8 10 9 7 72
8 11 20 3 48
8 11 19 3 80
8 11 16 5 32
8 11 15 5 8
8 11 14 5 24
8 11 13 5 24
8 11 12 5 24
8 11 11 5 24
8 11 10 7 72
8 12 20 3 32
8 12 19 3 64
8 12 16 5 96
8 12 7 3 50
8 12 6 3 90
8 13 20 3 40
8 13 19 3 0
8 13 18 3 80
8 13 16 5 104
8 13 8 3 48
8 13 7 3 72
8 14 19 3 32
8 14 18 3 64
8 14 11 9 48
8 14 10 3 16
8 14 9 3 16
8 14 8 0 64
8 15 19 3 40
8 15 18 3 0
8 15 17 3 80
8 15 15 9 48
8 15 14 9 16
8 15 13 9 16
8 15 12 9 16
8 15 11 9 0
8 15 10 9 0
8 15 9 9 0
8 15 8 9 0
8 15 7 3 80
8 16 18 3 32
8 16 17 3 0
8 16 16 3 16
8 16 15 9 0
8 16 14 9 0
8 16 13 9 0
8 16 12 9 0
8 16 11 9 0
8 16 10 9 0
8 16 9 9 0
8 16 8 9 0
8 16 7 8 66
8 17 18 3 40
8 17 17 3 0
8 17 16 9 0
8 17 15 9 0
8 17 14 9 0
8 17 13 9 0
8 17 12 9 0
8 17 11 9 0
8 17 10 9 0
8 17 9 9 0
8 17 8 9 0
8 17 7 10 74
8 18 17 3 32
8 18 16 9 0
8 18 15 9 0
8 18 14 9 0
8 18 13 9 0
8 18 12 9 0
8 18 11 9 0
8 18 10 9 0
8 18 9 9 0
8 18 8 11 64
8 19 17 3 32
8 19 16 9 0
8 19 15 9 0
8 19 14 9 0
8 19 13 9 0
8 19 12 9 0
8 19 11 9 0
8 19 10 9 0
8 19 9 9 0
8 19 8 9 64
8 20 17 3 32
8 20 16 3 0
8 20 15 3 0
8 20 14 3 0
8 20 13 3 0
8 20 12 3 0
8 20 11 3 0
8 20 10 3 0
8 20 9 9 0
8 20 8 9 64
8 21 17 3 32
8 21 16 3 0
8 21 15 3 0
8 21 14 3 0
8 21 13 3 0
8 21 12 3 0
8 21 11 3 0
8 21 10 3 0
8 21 9 9 0
8 21 8 9 64
8 22 17 3 32
8 22 16 3 0
8 22 15 3 0
8 22 14 3 0
8 22 13 3 0
8 22 12 3 0
8 22 11 3 0
8 22 10 3 0
8 22 9 3 0
8 22 8 3 0
8 22 7 3 88
8 23 17 3 40
8 23 16 3 0
8 23 15 3 0
8 23 14 3 0
8 23 13 3 0
8 23 12 3 0
8 23 11 3 0
8 23 10 3 0
8 23 9 3 0
8 23 8 3 72
8 24 16 3 40
8 24 15 3 0
8 24 14 3 0
8 24 13 3 0
8 24 12 3 0
8 24 11 3 0
8 24 10 3 8
8 24 9 3 76
8 25 15 3 40
8 25 14 3 8
8 25 13 3 8
8 25 12 3 8
8 25 11 3 72
9 1 14 4 48
9 1 13 4 16
9 1 12 4 16
9 1 11 4 16
9 1 10 4 16
9 1 9 4 16
9 1 8 4 80
9 2 17 5 114
9 2 15 4 48
9 2 14 1 0
9 2 13 1 0
9 2 12 1 0
9 2 11 1 0
9 2 10 1 0
9 2 9 1 0
9 2 8 4 0
9 2 7 4 80
9 3 17 5 96
9 3 15 4 32
9 3 14 1 0
9 3 13 1 0
9 3 12 1 0
9 3 11 1 0
9 3 10 1 0
9 3 9 1 0
9 3 8 0 0
9 3 7 4 72
9 4 17 5 32
9 4 16 5 16
9 4 15 6 0
9 4 14 6 0
9 4 13 6 0
9 4 12 6 0
9 4 11 6 0
9 4 10 6 0
9 4 9 1 0
9 4 8 6 64
9 5 17 5 32
9 5 16 5 0
9 5 15 6 0
9 5 14 6 0
9 5 13 6 0
9 5 12 6 0
9 5 11 6 0
9 5 10 6 0
9 5 9 1 0
9 5 8 6 72
9 6 17 5 40
9 6 16 6 0
9 6 15 6 0
9 6 14 6 0
9 6 13 6 0
9 6 12 6 0
9 6 11 6 0
9 6 10 6 0
9 6 9 7 64
9 7 16 5 40
9 7 15 6 0
9 7 14 6 0
9 7 13 6 0
9 7 12 6 0
9 7 11 6 0
9 7 10 6 0
9 7 9 7 64
9 8 15 5 32
9 8 14 6 0
9 8 13 6 0
9 8 12 6 0
9 8 11 6 0
9 8 10 6 0
9 8 9 7 64
9 9 15 5 32
9 9 14 5 8
9 9 13 6 8
9 9 12 6 8
9 9 11 6 8
9 9 10 5 0
9 9 9 5 0
9 9 8 2 90
9 10 16 2 48
9 10 15 5 64
9 10 10 5 32
9 10 9 2 72
9 11 20 3 48
9 11 19 3 80
9 11 16 5 32
9 11 15 5 8
9 11 14 5 24
9 11 13 5 24
9 11 12 5 24
9 11 11 5 24
9 11 10 7 72
9 12 20 3 32
9 12 19 3 64
9 12 16 5 96
9 13 20 3 40
9 13 19 3 0
9 13 18 3 80
9 13 16 5 104
9 13 8 3 48
9 13 7 3 82
9 14 19 3 32
9 14 18 3 64
9 14 11 9 48
9 14 10 3 16
9 14 9 3 16
9 14 8 3 0
9 14 7 3 70
9 15 19 3 40
9 15 18 3 0
9 15 17 3 80
9 15 15 9 48
9 15 14 9 16
9 15 13 9 16
9 15 12 9 16
9 15 11 9 0
9 15 10 9 0
9 15 9 9 0
9 15 8 9 0
9 15 7 3 74
9 16 18 3 32
9 16 17 3 0
9 16 16 3 16
9 16 15 9 0
9 16 14 9 0
9 16 13 9 0
9 16 12 9 0
9 16 11 9 0
9 16 10 9 0
9 16 9 9 0
9 16 8 9 64
9 17 18 3 40
9 17 17 3 0
9 17 16 9 0
9 17 15 9 0
9 17 14 9 0
9 17 13 9 0
9 17 12 9 0
9 17 11 9 0
9 17 10 9 0
9 17 9 9 0
9 17 8 9 64
9 18 17 3 32
9 18 16 9 0
9 18 15 9 0
9 18 14 9 0
9 18 13 9 0
9 18 12 9 0
9 18 11 9 0
9 18 10 9 0
9 18 9 9 0
9 18 8 9 64
9 19 17 3 32
9 19 16 9 0
9 19 15 9 0
9 19 14 9 0
9 19 13 9 0
9 19 12 9 0
9 19 11 9 0
9 19 10 9 0
9 19 9 9 0
9 19 8 0 64
9 20 17 3 32
9 20 16 3 0
9 20 15 3 0
9 20 14 3 0
9 20 13 3 0
9 20 12 3 0
9 20 11 3 0
9 20 10 3 0
9 20 9 9 0
9 20 8 9 64
9 21 17 3 32
9 21 16 3 0
9 21 15 3 0
9 21 14 3 0
9 21 13 3 0
9 21 12 3 0
9 21 11 3 0
9 21 10 3 0
9 21 9 9 0
9 21 8 3 0
9 21 7 3 86
9 22 17 3 32
9 22 16 3 0
9 22 15 3 0
9 22 14 3 0
9 22 13 3 0
9 22 12 3 0
9 22 11 3 0
9 22 10 3 0
9 22 9 3 0
9 22 8 3 0
9 22 7 3 72
9 23 17 3 40
9 23 16 3 0
9 23 15 3 0
9 23 14 3 0
9 23 13 3 0
9 23 12 3 0
9 23 11 3 0
9 23 10 3 0
9 23 9 3 0
9 23 8 3 72
9 24 16 3 40
9 24 15 3 0
9 24 14 3 0
9 24 13 3 0
9 24 12 3 0
9 24 11 3 0
9 24 10 3 8
9 24 9 3 72
9 25 15 3 40
9 25 14 3 8
9 25 13 3 8
9 25 12 3 8
9 25 11 3 72
10 1 14 4 48
10 1 13 4 16
10 1 12 4 16
10 1 11 4 16
10 1 10 4 16
10 1 9 4 16
10 1 8 4 80
10 2 15 4 48
10 2 14 1 0
10 2 13 1 0
10 2 12 1 0
10 2 11 1 0
10 2 10 1 0
10 2 9 1 0
10 2 8 4 0
10 2 7 4 80
10 3 17 5 114
10 3 15 4 32
10 3 14 1 0
10 3 13 1 0
10 3 12 1 0
10 3 11 1 0
10 3 10 1 0
10 3 9 1 0
10 3 8 0 0
10 3 7 4 72
10 4 17 5 34
10 4 16 5 16
10 4 15 6 0
10 4 14 6 0
10 4 13 6 0
10 4 12 6 0
10 4 11 6 0
10 4 10 1 0
10 4 9 1 0
10 4 8 6 64
10 5 17 5 34
10 5 16 5 0
10 5 15 6 0
10 5 14 6 0
10 5 13 6 0
10 5 12 6 0
10 5 11 6 0
10 5 10 1 0
10 5 9 1 0
10 5 8 6 72
10 6 17 5 42
10 6 16 5 0
10 6 15 6 0
10 6 14 6 0
10 6 13 6 0
10 6 12 6 0
10 6 11 6 0
10 6 10 6 0
10 6 9 7 64
10 7 16 5 40
10 7 15 6 0
10 7 14 6 0
10 7 13 6 0
10 7 12 6 0
10 7 11 6 0
10 7 10 6 0
10 7 9 6 0
10 7 8 5 92
10 8 15 5 32
10 8 14 6 0
10 8 13 6 0
10 8 12 6 0
10 8 11 6 0
10 8 10 6 0
10 8 9 5 64
10 9 15 5 32
10 9 14 5 0
10 9 13 6 0
10 9 12 6 0
10 9 11 6 0
10 9 10 5 0
10 9 9 5 64
10 10 16 5 48
10 10 15 5 0
10 10 14 5 4
10 10 13 5 4
10 10 12 5 4
10 10 11 5 4
10 10 10 5 0
10 10 9 2 72
10 11 20 3 48
10 11 19 3 80
10 11 16 5 32
10 11 15 2 8
10 11 14 2 8
10 11 13 2 8
10 11 12 2 8
10 11 11 2 8
10 11 10 2 72
10 12 20 3 32
10 12 19 3 64
10 12 16 5 96
10 13 20 3 40
10 13 19 3 0
10 13 18 3 80
10 13 16 5 104
10 13 8 3 114
10 14 19 3 32
10 14 18 3 64
10 14 11 9 50
10 14 10 3 16
10 14 9 3 16
10 14 8 3 66
10 15 19 3 40
10 15 18 3 0
10 15 17 3 80
10 15 15 9 48
10 15 14 9 16
10 15 13 9 16
10 15 12 9 16
10 15 11 9 0
10 15 10 9 0
10 15 9 9 0
10 15 8 9 64
10 16 18 3 32
10 16 17 3 0
10 16 16 3 18
10 16 15 9 0
10 16 14 9 0
10 16 13 9 0
10 16 12 9 0
10 16 11 9 0
10 16 10 9 0
10 16 9 9 0
10 16 8 9 64
10 17 18 3 40
10 17 17 3 0
10 17 16 3 2
10 17 15 9 0
10 17 14 9 0
10 17 13 9 0
10 17 12 9 0
10 17 11 9 0
10 17 10 9 0
10 17 9 9 0
10 17 8 0 64
10 18 17 3 32
10 18 16 9 0
10 18 15 9 0
10 18 14 9 0
10 18 13 9 0
10 18 12 9 0
10 18 11 9 0
10 18 10 9 0
10 18 9 9 0
10 18 8 9 64
10 19 17 3 32
10 19 16 9 0
10 19 15 9 0
10 19 14 9 0
10 19 13 9 0
10 19 12 9 0
10 19 11 9 0
10 19 10 9 0
10 19 9 9 0
10 19 8 0 64
10 20 17 3 32
10 20 16 3 0
10 20 15 3 0
10 20 14 3 0
10 20 13 3 0
10 20 12 3 0
10 20 11 3 0
10 20 10 9 0
10 20 9 9 0
10 20 8 9 64
10 21 17 3 32
10 21 16 3 0
10 21 15 3 0
10 21 14 3 0
10 21 13 3 0
10 21 12 3 0
10 21 11 3 0
10 21 10 9 0
10 21 9 9 0
10 21 8 9 64
10 22 17 3 32
10 22 16 3 0
10 22 15 3 0
10 22 14 3 0
10 22 13 3 0
10 22 12 3 0
10 22 11 3 0
10 22 10 3 0
10 22 9 3 0
10 22 8 3 0
10 22 7 3 88
10 23 17 3 40
10 23 16 3 0
10 23 15 3 0
10 23 14 3 0
10 23 13 3 0
10 23 12 3 0
10 23 11 3 0
10 23 10 3 0
10 23 9 3 0
10 23 8 3 72
10 24 16 3 40
10 24 15 3 0
10 24 14 3 0
10 24 13 3 0
10 24 12 3 0
10 24 11 3 0
10 24 10 3 8
10 24 9 3 72
10 25 15 3 42
10 25 14 3 10
10 25 13 3 10
10 25 12 3 10
10 25 11 3 74
11 1 14 4 50
11 1 13 4 18
11 1 12 4 18
11 1 11 4 18
11 1 10 4 18
11 1 9 4 18
11 1 8 4 82
11 2 15 4 48
11 2 14 1 0
11 2 13 1 0
11 2 12 1 0
11 2 11 1 0
11 2 10 4 0
11 2 9 4 0
11 2 8 4 0
11 2 7 4 82
11 3 15 4 32
11 3 14 1 0
11 3 13 1 0
11 3 12 1 0
11 3 11 1 0
11 3 10 1 0
11 3 9 1 0
11 3 8 0 0
11 3 7 4 74
11 4 16 5 50
11 4 15 6 0
11 4 14 6 0
11 4 13 6 0
11 4 12 6 0
11 4 11 6 0
11 4 10 1 0
11 4 9 6 2
11 4 8 6 66
11 5 16 5 34
11 5 15 6 0
11 5 14 6 0
11 5 13 6 0
11 5 12 6 0
11 5 11 6 0
11 5 10 1 0
11 5 9 5 2
11 5 8 5 66
11 6 16 5 34
11 6 15 6 0
11 6 14 6 0
11 6 13 6 0
11 6 12 5 0
11 6 11 5 0
11 6 10 5 0
11 6 9 5 2
11 6 8 5 70
11 7 16 5 42
11 7 15 6 0
11 7 14 6 0
11 7 13 6 0
11 7 12 6 0
11 7 11 6 0
11 7 10 6 0
11 7 9 5 2
11 7 8 5 74
11 8 15 5 34
11 8 14 5 2
11 8 13 5 2
11 8 12 5 2
11 8 11 5 2
11 8 10 5 2
11 8 9 5 66
11 9 15 5 34
11 9 14 5 2
11 9 13 5 2
11 9 12 5 2
11 9 11 5 2
11 9 10 5 2
11 9 9 5 66
11 10 16 5 50
11 10 15 5 2
11 10 14 5 2
11 10 13 5 2
11 10 12 5 2
11 10 11 5 2
11 10 10 5 2
11 10 9 5 66
11 11 20 3 48
11 11 19 3 80
11 11 16 5 32
11 11 15 2 8
11 11 14 2 8
11 11 13 2 8
11 11 12 2 8
11 11 11 2 8
11 11 10 2 8
11 11 9 2 78
11 12 20 3 32
11 12 19 3 64
11 12 16 5 96
11 13 20 3 40
11 13 19 3 0
11 13 18 3 80
11 13 16 5 104
11 14 19 3 32
11 14 18 3 64
11 14 10 3 50
11 14 9 3 82
11 15 19 3 40
11 15 18 3 0
11 15 17 3 80
11 15 15 9 50
11 15 14 9 18
11 15 13 9 18
11 15 12 9 18
11 15 11 3 16
11 15 10 3 0
11 15 9 3 0
11 15 8 9 82
11 16 18 3 32
11 16 17 3 64
11 16 15 9 32
11 16 14 9 0
11 16 13 9 0
11 16 12 9 0
11 16 11 9 0
11 16 10 9 0
11 16 9 9 0
11 16 8 9 64
11 17 18 3 40
11 17 17 3 64
11 17 15 9 32
11 17 14 9 0
11 17 13 9 0
11 17 12 9 0
11 17 11 9 0
11 17 10 9 0
11 17 9 9 0
11 17 8 9 64
11 18 17 3 32
11 18 16 3 16
11 18 15 9 0
11 18 14 9 0
11 18 13 9 0
11 18 12 9 0
11 18 11 9 0
11 18 10 9 0
11 18 9 9 0
11 18 8 9 64
11 19 17 3 34
11 19 16 9 0
11 19 15 9 0
11 19 14 9 0
11 19 13 9 0
11 19 12 9 0
11 19 11 9 0
11 19 10 9 0
11 19 9 9 0
11 19 8 0 64
11 20 17 3 34
11 20 16 3 0
11 20 15 3 0
11 20 14 3 0
11 20 13 3 0
11 20 12 3 0
11 20 11 3 0
11 20 10 9 0
11 20 9 9 0
11 20 8 9 64
11 21 17 3 34
11 21 16 3 0
11 21 15 3 0
11 21 14 3 0
11 21 13 3 0
11 21 12 3 0
11 21 11 3 0
11 21 10 9 0
11 21 9 9 0
11 21 8 9 64
11 22 17 3 34
11 22 16 3 0
11 22 15 3 0
11 22 14 3 0
11 22 13 3 0
11 22 12 3 0
11 22 11 3 0
11 22 10 3 0
11 22 9 3 0
11 22 8 3 0
11 22 7 3 88
11 23 17 3 42
11 23 16 3 0
11 23 15 3 0
11 23 14 3 0
11 23 13 3 0
11 23 12 3 0
11 23 11 3 0
11 23 10 3 0
11 23 9 3 0
11 23 8 3 74
11 24 16 3 42
11 24 15 3 10
11 24 14 3 10
11 24 13 3 10
11 24 12 3 10
11 24 11 3 10
11 24 10 3 10
11 24 9 3 74
12 2 15 4 50
12 2 14 4 18
12 2 13 4 18
12 2 12 4 18
12 2 11 4 18
12 2 10 4 18
12 2 9 4 18
12 2 8 4 82
12 3 15 4 34
12 3 14 4 2
12 3 13 4 2
12 3 12 4 2
12 3 11 4 2
12 3 10 4 2
12 3 9 4 10
12 3 8 4 74
12 4 15 5 34
12 4 14 5 2
12 4 13 5 2
12 4 12 5 2
12 4 11 5 2
12 4 10 5 66
12 5 15 5 34
12 5 14 5 2
12 5 13 5 2
12 5 12 5 2
12 5 11 5 2
12 5 10 5 66
12 6 15 5 34
12 6 14 5 2
12 6 13 5 2
12 6 12 5 2
12 6 11 5 2
12 6 10 5 66
12 7 15 5 42
12 7 14 5 10
12 7 13 5 10
12 7 12 5 10
12 7 11 5 10
12 7 10 5 74
12 11 20 3 50
12 11 19 3 82
12 11 16 5 50
12 11 15 5 18
12 11 14 5 18
12 11 13 5 18
12 11 12 5 18
12 11 11 5 18
12 11 10 5 82
12 12 20 3 34
12 12 19 3 66
12 12 16 5 34
12 12 15 5 6
12 12 14 5 6
12 12 13 5 6
12 12 12 5 14
12 12 11 5 14
12 12 10 5 78
12 13 20 3 42
12 13 19 3 2
12 13 18 3 82
12 13 16 5 42
12 13 15 5 14
12 13 14 5 14
12 13 13 5 78
12 14 19 3 34
12 14 18 3 66
12 15 19 3 42
12 15 18 3 2
12 15 17 3 82
12 15 11 3 50
12 15 10 3 18
12 15 9 3 82
12 16 18 3 34
12 16 17 3 66
12 16 15 9 50
12 16 14 9 18
12 16 13 9 18
12 16 12 9 18
12 16 11 3 0
12 16 10 3 0
12 16 9 9 2
12 16 8 9 82
12 17 18 3 42
12 17 17 3 66
12 17 15 9 34
12 17 14 9 2
12 17 13 9 2
12 17 12 9 2
12 17 11 3 0
12 17 10 3 0
12 17 9 9 2
12 17 8 9 66
12 18 17 3 42
12 18 16 3 18
12 18 15 9 2
12 18 14 9 0
12 18 13 9 0
12 18 12 9 2
12 18 11 3 0
12 18 10 3 0
12 18 9 9 2
12 18 8 9 66
12 19 16 3 34
12 19 15 3 2
12 19 14 9 0
12 19 13 9 0
12 19 12 9 2
12 19 11 3 0
12 19 10 3 0
12 19 9 3 2
12 19 8 9 66
12 20 16 3 34
12 20 15 3 2
12 20 14 3 2
12 20 13 3 2
12 20 12 3 2
12 20 11 3 0
12 20 10 3 0
12 20 9 3 2
12 20 8 3 66
12 21 16 3 34
12 21 15 3 2
12 21 14 3 0
12 21 13 3 0
12 21 12 3 0
12 21 11 3 0
12 21 10 3 0
12 21 9 3 0
12 21 8 3 64
12 22 16 3 34
12 22 15 3 2
12 22 14 3 0
12 22 13 3 0
12 22 12 3 0
12 22 11 3 0
12 22 10 3 0
12 22 9 3 0
12 22 8 3 8
12 22 7 3 90
12 23 16 3 42
12 23 15 3 10
12 23 14 3 10
12 23 13 3 10
12 23 12 3 10
12 23 11 3 10
12 23 10 3 10
12 23 9 3 74
13 16 11 3 50
13 16 10 3 82
13 17 11 3 34
13 17 10 3 66
13 18 14 9 48
13 18 13 9 82
13 18 11 3 34
13 18 10 3 66
13 19 14 9 40
13 19 13 9 72
13 19 11 3 34
13 19 10 3 66
13 20 11 3 34
13 20 10 3 66
13 21 14 3 50
13 21 13 3 18
13 21 12 3 18
13 21 11 3 2
13 21 10 3 2
13 21 9 3 18
13 21 8 3 82
13 22 14 3 42
13 22 13 3 10
13 22 12 3 10
13 22 11 3 10
13 22 10 3 10
13 22 9 3 10
13 22 8 3 74
14 18 14 9 114
14 19 14 9 42
14 19 13 9 90
