Qubicle Exchange Format
Version 0.2
www.minddesk.com
11 11 11
5
0.266667 0.156863 0.000000
0.368627 0.160784 0.121569
0.490196 0.352941 0.172549
0.525490 0.349020 0.113725
0.682353 0.466667 0.019608
1 1 9 2 52
1 1 8 0 20
1 1 7 0 20
1 1 6 0 20
1 1 5 0 20
1 1 4 0 20
1 1 3 0 20
1 1 2 0 20
1 1 1 0 20
1 1 0 2 84
1 2 9 0 36
1 2 8 2 4
1 2 7 0 12
1 2 6 0 12
1 2 5 0 12
1 2 4 0 12
1 2 3 0 12
1 2 2 0 12
1 2 1 2 4
1 2 0 0 68
1 3 9 0 36
1 3 8 0 68
1 3 1 0 36
1 3 0 0 68
1 4 9 0 36
1 4 8 0 68
1 4 1 0 36
1 4 0 0 68
1 5 9 0 36
1 5 8 0 68
1 5 1 0 36
1 5 0 0 68
1 6 9 0 36
1 6 8 0 68
1 6 1 0 36
1 6 0 0 68
1 7 9 0 36
1 7 8 0 68
1 7 1 0 36
1 7 0 0 68
1 8 9 0 36
1 8 8 0 68
1 8 1 0 36
1 8 0 0 68
1 9 9 0 36
1 9 8 2 4
1 9 7 0 20
1 9 6 0 20
1 9 5 0 20
1 9 4 0 20
1 9 3 0 20
1 9 2 0 20
1 9 1 2 4
1 9 0 0 68
1 10 9 2 44
1 10 8 0 12
1 10 7 0 12
1 10 6 0 12
1 10 5 0 12
1 10 4 0 12
1 10 3 0 12
1 10 2 0 12
1 10 1 0 12
1 10 0 2 76
2 1 9 0 48
2 1 8 2 16
2 1 7 0 18
2 1 6 0 18
2 1 5 0 18
2 1 4 0 18
2 1 3 0 18
2 1 2 0 18
2 1 1 2 16
2 1 0 0 80
2 2 9 2 32
2 2 8 0 0
2 2 7 0 0
2 2 6 0 0
2 2 5 0 0
2 2 4 0 0
2 2 3 0 0
2 2 2 0 0
2 2 1 0 0
2 2 0 2 64
2 3 9 0 34
2 3 8 4 0
2 3 7 3 4
2 3 6 3 4
2 3 5 3 4
2 3 4 3 4
2 3 3 3 4
2 3 2 3 4
2 3 1 4 0
2 3 0 0 66
2 4 9 0 34
2 4 8 4 0
2 4 7 3 4
2 4 6 3 4
2 4 5 3 4
2 4 4 3 4
2 4 3 3 4
2 4 2 3 4
2 4 1 4 0
2 4 0 0 66
2 5 9 0 34
2 5 8 4 0
2 5 7 3 4
2 5 6 3 4
2 5 5 3 4
2 5 4 3 4
2 5 3 3 4
2 5 2 4 4
2 5 1 4 0
2 5 0 0 66
2 6 9 0 34
2 6 8 4 0
2 6 7 3 4
2 6 6 3 4
2 6 5 3 4
2 6 4 3 4
2 6 3 3 4
2 6 2 3 4
2 6 1 4 0
2 6 0 0 66
2 7 9 0 34
2 7 8 4 0
2 7 7 1 4
2 7 6 3 4
2 7 5 3 4
2 7 4 3 4
2 7 3 3 4
2 7 2 3 4
2 7 1 4 0
2 7 0 0 66
2 8 9 0 34
2 8 8 4 0
2 8 7 3 4
2 8 6 3 4
2 8 5 3 4
2 8 4 3 4
2 8 3 3 4
2 8 2 3 4
2 8 1 4 0
2 8 0 0 66
2 9 9 2 32
2 9 8 0 0
2 9 7 0 0
2 9 6 0 0
2 9 5 0 0
2 9 4 0 0
2 9 3 0 0
2 9 2 0 0
2 9 1 0 0
2 9 0 2 64
2 10 9 0 40
2 10 8 2 8
2 10 7 0 10
2 10 6 0 10
2 10 5 0 10
2 10 4 0 10
2 10 3 0 10
2 10 2 0 10
2 10 1 2 8
2 10 0 0 72
3 1 9 0 48
3 1 8 0 80
3 1 1 0 48
3 1 0 0 80
3 2 9 0 40
3 2 8 0 0
3 2 7 3 16
3 2 6 1 16
3 2 5 3 16
3 2 4 1 16
3 2 3 3 16
3 2 2 1 16
3 2 1 0 0
3 2 0 0 72
3 3 8 3 32
3 3 7 4 0
3 3 6 4 0
3 3 5 4 0
3 3 4 4 0
3 3 3 4 0
3 3 2 4 0
3 3 1 3 64
3 4 8 3 32
3 4 7 4 0
3 4 6 4 0
3 4 5 4 0
3 4 4 4 0
3 4 3 4 0
3 4 2 4 0
3 4 1 3 64
3 5 8 3 32
3 5 7 4 0
3 5 6 4 0
3 5 5 4 0
3 5 4 4 0
3 5 3 4 0
3 5 2 4 0
3 5 1 3 64
3 6 8 3 32
3 6 7 4 0
3 6 6 4 0
3 6 5 4 0
3 6 4 4 0
3 6 3 4 0
3 6 2 4 0
3 6 1 3 64
3 7 8 3 32
3 7 7 4 0
3 7 6 4 0
3 7 5 4 0
3 7 4 4 0
3 7 3 4 0
3 7 2 4 0
3 7 1 3 64
3 8 8 1 32
3 8 7 4 0
3 8 6 4 0
3 8 5 4 0
3 8 4 4 0
3 8 3 4 0
3 8 2 4 0
3 8 1 3 64
3 9 9 0 48
3 9 8 0 0
3 9 7 3 8
3 9 6 1 8
3 9 5 3 8
3 9 4 3 8
3 9 3 3 8
3 9 2 1 8
3 9 1 0 0
3 9 0 0 80
3 10 9 0 40
3 10 8 0 72
3 10 1 0 40
3 10 0 0 72
4 1 9 0 48
4 1 8 0 80
4 1 1 0 48
4 1 0 0 80
4 2 9 0 40
4 2 8 0 0
4 2 7 3 16
4 2 6 3 16
4 2 5 3 16
4 2 4 3 16
4 2 3 3 16
4 2 2 3 16
4 2 1 0 0
4 2 0 0 72
4 3 8 3 32
4 3 7 4 0
4 3 6 4 0
4 3 5 4 0
4 3 4 4 0
4 3 3 4 0
4 3 2 4 0
4 3 1 3 64
4 4 8 1 32
4 4 7 4 0
4 4 6 4 0
4 4 5 4 0
4 4 4 4 0
4 4 3 4 0
4 4 2 4 0
4 4 1 3 64
4 5 8 3 32
4 5 7 4 0
4 5 6 4 0
4 5 5 4 0
4 5 4 4 0
4 5 3 4 0
4 5 2 4 0
4 5 1 3 64
4 6 8 3 32
4 6 7 4 0
4 6 6 4 0
4 6 5 4 0
4 6 4 4 0
4 6 3 4 0
4 6 2 4 0
4 6 1 3 64
4 7 8 3 32
4 7 7 4 0
4 7 6 4 0
4 7 5 4 0
4 7 4 4 0
4 7 3 4 0
4 7 2 4 0
4 7 1 3 64
4 8 8 3 32
4 8 7 4 0
4 8 6 4 0
4 8 5 4 0
4 8 4 4 0
4 8 3 4 0
4 8 2 4 0
4 8 1 3 64
4 9 9 2 48
4 9 8 0 0
4 9 7 3 8
4 9 6 3 8
4 9 5 3 8
4 9 4 3 8
4 9 3 3 8
4 9 2 3 8
4 9 1 0 0
4 9 0 0 80
4 10 9 0 40
4 10 8 0 72
4 10 1 0 40
4 10 0 0 72
5 1 9 0 48
5 1 8 0 80
5 1 1 0 48
5 1 0 0 80
5 2 9 0 40
5 2 8 0 0
5 2 7 3 16
5 2 6 3 16
5 2 5 3 16
5 2 4 1 16
5 2 3 3 16
5 2 2 3 16
5 2 1 0 0
5 2 0 0 72
5 3 8 3 32
5 3 7 4 0
5 3 6 4 0
5 3 5 4 0
5 3 4 4 0
5 3 3 4 0
5 3 2 4 0
5 3 1 3 64
5 4 8 3 32
5 4 7 4 0
5 4 6 4 0
5 4 5 4 0
5 4 4 4 0
5 4 3 4 0
5 4 2 4 0
5 4 1 3 64
5 5 8 3 32
5 5 7 4 0
5 5 6 4 0
5 5 5 4 0
5 5 4 4 0
5 5 3 4 0
5 5 2 4 0
5 5 1 3 64
5 6 8 1 32
5 6 7 4 0
5 6 6 4 0
5 6 5 4 0
5 6 4 4 0
5 6 3 4 0
5 6 2 4 0
5 6 1 3 64
5 7 8 3 32
5 7 7 4 0
5 7 6 4 0
5 7 5 4 0
5 7 4 4 0
5 7 3 4 0
5 7 2 4 0
5 7 1 3 64
5 8 8 3 32
5 8 7 4 0
5 8 6 4 0
5 8 5 4 0
5 8 4 4 0
5 8 3 4 0
5 8 2 4 0
5 8 1 3 64
5 9 9 2 48
5 9 8 0 0
5 9 7 1 8
5 9 6 3 8
5 9 5 3 8
5 9 4 3 8
5 9 3 3 8
5 9 2 1 8
5 9 1 0 0
5 9 0 0 80
5 10 9 0 40
5 10 8 0 72
5 10 1 0 40
5 10 0 0 72
6 1 9 0 48
6 1 8 0 80
6 1 1 0 48
6 1 0 0 80
6 2 9 0 40
6 2 8 0 0
6 2 7 3 16
6 2 6 3 16
6 2 5 3 16
6 2 4 3 16
6 2 3 3 16
6 2 2 4 16
6 2 1 0 0
6 2 0 0 72
6 3 8 3 32
6 3 7 4 0
6 3 6 4 0
6 3 5 4 0
6 3 4 4 0
6 3 3 4 0
6 3 2 4 0
6 3 1 3 64
6 4 8 3 32
6 4 7 4 0
6 4 6 4 0
6 4 5 4 0
6 4 4 4 0
6 4 3 4 0
6 4 2 4 0
6 4 1 3 64
6 5 8 3 32
6 5 7 4 0
6 5 6 4 0
6 5 5 4 0
6 5 4 4 0
6 5 3 4 0
6 5 2 4 0
6 5 1 3 64
6 6 8 3 32
6 6 7 4 0
6 6 6 4 0
6 6 5 4 0
6 6 4 4 0
6 6 3 4 0
6 6 2 4 0
6 6 1 3 64
6 7 8 3 32
6 7 7 4 0
6 7 6 4 0
6 7 5 4 0
6 7 4 4 0
6 7 3 4 0
6 7 2 4 0
6 7 1 3 64
6 8 8 3 32
6 8 7 4 0
6 8 6 4 0
6 8 5 4 0
6 8 4 4 0
6 8 3 4 0
6 8 2 4 0
6 8 1 3 64
6 9 9 0 48
6 9 8 0 0
6 9 7 3 8
6 9 6 3 8
6 9 5 3 8
6 9 4 3 8
6 9 3 3 8
6 9 2 3 8
6 9 1 0 0
6 9 0 0 80
6 10 9 0 40
6 10 8 0 72
6 10 1 0 40
6 10 0 0 72
7 1 9 0 48
7 1 8 0 80
7 1 1 0 48
7 1 0 0 80
7 2 9 0 40
7 2 8 0 0
7 2 7 3 16
7 2 6 3 16
7 2 5 3 16
7 2 4 3 16
7 2 3 3 16
7 2 2 1 16
7 2 1 0 0
7 2 0 0 72
7 3 8 3 32
7 3 7 4 0
7 3 6 4 0
7 3 5 4 0
7 3 4 4 0
7 3 3 4 0
7 3 2 4 0
7 3 1 3 64
7 4 8 3 32
7 4 7 4 0
7 4 6 4 0
7 4 5 4 0
7 4 4 4 0
7 4 3 4 0
7 4 2 4 0
7 4 1 3 64
7 5 8 3 32
7 5 7 4 0
7 5 6 4 0
7 5 5 4 0
7 5 4 4 0
7 5 3 4 0
7 5 2 4 0
7 5 1 3 64
7 6 8 3 32
7 6 7 4 0
7 6 6 4 0
7 6 5 4 0
7 6 4 4 0
7 6 3 4 0
7 6 2 4 0
7 6 1 3 64
7 7 8 3 32
7 7 7 4 0
7 7 6 4 0
7 7 5 4 0
7 7 4 4 0
7 7 3 4 0
7 7 2 4 0
7 7 1 3 64
7 8 8 3 32
7 8 7 4 0
7 8 6 4 0
7 8 5 4 0
7 8 4 4 0
7 8 3 4 0
7 8 2 4 0
7 8 1 3 64
7 9 9 0 48
7 9 8 0 0
7 9 7 3 8
7 9 6 1 8
7 9 5 3 8
7 9 4 3 8
7 9 3 3 8
7 9 2 3 8
7 9 1 0 0
7 9 0 0 80
7 10 9 0 40
7 10 8 0 72
7 10 1 0 40
7 10 0 0 72
8 1 9 0 48
8 1 8 0 80
8 1 1 0 48
8 1 0 0 80
8 2 9 0 40
8 2 8 0 0
8 2 7 3 16
8 2 6 3 16
8 2 5 3 16
8 2 4 3 16
8 2 3 3 16
8 2 2 3 16
8 2 1 0 0
8 2 0 0 72
8 3 8 3 32
8 3 7 4 0
8 3 6 4 0
8 3 5 4 0
8 3 4 4 0
8 3 3 4 0
8 3 2 4 0
8 3 1 3 64
8 4 8 3 32
8 4 7 4 0
8 4 6 4 0
8 4 5 4 0
8 4 4 4 0
8 4 3 4 0
8 4 2 4 0
8 4 1 3 64
8 5 8 3 32
8 5 7 4 0
8 5 6 4 0
8 5 5 4 0
8 5 4 4 0
8 5 3 4 0
8 5 2 4 0
8 5 1 3 64
8 6 8 3 32
8 6 7 4 0
8 6 6 4 0
8 6 5 4 0
8 6 4 4 0
8 6 3 4 0
8 6 2 4 0
8 6 1 3 64
8 7 8 3 32
8 7 7 4 0
8 7 6 4 0
8 7 5 4 0
8 7 4 4 0
8 7 3 4 0
8 7 2 4 0
8 7 1 3 64
8 8 8 1 32
8 8 7 4 0
8 8 6 4 0
8 8 5 4 0
8 8 4 4 0
8 8 3 4 0
8 8 2 4 0
8 8 1 3 64
8 9 9 0 48
8 9 8 0 0
8 9 7 3 8
8 9 6 3 8
8 9 5 3 8
8 9 4 3 8
8 9 3 3 8
8 9 2 3 8
8 9 1 0 0
8 9 0 0 80
8 10 9 0 40
8 10 8 0 72
8 10 1 0 40
8 10 0 0 72
9 1 9 0 48
9 1 8 2 16
9 1 7 0 20
9 1 6 0 20
9 1 5 0 20
9 1 4 0 20
9 1 3 0 20
9 1 2 0 20
9 1 1 2 16
9 1 0 0 80
9 2 9 2 32
9 2 8 0 0
9 2 7 0 0
9 2 6 0 0
9 2 5 0 0
9 2 4 0 0
9 2 3 0 0
9 2 2 0 0
9 2 1 0 0
9 2 0 2 64
9 3 9 0 36
9 3 8 4 0
9 3 7 3 2
9 3 6 3 2
9 3 5 3 2
9 3 4 3 2
9 3 3 3 2
9 3 2 3 2
9 3 1 4 0
9 3 0 0 68
9 4 9 0 36
9 4 8 4 0
9 4 7 3 2
9 4 6 3 2
9 4 5 3 2
9 4 4 3 2
9 4 3 3 2
9 4 2 3 2
9 4 1 4 0
9 4 0 0 68
9 5 9 0 36
9 5 8 4 0
9 5 7 3 2
9 5 6 3 2
9 5 5 3 2
9 5 4 3 2
9 5 3 3 2
9 5 2 3 2
9 5 1 4 0
9 5 0 0 68
9 6 9 0 36
9 6 8 4 0
9 6 7 3 2
9 6 6 3 2
9 6 5 3 2
9 6 4 3 2
9 6 3 3 2
9 6 2 3 2
9 6 1 4 0
9 6 0 0 68
9 7 9 0 36
9 7 8 4 0
9 7 7 1 2
9 7 6 3 2
9 7 5 3 2
9 7 4 3 2
9 7 3 3 2
9 7 2 3 2
9 7 1 4 0
9 7 0 0 68
9 8 9 0 36
9 8 8 4 0
9 8 7 3 2
9 8 6 3 2
9 8 5 3 2
9 8 4 3 2
9 8 3 3 2
9 8 2 3 2
9 8 1 4 0
9 8 0 0 68
9 9 9 2 32
9 9 8 0 0
9 9 7 0 0
9 9 6 0 0
9 9 5 0 0
9 9 4 0 0
9 9 3 0 0
9 9 2 0 0
9 9 1 0 0
9 9 0 2 64
9 10 9 0 40
9 10 8 2 8
9 10 7 0 12
9 10 6 0 12
9 10 5 0 12
9 10 4 0 12
9 10 3 0 12
9 10 2 0 12
9 10 1 2 8
9 10 0 0 72
10 1 9 2 50
10 1 8 0 18
10 1 7 0 18
10 1 6 0 18
10 1 5 0 18
10 1 4 0 18
10 1 3 0 18
10 1 2 0 18
10 1 1 0 18
10 1 0 2 82
10 2 9 0 34
10 2 8 2 2
10 2 7 0 10
10 2 6 0 10
10 2 5 0 10
10 2 4 0 10
10 2 3 0 10
10 2 2 0 10
10 2 1 2 2
10 2 0 0 66
10 3 9 0 34
10 3 8 0 66
10 3 1 0 34
10 3 0 0 66
10 4 9 0 34
10 4 8 0 66
10 4 1 0 34
10 4 0 0 66
10 5 9 0 34
10 5 8 0 66
10 5 1 0 34
10 5 0 0 66
10 6 9 0 34
10 6 8 0 66
10 6 1 0 34
10 6 0 0 66
10 7 9 0 34
10 7 8 0 66
10 7 1 0 34
10 7 0 0 66
10 8 9 0 34
10 8 8 0 66
10 8 1 0 34
10 8 0 0 66
10 9 9 0 34
10 9 8 2 2
10 9 7 0 18
10 9 6 0 18
10 9 5 0 18
10 9 4 0 18
10 9 3 0 18
10 9 2 0 18
10 9 1 2 2
10 9 0 0 66
10 10 9 2 42
10 10 8 0 10
10 10 7 0 10
10 10 6 0 10
10 10 5 0 10
10 10 4 0 10
10 10 3 0 10
10 10 2 0 10
10 10 1 0 10
10 10 0 2 74
