Qubicle Exchange Format
Version 0.2
www.minddesk.com
48 72 80
20
0.000000 0.000000 0.000000
0.188235 0.192157 0.196078
0.266667 0.156863 0.000000
0.313725 0.266667 0.223529
0.349020 0.129412 0.101961
0.356863 0.274510 0.160784
0.368627 0.160784 0.121569
0.376471 0.274510 0.141176
0.376471 0.384314 0.392157
0.439216 0.337255 0.203922
0.443137 0.349020 0.215686
0.478431 0.380392 0.250980
0.490196 0.352941 0.172549
0.501961 0.254902 0.215686
0.501961 0.352941 0.211765
0.525490 0.349020 0.113725
0.525490 0.403922 0.156863
0.894118 0.200000 0.203922
0.921569 0.282353 0.156863
1.000000 1.000000 1.000000
6 9 53 2 52
6 9 52 2 20
6 9 51 2 20
6 9 50 2 20
6 9 49 2 20
6 9 48 2 20
6 9 47 2 20
6 9 46 2 28
6 9 45 2 28
6 9 44 2 20
6 9 43 2 20
6 9 42 2 20
6 9 41 2 20
6 9 40 2 28
6 9 39 2 28
6 9 38 2 20
6 9 37 2 20
6 9 36 2 20
6 9 35 2 20
6 9 34 2 28
6 9 33 2 28
6 9 32 2 84
6 10 53 2 36
6 10 52 2 4
6 10 51 2 4
6 10 50 2 4
6 10 49 2 4
6 10 48 2 4
6 10 47 2 68
6 10 44 2 36
6 10 43 2 4
6 10 42 2 4
6 10 41 2 68
6 10 38 2 36
6 10 37 2 4
6 10 36 2 4
6 10 35 2 68
6 10 32 2 100
6 11 53 2 36
6 11 52 2 4
6 11 51 2 4
6 11 50 2 4
6 11 49 2 4
6 11 48 2 4
6 11 47 2 68
6 11 44 2 36
6 11 43 2 4
6 11 42 2 4
6 11 41 2 68
6 11 38 2 36
6 11 37 2 4
6 11 36 2 4
6 11 35 2 68
6 11 32 2 100
6 12 54 2 52
6 12 53 2 4
6 12 52 2 4
6 12 51 2 4
6 12 50 2 4
6 12 49 2 4
6 12 48 2 4
6 12 47 2 68
6 12 44 2 36
6 12 43 2 4
6 12 42 2 4
6 12 41 2 68
6 12 38 2 36
6 12 37 2 4
6 12 36 2 4
6 12 35 2 68
6 12 32 2 100
6 13 54 2 36
6 13 53 2 4
6 13 52 2 4
6 13 51 2 4
6 13 50 2 4
6 13 49 2 4
6 13 48 2 4
6 13 47 2 4
6 13 46 2 20
6 13 45 2 20
6 13 44 2 4
6 13 43 2 4
6 13 42 2 4
6 13 41 2 4
6 13 40 2 20
6 13 39 2 20
6 13 38 2 4
6 13 37 2 4
6 13 36 2 4
6 13 35 2 4
6 13 34 2 20
6 13 33 2 20
6 13 32 2 4
6 13 31 2 84
6 14 54 2 36
6 14 53 2 4
6 14 52 2 4
6 14 51 2 4
6 14 50 2 4
6 14 49 2 4
6 14 48 2 4
6 14 47 2 4
6 14 46 2 4
6 14 45 2 4
6 14 44 2 4
6 14 43 2 4
6 14 42 2 4
6 14 41 2 4
6 14 40 2 4
6 14 39 2 4
6 14 38 2 4
6 14 37 2 4
6 14 36 2 4
6 14 35 2 4
6 14 34 2 4
6 14 33 2 4
6 14 32 2 4
6 14 31 2 68
6 15 54 1 44
6 15 53 1 12
6 15 52 1 12
6 15 51 1 12
6 15 50 1 4
6 15 49 1 12
6 15 48 1 12
6 15 47 1 12
6 15 46 1 4
6 15 45 1 12
6 15 44 1 12
6 15 43 1 12
6 15 42 1 4
6 15 41 1 12
6 15 40 1 12
6 15 39 1 12
6 15 38 1 4
6 15 37 1 12
6 15 36 1 12
6 15 35 1 12
6 15 34 1 4
6 15 33 1 12
6 15 32 1 12
6 15 31 1 12
6 15 30 1 92
6 16 50 7 100
6 16 46 7 100
6 16 42 7 100
6 16 38 7 100
6 16 34 7 100
6 17 50 7 100
6 17 46 7 100
6 17 42 7 100
6 17 38 7 100
6 17 34 7 100
6 18 50 7 108
6 18 46 7 108
6 18 42 7 108
6 18 38 7 108
6 18 34 7 108
7 9 53 2 48
7 9 52 2 16
7 9 51 2 16
7 9 50 2 16
7 9 49 2 16
7 9 48 2 16
7 9 47 2 16
7 9 46 2 24
7 9 45 2 24
7 9 44 2 16
7 9 43 2 16
7 9 42 2 16
7 9 41 2 16
7 9 40 2 24
7 9 39 2 24
7 9 38 2 16
7 9 37 2 16
7 9 36 2 16
7 9 35 2 16
7 9 34 2 24
7 9 33 2 24
7 9 32 2 80
7 10 53 2 32
7 10 52 2 0
7 10 51 2 0
7 10 50 2 0
7 10 49 2 0
7 10 48 2 0
7 10 47 2 64
7 10 44 2 32
7 10 43 2 0
7 10 42 2 0
7 10 41 2 64
7 10 38 2 32
7 10 37 2 0
7 10 36 2 0
7 10 35 2 64
7 10 32 2 96
7 11 53 2 32
7 11 52 2 0
7 11 51 2 0
7 11 50 2 0
7 11 49 2 0
7 11 48 2 0
7 11 47 2 64
7 11 44 2 32
7 11 43 2 0
7 11 42 2 0
7 11 41 2 64
7 11 38 2 32
7 11 37 2 0
7 11 36 2 0
7 11 35 2 64
7 11 32 2 96
7 12 54 2 48
7 12 53 2 0
7 12 52 2 0
7 12 51 2 0
7 12 50 2 0
7 12 49 2 0
7 12 48 2 0
7 12 47 2 64
7 12 44 2 32
7 12 43 2 0
7 12 42 2 0
7 12 41 2 64
7 12 38 2 32
7 12 37 2 0
7 12 36 2 0
7 12 35 2 64
7 12 32 2 96
7 13 54 2 32
7 13 53 2 0
7 13 52 2 0
7 13 51 2 0
7 13 50 2 0
7 13 49 2 0
7 13 48 2 0
7 13 47 2 0
7 13 46 2 16
7 13 45 2 16
7 13 44 2 0
7 13 43 2 0
7 13 42 2 0
7 13 41 2 0
7 13 40 2 16
7 13 39 2 16
7 13 38 2 0
7 13 37 2 0
7 13 36 2 0
7 13 35 2 0
7 13 34 2 16
7 13 33 2 16
7 13 32 2 0
7 13 31 2 80
7 14 54 2 32
7 14 53 2 0
7 14 52 2 0
7 14 51 2 0
7 14 50 2 0
7 14 49 2 0
7 14 48 2 0
7 14 47 2 0
7 14 46 2 0
7 14 45 2 0
7 14 44 2 0
7 14 43 2 0
7 14 42 2 0
7 14 41 2 0
7 14 40 2 0
7 14 39 2 0
7 14 38 2 0
7 14 37 2 0
7 14 36 2 0
7 14 35 2 0
7 14 34 2 0
7 14 33 2 0
7 14 32 2 0
7 14 31 2 64
7 15 54 1 40
7 15 53 1 8
7 15 52 1 8
7 15 51 1 8
7 15 50 1 0
7 15 49 1 8
7 15 48 1 8
7 15 47 1 8
7 15 46 1 0
7 15 45 1 8
7 15 44 1 8
7 15 43 1 8
7 15 42 1 0
7 15 41 1 8
7 15 40 1 8
7 15 39 1 8
7 15 38 1 0
7 15 37 1 8
7 15 36 1 8
7 15 35 1 8
7 15 34 1 0
7 15 33 1 8
7 15 32 1 8
7 15 31 1 8
7 15 30 1 88
7 16 50 7 96
7 16 46 7 96
7 16 42 7 96
7 16 38 7 96
7 16 34 7 96
7 17 50 7 96
7 17 46 7 96
7 17 42 7 96
7 17 38 7 96
7 17 34 7 96
7 18 50 7 104
7 18 46 7 104
7 18 42 7 104
7 18 38 7 104
7 18 34 7 104
8 7 56 2 52
8 7 55 2 20
8 7 54 2 20
8 7 53 2 20
8 7 52 2 20
8 7 51 2 20
8 7 50 2 20
8 7 49 2 20
8 7 48 2 20
8 7 47 2 20
8 7 46 2 20
8 7 45 2 20
8 7 44 2 20
8 7 43 2 20
8 7 42 2 20
8 7 41 2 20
8 7 40 2 20
8 7 39 2 20
8 7 38 2 20
8 7 37 2 20
8 7 36 2 20
8 7 35 2 20
8 7 34 2 20
8 7 33 2 20
8 7 32 2 20
8 7 31 2 20
8 7 30 2 20
8 7 29 2 84
8 8 56 2 36
8 8 55 2 4
8 8 54 2 4
8 8 53 2 4
8 8 52 2 4
8 8 51 2 4
8 8 50 2 4
8 8 49 2 4
8 8 48 2 4
8 8 47 2 4
8 8 46 2 4
8 8 45 2 4
8 8 44 2 4
8 8 43 2 4
8 8 42 2 4
8 8 41 2 4
8 8 40 2 4
8 8 39 2 4
8 8 38 2 4
8 8 37 2 4
8 8 36 2 4
8 8 35 2 4
8 8 34 2 4
8 8 33 2 4
8 8 32 2 4
8 8 31 2 4
8 8 30 2 4
8 8 29 2 68
8 9 56 2 36
8 9 55 2 4
8 9 54 2 4
8 9 53 2 0
8 9 52 2 0
8 9 51 2 0
8 9 50 2 0
8 9 49 2 0
8 9 48 2 0
8 9 47 2 0
8 9 46 0 8
8 9 45 0 8
8 9 44 2 0
8 9 43 2 0
8 9 42 2 0
8 9 41 2 0
8 9 40 0 8
8 9 39 0 8
8 9 38 2 0
8 9 37 2 0
8 9 36 2 0
8 9 35 2 0
8 9 34 0 8
8 9 33 0 8
8 9 32 2 0
8 9 31 2 4
8 9 30 2 4
8 9 29 2 4
8 9 28 2 84
8 10 56 2 36
8 10 55 2 4
8 10 54 2 4
8 10 53 2 0
8 10 52 2 0
8 10 51 2 0
8 10 50 2 0
8 10 49 2 0
8 10 48 2 0
8 10 47 0 64
8 10 44 0 32
8 10 43 2 0
8 10 42 2 0
8 10 41 0 64
8 10 38 2 32
8 10 37 2 0
8 10 36 2 0
8 10 35 0 64
8 10 32 2 32
8 10 31 2 4
8 10 30 2 4
8 10 29 2 4
8 10 28 2 4
8 10 27 2 84
8 11 56 2 36
8 11 55 2 4
8 11 54 2 4
8 11 53 2 0
8 11 52 2 0
8 11 51 2 0
8 11 50 2 0
8 11 49 2 0
8 11 48 2 0
8 11 47 0 64
8 11 44 0 32
8 11 43 2 0
8 11 42 2 0
8 11 41 0 64
8 11 38 2 32
8 11 37 2 0
8 11 36 2 0
8 11 35 0 64
8 11 32 2 32
8 11 31 2 4
8 11 30 2 4
8 11 29 2 4
8 11 28 2 4
8 11 27 2 68
8 12 56 2 36
8 12 55 2 4
8 12 54 2 0
8 12 53 2 0
8 12 52 2 0
8 12 51 2 0
8 12 50 2 0
8 12 49 2 0
8 12 48 2 0
8 12 47 0 64
8 12 44 0 32
8 12 43 2 0
8 12 42 2 0
8 12 41 0 64
8 12 38 2 32
8 12 37 2 0
8 12 36 2 0
8 12 35 0 64
8 12 32 2 32
8 12 31 2 4
8 12 30 2 4
8 12 29 2 4
8 12 28 2 4
8 12 27 2 4
8 12 26 2 84
8 13 56 2 36
8 13 55 2 4
8 13 54 2 0
8 13 53 2 0
8 13 52 2 0
8 13 51 2 0
8 13 50 1 0
8 13 49 1 0
8 13 48 1 0
8 13 47 1 0
8 13 46 0 16
8 13 45 0 16
8 13 44 1 0
8 13 43 1 0
8 13 42 1 0
8 13 41 1 0
8 13 40 0 16
8 13 39 0 16
8 13 38 1 0
8 13 37 1 0
8 13 36 1 0
8 13 35 1 0
8 13 34 0 16
8 13 33 0 16
8 13 32 1 0
8 13 31 1 0
8 13 30 2 4
8 13 29 2 4
8 13 28 2 4
8 13 27 2 4
8 13 26 2 4
8 13 25 2 20
8 13 24 2 84
8 14 56 2 36
8 14 55 2 4
8 14 54 2 0
8 14 53 2 0
8 14 52 2 0
8 14 51 2 0
8 14 50 1 0
8 14 49 1 0
8 14 48 1 0
8 14 47 1 0
8 14 46 0 0
8 14 45 0 0
8 14 44 1 0
8 14 43 1 0
8 14 42 1 0
8 14 41 1 0
8 14 40 0 0
8 14 39 0 0
8 14 38 1 0
8 14 37 1 0
8 14 36 1 0
8 14 35 1 0
8 14 34 0 0
8 14 33 0 0
8 14 32 1 0
8 14 31 1 0
8 14 30 2 4
8 14 29 2 4
8 14 28 2 4
8 14 27 2 4
8 14 26 2 4
8 14 25 2 4
8 14 24 2 68
8 15 56 1 36
8 15 55 1 4
8 15 54 2 0
8 15 53 2 0
8 15 52 1 0
8 15 51 1 0
8 15 50 1 0
8 15 49 1 0
8 15 48 1 0
8 15 47 1 0
8 15 46 1 0
8 15 45 1 0
8 15 44 1 0
8 15 43 1 0
8 15 42 1 0
8 15 41 1 0
8 15 40 1 0
8 15 39 1 0
8 15 38 1 0
8 15 37 1 0
8 15 36 1 0
8 15 35 1 0
8 15 34 1 0
8 15 33 1 0
8 15 32 1 0
8 15 31 1 0
8 15 30 1 0
8 15 29 1 4
8 15 28 1 4
8 15 27 1 4
8 15 26 1 4
8 15 25 1 4
8 15 24 1 68
8 16 57 1 52
8 16 56 1 4
8 16 55 1 4
8 16 54 1 4
8 16 53 1 4
8 16 52 1 4
8 16 51 1 4
8 16 50 7 0
8 16 49 2 4
8 16 48 2 4
8 16 47 2 4
8 16 46 7 0
8 16 45 2 4
8 16 44 2 4
8 16 43 2 4
8 16 42 7 0
8 16 41 2 4
8 16 40 2 4
8 16 39 2 4
8 16 38 7 0
8 16 37 2 4
8 16 36 2 4
8 16 35 2 4
8 16 34 7 0
8 16 33 2 4
8 16 32 2 4
8 16 31 2 4
8 16 30 2 4
8 16 29 7 4
8 16 28 1 4
8 16 27 1 4
8 16 26 1 4
8 16 25 1 4
8 16 24 1 4
8 16 23 1 84
8 17 57 1 36
8 17 56 1 4
8 17 55 1 4
8 17 54 1 4
8 17 53 1 4
8 17 52 1 4
8 17 51 1 4
8 17 50 7 0
8 17 49 2 4
8 17 48 2 12
8 17 47 2 4
8 17 46 7 0
8 17 45 2 4
8 17 44 2 12
8 17 43 2 4
8 17 42 7 0
8 17 41 2 4
8 17 40 2 12
8 17 39 2 4
8 17 38 7 0
8 17 37 2 4
8 17 36 2 12
8 17 35 2 4
8 17 34 7 0
8 17 33 2 4
8 17 32 2 12
8 17 31 2 4
8 17 30 2 4
8 17 29 7 4
8 17 28 1 4
8 17 27 1 4
8 17 26 1 4
8 17 25 1 4
8 17 24 1 4
8 17 23 1 68
8 18 57 1 44
8 18 56 1 12
8 18 55 1 12
8 18 54 1 12
8 18 53 1 12
8 18 52 1 12
8 18 51 1 12
8 18 50 7 0
8 18 49 2 76
8 18 47 2 44
8 18 46 7 0
8 18 45 2 76
8 18 43 2 44
8 18 42 7 0
8 18 41 2 76
8 18 39 2 44
8 18 38 7 0
8 18 37 2 76
8 18 35 2 44
8 18 34 7 0
8 18 33 2 76
8 18 31 2 44
8 18 30 2 12
8 18 29 7 12
8 18 28 1 4
8 18 27 1 4
8 18 26 1 4
8 18 25 1 4
8 18 24 1 4
8 18 23 1 4
8 18 22 1 84
8 19 50 7 100
8 19 46 7 100
8 19 42 7 100
8 19 38 7 100
8 19 34 7 100
8 19 28 1 36
8 19 27 1 4
8 19 26 1 4
8 19 25 1 4
8 19 24 1 4
8 19 23 1 4
8 19 22 1 4
8 19 21 1 84
8 20 50 7 108
8 20 46 7 108
8 20 42 7 108
8 20 38 7 108
8 20 34 7 108
8 20 28 1 44
8 20 27 1 12
8 20 26 1 4
8 20 25 1 4
8 20 24 1 4
8 20 23 1 4
8 20 22 1 4
8 20 21 1 68
8 21 26 5 44
8 21 25 5 4
8 21 24 5 4
8 21 23 5 4
8 21 22 5 4
8 21 21 5 4
8 21 20 5 84
8 22 25 5 36
8 22 24 5 4
8 22 23 5 4
8 22 22 5 4
8 22 21 5 4
8 22 20 5 4
8 22 19 5 84
8 23 25 5 44
8 23 24 5 12
8 23 23 5 12
8 23 22 5 12
8 23 21 5 12
8 23 20 5 12
8 23 19 5 76
9 7 56 2 48
9 7 55 2 16
9 7 54 2 16
9 7 53 2 16
9 7 52 2 16
9 7 51 2 16
9 7 50 2 16
9 7 49 2 16
9 7 48 2 16
9 7 47 2 16
9 7 46 2 16
9 7 45 2 16
9 7 44 2 16
9 7 43 2 16
9 7 42 2 16
9 7 41 2 16
9 7 40 2 16
9 7 39 2 16
9 7 38 2 16
9 7 37 2 16
9 7 36 2 16
9 7 35 2 16
9 7 34 2 16
9 7 33 2 16
9 7 32 2 16
9 7 31 2 16
9 7 30 2 16
9 7 29 2 80
9 8 56 2 32
9 8 55 2 0
9 8 54 2 0
9 8 53 2 0
9 8 52 2 0
9 8 51 2 0
9 8 50 2 0
9 8 49 2 0
9 8 48 2 0
9 8 47 2 0
9 8 46 2 0
9 8 45 2 0
9 8 44 2 0
9 8 43 2 0
9 8 42 2 0
9 8 41 2 0
9 8 40 2 0
9 8 39 2 0
9 8 38 2 0
9 8 37 2 0
9 8 36 2 0
9 8 35 2 0
9 8 34 2 0
9 8 33 2 0
9 8 32 2 0
9 8 31 2 0
9 8 30 2 0
9 8 29 2 64
9 9 56 2 32
9 9 55 2 0
9 9 54 2 0
9 9 53 2 0
9 9 52 2 0
9 9 51 2 0
9 9 50 2 0
9 9 49 2 0
9 9 48 2 0
9 9 47 2 0
9 9 46 0 8
9 9 45 0 8
9 9 44 2 0
9 9 43 2 0
9 9 42 2 0
9 9 41 2 0
9 9 40 0 8
9 9 39 0 8
9 9 38 2 0
9 9 37 2 0
9 9 36 2 0
9 9 35 2 0
9 9 34 0 8
9 9 33 0 8
9 9 32 2 0
9 9 31 2 0
9 9 30 2 0
9 9 29 2 0
9 9 28 2 80
9 10 56 2 32
9 10 55 2 0
9 10 54 2 0
9 10 53 2 0
9 10 52 2 0
9 10 51 2 0
9 10 50 2 0
9 10 49 2 0
9 10 48 2 0
9 10 47 0 64
9 10 44 0 32
9 10 43 2 0
9 10 42 2 0
9 10 41 0 64
9 10 38 2 32
9 10 37 2 0
9 10 36 2 0
9 10 35 0 64
9 10 32 2 32
9 10 31 2 0
9 10 30 2 0
9 10 29 2 0
9 10 28 2 0
9 10 27 2 80
9 11 56 2 32
9 11 55 2 0
9 11 54 2 0
9 11 53 2 0
9 11 52 2 0
9 11 51 2 0
9 11 50 2 0
9 11 49 2 0
9 11 48 2 0
9 11 47 0 64
9 11 44 0 32
9 11 43 2 0
9 11 42 2 0
9 11 41 0 64
9 11 38 2 32
9 11 37 2 0
9 11 36 2 0
9 11 35 0 64
9 11 32 2 32
9 11 31 2 0
9 11 30 2 0
9 11 29 2 0
9 11 28 2 0
9 11 27 2 64
9 12 56 2 32
9 12 55 2 0
9 12 54 2 0
9 12 53 2 0
9 12 52 2 0
9 12 51 2 0
9 12 50 2 0
9 12 49 2 0
9 12 48 2 0
9 12 47 0 64
9 12 44 0 32
9 12 43 2 0
9 12 42 2 0
9 12 41 0 64
9 12 38 2 32
9 12 37 2 0
9 12 36 2 0
9 12 35 0 64
9 12 32 2 32
9 12 31 2 0
9 12 30 2 0
9 12 29 2 0
9 12 28 2 0
9 12 27 2 0
9 12 26 2 80
9 13 56 2 32
9 13 55 2 0
9 13 54 2 0
9 13 53 2 0
9 13 52 2 0
9 13 51 2 0
9 13 50 1 0
9 13 49 1 0
9 13 48 1 0
9 13 47 1 0
9 13 46 0 16
9 13 45 0 16
9 13 44 1 0
9 13 43 1 0
9 13 42 1 0
9 13 41 1 0
9 13 40 0 16
9 13 39 0 16
9 13 38 1 0
9 13 37 1 0
9 13 36 1 0
9 13 35 1 0
9 13 34 0 16
9 13 33 0 16
9 13 32 1 0
9 13 31 1 0
9 13 30 2 0
9 13 29 2 0
9 13 28 2 0
9 13 27 2 0
9 13 26 2 0
9 13 25 2 16
9 13 24 2 80
9 14 56 2 32
9 14 55 2 0
9 14 54 2 0
9 14 53 2 0
9 14 52 2 0
9 14 51 2 0
9 14 50 1 0
9 14 49 1 0
9 14 48 1 0
9 14 47 1 0
9 14 46 0 0
9 14 45 0 0
9 14 44 1 0
9 14 43 1 0
9 14 42 1 0
9 14 41 1 0
9 14 40 0 0
9 14 39 0 0
9 14 38 1 0
9 14 37 1 0
9 14 36 1 0
9 14 35 1 0
9 14 34 0 0
9 14 33 0 0
9 14 32 1 0
9 14 31 1 0
9 14 30 2 0
9 14 29 2 0
9 14 28 2 0
9 14 27 2 0
9 14 26 2 0
9 14 25 2 0
9 14 24 2 64
9 15 56 1 32
9 15 55 1 0
9 15 54 2 0
9 15 53 2 0
9 15 52 1 0
9 15 51 1 0
9 15 50 1 0
9 15 49 1 0
9 15 48 1 0
9 15 47 1 0
9 15 46 1 0
9 15 45 1 0
9 15 44 1 0
9 15 43 1 0
9 15 42 1 0
9 15 41 1 0
9 15 40 1 0
9 15 39 1 0
9 15 38 1 0
9 15 37 1 0
9 15 36 1 0
9 15 35 1 0
9 15 34 1 0
9 15 33 1 0
9 15 32 1 0
9 15 31 1 0
9 15 30 1 0
9 15 29 1 0
9 15 28 1 0
9 15 27 1 0
9 15 26 1 0
9 15 25 1 0
9 15 24 1 64
9 16 57 1 48
9 16 56 1 0
9 16 55 1 0
9 16 54 1 0
9 16 53 1 0
9 16 52 1 0
9 16 51 1 0
9 16 50 7 0
9 16 49 2 0
9 16 48 2 0
9 16 47 2 0
9 16 46 7 0
9 16 45 2 0
9 16 44 2 0
9 16 43 2 0
9 16 42 7 0
9 16 41 2 0
9 16 40 2 0
9 16 39 2 0
9 16 38 7 0
9 16 37 2 0
9 16 36 2 0
9 16 35 2 0
9 16 34 7 0
9 16 33 2 0
9 16 32 2 0
9 16 31 2 0
9 16 30 2 0
9 16 29 7 0
9 16 28 1 0
9 16 27 1 0
9 16 26 1 0
9 16 25 1 0
9 16 24 1 0
9 16 23 1 80
9 17 57 1 32
9 17 56 1 0
9 17 55 1 0
9 17 54 1 0
9 17 53 1 0
9 17 52 1 0
9 17 51 1 0
9 17 50 7 0
9 17 49 2 0
9 17 48 2 8
9 17 47 2 0
9 17 46 7 0
9 17 45 2 0
9 17 44 2 8
9 17 43 2 0
9 17 42 7 0
9 17 41 2 0
9 17 40 2 8
9 17 39 2 0
9 17 38 7 0
9 17 37 2 0
9 17 36 2 8
9 17 35 2 0
9 17 34 7 0
9 17 33 2 0
9 17 32 2 8
9 17 31 2 0
9 17 30 2 0
9 17 29 7 0
9 17 28 1 0
9 17 27 1 0
9 17 26 1 0
9 17 25 1 0
9 17 24 1 0
9 17 23 1 64
9 18 57 1 40
9 18 56 1 8
9 18 55 1 8
9 18 54 1 8
9 18 53 1 8
9 18 52 1 8
9 18 51 1 8
9 18 50 7 0
9 18 49 2 72
9 18 47 2 40
9 18 46 7 0
9 18 45 2 72
9 18 43 2 40
9 18 42 7 0
9 18 41 2 72
9 18 39 2 40
9 18 38 7 0
9 18 37 2 72
9 18 35 2 40
9 18 34 7 0
9 18 33 2 72
9 18 31 2 40
9 18 30 2 8
9 18 29 7 8
9 18 28 1 0
9 18 27 1 0
9 18 26 1 0
9 18 25 1 0
9 18 24 1 0
9 18 23 1 0
9 18 22 1 80
9 19 50 7 96
9 19 46 7 96
9 19 42 7 96
9 19 38 7 96
9 19 34 7 96
9 19 28 1 32
9 19 27 1 0
9 19 26 1 0
9 19 25 1 0
9 19 24 1 0
9 19 23 1 0
9 19 22 1 0
9 19 21 1 80
9 20 50 7 104
9 20 46 7 104
9 20 42 7 104
9 20 38 7 104
9 20 34 7 104
9 20 28 1 40
9 20 27 1 8
9 20 26 1 0
9 20 25 1 0
9 20 24 1 0
9 20 23 1 0
9 20 22 1 0
9 20 21 1 64
9 21 26 5 40
9 21 25 5 0
9 21 24 5 0
9 21 23 5 0
9 21 22 5 0
9 21 21 5 0
9 21 20 5 80
9 22 25 5 32
9 22 24 5 0
9 22 23 5 0
9 22 22 5 0
9 22 21 5 0
9 22 20 5 0
9 22 19 5 80
9 23 25 5 40
9 23 24 5 8
9 23 23 5 8
9 23 22 5 8
9 23 21 5 8
9 23 20 5 8
9 23 19 5 72
10 6 57 2 52
10 6 56 2 20
10 6 55 2 20
10 6 54 2 20
10 6 53 2 20
10 6 52 2 20
10 6 51 2 20
10 6 50 2 20
10 6 49 2 20
10 6 48 2 20
10 6 47 2 20
10 6 46 2 20
10 6 45 2 20
10 6 44 2 20
10 6 43 2 20
10 6 42 2 20
10 6 41 2 20
10 6 40 2 20
10 6 39 2 20
10 6 38 2 20
10 6 37 2 20
10 6 36 2 20
10 6 35 2 20
10 6 34 2 20
10 6 33 2 20
10 6 32 2 20
10 6 31 2 20
10 6 30 2 20
10 6 29 2 20
10 6 28 2 20
10 6 27 2 20
10 6 26 2 84
10 7 57 2 36
10 7 56 2 0
10 7 55 2 0
10 7 54 2 0
10 7 53 2 0
10 7 52 2 0
10 7 51 2 0
10 7 50 2 0
10 7 49 2 0
10 7 48 2 0
10 7 47 2 0
10 7 46 2 0
10 7 45 2 0
10 7 44 2 0
10 7 43 2 0
10 7 42 2 0
10 7 41 2 0
10 7 40 2 0
10 7 39 2 0
10 7 38 2 0
10 7 37 2 0
10 7 36 2 0
10 7 35 2 0
10 7 34 2 0
10 7 33 2 0
10 7 32 2 0
10 7 31 2 0
10 7 30 2 0
10 7 29 2 0
10 7 28 2 4
10 7 27 2 4
10 7 26 2 4
10 7 25 2 20
10 7 24 2 84
10 8 57 2 36
10 8 56 2 0
10 8 55 2 0
10 8 54 2 0
10 8 53 2 0
10 8 52 2 0
10 8 51 2 0
10 8 50 2 0
10 8 49 2 0
10 8 48 2 0
10 8 47 2 0
10 8 46 2 0
10 8 45 2 0
10 8 44 2 0
10 8 43 2 0
10 8 42 2 0
10 8 41 2 0
10 8 40 2 0
10 8 39 2 0
10 8 38 2 0
10 8 37 2 0
10 8 36 2 0
10 8 35 2 0
10 8 34 2 0
10 8 33 2 0
10 8 32 2 0
10 8 31 2 0
10 8 30 2 0
10 8 29 2 0
10 8 28 2 4
10 8 27 2 4
10 8 26 2 4
10 8 25 2 4
10 8 24 2 68
10 9 57 2 36
10 9 56 2 0
10 9 55 2 0
10 9 54 2 0
10 9 53 2 0
10 9 52 2 0
10 9 51 2 0
10 9 50 2 0
10 9 49 2 0
10 9 48 2 0
10 9 47 2 0
10 9 46 0 8
10 9 45 0 8
10 9 44 2 0
10 9 43 2 0
10 9 42 2 0
10 9 41 2 0
10 9 40 0 8
10 9 39 0 8
10 9 38 2 0
10 9 37 2 0
10 9 36 2 0
10 9 35 2 0
10 9 34 0 8
10 9 33 0 8
10 9 32 2 0
10 9 31 2 0
10 9 30 2 0
10 9 29 2 0
10 9 28 2 0
10 9 27 2 4
10 9 26 2 4
10 9 25 2 4
10 9 24 2 4
10 9 23 2 20
10 9 22 2 84
10 10 58 2 52
10 10 57 2 4
10 10 56 2 0
10 10 55 2 0
10 10 54 2 0
10 10 53 2 0
10 10 52 2 0
10 10 51 2 0
10 10 50 2 0
10 10 49 2 0
10 10 48 2 0
10 10 47 0 64
10 10 44 0 32
10 10 43 2 0
10 10 42 2 0
10 10 41 0 64
10 10 38 0 32
10 10 37 2 0
10 10 36 2 0
10 10 35 0 64
10 10 32 0 32
10 10 31 2 0
10 10 30 2 0
10 10 29 2 0
10 10 28 2 0
10 10 27 2 0
10 10 26 2 4
10 10 25 2 4
10 10 24 2 4
10 10 23 2 4
10 10 22 2 4
10 10 21 2 84
10 11 58 2 36
10 11 57 2 4
10 11 56 2 0
10 11 55 2 0
10 11 54 2 0
10 11 53 2 0
10 11 52 2 0
10 11 51 2 0
10 11 50 2 0
10 11 49 2 0
10 11 48 2 0
10 11 47 0 64
10 11 44 0 32
10 11 43 2 0
10 11 42 2 0
10 11 41 0 64
10 11 38 0 32
10 11 37 2 0
10 11 36 2 0
10 11 35 0 64
10 11 32 0 32
10 11 31 2 0
10 11 30 2 0
10 11 29 2 0
10 11 28 2 0
10 11 27 2 0
10 11 26 2 4
10 11 25 2 4
10 11 24 2 4
10 11 23 2 4
10 11 22 2 4
10 11 21 2 68
10 12 58 2 36
10 12 57 2 4
10 12 56 2 0
10 12 55 1 0
10 12 54 1 0
10 12 53 1 0
10 12 52 1 0
10 12 51 1 0
10 12 50 1 0
10 12 49 1 0
10 12 48 1 0
10 12 47 0 64
10 12 44 0 32
10 12 43 1 0
10 12 42 1 0
10 12 41 0 64
10 12 38 0 32
10 12 37 1 0
10 12 36 1 0
10 12 35 0 64
10 12 32 0 32
10 12 31 1 0
10 12 30 1 0
10 12 29 3 0
10 12 28 3 0
10 12 27 3 0
10 12 26 3 0
10 12 25 2 4
10 12 24 2 4
10 12 23 2 4
10 12 22 2 4
10 12 21 2 4
10 12 20 2 20
10 12 19 2 20
10 12 18 2 84
10 13 58 2 36
10 13 57 2 4
10 13 56 2 0
10 13 55 1 0
10 13 54 1 0
10 13 53 1 0
10 13 52 1 0
10 13 51 1 0
10 13 50 1 0
10 13 49 1 0
10 13 48 1 0
10 13 47 1 0
10 13 46 0 16
10 13 45 0 16
10 13 44 1 0
10 13 43 1 0
10 13 42 1 0
10 13 41 1 0
10 13 40 0 16
10 13 39 0 16
10 13 38 1 0
10 13 37 1 0
10 13 36 1 0
10 13 35 1 0
10 13 34 0 16
10 13 33 0 16
10 13 32 1 0
10 13 31 1 0
10 13 30 1 0
10 13 29 3 0
10 13 28 3 0
10 13 27 3 0
10 13 26 3 0
10 13 25 3 0
10 13 24 3 0
10 13 23 2 4
10 13 22 2 4
10 13 21 2 4
10 13 20 2 4
10 13 19 2 4
10 13 18 2 4
10 13 17 2 20
10 13 16 2 84
10 14 58 2 36
10 14 57 2 4
10 14 56 2 0
10 14 55 1 0
10 14 54 1 0
10 14 53 1 0
10 14 52 1 0
10 14 51 1 0
10 14 50 1 0
10 14 49 1 0
10 14 48 1 0
10 14 47 1 0
10 14 46 0 0
10 14 45 0 0
10 14 44 1 0
10 14 43 1 0
10 14 42 1 0
10 14 41 1 0
10 14 40 0 0
10 14 39 0 0
10 14 38 1 0
10 14 37 1 0
10 14 36 1 0
10 14 35 1 0
10 14 34 0 0
10 14 33 0 0
10 14 32 1 0
10 14 31 1 0
10 14 30 1 0
10 14 29 3 0
10 14 28 3 0
10 14 27 3 0
10 14 26 3 0
10 14 25 3 0
10 14 24 3 0
10 14 23 2 4
10 14 22 2 4
10 14 21 2 4
10 14 20 2 4
10 14 19 2 4
10 14 18 2 4
10 14 17 2 4
10 14 16 2 68
10 15 59 1 52
10 15 58 1 4
10 15 57 1 4
10 15 56 1 0
10 15 55 1 0
10 15 54 1 0
10 15 53 1 0
10 15 52 1 0
10 15 51 1 0
10 15 50 1 0
10 15 49 1 0
10 15 48 1 0
10 15 47 1 0
10 15 46 1 0
10 15 45 1 0
10 15 44 1 0
10 15 43 1 0
10 15 42 1 0
10 15 41 1 0
10 15 40 1 0
10 15 39 1 0
10 15 38 1 0
10 15 37 1 0
10 15 36 1 0
10 15 35 1 0
10 15 34 1 0
10 15 33 1 0
10 15 32 1 0
10 15 31 1 0
10 15 30 1 0
10 15 29 3 0
10 15 28 3 0
10 15 27 3 0
10 15 26 3 0
10 15 25 3 0
10 15 24 3 0
10 15 23 1 4
10 15 22 1 4
10 15 21 1 4
10 15 20 1 4
10 15 19 1 4
10 15 18 1 4
10 15 17 1 4
10 15 16 1 68
10 16 60 1 52
10 16 59 1 4
10 16 58 1 4
10 16 57 1 0
10 16 56 1 0
10 16 55 3 0
10 16 54 3 0
10 16 53 3 0
10 16 52 3 0
10 16 51 3 0
10 16 50 3 0
10 16 49 3 0
10 16 48 11 0
10 16 47 3 0
10 16 46 3 0
10 16 45 3 0
10 16 44 11 0
10 16 43 3 0
10 16 42 3 0
10 16 41 3 0
10 16 40 11 0
10 16 39 3 0
10 16 38 3 0
10 16 37 3 0
10 16 36 11 0
10 16 35 3 0
10 16 34 3 0
10 16 33 3 0
10 16 32 11 0
10 16 31 3 0
10 16 30 3 0
10 16 29 3 0
10 16 28 3 0
10 16 27 3 0
10 16 26 3 0
10 16 25 3 0
10 16 24 3 0
10 16 23 1 0
10 16 22 1 4
10 16 21 1 4
10 16 20 1 4
10 16 19 1 4
10 16 18 1 4
10 16 17 1 4
10 16 16 1 4
10 16 15 1 20
10 16 14 1 84
10 17 60 1 36
10 17 59 1 4
10 17 58 1 4
10 17 57 1 0
10 17 56 1 0
10 17 55 3 0
10 17 54 3 0
10 17 53 3 0
10 17 52 3 0
10 17 51 3 0
10 17 50 3 0
10 17 49 3 0
10 17 48 11 8
10 17 47 3 0
10 17 46 3 0
10 17 45 3 0
10 17 44 11 8
10 17 43 3 0
10 17 42 3 0
10 17 41 3 0
10 17 40 11 8
10 17 39 3 0
10 17 38 3 0
10 17 37 3 0
10 17 36 11 8
10 17 35 3 0
10 17 34 3 0
10 17 33 3 0
10 17 32 11 8
10 17 31 3 0
10 17 30 3 0
10 17 29 3 0
10 17 28 3 0
10 17 27 3 0
10 17 26 3 0
10 17 25 3 0
10 17 24 3 0
10 17 23 1 0
10 17 22 1 4
10 17 21 1 4
10 17 20 1 4
10 17 19 1 4
10 17 18 1 4
10 17 17 1 4
10 17 16 1 4
10 17 15 1 4
10 17 14 1 68
10 18 60 1 36
10 18 59 1 4
10 18 58 1 4
10 18 57 1 0
10 18 56 1 2
10 18 55 3 2
10 18 54 3 2
10 18 53 3 2
10 18 52 3 2
10 18 51 1 2
10 18 50 2 2
10 18 49 2 74
10 18 47 2 42
10 18 46 2 2
10 18 45 2 74
10 18 43 2 42
10 18 42 2 2
10 18 41 2 74
10 18 39 2 42
10 18 38 2 2
10 18 37 2 74
10 18 35 2 42
10 18 34 2 2
10 18 33 2 74
10 18 31 2 42
10 18 30 2 2
10 18 29 3 0
10 18 28 3 0
10 18 27 3 0
10 18 26 3 0
10 18 25 3 0
10 18 24 3 0
10 18 23 1 0
10 18 22 1 0
10 18 21 1 4
10 18 20 1 4
10 18 19 1 4
10 18 18 1 4
10 18 17 2 4
10 18 16 2 4
10 18 15 2 4
10 18 14 2 68
10 19 60 1 36
10 19 59 1 4
10 19 58 1 4
10 19 57 1 4
10 19 56 1 6
10 19 55 1 6
10 19 54 1 6
10 19 53 1 6
10 19 52 1 6
10 19 51 1 6
10 19 50 7 66
10 19 46 7 98
10 19 42 7 98
10 19 38 7 98
10 19 34 7 98
10 19 30 2 38
10 19 29 2 6
10 19 28 3 0
10 19 27 3 0
10 19 26 3 0
10 19 25 3 0
10 19 24 3 0
10 19 23 3 0
10 19 22 3 0
10 19 21 1 0
10 19 20 1 4
10 19 19 1 4
10 19 18 1 4
10 19 17 2 4
10 19 16 17 4
10 19 15 17 4
10 19 14 2 4
10 19 13 12 84
10 20 60 1 36
10 20 59 1 4
10 20 58 1 4
10 20 57 1 4
10 20 56 1 6
10 20 55 1 6
10 20 54 1 6
10 20 53 1 6
10 20 52 1 6
10 20 51 1 6
10 20 50 7 66
10 20 46 7 98
10 20 42 7 98
10 20 38 7 98
10 20 34 7 98
10 20 30 2 38
10 20 29 2 6
10 20 28 3 0
10 20 27 3 0
10 20 26 3 0
10 20 25 3 0
10 20 24 3 0
10 20 23 3 0
10 20 22 3 0
10 20 21 1 0
10 20 20 1 4
10 20 19 1 4
10 20 18 1 4
10 20 17 2 4
10 20 16 17 4
10 20 15 17 4
10 20 14 2 4
10 20 13 12 68
10 21 60 1 36
10 21 59 1 6
10 21 58 2 6
10 21 57 2 4
10 21 56 2 14
10 21 55 2 14
10 21 54 2 14
10 21 53 2 14
10 21 52 2 14
10 21 51 2 14
10 21 50 7 14
10 21 49 2 30
10 21 48 2 30
10 21 47 2 30
10 21 46 7 14
10 21 45 2 30
10 21 44 2 30
10 21 43 2 30
10 21 42 7 14
10 21 41 2 30
10 21 40 2 30
10 21 39 2 30
10 21 38 7 14
10 21 37 2 30
10 21 36 2 30
10 21 35 2 30
10 21 34 7 14
10 21 33 2 30
10 21 32 2 30
10 21 31 2 30
10 21 30 2 14
10 21 29 2 14
10 21 28 2 14
10 21 27 12 4
10 21 26 3 0
10 21 25 3 0
10 21 24 3 0
10 21 23 3 0
10 21 22 3 0
10 21 21 5 0
10 21 20 5 0
10 21 19 5 4
10 21 18 5 4
10 21 17 2 4
10 21 16 17 4
10 21 15 17 4
10 21 14 2 4
10 21 13 12 68
10 22 60 2 36
10 22 59 2 6
10 22 58 2 6
10 22 57 7 68
10 22 27 12 38
10 22 26 5 4
10 22 25 5 0
10 22 24 5 0
10 22 23 5 0
10 22 22 5 0
10 22 21 5 0
10 22 20 5 0
10 22 19 5 0
10 22 18 5 4
10 22 17 2 4
10 22 16 2 4
10 22 15 2 4
10 22 14 2 4
10 22 13 12 4
10 22 12 12 20
10 22 11 12 84
10 23 60 2 44
10 23 59 2 14
10 23 58 2 14
10 23 57 7 76
10 23 27 12 46
10 23 26 5 4
10 23 25 5 0
10 23 24 5 0
10 23 23 5 0
10 23 22 5 0
10 23 21 5 0
10 23 20 5 0
10 23 19 5 0
10 23 18 5 4
10 23 17 2 4
10 23 16 2 4
10 23 15 2 4
10 23 14 2 4
10 23 13 12 4
10 23 12 12 12
10 23 11 12 76
10 24 26 2 46
10 24 25 2 4
10 24 24 2 4
10 24 23 2 4
10 24 22 2 4
10 24 21 2 4
10 24 20 2 4
10 24 19 2 4
10 24 18 2 4
10 24 17 2 4
10 24 16 2 4
10 24 15 2 4
10 24 14 2 4
10 24 13 2 76
10 25 25 2 38
10 25 24 2 4
10 25 23 2 4
10 25 22 2 4
10 25 21 2 4
10 25 20 2 4
10 25 19 2 4
10 25 18 2 4
10 25 17 2 4
10 25 16 2 4
10 25 15 2 4
10 25 14 2 68
10 26 25 2 46
10 26 24 2 12
10 26 23 2 12
10 26 22 2 12
10 26 21 2 12
10 26 20 2 12
10 26 19 2 12
10 26 18 2 12
10 26 17 2 12
10 26 16 2 12
10 26 15 2 12
10 26 14 2 76
11 6 57 2 48
11 6 56 2 16
11 6 55 2 16
11 6 54 2 16
11 6 53 2 16
11 6 52 2 16
11 6 51 2 16
11 6 50 2 16
11 6 49 2 16
11 6 48 2 16
11 6 47 2 16
11 6 46 2 16
11 6 45 2 16
11 6 44 2 16
11 6 43 2 16
11 6 42 2 16
11 6 41 2 16
11 6 40 2 16
11 6 39 2 16
11 6 38 2 16
11 6 37 2 16
11 6 36 2 16
11 6 35 2 16
11 6 34 2 16
11 6 33 2 16
11 6 32 2 16
11 6 31 2 16
11 6 30 2 16
11 6 29 2 16
11 6 28 2 16
11 6 27 2 16
11 6 26 2 16
11 6 25 2 20
11 6 24 2 20
11 6 23 2 84
11 7 58 2 52
11 7 57 2 0
11 7 56 2 0
11 7 55 2 0
11 7 54 2 0
11 7 53 2 0
11 7 52 2 0
11 7 51 2 0
11 7 50 2 0
11 7 49 2 0
11 7 48 2 0
11 7 47 2 0
11 7 46 2 0
11 7 45 2 0
11 7 44 2 0
11 7 43 2 0
11 7 42 2 0
11 7 41 2 0
11 7 40 2 0
11 7 39 2 0
11 7 38 2 0
11 7 37 2 0
11 7 36 2 0
11 7 35 2 0
11 7 34 2 0
11 7 33 2 0
11 7 32 2 0
11 7 31 2 0
11 7 30 2 0
11 7 29 2 0
11 7 28 2 0
11 7 27 2 0
11 7 26 2 0
11 7 25 2 0
11 7 24 2 0
11 7 23 2 4
11 7 22 2 84
11 8 58 2 36
11 8 57 2 0
11 8 56 2 0
11 8 55 2 0
11 8 54 2 0
11 8 53 2 0
11 8 52 2 0
11 8 51 2 0
11 8 50 2 0
11 8 49 2 0
11 8 48 2 0
11 8 47 2 0
11 8 46 2 0
11 8 45 2 0
11 8 44 2 0
11 8 43 2 0
11 8 42 2 0
11 8 41 2 0
11 8 40 2 0
11 8 39 2 0
11 8 38 2 0
11 8 37 2 0
11 8 36 2 0
11 8 35 2 0
11 8 34 2 0
11 8 33 2 0
11 8 32 2 0
11 8 31 2 0
11 8 30 2 0
11 8 29 2 0
11 8 28 2 0
11 8 27 2 0
11 8 26 2 0
11 8 25 2 0
11 8 24 2 0
11 8 23 2 4
11 8 22 2 68
11 9 59 2 52
11 9 58 2 4
11 9 57 2 0
11 9 56 2 0
11 9 55 2 0
11 9 54 2 0
11 9 53 2 0
11 9 52 2 0
11 9 51 2 0
11 9 50 2 0
11 9 49 2 0
11 9 48 2 0
11 9 47 2 0
11 9 46 0 8
11 9 45 0 8
11 9 44 2 0
11 9 43 2 0
11 9 42 2 0
11 9 41 2 0
11 9 40 0 8
11 9 39 0 8
11 9 38 2 0
11 9 37 2 0
11 9 36 2 0
11 9 35 2 0
11 9 34 0 8
11 9 33 0 8
11 9 32 2 0
11 9 31 2 0
11 9 30 2 0
11 9 29 2 0
11 9 28 2 0
11 9 27 2 0
11 9 26 2 0
11 9 25 2 0
11 9 24 2 0
11 9 23 2 0
11 9 22 2 0
11 9 21 2 84
11 10 61 2 52
11 10 60 2 20
11 10 59 2 4
11 10 58 2 0
11 10 57 2 0
11 10 56 2 0
11 10 55 2 0
11 10 54 2 0
11 10 53 2 0
11 10 52 2 0
11 10 51 3 0
11 10 50 3 0
11 10 49 3 0
11 10 48 3 0
11 10 47 0 64
11 10 44 0 32
11 10 43 3 0
11 10 42 3 0
11 10 41 0 64
11 10 38 0 32
11 10 37 3 0
11 10 36 3 0
11 10 35 0 64
11 10 32 0 32
11 10 31 3 0
11 10 30 3 0
11 10 29 3 0
11 10 28 3 0
11 10 27 3 0
11 10 26 3 0
11 10 25 3 0
11 10 24 3 0
11 10 23 2 0
11 10 22 2 0
11 10 21 2 0
11 10 20 2 20
11 10 19 2 84
11 11 61 2 36
11 11 60 2 4
11 11 59 2 4
11 11 58 2 0
11 11 57 2 0
11 11 56 2 0
11 11 55 2 0
11 11 54 2 0
11 11 53 2 0
11 11 52 2 0
11 11 51 3 0
11 11 50 3 0
11 11 49 3 0
11 11 48 3 0
11 11 47 0 64
11 11 44 0 32
11 11 43 3 0
11 11 42 3 0
11 11 41 0 64
11 11 38 0 32
11 11 37 3 0
11 11 36 3 0
11 11 35 0 64
11 11 32 0 32
11 11 31 3 0
11 11 30 3 0
11 11 29 3 0
11 11 28 3 0
11 11 27 3 0
11 11 26 3 0
11 11 25 3 0
11 11 24 3 0
11 11 23 2 0
11 11 22 2 0
11 11 21 2 0
11 11 20 2 4
11 11 19 2 68
11 12 61 2 36
11 12 60 2 4
11 12 59 2 4
11 12 58 2 0
11 12 57 3 0
11 12 56 3 0
11 12 55 3 0
11 12 54 3 0
11 12 53 1 0
11 12 52 1 0
11 12 51 1 0
11 12 50 1 0
11 12 49 1 0
11 12 48 1 0
11 12 47 0 64
11 12 44 0 32
11 12 43 1 0
11 12 42 1 0
11 12 41 1 0
11 12 40 0 84
11 12 38 0 32
11 12 37 1 0
11 12 36 1 0
11 12 35 0 64
11 12 32 0 32
11 12 31 1 0
11 12 30 1 0
11 12 29 3 0
11 12 28 3 0
11 12 27 3 0
11 12 26 3 0
11 12 25 3 0
11 12 24 3 0
11 12 23 3 0
11 12 22 3 0
11 12 21 3 0
11 12 20 3 0
11 12 19 3 0
11 12 18 2 16
11 12 17 2 20
11 12 16 2 20
11 12 15 2 84
11 13 61 2 36
11 13 60 2 4
11 13 59 2 4
11 13 58 2 0
11 13 57 3 0
11 13 56 3 0
11 13 55 3 0
11 13 54 3 0
11 13 53 1 0
11 13 52 1 0
11 13 51 1 0
11 13 50 1 0
11 13 49 1 0
11 13 48 1 0
11 13 47 1 0
11 13 46 0 16
11 13 45 0 16
11 13 44 1 0
11 13 43 1 0
11 13 42 1 0
11 13 41 1 0
11 13 40 1 0
11 13 39 0 16
11 13 38 1 0
11 13 37 1 0
11 13 36 1 0
11 13 35 1 0
11 13 34 0 16
11 13 33 0 16
11 13 32 1 0
11 13 31 1 0
11 13 30 1 0
11 13 29 3 0
11 13 28 3 0
11 13 27 3 0
11 13 26 3 0
11 13 25 3 0
11 13 24 3 0
11 13 23 3 0
11 13 22 3 0
11 13 21 3 0
11 13 20 3 0
11 13 19 3 0
11 13 18 3 0
11 13 17 3 0
11 13 16 3 0
11 13 15 2 4
11 13 14 2 20
11 13 13 1 20
11 13 12 1 20
11 13 11 1 84
11 14 61 2 36
11 14 60 2 4
11 14 59 2 4
11 14 58 2 0
11 14 57 3 0
11 14 56 3 0
11 14 55 3 0
11 14 54 3 0
11 14 53 1 0
11 14 52 1 0
11 14 51 1 0
11 14 50 1 0
11 14 49 1 0
11 14 48 1 0
11 14 47 1 0
11 14 46 0 0
11 14 45 0 0
11 14 44 1 0
11 14 43 1 0
11 14 42 1 0
11 14 41 1 0
11 14 40 1 0
11 14 39 0 0
11 14 38 1 0
11 14 37 1 0
11 14 36 1 0
11 14 35 1 0
11 14 34 0 0
11 14 33 0 0
11 14 32 1 0
11 14 31 1 0
11 14 30 1 0
11 14 29 3 0
11 14 28 3 0
11 14 27 3 0
11 14 26 3 0
11 14 25 3 0
11 14 24 3 0
11 14 23 3 0
11 14 22 3 0
11 14 21 3 0
11 14 20 3 0
11 14 19 3 0
11 14 18 3 0
11 14 17 3 0
11 14 16 3 0
11 14 15 2 4
11 14 14 2 4
11 14 13 1 4
11 14 12 1 4
11 14 11 1 68
11 15 62 2 52
11 15 61 1 4
11 15 60 1 4
11 15 59 3 0
11 15 58 3 0
11 15 57 3 0
11 15 56 3 0
11 15 55 3 0
11 15 54 3 0
11 15 53 1 0
11 15 52 1 0
11 15 51 1 0
11 15 50 1 0
11 15 49 1 0
11 15 48 1 0
11 15 47 1 0
11 15 46 1 0
11 15 45 1 0
11 15 44 1 0
11 15 43 1 0
11 15 42 1 0
11 15 41 1 0
11 15 40 1 0
11 15 39 1 0
11 15 38 1 0
11 15 37 1 0
11 15 36 1 0
11 15 35 1 0
11 15 34 1 0
11 15 33 1 0
11 15 32 1 0
11 15 31 1 0
11 15 30 1 0
11 15 29 3 0
11 15 28 3 0
11 15 27 3 0
11 15 26 3 0
11 15 25 3 0
11 15 24 3 0
11 15 23 3 0
11 15 22 3 0
11 15 21 3 0
11 15 20 3 0
11 15 19 3 0
11 15 18 3 0
11 15 17 3 0
11 15 16 1 0
11 15 15 1 4
11 15 14 1 4
11 15 13 1 4
11 15 12 1 4
11 15 11 2 68
11 16 63 1 52
11 16 62 1 4
11 16 61 1 4
11 16 60 3 0
11 16 59 3 0
11 16 58 3 0
11 16 57 3 0
11 16 56 9 0
11 16 55 9 0
11 16 54 9 0
11 16 53 9 0
11 16 52 9 0
11 16 51 9 0
11 16 50 9 0
11 16 49 9 0
11 16 48 9 0
11 16 47 9 0
11 16 46 9 0
11 16 45 9 0
11 16 44 9 0
11 16 43 9 0
11 16 42 9 0
11 16 41 9 0
11 16 40 9 0
11 16 39 9 0
11 16 38 9 0
11 16 37 9 0
11 16 36 9 0
11 16 35 9 0
11 16 34 9 0
11 16 33 9 0
11 16 32 9 0
11 16 31 9 0
11 16 30 9 0
11 16 29 3 0
11 16 28 3 0
11 16 27 3 0
11 16 26 3 0
11 16 25 3 0
11 16 24 3 0
11 16 23 3 0
11 16 22 3 0
11 16 21 3 0
11 16 20 3 0
11 16 19 3 0
11 16 18 3 0
11 16 17 3 0
11 16 16 3 0
11 16 15 1 0
11 16 14 1 0
11 16 13 1 4
11 16 12 1 4
11 16 11 2 68
11 17 63 1 36
11 17 62 1 4
11 17 61 1 4
11 17 60 3 0
11 17 59 3 0
11 17 58 3 0
11 17 57 3 0
11 17 56 9 8
11 17 55 9 8
11 17 54 9 8
11 17 53 9 8
11 17 52 9 8
11 17 51 9 8
11 17 50 9 8
11 17 49 9 8
11 17 48 9 8
11 17 47 9 8
11 17 46 9 8
11 17 45 9 8
11 17 44 9 8
11 17 43 9 8
11 17 42 9 8
11 17 41 9 8
11 17 40 9 8
11 17 39 9 8
11 17 38 9 8
11 17 37 9 8
11 17 36 9 8
11 17 35 9 8
11 17 34 9 8
11 17 33 9 8
11 17 32 9 8
11 17 31 9 8
11 17 30 9 8
11 17 29 3 0
11 17 28 3 0
11 17 27 3 0
11 17 26 3 0
11 17 25 3 0
11 17 24 3 0
11 17 23 3 0
11 17 22 3 0
11 17 21 3 0
11 17 20 3 0
11 17 19 3 0
11 17 18 3 0
11 17 17 3 0
11 17 16 3 0
11 17 15 1 0
11 17 14 1 0
11 17 13 1 4
11 17 12 1 4
11 17 11 2 68
11 18 63 1 36
11 18 62 1 4
11 18 61 1 4
11 18 60 3 0
11 18 59 3 0
11 18 58 3 0
11 18 57 3 64
11 18 29 3 40
11 18 28 3 0
11 18 27 3 0
11 18 26 3 0
11 18 25 3 0
11 18 24 3 0
11 18 23 3 0
11 18 22 3 0
11 18 21 3 0
11 18 20 3 0
11 18 19 3 0
11 18 18 3 0
11 18 17 3 0
11 18 16 3 0
11 18 15 3 0
11 18 14 3 0
11 18 13 1 4
11 18 12 1 4
11 18 11 2 68
11 19 63 1 36
11 19 62 1 4
11 19 61 1 4
11 19 60 3 0
11 19 59 11 0
11 19 58 11 0
11 19 57 3 64
11 19 28 3 32
11 19 27 3 0
11 19 26 3 0
11 19 25 3 0
11 19 24 3 0
11 19 23 3 0
11 19 22 3 0
11 19 21 3 0
11 19 20 3 0
11 19 19 13 0
11 19 18 13 0
11 19 17 13 0
11 19 16 13 0
11 19 15 13 0
11 19 14 13 0
11 19 13 13 0
11 19 12 1 4
11 19 11 2 68
11 20 63 1 36
11 20 62 1 4
11 20 61 1 4
11 20 60 3 0
11 20 59 11 8
11 20 58 11 8
11 20 57 3 64
11 20 28 3 40
11 20 27 3 0
11 20 26 3 0
11 20 25 3 0
11 20 24 3 0
11 20 23 3 0
11 20 22 3 0
11 20 21 3 0
11 20 20 3 0
11 20 19 13 0
11 20 18 13 0
11 20 17 13 0
11 20 16 13 0
11 20 15 13 0
11 20 14 13 0
11 20 13 13 0
11 20 12 1 4
11 20 11 2 68
11 21 63 1 36
11 21 62 1 4
11 21 61 1 4
11 21 60 3 64
11 21 57 3 96
11 21 27 3 40
11 21 26 3 0
11 21 25 3 0
11 21 24 3 0
11 21 23 3 0
11 21 22 3 0
11 21 21 3 0
11 21 20 3 0
11 21 19 13 0
11 21 18 13 0
11 21 17 13 0
11 21 16 13 0
11 21 15 13 0
11 21 14 13 0
11 21 13 13 0
11 21 12 1 4
11 21 11 2 68
11 22 63 2 36
11 22 62 2 4
11 22 61 2 4
11 22 60 2 64
11 22 57 7 96
11 22 26 3 32
11 22 25 3 0
11 22 24 3 0
11 22 23 3 0
11 22 22 3 0
11 22 21 3 0
11 22 20 3 0
11 22 19 13 0
11 22 18 13 0
11 22 17 13 0
11 22 16 13 0
11 22 15 13 0
11 22 14 13 0
11 22 13 13 0
11 22 12 13 0
11 22 11 13 0
11 22 10 12 20
11 22 9 12 84
11 23 63 2 44
11 23 62 2 12
11 23 61 2 12
11 23 60 2 72
11 23 57 7 104
11 23 26 3 40
11 23 25 3 0
11 23 24 3 0
11 23 23 3 0
11 23 22 3 0
11 23 21 3 0
11 23 20 3 0
11 23 19 13 0
11 23 18 13 0
11 23 17 13 0
11 23 16 13 0
11 23 15 13 0
11 23 14 13 0
11 23 13 13 0
11 23 12 13 0
11 23 11 13 0
11 23 10 12 4
11 23 9 12 68
11 24 25 3 40
11 24 24 3 0
11 24 23 3 0
11 24 22 3 0
11 24 21 3 0
11 24 20 3 0
11 24 19 3 0
11 24 18 3 0
11 24 17 3 0
11 24 16 7 0
11 24 15 7 0
11 24 14 7 0
11 24 13 7 0
11 24 12 2 4
11 24 11 2 4
11 24 10 2 4
11 24 9 2 68
11 25 24 3 32
11 25 23 3 0
11 25 22 3 0
11 25 21 3 0
11 25 20 3 0
11 25 19 2 0
11 25 18 2 0
11 25 17 2 0
11 25 16 2 0
11 25 15 2 0
11 25 14 2 0
11 25 13 2 4
11 25 12 2 4
11 25 11 2 4
11 25 10 2 4
11 25 9 2 68
11 26 24 3 32
11 26 23 3 0
11 26 22 3 0
11 26 21 3 0
11 26 20 3 0
11 26 19 2 0
11 26 18 2 0
11 26 17 2 0
11 26 16 2 0
11 26 15 2 0
11 26 14 2 0
11 26 13 2 4
11 26 12 2 4
11 26 11 2 4
11 26 10 2 12
11 26 9 2 76
11 27 24 7 44
11 27 23 7 12
11 27 22 7 12
11 27 21 7 12
11 27 20 7 12
11 27 19 7 12
11 27 18 7 12
11 27 17 7 12
11 27 16 7 12
11 27 15 7 12
11 27 14 7 12
11 27 13 7 12
11 27 12 7 12
11 27 11 7 76
12 6 57 2 48
12 6 56 2 16
12 6 55 2 16
12 6 54 2 16
12 6 53 2 16
12 6 52 2 16
12 6 51 2 16
12 6 50 2 16
12 6 49 2 16
12 6 48 2 16
12 6 47 2 16
12 6 46 2 16
12 6 45 2 16
12 6 44 2 16
12 6 43 2 16
12 6 42 2 16
12 6 41 2 16
12 6 40 2 16
12 6 39 2 16
12 6 38 2 16
12 6 37 2 16
12 6 36 2 16
12 6 35 2 16
12 6 34 2 16
12 6 33 2 16
12 6 32 2 16
12 6 31 2 16
12 6 30 2 16
12 6 29 2 16
12 6 28 2 16
12 6 27 2 16
12 6 26 2 16
12 6 25 2 16
12 6 24 2 16
12 6 23 2 80
12 7 58 2 48
12 7 57 2 0
12 7 56 2 0
12 7 55 2 0
12 7 54 2 0
12 7 53 2 0
12 7 52 2 0
12 7 51 2 0
12 7 50 2 0
12 7 49 2 0
12 7 48 2 0
12 7 47 2 0
12 7 46 2 0
12 7 45 2 0
12 7 44 2 0
12 7 43 2 0
12 7 42 2 0
12 7 41 2 0
12 7 40 2 0
12 7 39 2 0
12 7 38 2 0
12 7 37 2 0
12 7 36 2 0
12 7 35 2 0
12 7 34 2 0
12 7 33 2 0
12 7 32 2 0
12 7 31 2 0
12 7 30 2 0
12 7 29 2 0
12 7 28 2 0
12 7 27 2 0
12 7 26 2 0
12 7 25 2 0
12 7 24 2 0
12 7 23 2 0
12 7 22 2 82
12 8 58 2 32
12 8 57 2 0
12 8 56 2 0
12 8 55 2 0
12 8 54 2 0
12 8 53 2 0
12 8 52 2 0
12 8 51 2 0
12 8 50 2 0
12 8 49 2 0
12 8 48 2 0
12 8 47 2 0
12 8 46 2 0
12 8 45 2 0
12 8 44 2 0
12 8 43 2 0
12 8 42 2 0
12 8 41 2 0
12 8 40 2 0
12 8 39 2 0
12 8 38 2 0
12 8 37 2 0
12 8 36 2 0
12 8 35 2 0
12 8 34 2 0
12 8 33 2 0
12 8 32 2 0
12 8 31 2 0
12 8 30 2 0
12 8 29 2 0
12 8 28 2 0
12 8 27 2 0
12 8 26 2 0
12 8 25 2 0
12 8 24 2 0
12 8 23 2 0
12 8 22 2 66
12 9 59 2 48
12 9 58 2 0
12 9 57 2 0
12 9 56 2 0
12 9 55 2 0
12 9 54 2 0
12 9 53 2 0
12 9 52 2 0
12 9 51 2 0
12 9 50 2 0
12 9 49 2 0
12 9 48 2 0
12 9 47 2 0
12 9 46 0 8
12 9 45 0 8
12 9 44 2 0
12 9 43 2 0
12 9 42 2 0
12 9 41 2 0
12 9 40 0 8
12 9 39 0 8
12 9 38 2 0
12 9 37 2 0
12 9 36 2 0
12 9 35 2 0
12 9 34 0 8
12 9 33 0 8
12 9 32 2 0
12 9 31 2 0
12 9 30 2 0
12 9 29 2 0
12 9 28 2 0
12 9 27 2 0
12 9 26 2 0
12 9 25 2 0
12 9 24 2 0
12 9 23 2 0
12 9 22 2 0
12 9 21 2 80
12 10 61 2 48
12 10 60 2 16
12 10 59 2 0
12 10 58 2 0
12 10 57 2 0
12 10 56 2 0
12 10 55 2 0
12 10 54 2 0
12 10 53 2 0
12 10 52 2 0
12 10 51 3 0
12 10 50 3 0
12 10 49 3 0
12 10 48 3 0
12 10 47 0 64
12 10 44 0 32
12 10 43 3 0
12 10 42 3 0
12 10 41 0 64
12 10 38 0 32
12 10 37 3 0
12 10 36 3 0
12 10 35 0 64
12 10 32 0 32
12 10 31 3 0
12 10 30 3 0
12 10 29 3 0
12 10 28 3 0
12 10 27 3 0
12 10 26 3 0
12 10 25 3 0
12 10 24 3 0
12 10 23 2 0
12 10 22 2 0
12 10 21 2 0
12 10 20 2 16
12 10 19 2 80
12 11 61 2 32
12 11 60 2 0
12 11 59 2 0
12 11 58 2 0
12 11 57 2 0
12 11 56 2 0
12 11 55 2 0
12 11 54 2 0
12 11 53 2 0
12 11 52 2 0
12 11 51 3 0
12 11 50 3 0
12 11 49 3 0
12 11 48 3 0
12 11 47 0 64
12 11 44 0 32
12 11 43 3 0
12 11 42 3 0
12 11 41 0 64
12 11 38 0 32
12 11 37 3 0
12 11 36 3 0
12 11 35 0 64
12 11 32 0 32
12 11 31 3 0
12 11 30 3 0
12 11 29 3 0
12 11 28 3 0
12 11 27 3 0
12 11 26 3 0
12 11 25 3 0
12 11 24 3 0
12 11 23 2 0
12 11 22 2 0
12 11 21 2 0
12 11 20 2 0
12 11 19 2 64
12 12 61 2 32
12 12 60 2 0
12 12 59 2 0
12 12 58 2 0
12 12 57 3 0
12 12 56 3 0
12 12 55 3 0
12 12 54 3 0
12 12 53 1 0
12 12 52 1 0
12 12 51 1 0
12 12 50 1 0
12 12 49 1 0
12 12 48 1 0
12 12 47 0 64
12 12 44 0 32
12 12 43 1 0
12 12 42 1 0
12 12 41 1 0
12 12 40 0 80
12 12 38 0 32
12 12 37 1 0
12 12 36 1 0
12 12 35 0 64
12 12 32 0 32
12 12 31 1 0
12 12 30 1 0
12 12 29 3 0
12 12 28 3 0
12 12 27 3 0
12 12 26 3 0
12 12 25 3 0
12 12 24 3 0
12 12 23 3 0
12 12 22 3 0
12 12 21 3 0
12 12 20 3 0
12 12 19 3 0
12 12 18 2 16
12 12 17 2 16
12 12 16 2 16
12 12 15 2 80
12 13 61 2 32
12 13 60 2 0
12 13 59 2 0
12 13 58 2 0
12 13 57 3 0
12 13 56 3 0
12 13 55 3 0
12 13 54 3 0
12 13 53 1 0
12 13 52 1 0
12 13 51 1 0
12 13 50 1 0
12 13 49 1 0
12 13 48 1 0
12 13 47 1 0
12 13 46 0 16
12 13 45 0 16
12 13 44 1 0
12 13 43 1 0
12 13 42 1 0
12 13 41 1 0
12 13 40 1 0
12 13 39 0 16
12 13 38 1 0
12 13 37 1 0
12 13 36 1 0
12 13 35 1 0
12 13 34 0 16
12 13 33 0 16
12 13 32 1 0
12 13 31 1 0
12 13 30 1 0
12 13 29 3 0
12 13 28 3 0
12 13 27 3 0
12 13 26 3 0
12 13 25 3 0
12 13 24 3 0
12 13 23 3 0
12 13 22 3 0
12 13 21 3 0
12 13 20 3 0
12 13 19 3 0
12 13 18 3 0
12 13 17 3 0
12 13 16 3 0
12 13 15 2 0
12 13 14 2 16
12 13 13 1 16
12 13 12 1 16
12 13 11 1 80
12 14 61 2 32
12 14 60 2 0
12 14 59 2 0
12 14 58 2 0
12 14 57 3 0
12 14 56 3 0
12 14 55 3 0
12 14 54 3 0
12 14 53 1 0
12 14 52 1 0
12 14 51 1 0
12 14 50 1 0
12 14 49 1 0
12 14 48 1 0
12 14 47 1 0
12 14 46 0 0
12 14 45 0 0
12 14 44 1 0
12 14 43 1 0
12 14 42 1 0
12 14 41 1 0
12 14 40 1 0
12 14 39 0 0
12 14 38 1 0
12 14 37 1 0
12 14 36 1 0
12 14 35 1 0
12 14 34 0 0
12 14 33 0 0
12 14 32 1 0
12 14 31 1 0
12 14 30 1 0
12 14 29 3 0
12 14 28 3 0
12 14 27 3 0
12 14 26 3 0
12 14 25 3 0
12 14 24 3 0
12 14 23 3 0
12 14 22 3 0
12 14 21 3 0
12 14 20 3 0
12 14 19 3 0
12 14 18 3 0
12 14 17 3 0
12 14 16 3 0
12 14 15 2 0
12 14 14 2 0
12 14 13 1 0
12 14 12 1 0
12 14 11 1 64
12 15 62 2 48
12 15 61 1 0
12 15 60 1 0
12 15 59 3 0
12 15 58 3 0
12 15 57 3 0
12 15 56 3 0
12 15 55 3 0
12 15 54 3 0
12 15 53 1 0
12 15 52 1 0
12 15 51 1 0
12 15 50 1 0
12 15 49 1 0
12 15 48 1 0
12 15 47 1 0
12 15 46 1 0
12 15 45 1 0
12 15 44 1 0
12 15 43 1 0
12 15 42 1 0
12 15 41 1 0
12 15 40 1 0
12 15 39 1 0
12 15 38 1 0
12 15 37 1 0
12 15 36 1 0
12 15 35 1 0
12 15 34 1 0
12 15 33 1 0
12 15 32 1 0
12 15 31 1 0
12 15 30 1 0
12 15 29 3 0
12 15 28 3 0
12 15 27 3 0
12 15 26 3 0
12 15 25 3 0
12 15 24 3 0
12 15 23 3 0
12 15 22 3 0
12 15 21 3 0
12 15 20 3 0
12 15 19 3 0
12 15 18 3 0
12 15 17 3 0
12 15 16 1 0
12 15 15 1 0
12 15 14 1 0
12 15 13 1 0
12 15 12 1 0
12 15 11 2 64
12 16 63 1 48
12 16 62 1 0
12 16 61 1 0
12 16 60 3 0
12 16 59 3 0
12 16 58 3 0
12 16 57 3 0
12 16 56 9 0
12 16 55 9 0
12 16 54 9 0
12 16 53 9 0
12 16 52 9 0
12 16 51 9 0
12 16 50 9 0
12 16 49 9 0
12 16 48 9 0
12 16 47 9 0
12 16 46 9 0
12 16 45 9 0
12 16 44 9 0
12 16 43 9 0
12 16 42 9 0
12 16 41 9 0
12 16 40 9 0
12 16 39 9 0
12 16 38 9 0
12 16 37 9 0
12 16 36 9 0
12 16 35 9 0
12 16 34 9 0
12 16 33 9 0
12 16 32 9 0
12 16 31 9 0
12 16 30 9 0
12 16 29 3 0
12 16 28 3 0
12 16 27 3 0
12 16 26 3 0
12 16 25 3 0
12 16 24 3 0
12 16 23 3 0
12 16 22 3 0
12 16 21 3 0
12 16 20 3 0
12 16 19 3 0
12 16 18 3 0
12 16 17 3 0
12 16 16 3 0
12 16 15 1 0
12 16 14 1 0
12 16 13 1 0
12 16 12 1 0
12 16 11 2 64
12 17 63 1 32
12 17 62 1 0
12 17 61 1 0
12 17 60 3 0
12 17 59 3 0
12 17 58 3 0
12 17 57 3 0
12 17 56 9 8
12 17 55 9 8
12 17 54 9 8
12 17 53 9 8
12 17 52 9 8
12 17 51 9 8
12 17 50 9 8
12 17 49 9 8
12 17 48 9 8
12 17 47 9 8
12 17 46 9 8
12 17 45 9 8
12 17 44 9 8
12 17 43 9 8
12 17 42 9 8
12 17 41 9 8
12 17 40 9 8
12 17 39 9 8
12 17 38 9 8
12 17 37 9 8
12 17 36 9 8
12 17 35 9 8
12 17 34 9 8
12 17 33 9 8
12 17 32 9 8
12 17 31 9 8
12 17 30 9 8
12 17 29 3 0
12 17 28 3 0
12 17 27 3 0
12 17 26 3 0
12 17 25 3 0
12 17 24 3 0
12 17 23 3 0
12 17 22 3 0
12 17 21 3 0
12 17 20 3 0
12 17 19 3 0
12 17 18 3 0
12 17 17 3 0
12 17 16 3 0
12 17 15 1 0
12 17 14 1 0
12 17 13 1 0
12 17 12 1 0
12 17 11 2 64
12 18 63 1 32
12 18 62 1 0
12 18 61 1 0
12 18 60 3 0
12 18 59 3 0
12 18 58 3 0
12 18 57 3 64
12 18 29 3 40
12 18 28 3 0
12 18 27 3 0
12 18 26 3 0
12 18 25 3 0
12 18 24 3 0
12 18 23 3 0
12 18 22 3 0
12 18 21 3 0
12 18 20 3 0
12 18 19 3 0
12 18 18 3 0
12 18 17 3 0
12 18 16 3 0
12 18 15 3 0
12 18 14 3 0
12 18 13 1 0
12 18 12 1 0
12 18 11 2 64
12 19 63 1 32
12 19 62 1 0
12 19 61 1 0
12 19 60 3 0
12 19 59 11 0
12 19 58 11 0
12 19 57 3 64
12 19 28 3 32
12 19 27 3 0
12 19 26 3 0
12 19 25 3 0
12 19 24 3 0
12 19 23 3 0
12 19 22 3 0
12 19 21 3 0
12 19 20 3 0
12 19 19 13 0
12 19 18 13 0
12 19 17 13 0
12 19 16 13 0
12 19 15 13 0
12 19 14 13 0
12 19 13 13 0
12 19 12 1 0
12 19 11 2 64
12 20 63 1 32
12 20 62 1 0
12 20 61 1 0
12 20 60 3 0
12 20 59 11 8
12 20 58 11 8
12 20 57 3 64
12 20 28 3 40
12 20 27 3 0
12 20 26 3 0
12 20 25 3 0
12 20 24 3 0
12 20 23 3 0
12 20 22 3 0
12 20 21 3 0
12 20 20 3 0
12 20 19 13 0
12 20 18 13 0
12 20 17 13 0
12 20 16 13 0
12 20 15 13 0
12 20 14 13 0
12 20 13 13 0
12 20 12 1 0
12 20 11 2 64
12 21 63 1 32
12 21 62 1 2
12 21 61 1 2
12 21 60 3 66
12 21 57 3 98
12 21 27 3 40
12 21 26 3 0
12 21 25 3 0
12 21 24 3 0
12 21 23 3 0
12 21 22 3 0
12 21 21 3 0
12 21 20 3 0
12 21 19 13 0
12 21 18 13 0
12 21 17 13 0
12 21 16 13 0
12 21 15 13 0
12 21 14 13 0
12 21 13 13 0
12 21 12 1 0
12 21 11 2 64
12 22 63 2 32
12 22 62 2 2
12 22 61 2 2
12 22 60 2 66
12 22 57 7 98
12 22 26 3 32
12 22 25 3 0
12 22 24 3 0
12 22 23 3 0
12 22 22 3 0
12 22 21 3 0
12 22 20 3 0
12 22 19 13 0
12 22 18 13 0
12 22 17 13 0
12 22 16 13 0
12 22 15 13 0
12 22 14 13 0
12 22 13 13 0
12 22 12 13 0
12 22 11 13 0
12 22 10 12 16
12 22 9 12 80
12 23 63 2 40
12 23 62 2 10
12 23 61 2 10
12 23 60 2 74
12 23 57 7 106
12 23 26 3 40
12 23 25 3 0
12 23 24 3 0
12 23 23 3 0
12 23 22 3 0
12 23 21 3 0
12 23 20 3 0
12 23 19 13 0
12 23 18 13 0
12 23 17 13 0
12 23 16 13 0
12 23 15 13 0
12 23 14 13 0
12 23 13 13 0
12 23 12 13 0
12 23 11 13 0
12 23 10 12 0
12 23 9 12 64
12 24 25 3 40
12 24 24 3 0
12 24 23 3 0
12 24 22 3 0
12 24 21 3 0
12 24 20 3 0
12 24 19 3 0
12 24 18 3 0
12 24 17 3 0
12 24 16 7 0
12 24 15 7 0
12 24 14 7 0
12 24 13 7 0
12 24 12 2 0
12 24 11 2 0
12 24 10 2 0
12 24 9 2 64
12 25 24 3 32
12 25 23 3 0
12 25 22 3 0
12 25 21 3 0
12 25 20 3 0
12 25 19 2 0
12 25 18 2 0
12 25 17 2 0
12 25 16 2 0
12 25 15 2 0
12 25 14 2 0
12 25 13 2 0
12 25 12 2 0
12 25 11 2 0
12 25 10 2 0
12 25 9 2 64
12 26 24 3 32
12 26 23 3 0
12 26 22 3 0
12 26 21 3 0
12 26 20 3 0
12 26 19 2 0
12 26 18 2 0
12 26 17 2 0
12 26 16 2 0
12 26 15 2 0
12 26 14 2 0
12 26 13 2 0
12 26 12 2 0
12 26 11 2 0
12 26 10 2 8
12 26 9 2 72
12 27 24 7 42
12 27 23 7 10
12 27 22 7 10
12 27 21 7 10
12 27 20 7 10
12 27 19 7 10
12 27 18 7 10
12 27 17 7 10
12 27 16 7 10
12 27 15 7 10
12 27 14 7 10
12 27 13 7 10
12 27 12 7 10
12 27 11 7 72
13 4 56 1 52
13 4 55 1 20
13 4 54 1 20
13 4 53 1 20
13 4 52 1 20
13 4 51 1 20
13 4 50 1 20
13 4 49 1 20
13 4 48 1 20
13 4 47 1 20
13 4 46 1 20
13 4 45 1 20
13 4 44 1 20
13 4 43 1 20
13 4 42 1 20
13 4 41 1 20
13 4 40 1 20
13 4 39 1 20
13 4 38 1 20
13 4 37 1 20
13 4 36 1 20
13 4 35 1 20
13 4 34 1 20
13 4 33 1 20
13 4 32 1 20
13 4 31 1 20
13 4 30 1 20
13 4 29 1 20
13 4 28 1 20
13 4 27 1 20
13 4 26 1 20
13 4 25 1 20
13 4 24 1 20
13 4 23 1 84
13 5 56 1 36
13 5 55 1 4
13 5 54 1 4
13 5 53 1 4
13 5 52 1 4
13 5 51 1 4
13 5 50 1 4
13 5 49 1 4
13 5 48 1 4
13 5 47 1 4
13 5 46 1 4
13 5 45 1 4
13 5 44 1 4
13 5 43 1 4
13 5 42 1 4
13 5 41 1 4
13 5 40 1 4
13 5 39 1 4
13 5 38 1 4
13 5 37 1 4
13 5 36 1 4
13 5 35 1 4
13 5 34 1 4
13 5 33 1 4
13 5 32 1 4
13 5 31 1 4
13 5 30 1 4
13 5 29 1 4
13 5 28 1 4
13 5 27 1 4
13 5 26 1 4
13 5 25 1 4
13 5 24 1 4
13 5 23 1 68
13 6 57 2 48
13 6 56 2 0
13 6 55 2 0
13 6 54 2 0
13 6 53 2 0
13 6 52 2 0
13 6 51 9 0
13 6 50 9 0
13 6 49 2 0
13 6 48 2 0
13 6 47 2 0
13 6 46 2 0
13 6 45 2 0
13 6 44 2 0
13 6 43 2 0
13 6 42 2 0
13 6 41 2 0
13 6 40 2 0
13 6 39 2 0
13 6 38 2 0
13 6 37 2 0
13 6 36 2 0
13 6 35 2 0
13 6 34 2 0
13 6 33 2 0
13 6 32 2 0
13 6 31 2 0
13 6 30 2 0
13 6 29 2 0
13 6 28 2 0
13 6 27 2 0
13 6 26 2 0
13 6 25 2 0
13 6 24 2 0
13 6 23 2 64
13 7 58 2 48
13 7 57 2 0
13 7 56 3 0
13 7 55 3 0
13 7 54 3 0
13 7 53 3 0
13 7 52 3 0
13 7 51 9 0
13 7 50 9 0
13 7 49 3 0
13 7 48 3 0
13 7 47 3 0
13 7 46 3 0
13 7 45 3 0
13 7 44 3 0
13 7 43 3 0
13 7 42 3 0
13 7 41 3 0
13 7 40 3 0
13 7 39 3 0
13 7 38 3 0
13 7 37 3 0
13 7 36 3 0
13 7 35 3 0
13 7 34 3 0
13 7 33 3 0
13 7 32 3 0
13 7 31 3 0
13 7 30 3 0
13 7 29 3 0
13 7 28 3 0
13 7 27 3 0
13 7 26 3 0
13 7 25 3 0
13 7 24 3 0
13 7 23 2 64
13 8 58 2 32
13 8 57 2 0
13 8 56 3 0
13 8 55 3 0
13 8 54 3 0
13 8 53 3 0
13 8 52 3 0
13 8 51 9 0
13 8 50 9 0
13 8 49 3 0
13 8 48 3 0
13 8 47 3 0
13 8 46 3 0
13 8 45 3 0
13 8 44 3 0
13 8 43 3 0
13 8 42 3 0
13 8 41 3 0
13 8 40 3 0
13 8 39 3 0
13 8 38 3 0
13 8 37 3 0
13 8 36 3 0
13 8 35 3 0
13 8 34 3 0
13 8 33 3 0
13 8 32 3 0
13 8 31 3 0
13 8 30 3 0
13 8 29 3 0
13 8 28 3 0
13 8 27 3 0
13 8 26 3 0
13 8 25 3 0
13 8 24 3 0
13 8 23 2 64
13 9 59 2 48
13 9 58 2 0
13 9 57 3 0
13 9 56 3 0
13 9 55 3 0
13 9 54 3 0
13 9 53 3 0
13 9 52 3 0
13 9 51 9 0
13 9 50 9 0
13 9 49 3 0
13 9 48 3 0
13 9 47 3 0
13 9 46 3 0
13 9 45 3 0
13 9 44 3 0
13 9 43 3 0
13 9 42 3 0
13 9 41 3 0
13 9 40 0 8
13 9 39 0 8
13 9 38 3 0
13 9 37 3 0
13 9 36 3 0
13 9 35 3 0
13 9 34 0 8
13 9 33 0 8
13 9 32 3 0
13 9 31 3 0
13 9 30 3 0
13 9 29 3 0
13 9 28 3 0
13 9 27 3 0
13 9 26 3 0
13 9 25 3 0
13 9 24 3 0
13 9 23 3 0
13 9 22 2 16
13 9 21 2 16
13 9 20 2 84
13 10 61 2 48
13 10 60 2 16
13 10 59 2 0
13 10 58 3 0
13 10 57 3 0
13 10 56 3 0
13 10 55 3 0
13 10 54 3 0
13 10 53 3 0
13 10 52 3 0
13 10 51 9 0
13 10 50 9 0
13 10 49 3 0
13 10 48 3 0
13 10 47 3 0
13 10 46 0 4
13 10 45 0 4
13 10 44 3 0
13 10 43 3 0
13 10 42 3 0
13 10 41 0 64
13 10 38 0 32
13 10 37 3 0
13 10 36 3 0
13 10 35 0 64
13 10 32 0 32
13 10 31 3 0
13 10 30 3 0
13 10 29 3 0
13 10 28 3 0
13 10 27 3 0
13 10 26 3 0
13 10 25 3 0
13 10 24 3 0
13 10 23 3 0
13 10 22 3 0
13 10 21 3 0
13 10 20 3 0
13 10 19 2 16
13 10 18 2 84
13 11 61 2 32
13 11 60 2 0
13 11 59 2 0
13 11 58 3 0
13 11 57 3 0
13 11 56 3 0
13 11 55 3 0
13 11 54 3 0
13 11 53 3 0
13 11 52 3 0
13 11 51 9 0
13 11 50 9 0
13 11 49 3 0
13 11 48 3 0
13 11 47 3 0
13 11 46 0 4
13 11 45 0 12
13 11 44 3 0
13 11 43 3 0
13 11 42 3 0
13 11 41 0 64
13 11 38 0 32
13 11 37 3 0
13 11 36 3 0
13 11 35 0 64
13 11 32 0 32
13 11 31 3 0
13 11 30 3 0
13 11 29 3 0
13 11 28 3 0
13 11 27 3 0
13 11 26 3 0
13 11 25 3 0
13 11 24 3 0
13 11 23 3 0
13 11 22 3 0
13 11 21 3 0
13 11 20 3 0
13 11 19 2 0
13 11 18 2 68
13 12 63 2 52
13 12 62 2 20
13 12 61 2 0
13 12 60 2 0
13 12 59 3 0
13 12 58 3 0
13 12 57 3 0
13 12 56 3 0
13 12 55 3 0
13 12 54 3 0
13 12 53 1 0
13 12 52 1 0
13 12 51 9 0
13 12 50 9 0
13 12 49 1 0
13 12 48 1 0
13 12 47 1 0
13 12 46 0 68
13 12 44 0 32
13 12 43 1 0
13 12 42 1 0
13 12 41 1 0
13 12 40 0 16
13 12 39 0 20
13 12 38 1 0
13 12 37 1 0
13 12 36 1 0
13 12 35 0 64
13 12 32 0 32
13 12 31 1 0
13 12 30 1 0
13 12 29 3 0
13 12 28 3 0
13 12 27 3 0
13 12 26 3 0
13 12 25 3 0
13 12 24 3 0
13 12 23 3 0
13 12 22 3 0
13 12 21 3 0
13 12 20 3 0
13 12 19 3 0
13 12 18 3 0
13 12 17 2 16
13 12 16 2 16
13 12 15 2 16
13 12 14 2 84
13 13 63 2 36
13 13 62 2 4
13 13 61 3 0
13 13 60 3 0
13 13 59 3 0
13 13 58 3 0
13 13 57 3 0
13 13 56 3 0
13 13 55 3 0
13 13 54 3 0
13 13 53 1 0
13 13 52 9 0
13 13 51 9 0
13 13 50 9 0
13 13 49 1 0
13 13 48 1 0
13 13 47 1 0
13 13 46 1 0
13 13 45 0 16
13 13 44 1 0
13 13 43 1 0
13 13 42 1 0
13 13 41 1 0
13 13 40 1 0
13 13 39 1 0
13 13 38 1 0
13 13 37 1 0
13 13 36 1 0
13 13 35 1 0
13 13 34 0 16
13 13 33 0 16
13 13 32 1 0
13 13 31 1 0
13 13 30 1 0
13 13 29 3 0
13 13 28 3 0
13 13 27 3 0
13 13 26 3 0
13 13 25 3 0
13 13 24 3 0
13 13 23 3 0
13 13 22 3 0
13 13 21 3 0
13 13 20 3 0
13 13 19 3 0
13 13 18 3 0
13 13 17 3 0
13 13 16 3 0
13 13 15 3 0
13 13 14 3 0
13 13 13 1 16
13 13 12 1 16
13 13 11 1 80
13 14 63 2 36
13 14 62 2 4
13 14 61 3 0
13 14 60 3 0
13 14 59 3 0
13 14 58 3 0
13 14 57 3 0
13 14 56 3 0
13 14 55 3 0
13 14 54 3 0
13 14 53 1 0
13 14 52 9 0
13 14 51 9 0
13 14 50 9 0
13 14 49 1 0
13 14 48 1 0
13 14 47 1 0
13 14 46 1 0
13 14 45 0 0
13 14 44 1 0
13 14 43 1 0
13 14 42 1 0
13 14 41 1 0
13 14 40 1 0
13 14 39 1 0
13 14 38 1 0
13 14 37 1 0
13 14 36 1 0
13 14 35 1 0
13 14 34 0 0
13 14 33 0 0
13 14 32 1 0
13 14 31 1 0
13 14 30 1 0
13 14 29 3 0
13 14 28 3 0
13 14 27 3 0
13 14 26 3 0
13 14 25 3 0
13 14 24 3 0
13 14 23 3 0
13 14 22 3 0
13 14 21 3 0
13 14 20 3 0
13 14 19 3 0
13 14 18 3 0
13 14 17 3 0
13 14 16 3 0
13 14 15 3 0
13 14 14 3 0
13 14 13 1 0
13 14 12 1 0
13 14 11 1 64
13 15 64 2 52
13 15 63 2 4
13 15 62 3 0
13 15 61 3 0
13 15 60 3 0
13 15 59 3 0
13 15 58 3 0
13 15 57 3 0
13 15 56 3 0
13 15 55 3 0
13 15 54 3 0
13 15 53 1 0
13 15 52 9 0
13 15 51 9 0
13 15 50 9 0
13 15 49 1 0
13 15 48 1 0
13 15 47 1 0
13 15 46 1 0
13 15 45 1 0
13 15 44 1 0
13 15 43 1 0
13 15 42 1 0
13 15 41 1 0
13 15 40 1 0
13 15 39 1 0
13 15 38 1 0
13 15 37 1 0
13 15 36 1 0
13 15 35 1 0
13 15 34 1 0
13 15 33 1 0
13 15 32 1 0
13 15 31 1 0
13 15 30 1 0
13 15 29 3 0
13 15 28 3 0
13 15 27 3 0
13 15 26 3 0
13 15 25 3 0
13 15 24 3 0
13 15 23 3 0
13 15 22 3 0
13 15 21 3 0
13 15 20 3 0
13 15 19 3 0
13 15 18 3 0
13 15 17 3 0
13 15 16 3 0
13 15 15 3 0
13 15 14 3 0
13 15 13 3 0
13 15 12 3 0
13 15 11 2 64
13 16 65 1 52
13 16 64 1 4
13 16 63 3 0
13 16 62 3 0
13 16 61 3 0
13 16 60 3 0
13 16 59 3 0
13 16 58 3 0
13 16 57 3 0
13 16 56 9 0
13 16 55 9 0
13 16 54 9 0
13 16 53 9 0
13 16 52 9 0
13 16 51 9 0
13 16 50 9 0
13 16 49 9 0
13 16 48 9 0
13 16 47 9 0
13 16 46 9 0
13 16 45 9 0
13 16 44 9 0
13 16 43 9 0
13 16 42 9 0
13 16 41 9 0
13 16 40 9 0
13 16 39 9 0
13 16 38 9 0
13 16 37 9 0
13 16 36 9 0
13 16 35 9 0
13 16 34 9 0
13 16 33 9 0
13 16 32 9 0
13 16 31 9 0
13 16 30 9 0
13 16 29 3 0
13 16 28 3 0
13 16 27 3 0
13 16 26 3 0
13 16 25 3 0
13 16 24 3 0
13 16 23 3 0
13 16 22 3 0
13 16 21 3 0
13 16 20 3 0
13 16 19 3 0
13 16 18 3 0
13 16 17 3 0
13 16 16 3 0
13 16 15 3 0
13 16 14 3 0
13 16 13 3 0
13 16 12 3 0
13 16 11 2 64
13 17 65 1 36
13 17 64 1 4
13 17 63 3 0
13 17 62 3 0
13 17 61 3 0
13 17 60 3 0
13 17 59 3 0
13 17 58 3 0
13 17 57 3 0
13 17 56 9 0
13 17 55 9 8
13 17 54 9 8
13 17 53 9 8
13 17 52 9 8
13 17 51 9 8
13 17 50 9 8
13 17 49 9 8
13 17 48 9 8
13 17 47 9 8
13 17 46 9 8
13 17 45 9 8
13 17 44 9 8
13 17 43 9 8
13 17 42 9 8
13 17 41 9 8
13 17 40 9 8
13 17 39 9 8
13 17 38 9 8
13 17 37 9 8
13 17 36 9 8
13 17 35 9 8
13 17 34 9 8
13 17 33 9 8
13 17 32 9 8
13 17 31 9 8
13 17 30 9 8
13 17 29 3 0
13 17 28 3 0
13 17 27 3 0
13 17 26 3 0
13 17 25 3 0
13 17 24 3 0
13 17 23 3 0
13 17 22 3 0
13 17 21 3 0
13 17 20 3 0
13 17 19 3 0
13 17 18 3 0
13 17 17 3 0
13 17 16 3 0
13 17 15 3 0
13 17 14 3 0
13 17 13 3 0
13 17 12 3 0
13 17 11 17 64
13 18 65 1 36
13 18 64 1 4
13 18 63 3 0
13 18 62 3 0
13 18 61 3 0
13 18 60 3 0
13 18 59 3 0
13 18 58 3 0
13 18 57 10 0
13 18 56 6 76
13 18 29 4 40
13 18 28 3 0
13 18 27 3 0
13 18 26 3 0
13 18 25 3 0
13 18 24 3 0
13 18 23 3 0
13 18 22 3 0
13 18 21 3 0
13 18 20 3 0
13 18 19 3 0
13 18 18 3 0
13 18 17 3 0
13 18 16 3 0
13 18 15 3 0
13 18 14 3 0
13 18 13 3 0
13 18 12 3 0
13 18 11 2 64
13 19 65 1 36
13 19 64 1 4
13 19 63 3 0
13 19 62 10 0
13 19 61 11 0
13 19 60 11 0
13 19 59 10 0
13 19 58 10 0
13 19 57 6 64
13 19 28 4 32
13 19 27 3 0
13 19 26 3 0
13 19 25 3 0
13 19 24 3 0
13 19 23 3 0
13 19 22 3 0
13 19 21 3 0
13 19 20 3 0
13 19 19 13 0
13 19 18 13 0
13 19 17 13 0
13 19 16 13 0
13 19 15 13 0
13 19 14 13 0
13 19 13 13 0
13 19 12 13 0
13 19 11 17 64
13 20 65 1 36
13 20 64 1 4
13 20 63 3 0
13 20 62 10 8
13 20 61 11 8
13 20 60 11 8
13 20 59 10 8
13 20 58 10 8
13 20 57 6 72
13 20 28 4 40
13 20 27 3 0
13 20 26 3 0
13 20 25 3 0
13 20 24 3 0
13 20 23 3 0
13 20 22 3 0
13 20 21 3 0
13 20 20 3 0
13 20 19 13 0
13 20 18 13 0
13 20 17 13 0
13 20 16 13 0
13 20 15 13 0
13 20 14 13 0
13 20 13 13 0
13 20 12 13 0
13 20 11 2 64
13 21 65 1 36
13 21 64 1 4
13 21 63 3 64
13 21 27 4 40
13 21 26 3 0
13 21 25 3 0
13 21 24 3 0
13 21 23 3 0
13 21 22 3 0
13 21 21 3 0
13 21 20 3 0
13 21 19 13 0
13 21 18 13 0
13 21 17 13 0
13 21 16 13 0
13 21 15 13 0
13 21 14 13 0
13 21 13 13 0
13 21 12 13 0
13 21 11 17 64
13 22 65 2 36
13 22 64 2 4
13 22 63 3 64
13 22 26 4 32
13 22 25 3 0
13 22 24 3 0
13 22 23 3 0
13 22 22 3 0
13 22 21 3 0
13 22 20 3 0
13 22 19 13 0
13 22 18 13 0
13 22 17 13 0
13 22 16 13 0
13 22 15 13 0
13 22 14 13 0
13 22 13 13 0
13 22 12 13 0
13 22 11 13 0
13 22 10 12 16
13 22 9 12 80
13 23 65 2 44
13 23 64 2 12
13 23 63 3 72
13 23 26 4 40
13 23 25 3 0
13 23 24 3 0
13 23 23 3 0
13 23 22 3 0
13 23 21 3 0
13 23 20 3 0
13 23 19 13 0
13 23 18 13 0
13 23 17 13 0
13 23 16 13 0
13 23 15 13 0
13 23 14 13 0
13 23 13 13 0
13 23 12 13 0
13 23 11 13 0
13 23 10 12 0
13 23 9 12 64
13 24 25 4 40
13 24 24 3 0
13 24 23 3 0
13 24 22 3 0
13 24 21 7 0
13 24 20 7 0
13 24 19 7 0
13 24 18 7 0
13 24 17 7 0
13 24 16 7 0
13 24 15 7 0
13 24 14 7 0
13 24 13 7 0
13 24 12 7 0
13 24 11 7 0
13 24 10 7 0
13 24 9 2 64
13 25 24 4 32
13 25 23 9 0
13 25 22 9 0
13 25 21 9 0
13 25 20 9 0
13 25 19 9 0
13 25 18 9 0
13 25 17 9 0
13 25 16 9 0
13 25 15 9 0
13 25 14 9 0
13 25 13 9 0
13 25 12 9 0
13 25 11 7 0
13 25 10 7 0
13 25 9 2 64
13 26 24 4 40
13 26 23 9 8
13 26 22 9 8
13 26 21 9 8
13 26 20 9 8
13 26 19 9 8
13 26 18 9 8
13 26 17 9 8
13 26 16 9 8
13 26 15 9 8
13 26 14 9 8
13 26 13 9 8
13 26 12 9 8
13 26 11 7 0
13 26 10 7 0
13 26 9 2 72
13 27 11 7 40
13 27 10 7 76
14 4 56 1 48
14 4 55 1 16
14 4 54 1 16
14 4 53 1 16
14 4 52 1 16
14 4 51 1 16
14 4 50 1 16
14 4 49 1 16
14 4 48 1 16
14 4 47 1 16
14 4 46 1 16
14 4 45 1 16
14 4 44 1 16
14 4 43 1 16
14 4 42 1 16
14 4 41 1 16
14 4 40 1 16
14 4 39 1 16
14 4 38 1 16
14 4 37 1 16
14 4 36 1 16
14 4 35 1 16
14 4 34 1 16
14 4 33 1 16
14 4 32 1 16
14 4 31 1 16
14 4 30 1 16
14 4 29 1 16
14 4 28 1 16
14 4 27 1 16
14 4 26 1 16
14 4 25 1 16
14 4 24 1 16
14 4 23 1 80
14 5 56 1 32
14 5 55 1 0
14 5 54 1 0
14 5 53 1 0
14 5 52 1 0
14 5 51 1 0
14 5 50 1 0
14 5 49 1 0
14 5 48 1 0
14 5 47 1 0
14 5 46 1 0
14 5 45 1 0
14 5 44 1 0
14 5 43 1 0
14 5 42 1 0
14 5 41 1 0
14 5 40 1 0
14 5 39 1 0
14 5 38 1 0
14 5 37 1 0
14 5 36 1 0
14 5 35 1 0
14 5 34 1 0
14 5 33 1 0
14 5 32 1 0
14 5 31 1 0
14 5 30 1 0
14 5 29 1 0
14 5 28 1 0
14 5 27 1 0
14 5 26 1 0
14 5 25 1 0
14 5 24 1 0
14 5 23 1 64
14 6 57 2 48
14 6 56 2 0
14 6 55 2 0
14 6 54 2 0
14 6 53 2 0
14 6 52 2 0
14 6 51 9 0
14 6 50 9 0
14 6 49 2 0
14 6 48 2 0
14 6 47 2 0
14 6 46 2 0
14 6 45 2 0
14 6 44 2 0
14 6 43 2 0
14 6 42 2 0
14 6 41 2 0
14 6 40 2 0
14 6 39 2 0
14 6 38 2 0
14 6 37 2 0
14 6 36 2 0
14 6 35 2 0
14 6 34 2 0
14 6 33 2 0
14 6 32 2 0
14 6 31 2 0
14 6 30 2 0
14 6 29 2 0
14 6 28 2 0
14 6 27 2 0
14 6 26 2 0
14 6 25 2 0
14 6 24 2 0
14 6 23 2 64
14 7 58 2 48
14 7 57 2 0
14 7 56 3 0
14 7 55 3 0
14 7 54 3 0
14 7 53 3 0
14 7 52 3 0
14 7 51 9 0
14 7 50 9 0
14 7 49 3 0
14 7 48 3 0
14 7 47 3 0
14 7 46 3 0
14 7 45 3 0
14 7 44 3 0
14 7 43 3 0
14 7 42 3 0
14 7 41 3 0
14 7 40 3 0
14 7 39 3 0
14 7 38 3 0
14 7 37 3 0
14 7 36 3 0
14 7 35 3 0
14 7 34 3 0
14 7 33 3 0
14 7 32 3 0
14 7 31 3 0
14 7 30 3 0
14 7 29 3 0
14 7 28 3 0
14 7 27 3 0
14 7 26 3 0
14 7 25 3 0
14 7 24 3 0
14 7 23 2 64
14 8 58 2 32
14 8 57 2 0
14 8 56 3 0
14 8 55 3 0
14 8 54 3 0
14 8 53 3 0
14 8 52 3 0
14 8 51 9 0
14 8 50 9 0
14 8 49 3 0
14 8 48 3 0
14 8 47 3 0
14 8 46 3 0
14 8 45 3 0
14 8 44 3 0
14 8 43 3 0
14 8 42 3 0
14 8 41 3 0
14 8 40 3 0
14 8 39 3 0
14 8 38 3 0
14 8 37 3 0
14 8 36 3 0
14 8 35 3 0
14 8 34 3 0
14 8 33 3 0
14 8 32 3 0
14 8 31 3 0
14 8 30 3 0
14 8 29 3 0
14 8 28 3 0
14 8 27 3 0
14 8 26 3 0
14 8 25 3 0
14 8 24 3 0
14 8 23 2 64
14 9 59 2 48
14 9 58 2 0
14 9 57 3 0
14 9 56 3 0
14 9 55 3 0
14 9 54 3 0
14 9 53 3 0
14 9 52 3 0
14 9 51 9 0
14 9 50 9 0
14 9 49 3 0
14 9 48 3 0
14 9 47 3 0
14 9 46 3 0
14 9 45 3 0
14 9 44 3 0
14 9 43 3 0
14 9 42 3 0
14 9 41 3 0
14 9 40 0 8
14 9 39 0 8
14 9 38 3 0
14 9 37 3 0
14 9 36 3 0
14 9 35 3 0
14 9 34 0 8
14 9 33 0 8
14 9 32 3 0
14 9 31 3 0
14 9 30 3 0
14 9 29 3 0
14 9 28 3 0
14 9 27 3 0
14 9 26 3 0
14 9 25 3 0
14 9 24 3 0
14 9 23 3 0
14 9 22 2 16
14 9 21 2 16
14 9 20 2 80
14 10 61 2 48
14 10 60 2 16
14 10 59 2 0
14 10 58 3 0
14 10 57 3 0
14 10 56 3 0
14 10 55 3 0
14 10 54 3 0
14 10 53 3 0
14 10 52 3 0
14 10 51 9 0
14 10 50 9 0
14 10 49 3 0
14 10 48 3 0
14 10 47 3 0
14 10 46 0 0
14 10 45 0 0
14 10 44 3 0
14 10 43 3 0
14 10 42 3 0
14 10 41 0 64
14 10 38 0 32
14 10 37 3 0
14 10 36 3 0
14 10 35 0 64
14 10 32 0 32
14 10 31 3 0
14 10 30 3 0
14 10 29 3 0
14 10 28 3 0
14 10 27 3 0
14 10 26 3 0
14 10 25 3 0
14 10 24 3 0
14 10 23 3 0
14 10 22 3 0
14 10 21 3 0
14 10 20 3 0
14 10 19 2 16
14 10 18 2 80
14 11 61 2 32
14 11 60 2 0
14 11 59 2 0
14 11 58 3 0
14 11 57 3 0
14 11 56 3 0
14 11 55 3 0
14 11 54 3 0
14 11 53 3 0
14 11 52 3 0
14 11 51 9 0
14 11 50 9 0
14 11 49 3 0
14 11 48 3 0
14 11 47 3 0
14 11 46 0 0
14 11 45 0 8
14 11 44 3 0
14 11 43 3 0
14 11 42 3 0
14 11 41 0 64
14 11 38 0 32
14 11 37 3 0
14 11 36 3 0
14 11 35 0 64
14 11 32 0 32
14 11 31 3 0
14 11 30 3 0
14 11 29 3 0
14 11 28 3 0
14 11 27 3 0
14 11 26 3 0
14 11 25 3 0
14 11 24 3 0
14 11 23 3 0
14 11 22 3 0
14 11 21 3 0
14 11 20 3 0
14 11 19 2 0
14 11 18 2 64
14 12 63 2 48
14 12 62 2 16
14 12 61 2 0
14 12 60 2 0
14 12 59 3 0
14 12 58 3 0
14 12 57 3 0
14 12 56 3 0
14 12 55 3 0
14 12 54 3 0
14 12 53 1 0
14 12 52 1 0
14 12 51 9 0
14 12 50 9 0
14 12 49 1 0
14 12 48 1 0
14 12 47 1 0
14 12 46 0 64
14 12 44 0 32
14 12 43 1 0
14 12 42 1 0
14 12 41 1 0
14 12 40 0 16
14 12 39 0 16
14 12 38 1 0
14 12 37 1 0
14 12 36 1 0
14 12 35 0 64
14 12 32 0 32
14 12 31 1 0
14 12 30 1 0
14 12 29 3 0
14 12 28 3 0
14 12 27 3 0
14 12 26 3 0
14 12 25 3 0
14 12 24 3 0
14 12 23 3 0
14 12 22 3 0
14 12 21 3 0
14 12 20 3 0
14 12 19 3 0
14 12 18 3 0
14 12 17 2 16
14 12 16 2 16
14 12 15 2 16
14 12 14 2 80
14 13 63 2 32
14 13 62 2 0
14 13 61 3 0
14 13 60 3 0
14 13 59 3 0
14 13 58 3 0
14 13 57 3 0
14 13 56 3 0
14 13 55 3 0
14 13 54 3 0
14 13 53 1 0
14 13 52 9 0
14 13 51 9 0
14 13 50 9 0
14 13 49 1 0
14 13 48 1 0
14 13 47 1 0
14 13 46 1 0
14 13 45 0 16
14 13 44 1 0
14 13 43 1 0
14 13 42 1 0
14 13 41 1 0
14 13 40 1 0
14 13 39 1 0
14 13 38 1 0
14 13 37 1 0
14 13 36 1 0
14 13 35 1 0
14 13 34 0 16
14 13 33 0 16
14 13 32 1 0
14 13 31 1 0
14 13 30 1 0
14 13 29 3 0
14 13 28 3 0
14 13 27 3 0
14 13 26 3 0
14 13 25 3 0
14 13 24 3 0
14 13 23 3 0
14 13 22 3 0
14 13 21 3 0
14 13 20 3 0
14 13 19 3 0
14 13 18 3 0
14 13 17 3 0
14 13 16 3 0
14 13 15 3 0
14 13 14 3 0
14 13 13 1 16
14 13 12 1 16
14 13 11 1 80
14 14 63 2 32
14 14 62 2 0
14 14 61 3 0
14 14 60 3 0
14 14 59 3 0
14 14 58 3 0
14 14 57 3 0
14 14 56 3 0
14 14 55 3 0
14 14 54 3 0
14 14 53 1 0
14 14 52 9 0
14 14 51 9 0
14 14 50 9 0
14 14 49 1 0
14 14 48 1 0
14 14 47 1 0
14 14 46 1 0
14 14 45 0 0
14 14 44 1 0
14 14 43 1 0
14 14 42 1 0
14 14 41 1 0
14 14 40 1 0
14 14 39 1 0
14 14 38 1 0
14 14 37 1 0
14 14 36 1 0
14 14 35 1 0
14 14 34 0 0
14 14 33 0 0
14 14 32 1 0
14 14 31 1 0
14 14 30 1 0
14 14 29 3 0
14 14 28 3 0
14 14 27 3 0
14 14 26 3 0
14 14 25 3 0
14 14 24 3 0
14 14 23 3 0
14 14 22 3 0
14 14 21 3 0
14 14 20 3 0
14 14 19 3 0
14 14 18 3 0
14 14 17 3 0
14 14 16 3 0
14 14 15 3 0
14 14 14 3 0
14 14 13 1 0
14 14 12 1 0
14 14 11 1 64
14 15 64 2 48
14 15 63 2 0
14 15 62 3 0
14 15 61 3 0
14 15 60 3 0
14 15 59 3 0
14 15 58 3 0
14 15 57 3 0
14 15 56 3 0
14 15 55 3 0
14 15 54 3 0
14 15 53 1 0
14 15 52 9 0
14 15 51 9 0
14 15 50 9 0
14 15 49 1 0
14 15 48 1 0
14 15 47 1 0
14 15 46 1 0
14 15 45 1 0
14 15 44 1 0
14 15 43 1 0
14 15 42 1 0
14 15 41 1 0
14 15 40 1 0
14 15 39 1 0
14 15 38 1 0
14 15 37 1 0
14 15 36 1 0
14 15 35 1 0
14 15 34 1 0
14 15 33 1 0
14 15 32 1 0
14 15 31 1 0
14 15 30 1 0
14 15 29 3 0
14 15 28 3 0
14 15 27 3 0
14 15 26 3 0
14 15 25 3 0
14 15 24 3 0
14 15 23 3 0
14 15 22 3 0
14 15 21 3 0
14 15 20 3 0
14 15 19 3 0
14 15 18 3 0
14 15 17 3 0
14 15 16 3 0
14 15 15 3 0
14 15 14 3 0
14 15 13 3 0
14 15 12 3 0
14 15 11 2 64
14 16 65 1 48
14 16 64 1 0
14 16 63 3 0
14 16 62 3 0
14 16 61 3 0
14 16 60 3 0
14 16 59 3 0
14 16 58 3 0
14 16 57 3 0
14 16 56 9 0
14 16 55 9 0
14 16 54 9 0
14 16 53 9 0
14 16 52 9 0
14 16 51 9 0
14 16 50 9 0
14 16 49 9 0
14 16 48 9 0
14 16 47 9 0
14 16 46 9 0
14 16 45 9 0
14 16 44 9 0
14 16 43 9 0
14 16 42 9 0
14 16 41 9 0
14 16 40 9 0
14 16 39 9 0
14 16 38 9 0
14 16 37 9 0
14 16 36 9 0
14 16 35 9 0
14 16 34 9 0
14 16 33 9 0
14 16 32 9 0
14 16 31 9 0
14 16 30 9 0
14 16 29 3 0
14 16 28 3 0
14 16 27 3 0
14 16 26 3 0
14 16 25 3 0
14 16 24 3 0
14 16 23 3 0
14 16 22 3 0
14 16 21 3 0
14 16 20 3 0
14 16 19 3 0
14 16 18 3 0
14 16 17 3 0
14 16 16 3 0
14 16 15 3 0
14 16 14 3 0
14 16 13 3 0
14 16 12 3 0
14 16 11 2 64
14 17 65 1 32
14 17 64 1 0
14 17 63 3 0
14 17 62 3 0
14 17 61 3 0
14 17 60 3 0
14 17 59 3 0
14 17 58 3 0
14 17 57 3 0
14 17 56 9 0
14 17 55 9 8
14 17 54 9 8
14 17 53 9 8
14 17 52 9 8
14 17 51 9 8
14 17 50 9 8
14 17 49 9 8
14 17 48 9 8
14 17 47 9 8
14 17 46 9 8
14 17 45 9 8
14 17 44 9 8
14 17 43 9 8
14 17 42 9 8
14 17 41 9 8
14 17 40 9 8
14 17 39 9 8
14 17 38 9 8
14 17 37 9 8
14 17 36 9 8
14 17 35 9 8
14 17 34 9 8
14 17 33 9 8
14 17 32 9 8
14 17 31 9 8
14 17 30 9 8
14 17 29 3 0
14 17 28 3 0
14 17 27 3 0
14 17 26 3 0
14 17 25 3 0
14 17 24 3 0
14 17 23 3 0
14 17 22 3 0
14 17 21 3 0
14 17 20 3 0
14 17 19 3 0
14 17 18 3 0
14 17 17 3 0
14 17 16 3 0
14 17 15 3 0
14 17 14 3 0
14 17 13 3 0
14 17 12 3 0
14 17 11 17 64
14 18 65 1 32
14 18 64 1 0
14 18 63 3 0
14 18 62 3 0
14 18 61 3 0
14 18 60 3 0
14 18 59 3 0
14 18 58 3 0
14 18 57 10 0
14 18 56 6 72
14 18 29 4 40
14 18 28 3 0
14 18 27 3 0
14 18 26 3 0
14 18 25 3 0
14 18 24 3 0
14 18 23 3 0
14 18 22 3 0
14 18 21 3 0
14 18 20 3 0
14 18 19 3 0
14 18 18 3 0
14 18 17 3 0
14 18 16 3 0
14 18 15 3 0
14 18 14 3 0
14 18 13 3 0
14 18 12 3 0
14 18 11 2 64
14 19 65 1 32
14 19 64 1 0
14 19 63 3 0
14 19 62 10 0
14 19 61 11 0
14 19 60 11 0
14 19 59 10 0
14 19 58 10 0
14 19 57 6 64
14 19 28 4 32
14 19 27 3 0
14 19 26 3 0
14 19 25 3 0
14 19 24 3 0
14 19 23 3 0
14 19 22 3 0
14 19 21 3 0
14 19 20 3 0
14 19 19 13 0
14 19 18 13 0
14 19 17 13 0
14 19 16 13 0
14 19 15 13 0
14 19 14 13 0
14 19 13 13 0
14 19 12 13 0
14 19 11 17 64
14 20 65 1 32
14 20 64 1 0
14 20 63 3 0
14 20 62 10 8
14 20 61 11 8
14 20 60 11 8
14 20 59 10 8
14 20 58 10 8
14 20 57 6 72
14 20 28 4 40
14 20 27 3 0
14 20 26 3 0
14 20 25 3 0
14 20 24 3 0
14 20 23 3 0
14 20 22 3 0
14 20 21 3 0
14 20 20 3 0
14 20 19 13 0
14 20 18 13 0
14 20 17 13 0
14 20 16 13 0
14 20 15 13 0
14 20 14 13 0
14 20 13 13 0
14 20 12 13 0
14 20 11 2 64
14 21 65 1 32
14 21 64 1 2
14 21 63 3 66
14 21 27 4 40
14 21 26 3 0
14 21 25 3 0
14 21 24 3 0
14 21 23 3 0
14 21 22 3 0
14 21 21 3 0
14 21 20 3 0
14 21 19 13 0
14 21 18 13 0
14 21 17 13 0
14 21 16 13 0
14 21 15 13 0
14 21 14 13 0
14 21 13 13 0
14 21 12 13 0
14 21 11 17 64
14 22 65 2 32
14 22 64 2 2
14 22 63 3 66
14 22 26 4 32
14 22 25 3 0
14 22 24 3 0
14 22 23 3 0
14 22 22 3 0
14 22 21 3 0
14 22 20 3 0
14 22 19 13 0
14 22 18 13 0
14 22 17 13 0
14 22 16 13 0
14 22 15 13 0
14 22 14 13 0
14 22 13 13 0
14 22 12 13 0
14 22 11 13 0
14 22 10 12 16
14 22 9 12 80
14 23 65 2 40
14 23 64 2 10
14 23 63 3 74
14 23 26 4 40
14 23 25 3 0
14 23 24 3 0
14 23 23 3 0
14 23 22 3 0
14 23 21 3 0
14 23 20 3 0
14 23 19 13 0
14 23 18 13 0
14 23 17 13 0
14 23 16 13 0
14 23 15 13 0
14 23 14 13 0
14 23 13 13 0
14 23 12 13 0
14 23 11 13 0
14 23 10 12 0
14 23 9 12 64
14 24 25 4 40
14 24 24 3 0
14 24 23 3 0
14 24 22 3 0
14 24 21 7 0
14 24 20 7 0
14 24 19 7 0
14 24 18 7 0
14 24 17 7 0
14 24 16 7 0
14 24 15 7 0
14 24 14 7 0
14 24 13 7 0
14 24 12 7 0
14 24 11 7 0
14 24 10 7 0
14 24 9 2 64
14 25 24 4 32
14 25 23 9 0
14 25 22 9 0
14 25 21 9 0
14 25 20 9 0
14 25 19 9 0
14 25 18 9 0
14 25 17 9 0
14 25 16 9 0
14 25 15 9 0
14 25 14 9 0
14 25 13 9 0
14 25 12 9 0
14 25 11 7 0
14 25 10 7 0
14 25 9 2 64
14 26 24 4 40
14 26 23 9 8
14 26 22 9 8
14 26 21 9 8
14 26 20 9 8
14 26 19 9 8
14 26 18 9 8
14 26 17 9 8
14 26 16 9 8
14 26 15 9 8
14 26 14 9 8
14 26 13 9 8
14 26 12 9 8
14 26 11 7 0
14 26 10 7 0
14 26 9 2 72
14 27 11 7 40
14 27 10 7 72
15 4 56 1 48
15 4 55 1 16
15 4 54 1 16
15 4 53 1 16
15 4 52 1 16
15 4 51 1 16
15 4 50 1 16
15 4 49 1 16
15 4 48 1 16
15 4 47 1 16
15 4 46 1 16
15 4 45 1 16
15 4 44 1 16
15 4 43 1 16
15 4 42 1 16
15 4 41 1 16
15 4 40 1 16
15 4 39 1 16
15 4 38 1 16
15 4 37 1 16
15 4 36 1 16
15 4 35 1 16
15 4 34 1 16
15 4 33 1 16
15 4 32 1 16
15 4 31 1 16
15 4 30 1 16
15 4 29 1 16
15 4 28 1 16
15 4 27 1 16
15 4 26 1 16
15 4 25 1 16
15 4 24 1 16
15 4 23 1 16
15 4 22 1 84
15 5 56 1 32
15 5 55 1 0
15 5 54 1 0
15 5 53 1 0
15 5 52 1 0
15 5 51 1 0
15 5 50 1 0
15 5 49 1 0
15 5 48 1 0
15 5 47 1 0
15 5 46 1 0
15 5 45 1 0
15 5 44 1 0
15 5 43 1 0
15 5 42 1 0
15 5 41 1 0
15 5 40 1 0
15 5 39 1 0
15 5 38 1 0
15 5 37 1 0
15 5 36 1 0
15 5 35 1 0
15 5 34 1 0
15 5 33 1 0
15 5 32 1 0
15 5 31 1 0
15 5 30 1 0
15 5 29 1 0
15 5 28 1 0
15 5 27 1 0
15 5 26 1 0
15 5 25 1 0
15 5 24 1 0
15 5 23 1 0
15 5 22 1 68
15 6 57 1 48
15 6 56 3 0
15 6 55 3 0
15 6 54 3 0
15 6 53 3 0
15 6 52 3 0
15 6 51 9 0
15 6 50 9 0
15 6 49 9 0
15 6 48 9 0
15 6 47 9 0
15 6 46 9 0
15 6 45 9 0
15 6 44 9 0
15 6 43 9 0
15 6 42 9 0
15 6 41 9 0
15 6 40 9 0
15 6 39 9 0
15 6 38 3 0
15 6 37 3 0
15 6 36 3 0
15 6 35 3 0
15 6 34 3 0
15 6 33 3 0
15 6 32 3 0
15 6 31 3 0
15 6 30 3 0
15 6 29 3 0
15 6 28 3 0
15 6 27 3 0
15 6 26 3 0
15 6 25 3 0
15 6 24 3 0
15 6 23 3 0
15 6 22 2 4
15 6 21 1 84
15 7 60 1 52
15 7 59 2 20
15 7 58 2 16
15 7 57 3 0
15 7 56 3 0
15 7 55 3 0
15 7 54 3 0
15 7 53 3 0
15 7 52 3 0
15 7 51 9 0
15 7 50 9 0
15 7 49 9 0
15 7 48 9 0
15 7 47 9 0
15 7 46 9 0
15 7 45 9 0
15 7 44 9 0
15 7 43 9 0
15 7 42 9 0
15 7 41 9 0
15 7 40 9 0
15 7 39 9 0
15 7 38 3 0
15 7 37 3 0
15 7 36 3 0
15 7 35 3 0
15 7 34 3 0
15 7 33 3 0
15 7 32 3 0
15 7 31 3 0
15 7 30 3 0
15 7 29 3 0
15 7 28 3 0
15 7 27 3 0
15 7 26 3 0
15 7 25 3 0
15 7 24 3 0
15 7 23 3 0
15 7 22 2 4
15 7 21 2 4
15 7 20 2 84
15 8 60 1 36
15 8 59 2 4
15 8 58 2 0
15 8 57 3 0
15 8 56 3 0
15 8 55 3 0
15 8 54 3 0
15 8 53 3 0
15 8 52 3 0
15 8 51 9 0
15 8 50 9 0
15 8 49 9 0
15 8 48 9 0
15 8 47 9 0
15 8 46 9 0
15 8 45 9 0
15 8 44 9 0
15 8 43 9 0
15 8 42 9 0
15 8 41 9 0
15 8 40 9 0
15 8 39 9 0
15 8 38 3 0
15 8 37 3 0
15 8 36 3 0
15 8 35 3 0
15 8 34 3 0
15 8 33 3 0
15 8 32 3 0
15 8 31 3 0
15 8 30 3 0
15 8 29 3 0
15 8 28 3 0
15 8 27 3 0
15 8 26 3 0
15 8 25 3 0
15 8 24 3 0
15 8 23 3 0
15 8 22 2 4
15 8 21 2 4
15 8 20 2 68
15 9 63 2 52
15 9 62 2 20
15 9 61 2 20
15 9 60 2 4
15 9 59 2 0
15 9 58 3 0
15 9 57 3 0
15 9 56 3 0
15 9 55 3 0
15 9 54 3 0
15 9 53 3 0
15 9 52 3 0
15 9 51 9 0
15 9 50 9 0
15 9 49 9 0
15 9 48 9 0
15 9 47 9 0
15 9 46 9 0
15 9 45 9 0
15 9 44 9 0
15 9 43 9 0
15 9 42 9 0
15 9 41 9 0
15 9 40 9 0
15 9 39 9 0
15 9 38 3 0
15 9 37 3 0
15 9 36 3 0
15 9 35 3 0
15 9 34 0 8
15 9 33 0 8
15 9 32 3 0
15 9 31 3 0
15 9 30 3 0
15 9 29 3 0
15 9 28 3 0
15 9 27 3 0
15 9 26 3 0
15 9 25 3 0
15 9 24 3 0
15 9 23 3 0
15 9 22 3 0
15 9 21 3 0
15 9 20 3 0
15 9 19 2 20
15 9 18 2 84
15 10 64 2 52
15 10 63 2 4
15 10 62 2 4
15 10 61 3 0
15 10 60 3 0
15 10 59 3 0
15 10 58 3 0
15 10 57 3 0
15 10 56 3 0
15 10 55 3 0
15 10 54 3 0
15 10 53 3 0
15 10 52 3 0
15 10 51 9 0
15 10 50 9 0
15 10 49 9 0
15 10 48 9 0
15 10 47 9 0
15 10 46 0 0
15 10 45 0 0
15 10 44 9 0
15 10 43 9 0
15 10 42 9 0
15 10 41 9 0
15 10 40 0 4
15 10 39 0 4
15 10 38 3 0
15 10 37 3 0
15 10 36 3 0
15 10 35 0 64
15 10 32 0 32
15 10 31 3 0
15 10 30 3 0
15 10 29 3 0
15 10 28 3 0
15 10 27 3 0
15 10 26 3 0
15 10 25 3 0
15 10 24 3 0
15 10 23 3 0
15 10 22 3 0
15 10 21 3 0
15 10 20 3 0
15 10 19 3 0
15 10 18 3 0
15 10 17 2 20
15 10 16 2 84
15 11 64 2 36
15 11 63 2 4
15 11 62 2 4
15 11 61 3 0
15 11 60 3 0
15 11 59 3 0
15 11 58 3 0
15 11 57 3 0
15 11 56 3 0
15 11 55 3 0
15 11 54 3 0
15 11 53 3 0
15 11 52 3 0
15 11 51 9 0
15 11 50 9 0
15 11 49 9 0
15 11 48 9 0
15 11 47 9 0
15 11 46 0 0
15 11 45 0 8
15 11 44 9 0
15 11 43 9 0
15 11 42 9 0
15 11 41 9 0
15 11 40 0 4
15 11 39 0 4
15 11 38 3 0
15 11 37 3 0
15 11 36 3 0
15 11 35 0 64
15 11 32 0 32
15 11 31 3 0
15 11 30 3 0
15 11 29 3 0
15 11 28 3 0
15 11 27 3 0
15 11 26 3 0
15 11 25 3 0
15 11 24 3 0
15 11 23 3 0
15 11 22 3 0
15 11 21 3 0
15 11 20 3 0
15 11 19 3 0
15 11 18 3 0
15 11 17 2 4
15 11 16 2 68
15 12 65 2 52
15 12 64 2 4
15 12 63 2 0
15 12 62 2 0
15 12 61 3 0
15 12 60 3 0
15 12 59 3 0
15 12 58 3 0
15 12 57 3 0
15 12 56 3 0
15 12 55 3 0
15 12 54 3 0
15 12 53 1 0
15 12 52 9 0
15 12 51 9 0
15 12 50 9 0
15 12 49 9 0
15 12 48 9 0
15 12 47 9 0
15 12 46 0 64
15 12 44 0 32
15 12 43 9 0
15 12 42 9 0
15 12 41 9 0
15 12 40 0 0
15 12 39 0 0
15 12 38 1 0
15 12 37 1 0
15 12 36 1 0
15 12 35 0 64
15 12 32 0 32
15 12 31 1 0
15 12 30 1 0
15 12 29 3 0
15 12 28 3 0
15 12 27 3 0
15 12 26 3 0
15 12 25 3 0
15 12 24 3 0
15 12 23 3 0
15 12 22 3 0
15 12 21 3 0
15 12 20 3 0
15 12 19 3 0
15 12 18 3 0
15 12 17 3 0
15 12 16 3 0
15 12 15 2 16
15 12 14 2 16
15 12 13 1 84
15 13 66 2 52
15 13 65 2 4
15 13 64 2 4
15 13 63 3 0
15 13 62 3 0
15 13 61 3 0
15 13 60 3 0
15 13 59 3 0
15 13 58 3 0
15 13 57 3 0
15 13 56 3 0
15 13 55 3 0
15 13 54 3 0
15 13 53 1 0
15 13 52 9 0
15 13 51 9 0
15 13 50 9 0
15 13 49 9 0
15 13 48 9 0
15 13 47 9 0
15 13 46 9 0
15 13 45 0 16
15 13 44 9 0
15 13 43 9 0
15 13 42 9 0
15 13 41 9 0
15 13 40 9 0
15 13 39 9 0
15 13 38 1 0
15 13 37 1 0
15 13 36 1 0
15 13 35 1 0
15 13 34 0 16
15 13 33 0 16
15 13 32 1 0
15 13 31 1 0
15 13 30 1 0
15 13 29 3 0
15 13 28 3 0
15 13 27 3 0
15 13 26 3 0
15 13 25 3 0
15 13 24 3 0
15 13 23 3 0
15 13 22 3 0
15 13 21 3 0
15 13 20 3 0
15 13 19 3 0
15 13 18 3 0
15 13 17 3 0
15 13 16 3 0
15 13 15 3 0
15 13 14 3 0
15 13 13 1 0
15 13 12 1 16
15 13 11 1 80
15 14 66 2 36
15 14 65 2 4
15 14 64 2 4
15 14 63 3 0
15 14 62 3 0
15 14 61 3 0
15 14 60 3 0
15 14 59 3 0
15 14 58 3 0
15 14 57 3 0
15 14 56 3 0
15 14 55 3 0
15 14 54 3 0
15 14 53 1 0
15 14 52 9 0
15 14 51 9 0
15 14 50 9 0
15 14 49 9 0
15 14 48 9 0
15 14 47 9 0
15 14 46 9 0
15 14 45 0 0
15 14 44 9 0
15 14 43 9 0
15 14 42 9 0
15 14 41 9 0
15 14 40 9 0
15 14 39 9 0
15 14 38 1 0
15 14 37 1 0
15 14 36 1 0
15 14 35 1 0
15 14 34 0 0
15 14 33 0 0
15 14 32 1 0
15 14 31 1 0
15 14 30 1 0
15 14 29 3 0
15 14 28 3 0
15 14 27 3 0
15 14 26 3 0
15 14 25 3 0
15 14 24 3 0
15 14 23 3 0
15 14 22 3 0
15 14 21 3 0
15 14 20 3 0
15 14 19 3 0
15 14 18 3 0
15 14 17 3 0
15 14 16 3 0
15 14 15 3 0
15 14 14 3 0
15 14 13 1 0
15 14 12 1 0
15 14 11 1 64
15 15 67 2 52
15 15 66 2 4
15 15 65 2 4
15 15 64 3 0
15 15 63 3 0
15 15 62 3 0
15 15 61 3 0
15 15 60 3 0
15 15 59 3 0
15 15 58 3 0
15 15 57 3 0
15 15 56 3 0
15 15 55 3 0
15 15 54 3 0
15 15 53 1 0
15 15 52 9 0
15 15 51 9 0
15 15 50 9 0
15 15 49 9 0
15 15 48 9 0
15 15 47 9 0
15 15 46 9 0
15 15 45 9 0
15 15 44 9 0
15 15 43 9 0
15 15 42 9 0
15 15 41 9 0
15 15 40 9 0
15 15 39 9 0
15 15 38 1 0
15 15 37 1 0
15 15 36 1 0
15 15 35 1 0
15 15 34 1 0
15 15 33 1 0
15 15 32 1 0
15 15 31 1 0
15 15 30 1 0
15 15 29 3 0
15 15 28 3 0
15 15 27 3 0
15 15 26 3 0
15 15 25 3 0
15 15 24 3 0
15 15 23 3 0
15 15 22 3 0
15 15 21 3 0
15 15 20 3 0
15 15 19 3 0
15 15 18 3 0
15 15 17 3 0
15 15 16 3 0
15 15 15 3 0
15 15 14 3 0
15 15 13 3 0
15 15 12 3 0
15 15 11 2 64
15 16 69 2 52
15 16 68 2 20
15 16 67 2 4
15 16 66 2 4
15 16 65 3 0
15 16 64 3 0
15 16 63 3 0
15 16 62 3 0
15 16 61 3 0
15 16 60 3 0
15 16 59 3 0
15 16 58 3 0
15 16 57 3 0
15 16 56 9 0
15 16 55 11 0
15 16 54 11 0
15 16 53 11 0
15 16 52 11 0
15 16 51 11 0
15 16 50 11 0
15 16 49 11 0
15 16 48 11 0
15 16 47 11 0
15 16 46 9 0
15 16 45 9 0
15 16 44 9 0
15 16 43 9 0
15 16 42 11 0
15 16 41 11 0
15 16 40 11 0
15 16 39 11 0
15 16 38 11 0
15 16 37 11 0
15 16 36 11 0
15 16 35 9 0
15 16 34 9 0
15 16 33 9 0
15 16 32 9 0
15 16 31 9 0
15 16 30 9 0
15 16 29 3 0
15 16 28 3 0
15 16 27 3 0
15 16 26 3 0
15 16 25 3 0
15 16 24 3 0
15 16 23 3 0
15 16 22 3 0
15 16 21 3 0
15 16 20 3 0
15 16 19 3 0
15 16 18 3 0
15 16 17 3 0
15 16 16 3 0
15 16 15 3 0
15 16 14 3 0
15 16 13 3 0
15 16 12 3 0
15 16 11 2 64
15 17 69 2 44
15 17 68 2 12
15 17 67 2 4
15 17 66 2 4
15 17 65 3 0
15 17 64 3 0
15 17 63 3 0
15 17 62 3 0
15 17 61 3 0
15 17 60 3 0
15 17 59 3 0
15 17 58 3 0
15 17 57 3 0
15 17 56 9 0
15 17 55 11 8
15 17 54 11 8
15 17 53 11 8
15 17 52 11 8
15 17 51 11 8
15 17 50 11 8
15 17 49 11 8
15 17 48 11 8
15 17 47 11 8
15 17 46 9 8
15 17 45 9 8
15 17 44 9 8
15 17 43 9 8
15 17 42 11 8
15 17 41 11 8
15 17 40 11 8
15 17 39 11 8
15 17 38 11 8
15 17 37 11 8
15 17 36 11 8
15 17 35 9 8
15 17 34 9 8
15 17 33 9 8
15 17 32 9 8
15 17 31 9 8
15 17 30 9 8
15 17 29 3 0
15 17 28 3 0
15 17 27 3 0
15 17 26 3 0
15 17 25 3 0
15 17 24 3 0
15 17 23 3 0
15 17 22 3 0
15 17 21 3 0
15 17 20 3 0
15 17 19 3 0
15 17 18 3 0
15 17 17 3 0
15 17 16 3 0
15 17 15 3 0
15 17 14 3 0
15 17 13 3 0
15 17 12 3 0
15 17 11 2 64
15 18 67 1 36
15 18 66 1 4
15 18 65 3 0
15 18 64 3 0
15 18 63 3 0
15 18 62 3 0
15 18 61 3 0
15 18 60 3 0
15 18 59 3 0
15 18 58 3 0
15 18 57 3 0
15 18 56 6 72
15 18 29 4 40
15 18 28 3 0
15 18 27 3 0
15 18 26 3 0
15 18 25 3 0
15 18 24 3 0
15 18 23 3 0
15 18 22 3 0
15 18 21 3 0
15 18 20 3 0
15 18 19 3 0
15 18 18 3 0
15 18 17 3 0
15 18 16 3 0
15 18 15 3 0
15 18 14 3 0
15 18 13 3 0
15 18 12 3 0
15 18 11 2 64
15 19 67 1 36
15 19 66 1 4
15 19 65 3 0
15 19 64 10 0
15 19 63 11 0
15 19 62 11 0
15 19 61 10 0
15 19 60 10 0
15 19 59 10 0
15 19 58 10 0
15 19 57 6 64
15 19 28 4 32
15 19 27 3 0
15 19 26 3 0
15 19 25 3 0
15 19 24 3 0
15 19 23 3 0
15 19 22 3 0
15 19 21 3 0
15 19 20 3 0
15 19 19 13 0
15 19 18 13 0
15 19 17 13 0
15 19 16 13 0
15 19 15 13 0
15 19 14 13 0
15 19 13 13 0
15 19 12 13 0
15 19 11 2 64
15 20 67 1 36
15 20 66 1 4
15 20 65 3 0
15 20 64 10 8
15 20 63 11 8
15 20 62 11 8
15 20 61 10 8
15 20 60 10 8
15 20 59 10 8
15 20 58 10 8
15 20 57 6 72
15 20 28 4 40
15 20 27 3 0
15 20 26 3 0
15 20 25 3 0
15 20 24 3 0
15 20 23 3 0
15 20 22 3 0
15 20 21 3 0
15 20 20 3 0
15 20 19 13 0
15 20 18 13 0
15 20 17 13 0
15 20 16 13 0
15 20 15 13 0
15 20 14 13 0
15 20 13 13 0
15 20 12 13 0
15 20 11 2 64
15 21 67 1 36
15 21 66 1 4
15 21 65 3 64
15 21 27 4 40
15 21 26 3 0
15 21 25 3 0
15 21 24 3 0
15 21 23 3 0
15 21 22 3 0
15 21 21 3 0
15 21 20 3 0
15 21 19 13 0
15 21 18 13 0
15 21 17 13 0
15 21 16 13 0
15 21 15 13 0
15 21 14 13 0
15 21 13 13 0
15 21 12 13 0
15 21 11 2 64
15 22 67 1 36
15 22 66 1 4
15 22 65 3 64
15 22 26 4 32
15 22 25 3 0
15 22 24 3 0
15 22 23 3 0
15 22 22 3 0
15 22 21 3 0
15 22 20 3 0
15 22 19 13 0
15 22 18 13 0
15 22 17 13 0
15 22 16 13 0
15 22 15 13 0
15 22 14 13 0
15 22 13 13 0
15 22 12 13 0
15 22 11 13 0
15 22 10 12 16
15 22 9 12 80
15 23 67 1 36
15 23 66 1 4
15 23 65 3 72
15 23 26 4 40
15 23 25 3 0
15 23 24 3 0
15 23 23 3 0
15 23 22 3 0
15 23 21 3 0
15 23 20 3 0
15 23 19 13 0
15 23 18 13 0
15 23 17 13 0
15 23 16 13 0
15 23 15 13 0
15 23 14 13 0
15 23 13 13 0
15 23 12 13 0
15 23 11 13 0
15 23 10 12 0
15 23 9 12 64
15 24 67 2 44
15 24 66 2 76
15 24 25 4 40
15 24 24 7 0
15 24 23 7 0
15 24 22 7 0
15 24 21 7 0
15 24 20 7 0
15 24 19 7 0
15 24 18 7 0
15 24 17 7 0
15 24 16 7 0
15 24 15 7 0
15 24 14 7 0
15 24 13 7 0
15 24 12 7 0
15 24 11 7 0
15 24 10 7 0
15 24 9 2 64
15 25 24 4 32
15 25 23 9 0
15 25 22 11 0
15 25 21 11 0
15 25 20 11 0
15 25 19 11 0
15 25 18 11 0
15 25 17 11 0
15 25 16 11 0
15 25 15 11 0
15 25 14 11 0
15 25 13 9 0
15 25 12 9 0
15 25 11 7 0
15 25 10 7 0
15 25 9 2 64
15 26 24 4 40
15 26 23 9 8
15 26 22 11 8
15 26 21 11 8
15 26 20 11 8
15 26 19 11 8
15 26 18 11 8
15 26 17 11 8
15 26 16 11 8
15 26 15 11 8
15 26 14 11 8
15 26 13 9 8
15 26 12 9 8
15 26 11 7 0
15 26 10 7 0
15 26 9 2 72
15 27 11 7 40
15 27 10 7 72
16 4 56 1 48
16 4 55 1 16
16 4 54 1 16
16 4 53 1 16
16 4 52 1 16
16 4 51 1 16
16 4 50 1 16
16 4 49 1 16
16 4 48 1 16
16 4 47 1 16
16 4 46 1 16
16 4 45 1 16
16 4 44 1 16
16 4 43 1 16
16 4 42 1 16
16 4 41 1 16
16 4 40 1 16
16 4 39 1 16
16 4 38 1 16
16 4 37 1 16
16 4 36 1 16
16 4 35 1 16
16 4 34 1 16
16 4 33 1 16
16 4 32 1 16
16 4 31 1 16
16 4 30 1 16
16 4 29 1 16
16 4 28 1 16
16 4 27 1 16
16 4 26 1 16
16 4 25 1 16
16 4 24 1 16
16 4 23 1 16
16 4 22 1 80
16 5 56 1 32
16 5 55 1 0
16 5 54 1 0
16 5 53 1 0
16 5 52 1 0
16 5 51 1 0
16 5 50 1 0
16 5 49 1 0
16 5 48 1 0
16 5 47 1 0
16 5 46 1 0
16 5 45 1 0
16 5 44 1 0
16 5 43 1 0
16 5 42 1 0
16 5 41 1 0
16 5 40 1 0
16 5 39 1 0
16 5 38 1 0
16 5 37 1 0
16 5 36 1 0
16 5 35 1 0
16 5 34 1 0
16 5 33 1 0
16 5 32 1 0
16 5 31 1 0
16 5 30 1 0
16 5 29 1 0
16 5 28 1 0
16 5 27 1 0
16 5 26 1 0
16 5 25 1 0
16 5 24 1 0
16 5 23 1 0
16 5 22 1 64
16 6 57 1 48
16 6 56 3 0
16 6 55 3 0
16 6 54 3 0
16 6 53 3 0
16 6 52 3 0
16 6 51 9 0
16 6 50 9 0
16 6 49 9 0
16 6 48 9 0
16 6 47 9 0
16 6 46 9 0
16 6 45 9 0
16 6 44 9 0
16 6 43 9 0
16 6 42 9 0
16 6 41 9 0
16 6 40 9 0
16 6 39 9 0
16 6 38 3 0
16 6 37 3 0
16 6 36 3 0
16 6 35 3 0
16 6 34 3 0
16 6 33 3 0
16 6 32 3 0
16 6 31 3 0
16 6 30 3 0
16 6 29 3 0
16 6 28 3 0
16 6 27 3 0
16 6 26 3 0
16 6 25 3 0
16 6 24 3 0
16 6 23 3 0
16 6 22 2 0
16 6 21 1 80
16 7 60 1 48
16 7 59 2 16
16 7 58 2 16
16 7 57 3 0
16 7 56 3 0
16 7 55 3 0
16 7 54 3 0
16 7 53 3 0
16 7 52 3 0
16 7 51 9 0
16 7 50 9 0
16 7 49 9 0
16 7 48 9 0
16 7 47 9 0
16 7 46 9 0
16 7 45 9 0
16 7 44 9 0
16 7 43 9 0
16 7 42 9 0
16 7 41 9 0
16 7 40 9 0
16 7 39 9 0
16 7 38 3 0
16 7 37 3 0
16 7 36 3 0
16 7 35 3 0
16 7 34 3 0
16 7 33 3 0
16 7 32 3 0
16 7 31 3 0
16 7 30 3 0
16 7 29 3 0
16 7 28 3 0
16 7 27 3 0
16 7 26 3 0
16 7 25 3 0
16 7 24 3 0
16 7 23 3 0
16 7 22 2 0
16 7 21 2 0
16 7 20 2 80
16 8 60 1 32
16 8 59 2 0
16 8 58 2 0
16 8 57 3 0
16 8 56 3 0
16 8 55 3 0
16 8 54 3 0
16 8 53 3 0
16 8 52 3 0
16 8 51 9 0
16 8 50 9 0
16 8 49 9 0
16 8 48 9 0
16 8 47 9 0
16 8 46 9 0
16 8 45 9 0
16 8 44 9 0
16 8 43 9 0
16 8 42 9 0
16 8 41 9 0
16 8 40 9 0
16 8 39 9 0
16 8 38 3 0
16 8 37 3 0
16 8 36 3 0
16 8 35 3 0
16 8 34 3 0
16 8 33 3 0
16 8 32 3 0
16 8 31 3 0
16 8 30 3 0
16 8 29 3 0
16 8 28 3 0
16 8 27 3 0
16 8 26 3 0
16 8 25 3 0
16 8 24 3 0
16 8 23 3 0
16 8 22 2 0
16 8 21 2 0
16 8 20 2 64
16 9 63 2 48
16 9 62 2 16
16 9 61 2 16
16 9 60 2 0
16 9 59 2 0
16 9 58 3 0
16 9 57 3 0
16 9 56 3 0
16 9 55 3 0
16 9 54 3 0
16 9 53 3 0
16 9 52 3 0
16 9 51 9 0
16 9 50 9 0
16 9 49 9 0
16 9 48 9 0
16 9 47 9 0
16 9 46 9 0
16 9 45 9 0
16 9 44 9 0
16 9 43 9 0
16 9 42 9 0
16 9 41 9 0
16 9 40 9 0
16 9 39 9 0
16 9 38 3 0
16 9 37 3 0
16 9 36 3 0
16 9 35 3 0
16 9 34 0 8
16 9 33 0 8
16 9 32 3 0
16 9 31 3 0
16 9 30 3 0
16 9 29 3 0
16 9 28 3 0
16 9 27 3 0
16 9 26 3 0
16 9 25 3 0
16 9 24 3 0
16 9 23 3 0
16 9 22 3 0
16 9 21 3 0
16 9 20 3 0
16 9 19 2 16
16 9 18 2 80
16 10 64 2 48
16 10 63 2 0
16 10 62 2 0
16 10 61 3 0
16 10 60 3 0
16 10 59 3 0
16 10 58 3 0
16 10 57 3 0
16 10 56 3 0
16 10 55 3 0
16 10 54 3 0
16 10 53 3 0
16 10 52 3 0
16 10 51 9 0
16 10 50 9 0
16 10 49 9 0
16 10 48 9 0
16 10 47 9 0
16 10 46 0 0
16 10 45 0 0
16 10 44 9 0
16 10 43 9 0
16 10 42 9 0
16 10 41 9 0
16 10 40 0 0
16 10 39 0 0
16 10 38 3 0
16 10 37 3 0
16 10 36 3 0
16 10 35 0 64
16 10 32 0 32
16 10 31 3 0
16 10 30 3 0
16 10 29 3 0
16 10 28 3 0
16 10 27 3 0
16 10 26 3 0
16 10 25 3 0
16 10 24 3 0
16 10 23 3 0
16 10 22 3 0
16 10 21 3 0
16 10 20 3 0
16 10 19 3 0
16 10 18 3 0
16 10 17 2 16
16 10 16 2 80
16 11 64 2 32
16 11 63 2 0
16 11 62 2 0
16 11 61 3 0
16 11 60 3 0
16 11 59 3 0
16 11 58 3 0
16 11 57 3 0
16 11 56 3 0
16 11 55 3 0
16 11 54 3 0
16 11 53 3 0
16 11 52 3 0
16 11 51 9 0
16 11 50 9 0
16 11 49 9 0
16 11 48 9 0
16 11 47 9 0
16 11 46 0 0
16 11 45 0 8
16 11 44 9 0
16 11 43 9 0
16 11 42 9 0
16 11 41 9 0
16 11 40 0 0
16 11 39 0 0
16 11 38 3 0
16 11 37 3 0
16 11 36 3 0
16 11 35 0 64
16 11 32 0 32
16 11 31 3 0
16 11 30 3 0
16 11 29 3 0
16 11 28 3 0
16 11 27 3 0
16 11 26 3 0
16 11 25 3 0
16 11 24 3 0
16 11 23 3 0
16 11 22 3 0
16 11 21 3 0
16 11 20 3 0
16 11 19 3 0
16 11 18 3 0
16 11 17 2 0
16 11 16 2 64
16 12 65 2 48
16 12 64 2 0
16 12 63 2 0
16 12 62 2 0
16 12 61 3 0
16 12 60 3 0
16 12 59 3 0
16 12 58 3 0
16 12 57 3 0
16 12 56 3 0
16 12 55 3 0
16 12 54 3 0
16 12 53 1 0
16 12 52 9 0
16 12 51 9 0
16 12 50 9 0
16 12 49 9 0
16 12 48 9 0
16 12 47 9 0
16 12 46 0 64
16 12 44 0 32
16 12 43 9 0
16 12 42 9 0
16 12 41 9 0
16 12 40 0 0
16 12 39 0 0
16 12 38 1 0
16 12 37 1 0
16 12 36 1 0
16 12 35 0 64
16 12 32 0 32
16 12 31 1 0
16 12 30 1 0
16 12 29 3 0
16 12 28 3 0
16 12 27 3 0
16 12 26 3 0
16 12 25 3 0
16 12 24 3 0
16 12 23 3 0
16 12 22 3 0
16 12 21 3 0
16 12 20 3 0
16 12 19 3 0
16 12 18 3 0
16 12 17 3 0
16 12 16 3 0
16 12 15 2 16
16 12 14 2 16
16 12 13 1 80
16 13 66 2 48
16 13 65 2 0
16 13 64 2 0
16 13 63 3 0
16 13 62 3 0
16 13 61 3 0
16 13 60 3 0
16 13 59 3 0
16 13 58 3 0
16 13 57 3 0
16 13 56 3 0
16 13 55 3 0
16 13 54 3 0
16 13 53 1 0
16 13 52 9 0
16 13 51 9 0
16 13 50 9 0
16 13 49 9 0
16 13 48 9 0
16 13 47 9 0
16 13 46 9 0
16 13 45 0 16
16 13 44 9 0
16 13 43 9 0
16 13 42 9 0
16 13 41 9 0
16 13 40 9 0
16 13 39 9 0
16 13 38 1 0
16 13 37 1 0
16 13 36 1 0
16 13 35 1 0
16 13 34 0 16
16 13 33 0 16
16 13 32 1 0
16 13 31 1 0
16 13 30 1 0
16 13 29 3 0
16 13 28 3 0
16 13 27 3 0
16 13 26 3 0
16 13 25 3 0
16 13 24 3 0
16 13 23 3 0
16 13 22 3 0
16 13 21 3 0
16 13 20 3 0
16 13 19 3 0
16 13 18 3 0
16 13 17 3 0
16 13 16 3 0
16 13 15 3 0
16 13 14 3 0
16 13 13 1 0
16 13 12 1 16
16 13 11 1 80
16 14 66 2 32
16 14 65 2 0
16 14 64 2 0
16 14 63 3 0
16 14 62 3 0
16 14 61 3 0
16 14 60 3 0
16 14 59 3 0
16 14 58 3 0
16 14 57 3 0
16 14 56 3 0
16 14 55 3 0
16 14 54 3 0
16 14 53 1 0
16 14 52 9 0
16 14 51 9 0
16 14 50 9 0
16 14 49 9 0
16 14 48 9 0
16 14 47 9 0
16 14 46 9 0
16 14 45 0 0
16 14 44 9 0
16 14 43 9 0
16 14 42 9 0
16 14 41 9 0
16 14 40 9 0
16 14 39 9 0
16 14 38 1 0
16 14 37 1 0
16 14 36 1 0
16 14 35 1 0
16 14 34 0 0
16 14 33 0 0
16 14 32 1 0
16 14 31 1 0
16 14 30 1 0
16 14 29 3 0
16 14 28 3 0
16 14 27 3 0
16 14 26 3 0
16 14 25 3 0
16 14 24 3 0
16 14 23 3 0
16 14 22 3 0
16 14 21 3 0
16 14 20 3 0
16 14 19 3 0
16 14 18 3 0
16 14 17 3 0
16 14 16 3 0
16 14 15 3 0
16 14 14 3 0
16 14 13 1 0
16 14 12 1 0
16 14 11 1 64
16 15 67 2 48
16 15 66 2 0
16 15 65 2 0
16 15 64 3 0
16 15 63 3 0
16 15 62 3 0
16 15 61 3 0
16 15 60 3 0
16 15 59 3 0
16 15 58 3 0
16 15 57 3 0
16 15 56 3 0
16 15 55 3 0
16 15 54 3 0
16 15 53 1 0
16 15 52 9 0
16 15 51 9 0
16 15 50 9 0
16 15 49 9 0
16 15 48 9 0
16 15 47 9 0
16 15 46 9 0
16 15 45 9 0
16 15 44 9 0
16 15 43 9 0
16 15 42 9 0
16 15 41 9 0
16 15 40 9 0
16 15 39 9 0
16 15 38 1 0
16 15 37 1 0
16 15 36 1 0
16 15 35 1 0
16 15 34 1 0
16 15 33 1 0
16 15 32 1 0
16 15 31 1 0
16 15 30 1 0
16 15 29 3 0
16 15 28 3 0
16 15 27 3 0
16 15 26 3 0
16 15 25 3 0
16 15 24 3 0
16 15 23 3 0
16 15 22 3 0
16 15 21 3 0
16 15 20 3 0
16 15 19 3 0
16 15 18 3 0
16 15 17 3 0
16 15 16 3 0
16 15 15 3 0
16 15 14 3 0
16 15 13 3 0
16 15 12 3 0
16 15 11 2 64
16 16 69 2 50
16 16 68 2 16
16 16 67 2 0
16 16 66 2 0
16 16 65 3 0
16 16 64 3 0
16 16 63 3 0
16 16 62 3 0
16 16 61 3 0
16 16 60 3 0
16 16 59 3 0
16 16 58 3 0
16 16 57 3 0
16 16 56 9 0
16 16 55 11 0
16 16 54 11 0
16 16 53 11 0
16 16 52 11 0
16 16 51 11 0
16 16 50 11 0
16 16 49 11 0
16 16 48 11 0
16 16 47 11 0
16 16 46 9 0
16 16 45 9 0
16 16 44 9 0
16 16 43 9 0
16 16 42 11 0
16 16 41 11 0
16 16 40 11 0
16 16 39 11 0
16 16 38 11 0
16 16 37 11 0
16 16 36 11 0
16 16 35 9 0
16 16 34 9 0
16 16 33 9 0
16 16 32 9 0
16 16 31 9 0
16 16 30 9 0
16 16 29 3 0
16 16 28 3 0
16 16 27 3 0
16 16 26 3 0
16 16 25 3 0
16 16 24 3 0
16 16 23 3 0
16 16 22 3 0
16 16 21 3 0
16 16 20 3 0
16 16 19 3 0
16 16 18 3 0
16 16 17 3 0
16 16 16 3 0
16 16 15 3 0
16 16 14 3 0
16 16 13 3 0
16 16 12 3 0
16 16 11 2 64
16 17 69 2 42
16 17 68 2 8
16 17 67 2 0
16 17 66 2 0
16 17 65 3 0
16 17 64 3 0
16 17 63 3 0
16 17 62 3 0
16 17 61 3 0
16 17 60 3 0
16 17 59 3 0
16 17 58 3 0
16 17 57 3 0
16 17 56 9 0
16 17 55 11 8
16 17 54 11 8
16 17 53 11 8
16 17 52 11 8
16 17 51 11 8
16 17 50 11 8
16 17 49 11 8
16 17 48 11 8
16 17 47 11 8
16 17 46 9 8
16 17 45 9 8
16 17 44 9 8
16 17 43 9 8
16 17 42 11 8
16 17 41 11 8
16 17 40 11 8
16 17 39 11 8
16 17 38 11 8
16 17 37 11 8
16 17 36 11 8
16 17 35 9 8
16 17 34 9 8
16 17 33 9 8
16 17 32 9 8
16 17 31 9 8
16 17 30 9 8
16 17 29 3 0
16 17 28 3 0
16 17 27 3 0
16 17 26 3 0
16 17 25 3 0
16 17 24 3 0
16 17 23 3 0
16 17 22 3 0
16 17 21 3 0
16 17 20 3 0
16 17 19 3 0
16 17 18 3 0
16 17 17 3 0
16 17 16 3 0
16 17 15 3 0
16 17 14 3 0
16 17 13 3 0
16 17 12 3 0
16 17 11 2 64
16 18 67 1 32
16 18 66 1 0
16 18 65 3 0
16 18 64 3 0
16 18 63 3 0
16 18 62 3 0
16 18 61 3 0
16 18 60 3 0
16 18 59 3 0
16 18 58 3 0
16 18 57 3 0
16 18 56 6 72
16 18 29 4 40
16 18 28 3 0
16 18 27 3 0
16 18 26 3 0
16 18 25 3 0
16 18 24 3 0
16 18 23 3 0
16 18 22 3 0
16 18 21 3 0
16 18 20 3 0
16 18 19 3 0
16 18 18 3 0
16 18 17 3 0
16 18 16 3 0
16 18 15 3 0
16 18 14 3 0
16 18 13 3 0
16 18 12 3 0
16 18 11 2 64
16 19 67 1 32
16 19 66 1 0
16 19 65 3 0
16 19 64 10 0
16 19 63 11 0
16 19 62 11 0
16 19 61 10 0
16 19 60 10 0
16 19 59 10 0
16 19 58 10 0
16 19 57 6 64
16 19 28 4 34
16 19 27 3 2
16 19 26 3 0
16 19 25 3 0
16 19 24 3 0
16 19 23 3 0
16 19 22 3 0
16 19 21 3 0
16 19 20 3 0
16 19 19 13 0
16 19 18 13 0
16 19 17 13 0
16 19 16 13 0
16 19 15 13 0
16 19 14 13 0
16 19 13 13 0
16 19 12 13 0
16 19 11 2 64
16 20 67 1 32
16 20 66 1 0
16 20 65 3 0
16 20 64 10 8
16 20 63 11 8
16 20 62 11 8
16 20 61 10 8
16 20 60 10 8
16 20 59 10 8
16 20 58 10 8
16 20 57 6 72
16 20 28 4 42
16 20 27 3 2
16 20 26 3 0
16 20 25 3 0
16 20 24 3 0
16 20 23 3 0
16 20 22 3 0
16 20 21 3 0
16 20 20 3 0
16 20 19 13 0
16 20 18 13 0
16 20 17 13 0
16 20 16 13 0
16 20 15 13 0
16 20 14 13 0
16 20 13 13 0
16 20 12 13 0
16 20 11 2 64
16 21 67 1 34
16 21 66 1 2
16 21 65 3 66
16 21 27 4 42
16 21 26 3 0
16 21 25 3 0
16 21 24 3 0
16 21 23 3 0
16 21 22 3 0
16 21 21 3 0
16 21 20 3 0
16 21 19 13 0
16 21 18 13 0
16 21 17 13 0
16 21 16 13 0
16 21 15 13 0
16 21 14 13 0
16 21 13 13 0
16 21 12 13 0
16 21 11 2 64
16 22 67 1 32
16 22 66 1 2
16 22 65 3 66
16 22 26 4 32
16 22 25 3 0
16 22 24 3 0
16 22 23 3 0
16 22 22 3 0
16 22 21 3 0
16 22 20 3 0
16 22 19 13 0
16 22 18 13 0
16 22 17 13 0
16 22 16 13 0
16 22 15 13 0
16 22 14 13 0
16 22 13 13 0
16 22 12 13 0
16 22 11 13 0
16 22 10 12 16
16 22 9 12 80
16 23 67 1 32
16 23 66 1 2
16 23 65 3 74
16 23 26 4 40
16 23 25 3 0
16 23 24 3 0
16 23 23 3 0
16 23 22 3 0
16 23 21 3 0
16 23 20 3 0
16 23 19 13 0
16 23 18 13 0
16 23 17 13 0
16 23 16 13 0
16 23 15 13 0
16 23 14 13 0
16 23 13 13 0
16 23 12 13 0
16 23 11 13 0
16 23 10 12 0
16 23 9 12 64
16 24 67 2 42
16 24 66 2 74
16 24 25 4 40
16 24 24 7 0
16 24 23 7 0
16 24 22 7 0
16 24 21 7 0
16 24 20 7 0
16 24 19 7 0
16 24 18 7 0
16 24 17 7 0
16 24 16 7 0
16 24 15 7 0
16 24 14 7 0
16 24 13 7 0
16 24 12 7 0
16 24 11 7 0
16 24 10 7 0
16 24 9 2 64
16 25 24 4 32
16 25 23 9 0
16 25 22 11 0
16 25 21 11 0
16 25 20 11 0
16 25 19 11 0
16 25 18 11 0
16 25 17 11 0
16 25 16 11 0
16 25 15 11 0
16 25 14 11 0
16 25 13 9 0
16 25 12 9 0
16 25 11 7 0
16 25 10 7 0
16 25 9 2 64
16 26 24 4 40
16 26 23 9 10
16 26 22 11 10
16 26 21 11 10
16 26 20 11 10
16 26 19 11 10
16 26 18 11 10
16 26 17 11 10
16 26 16 11 10
16 26 15 11 10
16 26 14 11 10
16 26 13 9 8
16 26 12 9 8
16 26 11 7 0
16 26 10 7 0
16 26 9 2 72
16 27 11 7 40
16 27 10 7 72
17 4 56 1 48
17 4 55 1 16
17 4 54 1 16
17 4 53 1 16
17 4 52 1 16
17 4 51 1 16
17 4 50 1 16
17 4 49 1 16
17 4 48 1 16
17 4 47 1 16
17 4 46 1 16
17 4 45 1 16
17 4 44 1 16
17 4 43 1 16
17 4 42 1 16
17 4 41 1 16
17 4 40 1 16
17 4 39 1 16
17 4 38 1 16
17 4 37 1 16
17 4 36 1 16
17 4 35 1 16
17 4 34 1 16
17 4 33 1 16
17 4 32 1 16
17 4 31 1 16
17 4 30 1 16
17 4 29 1 16
17 4 28 1 16
17 4 27 1 16
17 4 26 1 16
17 4 25 1 16
17 4 24 1 16
17 4 23 1 16
17 4 22 1 16
17 4 21 1 84
17 5 56 1 32
17 5 55 1 0
17 5 54 1 0
17 5 53 1 0
17 5 52 1 0
17 5 51 1 0
17 5 50 1 0
17 5 49 1 0
17 5 48 1 0
17 5 47 1 0
17 5 46 1 0
17 5 45 1 0
17 5 44 1 0
17 5 43 1 0
17 5 42 1 0
17 5 41 1 0
17 5 40 1 0
17 5 39 1 0
17 5 38 1 0
17 5 37 1 0
17 5 36 1 0
17 5 35 1 0
17 5 34 1 0
17 5 33 1 0
17 5 32 1 0
17 5 31 1 0
17 5 30 1 0
17 5 29 1 0
17 5 28 1 0
17 5 27 1 0
17 5 26 1 0
17 5 25 1 0
17 5 24 1 0
17 5 23 1 0
17 5 22 1 0
17 5 21 1 68
17 6 59 1 52
17 6 58 1 20
17 6 57 1 16
17 6 56 3 0
17 6 55 3 0
17 6 54 3 0
17 6 53 3 0
17 6 52 3 0
17 6 51 9 0
17 6 50 9 0
17 6 49 9 0
17 6 48 9 0
17 6 47 9 0
17 6 46 9 0
17 6 45 9 0
17 6 44 9 0
17 6 43 9 0
17 6 42 9 0
17 6 41 9 0
17 6 40 9 0
17 6 39 9 0
17 6 38 9 0
17 6 37 9 0
17 6 36 9 0
17 6 35 9 0
17 6 34 9 0
17 6 33 9 0
17 6 32 9 0
17 6 31 9 0
17 6 30 9 0
17 6 29 3 0
17 6 28 3 0
17 6 27 3 0
17 6 26 3 0
17 6 25 3 0
17 6 24 3 0
17 6 23 3 0
17 6 22 3 0
17 6 21 3 0
17 6 20 1 84
17 7 62 1 52
17 7 61 1 20
17 7 60 1 16
17 7 59 3 0
17 7 58 3 0
17 7 57 3 0
17 7 56 3 0
17 7 55 3 0
17 7 54 3 0
17 7 53 3 0
17 7 52 3 0
17 7 51 9 0
17 7 50 9 0
17 7 49 9 0
17 7 48 9 0
17 7 47 9 0
17 7 46 9 0
17 7 45 9 0
17 7 44 9 0
17 7 43 9 0
17 7 42 9 0
17 7 41 9 0
17 7 40 9 0
17 7 39 9 0
17 7 38 9 0
17 7 37 9 0
17 7 36 9 0
17 7 35 9 0
17 7 34 9 0
17 7 33 9 0
17 7 32 9 0
17 7 31 9 0
17 7 30 9 0
17 7 29 3 0
17 7 28 3 0
17 7 27 3 0
17 7 26 3 0
17 7 25 3 0
17 7 24 3 0
17 7 23 3 0
17 7 22 3 0
17 7 21 3 0
17 7 20 3 0
17 7 19 2 84
17 8 62 1 36
17 8 61 1 4
17 8 60 1 0
17 8 59 3 0
17 8 58 3 0
17 8 57 3 0
17 8 56 3 0
17 8 55 3 0
17 8 54 3 0
17 8 53 3 0
17 8 52 3 0
17 8 51 9 0
17 8 50 9 0
17 8 49 9 0
17 8 48 9 0
17 8 47 9 0
17 8 46 9 0
17 8 45 9 0
17 8 44 9 0
17 8 43 9 0
17 8 42 9 0
17 8 41 9 0
17 8 40 9 0
17 8 39 9 0
17 8 38 9 0
17 8 37 9 0
17 8 36 9 0
17 8 35 9 0
17 8 34 9 0
17 8 33 9 0
17 8 32 9 0
17 8 31 9 0
17 8 30 9 0
17 8 29 3 0
17 8 28 3 0
17 8 27 3 0
17 8 26 3 0
17 8 25 3 0
17 8 24 3 0
17 8 23 3 0
17 8 22 3 0
17 8 21 3 0
17 8 20 3 0
17 8 19 2 68
17 9 64 1 52
17 9 63 3 16
17 9 62 3 0
17 9 61 3 0
17 9 60 3 0
17 9 59 3 0
17 9 58 3 0
17 9 57 3 0
17 9 56 3 0
17 9 55 3 0
17 9 54 3 0
17 9 53 3 0
17 9 52 3 0
17 9 51 9 0
17 9 50 9 0
17 9 49 9 0
17 9 48 9 0
17 9 47 9 0
17 9 46 9 0
17 9 45 9 0
17 9 44 9 0
17 9 43 9 0
17 9 42 9 0
17 9 41 9 0
17 9 40 9 0
17 9 39 9 0
17 9 38 9 0
17 9 37 9 0
17 9 36 9 0
17 9 35 9 0
17 9 34 0 8
17 9 33 0 8
17 9 32 9 0
17 9 31 9 0
17 9 30 9 0
17 9 29 3 0
17 9 28 3 0
17 9 27 3 0
17 9 26 3 0
17 9 25 3 0
17 9 24 3 0
17 9 23 3 0
17 9 22 3 0
17 9 21 3 0
17 9 20 3 0
17 9 19 3 0
17 9 18 2 16
17 9 17 2 84
17 10 66 2 52
17 10 65 2 20
17 10 64 3 0
17 10 63 3 0
17 10 62 3 0
17 10 61 3 0
17 10 60 3 0
17 10 59 3 0
17 10 58 3 0
17 10 57 3 0
17 10 56 3 0
17 10 55 3 0
17 10 54 3 0
17 10 53 3 0
17 10 52 9 0
17 10 51 9 0
17 10 50 9 0
17 10 49 9 0
17 10 48 9 0
17 10 47 9 0
17 10 46 0 0
17 10 45 0 0
17 10 44 9 0
17 10 43 9 0
17 10 42 9 0
17 10 41 9 0
17 10 40 9 0
17 10 39 9 0
17 10 38 9 0
17 10 37 9 0
17 10 36 9 0
17 10 35 0 64
17 10 32 0 32
17 10 31 9 0
17 10 30 9 0
17 10 29 3 0
17 10 28 3 0
17 10 27 3 0
17 10 26 3 0
17 10 25 3 0
17 10 24 3 0
17 10 23 3 0
17 10 22 3 0
17 10 21 3 0
17 10 20 3 0
17 10 19 3 0
17 10 18 3 0
17 10 17 3 0
17 10 16 2 16
17 10 15 2 84
17 11 66 2 36
17 11 65 2 4
17 11 64 3 0
17 11 63 3 0
17 11 62 3 0
17 11 61 3 0
17 11 60 3 0
17 11 59 3 0
17 11 58 3 0
17 11 57 3 0
17 11 56 3 0
17 11 55 3 0
17 11 54 3 0
17 11 53 3 0
17 11 52 9 0
17 11 51 9 0
17 11 50 9 0
17 11 49 9 0
17 11 48 9 0
17 11 47 9 0
17 11 46 0 0
17 11 45 0 0
17 11 44 9 0
17 11 43 9 0
17 11 42 9 0
17 11 41 9 0
17 11 40 9 0
17 11 39 9 0
17 11 38 9 0
17 11 37 9 0
17 11 36 9 0
17 11 35 0 64
17 11 32 0 32
17 11 31 9 0
17 11 30 9 0
17 11 29 3 0
17 11 28 3 0
17 11 27 3 0
17 11 26 3 0
17 11 25 3 0
17 11 24 3 0
17 11 23 3 0
17 11 22 3 0
17 11 21 3 0
17 11 20 3 0
17 11 19 3 0
17 11 18 3 0
17 11 17 3 0
17 11 16 2 0
17 11 15 2 68
17 12 66 2 36
17 12 65 2 0
17 12 64 2 0
17 12 63 2 0
17 12 62 3 0
17 12 61 3 0
17 12 60 3 0
17 12 59 3 0
17 12 58 3 0
17 12 57 3 0
17 12 56 3 0
17 12 55 3 0
17 12 54 3 0
17 12 53 1 0
17 12 52 9 0
17 12 51 9 0
17 12 50 9 0
17 12 49 9 0
17 12 48 9 0
17 12 47 9 0
17 12 46 0 0
17 12 45 0 4
17 12 44 9 0
17 12 43 9 0
17 12 42 9 0
17 12 41 9 0
17 12 40 9 0
17 12 39 9 0
17 12 38 9 0
17 12 37 9 0
17 12 36 9 0
17 12 35 0 64
17 12 32 0 32
17 12 31 9 0
17 12 30 9 0
17 12 29 3 0
17 12 28 3 0
17 12 27 3 0
17 12 26 3 0
17 12 25 3 0
17 12 24 3 0
17 12 23 3 0
17 12 22 3 0
17 12 21 3 0
17 12 20 3 0
17 12 19 3 0
17 12 18 3 0
17 12 17 3 0
17 12 16 3 0
17 12 15 3 0
17 12 14 2 16
17 12 13 1 80
17 13 67 2 52
17 13 66 2 0
17 13 65 3 0
17 13 64 3 0
17 13 63 3 0
17 13 62 3 0
17 13 61 3 0
17 13 60 3 0
17 13 59 3 0
17 13 58 3 0
17 13 57 3 0
17 13 56 3 0
17 13 55 3 0
17 13 54 3 0
17 13 53 1 0
17 13 52 9 0
17 13 51 9 0
17 13 50 9 0
17 13 49 9 0
17 13 48 9 0
17 13 47 9 0
17 13 46 9 0
17 13 45 9 0
17 13 44 9 0
17 13 43 9 0
17 13 42 9 0
17 13 41 9 0
17 13 40 9 0
17 13 39 9 0
17 13 38 9 0
17 13 37 9 0
17 13 36 9 0
17 13 35 9 0
17 13 34 0 16
17 13 33 0 16
17 13 32 9 0
17 13 31 9 0
17 13 30 9 0
17 13 29 3 0
17 13 28 3 0
17 13 27 3 0
17 13 26 3 0
17 13 25 3 0
17 13 24 3 0
17 13 23 3 0
17 13 22 3 0
17 13 21 3 0
17 13 20 3 0
17 13 19 3 0
17 13 18 3 0
17 13 17 3 0
17 13 16 3 0
17 13 15 3 0
17 13 14 3 0
17 13 13 1 0
17 13 12 1 16
17 13 11 1 80
17 14 67 2 36
17 14 66 2 0
17 14 65 3 0
17 14 64 3 0
17 14 63 3 0
17 14 62 3 0
17 14 61 3 0
17 14 60 3 0
17 14 59 3 0
17 14 58 3 0
17 14 57 3 0
17 14 56 3 0
17 14 55 3 0
17 14 54 3 0
17 14 53 1 0
17 14 52 9 0
17 14 51 9 0
17 14 50 9 0
17 14 49 9 0
17 14 48 9 0
17 14 47 9 0
17 14 46 9 0
17 14 45 9 0
17 14 44 9 0
17 14 43 9 0
17 14 42 9 0
17 14 41 9 0
17 14 40 9 0
17 14 39 9 0
17 14 38 9 0
17 14 37 9 0
17 14 36 9 0
17 14 35 9 0
17 14 34 0 0
17 14 33 0 0
17 14 32 9 0
17 14 31 9 0
17 14 30 9 0
17 14 29 3 0
17 14 28 3 0
17 14 27 3 0
17 14 26 3 0
17 14 25 3 0
17 14 24 3 0
17 14 23 3 0
17 14 22 3 0
17 14 21 3 0
17 14 20 3 0
17 14 19 3 0
17 14 18 3 0
17 14 17 3 0
17 14 16 3 0
17 14 15 3 0
17 14 14 3 0
17 14 13 1 0
17 14 12 1 0
17 14 11 1 64
17 15 69 2 60
17 15 68 2 20
17 15 67 3 0
17 15 66 3 0
17 15 65 3 0
17 15 64 3 0
17 15 63 3 0
17 15 62 3 0
17 15 61 3 0
17 15 60 3 0
17 15 59 3 0
17 15 58 3 0
17 15 57 3 0
17 15 56 3 0
17 15 55 3 0
17 15 54 3 0
17 15 53 1 0
