Qubicle Exchange Format
Version 0.2
www.minddesk.com
21 51 38
10
0.000000 0.000000 0.000000
0.207843 0.454902 0.607843
0.603922 0.219608 0.560784
0.784314 0.200000 0.400000
0.890196 0.890196 0.733333
0.894118 0.200000 0.203922
0.909804 0.913725 0.913725
0.917647 0.447059 0.705882
0.921569 0.282353 0.156863
0.960784 0.533333 0.086275
1 29 17 2 52
1 29 16 2 20
1 29 15 2 20
1 29 14 2 20
1 29 13 2 84
1 30 17 2 36
1 30 16 2 4
1 30 15 2 4
1 30 14 2 4
1 30 13 2 68
1 31 17 2 36
1 31 16 2 4
1 31 15 2 4
1 31 14 2 4
1 31 13 2 68
1 32 17 2 44
1 32 16 2 12
1 32 15 2 12
1 32 14 2 12
1 32 13 2 76
2 29 18 2 60
2 29 17 2 16
2 29 16 2 16
2 29 15 2 16
2 29 14 2 16
2 29 13 2 16
2 29 12 2 84
2 30 17 2 32
2 30 16 3 0
2 30 15 3 0
2 30 14 3 0
2 30 13 3 0
2 30 12 2 4
2 30 11 2 84
2 31 17 2 32
2 31 16 3 0
2 31 15 3 0
2 31 14 3 0
2 31 13 3 0
2 31 12 2 4
2 31 11 2 76
2 32 18 2 60
2 32 17 2 8
2 32 16 2 8
2 32 15 2 8
2 32 14 2 8
2 32 13 2 8
2 32 12 2 76
3 25 19 8 52
3 25 18 8 20
3 25 17 9 20
3 25 16 9 20
3 25 15 8 20
3 25 14 8 20
3 25 13 9 20
3 25 12 9 20
3 25 11 9 20
3 25 10 8 20
3 25 9 9 20
3 25 8 8 20
3 25 7 9 20
3 25 6 8 20
3 25 5 9 20
3 25 4 8 20
3 25 3 9 20
3 25 2 8 84
3 26 20 8 52
3 26 19 5 4
3 26 18 3 4
3 26 17 3 4
3 26 16 5 4
3 26 15 5 4
3 26 14 5 4
3 26 13 3 4
3 26 12 3 4
3 26 11 5 4
3 26 10 5 4
3 26 9 5 4
3 26 8 3 12
3 26 7 8 4
3 26 6 8 4
3 26 5 8 12
3 26 4 8 12
3 26 3 8 12
3 26 2 8 12
3 26 1 8 92
3 27 21 8 52
3 27 20 8 4
3 27 19 5 4
3 27 18 5 4
3 27 17 5 4
3 27 16 3 4
3 27 15 3 4
3 27 14 5 4
3 27 13 3 4
3 27 12 5 4
3 27 11 3 4
3 27 10 5 4
3 27 9 3 68
3 27 7 4 38
3 27 6 4 70
3 28 21 8 36
3 28 20 8 4
3 28 19 3 4
3 28 18 5 4
3 28 17 3 4
3 28 16 3 4
3 28 15 3 4
3 28 14 3 4
3 28 13 3 4
3 28 12 3 4
3 28 11 5 4
3 28 10 5 4
3 28 9 5 68
3 28 7 4 46
3 28 6 4 70
3 29 21 8 36
3 29 20 8 4
3 29 19 5 4
3 29 18 3 0
3 29 17 3 0
3 29 16 3 0
3 29 15 3 0
3 29 14 3 0
3 29 13 3 0
3 29 12 3 0
3 29 11 3 4
3 29 10 3 4
3 29 9 3 68
3 29 6 4 110
3 30 21 8 44
3 30 20 8 4
3 30 19 3 4
3 30 18 5 4
3 30 17 3 0
3 30 16 3 0
3 30 15 3 0
3 30 14 3 0
3 30 13 3 0
3 30 12 3 0
3 30 11 3 0
3 30 10 3 4
3 30 9 5 68
3 31 20 8 44
3 31 19 5 4
3 31 18 3 4
3 31 17 3 0
3 31 16 3 0
3 31 15 3 0
3 31 14 3 0
3 31 13 3 0
3 31 12 3 0
3 31 11 3 0
3 31 10 5 4
3 31 9 3 68
3 32 19 3 44
3 32 18 3 0
3 32 17 3 0
3 32 16 3 0
3 32 15 3 0
3 32 14 3 0
3 32 13 3 0
3 32 12 3 0
3 32 11 5 4
3 32 10 3 4
3 32 9 3 68
3 33 18 8 44
3 33 17 8 4
3 33 16 3 4
3 33 15 3 4
3 33 14 8 4
3 33 13 3 4
3 33 12 5 4
3 33 11 3 4
3 33 10 5 4
3 33 9 5 4
3 33 8 3 20
3 33 7 8 20
3 33 6 8 20
3 33 5 8 20
3 33 4 8 20
3 33 3 8 20
3 33 2 8 92
3 34 17 9 44
3 34 16 8 12
3 34 15 8 12
3 34 14 9 12
3 34 13 8 12
3 34 12 8 12
3 34 11 8 12
3 34 10 3 12
3 34 9 9 12
3 34 8 9 12
3 34 7 8 12
3 34 6 9 12
3 34 5 8 12
3 34 4 9 12
3 34 3 8 76
4 25 20 8 52
4 25 19 9 16
4 25 18 9 16
4 25 17 9 16
4 25 16 9 16
4 25 15 9 16
4 25 14 9 16
4 25 13 9 16
4 25 12 9 16
4 25 11 9 16
4 25 10 9 16
4 25 9 9 16
4 25 8 9 16
4 25 7 9 16
4 25 6 9 16
4 25 5 9 16
4 25 4 9 16
4 25 3 9 16
4 25 2 9 16
4 25 1 9 84
4 26 21 8 52
4 26 20 9 0
4 26 19 3 0
4 26 18 3 0
4 26 17 3 0
4 26 16 3 0
4 26 15 3 0
4 26 14 3 0
4 26 13 3 0
4 26 12 3 0
4 26 11 3 0
4 26 10 3 0
4 26 9 3 0
4 26 8 3 8
4 26 7 9 8
4 26 6 9 8
4 26 5 9 8
4 26 4 9 0
4 26 3 9 0
4 26 2 9 0
4 26 1 8 72
4 27 21 8 32
4 27 20 9 0
4 27 19 3 0
4 27 18 3 0
4 27 17 3 0
4 27 16 3 0
4 27 15 3 0
4 27 14 3 0
4 27 13 3 0
4 27 12 3 0
4 27 11 3 0
4 27 10 3 0
4 27 9 7 64
4 27 4 4 46
4 27 3 4 6
4 27 2 4 70
4 28 21 8 32
4 28 20 9 0
4 28 19 3 0
4 28 18 3 0
4 28 17 3 0
4 28 16 3 0
4 28 15 3 0
4 28 14 3 0
4 28 13 3 0
4 28 12 3 0
4 28 11 3 0
4 28 10 3 0
4 28 9 7 64
4 28 3 4 46
4 28 2 4 70
4 29 21 8 32
4 29 20 9 0
4 29 19 3 0
4 29 18 3 0
4 29 17 3 0
4 29 16 3 0
4 29 15 3 0
4 29 14 3 0
4 29 13 3 0
4 29 12 3 0
4 29 11 3 0
4 29 10 3 0
4 29 9 7 66
4 29 2 4 110
4 30 21 8 32
4 30 20 9 0
4 30 19 3 0
4 30 18 3 0
4 30 17 3 0
4 30 16 3 0
4 30 15 3 0
4 30 14 3 0
4 30 13 3 0
4 30 12 3 0
4 30 11 3 0
4 30 10 3 0
4 30 9 7 66
4 31 21 8 44
4 31 20 9 0
4 31 19 3 0
4 31 18 3 0
4 31 17 3 0
4 31 16 3 0
4 31 15 3 0
4 31 14 3 0
4 31 13 3 0
4 31 12 3 0
4 31 11 3 0
4 31 10 3 0
4 31 9 7 64
4 31 4 4 118
4 32 20 8 44
4 32 19 3 0
4 32 18 3 0
4 32 17 3 0
4 32 16 3 0
4 32 15 3 0
4 32 14 3 0
4 32 13 3 0
4 32 12 3 0
4 32 11 3 0
4 32 10 3 0
4 32 9 7 64
4 32 7 4 118
4 32 5 4 54
4 32 4 4 70
4 33 19 8 44
4 33 18 3 0
4 33 17 3 0
4 33 16 3 0
4 33 15 3 0
4 33 14 3 0
4 33 13 3 0
4 33 12 3 0
4 33 11 3 0
4 33 10 3 0
4 33 9 3 0
4 33 8 3 16
4 33 7 9 0
4 33 6 9 16
4 33 5 8 0
4 33 4 8 0
4 33 3 8 16
4 33 2 8 16
4 33 1 8 92
4 34 18 9 44
4 34 17 9 0
4 34 16 9 0
4 34 15 9 0
4 34 14 9 0
4 34 13 9 0
4 34 12 9 0
4 34 11 9 0
4 34 10 9 0
4 34 9 9 0
4 34 8 9 0
4 34 7 9 0
4 34 6 9 0
4 34 5 9 0
4 34 4 9 0
4 34 3 9 0
4 34 2 9 76
4 35 17 9 44
4 35 16 8 12
4 35 15 9 12
4 35 14 8 12
4 35 13 9 12
4 35 12 9 12
4 35 11 9 12
4 35 10 8 12
4 35 9 8 12
4 35 8 9 12
4 35 7 9 4
4 35 6 9 4
4 35 5 9 4
4 35 4 9 12
4 35 3 9 76
4 36 7 0 36
4 36 6 0 4
4 36 5 0 68
4 37 7 0 36
4 37 6 6 4
4 37 5 0 68
4 38 7 0 44
4 38 6 0 12
4 38 5 0 76
5 24 19 8 52
5 24 18 9 20
5 24 17 9 20
5 24 16 8 20
5 24 15 9 20
5 24 14 9 20
5 24 13 8 20
5 24 12 9 20
5 24 11 8 20
5 24 10 9 20
5 24 9 8 20
5 24 8 9 20
5 24 7 9 20
5 24 6 9 20
5 24 5 8 20
5 24 4 9 20
5 24 3 8 20
5 24 2 8 84
5 25 21 9 52
5 25 20 9 16
5 25 19 9 0
5 25 18 9 0
5 25 17 9 0
5 25 16 9 0
5 25 15 9 0
5 25 14 9 0
5 25 13 9 0
5 25 12 9 0
5 25 11 9 0
5 25 10 9 0
5 25 9 9 0
5 25 8 9 0
5 25 7 9 0
5 25 6 9 0
5 25 5 9 0
5 25 4 9 0
5 25 3 9 0
5 25 2 9 0
5 25 1 9 16
5 25 0 9 84
5 26 22 8 52
5 26 21 9 0
5 26 20 9 0
5 26 19 3 0
5 26 18 3 0
5 26 17 3 0
5 26 16 3 0
5 26 15 3 0
5 26 14 3 0
5 26 13 3 0
5 26 12 3 0
5 26 11 3 0
5 26 10 3 0
5 26 9 3 0
5 26 8 3 8
5 26 7 9 8
5 26 6 9 8
5 26 5 9 8
5 26 4 9 8
5 26 3 9 8
5 26 2 9 8
5 26 1 9 8
5 26 0 8 76
5 27 22 8 36
5 27 21 9 0
5 27 20 9 0
5 27 19 3 0
5 27 18 3 0
5 27 17 3 0
5 27 16 3 0
5 27 15 3 0
5 27 14 3 0
5 27 13 3 0
5 27 12 3 0
5 27 11 3 0
5 27 10 3 0
5 27 9 7 64
5 28 22 8 36
5 28 21 9 0
5 28 20 9 0
5 28 19 3 0
5 28 18 3 0
5 28 17 3 0
5 28 16 3 0
5 28 15 3 0
5 28 14 3 0
5 28 13 3 0
5 28 12 3 0
5 28 11 3 0
5 28 10 3 0
5 28 9 7 72
5 29 22 8 36
5 29 21 9 0
5 29 20 9 0
5 29 19 3 0
5 29 18 3 0
5 29 17 3 0
5 29 16 3 0
5 29 15 3 0
5 29 14 3 0
5 29 13 3 0
5 29 12 3 0
5 29 11 3 0
5 29 10 7 64
5 30 22 8 44
5 30 21 9 0
5 30 20 9 0
5 30 19 3 0
5 30 18 3 0
5 30 17 3 0
5 30 16 3 0
5 30 15 3 0
5 30 14 3 0
5 30 13 3 0
5 30 12 3 0
5 30 11 3 0
5 30 10 7 64
5 31 21 8 32
5 31 20 9 0
5 31 19 3 0
5 31 18 3 0
5 31 17 3 0
5 31 16 3 0
5 31 15 3 0
5 31 14 3 0
5 31 13 3 0
5 31 12 3 0
5 31 11 3 0
5 31 10 3 0
5 31 9 7 80
5 31 1 4 118
5 32 21 8 44
5 32 20 8 8
5 32 19 3 0
5 32 18 3 0
5 32 17 3 0
5 32 16 3 0
5 32 15 3 0
5 32 14 3 0
5 32 13 3 0
5 32 12 3 0
5 32 11 3 0
5 32 10 3 0
5 32 9 7 64
5 32 2 4 54
5 32 1 4 70
5 33 19 3 32
5 33 18 3 0
5 33 17 3 0
5 33 16 3 0
5 33 15 3 0
5 33 14 3 0
5 33 13 3 0
5 33 12 3 0
5 33 11 3 0
5 33 10 3 0
5 33 9 3 0
5 33 8 3 16
5 33 7 9 16
5 33 6 9 16
5 33 5 9 16
5 33 4 9 16
5 33 3 9 16
5 33 2 9 0
5 33 1 8 0
5 33 0 8 92
5 34 19 8 44
5 34 18 9 0
5 34 17 9 0
5 34 16 9 0
5 34 15 9 0
5 34 14 9 0
5 34 13 9 0
5 34 12 9 0
5 34 11 9 0
5 34 10 9 0
5 34 9 9 0
5 34 8 9 0
5 34 7 9 0
5 34 6 9 0
5 34 5 9 0
5 34 4 9 0
5 34 3 9 0
5 34 2 9 0
5 34 1 9 76
5 35 18 8 44
5 35 17 9 8
5 35 16 9 0
5 35 15 9 0
5 35 14 9 0
5 35 13 9 0
5 35 12 9 0
5 35 11 9 0
5 35 10 9 0
5 35 9 9 0
5 35 8 9 0
5 35 7 9 0
5 35 6 9 0
5 35 5 9 0
5 35 4 9 0
5 35 3 9 8
5 35 2 9 76
5 36 16 8 44
5 36 15 8 12
5 36 14 9 12
5 36 13 8 12
5 36 12 9 12
5 36 11 8 12
5 36 10 9 12
5 36 9 8 12
5 36 8 9 12
5 36 7 9 0
5 36 6 9 0
5 36 5 9 0
5 36 4 8 76
5 37 7 9 32
5 37 6 9 0
5 37 5 9 64
5 38 7 9 42
5 38 6 9 10
5 38 5 9 74
6 24 20 9 52
6 24 19 9 16
6 24 18 9 16
6 24 17 9 16
6 24 16 9 16
6 24 15 9 16
6 24 14 9 16
6 24 13 9 16
6 24 12 9 16
6 24 11 9 16
6 24 10 9 16
6 24 9 9 16
6 24 8 9 16
6 24 7 9 16
6 24 6 9 16
6 24 5 9 16
6 24 4 9 16
6 24 3 9 16
6 24 2 9 16
6 24 1 9 84
6 25 22 8 52
6 25 21 9 16
6 25 20 9 0
6 25 19 9 0
6 25 18 9 0
6 25 17 9 0
6 25 16 9 0
6 25 15 9 0
6 25 14 9 0
6 25 13 9 0
6 25 12 9 0
6 25 11 9 0
6 25 10 9 0
6 25 9 9 0
6 25 8 9 0
6 25 7 9 0
6 25 6 9 0
6 25 5 9 0
6 25 4 9 0
6 25 3 9 0
6 25 2 9 0
6 25 1 9 0
6 25 0 9 80
6 26 22 8 32
6 26 21 9 0
6 26 20 9 0
6 26 19 3 0
6 26 18 3 0
6 26 17 3 0
6 26 16 3 0
6 26 15 3 0
6 26 14 3 0
6 26 13 3 0
6 26 12 3 0
6 26 11 3 0
6 26 10 3 0
6 26 9 3 0
6 26 8 3 8
6 26 7 9 8
6 26 6 9 8
6 26 5 9 8
6 26 4 9 8
6 26 3 9 8
6 26 2 9 8
6 26 1 9 8
6 26 0 8 72
6 27 22 8 32
6 27 21 9 0
6 27 20 9 0
6 27 19 3 0
6 27 18 3 0
6 27 17 3 0
6 27 16 3 0
6 27 15 3 0
6 27 14 3 0
6 27 13 3 0
6 27 12 3 0
6 27 11 3 0
6 27 10 3 0
6 27 9 7 66
6 28 22 8 32
6 28 21 9 0
6 28 20 9 0
6 28 19 3 0
6 28 18 3 0
6 28 17 3 0
6 28 16 3 0
6 28 15 3 0
6 28 14 3 0
6 28 13 3 0
6 28 12 3 0
6 28 11 3 0
6 28 10 3 0
6 28 9 7 74
6 29 22 8 32
6 29 21 9 0
6 29 20 9 0
6 29 19 3 0
6 29 18 3 0
6 29 17 3 0
6 29 16 3 0
6 29 15 3 0
6 29 14 3 0
6 29 13 3 0
6 29 12 3 0
6 29 11 3 0
6 29 10 7 66
6 30 22 8 32
6 30 21 9 0
6 30 20 9 0
6 30 19 3 0
6 30 18 3 0
6 30 17 3 0
6 30 16 3 0
6 30 15 3 0
6 30 14 3 0
6 30 13 3 0
6 30 12 3 0
6 30 11 3 0
6 30 10 7 66
6 31 22 8 44
6 31 21 9 0
6 31 20 9 0
6 31 19 3 0
6 31 18 3 0
6 31 17 3 0
6 31 16 3 0
6 31 15 3 0
6 31 14 3 0
6 31 13 3 0
6 31 12 3 0
6 31 11 3 0
6 31 10 7 2
6 31 9 7 82
6 32 21 8 40
6 32 20 8 8
6 32 19 3 0
6 32 18 3 0
6 32 17 3 0
6 32 16 3 0
6 32 15 3 0
6 32 14 3 0
6 32 13 3 0
6 32 12 3 0
6 32 11 3 0
6 32 10 7 2
6 32 9 7 66
6 33 19 3 32
6 33 18 3 0
6 33 17 3 0
6 33 16 3 0
6 33 15 3 0
6 33 14 3 0
6 33 13 3 0
6 33 12 3 0
6 33 11 3 0
6 33 10 3 2
6 33 9 3 2
6 33 8 3 18
6 33 7 9 16
6 33 6 9 16
6 33 5 9 16
6 33 4 9 16
6 33 3 9 16
6 33 2 9 16
6 33 1 9 16
6 33 0 8 80
6 34 19 8 40
6 34 18 9 0
6 34 17 9 0
6 34 16 9 0
6 34 15 9 0
6 34 14 9 0
6 34 13 9 0
6 34 12 9 0
6 34 11 9 0
6 34 10 9 2
6 34 9 9 2
6 34 8 9 2
6 34 7 9 0
6 34 6 9 0
6 34 5 9 0
6 34 4 9 0
6 34 3 9 0
6 34 2 9 0
6 34 1 9 0
6 34 0 9 76
6 35 18 9 40
6 35 17 9 8
6 35 16 9 0
6 35 15 9 0
6 35 14 9 0
6 35 13 9 0
6 35 12 9 0
6 35 11 9 0
6 35 10 9 0
6 35 9 9 0
6 35 8 9 0
6 35 7 9 0
6 35 6 9 0
6 35 5 9 0
6 35 4 9 0
6 35 3 9 0
6 35 2 9 0
6 35 1 9 76
6 36 16 9 40
6 36 15 9 8
6 36 14 9 0
6 36 13 9 0
6 36 12 9 0
6 36 11 9 0
6 36 10 9 0
6 36 9 9 0
6 36 8 9 0
6 36 7 9 0
6 36 6 9 0
6 36 5 9 0
6 36 4 9 8
6 36 3 9 12
6 36 2 9 76
6 37 14 8 44
6 37 13 9 12
6 37 12 9 12
6 37 11 9 12
6 37 10 8 12
6 37 9 9 12
6 37 8 9 12
6 37 7 9 8
6 37 6 9 8
6 37 5 9 72
7 23 18 9 52
7 23 17 9 20
7 23 16 9 20
7 23 15 9 20
7 23 14 9 20
7 23 13 9 20
7 23 12 9 20
7 23 11 9 20
7 23 10 9 20
7 23 9 9 20
7 23 8 9 20
7 23 7 8 20
7 23 6 9 20
7 23 5 9 20
7 23 4 9 20
7 23 3 9 84
7 24 21 9 52
7 24 20 9 16
7 24 19 9 16
7 24 18 9 0
7 24 17 9 0
7 24 16 9 0
7 24 15 9 0
7 24 14 9 0
7 24 13 9 0
7 24 12 9 0
7 24 11 9 0
7 24 10 9 0
7 24 9 9 0
7 24 8 9 0
7 24 7 9 0
7 24 6 9 0
7 24 5 9 0
7 24 4 9 0
7 24 3 9 0
7 24 2 9 16
7 24 1 9 16
7 24 0 9 84
7 25 22 8 48
7 25 21 9 0
7 25 20 9 0
7 25 19 9 0
7 25 18 9 0
7 25 17 9 0
7 25 16 9 0
7 25 15 9 0
7 25 14 9 0
7 25 13 9 0
7 25 12 9 0
7 25 11 9 0
7 25 10 9 0
7 25 9 9 0
7 25 8 9 0
7 25 7 9 0
7 25 6 9 0
7 25 5 9 0
7 25 4 9 0
7 25 3 9 0
7 25 2 9 0
7 25 1 9 0
7 25 0 9 64
7 26 23 8 52
7 26 22 9 0
7 26 21 9 0
7 26 20 9 0
7 26 19 3 0
7 26 18 3 0
7 26 17 3 0
7 26 16 3 0
7 26 15 3 0
7 26 14 3 0
7 26 13 3 0
7 26 12 3 0
7 26 11 3 0
7 26 10 3 0
7 26 9 3 8
7 26 8 3 8
7 26 7 9 8
7 26 6 9 8
7 26 5 9 8
7 26 4 9 8
7 26 3 9 8
7 26 2 9 0
7 26 1 9 0
7 26 0 8 64
7 27 23 8 36
7 27 22 9 0
7 27 21 9 0
7 27 20 9 0
7 27 19 3 0
7 27 18 3 0
7 27 17 3 0
7 27 16 3 0
7 27 15 3 0
7 27 14 3 0
7 27 13 3 0
7 27 12 3 0
7 27 11 3 0
7 27 10 7 64
7 27 2 4 46
7 27 1 4 4
7 27 0 4 68
7 28 23 8 36
7 28 22 9 0
7 28 21 9 0
7 28 20 9 0
7 28 19 3 0
7 28 18 3 0
7 28 17 3 0
7 28 16 3 0
7 28 15 3 0
7 28 14 3 0
7 28 13 3 0
7 28 12 3 0
7 28 11 3 0
7 28 10 7 72
7 28 1 4 46
7 28 0 4 68
7 29 23 8 36
7 29 22 9 0
7 29 21 9 0
7 29 20 9 0
7 29 19 3 0
7 29 18 3 0
7 29 17 3 0
7 29 16 3 0
7 29 15 3 0
7 29 14 3 0
7 29 13 3 0
7 29 12 3 0
7 29 11 7 64
7 29 0 4 108
7 30 23 8 44
7 30 22 9 0
7 30 21 9 0
7 30 20 9 0
7 30 19 3 0
7 30 18 3 0
7 30 17 3 0
7 30 16 3 0
7 30 15 3 0
7 30 14 3 0
7 30 13 3 0
7 30 12 3 0
7 30 11 7 64
7 31 22 8 32
7 31 21 9 0
7 31 20 9 0
7 31 19 3 0
7 31 18 3 0
7 31 17 3 0
7 31 16 3 0
7 31 15 3 0
7 31 14 3 0
7 31 13 3 0
7 31 12 3 0
7 31 11 7 64
7 32 22 8 44
7 32 21 8 8
7 32 20 9 0
7 32 19 3 0
7 32 18 3 0
7 32 17 3 0
7 32 16 3 0
7 32 15 3 0
7 32 14 3 0
7 32 13 3 0
7 32 12 3 0
7 32 11 7 64
7 33 20 8 44
7 33 19 3 0
7 33 18 3 0
7 33 17 3 0
7 33 16 3 0
7 33 15 3 0
7 33 14 3 0
7 33 13 3 0
7 33 12 3 0
7 33 11 3 64
7 33 7 9 48
7 33 6 9 16
7 33 5 9 16
7 33 4 9 16
7 33 3 9 16
7 33 2 9 16
7 33 1 9 16
7 33 0 8 80
7 34 19 8 40
7 34 18 9 0
7 34 17 9 0
7 34 16 9 0
7 34 15 9 0
7 34 14 9 0
7 34 13 9 0
7 34 12 9 0
7 34 11 9 64
7 34 7 9 32
7 34 6 9 0
7 34 5 9 0
7 34 4 9 0
7 34 3 9 0
7 34 2 9 0
7 34 1 9 0
7 34 0 9 64
7 35 18 8 40
7 35 17 9 0
7 35 16 9 0
7 35 15 9 0
7 35 14 9 0
7 35 13 9 0
7 35 12 9 0
7 35 11 9 0
7 35 10 9 16
7 35 9 9 16
7 35 8 9 16
7 35 7 9 0
7 35 6 9 0
7 35 5 9 0
7 35 4 9 0
7 35 3 9 0
7 35 2 9 0
7 35 1 9 0
7 35 0 9 76
7 36 17 8 44
7 36 16 9 8
7 36 15 9 0
7 36 14 9 0
7 36 13 9 0
7 36 12 9 0
7 36 11 9 0
7 36 10 9 0
7 36 9 9 0
7 36 8 9 0
7 36 7 9 0
7 36 6 9 0
7 36 5 9 0
7 36 4 9 0
7 36 3 9 0
7 36 2 9 0
7 36 1 9 76
7 37 15 9 44
7 37 14 9 8
7 37 13 9 8
7 37 12 9 8
7 37 11 9 0
7 37 10 9 0
7 37 9 9 0
7 37 8 9 0
7 37 7 9 0
7 37 6 9 0
7 37 5 9 8
7 37 4 9 12
7 37 3 9 12
7 37 2 9 76
7 38 11 9 44
7 38 10 9 12
7 38 9 9 12
7 38 8 9 12
7 38 7 9 12
7 38 6 9 76
8 23 19 9 52
8 23 18 9 16
8 23 17 9 16
8 23 16 9 16
8 23 15 9 16
8 23 14 9 16
8 23 13 9 16
8 23 12 9 16
8 23 11 9 16
8 23 10 9 16
8 23 9 9 16
8 23 8 9 16
8 23 7 9 16
8 23 6 9 16
8 23 5 9 16
8 23 4 9 16
8 23 3 9 16
8 23 2 9 84
8 24 21 9 48
8 24 20 9 16
8 24 19 9 0
8 24 18 9 0
8 24 17 9 0
8 24 16 9 0
8 24 15 9 0
8 24 14 9 0
8 24 13 9 0
8 24 12 9 0
8 24 11 9 0
8 24 10 9 0
8 24 9 9 0
8 24 8 9 0
8 24 7 9 0
8 24 6 9 0
8 24 5 9 0
8 24 4 9 0
8 24 3 9 0
8 24 2 9 0
8 24 1 9 16
8 24 0 9 80
8 25 22 9 48
8 25 21 9 0
8 25 20 9 0
8 25 19 9 0
8 25 18 9 0
8 25 17 9 0
8 25 16 9 0
8 25 15 9 0
8 25 14 9 0
8 25 13 9 0
8 25 12 9 0
8 25 11 9 0
8 25 10 9 0
8 25 9 9 0
8 25 8 9 0
8 25 7 9 0
8 25 6 9 0
8 25 5 9 0
8 25 4 9 0
8 25 3 9 0
8 25 2 9 0
8 25 1 9 0
8 25 0 9 64
8 26 23 8 48
8 26 22 9 0
8 26 21 9 0
8 26 20 9 0
8 26 19 3 0
8 26 18 3 0
8 26 17 3 0
8 26 16 3 0
8 26 15 3 0
8 26 14 3 0
8 26 13 3 0
8 26 12 3 0
8 26 11 3 0
8 26 10 3 0
8 26 9 3 8
8 26 8 3 8
8 26 7 9 8
8 26 6 9 8
8 26 5 9 8
8 26 4 9 8
8 26 3 9 8
8 26 2 9 8
8 26 1 9 0
8 26 0 8 64
8 27 23 8 32
8 27 22 9 0
8 27 21 9 0
8 27 20 9 0
8 27 19 3 0
8 27 18 3 0
8 27 17 3 0
8 27 16 3 0
8 27 15 3 0
8 27 14 3 0
8 27 13 3 0
8 27 12 3 0
8 27 11 3 0
8 27 10 7 64
8 27 1 4 42
8 27 0 4 66
8 28 23 8 32
8 28 22 9 0
8 28 21 9 0
8 28 20 9 0
8 28 19 3 0
8 28 18 3 0
8 28 17 3 0
8 28 16 3 0
8 28 15 3 0
8 28 14 3 0
8 28 13 3 0
8 28 12 3 0
8 28 11 3 0
8 28 10 7 72
8 28 0 4 98
8 29 23 8 32
8 29 22 9 0
8 29 21 9 0
8 29 20 9 0
8 29 19 3 0
8 29 18 3 0
8 29 17 3 0
8 29 16 3 0
8 29 15 3 0
8 29 14 3 0
8 29 13 3 0
8 29 12 3 0
8 29 11 7 64
8 29 0 4 98
8 30 23 8 32
8 30 22 9 0
8 30 21 9 0
8 30 20 9 0
8 30 19 3 0
8 30 18 3 0
8 30 17 3 0
8 30 16 3 0
8 30 15 3 0
8 30 14 3 0
8 30 13 3 0
8 30 12 3 0
8 30 11 7 64
8 30 0 4 110
8 31 23 8 44
8 31 22 9 0
8 31 21 9 0
8 31 20 9 0
8 31 19 3 0
8 31 18 3 0
8 31 17 3 0
8 31 16 3 0
8 31 15 3 0
8 31 14 3 0
8 31 13 3 0
8 31 12 3 0
8 31 11 7 64
8 32 22 9 40
8 32 21 9 0
8 32 20 9 0
8 32 19 3 0
8 32 18 3 0
8 32 17 3 0
8 32 16 3 0
8 32 15 3 0
8 32 14 3 0
8 32 13 3 0
8 32 12 3 0
8 32 11 7 64
8 33 21 9 44
8 33 20 9 0
8 33 19 3 0
8 33 18 3 0
8 33 17 3 0
8 33 16 3 0
8 33 15 3 0
8 33 14 3 0
8 33 13 3 0
8 33 12 3 0
8 33 11 3 64
8 33 7 9 48
8 33 6 9 16
8 33 5 9 16
8 33 4 9 16
8 33 3 9 16
8 33 2 9 16
8 33 1 9 16
8 33 0 8 80
8 34 20 9 44
8 34 19 9 0
8 34 18 9 0
8 34 17 9 0
8 34 16 9 0
8 34 15 9 0
8 34 14 9 0
8 34 13 9 0
8 34 12 9 0
8 34 11 9 64
8 34 7 9 32
8 34 6 9 0
8 34 5 9 0
8 34 4 9 0
8 34 3 9 0
8 34 2 9 0
8 34 1 9 0
8 34 0 9 64
8 35 19 9 44
8 35 18 9 0
8 35 17 9 0
8 35 16 9 0
8 35 15 9 0
8 35 14 9 0
8 35 13 9 0
8 35 12 9 0
8 35 11 9 0
8 35 10 9 16
8 35 9 9 16
8 35 8 9 16
8 35 7 9 0
8 35 6 9 0
8 35 5 9 0
8 35 4 9 0
8 35 3 9 0
8 35 2 9 0
8 35 1 9 0
8 35 0 9 64
8 36 18 9 44
8 36 17 9 8
8 36 16 9 0
8 36 15 9 0
8 36 14 9 0
8 36 13 9 0
8 36 12 9 0
8 36 11 9 0
8 36 10 9 0
8 36 9 9 0
8 36 8 9 0
8 36 7 9 0
8 36 6 9 0
8 36 5 9 0
8 36 4 9 0
8 36 3 9 0
8 36 2 9 0
8 36 1 9 8
8 36 0 9 76
8 37 16 9 44
8 37 15 9 8
8 37 14 9 0
8 37 13 9 0
8 37 12 9 0
8 37 11 9 0
8 37 10 9 0
8 37 9 9 0
8 37 8 9 0
8 37 7 9 0
8 37 6 9 0
8 37 5 9 0
8 37 4 9 0
8 37 3 9 0
8 37 2 9 64
8 38 14 9 44
8 38 13 9 12
8 38 12 9 12
8 38 11 9 8
8 38 10 9 8
8 38 9 9 8
8 38 8 9 8
8 38 7 9 8
8 38 6 9 8
8 38 5 9 12
8 38 4 9 12
8 38 3 9 12
8 38 2 9 76
9 19 14 1 52
9 19 13 9 20
9 19 12 1 84
9 20 14 1 36
9 20 13 9 4
9 20 12 1 4
9 20 11 1 20
9 20 10 1 84
9 21 36 8 116
9 21 15 9 52
9 21 14 9 4
9 21 13 1 4
9 21 12 1 4
9 21 11 9 4
9 21 10 1 4
9 21 9 9 20
9 21 8 9 84
9 22 36 8 44
9 22 35 8 84
9 22 15 1 36
9 22 14 9 4
9 22 13 9 4
9 22 12 9 4
9 22 11 1 4
9 22 10 9 4
9 22 9 9 4
9 22 8 1 4
9 22 7 9 20
9 22 6 1 84
9 23 35 8 36
9 23 34 8 84
9 23 20 9 52
9 23 19 9 16
9 23 18 9 16
9 23 17 9 16
9 23 16 9 16
9 23 15 9 0
9 23 14 9 0
9 23 13 9 0
9 23 12 9 0
9 23 11 9 0
9 23 10 9 0
9 23 9 9 0
9 23 8 9 0
9 23 7 9 0
9 23 6 9 0
9 23 5 9 16
9 23 4 9 16
9 23 3 9 16
9 23 2 9 16
9 23 1 9 84
9 24 35 8 44
9 24 34 8 12
9 24 33 8 20
9 24 32 8 84
9 24 21 9 48
9 24 20 9 0
9 24 19 9 0
9 24 18 9 0
9 24 17 9 0
9 24 16 9 0
9 24 15 9 0
9 24 14 9 0
9 24 13 9 0
9 24 12 9 0
9 24 11 9 0
9 24 10 9 0
9 24 9 9 0
9 24 8 9 0
9 24 7 9 0
9 24 6 9 0
9 24 5 9 0
9 24 4 9 0
9 24 3 9 0
9 24 2 9 0
9 24 1 9 0
9 24 0 9 80
9 25 33 8 36
9 25 32 8 4
9 25 31 8 84
9 25 23 9 54
9 25 22 9 16
9 25 21 9 0
9 25 20 9 0
9 25 19 9 0
9 25 18 9 0
9 25 17 9 0
9 25 16 9 0
9 25 15 9 0
9 25 14 9 0
9 25 13 9 0
9 25 12 9 0
9 25 11 9 0
9 25 10 9 0
9 25 9 9 0
9 25 8 9 0
9 25 7 9 0
9 25 6 9 0
9 25 5 9 0
9 25 4 9 0
9 25 3 9 0
9 25 2 9 0
9 25 1 9 0
9 25 0 9 64
9 26 33 8 36
9 26 32 8 4
9 26 31 8 4
9 26 30 8 20
9 26 29 8 84
9 26 24 8 52
9 26 23 9 0
9 26 22 9 0
9 26 21 9 0
9 26 20 9 0
9 26 19 3 0
9 26 18 3 0
9 26 17 3 0
9 26 16 3 0
9 26 15 3 0
9 26 14 3 0
9 26 13 3 0
9 26 12 3 0
9 26 11 3 0
9 26 10 3 0
9 26 9 3 8
9 26 8 3 8
9 26 7 9 8
9 26 6 9 8
9 26 5 9 8
9 26 4 9 8
9 26 3 9 8
9 26 2 9 8
9 26 1 9 8
9 26 0 8 72
9 27 33 8 36
9 27 32 8 4
9 27 31 8 4
9 27 30 8 4
9 27 29 8 4
9 27 28 8 84
9 27 25 8 52
9 27 24 8 4
9 27 23 9 0
9 27 22 9 0
9 27 21 9 0
9 27 20 9 0
9 27 19 3 0
9 27 18 3 0
9 27 17 3 0
9 27 16 3 0
9 27 15 3 0
9 27 14 3 0
9 27 13 3 0
9 27 12 3 0
9 27 11 3 0
9 27 10 7 64
9 28 33 8 36
9 28 32 8 4
9 28 31 8 4
9 28 30 8 4
9 28 29 8 4
9 28 28 8 4
9 28 27 8 20
9 28 26 8 20
9 28 25 8 4
9 28 24 8 4
9 28 23 9 0
9 28 22 9 0
9 28 21 9 0
9 28 20 9 0
9 28 19 3 0
9 28 18 3 0
9 28 17 3 0
9 28 16 3 0
9 28 15 3 0
9 28 14 3 0
9 28 13 3 0
9 28 12 3 0
9 28 11 3 0
9 28 10 7 72
9 29 33 8 36
9 29 32 8 4
9 29 31 8 4
9 29 30 8 4
9 29 29 8 4
9 29 28 8 4
9 29 27 8 12
9 29 26 8 12
9 29 25 8 4
9 29 24 8 4
9 29 23 9 0
9 29 22 9 0
9 29 21 9 0
9 29 20 9 0
9 29 19 3 0
9 29 18 3 0
9 29 17 3 0
9 29 16 3 0
9 29 15 3 0
9 29 14 3 0
9 29 13 3 0
9 29 12 3 0
9 29 11 7 64
9 30 33 8 36
9 30 32 8 4
9 30 31 8 4
9 30 30 8 4
9 30 29 8 4
9 30 28 8 76
9 30 25 8 44
9 30 24 8 4
9 30 23 9 0
9 30 22 9 0
9 30 21 9 0
9 30 20 9 0
9 30 19 3 0
9 30 18 3 0
9 30 17 3 0
9 30 16 3 0
9 30 15 3 0
9 30 14 3 0
9 30 13 3 0
9 30 12 3 0
9 30 11 7 64
9 31 33 8 36
9 31 32 8 4
9 31 31 8 4
9 31 30 8 4
9 31 29 8 76
9 31 24 8 44
9 31 23 9 8
9 31 22 9 0
9 31 21 9 0
9 31 20 9 0
9 31 19 3 0
9 31 18 3 0
9 31 17 3 0
9 31 16 3 0
9 31 15 3 0
9 31 14 3 0
9 31 13 3 0
9 31 12 3 0
9 31 11 7 64
9 32 33 8 36
9 32 32 8 4
9 32 31 8 4
9 32 30 8 76
9 32 22 9 40
9 32 21 9 0
9 32 20 9 0
9 32 19 3 0
9 32 18 3 0
9 32 17 3 0
9 32 16 3 0
9 32 15 3 0
9 32 14 3 0
9 32 13 3 0
9 32 12 3 0
9 32 11 7 64
9 33 33 8 36
9 33 32 8 4
9 33 31 8 76
9 33 21 9 40
9 33 20 9 0
9 33 19 3 0
9 33 18 3 0
9 33 17 3 0
9 33 16 3 0
9 33 15 3 0
9 33 14 3 0
9 33 13 3 0
9 33 12 3 0
9 33 11 3 64
9 33 7 9 48
9 33 6 9 16
9 33 5 9 16
9 33 4 9 16
9 33 3 9 16
9 33 2 9 16
9 33 1 9 16
9 33 0 8 80
9 34 33 8 36
9 34 32 8 68
9 34 20 9 40
9 34 19 9 0
9 34 18 9 0
9 34 17 9 0
9 34 16 9 0
9 34 15 9 0
9 34 14 9 0
9 34 13 9 0
9 34 12 9 0
9 34 11 9 64
9 34 7 9 32
9 34 6 9 0
9 34 5 9 0
9 34 4 9 0
9 34 3 9 0
9 34 2 9 0
9 34 1 9 0
9 34 0 9 64
9 35 33 8 36
9 35 32 8 68
9 35 19 9 40
9 35 18 9 0
9 35 17 9 0
9 35 16 9 0
9 35 15 9 0
9 35 14 9 0
9 35 13 9 0
9 35 12 9 0
9 35 11 9 0
9 35 10 9 16
9 35 9 9 16
9 35 8 9 16
9 35 7 9 0
9 35 6 9 0
9 35 5 9 0
9 35 4 9 0
9 35 3 9 0
9 35 2 9 0
9 35 1 9 0
9 35 0 9 64
9 36 33 8 36
9 36 32 8 76
9 36 18 9 40
9 36 17 9 8
9 36 16 9 0
9 36 15 9 0
9 36 14 9 0
9 36 13 9 0
9 36 12 9 0
9 36 11 9 0
9 36 10 9 0
9 36 9 9 0
9 36 8 9 0
9 36 7 9 0
9 36 6 9 0
9 36 5 9 0
9 36 4 9 0
9 36 3 9 0
9 36 2 9 0
9 36 1 9 0
9 36 0 9 72
9 37 35 8 52
9 37 34 8 20
9 37 33 8 68
9 37 16 9 40
9 37 15 9 0
9 37 14 9 0
9 37 13 9 0
9 37 12 9 0
9 37 11 9 0
9 37 10 9 0
9 37 9 9 0
9 37 8 9 0
9 37 7 9 0
9 37 6 9 0
9 37 5 9 0
9 37 4 9 0
9 37 3 9 0
9 37 2 9 0
9 37 1 8 76
9 38 35 8 36
9 38 34 8 4
9 38 33 8 76
9 38 15 9 36
9 38 14 9 0
9 38 13 9 0
9 38 12 9 0
9 38 11 9 0
9 38 10 9 0
9 38 9 9 8
9 38 8 9 0
9 38 7 9 0
9 38 6 9 0
9 38 5 9 0
9 38 4 9 0
9 38 3 9 0
9 38 2 9 72
9 39 36 8 60
9 39 35 8 12
9 39 34 8 76
9 39 15 9 36
9 39 14 1 4
9 39 13 1 4
9 39 12 9 12
9 39 11 9 12
9 39 10 1 76
9 39 8 9 44
9 39 7 1 4
9 39 6 1 4
9 39 5 1 12
9 39 4 9 12
9 39 3 1 76
9 40 15 1 36
9 40 14 1 12
9 40 13 1 76
9 40 7 1 36
9 40 6 1 76
9 41 15 1 108
9 41 7 1 108
10 16 16 1 52
10 16 15 1 20
10 16 14 1 84
10 17 16 1 44
10 17 15 1 4
10 17 14 1 4
10 17 13 1 20
10 17 12 1 84
10 18 15 1 36
10 18 14 1 4
10 18 13 1 4
10 18 12 1 4
10 18 11 1 84
10 19 15 1 36
10 19 14 9 0
10 19 13 9 0
10 19 12 9 0
10 19 11 1 4
10 19 10 1 20
10 19 9 1 84
10 20 16 1 52
10 20 15 1 4
10 20 14 9 0
10 20 13 9 0
10 20 12 9 0
10 20 11 9 0
10 20 10 9 0
10 20 9 9 4
10 20 8 1 20
10 20 7 1 84
10 21 36 9 48
10 21 35 9 20
10 21 34 9 84
10 21 16 1 36
10 21 15 9 0
10 21 14 9 0
10 21 13 9 0
10 21 12 9 0
10 21 11 9 0
10 21 10 9 0
10 21 9 9 0
10 21 8 9 0
10 21 7 1 4
10 21 6 1 20
10 21 5 9 84
10 22 36 9 40
10 22 35 9 0
10 22 34 9 4
10 22 33 8 84
10 22 17 9 52
10 22 16 9 4
10 22 15 9 0
10 22 14 9 0
10 22 13 9 0
10 22 12 9 0
10 22 11 9 0
10 22 10 9 0
10 22 9 9 0
10 22 8 9 0
10 22 7 9 0
10 22 6 9 0
10 22 5 9 68
10 23 35 9 32
10 23 34 9 0
10 23 33 9 4
10 23 32 9 20
10 23 31 9 20
10 23 30 9 84
10 23 20 9 48
10 23 19 9 16
10 23 18 9 16
10 23 17 9 0
10 23 16 9 0
10 23 15 9 0
10 23 14 9 0
10 23 13 9 0
10 23 12 9 0
10 23 11 9 0
10 23 10 9 0
10 23 9 9 0
10 23 8 9 0
10 23 7 9 0
10 23 6 9 0
10 23 5 9 0
10 23 4 9 16
10 23 3 9 16
10 23 2 9 16
10 23 1 9 80
10 24 35 9 40
10 24 34 9 8
10 24 33 9 0
10 24 32 9 0
10 24 31 9 4
10 24 30 8 4
10 24 29 9 20
10 24 28 9 20
10 24 27 8 84
10 24 21 9 48
10 24 20 9 0
10 24 19 9 0
10 24 18 9 0
10 24 17 9 0
10 24 16 9 0
10 24 15 9 0
10 24 14 9 0
10 24 13 9 0
10 24 12 9 0
10 24 11 9 0
10 24 10 9 0
10 24 9 9 0
10 24 8 9 0
10 24 7 9 0
10 24 6 9 0
10 24 5 9 0
10 24 4 9 0
10 24 3 9 0
10 24 2 9 0
10 24 1 9 0
10 24 0 9 80
10 25 33 9 32
10 25 32 9 0
10 25 31 9 0
10 25 30 9 4
10 25 29 9 4
10 25 28 8 4
10 25 27 9 4
10 25 26 9 84
10 25 22 9 48
10 25 21 9 0
10 25 20 9 0
10 25 19 9 0
10 25 18 9 0
10 25 17 9 0
10 25 16 9 0
10 25 15 9 0
10 25 14 9 0
10 25 13 9 0
10 25 12 9 0
10 25 11 9 0
10 25 10 9 0
10 25 9 9 0
10 25 8 9 0
10 25 7 9 0
10 25 6 9 0
10 25 5 9 0
10 25 4 9 0
10 25 3 9 0
10 25 2 9 0
10 25 1 9 0
10 25 0 9 64
10 26 33 9 32
10 26 32 9 0
10 26 31 9 0
10 26 30 9 0
10 26 29 9 0
10 26 28 9 4
10 26 27 9 4
10 26 26 9 4
10 26 25 9 20
10 26 24 9 16
10 26 23 9 16
10 26 22 9 0
10 26 21 9 0
10 26 20 9 0
10 26 19 3 0
10 26 18 3 0
10 26 17 3 0
10 26 16 3 0
10 26 15 3 0
10 26 14 3 0
10 26 13 3 0
10 26 12 3 0
10 26 11 3 0
10 26 10 3 0
10 26 9 3 8
10 26 8 3 8
10 26 7 9 8
10 26 6 9 8
10 26 5 9 8
10 26 4 9 8
10 26 3 9 8
10 26 2 9 8
10 26 1 9 8
10 26 0 8 72
10 27 33 9 32
10 27 32 9 0
10 27 31 9 0
10 27 30 9 0
10 27 29 9 0
10 27 28 9 0
10 27 27 9 4
10 27 26 9 4
10 27 25 9 0
10 27 24 9 0
10 27 23 9 0
10 27 22 9 0
10 27 21 9 0
10 27 20 9 0
10 27 19 3 0
10 27 18 3 0
10 27 17 3 0
10 27 16 3 0
10 27 15 3 0
10 27 14 3 0
10 27 13 3 0
10 27 12 3 0
10 27 11 3 0
10 27 10 7 64
10 28 33 9 32
10 28 32 9 0
10 28 31 9 0
10 28 30 9 0
10 28 29 9 0
10 28 28 9 0
10 28 27 9 0
10 28 26 9 0
10 28 25 9 0
10 28 24 9 0
10 28 23 9 0
10 28 22 9 0
10 28 21 9 0
10 28 20 9 0
10 28 19 3 0
10 28 18 3 0
10 28 17 3 0
10 28 16 3 0
10 28 15 3 0
10 28 14 3 0
10 28 13 3 0
10 28 12 3 0
10 28 11 3 0
10 28 10 7 72
10 29 33 9 32
10 29 32 9 0
10 29 31 9 0
10 29 30 9 0
10 29 29 9 0
10 29 28 9 0
10 29 27 9 0
10 29 26 9 0
10 29 25 9 0
10 29 24 9 0
10 29 23 9 0
10 29 22 9 0
10 29 21 9 0
10 29 20 9 0
10 29 19 3 0
10 29 18 3 0
10 29 17 3 0
10 29 16 3 0
10 29 15 3 0
10 29 14 3 0
10 29 13 3 0
10 29 12 3 0
10 29 11 7 64
10 30 33 9 32
10 30 32 9 0
10 30 31 9 0
10 30 30 9 0
10 30 29 9 0
10 30 28 9 0
10 30 27 9 4
10 30 26 9 4
10 30 25 9 0
10 30 24 9 0
10 30 23 9 0
10 30 22 9 0
10 30 21 9 0
10 30 20 9 0
10 30 19 3 0
10 30 18 3 0
10 30 17 3 0
10 30 16 3 0
10 30 15 3 0
10 30 14 3 0
10 30 13 3 0
10 30 12 3 0
10 30 11 7 64
10 31 33 9 32
10 31 32 9 0
10 31 31 9 0
10 31 30 9 0
10 31 29 9 0
10 31 28 8 4
10 31 27 9 4
10 31 26 9 4
10 31 25 9 12
10 31 24 9 8
10 31 23 9 8
10 31 22 9 0
10 31 21 9 0
10 31 20 9 0
10 31 19 3 0
10 31 18 3 0
10 31 17 3 0
10 31 16 3 0
10 31 15 3 0
10 31 14 3 0
10 31 13 3 0
10 31 12 3 0
10 31 11 7 64
10 32 33 9 32
10 32 32 9 0
10 32 31 9 0
10 32 30 9 0
10 32 29 9 4
10 32 28 9 4
10 32 27 8 4
10 32 26 8 76
10 32 22 9 40
10 32 21 9 0
10 32 20 9 0
10 32 19 3 0
10 32 18 3 0
10 32 17 3 0
10 32 16 3 0
10 32 15 3 0
10 32 14 3 0
10 32 13 3 0
10 32 12 3 0
10 32 11 7 64
10 33 33 9 32
10 33 32 9 0
10 33 31 9 0
10 33 30 8 4
10 33 29 9 4
10 33 28 9 12
10 33 27 9 76
10 33 21 9 40
10 33 20 9 0
10 33 19 3 0
10 33 18 3 0
10 33 17 3 0
10 33 16 3 0
10 33 15 3 0
10 33 14 3 0
10 33 13 3 0
10 33 12 3 0
10 33 11 3 64
10 33 7 9 48
10 33 6 9 16
10 33 5 9 16
10 33 4 9 16
10 33 3 9 16
10 33 2 9 16
10 33 1 9 16
10 33 0 8 80
10 34 33 9 32
10 34 32 9 0
10 34 31 9 4
10 34 30 9 4
10 34 29 8 76
10 34 20 9 40
10 34 19 9 0
10 34 18 9 0
10 34 17 9 0
10 34 16 9 0
10 34 15 9 0
10 34 14 9 0
10 34 13 9 0
10 34 12 9 0
10 34 11 9 64
10 34 7 9 32
10 34 6 9 0
10 34 5 9 0
10 34 4 9 0
10 34 3 9 0
10 34 2 9 0
10 34 1 9 0
10 34 0 9 64
10 35 33 9 32
10 35 32 9 0
10 35 31 9 4
10 35 30 9 76
10 35 19 9 40
10 35 18 9 0
10 35 17 9 0
10 35 16 9 0
10 35 15 9 0
10 35 14 9 0
10 35 13 9 0
10 35 12 9 0
10 35 11 9 0
10 35 10 9 16
10 35 9 9 16
10 35 8 9 16
10 35 7 9 0
10 35 6 9 0
10 35 5 9 0
10 35 4 9 0
10 35 3 9 0
10 35 2 9 0
10 35 1 9 0
10 35 0 9 64
10 36 33 9 32
10 36 32 9 0
10 36 31 9 68
10 36 18 9 40
10 36 17 9 0
10 36 16 9 0
10 36 15 9 0
10 36 14 9 0
10 36 13 9 0
10 36 12 9 0
10 36 11 9 0
10 36 10 9 0
10 36 9 9 0
10 36 8 9 0
10 36 7 9 0
10 36 6 9 0
10 36 5 9 0
10 36 4 9 0
10 36 3 9 0
10 36 2 9 0
10 36 1 9 0
10 36 0 9 72
10 37 35 9 48
10 37 34 9 16
10 37 33 9 0
10 37 32 9 4
10 37 31 8 68
10 37 17 9 44
10 37 16 9 8
10 37 15 9 0
10 37 14 9 0
10 37 13 9 0
10 37 12 9 0
10 37 11 9 0
10 37 10 9 0
10 37 9 9 0
10 37 8 9 0
10 37 7 9 0
10 37 6 9 0
10 37 5 9 0
10 37 4 9 0
10 37 3 9 0
10 37 2 9 0
10 37 1 9 72
10 38 35 9 32
10 38 34 9 0
10 38 33 9 0
10 38 32 9 12
10 38 31 9 76
10 38 15 9 32
10 38 14 9 0
10 38 13 9 0
10 38 12 9 0
10 38 11 9 0
10 38 10 9 0
10 38 9 9 8
10 38 8 9 0
10 38 7 9 0
10 38 6 9 0
10 38 5 9 0
10 38 4 9 0
10 38 3 9 0
10 38 2 9 72
10 39 36 9 48
10 39 35 9 0
10 39 34 9 0
10 39 33 9 76
10 39 16 9 52
10 39 15 9 0
10 39 14 9 0
10 39 13 9 0
10 39 12 9 0
10 39 11 9 0
10 39 10 9 72
10 39 8 9 32
10 39 7 9 0
10 39 6 9 0
10 39 5 9 0
10 39 4 9 0
10 39 3 9 72
10 40 36 9 44
10 40 35 9 12
10 40 34 9 76
10 40 16 1 36
10 40 15 1 0
10 40 14 1 0
10 40 13 1 0
10 40 12 1 4
10 40 11 1 76
10 40 8 1 36
10 40 7 1 0
10 40 6 1 0
10 40 5 1 4
10 40 4 1 76
10 41 16 1 36
10 41 15 1 0
10 41 14 1 4
10 41 13 1 12
10 41 12 1 76
10 41 8 1 36
10 41 7 1 0
10 41 6 1 12
10 41 5 1 76
10 42 16 1 36
10 42 15 1 12
10 42 14 1 76
10 42 8 1 36
10 42 7 1 76
10 43 16 1 108
10 43 8 1 108
11 16 16 1 50
11 16 15 1 18
11 16 14 1 82
11 17 16 1 42
11 17 15 1 2
11 17 14 1 2
11 17 13 1 18
11 17 12 1 82
11 18 15 1 34
11 18 14 1 2
11 18 13 1 2
11 18 12 1 2
11 18 11 1 82
11 19 15 1 34
11 19 14 9 0
11 19 13 9 0
11 19 12 9 0
11 19 11 1 2
11 19 10 1 18
11 19 9 1 82
11 20 16 1 50
11 20 15 1 2
11 20 14 9 0
11 20 13 9 0
11 20 12 9 0
11 20 11 9 0
11 20 10 9 0
11 20 9 9 2
11 20 8 1 18
11 20 7 1 82
11 21 36 9 48
11 21 35 9 18
11 21 34 9 82
11 21 16 1 34
11 21 15 9 0
11 21 14 9 0
11 21 13 9 0
11 21 12 9 0
11 21 11 9 0
11 21 10 9 0
11 21 9 9 0
11 21 8 9 0
11 21 7 1 2
11 21 6 1 18
11 21 5 9 82
11 22 36 9 40
11 22 35 9 0
11 22 34 9 2
11 22 33 8 82
11 22 17 9 50
11 22 16 9 2
11 22 15 9 0
11 22 14 9 0
11 22 13 9 0
11 22 12 9 0
11 22 11 9 0
11 22 10 9 0
11 22 9 9 0
11 22 8 9 0
11 22 7 9 0
11 22 6 9 0
11 22 5 9 66
11 23 35 9 32
11 23 34 9 0
11 23 33 9 2
11 23 32 9 18
11 23 31 9 18
11 23 30 9 82
11 23 20 9 48
11 23 19 9 16
11 23 18 9 16
11 23 17 9 0
11 23 16 9 0
11 23 15 9 0
11 23 14 9 0
11 23 13 9 0
11 23 12 9 0
11 23 11 9 0
11 23 10 9 0
11 23 9 9 0
11 23 8 9 0
11 23 7 9 0
11 23 6 9 0
11 23 5 9 0
11 23 4 9 16
11 23 3 9 16
11 23 2 9 16
11 23 1 9 80
11 24 35 9 40
11 24 34 9 8
11 24 33 9 0
11 24 32 9 0
11 24 31 9 2
11 24 30 8 2
11 24 29 9 18
11 24 28 9 18
11 24 27 8 82
11 24 21 9 48
11 24 20 9 0
11 24 19 9 0
11 24 18 9 0
11 24 17 9 0
11 24 16 9 0
11 24 15 9 0
11 24 14 9 0
11 24 13 9 0
11 24 12 9 0
11 24 11 9 0
11 24 10 9 0
11 24 9 9 0
11 24 8 9 0
11 24 7 9 0
11 24 6 9 0
11 24 5 9 0
11 24 4 9 0
11 24 3 9 0
11 24 2 9 0
11 24 1 9 0
11 24 0 9 80
11 25 33 9 32
11 25 32 9 0
11 25 31 9 0
11 25 30 9 2
11 25 29 9 2
11 25 28 8 2
11 25 27 9 2
11 25 26 9 82
11 25 22 9 48
11 25 21 9 0
11 25 20 9 0
11 25 19 9 0
11 25 18 9 0
11 25 17 9 0
11 25 16 9 0
11 25 15 9 0
11 25 14 9 0
11 25 13 9 0
11 25 12 9 0
11 25 11 9 0
11 25 10 9 0
11 25 9 9 0
11 25 8 9 0
11 25 7 9 0
11 25 6 9 0
11 25 5 9 0
11 25 4 9 0
11 25 3 9 0
11 25 2 9 0
11 25 1 9 0
11 25 0 9 64
11 26 33 9 32
11 26 32 9 0
11 26 31 9 0
11 26 30 9 0
11 26 29 9 0
11 26 28 9 2
11 26 27 9 2
11 26 26 9 2
11 26 25 9 18
11 26 24 9 16
11 26 23 9 16
11 26 22 9 0
11 26 21 9 0
11 26 20 9 0
11 26 19 3 0
11 26 18 3 0
11 26 17 3 0
11 26 16 3 0
11 26 15 3 0
11 26 14 3 0
11 26 13 3 0
11 26 12 3 0
11 26 11 3 0
11 26 10 3 0
11 26 9 3 8
11 26 8 3 8
11 26 7 9 8
11 26 6 9 8
11 26 5 9 8
11 26 4 9 8
11 26 3 9 8
11 26 2 9 8
11 26 1 9 8
11 26 0 8 72
11 27 33 9 32
11 27 32 9 0
11 27 31 9 0
11 27 30 9 0
11 27 29 9 0
11 27 28 9 0
11 27 27 9 2
11 27 26 9 2
11 27 25 9 0
11 27 24 9 0
11 27 23 9 0
11 27 22 9 0
11 27 21 9 0
11 27 20 9 0
11 27 19 3 0
11 27 18 3 0
11 27 17 3 0
11 27 16 3 0
11 27 15 3 0
11 27 14 3 0
11 27 13 3 0
11 27 12 3 0
11 27 11 3 0
11 27 10 7 64
11 28 33 9 32
11 28 32 9 0
11 28 31 9 0
11 28 30 9 0
11 28 29 9 0
11 28 28 9 0
11 28 27 9 0
11 28 26 9 0
11 28 25 9 0
11 28 24 9 0
11 28 23 9 0
11 28 22 9 0
11 28 21 9 0
11 28 20 9 0
11 28 19 3 0
11 28 18 3 0
11 28 17 3 0
11 28 16 3 0
11 28 15 3 0
11 28 14 3 0
11 28 13 3 0
11 28 12 3 0
11 28 11 3 0
11 28 10 7 72
11 29 33 9 32
11 29 32 9 0
11 29 31 9 0
11 29 30 9 0
11 29 29 9 0
11 29 28 9 0
11 29 27 9 0
11 29 26 9 0
11 29 25 9 0
11 29 24 9 0
11 29 23 9 0
11 29 22 9 0
11 29 21 9 0
11 29 20 9 0
11 29 19 3 0
11 29 18 3 0
11 29 17 3 0
11 29 16 3 0
11 29 15 3 0
11 29 14 3 0
11 29 13 3 0
11 29 12 3 0
11 29 11 7 64
11 30 33 9 32
11 30 32 9 0
11 30 31 9 0
11 30 30 9 0
11 30 29 9 0
11 30 28 9 0
11 30 27 9 2
11 30 26 9 2
11 30 25 9 0
11 30 24 9 0
11 30 23 9 0
11 30 22 9 0
11 30 21 9 0
11 30 20 9 0
11 30 19 3 0
11 30 18 3 0
11 30 17 3 0
11 30 16 3 0
11 30 15 3 0
11 30 14 3 0
11 30 13 3 0
11 30 12 3 0
11 30 11 7 64
11 31 33 9 32
11 31 32 9 0
11 31 31 9 0
11 31 30 9 0
11 31 29 9 0
11 31 28 8 2
11 31 27 9 2
11 31 26 9 2
11 31 25 9 10
11 31 24 9 8
11 31 23 9 8
11 31 22 9 0
11 31 21 9 0
11 31 20 9 0
11 31 19 3 0
11 31 18 3 0
11 31 17 3 0
11 31 16 3 0
11 31 15 3 0
11 31 14 3 0
11 31 13 3 0
11 31 12 3 0
11 31 11 7 64
11 32 33 9 32
11 32 32 9 0
11 32 31 9 0
11 32 30 9 0
11 32 29 9 2
11 32 28 9 2
11 32 27 8 2
11 32 26 8 74
11 32 22 9 40
11 32 21 9 0
11 32 20 9 0
11 32 19 3 0
11 32 18 3 0
11 32 17 3 0
11 32 16 3 0
11 32 15 3 0
11 32 14 3 0
11 32 13 3 0
11 32 12 3 0
11 32 11 7 64
11 33 33 9 32
11 33 32 9 0
11 33 31 9 0
11 33 30 8 2
11 33 29 9 2
11 33 28 9 10
11 33 27 9 74
11 33 21 9 40
11 33 20 9 0
11 33 19 3 0
11 33 18 3 0
11 33 17 3 0
11 33 16 3 0
11 33 15 3 0
11 33 14 3 0
11 33 13 3 0
11 33 12 3 0
11 33 11 3 64
11 33 7 9 48
11 33 6 9 16
11 33 5 9 16
11 33 4 9 16
11 33 3 9 16
11 33 2 9 16
11 33 1 9 16
11 33 0 8 80
11 34 33 9 32
11 34 32 9 0
11 34 31 9 2
11 34 30 9 2
11 34 29 8 74
11 34 20 9 40
11 34 19 9 0
11 34 18 9 0
11 34 17 9 0
11 34 16 9 0
11 34 15 9 0
11 34 14 9 0
11 34 13 9 0
11 34 12 9 0
11 34 11 9 64
11 34 7 9 32
11 34 6 9 0
11 34 5 9 0
11 34 4 9 0
11 34 3 9 0
11 34 2 9 0
11 34 1 9 0
11 34 0 9 64
11 35 33 9 32
11 35 32 9 0
11 35 31 9 2
11 35 30 9 74
11 35 19 9 40
11 35 18 9 0
11 35 17 9 0
11 35 16 9 0
11 35 15 9 0
11 35 14 9 0
11 35 13 9 0
11 35 12 9 0
11 35 11 9 0
11 35 10 9 16
11 35 9 9 16
11 35 8 9 16
11 35 7 9 0
11 35 6 9 0
11 35 5 9 0
11 35 4 9 0
11 35 3 9 0
11 35 2 9 0
11 35 1 9 0
11 35 0 9 64
11 36 33 9 32
11 36 32 9 0
11 36 31 9 66
11 36 18 9 40
11 36 17 9 0
11 36 16 9 0
11 36 15 9 0
11 36 14 9 0
11 36 13 9 0
11 36 12 9 0
11 36 11 9 0
11 36 10 9 0
11 36 9 9 0
11 36 8 9 0
11 36 7 9 0
11 36 6 9 0
11 36 5 9 0
11 36 4 9 0
11 36 3 9 0
11 36 2 9 0
11 36 1 9 0
11 36 0 9 72
11 37 35 9 48
11 37 34 9 16
11 37 33 9 0
11 37 32 9 2
11 37 31 8 66
11 37 17 9 42
11 37 16 9 8
11 37 15 9 0
11 37 14 9 0
11 37 13 9 0
11 37 12 9 0
11 37 11 9 0
11 37 10 9 0
11 37 9 9 0
11 37 8 9 0
11 37 7 9 0
11 37 6 9 0
11 37 5 9 0
11 37 4 9 0
11 37 3 9 0
11 37 2 9 0
11 37 1 9 72
11 38 35 9 32
11 38 34 9 0
11 38 33 9 0
11 38 32 9 10
11 38 31 9 74
11 38 15 9 32
11 38 14 9 0
11 38 13 9 0
11 38 12 9 0
11 38 11 9 0
11 38 10 9 0
11 38 9 9 8
11 38 8 9 0
11 38 7 9 0
11 38 6 9 0
11 38 5 9 0
11 38 4 9 0
11 38 3 9 0
11 38 2 9 72
11 39 36 9 48
11 39 35 9 0
11 39 34 9 0
11 39 33 9 74
11 39 16 9 50
11 39 15 9 0
11 39 14 9 0
11 39 13 9 0
11 39 12 9 0
11 39 11 9 0
11 39 10 9 72
11 39 8 9 32
11 39 7 9 0
11 39 6 9 0
11 39 5 9 0
11 39 4 9 0
11 39 3 9 72
11 40 36 9 42
11 40 35 9 10
11 40 34 9 74
11 40 16 1 34
11 40 15 1 0
11 40 14 1 0
11 40 13 1 0
11 40 12 1 2
11 40 11 1 74
11 40 8 1 34
11 40 7 1 0
11 40 6 1 0
11 40 5 1 2
11 40 4 1 74
11 41 16 1 34
11 41 15 1 0
11 41 14 1 2
11 41 13 1 10
11 41 12 1 74
11 41 8 1 34
11 41 7 1 0
11 41 6 1 10
11 41 5 1 74
11 42 16 1 34
11 42 15 1 10
11 42 14 1 74
11 42 8 1 34
11 42 7 1 74
11 43 16 1 106
11 43 8 1 106
12 19 14 1 50
12 19 13 9 18
12 19 12 1 82
12 20 14 1 34
12 20 13 9 2
12 20 12 1 2
12 20 11 1 18
12 20 10 1 82
12 21 36 8 114
12 21 15 9 50
12 21 14 9 2
12 21 13 1 2
12 21 12 1 2
12 21 11 9 2
12 21 10 1 2
12 21 9 9 18
12 21 8 9 82
12 22 36 8 42
12 22 35 8 82
12 22 15 1 34
12 22 14 9 2
12 22 13 9 2
12 22 12 9 2
12 22 11 1 2
12 22 10 9 2
12 22 9 9 2
12 22 8 1 2
12 22 7 9 18
12 22 6 1 82
12 23 35 8 34
12 23 34 8 82
12 23 20 9 50
12 23 19 9 16
12 23 18 9 16
12 23 17 9 16
12 23 16 9 16
12 23 15 9 0
12 23 14 9 0
12 23 13 9 0
12 23 12 9 0
12 23 11 9 0
12 23 10 9 0
12 23 9 9 0
12 23 8 9 0
12 23 7 9 0
12 23 6 9 0
12 23 5 9 16
12 23 4 9 16
12 23 3 9 16
12 23 2 9 16
12 23 1 9 82
12 24 35 8 42
12 24 34 8 10
12 24 33 8 18
12 24 32 8 82
12 24 21 9 48
12 24 20 9 0
12 24 19 9 0
12 24 18 9 0
12 24 17 9 0
12 24 16 9 0
12 24 15 9 0
12 24 14 9 0
12 24 13 9 0
12 24 12 9 0
12 24 11 9 0
12 24 10 9 0
12 24 9 9 0
12 24 8 9 0
12 24 7 9 0
12 24 6 9 0
12 24 5 9 0
12 24 4 9 0
12 24 3 9 0
12 24 2 9 0
12 24 1 9 0
12 24 0 9 80
12 25 33 8 34
12 25 32 8 2
12 25 31 8 82
12 25 23 9 54
12 25 22 9 16
12 25 21 9 0
12 25 20 9 0
12 25 19 9 0
12 25 18 9 0
12 25 17 9 0
12 25 16 9 0
12 25 15 9 0
12 25 14 9 0
12 25 13 9 0
12 25 12 9 0
12 25 11 9 0
12 25 10 9 0
12 25 9 9 0
12 25 8 9 0
12 25 7 9 0
12 25 6 9 0
12 25 5 9 0
12 25 4 9 0
12 25 3 9 0
12 25 2 9 0
12 25 1 9 0
12 25 0 9 64
12 26 33 8 34
12 26 32 8 2
12 26 31 8 2
12 26 30 8 18
12 26 29 8 82
12 26 24 8 50
12 26 23 9 0
12 26 22 9 0
12 26 21 9 0
12 26 20 9 0
12 26 19 3 0
12 26 18 3 0
12 26 17 3 0
12 26 16 3 0
12 26 15 3 0
12 26 14 3 0
12 26 13 3 0
12 26 12 3 0
12 26 11 3 0
12 26 10 3 0
12 26 9 3 8
12 26 8 3 8
12 26 7 9 8
12 26 6 9 8
12 26 5 9 8
12 26 4 9 8
12 26 3 9 8
12 26 2 9 8
12 26 1 9 8
12 26 0 8 72
12 27 33 8 34
12 27 32 8 2
12 27 31 8 2
12 27 30 8 2
12 27 29 8 2
12 27 28 8 82
12 27 25 8 50
12 27 24 8 2
12 27 23 9 0
12 27 22 9 0
12 27 21 9 0
12 27 20 9 0
12 27 19 3 0
12 27 18 3 0
12 27 17 3 0
12 27 16 3 0
12 27 15 3 0
12 27 14 3 0
12 27 13 3 0
12 27 12 3 0
12 27 11 3 0
12 27 10 7 64
12 28 33 8 34
12 28 32 8 2
12 28 31 8 2
12 28 30 8 2
12 28 29 8 2
12 28 28 8 2
12 28 27 8 18
12 28 26 8 18
12 28 25 8 2
12 28 24 8 2
12 28 23 9 0
12 28 22 9 0
12 28 21 9 0
12 28 20 9 0
12 28 19 3 0
12 28 18 3 0
12 28 17 3 0
12 28 16 3 0
12 28 15 3 0
12 28 14 3 0
12 28 13 3 0
12 28 12 3 0
12 28 11 3 0
12 28 10 7 72
12 29 33 8 34
12 29 32 8 2
12 29 31 8 2
12 29 30 8 2
12 29 29 8 2
12 29 28 8 2
12 29 27 8 10
12 29 26 8 10
12 29 25 8 2
12 29 24 8 2
12 29 23 9 0
12 29 22 9 0
12 29 21 9 0
12 29 20 9 0
12 29 19 3 0
12 29 18 3 0
12 29 17 3 0
12 29 16 3 0
12 29 15 3 0
12 29 14 3 0
12 29 13 3 0
12 29 12 3 0
12 29 11 7 64
12 30 33 8 34
12 30 32 8 2
12 30 31 8 2
12 30 30 8 2
12 30 29 8 2
12 30 28 8 74
12 30 25 8 42
12 30 24 8 2
12 30 23 9 0
12 30 22 9 0
12 30 21 9 0
12 30 20 9 0
12 30 19 3 0
12 30 18 3 0
12 30 17 3 0
12 30 16 3 0
12 30 15 3 0
12 30 14 3 0
12 30 13 3 0
12 30 12 3 0
12 30 11 7 64
12 31 33 8 34
12 31 32 8 2
12 31 31 8 2
12 31 30 8 2
12 31 29 8 74
12 31 24 8 42
12 31 23 9 8
12 31 22 9 0
12 31 21 9 0
12 31 20 9 0
12 31 19 3 0
12 31 18 3 0
12 31 17 3 0
12 31 16 3 0
12 31 15 3 0
12 31 14 3 0
12 31 13 3 0
12 31 12 3 0
12 31 11 7 64
12 32 33 8 34
12 32 32 8 2
12 32 31 8 2
12 32 30 8 74
12 32 22 9 40
12 32 21 9 0
12 32 20 9 0
12 32 19 3 0
12 32 18 3 0
12 32 17 3 0
12 32 16 3 0
12 32 15 3 0
12 32 14 3 0
12 32 13 3 0
12 32 12 3 0
12 32 11 7 64
12 33 33 8 34
12 33 32 8 2
12 33 31 8 74
12 33 21 9 40
12 33 20 9 0
12 33 19 3 0
12 33 18 3 0
12 33 17 3 0
12 33 16 3 0
12 33 15 3 0
12 33 14 3 0
12 33 13 3 0
12 33 12 3 0
12 33 11 3 64
12 33 7 9 48
12 33 6 9 16
12 33 5 9 16
12 33 4 9 16
12 33 3 9 16
12 33 2 9 16
12 33 1 9 16
12 33 0 8 80
12 34 33 8 34
12 34 32 8 66
12 34 20 9 40
12 34 19 9 0
12 34 18 9 0
12 34 17 9 0
12 34 16 9 0
12 34 15 9 0
12 34 14 9 0
12 34 13 9 0
12 34 12 9 0
12 34 11 9 64
12 34 7 9 32
12 34 6 9 0
12 34 5 9 0
12 34 4 9 0
12 34 3 9 0
12 34 2 9 0
12 34 1 9 0
12 34 0 9 64
12 35 33 8 34
12 35 32 8 66
12 35 19 9 40
12 35 18 9 0
12 35 17 9 0
12 35 16 9 0
12 35 15 9 0
12 35 14 9 0
12 35 13 9 0
12 35 12 9 0
12 35 11 9 0
12 35 10 9 16
12 35 9 9 16
12 35 8 9 16
12 35 7 9 0
12 35 6 9 0
12 35 5 9 0
12 35 4 9 0
12 35 3 9 0
12 35 2 9 0
12 35 1 9 0
12 35 0 9 64
12 36 33 8 34
12 36 32 8 74
12 36 18 9 40
12 36 17 9 8
12 36 16 9 0
12 36 15 9 0
12 36 14 9 0
12 36 13 9 0
12 36 12 9 0
12 36 11 9 0
12 36 10 9 0
12 36 9 9 0
12 36 8 9 0
12 36 7 9 0
12 36 6 9 0
12 36 5 9 0
12 36 4 9 0
12 36 3 9 0
12 36 2 9 0
12 36 1 9 0
12 36 0 9 72
12 37 35 8 50
12 37 34 8 18
12 37 33 8 66
12 37 16 9 40
12 37 15 9 0
12 37 14 9 0
12 37 13 9 0
12 37 12 9 0
12 37 11 9 0
12 37 10 9 0
12 37 9 9 0
12 37 8 9 0
12 37 7 9 0
12 37 6 9 0
12 37 5 9 0
12 37 4 9 0
12 37 3 9 0
12 37 2 9 0
12 37 1 8 74
12 38 35 8 34
12 38 34 8 2
12 38 33 8 74
12 38 15 9 34
12 38 14 9 0
12 38 13 9 0
12 38 12 9 0
12 38 11 9 0
12 38 10 9 0
12 38 9 9 8
12 38 8 9 0
12 38 7 9 0
12 38 6 9 0
12 38 5 9 0
12 38 4 9 0
12 38 3 9 0
12 38 2 9 72
12 39 36 8 58
12 39 35 8 10
12 39 34 8 74
12 39 15 9 34
12 39 14 1 2
12 39 13 1 2
12 39 12 9 10
12 39 11 9 10
12 39 10 1 74
12 39 8 9 42
12 39 7 1 2
12 39 6 1 2
12 39 5 1 10
12 39 4 9 10
12 39 3 1 74
12 40 15 1 34
12 40 14 1 10
12 40 13 1 74
12 40 7 1 34
12 40 6 1 74
12 41 15 1 106
12 41 7 1 106
13 23 19 9 50
13 23 18 9 16
13 23 17 9 16
13 23 16 9 16
13 23 15 9 16
13 23 14 9 16
13 23 13 9 16
13 23 12 9 16
13 23 11 9 16
13 23 10 9 16
13 23 9 9 16
13 23 8 9 16
13 23 7 9 16
13 23 6 9 16
13 23 5 9 16
13 23 4 9 16
13 23 3 9 16
13 23 2 9 82
13 24 21 9 48
13 24 20 9 16
13 24 19 9 0
13 24 18 9 0
13 24 17 9 0
13 24 16 9 0
13 24 15 9 0
13 24 14 9 0
13 24 13 9 0
13 24 12 9 0
13 24 11 9 0
13 24 10 9 0
13 24 9 9 0
13 24 8 9 0
13 24 7 9 0
13 24 6 9 0
13 24 5 9 0
13 24 4 9 0
13 24 3 9 0
13 24 2 9 0
13 24 1 9 16
13 24 0 9 80
13 25 22 9 48
13 25 21 9 0
13 25 20 9 0
13 25 19 9 0
13 25 18 9 0
13 25 17 9 0
13 25 16 9 0
13 25 15 9 0
13 25 14 9 0
13 25 13 9 0
13 25 12 9 0
13 25 11 9 0
13 25 10 9 0
13 25 9 9 0
13 25 8 9 0
13 25 7 9 0
13 25 6 9 0
13 25 5 9 0
13 25 4 9 0
13 25 3 9 0
13 25 2 9 0
13 25 1 9 0
13 25 0 9 64
13 26 23 8 48
13 26 22 9 0
13 26 21 9 0
13 26 20 9 0
13 26 19 3 0
13 26 18 3 0
13 26 17 3 0
13 26 16 3 0
13 26 15 3 0
13 26 14 3 0
13 26 13 3 0
13 26 12 3 0
13 26 11 3 0
13 26 10 3 0
13 26 9 3 8
13 26 8 3 8
13 26 7 9 8
13 26 6 9 8
13 26 5 9 8
13 26 4 9 8
13 26 3 9 8
13 26 2 9 8
13 26 1 9 0
13 26 0 8 64
13 27 23 8 32
13 27 22 9 0
13 27 21 9 0
13 27 20 9 0
13 27 19 3 0
13 27 18 3 0
13 27 17 3 0
13 27 16 3 0
13 27 15 3 0
13 27 14 3 0
13 27 13 3 0
13 27 12 3 0
13 27 11 3 0
13 27 10 7 64
13 27 1 4 44
13 27 0 4 68
13 28 23 8 32
13 28 22 9 0
13 28 21 9 0
13 28 20 9 0
13 28 19 3 0
13 28 18 3 0
13 28 17 3 0
13 28 16 3 0
13 28 15 3 0
13 28 14 3 0
13 28 13 3 0
13 28 12 3 0
13 28 11 3 0
13 28 10 7 72
13 28 0 4 100
13 29 23 8 32
13 29 22 9 0
13 29 21 9 0
13 29 20 9 0
13 29 19 3 0
13 29 18 3 0
13 29 17 3 0
13 29 16 3 0
13 29 15 3 0
13 29 14 3 0
13 29 13 3 0
13 29 12 3 0
13 29 11 7 64
13 29 0 4 100
13 30 23 8 32
13 30 22 9 0
13 30 21 9 0
13 30 20 9 0
13 30 19 3 0
13 30 18 3 0
13 30 17 3 0
13 30 16 3 0
13 30 15 3 0
13 30 14 3 0
13 30 13 3 0
13 30 12 3 0
13 30 11 7 64
13 30 0 4 110
13 31 23 8 42
13 31 22 9 0
13 31 21 9 0
13 31 20 9 0
13 31 19 3 0
13 31 18 3 0
13 31 17 3 0
13 31 16 3 0
13 31 15 3 0
13 31 14 3 0
13 31 13 3 0
13 31 12 3 0
13 31 11 7 64
13 32 22 9 40
13 32 21 9 0
13 32 20 9 0
13 32 19 3 0
13 32 18 3 0
13 32 17 3 0
13 32 16 3 0
13 32 15 3 0
13 32 14 3 0
13 32 13 3 0
13 32 12 3 0
13 32 11 7 64
13 33 21 9 42
13 33 20 9 0
13 33 19 3 0
13 33 18 3 0
13 33 17 3 0
13 33 16 3 0
13 33 15 3 0
13 33 14 3 0
13 33 13 3 0
13 33 12 3 0
13 33 11 3 64
13 33 7 9 48
13 33 6 9 16
13 33 5 9 16
13 33 4 9 16
13 33 3 9 16
13 33 2 9 16
13 33 1 9 16
13 33 0 8 80
13 34 20 9 42
13 34 19 9 0
13 34 18 9 0
13 34 17 9 0
13 34 16 9 0
13 34 15 9 0
13 34 14 9 0
13 34 13 9 0
13 34 12 9 0
13 34 11 9 64
13 34 7 9 32
13 34 6 9 0
13 34 5 9 0
13 34 4 9 0
13 34 3 9 0
13 34 2 9 0
13 34 1 9 0
13 34 0 9 64
13 35 19 9 42
13 35 18 9 0
13 35 17 9 0
13 35 16 9 0
13 35 15 9 0
13 35 14 9 0
13 35 13 9 0
13 35 12 9 0
13 35 11 9 0
13 35 10 9 16
13 35 9 9 16
13 35 8 9 16
13 35 7 9 0
13 35 6 9 0
13 35 5 9 0
13 35 4 9 0
13 35 3 9 0
13 35 2 9 0
13 35 1 9 0
13 35 0 9 64
13 36 18 9 42
13 36 17 9 8
13 36 16 9 0
13 36 15 9 0
13 36 14 9 0
13 36 13 9 0
13 36 12 9 0
13 36 11 9 0
13 36 10 9 0
13 36 9 9 0
13 36 8 9 0
13 36 7 9 0
13 36 6 9 0
13 36 5 9 0
13 36 4 9 0
13 36 3 9 0
13 36 2 9 0
13 36 1 9 8
13 36 0 9 74
13 37 16 9 42
13 37 15 9 8
13 37 14 9 0
13 37 13 9 0
13 37 12 9 0
13 37 11 9 0
13 37 10 9 0
13 37 9 9 0
13 37 8 9 0
13 37 7 9 0
13 37 6 9 0
13 37 5 9 0
13 37 4 9 0
13 37 3 9 0
13 37 2 9 64
13 38 14 9 42
13 38 13 9 10
13 38 12 9 10
13 38 11 9 8
13 38 10 9 8
13 38 9 9 8
13 38 8 9 8
13 38 7 9 8
13 38 6 9 8
13 38 5 9 10
13 38 4 9 10
13 38 3 9 10
13 38 2 9 74
14 23 18 9 50
14 23 17 9 18
14 23 16 9 18
14 23 15 9 18
14 23 14 9 18
14 23 13 9 18
14 23 12 9 18
14 23 11 9 18
14 23 10 9 18
14 23 9 9 18
14 23 8 9 18
14 23 7 8 18
14 23 6 9 18
14 23 5 9 18
14 23 4 9 18
14 23 3 9 82
14 24 21 9 50
14 24 20 9 16
14 24 19 9 16
14 24 18 9 0
14 24 17 9 0
14 24 16 9 0
14 24 15 9 0
14 24 14 9 0
14 24 13 9 0
14 24 12 9 0
14 24 11 9 0
14 24 10 9 0
14 24 9 9 0
14 24 8 9 0
14 24 7 9 0
14 24 6 9 0
14 24 5 9 0
14 24 4 9 0
14 24 3 9 0
14 24 2 9 16
14 24 1 9 16
14 24 0 9 82
14 25 22 8 48
14 25 21 9 0
14 25 20 9 0
14 25 19 9 0
14 25 18 9 0
14 25 17 9 0
14 25 16 9 0
14 25 15 9 0
14 25 14 9 0
14 25 13 9 0
14 25 12 9 0
14 25 11 9 0
14 25 10 9 0
14 25 9 9 0
14 25 8 9 0
14 25 7 9 0
14 25 6 9 0
14 25 5 9 0
14 25 4 9 0
14 25 3 9 0
14 25 2 9 0
14 25 1 9 0
14 25 0 9 64
14 26 23 8 50
14 26 22 9 0
14 26 21 9 0
14 26 20 9 0
14 26 19 3 0
14 26 18 3 0
14 26 17 3 0
14 26 16 3 0
14 26 15 3 0
14 26 14 3 0
14 26 13 3 0
14 26 12 3 0
14 26 11 3 0
14 26 10 3 0
14 26 9 3 8
14 26 8 3 8
14 26 7 9 8
14 26 6 9 8
14 26 5 9 8
14 26 4 9 8
14 26 3 9 8
14 26 2 9 0
14 26 1 9 0
14 26 0 8 64
14 27 23 8 34
14 27 22 9 0
14 27 21 9 0
14 27 20 9 0
14 27 19 3 0
14 27 18 3 0
14 27 17 3 0
14 27 16 3 0
14 27 15 3 0
14 27 14 3 0
14 27 13 3 0
14 27 12 3 0
14 27 11 3 0
14 27 10 7 64
14 27 2 4 46
14 27 1 4 2
14 27 0 4 66
14 28 23 8 34
14 28 22 9 0
14 28 21 9 0
14 28 20 9 0
14 28 19 3 0
14 28 18 3 0
14 28 17 3 0
14 28 16 3 0
14 28 15 3 0
14 28 14 3 0
14 28 13 3 0
14 28 12 3 0
14 28 11 3 0
14 28 10 7 72
14 28 1 4 46
14 28 0 4 66
14 29 23 8 34
14 29 22 9 0
14 29 21 9 0
14 29 20 9 0
14 29 19 3 0
14 29 18 3 0
14 29 17 3 0
14 29 16 3 0
14 29 15 3 0
14 29 14 3 0
14 29 13 3 0
14 29 12 3 0
14 29 11 7 64
14 29 0 4 106
14 30 23 8 42
14 30 22 9 0
14 30 21 9 0
14 30 20 9 0
14 30 19 3 0
14 30 18 3 0
14 30 17 3 0
14 30 16 3 0
14 30 15 3 0
14 30 14 3 0
14 30 13 3 0
14 30 12 3 0
14 30 11 7 64
14 31 22 8 32
14 31 21 9 0
14 31 20 9 0
14 31 19 3 0
14 31 18 3 0
14 31 17 3 0
14 31 16 3 0
14 31 15 3 0
14 31 14 3 0
14 31 13 3 0
14 31 12 3 0
14 31 11 7 64
14 32 22 8 42
14 32 21 8 8
14 32 20 9 0
14 32 19 3 0
14 32 18 3 0
14 32 17 3 0
14 32 16 3 0
14 32 15 3 0
14 32 14 3 0
14 32 13 3 0
14 32 12 3 0
14 32 11 7 64
14 33 20 8 42
14 33 19 3 0
14 33 18 3 0
14 33 17 3 0
14 33 16 3 0
14 33 15 3 0
14 33 14 3 0
14 33 13 3 0
14 33 12 3 0
14 33 11 3 64
14 33 7 9 48
14 33 6 9 16
14 33 5 9 16
14 33 4 9 16
14 33 3 9 16
14 33 2 9 16
14 33 1 9 16
14 33 0 8 80
14 34 19 8 40
14 34 18 9 0
14 34 17 9 0
14 34 16 9 0
14 34 15 9 0
14 34 14 9 0
14 34 13 9 0
14 34 12 9 0
14 34 11 9 64
14 34 7 9 32
14 34 6 9 0
14 34 5 9 0
14 34 4 9 0
14 34 3 9 0
14 34 2 9 0
14 34 1 9 0
14 34 0 9 64
14 35 18 8 40
14 35 17 9 0
14 35 16 9 0
14 35 15 9 0
14 35 14 9 0
14 35 13 9 0
14 35 12 9 0
14 35 11 9 0
14 35 10 9 16
14 35 9 9 16
14 35 8 9 16
14 35 7 9 0
14 35 6 9 0
14 35 5 9 0
14 35 4 9 0
14 35 3 9 0
14 35 2 9 0
14 35 1 9 0
14 35 0 9 74
14 36 17 8 42
14 36 16 9 8
14 36 15 9 0
14 36 14 9 0
14 36 13 9 0
14 36 12 9 0
14 36 11 9 0
14 36 10 9 0
14 36 9 9 0
14 36 8 9 0
14 36 7 9 0
14 36 6 9 0
14 36 5 9 0
14 36 4 9 0
14 36 3 9 0
14 36 2 9 0
14 36 1 9 74
14 37 15 9 42
14 37 14 9 8
14 37 13 9 8
14 37 12 9 8
14 37 11 9 0
14 37 10 9 0
14 37 9 9 0
14 37 8 9 0
14 37 7 9 0
14 37 6 9 0
14 37 5 9 8
14 37 4 9 10
14 37 3 9 10
14 37 2 9 74
14 38 11 9 42
14 38 10 9 10
14 38 9 9 10
14 38 8 9 10
14 38 7 9 10
14 38 6 9 74
15 24 20 9 50
15 24 19 9 16
15 24 18 9 16
15 24 17 9 16
15 24 16 9 16
15 24 15 9 16
15 24 14 9 16
15 24 13 9 16
15 24 12 9 16
15 24 11 9 16
15 24 10 9 16
15 24 9 9 16
15 24 8 9 16
15 24 7 9 16
15 24 6 9 16
15 24 5 9 16
15 24 4 9 16
15 24 3 9 16
15 24 2 9 16
15 24 1 9 82
15 25 22 8 50
15 25 21 9 16
15 25 20 9 0
15 25 19 9 0
15 25 18 9 0
15 25 17 9 0
15 25 16 9 0
15 25 15 9 0
15 25 14 9 0
15 25 13 9 0
15 25 12 9 0
15 25 11 9 0
15 25 10 9 0
15 25 9 9 0
15 25 8 9 0
15 25 7 9 0
15 25 6 9 0
15 25 5 9 0
15 25 4 9 0
15 25 3 9 0
15 25 2 9 0
15 25 1 9 0
15 25 0 9 80
15 26 22 8 32
15 26 21 9 0
15 26 20 9 0
15 26 19 3 0
15 26 18 3 0
15 26 17 3 0
15 26 16 3 0
15 26 15 3 0
15 26 14 3 0
15 26 13 3 0
15 26 12 3 0
15 26 11 3 0
15 26 10 3 0
15 26 9 3 0
15 26 8 3 8
15 26 7 9 8
15 26 6 9 8
15 26 5 9 8
15 26 4 9 8
15 26 3 9 8
15 26 2 9 8
15 26 1 9 8
15 26 0 8 72
15 27 22 8 32
15 27 21 9 0
15 27 20 9 0
15 27 19 3 0
15 27 18 3 0
15 27 17 3 0
15 27 16 3 0
15 27 15 3 0
15 27 14 3 0
15 27 13 3 0
15 27 12 3 0
15 27 11 3 0
15 27 10 3 0
15 27 9 7 68
15 28 22 8 32
15 28 21 9 0
15 28 20 9 0
15 28 19 3 0
15 28 18 3 0
15 28 17 3 0
15 28 16 3 0
15 28 15 3 0
15 28 14 3 0
15 28 13 3 0
15 28 12 3 0
15 28 11 3 0
15 28 10 3 0
15 28 9 7 76
15 29 22 8 32
15 29 21 9 0
15 29 20 9 0
15 29 19 3 0
15 29 18 3 0
15 29 17 3 0
15 29 16 3 0
15 29 15 3 0
15 29 14 3 0
15 29 13 3 0
15 29 12 3 0
15 29 11 3 0
15 29 10 7 68
15 30 22 8 32
15 30 21 9 0
15 30 20 9 0
15 30 19 3 0
15 30 18 3 0
15 30 17 3 0
15 30 16 3 0
15 30 15 3 0
15 30 14 3 0
15 30 13 3 0
15 30 12 3 0
15 30 11 3 0
15 30 10 7 68
15 31 22 8 42
15 31 21 9 0
15 31 20 9 0
15 31 19 3 0
15 31 18 3 0
15 31 17 3 0
15 31 16 3 0
15 31 15 3 0
15 31 14 3 0
15 31 13 3 0
15 31 12 3 0
15 31 11 3 0
15 31 10 7 4
15 31 9 7 84
15 32 21 8 40
15 32 20 8 8
15 32 19 3 0
15 32 18 3 0
15 32 17 3 0
15 32 16 3 0
15 32 15 3 0
15 32 14 3 0
15 32 13 3 0
15 32 12 3 0
15 32 11 3 0
15 32 10 7 4
15 32 9 7 68
15 33 19 3 32
15 33 18 3 0
15 33 17 3 0
15 33 16 3 0
15 33 15 3 0
15 33 14 3 0
15 33 13 3 0
15 33 12 3 0
15 33 11 3 0
15 33 10 3 4
15 33 9 3 4
15 33 8 3 20
15 33 7 9 16
15 33 6 9 16
15 33 5 9 16
15 33 4 9 16
15 33 3 9 16
15 33 2 9 16
15 33 1 9 16
15 33 0 8 80
15 34 19 8 40
15 34 18 9 0
15 34 17 9 0
15 34 16 9 0
15 34 15 9 0
15 34 14 9 0
15 34 13 9 0
15 34 12 9 0
15 34 11 9 0
15 34 10 9 4
15 34 9 9 4
15 34 8 9 4
15 34 7 9 0
15 34 6 9 0
15 34 5 9 0
15 34 4 9 0
15 34 3 9 0
15 34 2 9 0
15 34 1 9 0
15 34 0 9 74
15 35 18 9 40
15 35 17 9 8
15 35 16 9 0
15 35 15 9 0
15 35 14 9 0
15 35 13 9 0
15 35 12 9 0
15 35 11 9 0
15 35 10 9 0
15 35 9 9 0
15 35 8 9 0
15 35 7 9 0
15 35 6 9 0
15 35 5 9 0
15 35 4 9 0
15 35 3 9 0
15 35 2 9 0
15 35 1 9 74
15 36 16 9 40
15 36 15 9 8
15 36 14 9 0
15 36 13 9 0
15 36 12 9 0
15 36 11 9 0
15 36 10 9 0
15 36 9 9 0
15 36 8 9 0
15 36 7 9 0
15 36 6 9 0
15 36 5 9 0
15 36 4 9 8
15 36 3 9 10
15 36 2 9 74
15 37 14 8 42
15 37 13 9 10
15 37 12 9 10
15 37 11 9 10
15 37 10 8 10
15 37 9 9 10
15 37 8 9 10
15 37 7 9 8
15 37 6 9 8
15 37 5 9 72
16 24 19 8 50
16 24 18 9 18
16 24 17 9 18
16 24 16 8 18
16 24 15 9 18
16 24 14 9 18
16 24 13 8 18
16 24 12 9 18
16 24 11 8 18
16 24 10 9 18
16 24 9 8 18
16 24 8 9 18
16 24 7 9 18
16 24 6 9 18
16 24 5 8 18
16 24 4 9 18
16 24 3 8 18
16 24 2 8 82
16 25 21 9 50
16 25 20 9 16
16 25 19 9 0
16 25 18 9 0
16 25 17 9 0
16 25 16 9 0
16 25 15 9 0
16 25 14 9 0
16 25 13 9 0
16 25 12 9 0
16 25 11 9 0
16 25 10 9 0
16 25 9 9 0
16 25 8 9 0
16 25 7 9 0
16 25 6 9 0
16 25 5 9 0
16 25 4 9 0
16 25 3 9 0
16 25 2 9 0
16 25 1 9 16
16 25 0 9 82
16 26 22 8 50
16 26 21 9 0
16 26 20 9 0
16 26 19 3 0
16 26 18 3 0
16 26 17 3 0
16 26 16 3 0
16 26 15 3 0
16 26 14 3 0
16 26 13 3 0
16 26 12 3 0
16 26 11 3 0
16 26 10 3 0
16 26 9 3 0
16 26 8 3 8
16 26 7 9 8
16 26 6 9 8
16 26 5 9 8
16 26 4 9 8
16 26 3 9 8
16 26 2 9 8
16 26 1 9 8
16 26 0 8 74
16 27 22 8 34
16 27 21 9 0
16 27 20 9 0
16 27 19 3 0
16 27 18 3 0
16 27 17 3 0
16 27 16 3 0
16 27 15 3 0
16 27 14 3 0
16 27 13 3 0
16 27 12 3 0
16 27 11 3 0
16 27 10 3 0
16 27 9 7 64
16 28 22 8 34
16 28 21 9 0
16 28 20 9 0
16 28 19 3 0
16 28 18 3 0
16 28 17 3 0
16 28 16 3 0
16 28 15 3 0
16 28 14 3 0
16 28 13 3 0
16 28 12 3 0
16 28 11 3 0
16 28 10 3 0
16 28 9 7 72
16 29 22 8 34
16 29 21 9 0
16 29 20 9 0
16 29 19 3 0
16 29 18 3 0
16 29 17 3 0
16 29 16 3 0
16 29 15 3 0
16 29 14 3 0
16 29 13 3 0
16 29 12 3 0
16 29 11 3 0
16 29 10 7 64
16 30 22 8 42
16 30 21 9 0
16 30 20 9 0
16 30 19 3 0
16 30 18 3 0
16 30 17 3 0
16 30 16 3 0
16 30 15 3 0
16 30 14 3 0
16 30 13 3 0
16 30 12 3 0
16 30 11 3 0
16 30 10 7 64
16 31 21 8 32
16 31 20 9 0
16 31 19 3 0
16 31 18 3 0
16 31 17 3 0
16 31 16 3 0
16 31 15 3 0
16 31 14 3 0
16 31 13 3 0
16 31 12 3 0
16 31 11 3 0
16 31 10 3 0
16 31 9 7 80
16 31 1 4 118
16 32 21 8 42
16 32 20 8 8
16 32 19 3 0
16 32 18 3 0
16 32 17 3 0
16 32 16 3 0
16 32 15 3 0
16 32 14 3 0
16 32 13 3 0
16 32 12 3 0
16 32 11 3 0
16 32 10 3 0
16 32 9 7 64
16 32 2 4 54
16 32 1 4 70
16 33 19 3 32
16 33 18 3 0
16 33 17 3 0
16 33 16 3 0
16 33 15 3 0
16 33 14 3 0
16 33 13 3 0
16 33 12 3 0
16 33 11 3 0
16 33 10 3 0
16 33 9 3 0
16 33 8 3 16
16 33 7 9 16
16 33 6 9 16
16 33 5 9 16
16 33 4 9 16
16 33 3 9 16
16 33 2 9 0
16 33 1 8 0
16 33 0 8 90
16 34 19 8 42
16 34 18 9 0
16 34 17 9 0
16 34 16 9 0
16 34 15 9 0
16 34 14 9 0
16 34 13 9 0
16 34 12 9 0
16 34 11 9 0
16 34 10 9 0
16 34 9 9 0
16 34 8 9 0
16 34 7 9 0
16 34 6 9 0
16 34 5 9 0
16 34 4 9 0
16 34 3 9 0
16 34 2 9 0
16 34 1 9 74
16 35 18 8 42
16 35 17 9 8
16 35 16 9 0
16 35 15 9 0
16 35 14 9 0
16 35 13 9 0
16 35 12 9 0
16 35 11 9 0
16 35 10 9 0
16 35 9 9 0
16 35 8 9 0
16 35 7 9 0
16 35 6 9 0
16 35 5 9 0
16 35 4 9 0
16 35 3 9 8
16 35 2 9 74
16 36 16 8 42
16 36 15 8 10
16 36 14 9 10
16 36 13 8 10
16 36 12 9 10
16 36 11 8 10
16 36 10 9 10
16 36 9 8 10
16 36 8 9 10
16 36 7 9 0
16 36 6 9 0
16 36 5 9 0
16 36 4 8 74
16 37 7 9 32
16 37 6 9 0
16 37 5 9 64
16 38 7 9 44
16 38 6 9 12
16 38 5 9 76
17 25 20 8 50
17 25 19 9 16
17 25 18 9 16
17 25 17 9 16
17 25 16 9 16
17 25 15 9 16
17 25 14 9 16
17 25 13 9 16
17 25 12 9 16
17 25 11 9 16
17 25 10 9 16
17 25 9 9 16
17 25 8 9 16
17 25 7 9 16
17 25 6 9 16
17 25 5 9 16
17 25 4 9 16
17 25 3 9 16
17 25 2 9 16
17 25 1 9 82
17 26 21 8 50
17 26 20 9 0
17 26 19 3 0
17 26 18 3 0
17 26 17 3 0
17 26 16 3 0
17 26 15 3 0
17 26 14 3 0
17 26 13 3 0
17 26 12 3 0
17 26 11 3 0
17 26 10 3 0
17 26 9 3 0
17 26 8 3 8
17 26 7 9 8
17 26 6 9 8
17 26 5 9 8
17 26 4 9 0
17 26 3 9 0
17 26 2 9 0
17 26 1 8 72
17 27 21 8 32
17 27 20 9 0
17 27 19 3 0
17 27 18 3 0
17 27 17 3 0
17 27 16 3 0
17 27 15 3 0
17 27 14 3 0
17 27 13 3 0
17 27 12 3 0
17 27 11 3 0
17 27 10 3 0
17 27 9 7 64
17 27 4 4 46
17 27 3 4 6
17 27 2 4 70
17 28 21 8 32
17 28 20 9 0
17 28 19 3 0
17 28 18 3 0
17 28 17 3 0
17 28 16 3 0
17 28 15 3 0
17 28 14 3 0
17 28 13 3 0
17 28 12 3 0
17 28 11 3 0
17 28 10 3 0
17 28 9 7 64
17 28 3 4 46
17 28 2 4 70
17 29 21 8 32
17 29 20 9 0
17 29 19 3 0
17 29 18 3 0
17 29 17 3 0
17 29 16 3 0
17 29 15 3 0
17 29 14 3 0
17 29 13 3 0
17 29 12 3 0
17 29 11 3 0
17 29 10 3 0
17 29 9 7 68
17 29 2 4 110
17 30 21 8 32
17 30 20 9 0
17 30 19 3 0
17 30 18 3 0
17 30 17 3 0
17 30 16 3 0
17 30 15 3 0
17 30 14 3 0
17 30 13 3 0
17 30 12 3 0
17 30 11 3 0
17 30 10 3 0
17 30 9 7 68
17 31 21 8 42
17 31 20 9 0
17 31 19 3 0
17 31 18 3 0
17 31 17 3 0
17 31 16 3 0
17 31 15 3 0
17 31 14 3 0
17 31 13 3 0
17 31 12 3 0
17 31 11 3 0
17 31 10 3 0
17 31 9 7 64
17 31 4 4 118
17 32 20 8 42
17 32 19 3 0
17 32 18 3 0
17 32 17 3 0
17 32 16 3 0
17 32 15 3 0
17 32 14 3 0
17 32 13 3 0
17 32 12 3 0
17 32 11 3 0
17 32 10 3 0
17 32 9 7 64
17 32 7 4 118
17 32 5 4 54
17 32 4 4 70
17 33 19 8 42
17 33 18 3 0
17 33 17 3 0
17 33 16 3 0
17 33 15 3 0
17 33 14 3 0
17 33 13 3 0
17 33 12 3 0
17 33 11 3 0
17 33 10 3 0
17 33 9 3 0
17 33 8 3 16
17 33 7 9 0
17 33 6 9 16
17 33 5 8 0
17 33 4 8 0
17 33 3 8 16
17 33 2 8 16
17 33 1 8 90
17 34 18 9 42
17 34 17 9 0
17 34 16 9 0
17 34 15 9 0
17 34 14 9 0
17 34 13 9 0
17 34 12 9 0
17 34 11 9 0
17 34 10 9 0
17 34 9 9 0
17 34 8 9 0
17 34 7 9 0
17 34 6 9 0
17 34 5 9 0
17 34 4 9 0
17 34 3 9 0
17 34 2 9 74
17 35 17 9 42
17 35 16 8 10
17 35 15 9 10
17 35 14 8 10
17 35 13 9 10
17 35 12 9 10
17 35 11 9 10
17 35 10 8 10
17 35 9 8 10
17 35 8 9 10
17 35 7 9 2
17 35 6 9 2
17 35 5 9 2
17 35 4 9 10
17 35 3 9 74
17 36 7 0 34
17 36 6 0 2
17 36 5 0 66
17 37 7 0 34
17 37 6 6 2
17 37 5 0 66
17 38 7 0 42
17 38 6 0 10
17 38 5 0 74
18 25 19 8 50
18 25 18 8 18
18 25 17 9 18
18 25 16 9 18
18 25 15 8 18
18 25 14 8 18
18 25 13 9 18
18 25 12 9 18
18 25 11 9 18
18 25 10 8 18
18 25 9 9 18
18 25 8 8 18
18 25 7 9 18
18 25 6 8 18
18 25 5 9 18
18 25 4 8 18
18 25 3 9 18
18 25 2 8 82
18 26 20 8 50
18 26 19 5 2
18 26 18 3 2
18 26 17 3 2
18 26 16 5 2
18 26 15 5 2
18 26 14 5 2
18 26 13 3 2
18 26 12 3 2
18 26 11 5 2
18 26 10 5 2
18 26 9 5 2
18 26 8 3 10
18 26 7 8 2
18 26 6 8 2
18 26 5 8 10
18 26 4 8 10
18 26 3 8 10
18 26 2 8 10
18 26 1 8 90
18 27 21 8 50
18 27 20 8 2
18 27 19 5 2
18 27 18 5 2
18 27 17 5 2
18 27 16 3 2
18 27 15 3 2
18 27 14 5 2
18 27 13 3 2
18 27 12 5 2
18 27 11 3 2
18 27 10 5 2
18 27 9 3 66
18 27 7 4 38
18 27 6 4 70
18 28 21 8 34
18 28 20 8 2
18 28 19 3 2
18 28 18 5 2
18 28 17 3 2
18 28 16 3 2
18 28 15 3 2
18 28 14 3 2
18 28 13 3 2
18 28 12 3 2
18 28 11 5 2
18 28 10 5 2
18 28 9 5 66
18 28 7 4 46
18 28 6 4 70
18 29 21 8 34
18 29 20 8 2
18 29 19 5 2
18 29 18 3 0
18 29 17 3 0
18 29 16 3 0
18 29 15 3 0
18 29 14 3 0
18 29 13 3 0
18 29 12 3 0
18 29 11 3 2
18 29 10 3 2
18 29 9 3 66
18 29 6 4 110
18 30 21 8 42
18 30 20 8 2
18 30 19 3 2
18 30 18 5 2
18 30 17 3 0
18 30 16 3 0
18 30 15 3 0
18 30 14 3 0
18 30 13 3 0
18 30 12 3 0
18 30 11 3 0
18 30 10 3 2
18 30 9 5 66
18 31 20 8 42
18 31 19 5 2
18 31 18 3 2
18 31 17 3 0
18 31 16 3 0
18 31 15 3 0
18 31 14 3 0
18 31 13 3 0
18 31 12 3 0
18 31 11 3 0
18 31 10 5 2
18 31 9 3 66
18 32 19 3 42
18 32 18 3 0
18 32 17 3 0
18 32 16 3 0
18 32 15 3 0
18 32 14 3 0
18 32 13 3 0
18 32 12 3 0
18 32 11 5 2
18 32 10 3 2
18 32 9 3 66
18 33 18 8 42
18 33 17 8 2
18 33 16 3 2
18 33 15 3 2
18 33 14 8 2
18 33 13 3 2
18 33 12 5 2
18 33 11 3 2
18 33 10 5 2
18 33 9 5 2
18 33 8 3 18
18 33 7 8 18
18 33 6 8 18
18 33 5 8 18
18 33 4 8 18
18 33 3 8 18
18 33 2 8 90
18 34 17 9 42
18 34 16 8 10
18 34 15 8 10
18 34 14 9 10
18 34 13 8 10
18 34 12 8 10
18 34 11 8 10
18 34 10 3 10
18 34 9 9 10
18 34 8 9 10
18 34 7 8 10
18 34 6 9 10
18 34 5 8 10
18 34 4 9 10
18 34 3 8 74
19 29 18 2 58
19 29 17 2 16
19 29 16 2 16
19 29 15 2 16
19 29 14 2 16
19 29 13 2 16
19 29 12 2 82
19 30 17 2 32
19 30 16 3 0
19 30 15 3 0
19 30 14 3 0
19 30 13 3 0
19 30 12 2 2
19 30 11 2 82
19 31 17 2 32
19 31 16 3 0
19 31 15 3 0
19 31 14 3 0
19 31 13 3 0
19 31 12 2 2
19 31 11 2 74
19 32 18 2 58
19 32 17 2 8
19 32 16 2 8
19 32 15 2 8
19 32 14 2 8
19 32 13 2 8
19 32 12 2 74
20 29 17 2 50
20 29 16 2 18
20 29 15 2 18
20 29 14 2 18
20 29 13 2 82
20 30 17 2 34
20 30 16 2 2
20 30 15 2 2
20 30 14 2 2
20 30 13 2 66
20 31 17 2 34
20 31 16 2 2
20 31 15 2 2
20 31 14 2 2
20 31 13 2 66
20 32 17 2 42
20 32 16 2 10
20 32 15 2 10
20 32 14 2 10
20 32 13 2 74
