Qubicle Exchange Format
Version 0.2
www.minddesk.com
28 32 71
18
0.000000 0.000000 0.000000
0.266667 0.156863 0.000000
0.313725 0.266667 0.223529
0.349020 0.129412 0.101961
0.356863 0.274510 0.160784
0.368627 0.160784 0.121569
0.376471 0.274510 0.141176
0.439216 0.337255 0.203922
0.443137 0.349020 0.215686
0.478431 0.380392 0.250980
0.490196 0.352941 0.172549
0.498039 0.368627 0.184314
0.501961 0.254902 0.215686
0.501961 0.349020 0.176471
0.501961 0.352941 0.211765
0.525490 0.403922 0.156863
0.988235 0.784314 0.031373
1.000000 1.000000 1.000000
14 2 29 9 118
14 3 29 9 102
14 4 29 9 102
14 5 29 9 102
14 6 29 9 102
14 7 29 9 102
14 8 29 9 102
14 9 29 9 102
14 10 29 9 102
14 11 29 9 102
14 12 29 9 102
14 13 29 9 102
14 14 29 9 102
14 15 29 9 102
14 16 29 9 102
14 17 29 9 102
14 18 29 9 102
14 19 29 9 102
14 20 29 9 102
14 21 29 9 102
14 22 29 9 102
14 23 29 9 102
14 24 29 9 102
14 25 29 9 102
14 26 29 9 102
14 27 29 9 102
14 28 29 9 102
14 29 29 9 102
14 30 29 9 102
14 31 29 9 110
4 6 44 1 52
4 6 43 1 20
4 6 42 1 20
4 6 41 1 20
4 6 40 1 20
4 6 39 1 20
4 6 38 1 20
4 6 37 1 28
4 6 36 1 28
4 6 35 1 20
4 6 34 1 20
4 6 33 1 20
4 6 32 1 20
4 6 31 1 28
4 6 30 1 28
4 6 29 1 20
4 6 28 1 20
4 6 27 1 20
4 6 26 1 20
4 6 25 1 28
4 6 24 1 28
4 6 23 1 84
4 7 44 1 36
4 7 43 1 4
4 7 42 1 4
4 7 41 1 4
4 7 40 1 4
4 7 39 1 4
4 7 38 1 68
4 7 35 1 36
4 7 34 1 4
4 7 33 1 4
4 7 32 1 68
4 7 29 1 36
4 7 28 1 4
4 7 27 1 4
4 7 26 1 68
4 7 23 1 100
4 8 45 1 52
4 8 44 1 4
4 8 43 1 4
4 8 42 1 4
4 8 41 1 4
4 8 40 1 4
4 8 39 1 4
4 8 38 1 68
4 8 35 1 36
4 8 34 1 4
4 8 33 1 4
4 8 32 1 68
4 8 29 1 36
4 8 28 1 4
4 8 27 1 4
4 8 26 1 68
4 8 23 1 100
4 9 45 1 36
4 9 44 1 4
4 9 43 1 4
4 9 42 1 4
4 9 41 1 4
4 9 40 1 4
4 9 39 1 4
4 9 38 1 4
4 9 37 1 20
4 9 36 1 20
4 9 35 1 4
4 9 34 1 4
4 9 33 1 4
4 9 32 1 4
4 9 31 1 20
4 9 30 1 20
4 9 29 1 4
4 9 28 1 4
4 9 27 1 4
4 9 26 1 4
4 9 25 1 20
4 9 24 1 20
4 9 23 1 4
4 9 22 1 84
4 10 45 11 44
4 10 44 11 12
4 10 43 11 12
4 10 42 11 12
4 10 41 11 4
4 10 40 11 12
4 10 39 11 12
4 10 38 11 12
4 10 37 11 4
4 10 36 11 12
4 10 35 11 12
4 10 34 11 12
4 10 33 11 4
4 10 32 11 12
4 10 31 11 12
4 10 30 11 12
4 10 29 11 4
4 10 28 11 12
4 10 27 11 12
4 10 26 11 12
4 10 25 11 4
4 10 24 11 12
4 10 23 11 12
4 10 22 11 12
4 10 21 11 92
4 11 41 6 100
4 11 37 6 100
4 11 33 6 100
4 11 29 6 100
4 11 25 6 100
4 12 41 6 108
4 12 37 6 108
4 12 33 6 108
4 12 29 6 108
4 12 25 6 108
5 5 47 1 52
5 5 46 1 20
5 5 45 1 20
5 5 44 1 20
5 5 43 1 20
5 5 42 1 20
5 5 41 1 20
5 5 40 1 20
5 5 39 1 20
5 5 38 1 20
5 5 37 1 20
5 5 36 1 20
5 5 35 1 20
5 5 34 1 20
5 5 33 1 20
5 5 32 1 20
5 5 31 1 20
5 5 30 1 20
5 5 29 1 20
5 5 28 1 20
5 5 27 1 20
5 5 26 1 20
5 5 25 1 20
5 5 24 1 20
5 5 23 1 20
5 5 22 1 20
5 5 21 1 20
5 5 20 1 84
5 6 47 1 36
5 6 46 1 4
5 6 45 1 4
5 6 44 1 0
5 6 43 1 0
5 6 42 1 0
5 6 41 1 0
5 6 40 1 0
5 6 39 1 0
5 6 38 1 0
5 6 37 0 8
5 6 36 0 8
5 6 35 1 0
5 6 34 1 0
5 6 33 1 0
5 6 32 1 0
5 6 31 0 8
5 6 30 0 8
5 6 29 1 0
5 6 28 1 0
5 6 27 1 0
5 6 26 1 0
5 6 25 0 8
5 6 24 0 8
5 6 23 1 0
5 6 22 1 4
5 6 21 1 4
5 6 20 1 4
5 6 19 1 84
5 7 47 1 36
5 7 46 1 4
5 7 45 1 4
5 7 44 1 0
5 7 43 1 0
5 7 42 1 0
5 7 41 1 0
5 7 40 1 0
5 7 39 1 0
5 7 38 0 64
5 7 35 0 32
5 7 34 1 0
5 7 33 1 0
5 7 32 0 64
5 7 29 1 32
5 7 28 1 0
5 7 27 1 0
5 7 26 0 64
5 7 23 1 32
5 7 22 1 4
5 7 21 1 4
5 7 20 1 4
5 7 19 1 4
5 7 18 1 84
5 8 47 1 36
5 8 46 1 4
5 8 45 1 0
5 8 44 1 0
5 8 43 1 0
5 8 42 1 0
5 8 41 1 0
5 8 40 1 0
5 8 39 1 0
5 8 38 0 64
5 8 35 0 32
5 8 34 1 0
5 8 33 1 0
5 8 32 0 64
5 8 29 1 32
5 8 28 1 0
5 8 27 1 0
5 8 26 0 64
5 8 23 1 32
5 8 22 1 4
5 8 21 1 4
5 8 20 1 4
5 8 19 1 4
5 8 18 1 4
5 8 17 1 84
5 9 47 1 36
5 9 46 1 4
5 9 45 1 0
5 9 44 1 0
5 9 43 1 0
5 9 42 1 0
5 9 41 11 0
5 9 40 11 0
5 9 39 11 0
5 9 38 11 0
5 9 37 0 16
5 9 36 0 16
5 9 35 11 0
5 9 34 11 0
5 9 33 11 0
5 9 32 11 0
5 9 31 0 16
5 9 30 0 16
5 9 29 11 0
5 9 28 11 0
5 9 27 11 0
5 9 26 11 0
5 9 25 0 16
5 9 24 0 16
5 9 23 11 0
5 9 22 11 0
5 9 21 1 4
5 9 20 1 4
5 9 19 1 4
5 9 18 1 4
5 9 17 1 4
5 9 16 1 20
5 9 15 1 84
5 10 47 11 36
5 10 46 10 4
5 10 45 1 0
5 10 44 1 0
5 10 43 11 0
5 10 42 11 0
5 10 41 11 0
5 10 40 11 0
5 10 39 11 0
5 10 38 11 0
5 10 37 11 0
5 10 36 11 0
5 10 35 11 0
5 10 34 11 0
5 10 33 11 0
5 10 32 11 0
5 10 31 11 0
5 10 30 11 0
5 10 29 11 0
5 10 28 11 0
5 10 27 11 0
5 10 26 11 0
5 10 25 11 0
5 10 24 11 0
5 10 23 11 0
5 10 22 11 0
5 10 21 11 0
5 10 20 11 4
5 10 19 10 4
5 10 18 10 4
5 10 17 10 4
5 10 16 10 4
5 10 15 10 68
5 11 48 10 52
5 11 47 10 4
5 11 46 11 4
5 11 45 10 4
5 11 44 10 4
5 11 43 10 4
5 11 42 10 4
5 11 41 6 0
5 11 40 1 4
5 11 39 1 12
5 11 38 1 4
5 11 37 6 0
5 11 36 1 4
5 11 35 1 12
5 11 34 1 4
5 11 33 6 0
5 11 32 1 4
5 11 31 1 12
5 11 30 1 4
5 11 29 6 0
5 11 28 1 4
5 11 27 1 12
5 11 26 1 4
5 11 25 6 0
5 11 24 1 4
5 11 23 1 12
5 11 22 1 4
5 11 21 1 4
5 11 20 6 4
5 11 19 14 4
5 11 18 10 4
5 11 17 10 4
5 11 16 10 4
5 11 15 10 4
5 11 14 10 20
5 11 13 10 20
5 11 12 10 28
5 11 11 10 92
5 12 48 10 44
5 12 47 10 12
5 12 46 10 12
5 12 45 10 12
5 12 44 10 12
5 12 43 10 12
5 12 42 10 12
5 12 41 6 0
5 12 40 1 76
5 12 38 1 44
5 12 37 6 0
5 12 36 1 76
5 12 34 1 44
5 12 33 6 0
5 12 32 1 76
5 12 30 1 44
5 12 29 6 0
5 12 28 1 76
5 12 26 1 44
5 12 25 6 0
5 12 24 1 76
5 12 22 1 44
5 12 21 1 12
5 12 20 6 12
5 12 19 10 4
5 12 18 10 4
5 12 17 10 4
5 12 16 10 4
5 12 15 10 4
5 12 14 10 4
5 12 13 10 68
5 13 41 6 108
5 13 37 6 108
5 13 33 6 108
5 13 29 6 108
5 13 25 6 108
5 13 19 10 44
5 13 18 10 12
5 13 17 10 4
5 13 16 10 4
5 13 15 10 4
5 13 14 10 4
5 13 13 10 4
5 13 12 10 84
5 14 17 4 44
5 14 16 4 4
5 14 15 4 4
5 14 14 4 4
5 14 13 4 4
5 14 12 4 4
5 14 11 4 84
5 15 16 4 44
5 15 15 4 12
5 15 14 4 12
5 15 13 4 12
5 15 12 4 12
5 15 11 4 12
5 15 10 4 92
6 4 48 1 52
6 4 47 1 20
6 4 46 1 20
6 4 45 1 20
6 4 44 1 20
6 4 43 1 20
6 4 42 1 20
6 4 41 1 20
6 4 40 1 20
6 4 39 1 20
6 4 38 1 20
6 4 37 1 20
6 4 36 1 20
6 4 35 1 20
6 4 34 1 20
6 4 33 1 20
6 4 32 1 20
6 4 31 1 20
6 4 30 1 20
6 4 29 1 20
6 4 28 1 20
6 4 27 1 20
6 4 26 1 20
6 4 25 1 20
6 4 24 1 20
6 4 23 1 20
6 4 22 1 20
6 4 21 1 20
6 4 20 1 20
6 4 19 1 20
6 4 18 1 20
6 4 17 1 84
6 5 48 1 36
6 5 47 1 0
6 5 46 1 0
6 5 45 1 0
6 5 44 1 0
6 5 43 1 0
6 5 42 1 0
6 5 41 1 0
6 5 40 1 0
6 5 39 1 0
6 5 38 1 0
6 5 37 1 0
6 5 36 1 0
6 5 35 1 0
6 5 34 1 0
6 5 33 1 0
6 5 32 1 0
6 5 31 1 0
6 5 30 1 0
6 5 29 1 0
6 5 28 1 0
6 5 27 1 0
6 5 26 1 0
6 5 25 1 0
6 5 24 1 0
6 5 23 1 0
6 5 22 1 0
6 5 21 1 0
6 5 20 1 0
6 5 19 1 4
6 5 18 1 4
6 5 17 1 4
6 5 16 1 20
6 5 15 1 84
6 6 48 1 36
6 6 47 1 0
6 6 46 1 0
6 6 45 1 0
6 6 44 1 0
6 6 43 1 0
6 6 42 1 0
6 6 41 1 0
6 6 40 1 0
6 6 39 1 0
6 6 38 1 0
6 6 37 0 8
6 6 36 0 8
6 6 35 1 0
6 6 34 1 0
6 6 33 1 0
6 6 32 1 0
6 6 31 0 8
6 6 30 0 8
6 6 29 1 0
6 6 28 1 0
6 6 27 1 0
6 6 26 1 0
6 6 25 0 8
6 6 24 0 8
6 6 23 1 0
6 6 22 1 0
6 6 21 1 0
6 6 20 1 0
6 6 19 1 0
6 6 18 1 4
6 6 17 1 4
6 6 16 1 4
6 6 15 1 4
6 6 14 1 20
6 6 13 1 84
6 7 49 1 52
6 7 48 1 4
6 7 47 1 0
6 7 46 1 0
6 7 45 1 0
6 7 44 1 0
6 7 43 1 0
6 7 42 1 0
6 7 41 1 0
6 7 40 1 0
6 7 39 1 0
6 7 38 0 64
6 7 35 0 32
6 7 34 1 0
6 7 33 1 0
6 7 32 0 64
6 7 29 0 32
6 7 28 1 0
6 7 27 1 0
6 7 26 0 64
6 7 23 0 32
6 7 22 1 0
6 7 21 1 0
6 7 20 1 0
6 7 19 1 0
6 7 18 1 0
6 7 17 1 4
6 7 16 1 4
6 7 15 1 4
6 7 14 1 4
6 7 13 1 4
6 7 12 1 84
6 8 49 1 36
6 8 48 1 4
6 8 47 1 0
6 8 46 11 0
6 8 45 11 0
6 8 44 11 0
6 8 43 11 0
6 8 42 11 0
6 8 41 11 0
6 8 40 11 0
6 8 39 11 0
6 8 38 0 64
6 8 35 0 32
6 8 34 11 0
6 8 33 11 0
6 8 32 0 64
6 8 29 0 32
6 8 28 11 0
6 8 27 11 0
6 8 26 0 64
6 8 23 0 32
6 8 22 11 0
6 8 21 11 0
6 8 20 2 0
6 8 19 2 0
6 8 18 2 0
6 8 17 2 0
6 8 16 1 4
6 8 15 1 4
6 8 14 1 4
6 8 13 1 4
6 8 12 1 4
6 8 11 1 20
6 8 10 1 20
6 8 9 1 84
6 9 49 1 36
6 9 48 1 4
6 9 47 1 0
6 9 46 11 0
6 9 45 11 0
6 9 44 11 0
6 9 43 11 0
6 9 42 11 0
6 9 41 11 0
6 9 40 11 0
6 9 39 11 0
6 9 38 11 0
6 9 37 0 16
6 9 36 0 16
6 9 35 11 0
6 9 34 11 0
6 9 33 11 0
6 9 32 11 0
6 9 31 0 16
6 9 30 0 16
6 9 29 11 0
6 9 28 11 0
6 9 27 11 0
6 9 26 11 0
6 9 25 0 16
6 9 24 0 16
6 9 23 11 0
6 9 22 11 0
6 9 21 11 0
6 9 20 2 0
6 9 19 2 0
6 9 18 2 0
6 9 17 2 0
6 9 16 2 0
6 9 15 2 0
6 9 14 1 4
6 9 13 1 4
6 9 12 1 4
6 9 11 1 4
6 9 10 1 4
6 9 9 1 4
6 9 8 1 20
6 9 7 1 84
6 10 50 11 52
6 10 49 11 4
6 10 48 11 4
6 10 47 11 0
6 10 46 11 0
6 10 45 11 0
6 10 44 11 0
6 10 43 11 0
6 10 42 11 0
6 10 41 11 0
6 10 40 11 0
6 10 39 11 0
6 10 38 11 0
6 10 37 11 0
6 10 36 11 0
6 10 35 11 0
6 10 34 11 0
6 10 33 11 0
6 10 32 11 0
6 10 31 11 0
6 10 30 11 0
6 10 29 11 0
6 10 28 11 0
6 10 27 11 0
6 10 26 11 0
6 10 25 11 0
6 10 24 11 0
6 10 23 11 0
6 10 22 11 0
6 10 21 11 0
6 10 20 2 0
6 10 19 2 0
6 10 18 2 0
6 10 17 2 0
6 10 16 2 0
6 10 15 2 0
6 10 14 10 4
6 10 13 10 4
6 10 12 10 4
6 10 11 10 4
6 10 10 10 4
6 10 9 10 4
6 10 8 10 4
6 10 7 10 68
6 11 51 11 52
6 11 50 11 4
6 11 49 11 4
6 11 48 11 0
6 11 47 11 0
6 11 46 2 0
6 11 45 2 0
6 11 44 2 0
6 11 43 2 0
6 11 42 2 0
6 11 41 2 0
6 11 40 2 0
6 11 39 9 8
6 11 38 2 0
6 11 37 2 0
6 11 36 2 0
6 11 35 9 8
6 11 34 2 0
6 11 33 2 0
6 11 32 2 0
6 11 31 9 8
6 11 30 2 0
6 11 29 2 0
6 11 28 2 0
6 11 27 9 8
6 11 26 2 0
6 11 25 2 0
6 11 24 2 0
6 11 23 9 8
6 11 22 2 0
6 11 21 2 0
6 11 20 2 0
6 11 19 2 0
6 11 18 2 0
6 11 17 2 0
6 11 16 2 0
6 11 15 2 0
6 11 14 10 0
6 11 13 10 0
6 11 12 10 0
6 11 11 10 0
6 11 10 10 4
6 11 9 10 4
6 11 8 10 4
6 11 7 10 4
6 11 6 10 20
6 11 5 10 84
6 12 51 10 36
6 12 50 10 4
6 12 49 10 4
6 12 48 10 0
6 12 47 10 2
6 12 46 2 2
6 12 45 2 2
6 12 44 2 2
6 12 43 2 2
6 12 42 10 2
6 12 41 1 2
6 12 40 1 74
6 12 38 1 42
6 12 37 1 2
6 12 36 1 74
6 12 34 1 42
6 12 33 1 2
6 12 32 1 74
6 12 30 1 42
6 12 29 1 2
6 12 28 1 74
6 12 26 1 42
6 12 25 1 2
6 12 24 1 74
6 12 22 1 42
6 12 21 1 2
6 12 20 2 0
6 12 19 2 0
6 12 18 2 0
6 12 17 2 0
6 12 16 2 0
6 12 15 2 0
6 12 14 10 0
6 12 13 10 0
6 12 12 10 4
6 12 11 10 4
6 12 10 10 4
6 12 9 10 4
6 12 8 1 4
6 12 7 1 4
6 12 6 1 4
6 12 5 1 68
6 13 51 10 36
6 13 50 10 4
6 13 49 10 4
6 13 48 10 4
6 13 47 10 6
6 13 46 10 6
6 13 45 10 6
6 13 44 10 6
6 13 43 10 6
6 13 42 10 6
6 13 41 6 66
6 13 37 6 98
6 13 33 6 98
6 13 29 6 98
6 13 25 6 98
6 13 21 1 38
6 13 20 1 6
6 13 19 2 0
6 13 18 2 0
6 13 17 2 0
6 13 16 2 0
6 13 15 2 0
6 13 14 2 0
6 13 13 2 0
6 13 12 10 0
6 13 11 10 4
6 13 10 10 4
6 13 9 10 4
6 13 8 1 4
6 13 7 16 4
6 13 6 16 4
6 13 5 1 4
6 13 4 10 84
6 14 51 10 36
6 14 50 10 6
6 14 49 1 6
6 14 48 1 4
6 14 47 1 14
6 14 46 1 14
6 14 45 1 14
6 14 44 1 14
6 14 43 1 14
6 14 42 1 14
6 14 41 6 14
6 14 40 1 30
6 14 39 1 30
6 14 38 1 30
6 14 37 6 14
6 14 36 1 30
6 14 35 1 30
6 14 34 1 30
6 14 33 6 14
6 14 32 1 30
6 14 31 1 30
6 14 30 1 30
6 14 29 6 14
6 14 28 1 30
6 14 27 1 30
6 14 26 1 30
6 14 25 6 14
6 14 24 1 30
6 14 23 1 30
6 14 22 1 30
6 14 21 1 14
6 14 20 1 14
6 14 19 1 14
6 14 18 10 4
6 14 17 2 0
6 14 16 2 0
6 14 15 2 0
6 14 14 2 0
6 14 13 2 0
6 14 12 4 0
6 14 11 4 0
6 14 10 4 4
6 14 9 4 4
6 14 8 1 4
6 14 7 16 4
6 14 6 16 4
6 14 5 1 4
6 14 4 10 68
6 15 51 1 44
6 15 50 1 14
6 15 49 1 14
6 15 48 6 76
6 15 18 10 46
6 15 17 4 4
6 15 16 4 0
6 15 15 4 0
6 15 14 4 0
6 15 13 4 0
6 15 12 4 0
6 15 11 4 0
6 15 10 4 0
6 15 9 4 4
6 15 8 1 4
6 15 7 1 4
6 15 6 1 4
6 15 5 1 4
6 15 4 10 4
6 15 3 10 28
6 15 2 10 92
6 16 17 1 46
6 16 16 1 4
6 16 15 1 4
6 16 14 1 4
6 16 13 1 4
6 16 12 1 4
6 16 11 1 4
6 16 10 1 4
6 16 9 1 4
6 16 8 1 4
6 16 7 1 4
6 16 6 1 4
6 16 5 1 4
6 16 4 1 76
6 17 16 1 46
6 17 15 1 12
6 17 14 1 12
6 17 13 1 12
6 17 12 1 12
6 17 11 1 12
6 17 10 1 12
6 17 9 1 12
6 17 8 1 12
6 17 7 1 12
6 17 6 1 12
6 17 5 1 76
7 4 48 1 48
7 4 47 1 16
7 4 46 1 16
7 4 45 1 16
7 4 44 1 16
7 4 43 1 16
7 4 42 1 16
7 4 41 1 16
7 4 40 1 16
7 4 39 1 16
7 4 38 1 16
7 4 37 1 16
7 4 36 1 16
7 4 35 1 16
7 4 34 1 16
7 4 33 1 16
7 4 32 1 16
7 4 31 1 16
7 4 30 1 16
7 4 29 1 16
7 4 28 1 16
7 4 27 1 16
7 4 26 1 16
7 4 25 1 16
7 4 24 1 16
7 4 23 1 16
7 4 22 1 16
7 4 21 1 16
7 4 20 1 16
7 4 19 1 16
7 4 18 1 16
7 4 17 1 16
7 4 16 1 20
7 4 15 1 20
7 4 14 1 84
7 5 49 1 52
7 5 48 1 0
7 5 47 1 0
7 5 46 1 0
7 5 45 1 0
7 5 44 1 0
7 5 43 1 0
7 5 42 1 0
7 5 41 1 0
7 5 40 1 0
7 5 39 1 0
7 5 38 1 0
7 5 37 1 0
7 5 36 1 0
7 5 35 1 0
7 5 34 1 0
7 5 33 1 0
7 5 32 1 0
7 5 31 1 0
7 5 30 1 0
7 5 29 1 0
7 5 28 1 0
7 5 27 1 0
7 5 26 1 0
7 5 25 1 0
7 5 24 1 0
7 5 23 1 0
7 5 22 1 0
7 5 21 1 0
7 5 20 1 0
7 5 19 1 0
7 5 18 1 0
7 5 17 1 0
7 5 16 1 0
7 5 15 1 0
7 5 14 1 4
7 5 13 1 86
7 6 50 1 52
7 6 49 1 4
7 6 48 1 0
7 6 47 1 0
7 6 46 1 0
7 6 45 1 0
7 6 44 1 0
7 6 43 1 0
7 6 42 1 0
7 6 41 1 0
7 6 40 1 0
7 6 39 1 0
7 6 38 1 0
7 6 37 0 8
7 6 36 0 8
7 6 35 1 0
7 6 34 1 0
7 6 33 1 0
7 6 32 1 0
7 6 31 0 8
7 6 30 0 8
7 6 29 1 0
7 6 28 1 0
7 6 27 1 0
7 6 26 1 0
7 6 25 0 8
7 6 24 0 8
7 6 23 1 0
7 6 22 1 0
7 6 21 1 0
7 6 20 1 0
7 6 19 1 0
7 6 18 1 0
7 6 17 1 0
7 6 16 1 0
7 6 15 1 0
7 6 14 1 0
7 6 13 1 0
7 6 12 1 84
7 7 52 1 52
7 7 51 1 20
7 7 50 1 4
7 7 49 1 0
7 7 48 1 0
7 7 47 1 0
7 7 46 1 0
7 7 45 1 0
7 7 44 1 0
7 7 43 1 0
7 7 42 2 0
7 7 41 2 0
7 7 40 2 0
7 7 39 2 0
7 7 38 0 64
7 7 35 0 32
7 7 34 2 0
7 7 33 2 0
7 7 32 0 64
7 7 29 0 32
7 7 28 2 0
7 7 27 2 0
7 7 26 0 64
7 7 23 0 32
7 7 22 2 0
7 7 21 2 0
7 7 20 2 0
7 7 19 2 0
7 7 18 2 0
7 7 17 2 0
7 7 16 2 0
7 7 15 2 0
7 7 14 1 0
7 7 13 1 0
7 7 12 1 0
7 7 11 1 20
7 7 10 1 84
7 8 52 1 36
7 8 51 1 4
7 8 50 1 4
7 8 49 1 0
7 8 48 2 0
7 8 47 2 0
7 8 46 2 0
7 8 45 2 0
7 8 44 11 0
7 8 43 11 0
7 8 42 11 0
7 8 41 11 0
7 8 40 11 0
7 8 39 11 0
7 8 38 0 64
7 8 35 0 32
7 8 34 11 0
7 8 33 11 0
7 8 32 11 0
7 8 31 0 84
7 8 29 0 32
7 8 28 11 0
7 8 27 11 0
7 8 26 0 64
7 8 23 0 32
7 8 22 11 0
7 8 21 11 0
7 8 20 2 0
7 8 19 2 0
7 8 18 2 0
7 8 17 2 0
7 8 16 2 0
7 8 15 2 0
7 8 14 2 0
7 8 13 2 0
7 8 12 2 0
7 8 11 2 0
7 8 10 2 0
7 8 9 1 16
7 8 8 1 20
7 8 7 1 20
7 8 6 1 84
7 9 52 1 36
7 9 51 1 4
7 9 50 1 4
7 9 49 1 0
7 9 48 2 0
7 9 47 2 0
7 9 46 2 0
7 9 45 2 0
7 9 44 11 0
7 9 43 11 0
7 9 42 11 0
7 9 41 11 0
7 9 40 11 0
7 9 39 11 0
7 9 38 11 0
7 9 37 0 16
7 9 36 0 16
7 9 35 11 0
7 9 34 11 0
7 9 33 11 0
7 9 32 11 0
7 9 31 11 0
7 9 30 0 16
7 9 29 11 0
7 9 28 11 0
7 9 27 11 0
7 9 26 11 0
7 9 25 0 16
7 9 24 0 16
7 9 23 11 0
7 9 22 11 0
7 9 21 11 0
7 9 20 2 0
7 9 19 2 0
7 9 18 2 0
7 9 17 2 0
7 9 16 2 0
7 9 15 2 0
7 9 14 2 0
7 9 13 2 0
7 9 12 2 0
7 9 11 2 0
7 9 10 2 0
7 9 9 2 0
7 9 8 2 0
7 9 7 2 0
7 9 6 1 4
7 9 5 1 20
7 9 4 10 20
7 9 3 10 20
7 9 2 10 84
7 10 53 1 52
7 10 52 11 4
7 10 51 11 4
7 10 50 2 0
7 10 49 2 0
7 10 48 2 0
7 10 47 2 0
7 10 46 2 0
7 10 45 2 0
7 10 44 11 0
7 10 43 11 0
7 10 42 11 0
7 10 41 11 0
7 10 40 11 0
7 10 39 11 0
7 10 38 11 0
7 10 37 11 0
7 10 36 11 0
7 10 35 11 0
7 10 34 11 0
7 10 33 11 0
7 10 32 11 0
7 10 31 11 0
7 10 30 11 0
7 10 29 11 0
7 10 28 11 0
7 10 27 11 0
7 10 26 11 0
7 10 25 11 0
7 10 24 11 0
7 10 23 11 0
7 10 22 11 0
7 10 21 11 0
7 10 20 2 0
7 10 19 2 0
7 10 18 2 0
7 10 17 2 0
7 10 16 2 0
7 10 15 2 0
7 10 14 2 0
7 10 13 2 0
7 10 12 2 0
7 10 11 2 0
7 10 10 2 0
7 10 9 2 0
7 10 8 2 0
7 10 7 10 0
7 10 6 10 4
7 10 5 10 4
7 10 4 10 4
7 10 3 10 4
7 10 2 1 68
7 11 54 11 52
7 11 53 11 4
7 11 52 11 4
7 11 51 2 0
7 11 50 2 0
7 11 49 2 0
7 11 48 2 0
7 11 47 7 8
7 11 46 7 8
7 11 45 7 8
7 11 44 7 8
7 11 43 7 8
7 11 42 7 8
7 11 41 7 8
7 11 40 7 8
7 11 39 7 8
7 11 38 7 8
7 11 37 7 8
7 11 36 7 8
7 11 35 7 8
7 11 34 7 8
7 11 33 7 8
7 11 32 7 8
7 11 31 7 8
7 11 30 7 8
7 11 29 7 8
7 11 28 7 8
7 11 27 7 8
7 11 26 7 8
7 11 25 7 8
7 11 24 7 8
7 11 23 7 8
7 11 22 7 8
7 11 21 7 8
7 11 20 2 0
7 11 19 2 0
7 11 18 2 0
7 11 17 2 0
7 11 16 2 0
7 11 15 2 0
7 11 14 2 0
7 11 13 2 0
7 11 12 2 0
7 11 11 2 0
7 11 10 2 0
7 11 9 2 0
7 11 8 2 0
7 11 7 2 0
7 11 6 10 0
7 11 5 10 0
7 11 4 10 4
7 11 3 10 4
7 11 2 1 68
7 12 54 11 36
7 12 53 11 4
7 12 52 11 4
7 12 51 2 0
7 12 50 2 0
7 12 49 2 0
7 12 48 2 64
7 12 20 2 40
7 12 19 2 0
7 12 18 2 0
7 12 17 2 0
7 12 16 2 0
7 12 15 2 0
7 12 14 2 0
7 12 13 2 0
7 12 12 2 0
7 12 11 2 0
7 12 10 2 0
7 12 9 2 0
7 12 8 2 0
7 12 7 2 0
7 12 6 2 0
7 12 5 2 0
7 12 4 10 4
7 12 3 10 4
7 12 2 1 68
7 13 54 10 36
7 13 53 10 4
7 13 52 10 4
7 13 51 2 0
7 13 50 9 8
7 13 49 9 8
7 13 48 2 64
7 13 19 2 40
7 13 18 2 0
7 13 17 2 0
7 13 16 2 0
7 13 15 2 0
7 13 14 2 0
7 13 13 2 0
7 13 12 2 0
7 13 11 2 0
7 13 10 12 0
7 13 9 12 0
7 13 8 12 0
7 13 7 12 0
7 13 6 12 0
7 13 5 12 0
7 13 4 12 0
7 13 3 10 4
7 13 2 1 68
7 14 54 10 36
7 14 53 10 6
7 14 52 10 6
7 14 51 2 66
7 14 48 2 98
7 14 18 2 40
7 14 17 2 0
7 14 16 2 0
7 14 15 2 0
7 14 14 2 0
7 14 13 2 0
7 14 12 2 0
7 14 11 2 0
7 14 10 12 0
7 14 9 12 0
7 14 8 12 0
7 14 7 12 0
7 14 6 12 0
7 14 5 12 0
7 14 4 12 0
7 14 3 10 4
7 14 2 1 68
7 15 54 1 44
7 15 53 1 14
7 15 52 1 14
7 15 51 1 74
7 15 48 6 106
7 15 17 2 40
7 15 16 2 0
7 15 15 2 0
7 15 14 2 0
7 15 13 2 0
7 15 12 2 0
7 15 11 2 0
7 15 10 12 0
7 15 9 12 0
7 15 8 12 0
7 15 7 12 0
7 15 6 12 0
7 15 5 12 0
7 15 4 12 0
7 15 3 12 0
7 15 2 12 0
7 15 1 10 20
7 15 0 10 84
7 16 16 2 40
7 16 15 2 0
7 16 14 2 0
7 16 13 2 0
7 16 12 2 0
7 16 11 2 0
7 16 10 2 0
7 16 9 2 0
7 16 8 2 0
7 16 7 6 0
7 16 6 6 0
7 16 5 6 0
7 16 4 6 0
7 16 3 1 4
7 16 2 1 4
7 16 1 1 4
7 16 0 1 68
7 17 15 2 32
7 17 14 2 0
7 17 13 2 0
7 17 12 2 0
7 17 11 2 0
7 17 10 1 0
7 17 9 1 0
7 17 8 1 0
7 17 7 1 0
7 17 6 1 0
7 17 5 1 0
7 17 4 1 4
7 17 3 1 4
7 17 2 1 4
7 17 1 1 12
7 17 0 1 76
7 18 15 6 46
7 18 14 6 14
7 18 13 6 14
7 18 12 6 14
7 18 11 6 14
7 18 10 6 14
7 18 9 6 14
7 18 8 6 14
7 18 7 6 14
7 18 6 6 14
7 18 5 6 14
7 18 4 6 14
7 18 3 6 14
7 18 2 6 76
8 3 47 5 52
8 3 46 5 20
8 3 45 5 20
8 3 44 5 20
8 3 43 5 20
8 3 42 5 20
8 3 41 5 20
8 3 40 5 20
8 3 39 5 20
8 3 38 5 20
8 3 37 5 20
8 3 36 5 20
8 3 35 5 20
8 3 34 5 20
8 3 33 5 20
8 3 32 5 20
8 3 31 5 20
8 3 30 5 20
8 3 29 5 20
8 3 28 5 20
8 3 27 5 20
8 3 26 5 20
8 3 25 5 20
8 3 24 5 20
8 3 23 5 20
8 3 22 5 20
8 3 21 5 20
8 3 20 5 20
8 3 19 5 20
8 3 18 5 20
8 3 17 5 20
8 3 16 5 20
8 3 15 5 20
8 3 14 5 84
8 4 48 1 48
8 4 47 1 0
8 4 46 1 0
8 4 45 1 0
8 4 44 1 0
8 4 43 1 0
8 4 42 7 0
8 4 41 7 0
8 4 40 1 0
8 4 39 1 0
8 4 38 1 0
8 4 37 1 0
8 4 36 1 0
8 4 35 1 0
8 4 34 1 0
8 4 33 1 0
8 4 32 1 0
8 4 31 1 0
8 4 30 1 0
8 4 29 1 0
8 4 28 1 0
8 4 27 1 0
8 4 26 1 0
8 4 25 1 0
8 4 24 1 0
8 4 23 1 0
8 4 22 1 0
8 4 21 1 0
8 4 20 1 0
8 4 19 1 0
8 4 18 1 0
8 4 17 1 0
8 4 16 1 0
8 4 15 1 0
8 4 14 1 64
8 5 49 1 48
8 5 48 1 0
8 5 47 2 0
8 5 46 2 0
8 5 45 2 0
8 5 44 2 0
8 5 43 2 0
8 5 42 7 0
8 5 41 7 0
8 5 40 2 0
8 5 39 2 0
8 5 38 2 0
8 5 37 2 0
8 5 36 2 0
8 5 35 2 0
8 5 34 2 0
8 5 33 2 0
8 5 32 2 0
8 5 31 2 0
8 5 30 2 0
8 5 29 2 0
8 5 28 2 0
8 5 27 2 0
8 5 26 2 0
8 5 25 2 0
8 5 24 2 0
8 5 23 2 0
8 5 22 2 0
8 5 21 2 0
8 5 20 2 0
8 5 19 2 0
8 5 18 2 0
8 5 17 2 0
8 5 16 2 0
8 5 15 2 0
8 5 14 1 64
8 6 50 1 48
8 6 49 1 0
8 6 48 2 0
8 6 47 2 0
8 6 46 2 0
8 6 45 2 0
8 6 44 2 0
8 6 43 2 0
8 6 42 7 0
8 6 41 7 0
8 6 40 2 0
8 6 39 2 0
8 6 38 2 0
8 6 37 2 0
8 6 36 2 0
8 6 35 2 0
8 6 34 2 0
8 6 33 2 0
8 6 32 2 0
8 6 31 0 8
8 6 30 0 8
8 6 29 2 0
8 6 28 2 0
8 6 27 2 0
8 6 26 2 0
8 6 25 0 8
8 6 24 0 8
8 6 23 2 0
8 6 22 2 0
8 6 21 2 0
8 6 20 2 0
8 6 19 2 0
8 6 18 2 0
8 6 17 2 0
8 6 16 2 0
8 6 15 2 0
8 6 14 2 0
8 6 13 1 16
8 6 12 1 16
8 6 11 1 84
8 7 52 1 48
8 7 51 1 16
8 7 50 1 0
8 7 49 2 0
8 7 48 2 0
8 7 47 2 0
8 7 46 2 0
8 7 45 2 0
8 7 44 2 0
8 7 43 2 0
8 7 42 7 0
8 7 41 7 0
8 7 40 2 0
8 7 39 2 0
8 7 38 2 0
8 7 37 0 4
8 7 36 0 12
8 7 35 2 0
8 7 34 2 0
8 7 33 2 0
8 7 32 0 64
8 7 29 0 32
8 7 28 2 0
8 7 27 2 0
8 7 26 0 64
8 7 23 0 32
8 7 22 2 0
8 7 21 2 0
8 7 20 2 0
8 7 19 2 0
8 7 18 2 0
8 7 17 2 0
8 7 16 2 0
8 7 15 2 0
8 7 14 2 0
8 7 13 2 0
8 7 12 2 0
8 7 11 2 0
8 7 10 1 16
8 7 9 1 84
8 8 54 1 52
8 8 53 1 20
8 8 52 1 0
8 8 51 1 0
8 8 50 2 0
8 8 49 2 0
8 8 48 2 0
8 8 47 2 0
8 8 46 2 0
8 8 45 2 0
8 8 44 11 0
8 8 43 11 0
8 8 42 7 0
8 8 41 7 0
8 8 40 11 0
8 8 39 11 0
8 8 38 11 0
8 8 37 0 68
8 8 35 0 32
8 8 34 11 0
8 8 33 11 0
8 8 32 11 0
8 8 31 0 16
8 8 30 0 20
8 8 29 11 0
8 8 28 11 0
8 8 27 11 0
8 8 26 0 64
8 8 23 0 32
8 8 22 11 0
8 8 21 11 0
8 8 20 2 0
8 8 19 2 0
8 8 18 2 0
8 8 17 2 0
8 8 16 2 0
8 8 15 2 0
8 8 14 2 0
8 8 13 2 0
8 8 12 2 0
8 8 11 2 0
8 8 10 2 0
8 8 9 2 0
8 8 8 1 16
8 8 7 1 16
8 8 6 1 16
8 8 5 1 84
8 9 54 1 36
8 9 53 1 4
8 9 52 2 0
8 9 51 2 0
8 9 50 2 0
8 9 49 2 0
8 9 48 2 0
8 9 47 2 0
8 9 46 2 0
8 9 45 2 0
8 9 44 11 0
8 9 43 7 0
8 9 42 7 0
8 9 41 7 0
8 9 40 11 0
8 9 39 11 0
8 9 38 11 0
8 9 37 11 0
8 9 36 0 16
8 9 35 11 0
8 9 34 11 0
8 9 33 11 0
8 9 32 11 0
8 9 31 11 0
8 9 30 11 0
8 9 29 11 0
8 9 28 11 0
8 9 27 11 0
8 9 26 11 0
8 9 25 0 16
8 9 24 0 16
8 9 23 11 0
8 9 22 11 0
8 9 21 11 0
8 9 20 2 0
8 9 19 2 0
8 9 18 2 0
8 9 17 2 0
8 9 16 2 0
8 9 15 2 0
8 9 14 2 0
8 9 13 2 0
8 9 12 2 0
8 9 11 2 0
8 9 10 2 0
8 9 9 2 0
8 9 8 2 0
8 9 7 2 0
8 9 6 2 0
8 9 5 2 0
8 9 4 10 16
8 9 3 10 16
8 9 2 10 80
8 10 55 1 52
8 10 54 1 4
8 10 53 2 0
8 10 52 2 0
8 10 51 2 0
8 10 50 2 0
8 10 49 2 0
8 10 48 2 0
8 10 47 2 0
8 10 46 2 0
8 10 45 2 0
8 10 44 11 0
8 10 43 7 0
8 10 42 7 0
8 10 41 7 0
8 10 40 11 0
8 10 39 11 0
8 10 38 11 0
8 10 37 11 0
8 10 36 11 0
8 10 35 11 0
8 10 34 11 0
8 10 33 11 0
8 10 32 11 0
8 10 31 11 0
8 10 30 11 0
8 10 29 11 0
8 10 28 11 0
8 10 27 11 0
8 10 26 11 0
8 10 25 11 0
8 10 24 11 0
8 10 23 11 0
8 10 22 11 0
8 10 21 11 0
8 10 20 2 0
8 10 19 2 0
8 10 18 2 0
8 10 17 2 0
8 10 16 2 0
8 10 15 2 0
8 10 14 2 0
8 10 13 2 0
8 10 12 2 0
8 10 11 2 0
8 10 10 2 0
8 10 9 2 0
8 10 8 2 0
8 10 7 2 0
8 10 6 2 0
8 10 5 2 0
8 10 4 2 0
8 10 3 2 0
8 10 2 1 64
8 11 56 11 52
8 11 55 11 4
8 11 54 2 0
8 11 53 2 0
8 11 52 2 0
8 11 51 2 0
8 11 50 2 0
8 11 49 2 0
8 11 48 2 0
8 11 47 7 0
8 11 46 7 8
8 11 45 7 8
8 11 44 7 8
8 11 43 7 8
8 11 42 7 8
8 11 41 7 8
8 11 40 7 8
8 11 39 7 8
8 11 38 7 8
8 11 37 7 8
8 11 36 7 8
8 11 35 7 8
8 11 34 7 8
8 11 33 7 8
8 11 32 7 8
8 11 31 7 8
8 11 30 7 8
8 11 29 7 8
8 11 28 7 8
8 11 27 7 8
8 11 26 7 8
8 11 25 7 8
8 11 24 7 8
8 11 23 7 8
8 11 22 7 8
8 11 21 7 8
8 11 20 2 0
8 11 19 2 0
8 11 18 2 0
8 11 17 2 0
8 11 16 2 0
8 11 15 2 0
8 11 14 2 0
8 11 13 2 0
8 11 12 2 0
8 11 11 2 0
8 11 10 2 0
8 11 9 2 0
8 11 8 2 0
8 11 7 2 0
8 11 6 2 0
8 11 5 2 0
8 11 4 2 0
8 11 3 2 0
8 11 2 16 64
8 12 56 11 36
8 12 55 11 4
8 12 54 2 0
8 12 53 2 0
8 12 52 2 0
8 12 51 2 0
8 12 50 2 0
8 12 49 2 0
8 12 48 8 0
8 12 47 5 76
8 12 20 3 40
8 12 19 2 0
8 12 18 2 0
8 12 17 2 0
8 12 16 2 0
8 12 15 2 0
8 12 14 2 0
8 12 13 2 0
8 12 12 2 0
8 12 11 2 0
8 12 10 2 0
8 12 9 2 0
8 12 8 2 0
8 12 7 2 0
8 12 6 2 0
8 12 5 2 0
8 12 4 2 0
8 12 3 2 0
8 12 2 16 64
8 13 56 10 36
8 13 55 10 4
8 13 54 2 0
8 13 53 8 8
8 13 52 9 8
8 13 51 9 8
8 13 50 8 8
8 13 49 8 8
8 13 48 5 72
8 13 19 3 40
8 13 18 2 0
8 13 17 2 0
8 13 16 2 0
8 13 15 2 0
8 13 14 2 0
8 13 13 2 0
8 13 12 2 0
8 13 11 2 0
8 13 10 12 0
8 13 9 12 0
8 13 8 12 0
8 13 7 12 0
8 13 6 12 0
8 13 5 12 0
8 13 4 12 0
8 13 3 12 0
8 13 2 16 64
8 14 56 10 36
8 14 55 10 6
8 14 54 2 66
8 14 18 3 40
8 14 17 2 0
8 14 16 2 0
8 14 15 2 0
8 14 14 2 0
8 14 13 2 0
8 14 12 2 0
8 14 11 2 0
8 14 10 12 0
8 14 9 12 0
8 14 8 12 0
8 14 7 12 0
8 14 6 12 0
8 14 5 12 0
8 14 4 12 0
8 14 3 12 0
8 14 2 16 64
8 15 56 1 44
8 15 55 1 14
8 15 54 2 74
8 15 17 3 40
8 15 16 2 0
8 15 15 2 0
8 15 14 2 0
8 15 13 2 0
8 15 12 2 0
8 15 11 2 0
8 15 10 12 0
8 15 9 12 0
8 15 8 12 0
8 15 7 12 0
8 15 6 12 0
8 15 5 12 0
8 15 4 12 0
8 15 3 12 0
8 15 2 12 0
8 15 1 10 16
8 15 0 10 80
8 16 16 3 40
8 16 15 2 0
8 16 14 2 0
8 16 13 2 0
8 16 12 6 0
8 16 11 6 0
8 16 10 6 0
8 16 9 6 0
8 16 8 6 0
8 16 7 6 0
8 16 6 6 0
8 16 5 6 0
8 16 4 6 0
8 16 3 6 0
8 16 2 6 0
8 16 1 6 0
8 16 0 1 64
8 17 15 3 40
8 17 14 7 8
8 17 13 7 8
8 17 12 7 8
8 17 11 7 8
8 17 10 7 8
8 17 9 7 8
8 17 8 7 8
8 17 7 7 8
8 17 6 7 8
8 17 5 7 8
8 17 4 7 8
8 17 3 7 8
8 17 2 6 0
8 17 1 6 0
8 17 0 1 72
8 18 2 6 40
8 18 1 6 76
9 3 47 5 48
9 3 46 5 16
9 3 45 5 16
9 3 44 5 16
9 3 43 5 16
9 3 42 5 16
9 3 41 5 16
9 3 40 5 16
9 3 39 5 16
9 3 38 5 16
9 3 37 5 16
9 3 36 5 16
9 3 35 5 16
9 3 34 5 16
9 3 33 5 16
9 3 32 5 16
9 3 31 5 16
9 3 30 5 16
9 3 29 5 16
9 3 28 5 16
9 3 27 5 16
9 3 26 5 16
9 3 25 5 16
9 3 24 5 16
9 3 23 5 16
9 3 22 5 16
9 3 21 5 16
9 3 20 5 16
9 3 19 5 16
9 3 18 5 16
9 3 17 5 16
9 3 16 5 16
9 3 15 5 16
9 3 14 5 16
9 3 13 5 84
9 4 48 5 48
9 4 47 2 0
9 4 46 2 0
9 4 45 2 0
9 4 44 2 0
9 4 43 2 0
9 4 42 7 0
9 4 41 7 0
9 4 40 7 0
9 4 39 7 0
9 4 38 7 0
9 4 37 7 0
9 4 36 7 0
9 4 35 7 0
9 4 34 7 0
9 4 33 7 0
9 4 32 7 0
9 4 31 7 0
9 4 30 7 0
9 4 29 2 0
9 4 28 2 0
9 4 27 2 0
9 4 26 2 0
9 4 25 2 0
9 4 24 2 0
9 4 23 2 0
9 4 22 2 0
9 4 21 2 0
9 4 20 2 0
9 4 19 2 0
9 4 18 2 0
9 4 17 2 0
9 4 16 2 0
9 4 15 2 0
9 4 14 2 0
9 4 13 1 4
9 4 12 5 84
9 5 51 5 52
9 5 50 1 20
9 5 49 1 16
9 5 48 2 0
9 5 47 2 0
9 5 46 2 0
9 5 45 2 0
9 5 44 2 0
9 5 43 2 0
9 5 42 7 0
9 5 41 7 0
9 5 40 7 0
9 5 39 7 0
9 5 38 7 0
9 5 37 7 0
9 5 36 7 0
9 5 35 7 0
9 5 34 7 0
9 5 33 7 0
9 5 32 7 0
9 5 31 7 0
9 5 30 7 0
9 5 29 2 0
9 5 28 2 0
9 5 27 2 0
9 5 26 2 0
9 5 25 2 0
9 5 24 2 0
9 5 23 2 0
9 5 22 2 0
9 5 21 2 0
9 5 20 2 0
9 5 19 2 0
9 5 18 2 0
9 5 17 2 0
9 5 16 2 0
9 5 15 2 0
9 5 14 2 0
9 5 13 1 4
9 5 12 1 4
9 5 11 1 84
9 6 54 1 52
9 6 53 1 20
9 6 52 1 20
9 6 51 1 4
9 6 50 1 0
9 6 49 2 0
9 6 48 2 0
9 6 47 2 0
9 6 46 2 0
9 6 45 2 0
9 6 44 2 0
9 6 43 2 0
9 6 42 7 0
9 6 41 7 0
9 6 40 7 0
9 6 39 7 0
9 6 38 7 0
9 6 37 7 0
9 6 36 7 0
9 6 35 7 0
9 6 34 7 0
9 6 33 7 0
9 6 32 7 0
9 6 31 7 0
9 6 30 7 0
9 6 29 2 0
9 6 28 2 0
9 6 27 2 0
9 6 26 2 0
9 6 25 0 8
9 6 24 0 8
9 6 23 2 0
9 6 22 2 0
9 6 21 2 0
9 6 20 2 0
9 6 19 2 0
9 6 18 2 0
9 6 17 2 0
9 6 16 2 0
9 6 15 2 0
9 6 14 2 0
9 6 13 2 0
9 6 12 2 0
9 6 11 2 0
9 6 10 1 20
9 6 9 1 84
9 7 55 1 52
9 7 54 1 4
9 7 53 1 4
9 7 52 2 0
9 7 51 2 0
9 7 50 2 0
9 7 49 2 0
9 7 48 2 0
9 7 47 2 0
9 7 46 2 0
9 7 45 2 0
9 7 44 2 0
9 7 43 2 0
9 7 42 7 0
9 7 41 7 0
9 7 40 7 0
9 7 39 7 0
9 7 38 7 0
9 7 37 0 0
9 7 36 0 8
9 7 35 7 0
9 7 34 7 0
9 7 33 7 0
9 7 32 7 0
9 7 31 0 4
9 7 30 0 4
9 7 29 2 0
9 7 28 2 0
9 7 27 2 0
9 7 26 0 64
9 7 23 0 32
9 7 22 2 0
9 7 21 2 0
9 7 20 2 0
9 7 19 2 0
9 7 18 2 0
9 7 17 2 0
9 7 16 2 0
9 7 15 2 0
9 7 14 2 0
9 7 13 2 0
9 7 12 2 0
9 7 11 2 0
9 7 10 2 0
9 7 9 2 0
9 7 8 1 20
9 7 7 1 84
9 8 56 1 52
9 8 55 1 4
9 8 54 1 0
9 8 53 1 0
9 8 52 2 0
9 8 51 2 0
9 8 50 2 0
9 8 49 2 0
9 8 48 2 0
9 8 47 2 0
9 8 46 2 0
9 8 45 2 0
9 8 44 11 0
9 8 43 7 0
9 8 42 7 0
9 8 41 7 0
9 8 40 7 0
9 8 39 7 0
9 8 38 7 0
9 8 37 0 64
9 8 35 0 32
9 8 34 7 0
9 8 33 7 0
9 8 32 7 0
9 8 31 0 0
9 8 30 0 0
9 8 29 11 0
9 8 28 11 0
9 8 27 11 0
9 8 26 0 64
9 8 23 0 32
9 8 22 11 0
9 8 21 11 0
9 8 20 2 0
9 8 19 2 0
9 8 18 2 0
9 8 17 2 0
9 8 16 2 0
9 8 15 2 0
9 8 14 2 0
9 8 13 2 0
9 8 12 2 0
9 8 11 2 0
9 8 10 2 0
9 8 9 2 0
9 8 8 2 0
9 8 7 2 0
9 8 6 1 16
9 8 5 1 16
9 8 4 10 84
9 9 57 1 52
9 9 56 1 4
9 9 55 1 4
9 9 54 2 0
9 9 53 2 0
9 9 52 2 0
9 9 51 2 0
9 9 50 2 0
9 9 49 2 0
9 9 48 2 0
9 9 47 2 0
9 9 46 2 0
9 9 45 2 0
9 9 44 11 0
9 9 43 7 0
9 9 42 7 0
9 9 41 7 0
9 9 40 7 0
9 9 39 7 0
9 9 38 7 0
9 9 37 7 0
9 9 36 0 16
9 9 35 7 0
9 9 34 7 0
9 9 33 7 0
9 9 32 7 0
9 9 31 7 0
9 9 30 7 0
9 9 29 11 0
9 9 28 11 0
9 9 27 11 0
9 9 26 11 0
9 9 25 0 16
9 9 24 0 16
9 9 23 11 0
9 9 22 11 0
9 9 21 11 0
9 9 20 2 0
9 9 19 2 0
9 9 18 2 0
9 9 17 2 0
9 9 16 2 0
9 9 15 2 0
9 9 14 2 0
9 9 13 2 0
9 9 12 2 0
9 9 11 2 0
9 9 10 2 0
9 9 9 2 0
9 9 8 2 0
9 9 7 2 0
9 9 6 2 0
9 9 5 2 0
9 9 4 10 0
9 9 3 10 16
9 9 2 10 80
9 10 58 1 52
9 10 57 1 4
9 10 56 1 4
9 10 55 2 0
9 10 54 2 0
9 10 53 2 0
9 10 52 2 0
9 10 51 2 0
9 10 50 2 0
9 10 49 2 0
9 10 48 2 0
9 10 47 2 0
9 10 46 2 0
9 10 45 2 0
9 10 44 11 0
9 10 43 7 0
9 10 42 7 0
9 10 41 7 0
9 10 40 7 0
9 10 39 7 0
9 10 38 7 0
9 10 37 7 0
9 10 36 7 0
9 10 35 7 0
9 10 34 7 0
9 10 33 7 0
9 10 32 7 0
9 10 31 7 0
9 10 30 7 0
9 10 29 11 0
9 10 28 11 0
9 10 27 11 0
9 10 26 11 0
9 10 25 11 0
9 10 24 11 0
9 10 23 11 0
9 10 22 11 0
9 10 21 11 0
9 10 20 2 0
9 10 19 2 0
9 10 18 2 0
9 10 17 2 0
9 10 16 2 0
9 10 15 2 0
9 10 14 2 0
9 10 13 2 0
9 10 12 2 0
9 10 11 2 0
9 10 10 2 0
9 10 9 2 0
9 10 8 2 0
9 10 7 2 0
9 10 6 2 0
9 10 5 2 0
9 10 4 2 0
9 10 3 2 0
9 10 2 1 64
9 11 60 1 62
9 11 59 1 28
9 11 58 1 4
9 11 57 1 4
9 11 56 2 0
9 11 55 2 0
9 11 54 2 0
9 11 53 2 0
9 11 52 2 0
9 11 51 2 0
9 11 50 2 0
9 11 49 2 0
9 11 48 2 0
9 11 47 7 0
9 11 46 9 8
9 11 45 9 8
9 11 44 9 8
9 11 43 9 8
9 11 42 9 8
9 11 41 9 8
9 11 40 9 8
9 11 39 9 8
9 11 38 9 8
9 11 37 7 8
9 11 36 7 8
9 11 35 7 8
9 11 34 7 8
9 11 33 9 8
9 11 32 9 8
9 11 31 9 8
9 11 30 9 8
9 11 29 9 8
9 11 28 9 8
9 11 27 9 8
9 11 26 7 8
9 11 25 7 8
9 11 24 7 8
9 11 23 7 8
9 11 22 7 8
9 11 21 7 8
9 11 20 2 0
9 11 19 2 0
9 11 18 2 0
9 11 17 2 0
9 11 16 2 0
9 11 15 2 0
9 11 14 2 0
9 11 13 2 0
9 11 12 2 0
9 11 11 2 0
9 11 10 2 0
9 11 9 2 0
9 11 8 2 0
9 11 7 2 0
9 11 6 2 0
9 11 5 2 0
9 11 4 2 0
9 11 3 2 0
9 11 2 1 64
9 12 58 10 36
9 12 57 10 4
9 12 56 2 0
9 12 55 2 0
9 12 54 2 0
9 12 53 2 0
9 12 52 2 0
9 12 51 2 0
9 12 50 2 0
9 12 49 2 0
9 12 48 2 0
9 12 47 5 72
9 12 20 3 40
9 12 19 2 0
9 12 18 2 0
9 12 17 2 0
9 12 16 2 0
9 12 15 2 0
9 12 14 2 0
9 12 13 2 0
9 12 12 2 0
9 12 11 2 0
9 12 10 2 0
9 12 9 2 0
9 12 8 2 0
9 12 7 2 0
9 12 6 2 0
9 12 5 2 0
9 12 4 2 0
9 12 3 2 0
9 12 2 1 64
9 13 58 10 36
9 13 57 10 4
9 13 56 2 0
9 13 55 8 8
9 13 54 9 8
9 13 53 9 8
9 13 52 8 8
9 13 51 8 8
9 13 50 8 8
9 13 49 8 8
9 13 48 5 72
9 13 19 3 42
9 13 18 2 2
9 13 17 2 0
9 13 16 2 0
9 13 15 2 0
9 13 14 2 0
9 13 13 2 0
9 13 12 2 0
9 13 11 2 0
9 13 10 12 0
9 13 9 12 0
9 13 8 12 0
9 13 7 12 0
9 13 6 12 0
9 13 5 12 0
9 13 4 12 0
9 13 3 12 0
9 13 2 1 64
9 14 58 10 38
9 14 57 10 6
9 14 56 2 66
9 14 18 3 42
9 14 17 2 0
9 14 16 2 0
9 14 15 2 0
9 14 14 2 0
9 14 13 2 0
9 14 12 2 0
9 14 11 2 0
9 14 10 12 0
9 14 9 12 0
9 14 8 12 0
9 14 7 12 0
9 14 6 12 0
9 14 5 12 0
9 14 4 12 0
9 14 3 12 0
9 14 2 1 64
9 15 58 10 36
9 15 57 10 6
9 15 56 2 74
9 15 17 3 40
9 15 16 2 0
9 15 15 2 0
9 15 14 2 0
9 15 13 2 0
9 15 12 2 0
9 15 11 2 0
9 15 10 12 0
9 15 9 12 0
9 15 8 12 0
9 15 7 12 0
9 15 6 12 0
9 15 5 12 0
9 15 4 12 0
9 15 3 12 0
9 15 2 12 0
9 15 1 10 16
9 15 0 10 80
9 16 58 1 46
9 16 57 1 78
9 16 16 3 40
9 16 15 6 0
9 16 14 6 0
9 16 13 6 0
9 16 12 6 0
9 16 11 6 0
9 16 10 6 0
9 16 9 6 0
9 16 8 6 0
9 16 7 6 0
9 16 6 6 0
9 16 5 6 0
9 16 4 6 0
9 16 3 6 0
9 16 2 6 0
9 16 1 6 0
9 16 0 1 64
9 17 15 3 40
9 17 14 7 8
9 17 13 9 8
9 17 12 9 8
9 17 11 9 8
9 17 10 9 8
9 17 9 9 8
9 17 8 9 8
9 17 7 9 8
9 17 6 9 8
9 17 5 9 8
9 17 4 7 8
9 17 3 7 8
9 17 2 6 0
9 17 1 6 0
9 17 0 1 72
9 18 2 6 40
9 18 1 6 72
10 3 47 5 48
10 3 46 5 16
10 3 45 5 16
10 3 44 5 16
10 3 43 5 16
10 3 42 5 16
10 3 41 5 16
10 3 40 5 16
10 3 39 5 16
10 3 38 5 16
10 3 37 5 16
10 3 36 5 16
10 3 35 5 16
10 3 34 5 16
10 3 33 5 16
10 3 32 5 16
10 3 31 5 16
10 3 30 5 16
10 3 29 5 16
10 3 28 5 16
10 3 27 5 16
10 3 26 5 16
10 3 25 5 16
10 3 24 5 16
10 3 23 5 16
10 3 22 5 16
10 3 21 5 16
10 3 20 5 16
10 3 19 5 16
10 3 18 5 16
10 3 17 5 16
10 3 16 5 16
10 3 15 5 16
10 3 14 5 16
10 3 13 5 16
10 3 12 5 84
10 4 50 5 52
10 4 49 5 20
10 4 48 5 16
10 4 47 2 0
10 4 46 2 0
10 4 45 2 0
10 4 44 2 0
10 4 43 2 0
10 4 42 7 0
10 4 41 7 0
10 4 40 7 0
10 4 39 7 0
10 4 38 7 0
10 4 37 7 0
10 4 36 7 0
10 4 35 7 0
10 4 34 7 0
10 4 33 7 0
10 4 32 7 0
10 4 31 7 0
10 4 30 7 0
10 4 29 7 0
10 4 28 7 0
10 4 27 7 0
10 4 26 7 0
10 4 25 7 0
10 4 24 7 0
10 4 23 7 0
10 4 22 7 0
10 4 21 7 0
10 4 20 2 0
10 4 19 2 0
10 4 18 2 0
10 4 17 2 0
10 4 16 2 0
10 4 15 2 0
10 4 14 2 0
10 4 13 2 0
10 4 12 2 0
10 4 11 5 84
10 5 53 5 52
10 5 52 5 20
10 5 51 5 16
10 5 50 2 0
10 5 49 2 0
10 5 48 2 0
10 5 47 2 0
10 5 46 2 0
10 5 45 2 0
10 5 44 2 0
10 5 43 2 0
10 5 42 7 0
10 5 41 7 0
10 5 40 7 0
10 5 39 7 0
10 5 38 7 0
10 5 37 7 0
10 5 36 7 0
10 5 35 7 0
10 5 34 7 0
10 5 33 7 0
10 5 32 7 0
10 5 31 7 0
10 5 30 7 0
10 5 29 7 0
10 5 28 7 0
10 5 27 7 0
10 5 26 7 0
10 5 25 7 0
10 5 24 7 0
10 5 23 7 0
10 5 22 7 0
10 5 21 7 0
10 5 20 2 0
10 5 19 2 0
10 5 18 2 0
10 5 17 2 0
10 5 16 2 0
10 5 15 2 0
10 5 14 2 0
10 5 13 2 0
10 5 12 2 0
10 5 11 2 0
10 5 10 1 84
10 6 55 5 52
10 6 54 2 16
10 6 53 2 0
10 6 52 2 0
10 6 51 2 0
10 6 50 2 0
10 6 49 2 0
10 6 48 2 0
10 6 47 2 0
10 6 46 2 0
10 6 45 2 0
10 6 44 2 0
10 6 43 2 0
10 6 42 7 0
10 6 41 7 0
10 6 40 7 0
10 6 39 7 0
10 6 38 7 0
10 6 37 7 0
10 6 36 7 0
10 6 35 7 0
10 6 34 7 0
10 6 33 7 0
10 6 32 7 0
10 6 31 7 0
10 6 30 7 0
10 6 29 7 0
10 6 28 7 0
10 6 27 7 0
10 6 26 7 0
10 6 25 0 8
10 6 24 0 8
10 6 23 7 0
10 6 22 7 0
10 6 21 7 0
10 6 20 2 0
10 6 19 2 0
10 6 18 2 0
10 6 17 2 0
10 6 16 2 0
10 6 15 2 0
10 6 14 2 0
10 6 13 2 0
10 6 12 2 0
10 6 11 2 0
10 6 10 2 0
10 6 9 1 16
10 6 8 1 84
10 7 57 1 52
10 7 56 1 20
10 7 55 2 0
10 7 54 2 0
10 7 53 2 0
10 7 52 2 0
10 7 51 2 0
10 7 50 2 0
10 7 49 2 0
10 7 48 2 0
10 7 47 2 0
10 7 46 2 0
10 7 45 2 0
10 7 44 2 0
10 7 43 7 0
10 7 42 7 0
10 7 41 7 0
10 7 40 7 0
10 7 39 7 0
10 7 38 7 0
10 7 37 0 0
10 7 36 0 0
10 7 35 7 0
10 7 34 7 0
10 7 33 7 0
10 7 32 7 0
10 7 31 7 0
10 7 30 7 0
10 7 29 7 0
10 7 28 7 0
10 7 27 7 0
10 7 26 0 64
10 7 23 0 32
10 7 22 7 0
10 7 21 7 0
10 7 20 2 0
10 7 19 2 0
10 7 18 2 0
10 7 17 2 0
10 7 16 2 0
10 7 15 2 0
10 7 14 2 0
10 7 13 2 0
10 7 12 2 0
10 7 11 2 0
10 7 10 2 0
10 7 9 2 0
10 7 8 2 0
10 7 7 1 16
10 7 6 1 84
10 8 57 1 36
10 8 56 1 0
10 8 55 1 0
10 8 54 1 0
10 8 53 2 0
10 8 52 2 0
10 8 51 2 0
10 8 50 2 0
10 8 49 2 0
10 8 48 2 0
10 8 47 2 0
10 8 46 2 0
10 8 45 2 0
10 8 44 11 0
10 8 43 7 0
10 8 42 7 0
10 8 41 7 0
10 8 40 7 0
10 8 39 7 0
10 8 38 7 0
10 8 37 0 0
10 8 36 0 4
10 8 35 7 0
10 8 34 7 0
10 8 33 7 0
10 8 32 7 0
10 8 31 7 0
10 8 30 7 0
10 8 29 7 0
10 8 28 7 0
10 8 27 7 0
10 8 26 0 64
10 8 23 0 32
10 8 22 7 0
10 8 21 7 0
10 8 20 2 0
10 8 19 2 0
10 8 18 2 0
10 8 17 2 0
10 8 16 2 0
10 8 15 2 0
10 8 14 2 0
10 8 13 2 0
10 8 12 2 0
10 8 11 2 0
10 8 10 2 0
10 8 9 2 0
10 8 8 2 0
10 8 7 2 0
10 8 6 2 0
10 8 5 1 16
10 8 4 10 80
10 9 58 1 52
10 9 57 1 0
10 9 56 2 0
10 9 55 2 0
10 9 54 2 0
10 9 53 2 0
10 9 52 2 0
10 9 51 2 0
10 9 50 2 0
10 9 49 2 0
10 9 48 2 0
10 9 47 2 0
10 9 46 2 0
10 9 45 2 0
10 9 44 11 0
10 9 43 7 0
10 9 42 7 0
10 9 41 7 0
10 9 40 7 0
10 9 39 7 0
10 9 38 7 0
10 9 37 7 0
10 9 36 7 0
10 9 35 7 0
10 9 34 7 0
10 9 33 7 0
10 9 32 7 0
10 9 31 7 0
10 9 30 7 0
10 9 29 7 0
10 9 28 7 0
10 9 27 7 0
10 9 26 7 0
10 9 25 0 16
10 9 24 0 16
10 9 23 7 0
10 9 22 7 0
10 9 21 7 0
10 9 20 2 0
10 9 19 2 0
10 9 18 2 0
10 9 17 2 0
10 9 16 2 0
10 9 15 2 0
10 9 14 2 0
10 9 13 2 0
10 9 12 2 0
10 9 11 2 0
10 9 10 2 0
10 9 9 2 0
10 9 8 2 0
10 9 7 2 0
10 9 6 2 0
10 9 5 2 0
10 9 4 10 0
10 9 3 10 16
10 9 2 10 80
10 10 60 1 60
10 10 59 1 20
10 10 58 2 0
10 10 57 2 0
10 10 56 2 0
10 10 55 2 0
10 10 54 2 0
10 10 53 2 0
10 10 52 2 0
10 10 51 2 0
10 10 50 2 0
10 10 49 2 0
10 10 48 2 0
10 10 47 2 0
10 10 46 2 0
10 10 45 2 0
10 10 44 11 0
10 10 43 7 0
10 10 42 7 0
10 10 41 7 0
10 10 40 7 0
10 10 39 7 0
10 10 38 7 0
10 10 37 7 0
10 10 36 7 0
10 10 35 7 0
10 10 34 7 0
10 10 33 7 0
10 10 32 7 0
10 10 31 7 0
10 10 30 7 0
10 10 29 7 0
10 10 28 7 0
10 10 27 7 0
10 10 26 7 0
10 10 25 7 0
10 10 24 7 0
10 10 23 7 0
10 10 22 7 0
10 10 21 7 0
10 10 20 2 0
10 10 19 2 0
10 10 18 2 0
10 10 17 2 0
10 10 16 2 0
10 10 15 2 0
10 10 14 2 0
10 10 13 2 0
10 10 12 2 0
10 10 11 2 0
10 10 10 2 0
10 10 9 2 0
10 10 8 2 0
10 10 7 2 0
10 10 6 2 0
10 10 5 2 0
10 10 4 2 0
10 10 3 2 0
10 10 2 2 0
10 10 1 1 84
10 11 62 1 62
10 11 61 1 94
10 11 59 10 32
10 11 58 2 0
10 11 57 2 0
10 11 56 2 0
10 11 55 2 0
10 11 54 2 0
10 11 53 2 0
10 11 52 2 0
10 11 51 2 0
10 11 50 2 0
10 11 49 2 0
10 11 48 2 0
10 11 47 7 0
10 11 46 7 8
10 11 45 7 8
10 11 44 7 8
10 11 43 7 8
10 11 42 7 8
10 11 41 7 8
10 11 40 7 8
10 11 39 7 8
10 11 38 7 8
10 11 37 7 8
10 11 36 7 8
10 11 35 7 8
10 11 34 7 8
10 11 33 7 8
10 11 32 7 8
10 11 31 7 8
10 11 30 7 8
10 11 29 7 8
10 11 28 7 8
10 11 27 7 8
10 11 26 7 8
10 11 25 7 8
10 11 24 7 8
10 11 23 7 8
10 11 22 7 8
10 11 21 7 8
10 11 20 2 0
10 11 19 2 0
10 11 18 2 0
10 11 17 2 0
10 11 16 2 0
10 11 15 2 0
10 11 14 2 0
10 11 13 2 0
10 11 12 2 0
10 11 11 2 0
10 11 10 2 0
10 11 9 2 0
10 11 8 2 0
10 11 7 2 0
10 11 6 2 0
10 11 5 2 0
10 11 4 2 0
10 11 3 2 0
10 11 2 2 0
10 11 1 1 68
10 12 59 10 36
10 12 58 10 0
10 12 57 2 0
10 12 56 2 0
10 12 55 2 0
10 12 54 2 0
10 12 53 2 0
10 12 52 2 0
10 12 51 2 0
10 12 50 2 0
10 12 49 2 0
10 12 48 8 0
10 12 47 5 74
10 12 20 2 40
10 12 19 7 8
10 12 18 2 8
10 12 17 2 0
10 12 16 2 0
10 12 15 2 0
10 12 14 2 0
10 12 13 2 0
10 12 12 2 0
10 12 11 2 0
10 12 10 2 0
10 12 9 2 0
10 12 8 2 0
10 12 7 2 0
10 12 6 2 0
10 12 5 2 0
10 12 4 2 0
10 12 3 2 0
10 12 2 2 0
10 12 1 1 68
10 13 59 10 36
10 13 58 10 8
10 13 57 8 8
10 13 56 10 8
10 13 55 10 8
10 13 54 9 8
10 13 53 8 8
10 13 52 8 8
10 13 51 9 8
10 13 50 8 8
10 13 49 8 8
10 13 48 5 72
10 13 17 8 32
10 13 16 2 0
10 13 15 2 0
10 13 14 2 0
10 13 13 2 0
10 13 12 2 0
10 13 11 2 0
10 13 10 12 0
10 13 9 12 0
10 13 8 12 0
10 13 7 12 0
10 13 6 12 0
10 13 5 12 0
10 13 4 12 0
10 13 3 12 0
10 13 2 12 0
10 13 1 1 68
10 14 59 10 100
10 14 17 8 32
10 14 16 2 0
10 14 15 2 0
10 14 14 2 0
10 14 13 2 0
10 14 12 2 0
10 14 11 2 0
10 14 10 12 0
10 14 9 12 0
10 14 8 12 0
10 14 7 12 0
10 14 6 12 0
10 14 5 12 0
10 14 4 12 0
10 14 3 12 0
10 14 2 12 0
10 14 1 1 68
10 15 59 10 36
10 15 58 10 90
10 15 17 8 32
10 15 16 2 0
10 15 15 2 0
10 15 14 2 0
10 15 13 2 0
10 15 12 2 0
10 15 11 2 0
10 15 10 12 0
10 15 9 12 0
10 15 8 12 0
10 15 7 12 0
10 15 6 12 0
10 15 5 12 0
10 15 4 12 0
10 15 3 12 0
10 15 2 12 0
10 15 1 12 0
10 15 0 10 80
10 16 59 1 108
10 16 17 6 44
10 16 16 6 8
10 16 15 6 0
10 16 14 6 0
10 16 13 6 0
10 16 12 6 0
10 16 11 6 0
10 16 10 6 0
10 16 9 6 0
10 16 8 6 0
10 16 7 6 0
10 16 6 6 0
10 16 5 6 0
10 16 4 6 0
10 16 3 6 0
10 16 2 6 0
10 16 1 6 0
10 16 0 1 64
10 17 15 6 32
10 17 14 7 8
10 17 13 7 8
10 17 12 7 8
10 17 11 7 8
10 17 10 7 8
10 17 9 7 8
10 17 8 7 8
10 17 7 7 8
10 17 6 7 8
10 17 5 7 8
10 17 4 7 8
10 17 3 7 8
10 17 2 6 0
10 17 1 6 0
10 17 0 1 72
10 18 15 6 108
10 18 2 6 40
10 18 1 6 72
11 2 47 5 52
11 2 46 5 20
11 2 45 5 20
11 2 44 5 20
11 2 43 5 20
11 2 42 5 20
11 2 41 5 20
11 2 40 5 20
11 2 39 5 20
11 2 38 5 20
11 2 37 5 20
11 2 36 5 20
11 2 35 5 20
11 2 34 5 20
11 2 33 5 20
11 2 32 5 20
11 2 31 5 20
11 2 30 5 20
11 2 29 5 20
11 2 28 5 20
11 2 27 5 20
11 2 26 5 20
11 2 25 5 20
11 2 24 5 20
11 2 23 5 20
11 2 22 5 20
11 2 21 5 20
11 2 20 5 20
11 2 19 5 20
11 2 18 5 20
11 2 17 5 20
11 2 16 5 20
11 2 15 5 20
11 2 14 5 20
11 2 13 5 84
11 3 49 5 52
11 3 48 5 20
11 3 47 2 0
11 3 46 2 0
11 3 45 2 0
11 3 44 2 0
11 3 43 2 0
11 3 42 7 0
11 3 41 7 0
11 3 40 7 0
11 3 39 7 0
11 3 38 7 0
11 3 37 7 0
11 3 36 7 0
11 3 35 7 0
11 3 34 7 0
11 3 33 7 0
11 3 32 7 0
11 3 31 7 0
11 3 30 7 0
11 3 29 7 0
11 3 28 7 0
11 3 27 7 0
11 3 26 7 0
11 3 25 7 0
11 3 24 7 0
11 3 23 7 0
11 3 22 7 0
11 3 21 7 0
11 3 20 2 0
11 3 19 2 0
11 3 18 2 0
11 3 17 2 0
11 3 16 2 0
11 3 15 2 0
11 3 14 2 0
11 3 13 2 0
11 3 12 5 16
11 3 11 5 84
11 4 51 5 52
11 4 50 5 16
11 4 49 2 0
11 4 48 2 0
11 4 47 2 0
11 4 46 2 0
11 4 45 2 0
11 4 44 2 0
11 4 43 2 0
11 4 42 7 0
11 4 41 7 0
11 4 40 7 0
11 4 39 7 0
11 4 38 7 0
11 4 37 7 0
11 4 36 7 0
11 4 35 7 0
11 4 34 7 0
11 4 33 7 0
11 4 32 7 0
11 4 31 7 0
11 4 30 7 0
11 4 29 7 0
11 4 28 7 0
11 4 27 7 0
11 4 26 7 0
11 4 25 7 0
11 4 24 7 0
11 4 23 7 0
11 4 22 7 0
11 4 21 7 0
11 4 20 2 0
11 4 19 2 0
11 4 18 2 0
11 4 17 2 0
11 4 16 2 0
11 4 15 2 0
11 4 14 2 0
11 4 13 2 0
11 4 12 2 0
11 4 11 2 0
11 4 10 5 20
11 4 9 5 84
11 5 54 5 52
11 5 53 5 16
11 5 52 5 16
11 5 51 2 0
11 5 50 2 0
11 5 49 2 0
11 5 48 2 0
11 5 47 2 0
11 5 46 2 0
11 5 45 2 0
11 5 44 2 0
11 5 43 2 0
11 5 42 7 0
11 5 41 7 0
11 5 40 7 0
11 5 39 7 0
11 5 38 7 0
11 5 37 7 0
11 5 36 7 0
11 5 35 7 0
11 5 34 7 0
11 5 33 7 0
11 5 32 7 0
11 5 31 7 0
11 5 30 7 0
11 5 29 7 0
11 5 28 7 0
11 5 27 7 0
11 5 26 7 0
11 5 25 7 0
11 5 24 7 0
11 5 23 7 0
11 5 22 7 0
11 5 21 7 0
11 5 20 2 0
11 5 19 2 0
11 5 18 2 0
11 5 17 2 0
11 5 16 2 0
11 5 15 2 0
11 5 14 2 0
11 5 13 2 0
11 5 12 2 0
11 5 11 2 0
11 5 10 2 0
11 5 9 5 4
11 5 8 5 84
11 6 56 5 52
11 6 55 5 16
11 6 54 5 0
11 6 53 2 0
11 6 52 2 0
11 6 51 2 0
11 6 50 2 0
11 6 49 2 0
11 6 48 2 0
11 6 47 2 0
11 6 46 2 0
11 6 45 2 0
11 6 44 2 0
11 6 43 7 0
11 6 42 7 0
11 6 41 7 0
11 6 40 7 0
11 6 39 7 0
11 6 38 7 0
11 6 37 7 0
11 6 36 7 0
11 6 35 7 0
11 6 34 7 0
11 6 33 7 0
11 6 32 7 0
11 6 31 7 0
11 6 30 7 0
11 6 29 7 0
11 6 28 7 0
11 6 27 7 0
11 6 26 7 0
11 6 25 0 8
11 6 24 0 8
11 6 23 7 0
11 6 22 7 0
11 6 21 7 0
11 6 20 2 0
11 6 19 2 0
11 6 18 2 0
11 6 17 2 0
11 6 16 2 0
11 6 15 2 0
11 6 14 2 0
11 6 13 2 0
11 6 12 2 0
11 6 11 2 0
11 6 10 2 0
11 6 9 2 0
11 6 8 1 0
11 6 7 1 84
11 7 58 1 52
11 7 57 2 16
11 7 56 2 0
11 7 55 2 0
11 7 54 2 0
11 7 53 2 0
11 7 52 2 0
11 7 51 2 0
11 7 50 2 0
11 7 49 2 0
11 7 48 2 0
11 7 47 2 0
11 7 46 2 0
11 7 45 2 0
11 7 44 2 0
11 7 43 7 0
11 7 42 7 0
11 7 41 7 0
11 7 40 7 0
11 7 39 7 0
11 7 38 7 0
11 7 37 7 0
11 7 36 7 0
11 7 35 7 0
11 7 34 7 0
11 7 33 7 0
11 7 32 7 0
11 7 31 7 0
11 7 30 7 0
11 7 29 7 0
11 7 28 7 0
11 7 27 7 0
11 7 26 0 64
11 7 23 0 32
11 7 22 7 0
11 7 21 7 0
11 7 20 2 0
11 7 19 2 0
11 7 18 2 0
11 7 17 2 0
11 7 16 2 0
11 7 15 2 0
11 7 14 2 0
11 7 13 2 0
11 7 12 2 0
11 7 11 2 0
11 7 10 2 0
11 7 9 2 0
11 7 8 2 0
11 7 7 2 0
11 7 6 1 16
11 7 5 1 84
11 8 58 1 36
11 8 57 1 0
11 8 56 1 0
11 8 55 2 0
11 8 54 2 0
11 8 53 2 0
11 8 52 2 0
11 8 51 2 0
11 8 50 2 0
11 8 49 2 0
11 8 48 2 0
11 8 47 2 0
11 8 46 2 0
11 8 45 2 0
11 8 44 11 0
11 8 43 7 0
11 8 42 7 0
11 8 41 7 0
11 8 40 7 0
11 8 39 7 0
11 8 38 7 0
11 8 37 7 0
11 8 36 7 0
11 8 35 7 0
11 8 34 7 0
11 8 33 7 0
11 8 32 7 0
11 8 31 7 0
11 8 30 7 0
11 8 29 7 0
11 8 28 7 0
11 8 27 7 0
11 8 26 0 64
11 8 23 0 32
11 8 22 7 0
11 8 21 7 0
11 8 20 2 0
11 8 19 2 0
11 8 18 2 0
11 8 17 2 0
11 8 16 2 0
11 8 15 2 0
11 8 14 2 0
11 8 13 2 0
11 8 12 2 0
11 8 11 2 0
11 8 10 2 0
11 8 9 2 0
11 8 8 2 0
11 8 7 2 0
11 8 6 2 0
11 8 5 2 0
11 8 4 10 80
11 9 60 1 52
11 9 59 1 20
11 9 58 2 0
11 9 57 2 0
11 9 56 2 0
11 9 55 2 0
11 9 54 2 0
11 9 53 2 0
11 9 52 2 0
11 9 51 2 0
11 9 50 2 0
11 9 49 2 0
11 9 48 2 0
11 9 47 2 0
11 9 46 2 0
11 9 45 2 0
11 9 44 11 0
11 9 43 7 0
11 9 42 7 0
11 9 41 7 0
11 9 40 7 0
11 9 39 7 0
11 9 38 7 0
11 9 37 7 0
11 9 36 7 0
11 9 35 7 0
11 9 34 7 0
11 9 33 7 0
11 9 32 7 0
11 9 31 7 0
11 9 30 7 0
11 9 29 7 0
11 9 28 7 0
11 9 27 7 0
11 9 26 7 0
11 9 25 0 16
11 9 24 0 16
11 9 23 7 0
11 9 22 7 0
11 9 21 7 0
11 9 20 2 0
11 9 19 2 0
11 9 18 2 0
11 9 17 2 0
11 9 16 2 0
11 9 15 2 0
11 9 14 2 0
11 9 13 2 0
11 9 12 2 0
11 9 11 2 0
11 9 10 2 0
11 9 9 2 0
11 9 8 2 0
11 9 7 2 0
11 9 6 2 0
11 9 5 2 0
11 9 4 10 0
11 9 3 10 16
11 9 2 10 80
11 10 62 1 60
11 10 61 1 28
11 10 60 10 8
11 10 59 2 0
11 10 58 2 0
11 10 57 2 0
11 10 56 2 0
11 10 55 2 0
11 10 54 2 0
11 10 53 2 0
11 10 52 2 0
11 10 51 2 0
11 10 50 2 0
11 10 49 2 0
11 10 48 2 0
11 10 47 2 0
11 10 46 2 0
11 10 45 2 0
11 10 44 11 0
11 10 43 7 0
11 10 42 7 0
11 10 41 7 0
11 10 40 7 0
11 10 39 7 0
11 10 38 7 0
11 10 37 7 0
11 10 36 7 0
11 10 35 7 0
11 10 34 7 0
11 10 33 7 0
11 10 32 7 0
11 10 31 7 0
11 10 30 7 0
11 10 29 7 0
11 10 28 7 0
11 10 27 7 0
11 10 26 7 0
11 10 25 7 0
11 10 24 7 0
11 10 23 7 0
11 10 22 7 0
11 10 21 7 0
11 10 20 2 0
11 10 19 2 0
11 10 18 2 0
11 10 17 2 0
11 10 16 2 0
11 10 15 2 0
11 10 14 2 0
11 10 13 2 0
11 10 12 2 0
11 10 11 2 0
11 10 10 2 0
11 10 9 2 0
11 10 8 2 0
11 10 7 2 0
11 10 6 2 0
11 10 5 2 0
11 10 4 2 0
11 10 3 2 0
11 10 2 2 0
11 10 1 1 80
11 11 64 1 62
11 11 63 1 94
11 11 59 10 32
11 11 58 2 0
11 11 57 2 0
11 11 56 2 0
11 11 55 2 0
11 11 54 2 0
11 11 53 2 0
11 11 52 2 0
11 11 51 2 0
11 11 50 2 0
11 11 49 2 0
11 11 48 2 0
11 11 47 7 8
11 11 46 7 8
11 11 45 7 8
11 11 44 9 8
11 11 43 9 8
11 11 42 9 8
11 11 41 9 8
11 11 40 9 8
11 11 39 9 8
11 11 38 9 8
11 11 37 9 8
11 11 36 9 8
11 11 35 9 8
11 11 34 9 8
11 11 33 9 8
11 11 32 7 8
11 11 31 7 8
11 11 30 7 8
11 11 29 9 8
11 11 28 9 8
11 11 27 9 8
11 11 26 9 8
11 11 25 9 8
11 11 24 9 8
11 11 23 9 8
11 11 22 9 8
11 11 21 7 8
11 11 20 2 0
11 11 19 2 0
11 11 18 2 0
11 11 17 2 0
11 11 16 2 0
11 11 15 2 0
11 11 14 2 0
11 11 13 2 0
11 11 12 2 0
11 11 11 2 0
11 11 10 2 0
11 11 9 2 0
11 11 8 2 0
11 11 7 2 0
11 11 6 2 0
11 11 5 2 0
11 11 4 2 0
11 11 3 2 0
11 11 2 2 0
11 11 1 16 64
11 12 59 10 32
11 12 58 2 0
11 12 57 2 0
11 12 56 2 0
11 12 55 2 0
11 12 54 2 0
11 12 53 2 0
11 12 52 2 0
11 12 51 2 0
11 12 50 2 0
11 12 49 2 0
11 12 48 2 64
11 12 20 7 40
11 12 19 2 8
11 12 18 7 8
11 12 17 2 0
11 12 16 2 0
11 12 15 2 0
11 12 14 2 0
11 12 13 2 0
11 12 12 2 0
11 12 11 2 0
11 12 10 2 0
11 12 9 2 0
11 12 8 2 0
11 12 7 2 0
11 12 6 2 0
11 12 5 2 0
11 12 4 2 0
11 12 3 2 0
11 12 2 2 0
11 12 1 16 64
11 13 59 10 32
11 13 58 8 0
11 13 57 8 0
11 13 56 8 8
11 13 55 8 8
11 13 54 9 8
11 13 53 8 8
11 13 52 8 8
11 13 51 9 8
11 13 50 8 8
11 13 49 8 8
11 13 48 2 64
11 13 17 2 32
11 13 16 2 0
11 13 15 2 0
11 13 14 2 0
11 13 13 2 0
11 13 12 2 0
11 13 11 2 0
11 13 10 12 0
11 13 9 12 0
11 13 8 12 0
11 13 7 12 0
11 13 6 12 0
11 13 5 12 0
11 13 4 12 0
11 13 3 12 0
11 13 2 12 0
11 13 1 16 64
11 14 59 10 32
11 14 58 10 14
11 14 57 10 78
11 14 48 15 102
11 14 17 2 32
11 14 16 2 0
11 14 15 2 0
11 14 14 2 0
11 14 13 2 0
11 14 12 2 0
11 14 11 2 0
11 14 10 12 0
11 14 9 12 0
11 14 8 12 0
11 14 7 12 0
11 14 6 12 0
11 14 5 12 0
11 14 4 12 0
11 14 3 12 0
11 14 2 12 0
11 14 1 16 64
11 15 59 10 98
11 15 48 6 108
11 15 17 2 32
11 15 16 2 0
11 15 15 2 0
11 15 14 2 0
11 15 13 2 0
11 15 12 2 0
11 15 11 2 0
11 15 10 12 0
11 15 9 12 0
11 15 8 12 0
11 15 7 12 0
11 15 6 12 0
11 15 5 12 0
11 15 4 12 0
11 15 3 12 0
11 15 2 12 0
11 15 1 12 0
11 15 0 10 80
11 16 59 1 106
11 16 17 6 40
11 16 16 6 8
11 16 15 6 0
11 16 14 6 0
11 16 13 6 0
11 16 12 6 0
11 16 11 6 0
11 16 10 6 0
11 16 9 6 0
11 16 8 6 0
11 16 7 6 0
11 16 6 6 0
11 16 5 6 0
11 16 4 6 0
11 16 3 6 0
11 16 2 6 0
11 16 1 6 0
11 16 0 1 64
11 17 15 6 32
11 17 14 7 8
11 17 13 9 8
11 17 12 9 8
11 17 11 9 8
11 17 10 9 8
11 17 9 9 8
11 17 8 9 8
11 17 7 9 8
11 17 6 9 8
11 17 5 9 8
11 17 4 7 8
11 17 3 7 8
11 17 2 6 0
11 17 1 6 0
11 17 0 1 72
11 18 15 6 104
11 18 2 6 40
11 18 1 6 72
12 2 47 5 48
12 2 46 5 16
12 2 45 5 16
12 2 44 5 16
12 2 43 5 16
12 2 42 5 16
12 2 41 5 16
12 2 40 5 16
12 2 39 5 16
12 2 38 5 16
12 2 37 5 16
12 2 36 5 16
12 2 35 5 16
12 2 34 5 16
12 2 33 5 16
12 2 32 5 16
12 2 31 5 16
12 2 30 5 16
12 2 29 5 16
12 2 28 5 16
12 2 27 5 16
12 2 26 5 16
12 2 25 5 16
12 2 24 5 16
12 2 23 5 16
12 2 22 5 16
12 2 21 5 16
12 2 20 5 16
12 2 19 5 16
12 2 18 5 16
12 2 17 5 16
12 2 16 5 16
12 2 15 5 16
12 2 14 5 16
12 2 13 5 16
12 2 12 5 84
12 3 50 5 52
12 3 49 5 16
12 3 48 5 16
12 3 47 2 0
12 3 46 2 0
12 3 45 2 0
12 3 44 2 0
12 3 43 2 0
12 3 42 7 0
12 3 41 7 0
12 3 40 7 0
12 3 39 7 0
12 3 38 7 0
12 3 37 7 0
12 3 36 7 0
12 3 35 7 0
12 3 34 7 0
12 3 33 7 0
12 3 32 7 0
12 3 31 7 0
12 3 30 7 0
12 3 29 7 0
12 3 28 7 0
12 3 27 7 0
12 3 26 7 0
12 3 25 7 0
12 3 24 7 0
12 3 23 7 0
12 3 22 7 0
12 3 21 7 0
12 3 20 2 0
12 3 19 2 0
12 3 18 2 0
12 3 17 2 0
12 3 16 2 0
12 3 15 2 0
12 3 14 2 0
12 3 13 2 0
12 3 12 2 0
12 3 11 5 16
12 3 10 5 84
12 4 52 5 52
12 4 51 5 16
12 4 50 2 0
12 4 49 2 0
12 4 48 2 0
12 4 47 2 0
12 4 46 2 0
12 4 45 2 0
12 4 44 2 0
12 4 43 2 0
12 4 42 7 0
12 4 41 7 0
12 4 40 7 0
12 4 39 7 0
12 4 38 7 0
12 4 37 7 0
12 4 36 7 0
12 4 35 7 0
12 4 34 7 0
12 4 33 7 0
12 4 32 7 0
12 4 31 7 0
12 4 30 7 0
12 4 29 7 0
12 4 28 7 0
12 4 27 7 0
12 4 26 7 0
12 4 25 7 0
12 4 24 7 0
12 4 23 7 0
12 4 22 7 0
12 4 21 7 0
12 4 20 2 0
12 4 19 2 0
12 4 18 2 0
12 4 17 2 0
12 4 16 2 0
12 4 15 2 0
12 4 14 2 0
12 4 13 2 0
12 4 12 2 0
12 4 11 2 0
12 4 10 2 0
12 4 9 5 16
12 4 8 5 84
12 5 55 5 52
12 5 54 5 16
12 5 53 5 16
12 5 52 2 0
12 5 51 2 0
12 5 50 2 0
12 5 49 2 0
12 5 48 2 0
12 5 47 2 0
12 5 46 2 0
12 5 45 2 0
12 5 44 2 0
12 5 43 7 0
12 5 42 7 0
12 5 41 7 0
12 5 40 7 0
12 5 39 7 0
12 5 38 7 0
12 5 37 7 0
12 5 36 7 0
12 5 35 7 0
12 5 34 7 0
12 5 33 7 0
12 5 32 7 0
12 5 31 7 0
12 5 30 7 0
12 5 29 7 0
12 5 28 7 0
12 5 27 7 0
12 5 26 7 0
12 5 25 7 0
12 5 24 7 0
12 5 23 7 0
12 5 22 7 0
12 5 21 7 0
12 5 20 2 0
12 5 19 2 0
12 5 18 2 0
12 5 17 2 0
12 5 16 2 0
12 5 15 2 0
12 5 14 2 0
12 5 13 2 0
12 5 12 2 0
12 5 11 2 0
12 5 10 2 0
12 5 9 2 0
12 5 8 2 0
12 5 7 5 84
12 6 57 5 52
12 6 56 5 16
12 6 55 2 0
12 6 54 2 0
12 6 53 2 0
12 6 52 2 0
12 6 51 2 0
12 6 50 2 0
12 6 49 2 0
12 6 48 2 0
12 6 47 2 0
12 6 46 2 0
12 6 45 2 0
12 6 44 2 0
12 6 43 7 0
12 6 42 7 0
12 6 41 7 0
12 6 40 7 0
12 6 39 7 0
12 6 38 7 0
12 6 37 7 0
12 6 36 7 0
12 6 35 7 0
12 6 34 7 0
12 6 33 7 0
12 6 32 7 0
12 6 31 7 0
12 6 30 7 0
12 6 29 7 0
12 6 28 7 0
12 6 27 7 0
12 6 26 7 0
12 6 25 7 0
12 6 24 7 0
12 6 23 7 0
12 6 22 7 0
12 6 21 7 0
12 6 20 2 0
12 6 19 2 0
12 6 18 2 0
12 6 17 2 0
12 6 16 2 0
12 6 15 2 0
12 6 14 2 0
12 6 13 2 0
12 6 12 2 0
12 6 11 2 0
12 6 10 2 0
12 6 9 2 0
12 6 8 2 0
12 6 7 2 0
12 6 6 1 84
12 7 59 1 52
12 7 58 2 16
12 7 57 2 0
12 7 56 2 0
12 7 55 2 0
12 7 54 2 0
12 7 53 2 0
12 7 52 2 0
12 7 51 2 0
12 7 50 2 0
12 7 49 2 0
12 7 48 2 0
12 7 47 2 0
12 7 46 2 0
12 7 45 2 0
12 7 44 2 0
12 7 43 7 0
12 7 42 7 0
12 7 41 7 0
12 7 40 7 0
12 7 39 7 0
12 7 38 7 0
12 7 37 7 0
12 7 36 7 0
12 7 35 7 0
12 7 34 7 0
12 7 33 7 0
12 7 32 7 0
12 7 31 7 0
12 7 30 7 0
12 7 29 7 0
12 7 28 7 0
12 7 27 7 0
12 7 26 7 0
12 7 25 0 4
12 7 24 0 4
12 7 23 7 0
12 7 22 7 0
12 7 21 7 0
12 7 20 2 0
12 7 19 2 0
12 7 18 2 0
12 7 17 2 0
12 7 16 2 0
12 7 15 2 0
12 7 14 2 0
12 7 13 2 0
12 7 12 2 0
12 7 11 2 0
12 7 10 2 0
12 7 9 2 0
12 7 8 2 0
12 7 7 2 0
12 7 6 1 0
12 7 5 1 80
12 8 60 1 52
12 8 59 1 4
12 8 58 1 0
12 8 57 2 0
12 8 56 2 0
12 8 55 2 0
12 8 54 2 0
12 8 53 2 0
12 8 52 2 0
12 8 51 2 0
12 8 50 2 0
12 8 49 2 0
12 8 48 2 0
12 8 47 2 0
12 8 46 2 0
12 8 45 2 0
12 8 44 11 0
12 8 43 7 0
12 8 42 7 0
12 8 41 7 0
12 8 40 7 0
12 8 39 7 0
12 8 38 7 0
12 8 37 7 0
12 8 36 7 0
12 8 35 7 0
12 8 34 7 0
12 8 33 7 0
12 8 32 7 0
12 8 31 7 0
12 8 30 7 0
12 8 29 7 0
12 8 28 7 0
12 8 27 7 0
12 8 26 7 0
12 8 25 0 4
12 8 24 0 4
12 8 23 7 0
12 8 22 7 0
12 8 21 7 0
12 8 20 2 0
12 8 19 2 0
12 8 18 2 0
12 8 17 2 0
12 8 16 2 0
12 8 15 2 0
12 8 14 2 0
12 8 13 2 0
12 8 12 2 0
12 8 11 2 0
12 8 10 2 0
12 8 9 2 0
12 8 8 2 0
12 8 7 2 0
12 8 6 2 0
12 8 5 2 0
12 8 4 10 80
12 9 63 1 52
12 9 62 1 20
12 9 61 1 20
12 9 60 2 0
12 9 59 2 0
12 9 58 2 0
12 9 57 2 0
12 9 56 2 0
12 9 55 2 0
12 9 54 2 0
12 9 53 2 0
12 9 52 2 0
12 9 51 2 0
12 9 50 2 0
12 9 49 2 0
12 9 48 2 0
12 9 47 2 0
12 9 46 2 0
12 9 45 2 0
12 9 44 11 0
12 9 43 7 0
12 9 42 7 0
12 9 41 7 0
12 9 40 7 0
12 9 39 7 0
12 9 38 7 0
12 9 37 7 0
12 9 36 7 0
12 9 35 7 0
12 9 34 7 0
12 9 33 7 0
12 9 32 7 0
12 9 31 7 0
12 9 30 7 0
12 9 29 7 0
12 9 28 7 0
12 9 27 7 0
12 9 26 7 0
12 9 25 7 0
12 9 24 7 0
12 9 23 7 0
12 9 22 7 0
12 9 21 7 0
12 9 20 2 0
12 9 19 2 0
12 9 18 2 0
12 9 17 2 0
12 9 16 2 0
12 9 15 2 0
12 9 14 2 0
12 9 13 2 0
12 9 12 2 0
12 9 11 2 0
12 9 10 2 0
12 9 9 2 0
12 9 8 2 0
12 9 7 2 0
12 9 6 2 0
12 9 5 2 0
12 9 4 2 0
12 9 3 10 16
12 9 2 10 80
12 10 64 1 60
12 10 63 1 12
12 10 62 10 8
12 10 61 10 8
12 10 60 2 0
12 10 59 2 0
12 10 58 2 0
12 10 57 2 0
12 10 56 2 0
12 10 55 2 0
12 10 54 2 0
12 10 53 2 0
12 10 52 2 0
12 10 51 2 0
12 10 50 2 0
12 10 49 2 0
12 10 48 2 0
12 10 47 2 0
12 10 46 2 0
12 10 45 2 0
12 10 44 11 0
12 10 43 7 0
12 10 42 7 0
12 10 41 7 0
12 10 40 7 0
12 10 39 7 0
12 10 38 7 0
12 10 37 7 0
12 10 36 7 0
12 10 35 7 0
12 10 34 7 0
12 10 33 7 0
12 10 32 7 0
12 10 31 7 0
12 10 30 7 0
12 10 29 7 0
12 10 28 7 0
12 10 27 7 0
12 10 26 7 0
12 10 25 7 0
12 10 24 7 0
12 10 23 7 0
12 10 22 7 0
12 10 21 7 0
12 10 20 2 0
12 10 19 2 0
12 10 18 2 0
12 10 17 2 0
12 10 16 2 0
12 10 15 2 0
12 10 14 2 0
12 10 13 2 0
12 10 12 2 0
12 10 11 2 0
12 10 10 2 0
12 10 9 2 0
12 10 8 2 0
12 10 7 2 0
12 10 6 2 0
12 10 5 2 0
12 10 4 2 0
12 10 3 2 0
12 10 2 2 0
12 10 1 1 80
12 11 65 1 126
12 11 60 10 36
12 11 59 2 0
12 11 58 2 0
12 11 57 2 0
12 11 56 2 0
12 11 55 2 0
12 11 54 2 0
12 11 53 2 0
12 11 52 2 0
12 11 51 2 0
12 11 50 2 0
12 11 49 2 0
12 11 48 2 0
12 11 47 7 8
12 11 46 7 8
12 11 45 7 8
12 11 44 7 8
12 11 43 7 8
12 11 42 7 8
12 11 41 7 8
12 11 40 7 8
12 11 39 7 8
12 11 38 7 8
12 11 37 7 8
12 11 36 7 8
12 11 35 7 8
12 11 34 7 8
12 11 33 7 8
12 11 32 7 8
12 11 31 7 8
12 11 30 7 8
12 11 29 7 8
12 11 28 7 8
12 11 27 7 8
12 11 26 7 8
12 11 25 7 8
12 11 24 7 8
12 11 23 7 8
12 11 22 7 8
12 11 21 7 8
12 11 20 2 0
12 11 19 2 0
12 11 18 2 0
12 11 17 2 0
12 11 16 2 0
12 11 15 2 0
12 11 14 2 0
12 11 13 2 0
12 11 12 2 0
12 11 11 2 0
12 11 10 2 0
12 11 9 2 0
12 11 8 2 0
12 11 7 2 0
12 11 6 2 0
12 11 5 2 0
12 11 4 2 0
12 11 3 2 0
12 11 2 2 0
12 11 1 16 64
12 12 60 10 36
12 12 59 2 0
12 12 58 2 0
12 12 57 2 0
12 12 56 2 0
12 12 55 2 0
12 12 54 2 0
12 12 53 2 0
12 12 52 2 0
12 12 51 2 0
12 12 50 2 0
12 12 49 2 0
12 12 48 8 64
12 12 20 2 40
12 12 19 7 8
12 12 18 2 8
12 12 17 2 0
12 12 16 2 0
12 12 15 2 0
12 12 14 2 0
12 12 13 2 0
12 12 12 2 0
12 12 11 2 0
12 12 10 2 0
12 12 9 2 0
12 12 8 2 0
12 12 7 2 0
12 12 6 2 0
12 12 5 2 0
12 12 4 2 0
12 12 3 2 0
12 12 2 2 0
12 12 1 16 64
12 13 60 10 36
12 13 59 8 0
12 13 58 8 8
12 13 57 8 8
12 13 56 8 8
12 13 55 8 8
12 13 54 9 8
12 13 53 8 8
12 13 52 8 8
12 13 51 9 8
12 13 50 8 8
12 13 49 8 8
12 13 48 8 72
12 13 17 2 32
12 13 16 2 0
12 13 15 2 0
12 13 14 2 0
12 13 13 2 0
12 13 12 2 0
12 13 11 2 0
12 13 10 12 0
12 13 9 12 0
12 13 8 12 0
12 13 7 12 0
12 13 6 12 0
12 13 5 12 0
12 13 4 12 0
12 13 3 12 0
12 13 2 12 0
12 13 1 16 64
12 14 60 10 36
12 14 59 10 74
12 14 17 2 32
12 14 16 2 0
12 14 15 2 0
12 14 14 2 0
12 14 13 2 0
12 14 12 2 0
12 14 11 2 0
12 14 10 12 0
12 14 9 12 0
12 14 8 12 0
12 14 7 12 0
12 14 6 12 0
12 14 5 12 0
12 14 4 12 0
12 14 3 12 0
12 14 2 12 0
12 14 1 16 64
12 15 60 10 100
12 15 48 6 120
12 15 17 2 32
12 15 16 2 0
12 15 15 2 0
12 15 14 2 0
12 15 13 2 0
12 15 12 2 0
12 15 11 2 0
12 15 10 12 0
12 15 9 12 0
12 15 8 12 0
12 15 7 12 0
12 15 6 12 0
12 15 5 12 0
12 15 4 12 0
12 15 3 12 0
12 15 2 12 0
12 15 1 12 0
12 15 0 10 80
12 16 60 1 108
12 16 17 6 40
12 16 16 6 8
12 16 15 6 0
12 16 14 6 0
12 16 13 6 0
12 16 12 6 0
12 16 11 6 0
12 16 10 6 0
12 16 9 6 0
12 16 8 6 0
12 16 7 6 0
12 16 6 6 0
12 16 5 6 0
12 16 4 6 0
12 16 3 6 0
12 16 2 6 0
12 16 1 6 0
12 16 0 1 64
12 17 15 6 32
12 17 14 7 8
12 17 13 7 8
12 17 12 7 8
12 17 11 7 8
12 17 10 7 8
12 17 9 7 8
12 17 8 7 8
12 17 7 7 8
12 17 6 7 8
12 17 5 7 8
12 17 4 7 8
12 17 3 7 8
12 17 2 6 0
12 17 1 6 0
12 17 0 1 72
12 18 15 6 104
12 18 2 6 40
12 18 1 6 72
13 1 43 5 52
13 1 42 5 20
13 1 41 5 20
13 1 40 5 20
13 1 39 5 20
13 1 38 5 20
13 1 37 5 20
13 1 36 5 20
13 1 35 5 20
13 1 34 5 20
13 1 33 5 20
13 1 32 5 20
13 1 31 5 20
13 1 30 5 20
13 1 29 5 20
13 1 28 5 20
13 1 27 5 20
13 1 26 5 20
13 1 25 5 20
13 1 24 5 20
13 1 23 5 20
13 1 22 5 20
13 1 21 5 20
13 1 20 5 20
13 1 19 5 20
13 1 18 5 20
13 1 17 5 20
13 1 16 5 20
13 1 15 5 20
13 1 14 5 84
13 2 47 5 48
13 2 46 5 16
13 2 45 5 16
13 2 44 5 16
13 2 43 5 0
13 2 42 5 0
13 2 41 5 0
13 2 40 5 0
13 2 39 5 0
13 2 38 5 0
13 2 37 5 0
13 2 36 5 0
13 2 35 5 0
13 2 34 5 0
13 2 33 5 0
13 2 32 5 0
13 2 31 5 0
13 2 30 5 0
13 2 29 5 0
13 2 28 5 0
13 2 27 5 0
13 2 26 5 0
13 2 25 5 0
13 2 24 5 0
13 2 23 5 0
13 2 22 5 0
13 2 21 5 0
13 2 20 5 0
13 2 19 5 0
13 2 18 5 0
13 2 17 5 0
13 2 16 5 0
13 2 15 5 0
13 2 14 5 0
13 2 13 5 16
13 2 12 5 16
13 2 11 5 84
13 3 51 5 52
13 3 50 5 16
13 3 49 5 16
13 3 48 5 16
13 3 47 2 0
13 3 46 2 0
13 3 45 2 0
13 3 44 2 0
13 3 43 2 0
13 3 42 7 0
13 3 41 7 0
13 3 40 7 0
13 3 39 7 0
13 3 38 7 0
13 3 37 7 0
13 3 36 7 0
13 3 35 7 0
13 3 34 7 0
13 3 33 7 0
13 3 32 7 0
13 3 31 7 0
13 3 30 7 0
13 3 29 7 0
13 3 28 7 0
13 3 27 7 0
13 3 26 7 0
13 3 25 7 0
13 3 24 7 0
13 3 23 7 0
13 3 22 7 0
13 3 21 7 0
13 3 20 2 0
13 3 19 2 0
13 3 18 2 0
13 3 17 2 0
13 3 16 2 0
13 3 15 2 0
13 3 14 2 0
13 3 13 2 0
13 3 12 2 0
13 3 11 2 0
13 3 10 5 16
13 3 9 5 84
13 4 53 5 52
13 4 52 5 16
13 4 51 2 0
13 4 50 2 0
13 4 49 2 0
13 4 48 2 0
13 4 47 2 0
13 4 46 2 0
13 4 45 2 0
13 4 44 2 0
13 4 43 7 0
13 4 42 7 0
13 4 41 7 0
13 4 40 7 0
13 4 39 7 0
13 4 38 7 0
13 4 37 7 0
13 4 36 7 0
13 4 35 7 0
13 4 34 7 0
13 4 33 7 0
13 4 32 7 0
13 4 31 7 0
13 4 30 7 0
13 4 29 7 0
13 4 28 7 0
13 4 27 7 0
13 4 26 7 0
13 4 25 7 0
13 4 24 7 0
13 4 23 7 0
13 4 22 7 0
13 4 21 7 0
13 4 20 2 0
13 4 19 2 0
13 4 18 2 0
13 4 17 2 0
13 4 16 2 0
13 4 15 2 0
13 4 14 2 0
13 4 13 2 0
13 4 12 2 0
13 4 11 2 0
13 4 10 2 0
13 4 9 2 0
13 4 8 5 16
13 4 7 5 84
13 5 56 5 52
13 5 55 5 16
13 5 54 5 16
13 5 53 2 0
13 5 52 2 0
13 5 51 2 0
13 5 50 2 0
13 5 49 2 0
13 5 48 2 0
13 5 47 2 0
13 5 46 2 0
13 5 45 2 0
13 5 44 2 0
13 5 43 7 0
13 5 42 7 0
13 5 41 7 0
13 5 40 7 0
13 5 39 7 0
13 5 38 7 0
13 5 37 7 0
13 5 36 7 0
13 5 35 7 0
13 5 34 7 0
13 5 33 7 0
13 5 32 7 0
13 5 31 7 0
13 5 30 7 0
13 5 29 7 0
13 5 28 7 0
13 5 27 7 0
13 5 26 7 0
13 5 25 7 0
13 5 24 7 0
13 5 23 7 0
13 5 22 7 0
13 5 21 7 0
13 5 20 2 0
13 5 19 2 0
13 5 18 2 0
13 5 17 2 0
13 5 16 2 0
13 5 15 2 0
13 5 14 2 0
13 5 13 2 0
13 5 12 2 0
13 5 11 2 0
13 5 10 2 0
13 5 9 2 0
13 5 8 2 0
13 5 7 5 64
13 6 58 5 52
13 6 57 5 16
13 6 56 2 0
13 6 55 2 0
13 6 54 2 0
13 6 53 2 0
13 6 52 2 0
13 6 51 2 0
13 6 50 2 0
13 6 49 2 0
13 6 48 2 0
13 6 47 2 0
13 6 46 2 0
13 6 45 2 0
13 6 44 2 0
13 6 43 7 0
13 6 42 7 0
13 6 41 7 0
13 6 40 7 0
13 6 39 7 0
13 6 38 7 0
13 6 37 7 0
13 6 36 7 0
13 6 35 7 0
13 6 34 7 0
13 6 33 7 0
13 6 32 7 0
13 6 31 7 0
13 6 30 7 0
13 6 29 7 0
13 6 28 7 0
13 6 27 7 0
13 6 26 7 0
13 6 25 7 0
13 6 24 7 0
13 6 23 7 0
13 6 22 7 0
13 6 21 7 0
13 6 20 2 0
13 6 19 2 0
13 6 18 2 0
13 6 17 2 0
13 6 16 2 0
13 6 15 2 0
13 6 14 2 0
13 6 13 2 0
13 6 12 2 0
13 6 11 2 0
13 6 10 2 0
13 6 9 2 0
13 6 8 2 0
13 6 7 2 0
13 6 6 1 80
13 7 60 1 52
13 7 59 2 16
13 7 58 2 0
13 7 57 2 0
13 7 56 2 0
13 7 55 2 0
13 7 54 2 0
13 7 53 2 0
13 7 52 2 0
13 7 51 2 0
13 7 50 2 0
13 7 49 2 0
13 7 48 2 0
13 7 47 2 0
13 7 46 2 0
13 7 45 2 0
13 7 44 2 0
13 7 43 7 0
13 7 42 7 0
13 7 41 7 0
13 7 40 7 0
13 7 39 7 0
13 7 38 7 0
13 7 37 7 0
13 7 36 7 0
13 7 35 7 0
13 7 34 7 0
13 7 33 7 0
13 7 32 7 0
13 7 31 7 0
13 7 30 7 0
13 7 29 7 0
13 7 28 7 0
13 7 27 7 0
13 7 26 7 0
13 7 25 7 0
13 7 24 7 0
13 7 23 7 0
13 7 22 7 0
13 7 21 7 0
13 7 20 2 0
13 7 19 2 0
13 7 18 2 0
13 7 17 2 0
13 7 16 2 0
13 7 15 2 0
13 7 14 2 0
13 7 13 2 0
13 7 12 2 0
13 7 11 2 0
13 7 10 2 0
13 7 9 2 0
13 7 8 2 0
13 7 7 2 0
13 7 6 2 0
13 7 5 1 80
13 8 62 1 52
13 8 61 1 20
13 8 60 2 0
13 8 59 2 0
13 8 58 2 0
13 8 57 2 0
13 8 56 2 0
13 8 55 2 0
13 8 54 2 0
13 8 53 2 0
13 8 52 2 0
13 8 51 2 0
13 8 50 2 0
13 8 49 2 0
13 8 48 2 0
13 8 47 2 0
13 8 46 2 0
13 8 45 2 0
13 8 44 11 0
13 8 43 7 0
13 8 42 7 0
13 8 41 7 0
13 8 40 7 0
13 8 39 7 0
13 8 38 7 0
13 8 37 7 0
13 8 36 7 0
13 8 35 7 0
13 8 34 7 0
13 8 33 7 0
13 8 32 7 0
13 8 31 7 0
13 8 30 7 0
13 8 29 7 0
13 8 28 7 0
13 8 27 7 0
13 8 26 7 0
13 8 25 7 0
13 8 24 7 0
13 8 23 7 0
13 8 22 7 0
13 8 21 7 0
13 8 20 2 0
13 8 19 2 0
13 8 18 2 0
13 8 17 2 0
13 8 16 2 0
13 8 15 2 0
13 8 14 2 0
13 8 13 2 0
13 8 12 2 0
13 8 11 2 0
13 8 10 2 0
13 8 9 2 0
13 8 8 2 0
13 8 7 2 0
13 8 6 2 0
13 8 5 2 0
13 8 4 10 80
13 9 64 1 52
13 9 63 1 16
13 9 62 2 0
13 9 61 2 0
13 9 60 2 0
13 9 59 2 0
13 9 58 2 0
13 9 57 2 0
13 9 56 2 0
13 9 55 2 0
13 9 54 2 0
13 9 53 2 0
13 9 52 2 0
13 9 51 2 0
13 9 50 2 0
13 9 49 2 0
13 9 48 2 0
13 9 47 2 0
13 9 46 2 0
13 9 45 2 0
13 9 44 11 0
13 9 43 7 0
13 9 42 7 0
13 9 41 7 0
13 9 40 7 0
13 9 39 7 0
13 9 38 7 0
13 9 37 7 0
13 9 36 7 0
13 9 35 7 0
13 9 34 7 0
13 9 33 7 0
13 9 32 7 0
13 9 31 7 0
13 9 30 7 0
13 9 29 7 0
13 9 28 7 0
13 9 27 7 0
13 9 26 7 0
13 9 25 7 0
13 9 24 7 0
13 9 23 7 0
13 9 22 7 0
13 9 21 7 0
13 9 20 2 0
13 9 19 2 0
13 9 18 2 0
13 9 17 2 0
13 9 16 2 0
13 9 15 2 0
13 9 14 2 0
13 9 13 2 0
13 9 12 2 0
13 9 11 2 0
13 9 10 2 0
13 9 9 2 0
13 9 8 2 0
13 9 7 2 0
13 9 6 2 0
13 9 5 2 0
13 9 4 2 0
13 9 3 10 16
13 9 2 10 80
13 10 66 1 52
13 10 65 1 28
13 10 64 10 8
13 10 63 10 8
13 10 62 10 8
13 10 61 10 8
13 10 60 2 0
13 10 59 2 0
13 10 58 2 0
13 10 57 2 0
13 10 56 2 0
13 10 55 2 0
13 10 54 2 0
13 10 53 2 0
13 10 52 2 0
13 10 51 2 0
13 10 50 2 0
13 10 49 2 0
13 10 48 2 0
13 10 47 2 0
13 10 46 2 0
13 10 45 2 0
13 10 44 11 0
13 10 43 7 0
13 10 42 7 0
13 10 41 7 0
13 10 40 7 0
13 10 39 7 0
13 10 38 7 0
13 10 37 7 0
13 10 36 7 0
13 10 35 7 0
13 10 34 7 0
13 10 33 7 0
13 10 32 7 0
13 10 31 7 0
13 10 30 7 0
13 10 29 7 0
13 10 28 7 0
13 10 27 7 0
13 10 26 7 0
13 10 25 7 0
13 10 24 7 0
13 10 23 7 0
13 10 22 7 0
13 10 21 14 0
13 10 20 2 0
13 10 19 2 0
13 10 18 2 0
13 10 17 2 0
13 10 16 2 0
13 10 15 2 0
13 10 14 2 0
13 10 13 2 0
13 10 12 2 0
13 10 11 2 0
13 10 10 2 0
13 10 9 2 0
13 10 8 2 0
13 10 7 2 0
13 10 6 2 0
13 10 5 2 0
13 10 4 2 0
13 10 3 2 0
13 10 2 2 0
13 10 1 1 82
13 11 66 1 100
13 11 60 10 32
13 11 59 2 0
13 11 58 2 0
13 11 57 2 0
13 11 56 2 0
13 11 55 2 0
13 11 54 2 0
13 11 53 2 0
13 11 52 2 0
13 11 51 2 0
13 11 50 2 0
13 11 49 2 0
13 11 48 2 0
13 11 47 9 8
13 11 46 9 8
13 11 45 9 8
13 11 44 9 8
13 11 43 9 8
13 11 42 9 8
13 11 41 9 8
13 11 40 9 8
13 11 39 9 8
13 11 38 9 8
13 11 37 7 8
13 11 36 7 8
13 11 35 7 8
13 11 34 7 8
13 11 33 7 8
13 11 32 9 8
13 11 31 9 8
13 11 30 9 8
13 11 29 9 8
13 11 28 9 8
13 11 27 9 8
13 11 26 9 8
13 11 25 7 8
13 11 24 7 8
13 11 23 7 8
13 11 22 7 8
13 11 21 7 8
13 11 20 2 0
13 11 19 2 0
13 11 18 2 0
13 11 17 2 0
13 11 16 2 0
13 11 15 2 0
13 11 14 2 0
13 11 13 2 0
13 11 12 2 0
13 11 11 2 0
13 11 10 2 0
13 11 9 2 0
13 11 8 2 0
13 11 7 2 0
13 11 6 2 0
13 11 5 2 0
13 11 4 2 0
13 11 3 2 0
13 11 2 2 0
13 11 1 1 66
13 12 66 1 108
13 12 60 13 32
13 12 59 2 0
13 12 58 2 0
13 12 57 2 0
13 12 56 2 0
13 12 55 2 0
13 12 54 2 0
13 12 53 2 0
13 12 52 2 0
13 12 51 2 0
13 12 50 2 0
13 12 49 2 0
13 12 48 2 64
13 12 20 7 40
13 12 19 2 8
13 12 18 7 8
13 12 17 2 0
13 12 16 2 0
13 12 15 2 0
13 12 14 2 0
13 12 13 2 0
13 12 12 2 0
13 12 11 2 0
13 12 10 2 0
13 12 9 2 0
13 12 8 2 0
13 12 7 2 0
13 12 6 2 0
13 12 5 2 0
13 12 4 2 0
13 12 3 2 0
13 12 2 2 0
13 12 1 1 66
13 13 60 13 32
13 13 59 8 8
13 13 58 8 8
13 13 57 8 8
13 13 56 8 8
13 13 55 8 8
13 13 54 9 8
13 13 53 8 8
13 13 52 8 8
13 13 51 9 8
13 13 50 8 8
13 13 49 8 8
13 13 48 2 64
13 13 17 8 32
13 13 16 2 0
13 13 15 2 0
13 13 14 2 0
13 13 13 2 0
13 13 12 2 0
13 13 11 2 0
13 13 10 12 0
13 13 9 12 0
13 13 8 12 0
13 13 7 12 0
13 13 6 12 0
13 13 5 12 0
13 13 4 12 0
13 13 3 12 0
13 13 2 12 0
13 13 1 1 66
13 14 60 10 96
13 14 48 15 102
13 14 17 8 32
13 14 16 2 0
13 14 15 2 0
13 14 14 2 0
13 14 13 2 0
13 14 12 2 0
13 14 11 2 0
13 14 10 12 0
13 14 9 12 0
13 14 8 12 0
13 14 7 12 0
13 14 6 12 0
13 14 5 12 0
13 14 4 12 0
13 14 3 12 0
13 14 2 12 0
13 14 1 1 66
13 15 60 10 96
13 15 48 6 104
13 15 17 8 32
13 15 16 2 0
13 15 15 2 0
13 15 14 2 0
13 15 13 2 0
13 15 12 2 0
13 15 11 2 0
13 15 10 12 0
13 15 9 12 0
13 15 8 12 0
13 15 7 12 0
13 15 6 12 0
13 15 5 12 0
13 15 4 12 0
13 15 3 12 0
13 15 2 12 0
13 15 1 12 0
13 15 0 10 80
13 16 60 1 104
13 16 17 6 40
13 16 16 6 8
13 16 15 6 0
13 16 14 6 0
13 16 13 6 0
13 16 12 6 0
13 16 11 6 0
13 16 10 6 0
13 16 9 6 0
13 16 8 6 0
13 16 7 6 0
13 16 6 6 0
13 16 5 6 0
13 16 4 6 0
13 16 3 6 0
13 16 2 6 0
13 16 1 6 0
13 16 0 1 64
13 17 15 6 32
13 17 14 7 8
13 17 13 9 8
13 17 12 9 8
13 17 11 9 8
13 17 10 9 8
13 17 9 9 8
13 17 8 9 8
13 17 7 9 8
13 17 6 9 8
13 17 5 9 8
13 17 4 7 8
13 17 3 7 8
13 17 2 6 0
13 17 1 6 0
13 17 0 1 72
13 18 15 6 104
13 18 2 6 40
13 18 1 6 72
14 1 43 5 48
14 1 42 5 16
14 1 41 5 16
14 1 40 5 16
14 1 39 5 16
14 1 38 5 16
14 1 37 5 16
14 1 36 5 16
14 1 35 5 16
14 1 34 5 16
14 1 33 5 16
14 1 32 5 16
14 1 31 5 16
14 1 30 5 16
14 1 29 5 16
14 1 28 5 16
14 1 27 5 16
14 1 26 5 16
14 1 25 5 16
14 1 24 5 16
14 1 23 5 16
14 1 22 5 16
14 1 21 5 16
14 1 20 5 16
14 1 19 5 16
14 1 18 5 16
14 1 17 5 16
14 1 16 5 16
14 1 15 5 16
14 1 14 5 16
14 1 13 5 22
14 1 12 5 86
14 2 47 5 48
14 2 46 5 16
14 2 45 5 16
14 2 44 5 16
14 2 43 5 0
14 2 42 5 0
14 2 41 5 0
14 2 40 5 0
14 2 39 5 0
14 2 38 5 0
14 2 37 5 0
14 2 36 5 0
14 2 35 5 0
14 2 34 5 0
14 2 33 5 0
14 2 32 5 0
14 2 31 5 0
14 2 30 5 0
14 2 29 5 0
14 2 28 5 0
14 2 27 5 0
14 2 26 5 0
14 2 25 5 0
14 2 24 5 0
14 2 23 5 0
14 2 22 5 0
14 2 21 5 0
14 2 20 5 0
14 2 19 5 0
14 2 18 5 0
14 2 17 5 0
14 2 16 5 0
14 2 15 5 0
14 2 14 5 0
14 2 13 5 0
14 2 12 5 0
14 2 11 5 16
14 2 10 5 86
14 3 51 5 48
14 3 50 5 16
14 3 49 5 16
14 3 48 5 16
14 3 47 2 0
14 3 46 2 0
14 3 45 2 0
14 3 44 2 0
14 3 43 2 0
14 3 42 7 0
14 3 41 7 0
14 3 40 7 0
14 3 39 7 0
14 3 38 7 0
14 3 37 7 0
14 3 36 7 0
14 3 35 7 0
14 3 34 7 0
14 3 33 7 0
14 3 32 7 0
14 3 31 7 0
14 3 30 7 0
14 3 29 7 0
14 3 28 7 0
14 3 27 7 0
14 3 26 7 0
14 3 25 7 0
14 3 24 7 0
14 3 23 7 0
14 3 22 7 0
14 3 21 7 0
14 3 20 2 0
14 3 19 2 0
14 3 18 2 0
14 3 17 2 0
14 3 16 2 0
14 3 15 2 0
14 3 14 2 0
14 3 13 2 0
14 3 12 2 0
14 3 11 2 0
14 3 10 2 0
14 3 9 5 16
14 3 8 5 86
14 4 53 5 48
14 4 52 5 16
14 4 51 2 0
14 4 50 2 0
14 4 49 2 0
14 4 48 2 0
14 4 47 2 0
14 4 46 2 0
14 4 45 2 0
14 4 44 2 0
14 4 43 7 0
14 4 42 7 0
14 4 41 7 0
14 4 40 7 0
14 4 39 7 0
14 4 38 7 0
14 4 37 7 0
14 4 36 7 0
14 4 35 7 0
14 4 34 7 0
14 4 33 7 0
14 4 32 7 0
14 4 31 7 0
14 4 30 7 0
14 4 29 7 0
14 4 28 7 0
14 4 27 7 0
14 4 26 7 0
14 4 25 7 0
14 4 24 7 0
14 4 23 7 0
14 4 22 7 0
14 4 21 7 0
14 4 20 2 0
14 4 19 2 0
14 4 18 2 0
14 4 17 2 0
14 4 16 2 0
14 4 15 2 0
14 4 14 2 0
14 4 13 2 0
14 4 12 2 0
14 4 11 2 0
14 4 10 2 0
14 4 9 2 0
14 4 8 2 0
14 4 7 5 80
14 5 56 5 48
14 5 55 5 16
14 5 54 5 16
14 5 53 2 0
14 5 52 2 0
14 5 51 2 0
14 5 50 2 0
14 5 49 2 0
14 5 48 2 0
14 5 47 2 0
14 5 46 2 0
14 5 45 2 0
14 5 44 2 0
14 5 43 7 0
14 5 42 7 0
14 5 41 7 0
14 5 40 7 0
14 5 39 7 0
14 5 38 7 0
14 5 37 7 0
14 5 36 7 0
14 5 35 7 0
14 5 34 7 0
14 5 33 7 0
14 5 32 7 0
14 5 31 7 0
14 5 30 7 0
14 5 29 7 0
14 5 28 7 0
14 5 27 7 0
14 5 26 7 0
14 5 25 7 0
14 5 24 7 0
14 5 23 7 0
14 5 22 7 0
14 5 21 7 0
14 5 20 2 0
14 5 19 2 0
14 5 18 2 0
14 5 17 2 0
14 5 16 2 0
14 5 15 2 0
14 5 14 2 0
14 5 13 2 0
14 5 12 2 0
14 5 11 2 0
14 5 10 2 0
14 5 9 2 0
14 5 8 2 0
14 5 7 5 64
14 6 59 5 54
14 6 58 5 16
14 6 57 5 16
14 6 56 2 0
14 6 55 2 0
14 6 54 2 0
14 6 53 2 0
14 6 52 2 0
14 6 51 2 0
14 6 50 2 0
14 6 49 2 0
14 6 48 2 0
14 6 47 2 0
14 6 46 2 0
14 6 45 2 0
14 6 44 2 0
14 6 43 7 0
14 6 42 7 0
14 6 41 7 0
14 6 40 7 0
14 6 39 7 0
14 6 38 7 0
14 6 37 7 0
14 6 36 7 0
14 6 35 7 0
14 6 34 7 0
14 6 33 7 0
14 6 32 7 0
14 6 31 7 0
14 6 30 7 0
14 6 29 7 0
14 6 28 7 0
14 6 27 7 0
14 6 26 7 0
14 6 25 7 0
14 6 24 7 0
14 6 23 7 0
14 6 22 7 0
14 6 21 7 0
14 6 20 2 0
14 6 19 2 0
14 6 18 2 0
14 6 17 2 0
14 6 16 2 0
14 6 15 2 0
14 6 14 2 0
14 6 13 2 0
14 6 12 2 0
14 6 11 2 0
14 6 10 2 0
14 6 9 2 0
14 6 8 2 0
14 6 7 2 0
14 6 6 1 80
14 7 61 1 54
14 7 60 2 16
14 7 59 2 0
14 7 58 2 0
14 7 57 2 0
14 7 56 2 0
14 7 55 2 0
14 7 54 2 0
14 7 53 2 0
14 7 52 2 0
14 7 51 2 0
14 7 50 2 0
14 7 49 2 0
14 7 48 2 0
14 7 47 2 0
14 7 46 2 0
14 7 45 2 0
14 7 44 2 0
14 7 43 7 0
14 7 42 7 0
14 7 41 7 0
14 7 40 7 0
14 7 39 7 0
14 7 38 7 0
14 7 37 7 0
14 7 36 7 0
14 7 35 7 0
14 7 34 7 0
14 7 33 7 0
14 7 32 7 0
14 7 31 7 0
14 7 30 7 0
14 7 29 7 0
14 7 28 7 0
14 7 27 7 0
14 7 26 7 0
14 7 25 7 0
14 7 24 7 0
14 7 23 7 0
14 7 22 7 0
14 7 21 7 0
14 7 20 2 0
14 7 19 2 0
14 7 18 2 0
14 7 17 2 0
14 7 16 2 0
14 7 15 2 0
14 7 14 2 0
14 7 13 2 0
14 7 12 2 0
14 7 11 2 0
14 7 10 2 0
14 7 9 2 0
14 7 8 2 0
14 7 7 2 0
14 7 6 2 0
14 7 5 1 80
14 8 63 1 54
14 8 62 1 16
14 8 61 2 0
14 8 60 2 0
14 8 59 2 0
14 8 58 2 0
14 8 57 2 0
14 8 56 2 0
14 8 55 2 0
14 8 54 2 0
14 8 53 2 0
14 8 52 2 0
14 8 51 2 0
14 8 50 2 0
14 8 49 2 0
14 8 48 2 0
14 8 47 2 0
14 8 46 2 0
14 8 45 2 0
14 8 44 11 0
14 8 43 7 0
14 8 42 7 0
14 8 41 7 0
14 8 40 7 0
14 8 39 7 0
14 8 38 7 0
14 8 37 7 0
14 8 36 7 0
14 8 35 7 0
14 8 34 7 0
14 8 33 7 0
14 8 32 7 0
14 8 31 7 0
14 8 30 7 0
14 8 29 7 0
14 8 28 7 0
14 8 27 7 0
14 8 26 7 0
14 8 25 7 0
14 8 24 7 0
14 8 23 7 0
14 8 22 7 0
14 8 21 7 0
14 8 20 2 0
14 8 19 2 0
14 8 18 2 0
14 8 17 2 0
14 8 16 2 0
14 8 15 2 0
14 8 14 2 0
14 8 13 2 0
14 8 12 2 0
14 8 11 2 0
14 8 10 2 0
14 8 9 2 0
14 8 8 2 0
14 8 7 2 0
14 8 6 2 0
14 8 5 2 0
14 8 4 10 80
14 9 65 1 54
14 9 64 1 16
14 9 63 2 0
14 9 62 2 0
14 9 61 2 0
14 9 60 2 0
14 9 59 2 0
14 9 58 2 0
14 9 57 2 0
14 9 56 2 0
14 9 55 2 0
14 9 54 2 0
14 9 53 2 0
14 9 52 2 0
14 9 51 2 0
14 9 50 2 0
14 9 49 2 0
14 9 48 2 0
14 9 47 2 0
14 9 46 2 0
14 9 45 2 0
14 9 44 11 0
14 9 43 7 0
14 9 42 7 0
14 9 41 7 0
14 9 40 7 0
14 9 39 7 0
14 9 38 7 0
14 9 37 7 0
14 9 36 7 0
14 9 35 7 0
14 9 34 7 0
14 9 33 7 0
14 9 32 7 0
14 9 31 7 0
14 9 30 7 0
14 9 29 7 0
14 9 28 7 0
14 9 27 7 0
14 9 26 7 0
14 9 25 7 0
14 9 24 7 0
14 9 23 7 0
14 9 22 7 0
14 9 21 7 0
14 9 20 2 0
14 9 19 2 0
14 9 18 2 0
14 9 17 2 0
14 9 16 2 0
14 9 15 2 0
14 9 14 2 0
14 9 13 2 0
14 9 12 2 0
14 9 11 2 0
14 9 10 2 0
14 9 9 2 0
14 9 8 2 0
14 9 7 2 0
14 9 6 2 0
14 9 5 2 0
14 9 4 2 0
14 9 3 10 16
14 9 2 10 80
14 10 66 1 48
14 10 65 10 8
14 10 64 10 8
14 10 63 10 8
14 10 62 10 8
14 10 61 10 8
14 10 60 2 0
14 10 59 2 0
14 10 58 2 0
14 10 57 2 0
14 10 56 2 0
14 10 55 2 0
14 10 54 2 0
14 10 53 2 0
14 10 52 2 0
14 10 51 2 0
14 10 50 2 0
14 10 49 2 0
14 10 48 2 0
14 10 47 2 0
14 10 46 2 0
14 10 45 2 0
14 10 44 11 0
14 10 43 7 0
14 10 42 7 0
14 10 41 7 0
14 10 40 7 0
14 10 39 7 0
14 10 38 7 0
14 10 37 7 0
14 10 36 7 0
14 10 35 7 0
14 10 34 7 0
14 10 33 7 0
14 10 32 7 0
14 10 31 7 0
14 10 30 7 0
14 10 29 7 0
14 10 28 7 0
14 10 27 7 0
14 10 26 7 0
14 10 25 7 0
14 10 24 7 0
14 10 23 7 0
14 10 22 7 0
14 10 21 7 0
14 10 20 2 0
14 10 19 2 0
14 10 18 2 0
14 10 17 2 0
14 10 16 2 0
14 10 15 2 0
14 10 14 2 0
14 10 13 2 0
14 10 12 2 0
14 10 11 2 0
14 10 10 2 0
14 10 9 2 0
14 10 8 2 0
14 10 7 2 0
14 10 6 2 0
14 10 5 2 0
14 10 4 2 0
14 10 3 2 0
14 10 2 10 64
14 11 67 1 54
14 11 66 2 64
14 11 60 10 32
14 11 59 2 0
14 11 58 2 0
14 11 57 2 0
14 11 56 2 0
14 11 55 2 0
14 11 54 2 0
14 11 53 2 0
14 11 52 2 0
14 11 51 2 0
14 11 50 2 0
14 11 49 2 0
14 11 48 2 0
14 11 47 7 8
14 11 46 7 8
14 11 45 7 8
14 11 44 7 8
14 11 43 7 8
14 11 42 7 8
14 11 41 7 8
14 11 40 7 8
14 11 39 7 8
14 11 38 7 8
14 11 37 7 8
14 11 36 7 8
14 11 35 7 8
14 11 34 7 8
14 11 33 7 8
14 11 32 7 8
14 11 31 7 8
14 11 30 7 8
14 11 29 7 8
14 11 28 7 8
14 11 27 7 8
14 11 26 7 8
14 11 25 7 8
14 11 24 7 8
14 11 23 7 8
14 11 22 7 8
14 11 21 7 8
14 11 20 2 0
14 11 19 2 0
14 11 18 2 0
14 11 17 2 0
14 11 16 2 0
14 11 15 2 0
14 11 14 2 0
14 11 13 2 0
14 11 12 2 0
14 11 11 2 0
14 11 10 2 0
14 11 9 2 0
14 11 8 2 0
14 11 7 2 0
14 11 6 2 0
14 11 5 2 0
14 11 4 2 0
14 11 3 2 0
14 11 2 10 64
14 12 67 1 46
14 12 66 1 72
14 12 60 13 32
14 12 59 2 0
14 12 58 2 0
14 12 57 2 0
14 12 56 2 0
14 12 55 2 0
14 12 54 2 0
14 12 53 2 0
14 12 52 2 0
14 12 51 2 0
14 12 50 2 0
14 12 49 2 0
14 12 48 8 64
14 12 20 2 40
14 12 19 7 8
14 12 18 2 8
14 12 17 2 0
14 12 16 2 0
14 12 15 2 0
14 12 14 2 0
14 12 13 2 0
14 12 12 2 0
14 12 11 2 0
14 12 10 2 0
14 12 9 2 0
14 12 8 2 0
14 12 7 2 0
14 12 6 2 0
14 12 5 2 0
14 12 4 2 0
14 12 3 2 0
14 12 2 10 64
14 13 60 13 32
14 13 59 8 8
14 13 58 8 8
14 13 57 8 8
14 13 56 8 8
14 13 55 8 8
14 13 54 9 8
14 13 53 8 8
14 13 52 8 8
14 13 51 9 8
14 13 50 8 8
14 13 49 8 8
14 13 48 8 72
14 13 17 8 32
14 13 16 2 0
14 13 15 2 0
14 13 14 2 0
14 13 13 2 0
14 13 12 2 0
14 13 11 2 0
14 13 10 12 0
14 13 9 12 0
14 13 8 12 0
14 13 7 12 0
14 13 6 12 0
14 13 5 12 0
14 13 4 12 0
14 13 3 12 0
14 13 2 10 64
14 14 60 10 96
14 14 17 8 32
14 14 16 2 0
14 14 15 2 0
14 14 14 2 0
14 14 13 2 0
14 14 12 2 0
14 14 11 2 0
14 14 10 12 0
14 14 9 12 0
14 14 8 12 0
14 14 7 12 0
14 14 6 12 0
14 14 5 12 0
14 14 4 12 0
14 14 3 12 0
14 14 2 10 64
14 15 60 10 96
14 15 48 6 120
14 15 17 8 32
14 15 16 2 0
14 15 15 2 0
14 15 14 2 0
14 15 13 2 0
14 15 12 2 0
14 15 11 2 0
14 15 10 12 0
14 15 9 12 0
14 15 8 12 0
14 15 7 12 0
14 15 6 12 0
14 15 5 12 0
14 15 4 12 0
14 15 3 12 0
14 15 2 12 0
14 15 1 10 16
14 15 0 10 80
14 16 60 1 104
14 16 17 6 40
14 16 16 6 8
14 16 15 6 0
14 16 14 6 0
14 16 13 6 0
14 16 12 6 0
14 16 11 6 0
14 16 10 6 0
14 16 9 6 0
14 16 8 6 0
14 16 7 6 0
14 16 6 6 0
14 16 5 6 0
14 16 4 6 0
14 16 3 6 0
14 16 2 6 0
14 16 1 6 0
14 16 0 1 64
14 17 15 6 32
14 17 14 7 8
14 17 13 7 8
14 17 12 7 8
14 17 11 7 8
14 17 10 7 8
14 17 9 7 8
14 17 8 7 8
14 17 7 7 8
14 17 6 7 8
14 17 5 7 8
14 17 4 7 8
14 17 3 7 8
14 17 2 6 0
14 17 1 6 0
14 17 0 1 72
14 18 15 6 104
14 18 2 6 40
14 18 1 6 72
15 1 43 5 50
15 1 42 5 18
15 1 41 5 18
15 1 40 5 18
15 1 39 5 18
15 1 38 5 18
15 1 37 5 18
15 1 36 5 18
15 1 35 5 18
15 1 34 5 18
15 1 33 5 18
15 1 32 5 18
15 1 31 5 18
15 1 30 5 18
15 1 29 5 18
15 1 28 5 18
15 1 27 5 18
15 1 26 5 18
15 1 25 5 18
15 1 24 5 18
15 1 23 5 18
15 1 22 5 18
15 1 21 5 18
15 1 20 5 18
15 1 19 5 18
15 1 18 5 18
15 1 17 5 18
15 1 16 5 18
15 1 15 5 18
15 1 14 5 82
15 2 47 5 48
15 2 46 5 16
15 2 45 5 16
15 2 44 5 16
15 2 43 5 0
15 2 42 5 0
15 2 41 5 0
15 2 40 5 0
15 2 39 5 0
15 2 38 5 0
15 2 37 5 0
15 2 36 5 0
15 2 35 5 0
15 2 34 5 0
15 2 33 5 0
15 2 32 5 0
15 2 31 5 0
15 2 30 5 0
15 2 29 5 0
15 2 28 5 0
15 2 27 5 0
15 2 26 5 0
15 2 25 5 0
15 2 24 5 0
15 2 23 5 0
15 2 22 5 0
15 2 21 5 0
15 2 20 5 0
15 2 19 5 0
15 2 18 5 0
15 2 17 5 0
15 2 16 5 0
15 2 15 5 0
15 2 14 5 0
15 2 13 5 16
15 2 12 5 16
15 2 11 5 82
15 3 51 5 50
15 3 50 5 16
15 3 49 5 16
15 3 48 5 16
15 3 47 2 0
15 3 46 2 0
15 3 45 2 0
15 3 44 2 0
15 3 43 2 0
15 3 42 7 0
15 3 41 7 0
15 3 40 7 0
15 3 39 7 0
15 3 38 7 0
15 3 37 7 0
15 3 36 7 0
15 3 35 7 0
15 3 34 7 0
15 3 33 7 0
15 3 32 7 0
15 3 31 7 0
15 3 30 7 0
15 3 29 7 0
15 3 28 7 0
15 3 27 7 0
15 3 26 7 0
15 3 25 7 0
15 3 24 7 0
15 3 23 7 0
15 3 22 7 0
15 3 21 7 0
15 3 20 2 0
15 3 19 2 0
15 3 18 2 0
15 3 17 2 0
15 3 16 2 0
15 3 15 2 0
15 3 14 2 0
15 3 13 2 0
15 3 12 2 0
15 3 11 2 0
15 3 10 5 16
15 3 9 5 82
15 4 53 5 50
15 4 52 5 16
15 4 51 2 0
15 4 50 2 0
15 4 49 2 0
15 4 48 2 0
15 4 47 2 0
15 4 46 2 0
15 4 45 2 0
15 4 44 2 0
15 4 43 7 0
15 4 42 7 0
15 4 41 7 0
15 4 40 7 0
15 4 39 7 0
15 4 38 7 0
15 4 37 7 0
15 4 36 7 0
15 4 35 7 0
15 4 34 7 0
15 4 33 7 0
15 4 32 7 0
15 4 31 7 0
15 4 30 7 0
15 4 29 7 0
15 4 28 7 0
15 4 27 7 0
15 4 26 7 0
15 4 25 7 0
15 4 24 7 0
15 4 23 7 0
15 4 22 7 0
15 4 21 7 0
15 4 20 2 0
15 4 19 2 0
15 4 18 2 0
15 4 17 2 0
15 4 16 2 0
15 4 15 2 0
15 4 14 2 0
15 4 13 2 0
15 4 12 2 0
15 4 11 2 0
15 4 10 2 0
15 4 9 2 0
15 4 8 5 16
15 4 7 5 82
15 5 56 5 50
15 5 55 5 16
15 5 54 5 16
15 5 53 2 0
15 5 52 2 0
15 5 51 2 0
15 5 50 2 0
15 5 49 2 0
15 5 48 2 0
15 5 47 2 0
15 5 46 2 0
15 5 45 2 0
15 5 44 2 0
15 5 43 7 0
15 5 42 7 0
15 5 41 7 0
15 5 40 7 0
15 5 39 7 0
15 5 38 7 0
15 5 37 7 0
15 5 36 7 0
15 5 35 7 0
15 5 34 7 0
15 5 33 7 0
15 5 32 7 0
15 5 31 7 0
15 5 30 7 0
15 5 29 7 0
15 5 28 7 0
15 5 27 7 0
15 5 26 7 0
15 5 25 7 0
15 5 24 7 0
15 5 23 7 0
15 5 22 7 0
15 5 21 7 0
15 5 20 2 0
15 5 19 2 0
15 5 18 2 0
15 5 17 2 0
15 5 16 2 0
15 5 15 2 0
15 5 14 2 0
15 5 13 2 0
15 5 12 2 0
15 5 11 2 0
15 5 10 2 0
15 5 9 2 0
15 5 8 2 0
15 5 7 5 64
15 6 58 5 50
15 6 57 5 16
15 6 56 2 0
15 6 55 2 0
15 6 54 2 0
15 6 53 2 0
15 6 52 2 0
15 6 51 2 0
15 6 50 2 0
15 6 49 2 0
15 6 48 2 0
15 6 47 2 0
15 6 46 2 0
15 6 45 2 0
15 6 44 2 0
15 6 43 7 0
15 6 42 7 0
15 6 41 7 0
15 6 40 7 0
15 6 39 7 0
15 6 38 7 0
15 6 37 7 0
15 6 36 7 0
15 6 35 7 0
15 6 34 7 0
15 6 33 7 0
15 6 32 7 0
15 6 31 7 0
15 6 30 7 0
15 6 29 7 0
15 6 28 7 0
15 6 27 7 0
15 6 26 7 0
15 6 25 7 0
15 6 24 7 0
15 6 23 7 0
15 6 22 7 0
15 6 21 7 0
15 6 20 2 0
15 6 19 2 0
15 6 18 2 0
15 6 17 2 0
15 6 16 2 0
15 6 15 2 0
15 6 14 2 0
15 6 13 2 0
15 6 12 2 0
15 6 11 2 0
15 6 10 2 0
15 6 9 2 0
15 6 8 2 0
15 6 7 2 0
15 6 6 1 80
15 7 60 1 50
15 7 59 2 16
15 7 58 2 0
15 7 57 2 0
15 7 56 2 0
15 7 55 2 0
15 7 54 2 0
15 7 53 2 0
15 7 52 2 0
15 7 51 2 0
15 7 50 2 0
15 7 49 2 0
15 7 48 2 0
15 7 47 2 0
15 7 46 2 0
15 7 45 2 0
15 7 44 2 0
15 7 43 7 0
15 7 42 7 0
15 7 41 7 0
15 7 40 7 0
15 7 39 7 0
15 7 38 7 0
15 7 37 7 0
15 7 36 7 0
15 7 35 7 0
15 7 34 7 0
15 7 33 7 0
15 7 32 7 0
15 7 31 7 0
15 7 30 7 0
15 7 29 7 0
15 7 28 7 0
15 7 27 7 0
15 7 26 7 0
15 7 25 7 0
15 7 24 7 0
15 7 23 7 0
15 7 22 7 0
15 7 21 7 0
15 7 20 2 0
15 7 19 2 0
15 7 18 2 0
15 7 17 2 0
15 7 16 2 0
15 7 15 2 0
15 7 14 2 0
15 7 13 2 0
15 7 12 2 0
15 7 11 2 0
15 7 10 2 0
15 7 9 2 0
15 7 8 2 0
15 7 7 2 0
15 7 6 2 0
15 7 5 1 80
15 8 62 1 50
15 8 61 1 18
15 8 60 2 0
15 8 59 2 0
15 8 58 2 0
15 8 57 2 0
15 8 56 2 0
15 8 55 2 0
15 8 54 2 0
15 8 53 2 0
15 8 52 2 0
15 8 51 2 0
15 8 50 2 0
15 8 49 2 0
15 8 48 2 0
15 8 47 2 0
15 8 46 2 0
15 8 45 2 0
15 8 44 11 0
15 8 43 7 0
15 8 42 7 0
15 8 41 7 0
15 8 40 7 0
15 8 39 7 0
15 8 38 7 0
15 8 37 7 0
15 8 36 7 0
15 8 35 7 0
15 8 34 7 0
15 8 33 7 0
15 8 32 7 0
15 8 31 7 0
15 8 30 7 0
15 8 29 7 0
15 8 28 7 0
15 8 27 7 0
15 8 26 7 0
15 8 25 7 0
15 8 24 7 0
15 8 23 7 0
15 8 22 7 0
15 8 21 7 0
15 8 20 2 0
15 8 19 2 0
15 8 18 2 0
15 8 17 2 0
15 8 16 2 0
15 8 15 2 0
15 8 14 2 0
15 8 13 2 0
15 8 12 2 0
15 8 11 2 0
15 8 10 2 0
15 8 9 2 0
15 8 8 2 0
15 8 7 2 0
15 8 6 2 0
15 8 5 2 0
15 8 4 10 80
15 9 64 1 50
15 9 63 1 16
15 9 62 2 0
15 9 61 2 0
15 9 60 2 0
15 9 59 2 0
15 9 58 2 0
15 9 57 2 0
15 9 56 2 0
15 9 55 2 0
15 9 54 2 0
15 9 53 2 0
15 9 52 2 0
15 9 51 2 0
15 9 50 2 0
15 9 49 2 0
15 9 48 2 0
15 9 47 2 0
15 9 46 2 0
15 9 45 2 0
15 9 44 11 0
15 9 43 7 0
15 9 42 7 0
15 9 41 7 0
15 9 40 7 0
15 9 39 7 0
15 9 38 7 0
15 9 37 7 0
15 9 36 7 0
15 9 35 7 0
15 9 34 7 0
15 9 33 7 0
15 9 32 7 0
15 9 31 7 0
15 9 30 7 0
15 9 29 7 0
15 9 28 7 0
15 9 27 7 0
15 9 26 7 0
15 9 25 7 0
15 9 24 7 0
15 9 23 7 0
15 9 22 7 0
15 9 21 7 0
15 9 20 2 0
15 9 19 2 0
15 9 18 2 0
15 9 17 2 0
15 9 16 2 0
15 9 15 2 0
15 9 14 2 0
15 9 13 2 0
15 9 12 2 0
15 9 11 2 0
15 9 10 2 0
15 9 9 2 0
15 9 8 2 0
15 9 7 2 0
15 9 6 2 0
15 9 5 2 0
15 9 4 2 0
15 9 3 10 16
15 9 2 10 80
15 10 66 1 50
15 10 65 1 26
15 10 64 10 8
15 10 63 10 8
15 10 62 10 8
15 10 61 10 8
15 10 60 2 0
15 10 59 2 0
15 10 58 2 0
15 10 57 2 0
15 10 56 2 0
15 10 55 2 0
15 10 54 2 0
15 10 53 2 0
15 10 52 2 0
15 10 51 2 0
15 10 50 2 0
15 10 49 2 0
15 10 48 2 0
15 10 47 2 0
15 10 46 2 0
15 10 45 2 0
15 10 44 11 0
15 10 43 7 0
15 10 42 7 0
15 10 41 7 0
15 10 40 7 0
15 10 39 7 0
15 10 38 7 0
15 10 37 7 0
15 10 36 7 0
15 10 35 7 0
15 10 34 7 0
15 10 33 7 0
15 10 32 7 0
15 10 31 7 0
15 10 30 7 0
15 10 29 7 0
15 10 28 7 0
15 10 27 7 0
15 10 26 7 0
15 10 25 7 0
15 10 24 7 0
15 10 23 7 0
15 10 22 7 0
15 10 21 14 0
15 10 20 2 0
15 10 19 2 0
15 10 18 2 0
15 10 17 2 0
15 10 16 2 0
15 10 15 2 0
15 10 14 2 0
15 10 13 2 0
15 10 12 2 0
15 10 11 2 0
15 10 10 2 0
15 10 9 2 0
15 10 8 2 0
15 10 7 2 0
15 10 6 2 0
15 10 5 2 0
15 10 4 2 0
15 10 3 2 0
15 10 2 2 0
15 10 1 1 84
15 11 66 1 98
15 11 60 10 32
15 11 59 2 0
15 11 58 2 0
15 11 57 2 0
15 11 56 2 0
15 11 55 2 0
15 11 54 2 0
15 11 53 2 0
15 11 52 2 0
15 11 51 2 0
15 11 50 2 0
15 11 49 2 0
15 11 48 2 0
15 11 47 9 8
15 11 46 9 8
15 11 45 9 8
15 11 44 9 8
15 11 43 9 8
15 11 42 9 8
15 11 41 9 8
15 11 40 9 8
15 11 39 9 8
15 11 38 9 8
15 11 37 7 8
15 11 36 7 8
15 11 35 7 8
15 11 34 7 8
15 11 33 7 8
15 11 32 9 8
15 11 31 9 8
15 11 30 9 8
15 11 29 9 8
15 11 28 9 8
15 11 27 9 8
15 11 26 9 8
15 11 25 7 8
15 11 24 7 8
15 11 23 7 8
15 11 22 7 8
15 11 21 7 8
15 11 20 2 0
15 11 19 2 0
15 11 18 2 0
15 11 17 2 0
15 11 16 2 0
15 11 15 2 0
15 11 14 2 0
15 11 13 2 0
15 11 12 2 0
15 11 11 2 0
15 11 10 2 0
15 11 9 2 0
15 11 8 2 0
15 11 7 2 0
15 11 6 2 0
15 11 5 2 0
15 11 4 2 0
15 11 3 2 0
15 11 2 2 0
15 11 1 1 68
15 12 66 1 106
15 12 60 13 32
15 12 59 2 0
15 12 58 2 0
15 12 57 2 0
15 12 56 2 0
15 12 55 2 0
15 12 54 2 0
15 12 53 2 0
15 12 52 2 0
15 12 51 2 0
15 12 50 2 0
15 12 49 2 0
15 12 48 2 64
15 12 20 7 40
15 12 19 2 8
15 12 18 7 8
15 12 17 2 0
15 12 16 2 0
15 12 15 2 0
15 12 14 2 0
15 12 13 2 0
15 12 12 2 0
15 12 11 2 0
15 12 10 2 0
15 12 9 2 0
15 12 8 2 0
15 12 7 2 0
15 12 6 2 0
15 12 5 2 0
15 12 4 2 0
15 12 3 2 0
15 12 2 2 0
15 12 1 1 68
15 13 60 13 32
15 13 59 8 8
15 13 58 8 8
15 13 57 8 8
15 13 56 8 8
15 13 55 8 8
15 13 54 9 8
15 13 53 8 8
15 13 52 8 8
15 13 51 9 8
15 13 50 8 8
15 13 49 8 8
15 13 48 2 64
15 13 17 8 32
15 13 16 2 0
15 13 15 2 0
15 13 14 2 0
15 13 13 2 0
15 13 12 2 0
15 13 11 2 0
15 13 10 12 0
15 13 9 12 0
15 13 8 12 0
15 13 7 12 0
15 13 6 12 0
15 13 5 12 0
15 13 4 12 0
15 13 3 12 0
15 13 2 12 0
15 13 1 1 68
15 14 60 10 96
15 14 48 15 102
15 14 17 8 32
15 14 16 2 0
15 14 15 2 0
15 14 14 2 0
15 14 13 2 0
15 14 12 2 0
15 14 11 2 0
15 14 10 12 0
15 14 9 12 0
15 14 8 12 0
15 14 7 12 0
15 14 6 12 0
15 14 5 12 0
15 14 4 12 0
15 14 3 12 0
15 14 2 12 0
15 14 1 1 68
15 15 60 10 96
15 15 48 6 104
15 15 17 8 32
15 15 16 2 0
15 15 15 2 0
15 15 14 2 0
15 15 13 2 0
15 15 12 2 0
15 15 11 2 0
15 15 10 12 0
15 15 9 12 0
15 15 8 12 0
15 15 7 12 0
15 15 6 12 0
15 15 5 12 0
15 15 4 12 0
15 15 3 12 0
15 15 2 12 0
15 15 1 12 0
15 15 0 10 80
15 16 60 1 104
15 16 17 6 40
15 16 16 6 8
15 16 15 6 0
15 16 14 6 0
15 16 13 6 0
15 16 12 6 0
15 16 11 6 0
15 16 10 6 0
15 16 9 6 0
15 16 8 6 0
15 16 7 6 0
15 16 6 6 0
15 16 5 6 0
15 16 4 6 0
15 16 3 6 0
15 16 2 6 0
15 16 1 6 0
15 16 0 1 64
15 17 15 6 32
15 17 14 7 8
15 17 13 9 8
15 17 12 9 8
15 17 11 9 8
15 17 10 9 8
15 17 9 9 8
15 17 8 9 8
15 17 7 9 8
15 17 6 9 8
15 17 5 9 8
15 17 4 7 8
15 17 3 7 8
15 17 2 6 0
15 17 1 6 0
15 17 0 1 72
15 18 15 6 104
15 18 2 6 40
15 18 1 6 72
16 2 47 5 48
16 2 46 5 16
16 2 45 5 16
16 2 44 5 16
16 2 43 5 16
16 2 42 5 16
16 2 41 5 16
16 2 40 5 16
16 2 39 5 16
16 2 38 5 16
16 2 37 5 16
16 2 36 5 16
16 2 35 5 16
16 2 34 5 16
16 2 33 5 16
16 2 32 5 16
16 2 31 5 16
16 2 30 5 16
16 2 29 5 16
16 2 28 5 16
16 2 27 5 16
16 2 26 5 16
16 2 25 5 16
16 2 24 5 16
16 2 23 5 16
16 2 22 5 16
16 2 21 5 16
16 2 20 5 16
16 2 19 5 16
16 2 18 5 16
16 2 17 5 16
16 2 16 5 16
16 2 15 5 16
16 2 14 5 16
16 2 13 5 16
16 2 12 5 82
16 3 50 5 50
16 3 49 5 16
16 3 48 5 16
16 3 47 2 0
16 3 46 2 0
16 3 45 2 0
16 3 44 2 0
16 3 43 2 0
16 3 42 7 0
16 3 41 7 0
16 3 40 7 0
16 3 39 7 0
16 3 38 7 0
16 3 37 7 0
16 3 36 7 0
16 3 35 7 0
16 3 34 7 0
16 3 33 7 0
16 3 32 7 0
16 3 31 7 0
16 3 30 7 0
16 3 29 7 0
16 3 28 7 0
16 3 27 7 0
16 3 26 7 0
16 3 25 7 0
16 3 24 7 0
16 3 23 7 0
16 3 22 7 0
16 3 21 7 0
16 3 20 2 0
16 3 19 2 0
16 3 18 2 0
16 3 17 2 0
16 3 16 2 0
16 3 15 2 0
16 3 14 2 0
16 3 13 2 0
16 3 12 2 0
16 3 11 5 16
16 3 10 5 82
16 4 52 5 50
16 4 51 5 16
16 4 50 2 0
16 4 49 2 0
16 4 48 2 0
16 4 47 2 0
16 4 46 2 0
16 4 45 2 0
16 4 44 2 0
16 4 43 2 0
16 4 42 7 0
16 4 41 7 0
16 4 40 7 0
16 4 39 7 0
16 4 38 7 0
16 4 37 7 0
16 4 36 7 0
16 4 35 7 0
16 4 34 7 0
16 4 33 7 0
16 4 32 7 0
16 4 31 7 0
16 4 30 7 0
16 4 29 7 0
16 4 28 7 0
16 4 27 7 0
16 4 26 7 0
16 4 25 7 0
16 4 24 7 0
16 4 23 7 0
16 4 22 7 0
16 4 21 7 0
16 4 20 2 0
16 4 19 2 0
16 4 18 2 0
16 4 17 2 0
16 4 16 2 0
16 4 15 2 0
16 4 14 2 0
16 4 13 2 0
16 4 12 2 0
16 4 11 2 0
16 4 10 2 0
16 4 9 5 16
16 4 8 5 82
16 5 55 5 50
16 5 54 5 16
16 5 53 5 16
16 5 52 2 0
16 5 51 2 0
16 5 50 2 0
16 5 49 2 0
16 5 48 2 0
16 5 47 2 0
16 5 46 2 0
16 5 45 2 0
16 5 44 2 0
16 5 43 7 0
16 5 42 7 0
16 5 41 7 0
16 5 40 7 0
16 5 39 7 0
16 5 38 7 0
16 5 37 7 0
16 5 36 7 0
16 5 35 7 0
16 5 34 7 0
16 5 33 7 0
16 5 32 7 0
16 5 31 7 0
16 5 30 7 0
16 5 29 7 0
16 5 28 7 0
16 5 27 7 0
16 5 26 7 0
16 5 25 7 0
16 5 24 7 0
16 5 23 7 0
16 5 22 7 0
16 5 21 7 0
16 5 20 2 0
16 5 19 2 0
16 5 18 2 0
16 5 17 2 0
16 5 16 2 0
16 5 15 2 0
16 5 14 2 0
16 5 13 2 0
16 5 12 2 0
16 5 11 2 0
16 5 10 2 0
16 5 9 2 0
16 5 8 2 0
16 5 7 5 82
16 6 57 5 50
16 6 56 5 16
16 6 55 2 0
16 6 54 2 0
16 6 53 2 0
16 6 52 2 0
16 6 51 2 0
16 6 50 2 0
16 6 49 2 0
16 6 48 2 0
16 6 47 2 0
16 6 46 2 0
16 6 45 2 0
16 6 44 2 0
16 6 43 7 0
16 6 42 7 0
16 6 41 7 0
16 6 40 7 0
16 6 39 7 0
16 6 38 7 0
16 6 37 7 0
16 6 36 7 0
16 6 35 7 0
16 6 34 7 0
16 6 33 7 0
16 6 32 7 0
16 6 31 7 0
16 6 30 7 0
16 6 29 7 0
16 6 28 7 0
16 6 27 7 0
16 6 26 7 0
16 6 25 7 0
16 6 24 7 0
16 6 23 7 0
16 6 22 7 0
16 6 21 7 0
16 6 20 2 0
16 6 19 2 0
16 6 18 2 0
16 6 17 2 0
16 6 16 2 0
16 6 15 2 0
16 6 14 2 0
16 6 13 2 0
16 6 12 2 0
16 6 11 2 0
16 6 10 2 0
16 6 9 2 0
16 6 8 2 0
16 6 7 2 0
16 6 6 1 82
16 7 59 1 50
16 7 58 2 16
16 7 57 2 0
16 7 56 2 0
16 7 55 2 0
16 7 54 2 0
16 7 53 2 0
16 7 52 2 0
16 7 51 2 0
16 7 50 2 0
16 7 49 2 0
16 7 48 2 0
16 7 47 2 0
16 7 46 2 0
16 7 45 2 0
16 7 44 2 0
16 7 43 7 0
16 7 42 7 0
16 7 41 7 0
16 7 40 7 0
16 7 39 7 0
16 7 38 7 0
16 7 37 7 0
16 7 36 7 0
16 7 35 7 0
16 7 34 7 0
16 7 33 7 0
16 7 32 7 0
16 7 31 7 0
16 7 30 7 0
16 7 29 7 0
16 7 28 7 0
16 7 27 7 0
16 7 26 7 0
16 7 25 0 2
16 7 24 0 2
16 7 23 7 0
16 7 22 7 0
16 7 21 7 0
16 7 20 2 0
16 7 19 2 0
16 7 18 2 0
16 7 17 2 0
16 7 16 2 0
16 7 15 2 0
16 7 14 2 0
16 7 13 2 0
16 7 12 2 0
16 7 11 2 0
16 7 10 2 0
16 7 9 2 0
16 7 8 2 0
16 7 7 2 0
16 7 6 1 0
16 7 5 1 80
16 8 60 1 50
16 8 59 1 2
16 8 58 1 0
16 8 57 2 0
16 8 56 2 0
16 8 55 2 0
16 8 54 2 0
16 8 53 2 0
16 8 52 2 0
16 8 51 2 0
16 8 50 2 0
16 8 49 2 0
16 8 48 2 0
16 8 47 2 0
16 8 46 2 0
16 8 45 2 0
16 8 44 11 0
16 8 43 7 0
16 8 42 7 0
16 8 41 7 0
16 8 40 7 0
16 8 39 7 0
16 8 38 7 0
16 8 37 7 0
16 8 36 7 0
16 8 35 7 0
16 8 34 7 0
16 8 33 7 0
16 8 32 7 0
16 8 31 7 0
16 8 30 7 0
16 8 29 7 0
16 8 28 7 0
16 8 27 7 0
16 8 26 7 0
16 8 25 0 2
16 8 24 0 2
16 8 23 7 0
16 8 22 7 0
16 8 21 7 0
16 8 20 2 0
16 8 19 2 0
16 8 18 2 0
16 8 17 2 0
16 8 16 2 0
16 8 15 2 0
16 8 14 2 0
16 8 13 2 0
16 8 12 2 0
16 8 11 2 0
16 8 10 2 0
16 8 9 2 0
16 8 8 2 0
16 8 7 2 0
16 8 6 2 0
16 8 5 2 0
16 8 4 10 80
16 9 63 1 50
16 9 62 1 18
16 9 61 1 18
16 9 60 2 0
16 9 59 2 0
16 9 58 2 0
16 9 57 2 0
16 9 56 2 0
16 9 55 2 0
16 9 54 2 0
16 9 53 2 0
16 9 52 2 0
16 9 51 2 0
16 9 50 2 0
16 9 49 2 0
16 9 48 2 0
16 9 47 2 0
16 9 46 2 0
16 9 45 2 0
16 9 44 11 0
16 9 43 7 0
16 9 42 7 0
16 9 41 7 0
16 9 40 7 0
16 9 39 7 0
16 9 38 7 0
16 9 37 7 0
16 9 36 7 0
16 9 35 7 0
16 9 34 7 0
16 9 33 7 0
16 9 32 7 0
16 9 31 7 0
16 9 30 7 0
16 9 29 7 0
16 9 28 7 0
16 9 27 7 0
16 9 26 7 0
16 9 25 7 0
16 9 24 7 0
16 9 23 7 0
16 9 22 7 0
16 9 21 7 0
16 9 20 2 0
16 9 19 2 0
16 9 18 2 0
16 9 17 2 0
16 9 16 2 0
16 9 15 2 0
16 9 14 2 0
16 9 13 2 0
16 9 12 2 0
16 9 11 2 0
16 9 10 2 0
16 9 9 2 0
16 9 8 2 0
16 9 7 2 0
16 9 6 2 0
16 9 5 2 0
16 9 4 2 0
16 9 3 10 16
16 9 2 10 80
16 10 64 1 58
16 10 63 1 10
16 10 62 10 8
16 10 61 10 8
16 10 60 2 0
16 10 59 2 0
16 10 58 2 0
16 10 57 2 0
16 10 56 2 0
16 10 55 2 0
16 10 54 2 0
16 10 53 2 0
16 10 52 2 0
16 10 51 2 0
16 10 50 2 0
16 10 49 2 0
16 10 48 2 0
16 10 47 2 0
16 10 46 2 0
16 10 45 2 0
16 10 44 11 0
16 10 43 7 0
16 10 42 7 0
16 10 41 7 0
16 10 40 7 0
16 10 39 7 0
16 10 38 7 0
16 10 37 7 0
16 10 36 7 0
16 10 35 7 0
16 10 34 7 0
16 10 33 7 0
16 10 32 7 0
16 10 31 7 0
16 10 30 7 0
16 10 29 7 0
16 10 28 7 0
16 10 27 7 0
16 10 26 7 0
16 10 25 7 0
16 10 24 7 0
16 10 23 7 0
16 10 22 7 0
16 10 21 7 0
16 10 20 2 0
16 10 19 2 0
16 10 18 2 0
16 10 17 2 0
16 10 16 2 0
16 10 15 2 0
16 10 14 2 0
16 10 13 2 0
16 10 12 2 0
16 10 11 2 0
16 10 10 2 0
16 10 9 2 0
16 10 8 2 0
16 10 7 2 0
16 10 6 2 0
16 10 5 2 0
16 10 4 2 0
16 10 3 2 0
16 10 2 2 0
16 10 1 1 80
16 11 65 1 126
16 11 60 10 34
16 11 59 2 0
16 11 58 2 0
16 11 57 2 0
16 11 56 2 0
16 11 55 2 0
16 11 54 2 0
16 11 53 2 0
16 11 52 2 0
16 11 51 2 0
16 11 50 2 0
16 11 49 2 0
16 11 48 2 0
16 11 47 7 8
16 11 46 7 8
16 11 45 7 8
16 11 44 7 8
16 11 43 7 8
16 11 42 7 8
16 11 41 7 8
16 11 40 7 8
16 11 39 7 8
16 11 38 7 8
16 11 37 7 8
16 11 36 7 8
16 11 35 7 8
16 11 34 7 8
16 11 33 7 8
16 11 32 7 8
16 11 31 7 8
16 11 30 7 8
16 11 29 7 8
16 11 28 7 8
16 11 27 7 8
16 11 26 7 8
16 11 25 7 8
16 11 24 7 8
16 11 23 7 8
16 11 22 7 8
16 11 21 7 8
16 11 20 2 0
16 11 19 2 0
16 11 18 2 0
16 11 17 2 0
16 11 16 2 0
16 11 15 2 0
16 11 14 2 0
16 11 13 2 0
16 11 12 2 0
16 11 11 2 0
16 11 10 2 0
16 11 9 2 0
16 11 8 2 0
16 11 7 2 0
16 11 6 2 0
16 11 5 2 0
16 11 4 2 0
16 11 3 2 0
16 11 2 2 0
16 11 1 16 64
16 12 60 10 34
16 12 59 2 0
16 12 58 2 0
16 12 57 2 0
16 12 56 2 0
16 12 55 2 0
16 12 54 2 0
16 12 53 2 0
16 12 52 2 0
16 12 51 2 0
16 12 50 2 0
16 12 49 2 0
16 12 48 8 64
16 12 20 2 40
16 12 19 7 8
16 12 18 2 8
16 12 17 2 0
16 12 16 2 0
16 12 15 2 0
16 12 14 2 0
16 12 13 2 0
16 12 12 2 0
16 12 11 2 0
16 12 10 2 0
16 12 9 2 0
16 12 8 2 0
16 12 7 2 0
16 12 6 2 0
16 12 5 2 0
16 12 4 2 0
16 12 3 2 0
16 12 2 2 0
16 12 1 16 64
16 13 60 10 34
16 13 59 8 0
16 13 58 8 8
16 13 57 8 8
16 13 56 8 8
16 13 55 8 8
16 13 54 9 8
16 13 53 8 8
16 13 52 8 8
16 13 51 9 8
16 13 50 8 8
16 13 49 8 8
16 13 48 8 72
16 13 17 2 32
16 13 16 2 0
16 13 15 2 0
16 13 14 2 0
16 13 13 2 0
16 13 12 2 0
16 13 11 2 0
16 13 10 12 0
16 13 9 12 0
16 13 8 12 0
16 13 7 12 0
16 13 6 12 0
16 13 5 12 0
16 13 4 12 0
16 13 3 12 0
16 13 2 12 0
16 13 1 16 64
16 14 60 10 34
16 14 59 10 76
16 14 17 2 32
16 14 16 2 0
16 14 15 2 0
16 14 14 2 0
16 14 13 2 0
16 14 12 2 0
16 14 11 2 0
16 14 10 12 0
16 14 9 12 0
16 14 8 12 0
16 14 7 12 0
16 14 6 12 0
16 14 5 12 0
16 14 4 12 0
16 14 3 12 0
16 14 2 12 0
16 14 1 16 64
16 15 60 10 98
16 15 48 6 120
16 15 17 2 32
16 15 16 2 0
16 15 15 2 0
16 15 14 2 0
16 15 13 2 0
16 15 12 2 0
16 15 11 2 0
16 15 10 12 0
16 15 9 12 0
16 15 8 12 0
16 15 7 12 0
16 15 6 12 0
16 15 5 12 0
16 15 4 12 0
16 15 3 12 0
16 15 2 12 0
16 15 1 12 0
16 15 0 10 80
16 16 60 1 106
16 16 17 6 40
16 16 16 6 8
16 16 15 6 0
16 16 14 6 0
16 16 13 6 0
16 16 12 6 0
16 16 11 6 0
16 16 10 6 0
16 16 9 6 0
16 16 8 6 0
16 16 7 6 0
16 16 6 6 0
16 16 5 6 0
16 16 4 6 0
16 16 3 6 0
16 16 2 6 0
16 16 1 6 0
16 16 0 1 64
16 17 15 6 32
16 17 14 7 8
16 17 13 7 8
16 17 12 7 8
16 17 11 7 8
16 17 10 7 8
16 17 9 7 8
16 17 8 7 8
16 17 7 7 8
16 17 6 7 8
16 17 5 7 8
16 17 4 7 8
16 17 3 7 8
16 17 2 6 0
16 17 1 6 0
16 17 0 1 72
16 18 15 6 104
16 18 2 6 40
16 18 1 6 72
17 2 47 5 50
17 2 46 5 18
17 2 45 5 18
17 2 44 5 18
17 2 43 5 18
17 2 42 5 18
17 2 41 5 18
17 2 40 5 18
17 2 39 5 18
17 2 38 5 18
17 2 37 5 18
17 2 36 5 18
17 2 35 5 18
17 2 34 5 18
17 2 33 5 18
17 2 32 5 18
17 2 31 5 18
17 2 30 5 18
17 2 29 5 18
17 2 28 5 18
17 2 27 5 18
17 2 26 5 18
17 2 25 5 18
17 2 24 5 18
17 2 23 5 18
17 2 22 5 18
17 2 21 5 18
17 2 20 5 18
17 2 19 5 18
17 2 18 5 18
17 2 17 5 18
17 2 16 5 18
17 2 15 5 18
17 2 14 5 18
17 2 13 5 82
17 3 49 5 50
17 3 48 5 18
17 3 47 2 0
17 3 46 2 0
17 3 45 2 0
17 3 44 2 0
17 3 43 2 0
17 3 42 7 0
17 3 41 7 0
17 3 40 7 0
17 3 39 7 0
17 3 38 7 0
17 3 37 7 0
17 3 36 7 0
17 3 35 7 0
17 3 34 7 0
17 3 33 7 0
17 3 32 7 0
17 3 31 7 0
17 3 30 7 0
17 3 29 7 0
17 3 28 7 0
17 3 27 7 0
17 3 26 7 0
17 3 25 7 0
17 3 24 7 0
17 3 23 7 0
17 3 22 7 0
17 3 21 7 0
17 3 20 2 0
17 3 19 2 0
17 3 18 2 0
17 3 17 2 0
17 3 16 2 0
17 3 15 2 0
17 3 14 2 0
17 3 13 2 0
17 3 12 5 16
17 3 11 5 82
17 4 51 5 50
17 4 50 5 16
17 4 49 2 0
17 4 48 2 0
17 4 47 2 0
17 4 46 2 0
17 4 45 2 0
17 4 44 2 0
17 4 43 2 0
17 4 42 7 0
17 4 41 7 0
17 4 40 7 0
17 4 39 7 0
17 4 38 7 0
17 4 37 7 0
17 4 36 7 0
17 4 35 7 0
17 4 34 7 0
17 4 33 7 0
17 4 32 7 0
17 4 31 7 0
17 4 30 7 0
17 4 29 7 0
17 4 28 7 0
17 4 27 7 0
17 4 26 7 0
17 4 25 7 0
17 4 24 7 0
17 4 23 7 0
17 4 22 7 0
17 4 21 7 0
17 4 20 2 0
17 4 19 2 0
17 4 18 2 0
17 4 17 2 0
17 4 16 2 0
17 4 15 2 0
17 4 14 2 0
17 4 13 2 0
17 4 12 2 0
17 4 11 2 0
17 4 10 5 18
17 4 9 5 82
17 5 54 5 50
17 5 53 5 16
17 5 52 5 16
17 5 51 2 0
17 5 50 2 0
17 5 49 2 0
17 5 48 2 0
17 5 47 2 0
17 5 46 2 0
17 5 45 2 0
17 5 44 2 0
17 5 43 2 0
17 5 42 7 0
17 5 41 7 0
17 5 40 7 0
17 5 39 7 0
17 5 38 7 0
17 5 37 7 0
17 5 36 7 0
17 5 35 7 0
17 5 34 7 0
17 5 33 7 0
17 5 32 7 0
17 5 31 7 0
17 5 30 7 0
17 5 29 7 0
17 5 28 7 0
17 5 27 7 0
17 5 26 7 0
17 5 25 7 0
17 5 24 7 0
17 5 23 7 0
17 5 22 7 0
17 5 21 7 0
17 5 20 2 0
17 5 19 2 0
17 5 18 2 0
17 5 17 2 0
17 5 16 2 0
17 5 15 2 0
17 5 14 2 0
17 5 13 2 0
17 5 12 2 0
17 5 11 2 0
17 5 10 2 0
17 5 9 5 2
17 5 8 5 82
17 6 56 5 50
17 6 55 5 16
17 6 54 5 0
17 6 53 2 0
17 6 52 2 0
17 6 51 2 0
17 6 50 2 0
17 6 49 2 0
17 6 48 2 0
17 6 47 2 0
17 6 46 2 0
17 6 45 2 0
17 6 44 2 0
17 6 43 7 0
17 6 42 7 0
17 6 41 7 0
17 6 40 7 0
17 6 39 7 0
17 6 38 7 0
17 6 37 7 0
17 6 36 7 0
17 6 35 7 0
17 6 34 7 0
17 6 33 7 0
17 6 32 7 0
17 6 31 7 0
17 6 30 7 0
17 6 29 7 0
17 6 28 7 0
17 6 27 7 0
17 6 26 7 0
17 6 25 0 8
17 6 24 0 8
17 6 23 7 0
17 6 22 7 0
17 6 21 7 0
17 6 20 2 0
17 6 19 2 0
17 6 18 2 0
17 6 17 2 0
17 6 16 2 0
17 6 15 2 0
17 6 14 2 0
17 6 13 2 0
17 6 12 2 0
17 6 11 2 0
17 6 10 2 0
17 6 9 2 0
17 6 8 1 0
17 6 7 1 82
17 7 58 1 50
17 7 57 2 16
17 7 56 2 0
17 7 55 2 0
17 7 54 2 0
17 7 53 2 0
17 7 52 2 0
17 7 51 2 0
17 7 50 2 0
17 7 49 2 0
17 7 48 2 0
17 7 47 2 0
17 7 46 2 0
17 7 45 2 0
17 7 44 2 0
17 7 43 7 0
17 7 42 7 0
17 7 41 7 0
17 7 40 7 0
17 7 39 7 0
17 7 38 7 0
17 7 37 7 0
17 7 36 7 0
17 7 35 7 0
17 7 34 7 0
17 7 33 7 0
17 7 32 7 0
17 7 31 7 0
17 7 30 7 0
17 7 29 7 0
17 7 28 7 0
17 7 27 7 0
17 7 26 0 64
17 7 23 0 32
17 7 22 7 0
17 7 21 7 0
17 7 20 2 0
17 7 19 2 0
17 7 18 2 0
17 7 17 2 0
17 7 16 2 0
17 7 15 2 0
17 7 14 2 0
17 7 13 2 0
17 7 12 2 0
17 7 11 2 0
17 7 10 2 0
17 7 9 2 0
17 7 8 2 0
17 7 7 2 0
17 7 6 1 16
17 7 5 1 82
17 8 58 1 34
17 8 57 1 0
17 8 56 1 0
17 8 55 2 0
17 8 54 2 0
17 8 53 2 0
17 8 52 2 0
17 8 51 2 0
17 8 50 2 0
17 8 49 2 0
17 8 48 2 0
17 8 47 2 0
17 8 46 2 0
17 8 45 2 0
17 8 44 11 0
17 8 43 7 0
17 8 42 7 0
17 8 41 7 0
17 8 40 7 0
17 8 39 7 0
17 8 38 7 0
17 8 37 7 0
17 8 36 7 0
17 8 35 7 0
17 8 34 7 0
17 8 33 7 0
17 8 32 7 0
17 8 31 7 0
17 8 30 7 0
17 8 29 7 0
17 8 28 7 0
17 8 27 7 0
17 8 26 0 64
17 8 23 0 32
17 8 22 7 0
17 8 21 7 0
17 8 20 2 0
17 8 19 2 0
17 8 18 2 0
17 8 17 2 0
17 8 16 2 0
17 8 15 2 0
17 8 14 2 0
17 8 13 2 0
17 8 12 2 0
17 8 11 2 0
17 8 10 2 0
17 8 9 2 0
17 8 8 2 0
17 8 7 2 0
17 8 6 2 0
17 8 5 2 0
17 8 4 10 80
17 9 60 1 50
17 9 59 1 18
17 9 58 2 0
17 9 57 2 0
17 9 56 2 0
17 9 55 2 0
17 9 54 2 0
17 9 53 2 0
17 9 52 2 0
17 9 51 2 0
17 9 50 2 0
17 9 49 2 0
17 9 48 2 0
17 9 47 2 0
17 9 46 2 0
17 9 45 2 0
17 9 44 11 0
17 9 43 7 0
17 9 42 7 0
17 9 41 7 0
17 9 40 7 0
17 9 39 7 0
17 9 38 7 0
17 9 37 7 0
17 9 36 7 0
17 9 35 7 0
17 9 34 7 0
17 9 33 7 0
17 9 32 7 0
17 9 31 7 0
17 9 30 7 0
17 9 29 7 0
17 9 28 7 0
17 9 27 7 0
17 9 26 7 0
17 9 25 0 16
17 9 24 0 16
17 9 23 7 0
17 9 22 7 0
17 9 21 7 0
17 9 20 2 0
17 9 19 2 0
17 9 18 2 0
17 9 17 2 0
17 9 16 2 0
17 9 15 2 0
17 9 14 2 0
17 9 13 2 0
