Qubicle Exchange Format
Version 0.2
www.minddesk.com
29 58 80
22
0.000000 0.000000 0.000000
0.113725 0.113725 0.113725
0.172549 0.156863 0.137255
0.266667 0.156863 0.000000
0.313725 0.266667 0.223529
0.349020 0.129412 0.101961
0.356863 0.274510 0.160784
0.368627 0.160784 0.121569
0.376471 0.274510 0.141176
0.376471 0.384314 0.392157
0.439216 0.337255 0.203922
0.443137 0.349020 0.215686
0.478431 0.380392 0.250980
0.490196 0.352941 0.172549
0.498039 0.368627 0.184314
0.501961 0.254902 0.215686
0.501961 0.349020 0.176471
0.501961 0.352941 0.211765
0.525490 0.349020 0.113725
0.525490 0.403922 0.156863
0.988235 0.784314 0.031373
1.000000 1.000000 1.000000
5 6 53 3 52
5 6 52 3 20
5 6 51 3 20
5 6 50 3 20
5 6 49 3 20
5 6 48 3 20
5 6 47 3 20
5 6 46 3 28
5 6 45 3 28
5 6 44 3 20
5 6 43 3 20
5 6 42 3 20
5 6 41 3 20
5 6 40 3 28
5 6 39 3 28
5 6 38 3 20
5 6 37 3 20
5 6 36 3 20
5 6 35 3 20
5 6 34 3 28
5 6 33 3 28
5 6 32 3 84
5 7 53 3 36
5 7 52 3 4
5 7 51 3 4
5 7 50 3 4
5 7 49 3 4
5 7 48 3 4
5 7 47 3 68
5 7 44 3 36
5 7 43 3 4
5 7 42 3 4
5 7 41 3 68
5 7 38 3 36
5 7 37 3 4
5 7 36 3 4
5 7 35 3 68
5 7 32 3 100
5 8 54 3 52
5 8 53 3 4
5 8 52 3 4
5 8 51 3 4
5 8 50 3 4
5 8 49 3 4
5 8 48 3 4
5 8 47 3 68
5 8 44 3 36
5 8 43 3 4
5 8 42 3 4
5 8 41 3 68
5 8 38 3 36
5 8 37 3 4
5 8 36 3 4
5 8 35 3 68
5 8 32 3 100
5 9 54 3 36
5 9 53 3 4
5 9 52 3 4
5 9 51 3 4
5 9 50 3 4
5 9 49 3 4
5 9 48 3 4
5 9 47 3 4
5 9 46 3 20
5 9 45 3 20
5 9 44 3 4
5 9 43 3 4
5 9 42 3 4
5 9 41 3 4
5 9 40 3 20
5 9 39 3 20
5 9 38 3 4
5 9 37 3 4
5 9 36 3 4
5 9 35 3 4
5 9 34 3 20
5 9 33 3 20
5 9 32 3 4
5 9 31 3 84
5 10 54 14 44
5 10 53 14 12
5 10 52 14 12
5 10 51 14 12
5 10 50 14 4
5 10 49 14 12
5 10 48 14 12
5 10 47 14 12
5 10 46 14 4
5 10 45 14 12
5 10 44 14 12
5 10 43 14 12
5 10 42 14 4
5 10 41 14 12
5 10 40 14 12
5 10 39 14 12
5 10 38 14 4
5 10 37 14 12
5 10 36 14 12
5 10 35 14 12
5 10 34 14 4
5 10 33 14 12
5 10 32 14 12
5 10 31 14 12
5 10 30 14 92
5 11 50 8 100
5 11 46 8 100
5 11 42 8 100
5 11 38 8 100
5 11 34 8 100
5 12 50 8 108
5 12 46 8 108
5 12 42 8 108
5 12 38 8 108
5 12 34 8 108
6 5 56 3 52
6 5 55 3 20
6 5 54 3 20
6 5 53 3 20
6 5 52 3 20
6 5 51 3 20
6 5 50 3 20
6 5 49 3 20
6 5 48 3 20
6 5 47 3 20
6 5 46 3 20
6 5 45 3 20
6 5 44 3 20
6 5 43 3 20
6 5 42 3 20
6 5 41 3 20
6 5 40 3 20
6 5 39 3 20
6 5 38 3 20
6 5 37 3 20
6 5 36 3 20
6 5 35 3 20
6 5 34 3 20
6 5 33 3 20
6 5 32 3 20
6 5 31 3 20
6 5 30 3 20
6 5 29 3 84
6 6 56 3 36
6 6 55 3 4
6 6 54 3 4
6 6 53 3 0
6 6 52 3 0
6 6 51 3 0
6 6 50 3 0
6 6 49 3 0
6 6 48 3 0
6 6 47 3 0
6 6 46 0 8
6 6 45 0 8
6 6 44 3 0
6 6 43 3 0
6 6 42 3 0
6 6 41 3 0
6 6 40 0 8
6 6 39 0 8
6 6 38 3 0
6 6 37 3 0
6 6 36 3 0
6 6 35 3 0
6 6 34 0 8
6 6 33 0 8
6 6 32 3 0
6 6 31 3 4
6 6 30 3 4
6 6 29 3 4
6 6 28 3 84
6 7 56 3 36
6 7 55 3 4
6 7 54 3 4
6 7 53 3 0
6 7 52 3 0
6 7 51 3 0
6 7 50 3 0
6 7 49 3 0
6 7 48 3 0
6 7 47 0 64
6 7 44 0 32
6 7 43 3 0
6 7 42 3 0
6 7 41 0 64
6 7 38 3 32
6 7 37 3 0
6 7 36 3 0
6 7 35 0 64
6 7 32 3 32
6 7 31 3 4
6 7 30 3 4
6 7 29 3 4
6 7 28 3 4
6 7 27 3 84
6 8 56 3 36
6 8 55 3 4
6 8 54 3 0
6 8 53 3 0
6 8 52 3 0
6 8 51 3 0
6 8 50 3 0
6 8 49 3 0
6 8 48 3 0
6 8 47 0 64
6 8 44 0 32
6 8 43 3 0
6 8 42 3 0
6 8 41 0 64
6 8 38 3 32
6 8 37 3 0
6 8 36 3 0
6 8 35 0 64
6 8 32 3 32
6 8 31 3 4
6 8 30 3 4
6 8 29 3 4
6 8 28 3 4
6 8 27 3 4
6 8 26 3 84
6 9 56 3 36
6 9 55 3 4
6 9 54 3 0
6 9 53 3 0
6 9 52 3 0
6 9 51 3 0
6 9 50 14 0
6 9 49 14 0
6 9 48 14 0
6 9 47 14 0
6 9 46 0 16
6 9 45 0 16
6 9 44 14 0
6 9 43 14 0
6 9 42 14 0
6 9 41 14 0
6 9 40 0 16
6 9 39 0 16
6 9 38 14 0
6 9 37 14 0
6 9 36 14 0
6 9 35 14 0
6 9 34 0 16
6 9 33 0 16
6 9 32 14 0
6 9 31 14 0
6 9 30 3 4
6 9 29 3 4
6 9 28 3 4
6 9 27 3 4
6 9 26 3 4
6 9 25 3 20
6 9 24 3 84
6 10 56 14 36
6 10 55 13 4
6 10 54 3 0
6 10 53 3 0
6 10 52 14 0
6 10 51 14 0
6 10 50 14 0
6 10 49 14 0
6 10 48 14 0
6 10 47 14 0
6 10 46 14 0
6 10 45 14 0
6 10 44 14 0
6 10 43 14 0
6 10 42 14 0
6 10 41 14 0
6 10 40 14 0
6 10 39 14 0
6 10 38 14 0
6 10 37 14 0
6 10 36 14 0
6 10 35 14 0
6 10 34 14 0
6 10 33 14 0
6 10 32 14 0
6 10 31 14 0
6 10 30 14 0
6 10 29 14 4
6 10 28 13 4
6 10 27 13 4
6 10 26 13 4
6 10 25 13 4
6 10 24 13 68
6 11 57 13 52
6 11 56 13 4
6 11 55 14 4
6 11 54 13 4
6 11 53 13 4
6 11 52 13 4
6 11 51 13 4
6 11 50 8 0
6 11 49 3 4
6 11 48 3 12
6 11 47 3 4
6 11 46 8 0
6 11 45 3 4
6 11 44 3 12
6 11 43 3 4
6 11 42 8 0
6 11 41 3 4
6 11 40 3 12
6 11 39 3 4
6 11 38 8 0
6 11 37 3 4
6 11 36 3 12
6 11 35 3 4
6 11 34 8 0
6 11 33 3 4
6 11 32 3 12
6 11 31 3 4
6 11 30 3 4
6 11 29 8 4
6 11 28 17 4
6 11 27 13 4
6 11 26 13 4
6 11 25 13 4
6 11 24 13 4
6 11 23 13 84
6 12 57 13 44
6 12 56 13 12
6 12 55 13 12
6 12 54 13 12
6 12 53 13 12
6 12 52 13 12
6 12 51 13 12
6 12 50 8 0
6 12 49 3 76
6 12 47 3 44
6 12 46 8 0
6 12 45 3 76
6 12 43 3 44
6 12 42 8 0
6 12 41 3 76
6 12 39 3 44
6 12 38 8 0
6 12 37 3 76
6 12 35 3 44
6 12 34 8 0
6 12 33 3 76
6 12 31 3 44
6 12 30 3 12
6 12 29 8 12
6 12 28 13 4
6 12 27 13 4
6 12 26 13 4
6 12 25 13 4
6 12 24 13 4
6 12 23 13 4
6 12 22 13 84
6 13 50 8 108
6 13 46 8 108
6 13 42 8 108
6 13 38 8 108
6 13 34 8 108
6 13 28 13 44
6 13 27 13 12
6 13 26 13 4
6 13 25 13 4
6 13 24 13 4
6 13 23 13 4
6 13 22 13 4
6 13 21 13 84
6 14 26 6 44
6 14 25 6 4
6 14 24 6 4
6 14 23 6 4
6 14 22 6 4
6 14 21 6 4
6 14 20 6 84
6 15 25 6 44
6 15 24 6 12
6 15 23 6 12
6 15 22 6 12
6 15 21 6 12
6 15 20 6 12
6 15 19 6 92
7 4 57 3 52
7 4 56 3 20
7 4 55 3 20
7 4 54 3 20
7 4 53 3 20
7 4 52 3 20
7 4 51 3 20
7 4 50 3 20
7 4 49 3 20
7 4 48 3 20
7 4 47 3 20
7 4 46 3 20
7 4 45 3 20
7 4 44 3 20
7 4 43 3 20
7 4 42 3 20
7 4 41 3 20
7 4 40 3 20
7 4 39 3 20
7 4 38 3 20
7 4 37 3 20
7 4 36 3 20
7 4 35 3 20
7 4 34 3 20
7 4 33 3 20
7 4 32 3 20
7 4 31 3 20
7 4 30 3 20
7 4 29 3 20
7 4 28 3 20
7 4 27 3 20
7 4 26 3 84
7 5 57 3 36
7 5 56 3 0
7 5 55 3 0
7 5 54 3 0
7 5 53 3 0
7 5 52 3 0
7 5 51 3 0
7 5 50 3 0
7 5 49 3 0
7 5 48 3 0
7 5 47 3 0
7 5 46 3 0
7 5 45 3 0
7 5 44 3 0
7 5 43 3 0
7 5 42 3 0
7 5 41 3 0
7 5 40 3 0
7 5 39 3 0
7 5 38 3 0
7 5 37 3 0
7 5 36 3 0
7 5 35 3 0
7 5 34 3 0
7 5 33 3 0
7 5 32 3 0
7 5 31 3 0
7 5 30 3 0
7 5 29 3 0
7 5 28 3 4
7 5 27 3 4
7 5 26 3 4
7 5 25 3 20
7 5 24 3 84
7 6 57 3 36
7 6 56 3 0
7 6 55 3 0
7 6 54 3 0
7 6 53 3 0
7 6 52 3 0
7 6 51 3 0
7 6 50 3 0
7 6 49 3 0
7 6 48 3 0
7 6 47 3 0
7 6 46 0 8
7 6 45 0 8
7 6 44 3 0
7 6 43 3 0
7 6 42 3 0
7 6 41 3 0
7 6 40 0 8
7 6 39 0 8
7 6 38 3 0
7 6 37 3 0
7 6 36 3 0
7 6 35 3 0
7 6 34 0 8
7 6 33 0 8
7 6 32 3 0
7 6 31 3 0
7 6 30 3 0
7 6 29 3 0
7 6 28 3 0
7 6 27 3 4
7 6 26 3 4
7 6 25 3 4
7 6 24 3 4
7 6 23 3 20
7 6 22 3 84
7 7 58 3 52
7 7 57 3 4
7 7 56 3 0
7 7 55 3 0
7 7 54 3 0
7 7 53 3 0
7 7 52 3 0
7 7 51 3 0
7 7 50 3 0
7 7 49 3 0
7 7 48 3 0
7 7 47 0 64
7 7 44 0 32
7 7 43 3 0
7 7 42 3 0
7 7 41 0 64
7 7 38 0 32
7 7 37 3 0
7 7 36 3 0
7 7 35 0 64
7 7 32 0 32
7 7 31 3 0
7 7 30 3 0
7 7 29 3 0
7 7 28 3 0
7 7 27 3 0
7 7 26 3 4
7 7 25 3 4
7 7 24 3 4
7 7 23 3 4
7 7 22 3 4
7 7 21 3 84
7 8 58 3 36
7 8 57 3 4
7 8 56 3 0
7 8 55 14 0
7 8 54 14 0
7 8 53 14 0
7 8 52 14 0
7 8 51 14 0
7 8 50 14 0
7 8 49 14 0
7 8 48 14 0
7 8 47 0 64
7 8 44 0 32
7 8 43 14 0
7 8 42 14 0
7 8 41 0 64
7 8 38 0 32
7 8 37 14 0
7 8 36 14 0
7 8 35 0 64
7 8 32 0 32
7 8 31 14 0
7 8 30 14 0
7 8 29 4 0
7 8 28 4 0
7 8 27 4 0
7 8 26 4 0
7 8 25 3 4
7 8 24 3 4
7 8 23 3 4
7 8 22 3 4
7 8 21 3 4
7 8 20 3 20
7 8 19 3 20
7 8 18 3 84
7 9 58 3 36
7 9 57 3 4
7 9 56 3 0
7 9 55 14 0
7 9 54 14 0
7 9 53 14 0
7 9 52 14 0
7 9 51 14 0
7 9 50 14 0
7 9 49 14 0
7 9 48 14 0
7 9 47 14 0
7 9 46 0 16
7 9 45 0 16
7 9 44 14 0
7 9 43 14 0
7 9 42 14 0
7 9 41 14 0
7 9 40 0 16
7 9 39 0 16
7 9 38 14 0
7 9 37 14 0
7 9 36 14 0
7 9 35 14 0
7 9 34 0 16
7 9 33 0 16
7 9 32 14 0
7 9 31 14 0
7 9 30 14 0
7 9 29 4 0
7 9 28 4 0
7 9 27 4 0
7 9 26 4 0
7 9 25 4 0
7 9 24 4 0
7 9 23 3 4
7 9 22 3 4
7 9 21 3 4
7 9 20 3 4
7 9 19 3 4
7 9 18 3 4
7 9 17 3 20
7 9 16 3 84
7 10 59 14 52
7 10 58 14 4
7 10 57 14 4
7 10 56 14 0
7 10 55 14 0
7 10 54 14 0
7 10 53 14 0
7 10 52 14 0
7 10 51 14 0
7 10 50 14 0
7 10 49 14 0
7 10 48 14 0
7 10 47 14 0
7 10 46 14 0
7 10 45 14 0
7 10 44 14 0
7 10 43 14 0
7 10 42 14 0
7 10 41 14 0
7 10 40 14 0
7 10 39 14 0
7 10 38 14 0
7 10 37 14 0
7 10 36 14 0
7 10 35 14 0
7 10 34 14 0
7 10 33 14 0
7 10 32 14 0
7 10 31 14 0
7 10 30 14 0
7 10 29 4 0
7 10 28 4 0
7 10 27 4 0
7 10 26 4 0
7 10 25 4 0
7 10 24 4 0
7 10 23 13 4
7 10 22 13 4
7 10 21 13 4
7 10 20 13 4
7 10 19 13 4
7 10 18 13 4
7 10 17 13 4
7 10 16 13 68
7 11 60 14 52
7 11 59 14 4
7 11 58 14 4
7 11 57 14 0
7 11 56 14 0
7 11 55 4 0
7 11 54 4 0
7 11 53 4 0
7 11 52 4 0
7 11 51 4 0
7 11 50 4 0
7 11 49 4 0
7 11 48 12 8
7 11 47 4 0
7 11 46 4 0
7 11 45 4 0
7 11 44 12 8
7 11 43 4 0
7 11 42 4 0
7 11 41 4 0
7 11 40 12 8
7 11 39 4 0
7 11 38 4 0
7 11 37 4 0
7 11 36 12 8
7 11 35 4 0
7 11 34 4 0
7 11 33 4 0
7 11 32 12 8
7 11 31 4 0
7 11 30 4 0
7 11 29 4 0
7 11 28 4 0
7 11 27 4 0
7 11 26 4 0
7 11 25 4 0
7 11 24 4 0
7 11 23 13 0
7 11 22 13 4
7 11 21 13 4
7 11 20 13 4
7 11 19 13 4
7 11 18 13 4
7 11 17 13 4
7 11 16 13 4
7 11 15 13 20
7 11 14 13 84
7 12 60 13 36
7 12 59 13 4
7 12 58 13 4
7 12 57 13 0
7 12 56 13 2
7 12 55 4 2
7 12 54 4 2
7 12 53 4 2
7 12 52 4 2
7 12 51 13 2
7 12 50 3 2
7 12 49 3 74
7 12 47 3 42
7 12 46 3 2
7 12 45 3 74
7 12 43 3 42
7 12 42 3 2
7 12 41 3 74
7 12 39 3 42
7 12 38 3 2
7 12 37 3 74
7 12 35 3 42
7 12 34 3 2
7 12 33 3 74
7 12 31 3 42
7 12 30 3 2
7 12 29 4 0
7 12 28 4 0
7 12 27 4 0
7 12 26 4 0
7 12 25 4 0
7 12 24 4 0
7 12 23 13 0
7 12 22 13 0
7 12 21 13 4
7 12 20 13 4
7 12 19 13 4
7 12 18 13 4
7 12 17 3 4
7 12 16 3 4
7 12 15 3 4
7 12 14 3 68
7 13 60 13 36
7 13 59 13 4
7 13 58 13 4
7 13 57 13 4
7 13 56 13 6
7 13 55 13 6
7 13 54 13 6
7 13 53 13 6
7 13 52 13 6
7 13 51 13 6
7 13 50 8 66
7 13 46 8 98
7 13 42 8 98
7 13 38 8 98
7 13 34 8 98
7 13 30 3 38
7 13 29 3 6
7 13 28 4 0
7 13 27 4 0
7 13 26 4 0
7 13 25 4 0
7 13 24 4 0
7 13 23 4 0
7 13 22 4 0
7 13 21 13 0
7 13 20 13 4
7 13 19 13 4
7 13 18 13 4
7 13 17 3 4
7 13 16 20 4
7 13 15 20 4
7 13 14 3 4
7 13 13 13 84
7 14 60 13 36
7 14 59 13 6
7 14 58 3 6
7 14 57 3 4
7 14 56 3 14
7 14 55 3 14
7 14 54 3 14
7 14 53 3 14
7 14 52 3 14
7 14 51 3 14
7 14 50 8 14
7 14 49 3 30
7 14 48 3 30
7 14 47 3 30
7 14 46 8 14
7 14 45 3 30
7 14 44 3 30
7 14 43 3 30
7 14 42 8 14
7 14 41 3 30
7 14 40 3 30
7 14 39 3 30
7 14 38 8 14
7 14 37 3 30
7 14 36 3 30
7 14 35 3 30
7 14 34 8 14
7 14 33 3 30
7 14 32 3 30
7 14 31 3 30
7 14 30 3 14
7 14 29 3 14
7 14 28 3 14
7 14 27 13 4
7 14 26 4 0
7 14 25 4 0
7 14 24 4 0
7 14 23 4 0
7 14 22 4 0
7 14 21 6 0
7 14 20 6 0
7 14 19 6 4
7 14 18 6 4
7 14 17 3 4
7 14 16 20 4
7 14 15 20 4
7 14 14 3 4
7 14 13 13 68
7 15 60 3 44
7 15 59 3 14
7 15 58 3 14
7 15 57 8 76
7 15 27 13 46
7 15 26 6 4
7 15 25 6 0
7 15 24 6 0
7 15 23 6 0
7 15 22 6 0
7 15 21 6 0
7 15 20 6 0
7 15 19 6 0
7 15 18 6 4
7 15 17 3 4
7 15 16 3 4
7 15 15 3 4
7 15 14 3 4
7 15 13 13 4
7 15 12 13 28
7 15 11 13 92
7 16 26 3 46
7 16 25 3 4
7 16 24 3 4
7 16 23 3 4
7 16 22 3 4
7 16 21 3 4
7 16 20 3 4
7 16 19 3 4
7 16 18 3 4
7 16 17 3 4
7 16 16 3 4
7 16 15 3 4
7 16 14 3 4
7 16 13 3 76
7 17 25 3 46
7 17 24 3 12
7 17 23 3 12
7 17 22 3 12
7 17 21 3 12
7 17 20 3 12
7 17 19 3 12
7 17 18 3 12
7 17 17 3 12
7 17 16 3 12
7 17 15 3 12
7 17 14 3 76
8 4 57 3 48
8 4 56 3 16
8 4 55 3 16
8 4 54 3 16
8 4 53 3 16
8 4 52 3 16
8 4 51 3 16
8 4 50 3 16
8 4 49 3 16
8 4 48 3 16
8 4 47 3 16
8 4 46 3 16
8 4 45 3 16
8 4 44 3 16
8 4 43 3 16
8 4 42 3 16
8 4 41 3 16
8 4 40 3 16
8 4 39 3 16
8 4 38 3 16
8 4 37 3 16
8 4 36 3 16
8 4 35 3 16
8 4 34 3 16
8 4 33 3 16
8 4 32 3 16
8 4 31 3 16
8 4 30 3 16
8 4 29 3 16
8 4 28 3 16
8 4 27 3 16
8 4 26 3 16
8 4 25 3 20
8 4 24 3 20
8 4 23 3 84
8 5 58 3 52
8 5 57 3 0
8 5 56 3 0
8 5 55 3 0
8 5 54 3 0
8 5 53 3 0
8 5 52 3 0
8 5 51 3 0
8 5 50 3 0
8 5 49 3 0
8 5 48 3 0
8 5 47 3 0
8 5 46 3 0
8 5 45 3 0
8 5 44 3 0
8 5 43 3 0
8 5 42 3 0
8 5 41 3 0
8 5 40 3 0
8 5 39 3 0
8 5 38 3 0
8 5 37 3 0
8 5 36 3 0
8 5 35 3 0
8 5 34 3 0
8 5 33 3 0
8 5 32 3 0
8 5 31 3 0
8 5 30 3 0
8 5 29 3 0
8 5 28 3 0
8 5 27 3 0
8 5 26 3 0
8 5 25 3 0
8 5 24 3 0
8 5 23 3 4
8 5 22 3 86
8 6 59 3 52
8 6 58 3 4
8 6 57 3 0
8 6 56 3 0
8 6 55 3 0
8 6 54 3 0
8 6 53 3 0
8 6 52 3 0
8 6 51 3 0
8 6 50 3 0
8 6 49 3 0
8 6 48 3 0
8 6 47 3 0
8 6 46 0 8
8 6 45 0 8
8 6 44 3 0
8 6 43 3 0
8 6 42 3 0
8 6 41 3 0
8 6 40 0 8
8 6 39 0 8
8 6 38 3 0
8 6 37 3 0
8 6 36 3 0
8 6 35 3 0
8 6 34 0 8
8 6 33 0 8
8 6 32 3 0
8 6 31 3 0
8 6 30 3 0
8 6 29 3 0
8 6 28 3 0
8 6 27 3 0
8 6 26 3 0
8 6 25 3 0
8 6 24 3 0
8 6 23 3 0
8 6 22 3 0
8 6 21 3 84
8 7 61 3 52
8 7 60 3 20
8 7 59 3 4
8 7 58 3 0
8 7 57 3 0
8 7 56 3 0
8 7 55 3 0
8 7 54 3 0
8 7 53 3 0
8 7 52 3 0
8 7 51 4 0
8 7 50 4 0
8 7 49 4 0
8 7 48 4 0
8 7 47 0 64
8 7 44 0 32
8 7 43 4 0
8 7 42 4 0
8 7 41 0 64
8 7 38 0 32
8 7 37 4 0
8 7 36 4 0
8 7 35 0 64
8 7 32 0 32
8 7 31 4 0
8 7 30 4 0
8 7 29 4 0
8 7 28 4 0
8 7 27 4 0
8 7 26 4 0
8 7 25 4 0
8 7 24 4 0
8 7 23 3 0
8 7 22 3 0
8 7 21 3 0
8 7 20 3 20
8 7 19 3 84
8 8 61 3 36
8 8 60 3 4
8 8 59 3 4
8 8 58 3 0
8 8 57 4 0
8 8 56 4 0
8 8 55 4 0
8 8 54 4 0
8 8 53 14 0
8 8 52 14 0
8 8 51 14 0
8 8 50 14 0
8 8 49 14 0
8 8 48 14 0
8 8 47 0 64
8 8 44 0 32
8 8 43 14 0
8 8 42 14 0
8 8 41 14 0
8 8 40 0 84
8 8 38 0 32
8 8 37 14 0
8 8 36 14 0
8 8 35 0 64
8 8 32 0 32
8 8 31 14 0
8 8 30 14 0
8 8 29 4 0
8 8 28 4 0
8 8 27 4 0
8 8 26 4 0
8 8 25 4 0
8 8 24 4 0
8 8 23 4 0
8 8 22 4 0
8 8 21 4 0
8 8 20 4 0
8 8 19 4 0
8 8 18 3 16
8 8 17 3 20
8 8 16 3 20
8 8 15 3 84
8 9 61 3 36
8 9 60 3 4
8 9 59 3 4
8 9 58 3 0
8 9 57 4 0
8 9 56 4 0
8 9 55 4 0
8 9 54 4 0
8 9 53 14 0
8 9 52 14 0
8 9 51 14 0
8 9 50 14 0
8 9 49 14 0
8 9 48 14 0
8 9 47 14 0
8 9 46 0 16
8 9 45 0 16
8 9 44 14 0
8 9 43 14 0
8 9 42 14 0
8 9 41 14 0
8 9 40 14 0
8 9 39 0 16
8 9 38 14 0
8 9 37 14 0
8 9 36 14 0
8 9 35 14 0
8 9 34 0 16
8 9 33 0 16
8 9 32 14 0
8 9 31 14 0
8 9 30 14 0
8 9 29 4 0
8 9 28 4 0
8 9 27 4 0
8 9 26 4 0
8 9 25 4 0
8 9 24 4 0
8 9 23 4 0
8 9 22 4 0
8 9 21 4 0
8 9 20 4 0
8 9 19 4 0
8 9 18 4 0
8 9 17 4 0
8 9 16 4 0
8 9 15 3 4
8 9 14 3 20
8 9 13 13 20
8 9 12 13 20
8 9 11 13 84
8 10 62 3 52
8 10 61 14 4
8 10 60 14 4
8 10 59 4 0
8 10 58 4 0
8 10 57 4 0
8 10 56 4 0
8 10 55 4 0
8 10 54 4 0
8 10 53 14 0
8 10 52 14 0
8 10 51 14 0
8 10 50 14 0
8 10 49 14 0
8 10 48 14 0
8 10 47 14 0
8 10 46 14 0
8 10 45 14 0
8 10 44 14 0
8 10 43 14 0
8 10 42 14 0
8 10 41 14 0
8 10 40 14 0
8 10 39 14 0
8 10 38 14 0
8 10 37 14 0
8 10 36 14 0
8 10 35 14 0
8 10 34 14 0
8 10 33 14 0
8 10 32 14 0
8 10 31 14 0
8 10 30 14 0
8 10 29 4 0
8 10 28 4 0
8 10 27 4 0
8 10 26 4 0
8 10 25 4 0
8 10 24 4 0
8 10 23 4 0
8 10 22 4 0
8 10 21 4 0
8 10 20 4 0
8 10 19 4 0
8 10 18 4 0
8 10 17 4 0
8 10 16 13 0
8 10 15 13 4
8 10 14 13 4
8 10 13 13 4
8 10 12 13 4
8 10 11 3 68
8 11 63 14 52
8 11 62 14 4
8 11 61 14 4
8 11 60 4 0
8 11 59 4 0
8 11 58 4 0
8 11 57 4 0
8 11 56 10 8
8 11 55 10 8
8 11 54 10 8
8 11 53 10 8
8 11 52 10 8
8 11 51 10 8
8 11 50 10 8
8 11 49 10 8
8 11 48 10 8
8 11 47 10 8
8 11 46 10 8
8 11 45 10 8
8 11 44 10 8
8 11 43 10 8
8 11 42 10 8
8 11 41 10 8
8 11 40 10 8
8 11 39 10 8
8 11 38 10 8
8 11 37 10 8
8 11 36 10 8
8 11 35 10 8
8 11 34 10 8
8 11 33 10 8
8 11 32 10 8
8 11 31 10 8
8 11 30 10 8
8 11 29 4 0
8 11 28 4 0
8 11 27 4 0
8 11 26 4 0
8 11 25 4 0
8 11 24 4 0
8 11 23 4 0
8 11 22 4 0
8 11 21 4 0
8 11 20 4 0
8 11 19 4 0
8 11 18 4 0
8 11 17 4 0
8 11 16 4 0
8 11 15 13 0
8 11 14 13 0
8 11 13 13 4
8 11 12 13 4
8 11 11 3 68
8 12 63 14 36
8 12 62 14 4
8 12 61 14 4
8 12 60 4 0
8 12 59 4 0
8 12 58 4 0
8 12 57 4 64
8 12 29 4 40
8 12 28 4 0
8 12 27 4 0
8 12 26 4 0
8 12 25 4 0
8 12 24 4 0
8 12 23 4 0
8 12 22 4 0
8 12 21 4 0
8 12 20 4 0
8 12 19 4 0
8 12 18 4 0
8 12 17 4 0
8 12 16 4 0
8 12 15 4 0
8 12 14 4 0
8 12 13 13 4
8 12 12 13 4
8 12 11 3 68
8 13 63 13 36
8 13 62 13 4
8 13 61 13 4
8 13 60 4 0
8 13 59 12 8
8 13 58 12 8
8 13 57 4 64
8 13 28 4 40
8 13 27 4 0
8 13 26 4 0
8 13 25 4 0
8 13 24 4 0
8 13 23 4 0
8 13 22 4 0
8 13 21 4 0
8 13 20 4 0
8 13 19 15 0
8 13 18 15 0
8 13 17 15 0
8 13 16 15 0
8 13 15 15 0
8 13 14 15 0
8 13 13 15 0
8 13 12 13 4
8 13 11 3 68
8 14 63 13 36
8 14 62 13 6
8 14 61 13 6
8 14 60 4 66
8 14 57 4 98
8 14 27 4 40
8 14 26 4 0
8 14 25 4 0
8 14 24 4 0
8 14 23 4 0
8 14 22 4 0
8 14 21 4 0
8 14 20 4 0
8 14 19 15 0
8 14 18 15 0
8 14 17 15 0
8 14 16 15 0
8 14 15 15 0
8 14 14 15 0
8 14 13 15 0
8 14 12 13 4
8 14 11 3 68
8 15 63 3 44
8 15 62 3 14
8 15 61 3 14
8 15 60 3 74
8 15 57 8 106
8 15 26 4 40
8 15 25 4 0
8 15 24 4 0
8 15 23 4 0
8 15 22 4 0
8 15 21 4 0
8 15 20 4 0
8 15 19 15 0
8 15 18 15 0
8 15 17 15 0
8 15 16 15 0
8 15 15 15 0
8 15 14 15 0
8 15 13 15 0
8 15 12 15 0
8 15 11 15 0
8 15 10 13 20
8 15 9 13 84
8 16 25 4 40
8 16 24 4 0
8 16 23 4 0
8 16 22 4 0
8 16 21 4 0
8 16 20 4 0
8 16 19 4 0
8 16 18 4 0
8 16 17 4 0
8 16 16 8 0
8 16 15 8 0
8 16 14 8 0
8 16 13 8 0
8 16 12 3 4
8 16 11 3 4
8 16 10 3 4
8 16 9 3 68
8 17 24 4 32
8 17 23 4 0
8 17 22 4 0
8 17 21 4 0
8 17 20 4 0
8 17 19 3 0
8 17 18 3 0
8 17 17 3 0
8 17 16 3 0
8 17 15 3 0
8 17 14 3 0
8 17 13 3 4
8 17 12 3 4
8 17 11 3 4
8 17 10 3 12
8 17 9 3 76
8 18 24 8 46
8 18 23 8 14
8 18 22 8 14
8 18 21 8 14
8 18 20 8 14
8 18 19 8 14
8 18 18 8 14
8 18 17 8 14
8 18 16 8 14
8 18 15 8 14
8 18 14 8 14
8 18 13 8 14
8 18 12 8 14
8 18 11 8 76
9 3 56 7 52
9 3 55 7 20
9 3 54 7 20
9 3 53 7 20
9 3 52 7 20
9 3 51 7 20
9 3 50 7 20
9 3 49 7 20
9 3 48 7 20
9 3 47 7 20
9 3 46 7 20
9 3 45 7 20
9 3 44 7 20
9 3 43 7 20
9 3 42 7 20
9 3 41 7 20
9 3 40 7 20
9 3 39 7 20
9 3 38 7 20
9 3 37 7 20
9 3 36 7 20
9 3 35 7 20
9 3 34 7 20
9 3 33 7 20
9 3 32 7 20
9 3 31 7 20
9 3 30 7 20
9 3 29 7 20
9 3 28 7 20
9 3 27 7 20
9 3 26 7 20
9 3 25 7 20
9 3 24 7 20
9 3 23 7 84
9 4 57 3 48
9 4 56 3 0
9 4 55 3 0
9 4 54 3 0
9 4 53 3 0
9 4 52 3 0
9 4 51 10 0
9 4 50 10 0
9 4 49 3 0
9 4 48 3 0
9 4 47 3 0
9 4 46 3 0
9 4 45 3 0
9 4 44 3 0
9 4 43 3 0
9 4 42 3 0
9 4 41 3 0
9 4 40 3 0
9 4 39 3 0
9 4 38 3 0
9 4 37 3 0
9 4 36 3 0
9 4 35 3 0
9 4 34 3 0
9 4 33 3 0
9 4 32 3 0
9 4 31 3 0
9 4 30 3 0
9 4 29 3 0
9 4 28 3 0
9 4 27 3 0
9 4 26 3 0
9 4 25 3 0
9 4 24 3 0
9 4 23 3 64
9 5 58 3 48
9 5 57 3 0
9 5 56 4 0
9 5 55 4 0
9 5 54 4 0
9 5 53 4 0
9 5 52 4 0
9 5 51 10 0
9 5 50 10 0
9 5 49 4 0
9 5 48 4 0
9 5 47 4 0
9 5 46 4 0
9 5 45 4 0
9 5 44 4 0
9 5 43 4 0
9 5 42 4 0
9 5 41 4 0
9 5 40 4 0
9 5 39 4 0
9 5 38 4 0
9 5 37 4 0
9 5 36 4 0
9 5 35 4 0
9 5 34 4 0
9 5 33 4 0
9 5 32 4 0
9 5 31 4 0
9 5 30 4 0
9 5 29 4 0
9 5 28 4 0
9 5 27 4 0
9 5 26 4 0
9 5 25 4 0
9 5 24 4 0
9 5 23 3 64
9 6 59 3 48
9 6 58 3 0
9 6 57 4 0
9 6 56 4 0
9 6 55 4 0
9 6 54 4 0
9 6 53 4 0
9 6 52 4 0
9 6 51 10 0
9 6 50 10 0
9 6 49 4 0
9 6 48 4 0
9 6 47 4 0
9 6 46 4 0
9 6 45 4 0
9 6 44 4 0
9 6 43 4 0
9 6 42 4 0
9 6 41 4 0
9 6 40 0 8
9 6 39 0 8
9 6 38 4 0
9 6 37 4 0
9 6 36 4 0
9 6 35 4 0
9 6 34 0 8
9 6 33 0 8
9 6 32 4 0
9 6 31 4 0
9 6 30 4 0
9 6 29 4 0
9 6 28 4 0
9 6 27 4 0
9 6 26 4 0
9 6 25 4 0
9 6 24 4 0
9 6 23 4 0
9 6 22 3 16
9 6 21 3 16
9 6 20 3 84
9 7 61 3 48
9 7 60 3 16
9 7 59 3 0
9 7 58 4 0
9 7 57 4 0
9 7 56 4 0
9 7 55 4 0
9 7 54 4 0
9 7 53 4 0
9 7 52 4 0
9 7 51 10 0
9 7 50 10 0
9 7 49 4 0
9 7 48 4 0
9 7 47 4 0
9 7 46 0 4
9 7 45 0 12
9 7 44 4 0
9 7 43 4 0
9 7 42 4 0
9 7 41 0 64
9 7 38 0 32
9 7 37 4 0
9 7 36 4 0
9 7 35 0 64
9 7 32 0 32
9 7 31 4 0
9 7 30 4 0
9 7 29 4 0
9 7 28 4 0
9 7 27 4 0
9 7 26 4 0
9 7 25 4 0
9 7 24 4 0
9 7 23 4 0
9 7 22 4 0
9 7 21 4 0
9 7 20 4 0
9 7 19 3 16
9 7 18 3 84
9 8 63 3 52
9 8 62 3 20
9 8 61 3 0
9 8 60 3 0
9 8 59 4 0
9 8 58 4 0
9 8 57 4 0
9 8 56 4 0
9 8 55 4 0
9 8 54 4 0
9 8 53 14 0
9 8 52 14 0
9 8 51 10 0
9 8 50 10 0
9 8 49 14 0
9 8 48 14 0
9 8 47 14 0
9 8 46 0 68
9 8 44 0 32
9 8 43 14 0
9 8 42 14 0
9 8 41 14 0
9 8 40 0 16
9 8 39 0 20
9 8 38 14 0
9 8 37 14 0
9 8 36 14 0
9 8 35 0 64
9 8 32 0 32
9 8 31 14 0
9 8 30 14 0
9 8 29 4 0
9 8 28 4 0
9 8 27 4 0
9 8 26 4 0
9 8 25 4 0
9 8 24 4 0
9 8 23 4 0
9 8 22 4 0
9 8 21 4 0
9 8 20 4 0
9 8 19 4 0
9 8 18 4 0
9 8 17 3 16
9 8 16 3 16
9 8 15 3 16
9 8 14 3 84
9 9 63 3 36
9 9 62 3 4
9 9 61 4 0
9 9 60 4 0
9 9 59 4 0
9 9 58 4 0
9 9 57 4 0
9 9 56 4 0
9 9 55 4 0
9 9 54 4 0
9 9 53 14 0
9 9 52 10 0
9 9 51 10 0
9 9 50 10 0
9 9 49 14 0
9 9 48 14 0
9 9 47 14 0
9 9 46 14 0
9 9 45 0 16
9 9 44 14 0
9 9 43 14 0
9 9 42 14 0
9 9 41 14 0
9 9 40 14 0
9 9 39 14 0
9 9 38 14 0
9 9 37 14 0
9 9 36 14 0
9 9 35 14 0
9 9 34 0 16
9 9 33 0 16
9 9 32 14 0
9 9 31 14 0
9 9 30 14 0
9 9 29 4 0
9 9 28 4 0
9 9 27 4 0
9 9 26 4 0
9 9 25 4 0
9 9 24 4 0
9 9 23 4 0
9 9 22 4 0
9 9 21 4 0
9 9 20 4 0
9 9 19 4 0
9 9 18 4 0
9 9 17 4 0
9 9 16 4 0
9 9 15 4 0
9 9 14 4 0
9 9 13 13 16
9 9 12 13 16
9 9 11 13 80
9 10 64 3 52
9 10 63 3 4
9 10 62 4 0
9 10 61 4 0
9 10 60 4 0
9 10 59 4 0
9 10 58 4 0
9 10 57 4 0
9 10 56 4 0
9 10 55 4 0
9 10 54 4 0
9 10 53 14 0
9 10 52 10 0
9 10 51 10 0
9 10 50 10 0
9 10 49 14 0
9 10 48 14 0
9 10 47 14 0
9 10 46 14 0
9 10 45 14 0
9 10 44 14 0
9 10 43 14 0
9 10 42 14 0
9 10 41 14 0
9 10 40 14 0
9 10 39 14 0
9 10 38 14 0
9 10 37 14 0
9 10 36 14 0
9 10 35 14 0
9 10 34 14 0
9 10 33 14 0
9 10 32 14 0
9 10 31 14 0
9 10 30 14 0
9 10 29 4 0
9 10 28 4 0
9 10 27 4 0
9 10 26 4 0
9 10 25 4 0
9 10 24 4 0
9 10 23 4 0
9 10 22 4 0
9 10 21 4 0
9 10 20 4 0
9 10 19 4 0
9 10 18 4 0
9 10 17 4 0
9 10 16 4 0
9 10 15 4 0
9 10 14 4 0
9 10 13 4 0
9 10 12 4 0
9 10 11 3 64
9 11 65 14 52
9 11 64 14 4
9 11 63 4 0
9 11 62 4 0
9 11 61 4 0
9 11 60 4 0
9 11 59 4 0
9 11 58 4 0
9 11 57 4 0
9 11 56 10 0
9 11 55 10 8
9 11 54 10 8
9 11 53 10 8
9 11 52 10 8
9 11 51 10 8
9 11 50 10 8
9 11 49 10 8
9 11 48 10 8
9 11 47 10 8
9 11 46 10 8
9 11 45 10 8
9 11 44 10 8
9 11 43 10 8
9 11 42 10 8
9 11 41 10 8
9 11 40 10 8
9 11 39 10 8
9 11 38 10 8
9 11 37 10 8
9 11 36 10 8
9 11 35 10 8
9 11 34 10 8
9 11 33 10 8
9 11 32 10 8
9 11 31 10 8
9 11 30 10 8
9 11 29 4 0
9 11 28 4 0
9 11 27 4 0
9 11 26 4 0
9 11 25 4 0
9 11 24 4 0
9 11 23 4 0
9 11 22 4 0
9 11 21 4 0
9 11 20 4 0
9 11 19 4 0
9 11 18 4 0
9 11 17 4 0
9 11 16 4 0
9 11 15 4 0
9 11 14 4 0
9 11 13 4 0
9 11 12 4 0
9 11 11 20 64
9 12 65 14 36
9 12 64 14 4
9 12 63 4 0
9 12 62 4 0
9 12 61 4 0
9 12 60 4 0
9 12 59 4 0
9 12 58 4 0
9 12 57 11 0
9 12 56 7 76
9 12 29 5 40
9 12 28 4 0
9 12 27 4 0
9 12 26 4 0
9 12 25 4 0
9 12 24 4 0
9 12 23 4 0
9 12 22 4 0
9 12 21 4 0
9 12 20 4 0
9 12 19 4 0
9 12 18 4 0
9 12 17 4 0
9 12 16 4 0
9 12 15 4 0
9 12 14 4 0
9 12 13 4 0
9 12 12 4 0
9 12 11 20 64
9 13 65 13 36
9 13 64 13 4
9 13 63 4 0
9 13 62 11 8
9 13 61 12 8
9 13 60 12 8
9 13 59 11 8
9 13 58 11 8
9 13 57 7 72
9 13 28 5 40
9 13 27 4 0
9 13 26 4 0
9 13 25 4 0
9 13 24 4 0
9 13 23 4 0
9 13 22 4 0
9 13 21 4 0
9 13 20 4 0
9 13 19 15 0
9 13 18 15 0
9 13 17 15 0
9 13 16 15 0
9 13 15 15 0
9 13 14 15 0
9 13 13 15 0
9 13 12 15 0
9 13 11 20 64
9 14 65 13 36
9 14 64 13 6
9 14 63 4 66
9 14 27 5 40
9 14 26 4 0
9 14 25 4 0
9 14 24 4 0
9 14 23 4 0
9 14 22 4 0
9 14 21 4 0
9 14 20 4 0
9 14 19 15 0
9 14 18 15 0
9 14 17 15 0
9 14 16 15 0
9 14 15 15 0
9 14 14 15 0
9 14 13 15 0
9 14 12 15 0
9 14 11 20 64
9 15 65 3 44
9 15 64 3 14
9 15 63 4 74
9 15 26 5 40
9 15 25 4 0
9 15 24 4 0
9 15 23 4 0
9 15 22 4 0
9 15 21 4 0
9 15 20 4 0
9 15 19 15 0
9 15 18 15 0
9 15 17 15 0
9 15 16 15 0
9 15 15 15 0
9 15 14 15 0
9 15 13 15 0
9 15 12 15 0
9 15 11 15 0
9 15 10 13 16
9 15 9 13 80
9 16 25 5 40
9 16 24 4 0
9 16 23 4 0
9 16 22 4 0
9 16 21 8 0
9 16 20 8 0
9 16 19 8 0
9 16 18 8 0
9 16 17 8 0
9 16 16 8 0
9 16 15 8 0
9 16 14 8 0
9 16 13 8 0
9 16 12 8 0
9 16 11 8 0
9 16 10 8 0
9 16 9 3 64
9 17 24 5 40
9 17 23 10 8
9 17 22 10 8
9 17 21 10 8
9 17 20 10 8
9 17 19 10 8
9 17 18 10 8
9 17 17 10 8
9 17 16 10 8
9 17 15 10 8
9 17 14 10 8
9 17 13 10 8
9 17 12 10 8
9 17 11 8 0
9 17 10 8 0
9 17 9 3 72
9 18 11 8 40
9 18 10 8 76
10 3 56 7 48
10 3 55 7 16
10 3 54 7 16
10 3 53 7 16
10 3 52 7 16
10 3 51 7 16
10 3 50 7 16
10 3 49 7 16
10 3 48 7 16
10 3 47 7 16
10 3 46 7 16
10 3 45 7 16
10 3 44 7 16
10 3 43 7 16
10 3 42 7 16
10 3 41 7 16
10 3 40 7 16
10 3 39 7 16
10 3 38 7 16
10 3 37 7 16
10 3 36 7 16
10 3 35 7 16
10 3 34 7 16
10 3 33 7 16
10 3 32 7 16
10 3 31 7 16
10 3 30 7 16
10 3 29 7 16
10 3 28 7 16
10 3 27 7 16
10 3 26 7 16
10 3 25 7 16
10 3 24 7 16
10 3 23 7 16
10 3 22 7 84
10 4 57 7 48
10 4 56 4 0
10 4 55 4 0
10 4 54 4 0
10 4 53 4 0
10 4 52 4 0
10 4 51 10 0
10 4 50 10 0
10 4 49 10 0
10 4 48 10 0
10 4 47 10 0
10 4 46 10 0
10 4 45 10 0
10 4 44 10 0
10 4 43 10 0
10 4 42 10 0
10 4 41 10 0
10 4 40 10 0
10 4 39 10 0
10 4 38 4 0
10 4 37 4 0
10 4 36 4 0
10 4 35 4 0
10 4 34 4 0
10 4 33 4 0
10 4 32 4 0
10 4 31 4 0
10 4 30 4 0
10 4 29 4 0
10 4 28 4 0
10 4 27 4 0
10 4 26 4 0
10 4 25 4 0
10 4 24 4 0
10 4 23 4 0
10 4 22 3 4
10 4 21 7 84
10 5 60 7 52
10 5 59 3 20
10 5 58 3 16
10 5 57 4 0
10 5 56 4 0
10 5 55 4 0
10 5 54 4 0
10 5 53 4 0
10 5 52 4 0
10 5 51 10 0
10 5 50 10 0
10 5 49 10 0
10 5 48 10 0
10 5 47 10 0
10 5 46 10 0
10 5 45 10 0
10 5 44 10 0
10 5 43 10 0
10 5 42 10 0
10 5 41 10 0
10 5 40 10 0
10 5 39 10 0
10 5 38 4 0
10 5 37 4 0
10 5 36 4 0
10 5 35 4 0
10 5 34 4 0
10 5 33 4 0
10 5 32 4 0
10 5 31 4 0
10 5 30 4 0
10 5 29 4 0
10 5 28 4 0
10 5 27 4 0
10 5 26 4 0
10 5 25 4 0
10 5 24 4 0
10 5 23 4 0
10 5 22 3 4
10 5 21 3 4
10 5 20 3 84
10 6 63 3 52
10 6 62 3 20
10 6 61 3 20
10 6 60 3 4
10 6 59 3 0
10 6 58 4 0
10 6 57 4 0
10 6 56 4 0
10 6 55 4 0
10 6 54 4 0
10 6 53 4 0
10 6 52 4 0
10 6 51 10 0
10 6 50 10 0
10 6 49 10 0
10 6 48 10 0
10 6 47 10 0
10 6 46 10 0
10 6 45 10 0
10 6 44 10 0
10 6 43 10 0
10 6 42 10 0
10 6 41 10 0
10 6 40 10 0
10 6 39 10 0
10 6 38 4 0
10 6 37 4 0
10 6 36 4 0
10 6 35 4 0
10 6 34 0 8
10 6 33 0 8
10 6 32 4 0
10 6 31 4 0
10 6 30 4 0
10 6 29 4 0
10 6 28 4 0
10 6 27 4 0
10 6 26 4 0
10 6 25 4 0
10 6 24 4 0
10 6 23 4 0
10 6 22 4 0
10 6 21 4 0
10 6 20 4 0
10 6 19 3 20
10 6 18 3 84
10 7 64 3 52
10 7 63 3 4
10 7 62 3 4
10 7 61 4 0
10 7 60 4 0
10 7 59 4 0
10 7 58 4 0
10 7 57 4 0
10 7 56 4 0
10 7 55 4 0
10 7 54 4 0
10 7 53 4 0
10 7 52 4 0
10 7 51 10 0
10 7 50 10 0
10 7 49 10 0
10 7 48 10 0
10 7 47 10 0
10 7 46 0 0
10 7 45 0 8
10 7 44 10 0
10 7 43 10 0
10 7 42 10 0
10 7 41 10 0
10 7 40 0 4
10 7 39 0 4
10 7 38 4 0
10 7 37 4 0
10 7 36 4 0
10 7 35 0 64
10 7 32 0 32
10 7 31 4 0
10 7 30 4 0
10 7 29 4 0
10 7 28 4 0
10 7 27 4 0
10 7 26 4 0
10 7 25 4 0
10 7 24 4 0
10 7 23 4 0
10 7 22 4 0
10 7 21 4 0
10 7 20 4 0
10 7 19 4 0
10 7 18 4 0
10 7 17 3 20
10 7 16 3 84
10 8 65 3 52
10 8 64 3 4
10 8 63 3 0
10 8 62 3 0
10 8 61 4 0
10 8 60 4 0
10 8 59 4 0
10 8 58 4 0
10 8 57 4 0
10 8 56 4 0
10 8 55 4 0
10 8 54 4 0
10 8 53 14 0
10 8 52 10 0
10 8 51 10 0
10 8 50 10 0
10 8 49 10 0
10 8 48 10 0
10 8 47 10 0
10 8 46 0 64
10 8 44 0 32
10 8 43 10 0
10 8 42 10 0
10 8 41 10 0
10 8 40 0 0
10 8 39 0 0
10 8 38 14 0
10 8 37 14 0
10 8 36 14 0
10 8 35 0 64
10 8 32 0 32
10 8 31 14 0
10 8 30 14 0
10 8 29 4 0
10 8 28 4 0
10 8 27 4 0
10 8 26 4 0
10 8 25 4 0
10 8 24 4 0
10 8 23 4 0
10 8 22 4 0
10 8 21 4 0
10 8 20 4 0
10 8 19 4 0
10 8 18 4 0
10 8 17 4 0
10 8 16 4 0
10 8 15 3 16
10 8 14 3 16
10 8 13 13 84
10 9 66 3 52
10 9 65 3 4
10 9 64 3 4
10 9 63 4 0
10 9 62 4 0
10 9 61 4 0
10 9 60 4 0
10 9 59 4 0
10 9 58 4 0
10 9 57 4 0
10 9 56 4 0
10 9 55 4 0
10 9 54 4 0
10 9 53 14 0
10 9 52 10 0
10 9 51 10 0
10 9 50 10 0
10 9 49 10 0
10 9 48 10 0
10 9 47 10 0
10 9 46 10 0
10 9 45 0 16
10 9 44 10 0
10 9 43 10 0
10 9 42 10 0
10 9 41 10 0
10 9 40 10 0
10 9 39 10 0
10 9 38 14 0
10 9 37 14 0
10 9 36 14 0
10 9 35 14 0
10 9 34 0 16
10 9 33 0 16
10 9 32 14 0
10 9 31 14 0
10 9 30 14 0
10 9 29 4 0
10 9 28 4 0
10 9 27 4 0
10 9 26 4 0
10 9 25 4 0
10 9 24 4 0
10 9 23 4 0
10 9 22 4 0
10 9 21 4 0
10 9 20 4 0
10 9 19 4 0
10 9 18 4 0
10 9 17 4 0
10 9 16 4 0
10 9 15 4 0
10 9 14 4 0
10 9 13 13 0
10 9 12 13 16
10 9 11 13 80
10 10 67 3 52
10 10 66 3 4
10 10 65 3 4
10 10 64 4 0
10 10 63 4 0
10 10 62 4 0
10 10 61 4 0
10 10 60 4 0
10 10 59 4 0
10 10 58 4 0
10 10 57 4 0
10 10 56 4 0
10 10 55 4 0
10 10 54 4 0
10 10 53 14 0
10 10 52 10 0
10 10 51 10 0
10 10 50 10 0
10 10 49 10 0
10 10 48 10 0
10 10 47 10 0
10 10 46 10 0
10 10 45 10 0
10 10 44 10 0
10 10 43 10 0
10 10 42 10 0
10 10 41 10 0
10 10 40 10 0
10 10 39 10 0
10 10 38 14 0
10 10 37 14 0
10 10 36 14 0
10 10 35 14 0
10 10 34 14 0
10 10 33 14 0
10 10 32 14 0
10 10 31 14 0
10 10 30 14 0
10 10 29 4 0
10 10 28 4 0
10 10 27 4 0
10 10 26 4 0
10 10 25 4 0
10 10 24 4 0
10 10 23 4 0
10 10 22 4 0
10 10 21 4 0
10 10 20 4 0
10 10 19 4 0
10 10 18 4 0
10 10 17 4 0
10 10 16 4 0
10 10 15 4 0
10 10 14 4 0
10 10 13 4 0
10 10 12 4 0
10 10 11 3 64
10 11 69 3 62
10 11 68 3 28
10 11 67 3 4
10 11 66 3 4
10 11 65 4 0
10 11 64 4 0
10 11 63 4 0
10 11 62 4 0
10 11 61 4 0
10 11 60 4 0
10 11 59 4 0
10 11 58 4 0
10 11 57 4 0
10 11 56 10 0
10 11 55 12 8
10 11 54 12 8
10 11 53 12 8
10 11 52 12 8
10 11 51 12 8
10 11 50 12 8
10 11 49 12 8
10 11 48 12 8
10 11 47 12 8
10 11 46 10 8
10 11 45 10 8
10 11 44 10 8
10 11 43 10 8
10 11 42 12 8
10 11 41 12 8
10 11 40 12 8
10 11 39 12 8
10 11 38 12 8
10 11 37 12 8
10 11 36 12 8
10 11 35 10 8
10 11 34 10 8
10 11 33 10 8
10 11 32 10 8
10 11 31 10 8
10 11 30 10 8
10 11 29 4 0
10 11 28 4 0
10 11 27 4 0
10 11 26 4 0
10 11 25 4 0
10 11 24 4 0
10 11 23 4 0
10 11 22 4 0
10 11 21 4 0
10 11 20 4 0
10 11 19 4 0
10 11 18 4 0
10 11 17 4 0
10 11 16 4 0
10 11 15 4 0
10 11 14 4 0
10 11 13 4 0
10 11 12 4 0
10 11 11 3 64
10 12 67 13 36
10 12 66 13 4
10 12 65 4 0
10 12 64 4 0
10 12 63 4 0
10 12 62 4 0
10 12 61 4 0
10 12 60 4 0
10 12 59 4 0
10 12 58 4 0
10 12 57 4 0
10 12 56 7 72
10 12 29 5 40
10 12 28 4 0
10 12 27 4 0
10 12 26 4 0
10 12 25 4 0
10 12 24 4 0
10 12 23 4 0
10 12 22 4 0
10 12 21 4 0
10 12 20 4 0
10 12 19 4 0
10 12 18 4 0
10 12 17 4 0
10 12 16 4 0
10 12 15 4 0
10 12 14 4 0
10 12 13 4 0
10 12 12 4 0
10 12 11 3 64
10 13 67 13 36
10 13 66 13 4
10 13 65 4 0
10 13 64 11 8
10 13 63 12 8
10 13 62 12 8
10 13 61 11 8
10 13 60 11 8
10 13 59 11 8
10 13 58 11 8
10 13 57 7 72
10 13 28 5 42
10 13 27 4 2
10 13 26 4 0
10 13 25 4 0
10 13 24 4 0
10 13 23 4 0
10 13 22 4 0
10 13 21 4 0
10 13 20 4 0
10 13 19 15 0
10 13 18 15 0
10 13 17 15 0
10 13 16 15 0
10 13 15 15 0
10 13 14 15 0
10 13 13 15 0
10 13 12 15 0
10 13 11 3 64
10 14 67 13 38
10 14 66 13 6
10 14 65 4 66
10 14 27 5 42
10 14 26 4 0
10 14 25 4 0
10 14 24 4 0
10 14 23 4 0
10 14 22 4 0
10 14 21 4 0
10 14 20 4 0
10 14 19 15 0
10 14 18 15 0
10 14 17 15 0
10 14 16 15 0
10 14 15 15 0
10 14 14 15 0
10 14 13 15 0
10 14 12 15 0
10 14 11 3 64
10 15 67 13 36
10 15 66 13 6
10 15 65 4 74
10 15 26 5 40
10 15 25 4 0
10 15 24 4 0
10 15 23 4 0
10 15 22 4 0
10 15 21 4 0
10 15 20 4 0
10 15 19 15 0
10 15 18 15 0
10 15 17 15 0
10 15 16 15 0
10 15 15 15 0
10 15 14 15 0
10 15 13 15 0
10 15 12 15 0
10 15 11 15 0
10 15 10 13 16
10 15 9 13 80
10 16 67 3 46
10 16 66 3 78
10 16 25 5 40
10 16 24 8 0
10 16 23 8 0
10 16 22 8 0
10 16 21 8 0
10 16 20 8 0
10 16 19 8 0
10 16 18 8 0
10 16 17 8 0
10 16 16 8 0
10 16 15 8 0
10 16 14 8 0
10 16 13 8 0
10 16 12 8 0
10 16 11 8 0
10 16 10 8 0
10 16 9 3 64
10 17 24 5 40
10 17 23 10 8
10 17 22 12 8
10 17 21 12 8
10 17 20 12 8
10 17 19 12 8
10 17 18 12 8
10 17 17 12 8
10 17 16 12 8
10 17 15 12 8
10 17 14 12 8
10 17 13 10 8
10 17 12 10 8
10 17 11 8 0
10 17 10 8 0
10 17 9 3 72
10 18 11 8 40
10 18 10 8 72
11 3 56 7 48
11 3 55 7 16
11 3 54 7 16
11 3 53 7 16
11 3 52 7 16
11 3 51 7 16
11 3 50 7 16
11 3 49 7 16
11 3 48 7 16
11 3 47 7 16
11 3 46 7 16
11 3 45 7 16
11 3 44 7 16
11 3 43 7 16
11 3 42 7 16
11 3 41 7 16
11 3 40 7 16
11 3 39 7 16
11 3 38 7 16
11 3 37 7 16
11 3 36 7 16
11 3 35 7 16
11 3 34 7 16
11 3 33 7 16
11 3 32 7 16
11 3 31 7 16
11 3 30 7 16
11 3 29 7 16
11 3 28 7 16
11 3 27 7 16
11 3 26 7 16
11 3 25 7 16
11 3 24 7 16
11 3 23 7 16
11 3 22 7 16
11 3 21 7 84
11 4 59 7 52
11 4 58 7 20
11 4 57 7 16
11 4 56 4 0
11 4 55 4 0
11 4 54 4 0
11 4 53 4 0
11 4 52 4 0
11 4 51 10 0
11 4 50 10 0
11 4 49 10 0
11 4 48 10 0
11 4 47 10 0
11 4 46 10 0
11 4 45 10 0
11 4 44 10 0
11 4 43 10 0
11 4 42 10 0
11 4 41 10 0
11 4 40 10 0
11 4 39 10 0
11 4 38 10 0
11 4 37 10 0
11 4 36 10 0
11 4 35 10 0
11 4 34 10 0
11 4 33 10 0
11 4 32 10 0
11 4 31 10 0
11 4 30 10 0
11 4 29 4 0
11 4 28 4 0
11 4 27 4 0
11 4 26 4 0
11 4 25 4 0
11 4 24 4 0
11 4 23 4 0
11 4 22 4 0
11 4 21 4 0
11 4 20 7 84
11 5 62 7 52
11 5 61 7 20
11 5 60 7 16
11 5 59 4 0
11 5 58 4 0
11 5 57 4 0
11 5 56 4 0
11 5 55 4 0
11 5 54 4 0
11 5 53 4 0
11 5 52 4 0
11 5 51 10 0
11 5 50 10 0
11 5 49 10 0
11 5 48 10 0
11 5 47 10 0
11 5 46 10 0
11 5 45 10 0
11 5 44 10 0
11 5 43 10 0
11 5 42 10 0
11 5 41 10 0
11 5 40 10 0
11 5 39 10 0
11 5 38 10 0
11 5 37 10 0
11 5 36 10 0
11 5 35 10 0
11 5 34 10 0
11 5 33 10 0
11 5 32 10 0
11 5 31 10 0
11 5 30 10 0
11 5 29 4 0
11 5 28 4 0
11 5 27 4 0
11 5 26 4 0
11 5 25 4 0
11 5 24 4 0
11 5 23 4 0
11 5 22 4 0
11 5 21 4 0
11 5 20 4 0
11 5 19 3 84
11 6 64 7 52
11 6 63 4 16
11 6 62 4 0
11 6 61 4 0
11 6 60 4 0
11 6 59 4 0
11 6 58 4 0
11 6 57 4 0
11 6 56 4 0
11 6 55 4 0
11 6 54 4 0
11 6 53 4 0
11 6 52 4 0
11 6 51 10 0
11 6 50 10 0
11 6 49 10 0
11 6 48 10 0
11 6 47 10 0
11 6 46 10 0
11 6 45 10 0
11 6 44 10 0
11 6 43 10 0
11 6 42 10 0
11 6 41 10 0
11 6 40 10 0
11 6 39 10 0
11 6 38 10 0
11 6 37 10 0
11 6 36 10 0
11 6 35 10 0
11 6 34 0 8
11 6 33 0 8
11 6 32 10 0
11 6 31 10 0
11 6 30 10 0
11 6 29 4 0
11 6 28 4 0
11 6 27 4 0
11 6 26 4 0
11 6 25 4 0
11 6 24 4 0
11 6 23 4 0
11 6 22 4 0
11 6 21 4 0
11 6 20 4 0
11 6 19 4 0
11 6 18 3 16
11 6 17 3 84
11 7 66 3 52
11 7 65 3 20
11 7 64 4 0
11 7 63 4 0
11 7 62 4 0
11 7 61 4 0
11 7 60 4 0
11 7 59 4 0
11 7 58 4 0
11 7 57 4 0
11 7 56 4 0
11 7 55 4 0
11 7 54 4 0
11 7 53 4 0
11 7 52 10 0
11 7 51 10 0
11 7 50 10 0
11 7 49 10 0
11 7 48 10 0
11 7 47 10 0
11 7 46 0 0
11 7 45 0 0
11 7 44 10 0
11 7 43 10 0
11 7 42 10 0
11 7 41 10 0
11 7 40 10 0
11 7 39 10 0
11 7 38 10 0
11 7 37 10 0
11 7 36 10 0
11 7 35 0 64
11 7 32 0 32
11 7 31 10 0
11 7 30 10 0
11 7 29 4 0
11 7 28 4 0
11 7 27 4 0
11 7 26 4 0
11 7 25 4 0
11 7 24 4 0
11 7 23 4 0
11 7 22 4 0
11 7 21 4 0
11 7 20 4 0
11 7 19 4 0
11 7 18 4 0
11 7 17 4 0
11 7 16 3 16
11 7 15 3 84
11 8 66 3 36
11 8 65 3 0
11 8 64 3 0
11 8 63 3 0
11 8 62 4 0
11 8 61 4 0
11 8 60 4 0
11 8 59 4 0
11 8 58 4 0
11 8 57 4 0
11 8 56 4 0
11 8 55 4 0
11 8 54 4 0
11 8 53 14 0
11 8 52 10 0
11 8 51 10 0
11 8 50 10 0
11 8 49 10 0
11 8 48 10 0
11 8 47 10 0
11 8 46 0 0
11 8 45 0 4
11 8 44 10 0
11 8 43 10 0
11 8 42 10 0
11 8 41 10 0
11 8 40 10 0
11 8 39 10 0
11 8 38 10 0
11 8 37 10 0
11 8 36 10 0
11 8 35 0 64
11 8 32 0 32
11 8 31 10 0
11 8 30 10 0
11 8 29 4 0
11 8 28 4 0
11 8 27 4 0
11 8 26 4 0
11 8 25 4 0
11 8 24 4 0
11 8 23 4 0
11 8 22 4 0
11 8 21 4 0
11 8 20 4 0
11 8 19 4 0
11 8 18 4 0
11 8 17 4 0
11 8 16 4 0
11 8 15 4 0
11 8 14 3 16
11 8 13 13 80
11 9 67 3 52
11 9 66 3 0
11 9 65 4 0
11 9 64 4 0
11 9 63 4 0
11 9 62 4 0
11 9 61 4 0
11 9 60 4 0
11 9 59 4 0
11 9 58 4 0
11 9 57 4 0
11 9 56 4 0
11 9 55 4 0
11 9 54 4 0
11 9 53 14 0
11 9 52 10 0
11 9 51 10 0
11 9 50 10 0
11 9 49 10 0
11 9 48 10 0
11 9 47 10 0
11 9 46 10 0
11 9 45 10 0
11 9 44 10 0
11 9 43 10 0
11 9 42 10 0
11 9 41 10 0
11 9 40 10 0
11 9 39 10 0
11 9 38 10 0
11 9 37 10 0
11 9 36 10 0
11 9 35 10 0
11 9 34 0 16
11 9 33 0 16
11 9 32 10 0
11 9 31 10 0
11 9 30 10 0
11 9 29 4 0
11 9 28 4 0
11 9 27 4 0
11 9 26 4 0
11 9 25 4 0
11 9 24 4 0
11 9 23 4 0
11 9 22 4 0
11 9 21 4 0
11 9 20 4 0
11 9 19 4 0
11 9 18 4 0
11 9 17 4 0
11 9 16 4 0
11 9 15 4 0
11 9 14 4 0
11 9 13 13 0
11 9 12 13 16
11 9 11 13 80
11 10 69 3 60
11 10 68 3 20
11 10 67 4 0
11 10 66 4 0
11 10 65 4 0
11 10 64 4 0
11 10 63 4 0
11 10 62 4 0
11 10 61 4 0
11 10 60 4 0
11 10 59 4 0
11 10 58 4 0
11 10 57 4 0
11 10 56 4 0
11 10 55 4 0
11 10 54 4 0
11 10 53 14 0
11 10 52 10 0
11 10 51 10 0
11 10 50 10 0
11 10 49 10 0
11 10 48 10 0
11 10 47 10 0
11 10 46 10 0
11 10 45 10 0
11 10 44 10 0
11 10 43 10 0
11 10 42 10 0
11 10 41 10 0
11 10 40 10 0
11 10 39 10 0
11 10 38 10 0
11 10 37 10 0
11 10 36 10 0
11 10 35 10 2
11 10 34 10 2
11 10 33 10 2
11 10 32 10 0
11 10 31 10 0
11 10 30 10 0
11 10 29 4 0
11 10 28 4 0
11 10 27 4 0
11 10 26 4 0
11 10 25 4 0
11 10 24 4 0
11 10 23 4 0
11 10 22 4 0
11 10 21 4 0
11 10 20 4 0
11 10 19 4 0
11 10 18 4 0
11 10 17 4 0
11 10 16 4 0
11 10 15 4 0
11 10 14 4 0
11 10 13 4 0
11 10 12 4 0
11 10 11 4 0
11 10 10 3 84
11 11 71 3 62
11 11 70 3 94
11 11 68 13 32
11 11 67 4 0
11 11 66 4 0
11 11 65 4 0
11 11 64 4 0
11 11 63 4 0
11 11 62 4 0
11 11 61 4 0
11 11 60 4 0
11 11 59 4 0
11 11 58 4 0
11 11 57 4 0
11 11 56 10 0
11 11 55 10 8
11 11 54 10 8
11 11 53 10 8
11 11 52 10 8
11 11 51 10 8
11 11 50 10 8
11 11 49 10 8
11 11 48 10 8
11 11 47 10 8
11 11 46 10 8
11 11 45 10 8
11 11 44 10 8
11 11 43 10 8
11 11 42 10 8
11 11 41 10 8
11 11 40 10 8
11 11 39 10 8
11 11 38 10 8
11 11 37 10 8
11 11 36 10 0
11 11 35 10 2
11 11 34 10 2
11 11 33 10 2
11 11 32 10 0
11 11 31 10 8
11 11 30 10 8
11 11 29 4 0
11 11 28 4 0
11 11 27 4 0
11 11 26 4 0
11 11 25 4 0
11 11 24 4 0
11 11 23 4 0
11 11 22 4 0
11 11 21 4 0
11 11 20 4 0
11 11 19 4 0
11 11 18 4 0
11 11 17 4 0
11 11 16 4 0
11 11 15 4 0
11 11 14 4 0
11 11 13 4 0
11 11 12 4 0
11 11 11 4 0
11 11 10 3 68
11 12 68 13 36
11 12 67 13 0
11 12 66 4 0
11 12 65 4 0
11 12 64 4 0
11 12 63 4 0
11 12 62 4 0
11 12 61 4 0
11 12 60 4 0
11 12 59 4 0
11 12 58 4 0
11 12 57 11 0
11 12 56 7 74
11 12 36 9 44
11 12 35 9 14
11 12 34 9 12
11 12 33 9 14
11 12 32 9 76
11 12 29 4 40
11 12 28 10 8
11 12 27 4 8
11 12 26 4 0
11 12 25 4 0
11 12 24 4 0
11 12 23 4 0
11 12 22 4 0
11 12 21 4 0
11 12 20 4 0
11 12 19 4 0
11 12 18 4 0
11 12 17 4 0
11 12 16 4 0
11 12 15 4 0
11 12 14 4 0
11 12 13 4 0
11 12 12 4 0
11 12 11 4 0
11 12 10 3 68
11 13 68 13 36
11 13 67 13 8
11 13 66 11 8
11 13 65 13 8
11 13 64 13 8
11 13 63 12 8
11 13 62 11 8
11 13 61 11 8
11 13 60 12 8
11 13 59 11 8
11 13 58 11 8
11 13 57 7 72
11 13 26 11 32
11 13 25 4 0
11 13 24 4 0
11 13 23 4 0
11 13 22 4 0
11 13 21 4 0
11 13 20 4 0
11 13 19 15 0
11 13 18 15 0
11 13 17 15 0
11 13 16 15 0
11 13 15 15 0
11 13 14 15 0
11 13 13 15 0
11 13 12 15 0
11 13 11 15 0
11 13 10 3 68
11 14 68 13 100
11 14 26 11 32
11 14 25 4 0
11 14 24 4 0
11 14 23 4 0
11 14 22 4 0
11 14 21 4 0
11 14 20 4 0
11 14 19 15 0
11 14 18 15 0
11 14 17 15 0
11 14 16 15 0
11 14 15 15 0
11 14 14 15 0
11 14 13 15 0
11 14 12 15 0
11 14 11 15 0
11 14 10 3 68
11 15 68 13 36
11 15 67 13 90
11 15 26 11 32
11 15 25 4 0
11 15 24 4 0
11 15 23 4 0
11 15 22 4 0
11 15 21 4 0
11 15 20 4 0
11 15 19 15 0
11 15 18 15 0
11 15 17 15 0
11 15 16 15 0
11 15 15 15 0
11 15 14 15 0
11 15 13 15 0
11 15 12 15 0
11 15 11 15 0
11 15 10 15 0
11 15 9 13 80
11 16 68 3 108
11 16 26 8 44
11 16 25 8 8
11 16 24 8 0
11 16 23 8 0
11 16 22 8 0
11 16 21 8 0
11 16 20 8 0
11 16 19 8 0
11 16 18 8 0
11 16 17 8 0
11 16 16 8 0
11 16 15 8 0
11 16 14 8 0
11 16 13 8 0
11 16 12 8 0
11 16 11 8 0
11 16 10 8 0
11 16 9 3 64
11 17 24 8 32
11 17 23 10 8
11 17 22 10 8
11 17 21 10 8
11 17 20 10 8
11 17 19 10 8
11 17 18 10 8
11 17 17 10 8
11 17 16 10 8
11 17 15 10 8
11 17 14 10 8
11 17 13 10 8
11 17 12 10 8
11 17 11 8 0
11 17 10 8 0
11 17 9 3 72
11 18 24 8 108
11 18 11 8 40
11 18 10 8 72
12 2 56 7 52
12 2 55 7 20
12 2 54 7 20
12 2 53 7 20
12 2 52 7 20
12 2 51 7 20
12 2 50 7 20
12 2 49 7 20
12 2 48 7 20
12 2 47 7 20
12 2 46 7 20
12 2 45 7 20
12 2 44 7 20
12 2 43 7 20
12 2 42 7 20
12 2 41 7 20
12 2 40 7 20
12 2 39 7 20
12 2 38 7 20
12 2 37 7 20
12 2 36 7 20
12 2 35 7 20
12 2 34 7 20
12 2 33 7 20
12 2 32 7 20
12 2 31 7 20
12 2 30 7 20
12 2 29 7 20
12 2 28 7 20
12 2 27 7 20
12 2 26 7 20
12 2 25 7 20
12 2 24 7 20
12 2 23 7 20
12 2 22 7 84
12 3 58 7 52
12 3 57 7 20
12 3 56 4 0
12 3 55 4 0
12 3 54 4 0
12 3 53 4 0
12 3 52 4 0
12 3 51 10 0
12 3 50 10 0
12 3 49 10 0
12 3 48 10 0
12 3 47 10 0
12 3 46 10 0
12 3 45 10 0
12 3 44 10 0
12 3 43 10 0
12 3 42 10 0
12 3 41 10 0
12 3 40 10 0
12 3 39 10 0
12 3 38 10 0
12 3 37 10 0
12 3 36 10 0
12 3 35 10 0
12 3 34 10 0
12 3 33 10 0
12 3 32 10 0
12 3 31 10 0
12 3 30 10 0
12 3 29 4 0
12 3 28 4 0
12 3 27 4 0
12 3 26 4 0
12 3 25 4 0
12 3 24 4 0
12 3 23 4 0
12 3 22 4 0
12 3 21 7 16
12 3 20 7 84
12 4 60 7 52
12 4 59 7 16
12 4 58 4 0
12 4 57 4 0
12 4 56 4 0
12 4 55 4 0
12 4 54 4 0
12 4 53 4 0
12 4 52 4 0
12 4 51 10 0
12 4 50 10 0
12 4 49 10 0
12 4 48 10 0
12 4 47 10 0
12 4 46 10 0
12 4 45 10 0
12 4 44 10 0
12 4 43 10 0
12 4 42 10 0
12 4 41 10 0
12 4 40 10 0
12 4 39 10 0
12 4 38 10 0
12 4 37 10 0
12 4 36 10 0
12 4 35 10 0
12 4 34 10 0
12 4 33 10 0
12 4 32 10 0
12 4 31 10 0
12 4 30 10 0
12 4 29 4 0
12 4 28 4 0
12 4 27 4 0
12 4 26 4 0
12 4 25 4 0
12 4 24 4 0
12 4 23 4 0
12 4 22 4 0
12 4 21 4 0
12 4 20 4 0
12 4 19 7 20
12 4 18 7 84
12 5 63 7 52
12 5 62 7 16
12 5 61 7 16
12 5 60 4 0
12 5 59 4 0
12 5 58 4 0
12 5 57 4 0
12 5 56 4 0
12 5 55 4 0
12 5 54 4 0
12 5 53 4 0
12 5 52 4 0
12 5 51 10 0
12 5 50 10 0
12 5 49 10 0
12 5 48 10 0
12 5 47 10 0
12 5 46 10 0
12 5 45 10 0
12 5 44 10 0
12 5 43 10 0
12 5 42 10 0
12 5 41 10 0
12 5 40 10 0
12 5 39 10 0
12 5 38 10 0
12 5 37 10 0
12 5 36 10 0
12 5 35 10 0
12 5 34 10 0
12 5 33 10 0
12 5 32 10 0
12 5 31 10 0
12 5 30 10 0
12 5 29 4 0
12 5 28 4 0
12 5 27 4 0
12 5 26 4 0
12 5 25 4 0
12 5 24 4 0
12 5 23 4 0
12 5 22 4 0
12 5 21 4 0
12 5 20 4 0
12 5 19 4 0
12 5 18 7 4
12 5 17 7 84
12 6 65 7 52
12 6 64 7 16
12 6 63 7 0
12 6 62 4 0
12 6 61 4 0
12 6 60 4 0
12 6 59 4 0
12 6 58 4 0
12 6 57 4 0
12 6 56 4 0
12 6 55 4 0
12 6 54 4 0
12 6 53 4 0
12 6 52 10 0
12 6 51 10 0
12 6 50 10 0
12 6 49 10 0
12 6 48 10 0
12 6 47 10 0
12 6 46 10 0
12 6 45 10 0
12 6 44 10 0
12 6 43 10 0
12 6 42 10 0
12 6 41 10 0
12 6 40 10 0
12 6 39 10 0
12 6 38 10 0
12 6 37 10 0
12 6 36 10 0
12 6 35 10 0
12 6 34 0 8
12 6 33 0 8
12 6 32 10 0
12 6 31 10 0
12 6 30 10 0
12 6 29 4 0
12 6 28 4 0
12 6 27 4 0
12 6 26 4 0
12 6 25 4 0
12 6 24 4 0
12 6 23 4 0
12 6 22 4 0
12 6 21 4 0
12 6 20 4 0
12 6 19 4 0
12 6 18 4 0
12 6 17 3 0
12 6 16 3 84
12 7 67 3 52
12 7 66 4 16
12 7 65 4 0
12 7 64 4 0
12 7 63 4 0
12 7 62 4 0
12 7 61 4 0
12 7 60 4 0
12 7 59 4 0
12 7 58 4 0
12 7 57 4 0
12 7 56 4 0
12 7 55 4 0
12 7 54 4 0
12 7 53 4 0
12 7 52 10 0
12 7 51 10 0
12 7 50 10 0
12 7 49 10 0
12 7 48 10 0
12 7 47 10 0
12 7 46 10 0
12 7 45 10 0
12 7 44 10 0
12 7 43 10 0
12 7 42 10 0
12 7 41 10 0
12 7 40 10 0
12 7 39 10 0
12 7 38 10 0
12 7 37 10 0
12 7 36 10 0
12 7 35 0 64
12 7 32 0 32
12 7 31 10 0
12 7 30 10 0
12 7 29 4 0
12 7 28 4 0
12 7 27 4 0
12 7 26 4 0
12 7 25 4 0
12 7 24 4 0
12 7 23 4 0
12 7 22 4 0
12 7 21 4 0
12 7 20 4 0
12 7 19 4 0
12 7 18 4 0
12 7 17 4 0
12 7 16 4 0
12 7 15 3 16
12 7 14 3 84
12 8 67 3 36
12 8 66 3 0
12 8 65 3 0
12 8 64 4 0
12 8 63 4 0
12 8 62 4 0
12 8 61 4 0
12 8 60 4 0
12 8 59 4 0
12 8 58 4 0
12 8 57 4 0
12 8 56 4 0
12 8 55 4 0
12 8 54 4 0
12 8 53 14 0
12 8 52 10 0
12 8 51 10 0
12 8 50 10 0
12 8 49 10 0
12 8 48 10 0
12 8 47 10 0
12 8 46 10 0
12 8 45 10 0
12 8 44 10 0
12 8 43 10 0
12 8 42 10 0
12 8 41 10 0
12 8 40 10 0
12 8 39 10 0
12 8 38 10 0
12 8 37 10 0
12 8 36 10 0
12 8 35 0 64
12 8 32 0 32
12 8 31 10 0
12 8 30 10 0
12 8 29 4 0
12 8 28 4 0
12 8 27 4 0
12 8 26 4 0
12 8 25 4 0
12 8 24 4 0
12 8 23 4 0
12 8 22 4 0
12 8 21 4 0
12 8 20 4 0
12 8 19 4 0
12 8 18 4 0
12 8 17 4 0
12 8 16 4 0
12 8 15 4 0
12 8 14 4 0
12 8 13 13 80
12 9 69 3 52
12 9 68 3 20
12 9 67 4 0
12 9 66 4 0
12 9 65 4 0
12 9 64 4 0
12 9 63 4 0
12 9 62 4 0
12 9 61 4 0
12 9 60 4 0
12 9 59 4 0
12 9 58 4 0
12 9 57 4 0
12 9 56 4 0
12 9 55 4 0
12 9 54 4 0
12 9 53 14 0
12 9 52 10 0
12 9 51 10 0
12 9 50 10 0
12 9 49 10 0
12 9 48 10 0
12 9 47 10 0
12 9 46 10 0
12 9 45 10 0
12 9 44 10 0
12 9 43 10 0
12 9 42 10 0
12 9 41 10 0
12 9 40 10 0
12 9 39 10 0
12 9 38 10 0
12 9 37 10 0
12 9 36 10 0
12 9 35 3 8
12 9 34 3 24
12 9 33 3 24
12 9 32 10 0
12 9 31 10 0
12 9 30 10 0
12 9 29 4 0
12 9 28 4 0
12 9 27 4 0
12 9 26 4 0
12 9 25 4 0
12 9 24 4 0
12 9 23 4 0
12 9 22 4 0
12 9 21 4 0
12 9 20 4 0
12 9 19 4 0
12 9 18 4 0
12 9 17 4 0
12 9 16 4 0
12 9 15 4 0
12 9 14 4 0
12 9 13 13 0
12 9 12 13 16
12 9 11 13 80
12 10 71 3 60
12 10 70 3 28
12 10 69 13 8
12 10 68 4 0
12 10 67 4 0
12 10 66 4 0
12 10 65 4 0
12 10 64 4 0
12 10 63 4 0
12 10 62 4 0
12 10 61 4 0
12 10 60 4 0
12 10 59 4 0
12 10 58 4 0
12 10 57 4 0
12 10 56 4 0
12 10 55 4 0
12 10 54 4 0
12 10 53 14 0
12 10 52 10 0
12 10 51 10 0
12 10 50 10 0
12 10 49 10 0
12 10 48 10 0
12 10 47 10 0
12 10 46 10 0
12 10 45 10 0
12 10 44 10 0
12 10 43 10 0
12 10 42 10 0
12 10 41 10 0
12 10 40 10 0
12 10 39 10 0
12 10 38 10 0
12 10 37 10 0
12 10 36 10 64
12 10 32 10 32
12 10 31 10 0
12 10 30 10 0
12 10 29 4 0
12 10 28 4 0
12 10 27 4 0
12 10 26 4 0
12 10 25 4 0
12 10 24 4 0
12 10 23 4 0
12 10 22 4 0
12 10 21 4 0
12 10 20 4 0
12 10 19 4 0
12 10 18 4 0
12 10 17 4 0
12 10 16 4 0
12 10 15 4 0
12 10 14 4 0
12 10 13 4 0
12 10 12 4 0
12 10 11 4 0
12 10 10 3 80
12 11 73 3 62
12 11 72 3 94
12 11 68 13 32
12 11 67 4 0
12 11 66 4 0
12 11 65 4 0
12 11 64 4 0
12 11 63 4 0
12 11 62 4 0
12 11 61 4 0
12 11 60 4 0
12 11 59 4 0
12 11 58 4 0
12 11 57 4 0
12 11 56 10 8
12 11 55 10 8
12 11 54 10 8
12 11 53 12 8
12 11 52 12 8
12 11 51 12 8
12 11 50 12 8
12 11 49 12 8
12 11 48 12 8
12 11 47 12 8
12 11 46 12 8
12 11 45 12 8
12 11 44 12 8
12 11 43 12 8
12 11 42 12 8
12 11 41 10 8
12 11 40 10 8
12 11 39 10 8
12 11 38 12 8
12 11 37 12 8
12 11 36 12 64
12 11 32 12 32
12 11 31 12 8
12 11 30 10 8
12 11 29 4 0
12 11 28 4 0
12 11 27 4 0
12 11 26 4 0
12 11 25 4 0
12 11 24 4 0
12 11 23 4 0
12 11 22 4 0
12 11 21 4 0
12 11 20 4 0
12 11 19 4 0
12 11 18 4 0
12 11 17 4 0
12 11 16 4 0
12 11 15 4 0
12 11 14 4 0
12 11 13 4 0
12 11 12 4 0
12 11 11 4 0
12 11 10 20 64
12 12 68 13 32
12 12 67 4 0
12 12 66 4 0
12 12 65 4 0
12 12 64 4 0
12 12 63 4 0
12 12 62 4 0
12 12 61 4 0
12 12 60 4 0
12 12 59 4 0
12 12 58 4 0
12 12 57 4 64
12 12 36 9 104
12 12 34 9 122
12 12 32 9 104
12 12 29 10 40
12 12 28 4 8
12 12 27 10 8
12 12 26 4 0
12 12 25 4 0
12 12 24 4 0
12 12 23 4 0
12 12 22 4 0
12 12 21 4 0
12 12 20 4 0
12 12 19 4 0
12 12 18 4 0
12 12 17 4 0
12 12 16 4 0
12 12 15 4 0
12 12 14 4 0
12 12 13 4 0
12 12 12 4 0
12 12 11 4 0
12 12 10 20 64
12 13 68 13 32
12 13 67 11 0
12 13 66 11 0
12 13 65 11 8
12 13 64 11 8
12 13 63 12 8
12 13 62 11 8
12 13 61 11 8
12 13 60 12 8
12 13 59 11 8
12 13 58 11 8
12 13 57 4 64
12 13 26 4 32
12 13 25 4 0
12 13 24 4 0
12 13 23 4 0
12 13 22 4 0
12 13 21 4 0
12 13 20 4 0
12 13 19 15 0
12 13 18 15 0
12 13 17 15 0
12 13 16 15 0
12 13 15 15 0
12 13 14 15 0
12 13 13 15 0
12 13 12 15 0
12 13 11 15 0
12 13 10 20 64
12 14 68 13 32
12 14 67 13 14
12 14 66 13 78
12 14 57 19 102
12 14 26 4 32
12 14 25 4 0
12 14 24 4 0
12 14 23 4 0
12 14 22 4 0
12 14 21 4 0
12 14 20 4 0
12 14 19 15 0
12 14 18 15 0
12 14 17 15 0
12 14 16 15 0
12 14 15 15 0
12 14 14 15 0
12 14 13 15 0
12 14 12 15 0
12 14 11 15 0
12 14 10 20 64
12 15 68 13 98
12 15 57 8 108
12 15 26 4 32
12 15 25 4 0
12 15 24 4 0
12 15 23 4 0
12 15 22 4 0
12 15 21 4 0
12 15 20 4 0
12 15 19 15 0
12 15 18 15 0
12 15 17 15 0
12 15 16 15 0
12 15 15 15 0
12 15 14 15 0
12 15 13 15 0
12 15 12 15 0
12 15 11 15 0
12 15 10 15 0
12 15 9 13 80
12 16 68 3 106
12 16 26 8 40
12 16 25 8 8
12 16 24 8 0
12 16 23 8 0
12 16 22 8 0
12 16 21 8 0
12 16 20 8 0
12 16 19 8 0
12 16 18 8 0
12 16 17 8 0
12 16 16 8 0
12 16 15 8 0
12 16 14 8 0
12 16 13 8 0
12 16 12 8 0
12 16 11 8 0
12 16 10 8 0
12 16 9 3 64
12 17 24 8 32
12 17 23 10 8
12 17 22 12 8
12 17 21 12 8
12 17 20 12 8
12 17 19 12 8
12 17 18 12 8
12 17 17 12 8
12 17 16 12 8
12 17 15 12 8
12 17 14 12 8
12 17 13 10 8
12 17 12 10 8
12 17 11 8 0
12 17 10 8 0
12 17 9 3 72
12 18 24 8 104
12 18 11 8 40
12 18 10 8 72
13 2 56 7 48
13 2 55 7 16
13 2 54 7 16
13 2 53 7 16
13 2 52 7 16
13 2 51 7 16
13 2 50 7 16
13 2 49 7 16
13 2 48 7 16
13 2 47 7 16
13 2 46 7 16
13 2 45 7 16
13 2 44 7 16
13 2 43 7 16
13 2 42 7 16
13 2 41 7 16
13 2 40 7 16
13 2 39 7 16
13 2 38 7 16
13 2 37 7 16
13 2 36 7 16
13 2 35 7 16
13 2 34 7 16
13 2 33 7 16
13 2 32 7 16
13 2 31 7 16
13 2 30 7 16
13 2 29 7 16
13 2 28 7 16
13 2 27 7 16
13 2 26 7 16
13 2 25 7 16
13 2 24 7 16
13 2 23 7 16
13 2 22 7 16
13 2 21 7 84
13 3 59 7 52
13 3 58 7 16
13 3 57 7 16
13 3 56 4 0
13 3 55 4 0
13 3 54 4 0
13 3 53 4 0
13 3 52 4 0
13 3 51 10 0
13 3 50 10 0
13 3 49 10 0
13 3 48 10 0
13 3 47 10 0
13 3 46 10 0
13 3 45 10 0
13 3 44 10 0
13 3 43 10 0
13 3 42 10 0
13 3 41 10 0
13 3 40 10 0
13 3 39 10 0
13 3 38 10 0
13 3 37 10 0
13 3 36 10 0
13 3 35 10 0
13 3 34 10 0
13 3 33 10 0
13 3 32 10 0
13 3 31 10 0
13 3 30 10 0
13 3 29 4 0
13 3 28 4 0
13 3 27 4 0
13 3 26 4 0
13 3 25 4 0
13 3 24 4 0
13 3 23 4 0
13 3 22 4 0
13 3 21 4 0
13 3 20 7 16
13 3 19 7 84
13 4 61 7 52
13 4 60 7 16
13 4 59 4 0
13 4 58 4 0
13 4 57 4 0
13 4 56 4 0
13 4 55 4 0
13 4 54 4 0
13 4 53 4 0
13 4 52 4 0
13 4 51 10 0
13 4 50 10 0
13 4 49 10 0
13 4 48 10 0
13 4 47 10 0
13 4 46 10 0
13 4 45 10 0
13 4 44 10 0
13 4 43 10 0
13 4 42 10 0
13 4 41 10 0
13 4 40 10 0
13 4 39 10 0
13 4 38 10 0
13 4 37 10 0
13 4 36 10 0
13 4 35 10 0
13 4 34 10 0
13 4 33 10 0
13 4 32 10 0
13 4 31 10 0
13 4 30 10 0
13 4 29 4 0
13 4 28 4 0
13 4 27 4 0
13 4 26 4 0
13 4 25 4 0
13 4 24 4 0
13 4 23 4 0
13 4 22 4 0
13 4 21 4 0
13 4 20 4 0
13 4 19 4 0
13 4 18 7 16
13 4 17 7 84
13 5 64 7 52
13 5 63 7 16
13 5 62 7 16
13 5 61 4 0
13 5 60 4 0
13 5 59 4 0
13 5 58 4 0
13 5 57 4 0
13 5 56 4 0
13 5 55 4 0
13 5 54 4 0
13 5 53 4 0
13 5 52 10 0
13 5 51 10 0
13 5 50 10 0
13 5 49 10 0
13 5 48 10 0
13 5 47 10 0
13 5 46 10 0
13 5 45 10 0
13 5 44 10 0
13 5 43 10 0
13 5 42 10 0
13 5 41 10 0
13 5 40 10 0
13 5 39 10 0
13 5 38 10 0
13 5 37 10 0
13 5 36 10 0
13 5 35 10 0
13 5 34 10 0
13 5 33 10 0
13 5 32 10 0
13 5 31 10 0
13 5 30 10 0
13 5 29 4 0
13 5 28 4 0
13 5 27 4 0
13 5 26 4 0
13 5 25 4 0
13 5 24 4 0
13 5 23 4 0
13 5 22 4 0
13 5 21 4 0
13 5 20 4 0
13 5 19 4 0
13 5 18 4 0
13 5 17 4 0
13 5 16 7 84
13 6 66 7 52
13 6 65 7 16
13 6 64 4 0
13 6 63 4 0
13 6 62 4 0
13 6 61 4 0
13 6 60 4 0
13 6 59 4 0
13 6 58 4 0
13 6 57 4 0
13 6 56 4 0
13 6 55 4 0
13 6 54 4 0
13 6 53 4 0
13 6 52 10 0
13 6 51 10 0
13 6 50 10 0
13 6 49 10 0
13 6 48 10 0
13 6 47 10 0
13 6 46 10 0
13 6 45 10 0
13 6 44 10 0
13 6 43 10 0
13 6 42 10 0
13 6 41 10 0
13 6 40 10 0
13 6 39 10 0
13 6 38 10 0
13 6 37 10 0
13 6 36 10 0
13 6 35 10 0
13 6 34 10 0
13 6 33 10 0
13 6 32 10 0
13 6 31 10 0
13 6 30 10 0
13 6 29 4 0
13 6 28 4 0
13 6 27 4 0
13 6 26 4 0
13 6 25 4 0
13 6 24 4 0
13 6 23 4 0
13 6 22 4 0
13 6 21 4 0
13 6 20 4 0
13 6 19 4 0
13 6 18 4 0
13 6 17 4 0
13 6 16 4 0
13 6 15 3 84
13 7 68 3 52
13 7 67 4 16
13 7 66 4 0
13 7 65 4 0
13 7 64 4 0
13 7 63 4 0
13 7 62 4 0
13 7 61 4 0
13 7 60 4 0
13 7 59 4 0
13 7 58 4 0
13 7 57 4 0
13 7 56 4 0
13 7 55 4 0
13 7 54 4 0
13 7 53 4 0
13 7 52 10 0
13 7 51 10 0
13 7 50 10 0
13 7 49 10 0
13 7 48 10 0
13 7 47 10 0
13 7 46 10 0
13 7 45 10 0
13 7 44 10 0
13 7 43 10 0
13 7 42 10 0
13 7 41 10 0
13 7 40 10 0
13 7 39 10 0
13 7 38 10 0
13 7 37 10 0
13 7 36 10 0
13 7 35 10 0
13 7 34 0 4
13 7 33 0 4
13 7 32 10 0
13 7 31 10 0
13 7 30 10 0
13 7 29 4 0
13 7 28 4 0
13 7 27 4 0
13 7 26 4 0
13 7 25 4 0
13 7 24 4 0
13 7 23 4 0
13 7 22 4 0
13 7 21 4 0
13 7 20 4 0
13 7 19 4 0
13 7 18 4 0
13 7 17 4 0
13 7 16 4 0
13 7 15 3 0
13 7 14 3 80
13 8 69 3 52
13 8 68 3 4
13 8 67 3 0
13 8 66 4 0
13 8 65 4 0
13 8 64 4 0
13 8 63 4 0
13 8 62 4 0
13 8 61 4 0
13 8 60 4 0
13 8 59 4 0
13 8 58 4 0
13 8 57 4 0
13 8 56 4 0
13 8 55 4 0
13 8 54 4 0
13 8 53 14 0
13 8 52 10 0
13 8 51 10 0
13 8 50 10 0
13 8 49 10 0
13 8 48 10 0
13 8 47 10 0
13 8 46 10 0
13 8 45 10 0
13 8 44 10 0
13 8 43 10 0
13 8 42 10 0
13 8 41 10 0
13 8 40 10 0
13 8 39 10 0
13 8 38 10 0
13 8 37 10 0
13 8 36 10 0
13 8 35 10 0
13 8 34 0 4
13 8 33 0 4
13 8 32 10 0
13 8 31 10 0
13 8 30 10 0
13 8 29 4 0
13 8 28 4 0
13 8 27 4 0
13 8 26 4 0
13 8 25 4 0
13 8 24 4 0
13 8 23 4 0
13 8 22 4 0
13 8 21 4 0
13 8 20 4 0
13 8 19 4 0
13 8 18 4 0
13 8 17 4 0
13 8 16 4 0
13 8 15 4 0
13 8 14 4 0
13 8 13 13 80
13 9 72 3 52
13 9 71 3 20
13 9 70 3 20
13 9 69 4 0
13 9 68 4 0
13 9 67 4 0
13 9 66 4 0
13 9 65 4 0
13 9 64 4 0
13 9 63 4 0
13 9 62 4 0
13 9 61 4 0
13 9 60 4 0
13 9 59 4 0
13 9 58 4 0
13 9 57 4 0
13 9 56 4 0
13 9 55 4 0
13 9 54 4 0
13 9 53 14 0
13 9 52 10 0
13 9 51 10 0
13 9 50 10 0
13 9 49 10 0
13 9 48 10 0
13 9 47 10 0
13 9 46 10 0
13 9 45 10 0
13 9 44 10 0
13 9 43 10 0
13 9 42 10 0
13 9 41 10 0
13 9 40 10 0
13 9 39 10 0
13 9 38 10 0
13 9 37 10 0
13 9 36 10 0
13 9 35 3 8
13 9 34 3 8
13 9 33 3 8
13 9 32 10 0
13 9 31 10 0
13 9 30 10 0
13 9 29 4 0
13 9 28 4 0
13 9 27 4 0
13 9 26 4 0
13 9 25 4 0
13 9 24 4 0
13 9 23 4 0
13 9 22 4 0
13 9 21 4 0
13 9 20 4 0
13 9 19 4 0
13 9 18 4 0
13 9 17 4 0
13 9 16 4 0
13 9 15 4 0
13 9 14 4 0
13 9 13 4 0
13 9 12 13 16
13 9 11 13 80
13 10 73 3 60
13 10 72 3 12
13 10 71 13 8
13 10 70 13 8
13 10 69 4 0
13 10 68 4 0
13 10 67 4 0
13 10 66 4 0
13 10 65 4 0
13 10 64 4 0
13 10 63 4 0
13 10 62 4 0
13 10 61 4 0
13 10 60 4 0
13 10 59 4 0
13 10 58 4 0
13 10 57 4 0
13 10 56 4 0
13 10 55 4 0
13 10 54 4 0
13 10 53 14 0
13 10 52 10 0
13 10 51 10 0
13 10 50 10 0
13 10 49 10 0
13 10 48 10 0
13 10 47 10 0
13 10 46 10 0
13 10 45 10 0
13 10 44 10 0
13 10 43 10 0
13 10 42 10 0
13 10 41 10 0
13 10 40 10 0
13 10 39 10 0
13 10 38 10 0
13 10 37 10 0
13 10 36 10 64
13 10 32 10 32
13 10 31 10 0
13 10 30 10 0
13 10 29 4 0
13 10 28 4 0
13 10 27 4 0
13 10 26 4 0
13 10 25 4 0
13 10 24 4 0
13 10 23 4 0
13 10 22 4 0
13 10 21 4 0
13 10 20 4 0
13 10 19 4 0
13 10 18 4 0
13 10 17 4 0
13 10 16 4 0
13 10 15 4 0
13 10 14 4 0
13 10 13 4 0
13 10 12 4 0
13 10 11 4 0
13 10 10 3 80
13 11 74 3 126
13 11 69 13 36
13 11 68 4 0
13 11 67 4 0
13 11 66 4 0
13 11 65 4 0
13 11 64 4 0
13 11 63 4 0
13 11 62 4 0
13 11 61 4 0
13 11 60 4 0
13 11 59 4 0
13 11 58 4 0
13 11 57 4 0
13 11 56 10 8
13 11 55 10 8
13 11 54 10 8
13 11 53 10 8
13 11 52 10 8
13 11 51 10 8
13 11 50 10 8
13 11 49 10 8
13 11 48 10 8
13 11 47 10 8
13 11 46 10 8
13 11 45 10 8
13 11 44 10 8
13 11 43 10 8
13 11 42 10 8
13 11 41 10 8
13 11 40 10 8
13 11 39 10 8
13 11 38 10 8
13 11 37 10 8
13 11 36 10 64
13 11 32 10 32
13 11 31 10 8
13 11 30 10 8
13 11 29 4 0
13 11 28 4 0
13 11 27 4 0
13 11 26 4 0
13 11 25 4 0
13 11 24 4 0
13 11 23 4 0
13 11 22 4 0
13 11 21 4 0
13 11 20 4 0
13 11 19 4 0
13 11 18 4 0
13 11 17 4 0
13 11 16 4 0
13 11 15 4 0
13 11 14 4 0
13 11 13 4 0
13 11 12 4 0
13 11 11 4 0
13 11 10 20 64
13 12 69 13 36
13 12 68 4 0
13 12 67 4 0
13 12 66 4 0
13 12 65 4 0
13 12 64 4 0
13 12 63 4 0
13 12 62 4 0
13 12 61 4 0
13 12 60 4 0
13 12 59 4 0
13 12 58 4 0
13 12 57 11 64
13 12 36 9 40
13 12 35 9 94
13 12 33 9 62
13 12 32 9 72
13 12 29 4 40
13 12 28 10 8
13 12 27 4 8
13 12 26 4 0
13 12 25 4 0
13 12 24 4 0
13 12 23 4 0
13 12 22 4 0
13 12 21 4 0
13 12 20 4 0
13 12 19 4 0
13 12 18 4 0
13 12 17 4 0
13 12 16 4 0
13 12 15 4 0
13 12 14 4 0
13 12 13 4 0
13 12 12 4 0
13 12 11 4 0
13 12 10 20 64
13 13 69 13 36
13 13 68 11 0
13 13 67 11 8
13 13 66 11 8
13 13 65 11 8
13 13 64 11 8
13 13 63 12 8
13 13 62 11 8
13 13 61 11 8
13 13 60 12 8
13 13 59 11 8
13 13 58 11 8
13 13 57 11 72
13 13 26 4 32
13 13 25 4 0
13 13 24 4 0
13 13 23 4 0
13 13 22 4 0
13 13 21 4 0
13 13 20 4 0
13 13 19 15 0
13 13 18 15 0
13 13 17 15 0
13 13 16 15 0
13 13 15 15 0
13 13 14 15 0
13 13 13 15 0
13 13 12 15 0
13 13 11 15 0
13 13 10 20 64
13 14 69 13 36
13 14 68 13 74
13 14 26 4 32
13 14 25 4 0
13 14 24 4 0
13 14 23 4 0
13 14 22 4 0
13 14 21 4 0
13 14 20 4 0
13 14 19 15 0
13 14 18 15 0
13 14 17 15 0
13 14 16 15 0
13 14 15 15 0
13 14 14 15 0
13 14 13 15 0
13 14 12 15 0
13 14 11 15 0
13 14 10 20 64
13 15 69 13 100
13 15 57 8 120
13 15 26 4 32
13 15 25 4 0
13 15 24 4 0
13 15 23 4 0
13 15 22 4 0
13 15 21 4 0
13 15 20 4 0
13 15 19 15 0
13 15 18 15 0
13 15 17 15 0
13 15 16 15 0
13 15 15 15 0
13 15 14 15 0
13 15 13 15 0
13 15 12 15 0
13 15 11 15 0
13 15 10 15 0
13 15 9 13 80
13 16 69 3 108
13 16 26 8 40
13 16 25 8 8
13 16 24 8 0
13 16 23 8 0
13 16 22 8 0
13 16 21 8 0
13 16 20 8 0
13 16 19 8 0
13 16 18 8 0
13 16 17 8 0
13 16 16 8 0
13 16 15 8 0
13 16 14 8 0
13 16 13 8 0
13 16 12 8 0
13 16 11 8 0
13 16 10 8 0
13 16 9 3 64
13 17 24 8 32
13 17 23 10 8
13 17 22 10 8
13 17 21 10 8
13 17 20 10 8
13 17 19 10 8
13 17 18 10 8
13 17 17 10 8
13 17 16 10 8
13 17 15 10 8
13 17 14 10 8
13 17 13 10 8
13 17 12 10 8
13 17 11 8 0
13 17 10 8 0
13 17 9 3 72
13 18 24 8 104
13 18 11 8 40
13 18 10 8 72
14 1 52 7 52
14 1 51 7 20
14 1 50 7 20
14 1 49 7 20
14 1 48 7 20
14 1 47 7 20
14 1 46 7 20
14 1 45 7 20
14 1 44 7 20
14 1 43 7 20
14 1 42 7 20
14 1 41 7 20
14 1 40 7 20
14 1 39 7 20
14 1 38 7 20
14 1 37 7 20
14 1 36 7 20
14 1 35 7 20
14 1 34 7 20
14 1 33 7 20
14 1 32 7 20
14 1 31 7 20
14 1 30 7 20
14 1 29 7 20
14 1 28 7 20
14 1 27 7 20
14 1 26 7 20
14 1 25 7 20
14 1 24 7 20
14 1 23 7 84
14 2 56 7 48
14 2 55 7 16
14 2 54 7 16
14 2 53 7 16
14 2 52 7 0
14 2 51 7 0
14 2 50 7 0
14 2 49 7 0
14 2 48 7 0
14 2 47 7 0
14 2 46 7 0
14 2 45 7 0
14 2 44 7 0
14 2 43 7 0
14 2 42 7 0
14 2 41 7 0
14 2 40 7 0
14 2 39 7 0
14 2 38 7 0
14 2 37 7 0
14 2 36 7 0
14 2 35 7 0
14 2 34 7 0
14 2 33 7 0
14 2 32 7 0
14 2 31 7 0
14 2 30 7 0
14 2 29 7 0
14 2 28 7 0
14 2 27 7 0
14 2 26 7 0
14 2 25 7 0
14 2 24 7 0
14 2 23 7 0
14 2 22 7 16
14 2 21 7 16
14 2 20 7 84
14 3 60 7 52
14 3 59 7 16
14 3 58 7 16
14 3 57 7 16
14 3 56 4 0
14 3 55 4 0
14 3 54 4 0
14 3 53 4 0
14 3 52 4 0
14 3 51 10 0
14 3 50 10 0
14 3 49 10 0
14 3 48 10 0
14 3 47 10 0
14 3 46 10 0
14 3 45 10 0
14 3 44 10 0
14 3 43 10 0
14 3 42 10 0
14 3 41 10 0
14 3 40 10 0
14 3 39 10 0
14 3 38 10 0
14 3 37 10 0
14 3 36 10 0
14 3 35 10 0
14 3 34 10 0
14 3 33 10 0
14 3 32 10 0
14 3 31 10 0
14 3 30 10 0
14 3 29 4 0
14 3 28 4 0
14 3 27 4 0
14 3 26 4 0
14 3 25 4 0
14 3 24 4 0
14 3 23 4 0
14 3 22 4 0
14 3 21 4 0
14 3 20 4 0
14 3 19 7 16
14 3 18 7 84
14 4 62 7 52
14 4 61 7 16
14 4 60 4 0
14 4 59 4 0
14 4 58 4 0
14 4 57 4 0
14 4 56 4 0
14 4 55 4 0
14 4 54 4 0
14 4 53 4 0
14 4 52 10 0
14 4 51 10 0
14 4 50 10 0
14 4 49 10 0
14 4 48 10 0
14 4 47 10 0
14 4 46 10 0
14 4 45 10 0
14 4 44 10 0
14 4 43 10 0
14 4 42 10 0
14 4 41 10 0
14 4 40 10 0
14 4 39 10 0
14 4 38 10 0
14 4 37 10 0
14 4 36 10 0
14 4 35 10 0
14 4 34 10 0
14 4 33 10 0
14 4 32 10 0
14 4 31 10 0
14 4 30 10 0
14 4 29 4 0
14 4 28 4 0
14 4 27 4 0
14 4 26 4 0
14 4 25 4 0
14 4 24 4 0
14 4 23 4 0
14 4 22 4 0
14 4 21 4 0
14 4 20 4 0
14 4 19 4 0
14 4 18 4 0
14 4 17 7 16
14 4 16 7 84
14 5 65 7 52
14 5 64 7 16
14 5 63 7 16
14 5 62 4 0
14 5 61 4 0
14 5 60 4 0
14 5 59 4 0
14 5 58 4 0
14 5 57 4 0
14 5 56 4 0
14 5 55 4 0
14 5 54 4 0
14 5 53 4 0
14 5 52 10 0
14 5 51 10 0
14 5 50 10 0
14 5 49 10 0
14 5 48 10 0
14 5 47 10 0
14 5 46 10 0
14 5 45 10 0
14 5 44 10 0
14 5 43 10 0
14 5 42 10 0
14 5 41 10 0
14 5 40 10 0
14 5 39 10 0
14 5 38 10 0
14 5 37 10 0
14 5 36 10 0
14 5 35 10 0
14 5 34 10 0
14 5 33 10 0
14 5 32 10 0
14 5 31 10 0
14 5 30 10 0
14 5 29 4 0
14 5 28 4 0
14 5 27 4 0
14 5 26 4 0
14 5 25 4 0
14 5 24 4 0
14 5 23 4 0
14 5 22 4 0
14 5 21 4 0
14 5 20 4 0
14 5 19 4 0
14 5 18 4 0
14 5 17 4 0
14 5 16 7 64
14 6 67 7 52
14 6 66 7 16
14 6 65 4 0
14 6 64 4 0
14 6 63 4 0
14 6 62 4 0
14 6 61 4 0
14 6 60 4 0
14 6 59 4 0
14 6 58 4 0
14 6 57 4 0
14 6 56 4 0
14 6 55 4 0
14 6 54 4 0
14 6 53 4 0
14 6 52 10 0
14 6 51 10 0
14 6 50 10 0
14 6 49 10 0
14 6 48 10 0
14 6 47 10 0
14 6 46 10 0
14 6 45 10 0
14 6 44 10 0
14 6 43 10 0
14 6 42 10 0
14 6 41 10 0
14 6 40 10 0
14 6 39 10 0
14 6 38 10 0
14 6 37 10 0
14 6 36 10 0
14 6 35 10 0
14 6 34 10 0
14 6 33 10 0
14 6 32 10 0
14 6 31 10 0
14 6 30 10 0
14 6 29 4 0
14 6 28 4 0
14 6 27 4 0
14 6 26 4 0
14 6 25 4 0
14 6 24 4 0
14 6 23 4 0
14 6 22 4 0
14 6 21 4 0
14 6 20 4 0
14 6 19 4 0
14 6 18 4 0
14 6 17 4 0
14 6 16 4 0
14 6 15 3 80
14 7 69 3 52
14 7 68 4 16
14 7 67 4 0
14 7 66 4 0
14 7 65 4 0
14 7 64 4 0
14 7 63 4 0
14 7 62 4 0
14 7 61 4 0
14 7 60 4 0
14 7 59 4 0
14 7 58 4 0
14 7 57 4 0
14 7 56 4 0
14 7 55 4 0
14 7 54 4 0
14 7 53 4 0
14 7 52 10 0
14 7 51 10 0
14 7 50 10 0
14 7 49 10 0
14 7 48 10 0
14 7 47 10 0
14 7 46 10 0
14 7 45 10 0
14 7 44 10 0
14 7 43 10 0
14 7 42 10 0
14 7 41 10 0
14 7 40 10 0
14 7 39 10 0
14 7 38 10 0
14 7 37 10 0
14 7 36 10 0
14 7 35 10 0
14 7 34 10 0
14 7 33 10 0
14 7 32 10 0
14 7 31 10 0
14 7 30 10 0
14 7 29 4 0
14 7 28 4 0
14 7 27 4 0
14 7 26 4 0
14 7 25 4 0
14 7 24 4 0
14 7 23 4 0
14 7 22 4 0
14 7 21 4 0
14 7 20 4 0
14 7 19 4 0
14 7 18 4 0
14 7 17 4 0
14 7 16 4 0
14 7 15 4 0
14 7 14 3 80
14 8 71 3 52
14 8 70 3 20
14 8 69 4 0
14 8 68 4 0
14 8 67 4 0
14 8 66 4 0
14 8 65 4 0
14 8 64 4 0
14 8 63 4 0
14 8 62 4 0
14 8 61 4 0
14 8 60 4 0
14 8 59 4 0
14 8 58 4 0
14 8 57 4 0
14 8 56 4 0
14 8 55 4 0
14 8 54 4 0
14 8 53 14 0
14 8 52 10 0
14 8 51 10 0
14 8 50 10 0
14 8 49 10 0
14 8 48 10 0
14 8 47 10 0
14 8 46 10 0
14 8 45 10 0
14 8 44 10 0
14 8 43 10 0
14 8 42 10 0
14 8 41 10 0
14 8 40 10 0
14 8 39 10 0
14 8 38 10 0
14 8 37 10 0
14 8 36 10 0
14 8 35 10 0
14 8 34 10 0
14 8 33 10 0
14 8 32 10 0
14 8 31 10 0
14 8 30 10 0
14 8 29 4 0
14 8 28 4 0
14 8 27 4 0
14 8 26 4 0
14 8 25 4 0
14 8 24 4 0
14 8 23 4 0
14 8 22 4 0
14 8 21 4 0
14 8 20 4 0
14 8 19 4 0
14 8 18 4 0
14 8 17 4 0
14 8 16 4 0
14 8 15 4 0
14 8 14 4 0
14 8 13 13 80
14 9 73 3 52
14 9 72 3 16
14 9 71 4 0
14 9 70 4 0
14 9 69 4 0
14 9 68 4 0
14 9 67 4 0
14 9 66 4 0
14 9 65 4 0
14 9 64 4 0
14 9 63 4 0
14 9 62 4 0
14 9 61 4 0
14 9 60 4 0
14 9 59 4 0
14 9 58 4 0
14 9 57 4 0
14 9 56 4 0
14 9 55 4 0
14 9 54 4 0
14 9 53 14 0
14 9 52 10 0
14 9 51 10 0
14 9 50 10 0
14 9 49 10 0
14 9 48 10 0
14 9 47 10 0
14 9 46 10 0
14 9 45 10 0
14 9 44 10 0
14 9 43 10 0
14 9 42 10 0
14 9 41 10 0
14 9 40 10 0
14 9 39 10 0
14 9 38 10 0
14 9 37 10 0
14 9 36 10 0
14 9 35 3 8
14 9 34 3 8
14 9 33 3 8
14 9 32 10 0
14 9 31 10 0
14 9 30 10 0
14 9 29 4 0
14 9 28 4 0
14 9 27 4 0
14 9 26 4 0
14 9 25 4 0
14 9 24 4 0
14 9 23 4 0
14 9 22 4 0
14 9 21 4 0
14 9 20 4 0
14 9 19 4 0
14 9 18 4 0
14 9 17 4 0
14 9 16 4 0
14 9 15 4 0
14 9 14 4 0
14 9 13 4 0
14 9 12 13 16
14 9 11 13 80
14 10 75 3 52
14 10 74 3 28
14 10 73 13 8
14 10 72 13 8
14 10 71 13 8
14 10 70 13 8
14 10 69 4 0
14 10 68 4 0
14 10 67 4 0
14 10 66 4 0
14 10 65 4 0
14 10 64 4 0
14 10 63 4 0
14 10 62 4 0
14 10 61 4 0
14 10 60 4 0
14 10 59 4 0
14 10 58 4 0
14 10 57 4 0
14 10 56 4 0
14 10 55 4 0
14 10 54 4 0
14 10 53 14 0
14 10 52 10 0
14 10 51 10 0
14 10 50 10 0
14 10 49 10 0
14 10 48 10 0
14 10 47 10 0
14 10 46 10 0
14 10 45 10 0
14 10 44 10 0
14 10 43 10 0
14 10 42 10 0
14 10 41 10 0
14 10 40 10 0
14 10 39 10 0
14 10 38 10 0
14 10 37 10 0
14 10 36 10 64
14 10 32 10 32
14 10 31 10 0
14 10 30 17 0
14 10 29 4 0
14 10 28 4 0
14 10 27 4 0
14 10 26 4 0
14 10 25 4 0
14 10 24 4 0
14 10 23 4 0
14 10 22 4 0
14 10 21 4 0
14 10 20 4 0
14 10 19 4 0
14 10 18 4 0
14 10 17 4 0
14 10 16 4 0
14 10 15 4 0
14 10 14 4 0
14 10 13 4 0
14 10 12 4 0
14 10 11 4 0
14 10 10 3 82
14 11 75 3 100
14 11 69 13 32
14 11 68 4 0
14 11 67 4 0
14 11 66 4 0
14 11 65 4 0
14 11 64 4 0
14 11 63 4 0
14 11 62 4 0
14 11 61 4 0
14 11 60 4 0
14 11 59 4 0
14 11 58 4 0
14 11 57 4 0
14 11 56 12 8
14 11 55 12 8
14 11 54 12 8
14 11 53 12 8
14 11 52 12 8
14 11 51 12 8
14 11 50 12 8
14 11 49 12 8
14 11 48 12 8
14 11 47 12 8
14 11 46 10 8
14 11 45 10 8
14 11 44 10 8
14 11 43 10 8
14 11 42 10 8
14 11 41 12 8
14 11 40 12 8
14 11 39 12 8
14 11 38 12 8
14 11 37 12 8
14 11 36 12 64
14 11 32 10 32
14 11 31 10 8
14 11 30 10 8
14 11 29 4 0
14 11 28 4 0
14 11 27 4 0
14 11 26 4 0
14 11 25 4 0
14 11 24 4 0
14 11 23 4 0
14 11 22 4 0
14 11 21 4 0
14 11 20 4 0
14 11 19 4 0
14 11 18 4 0
14 11 17 4 0
14 11 16 4 0
14 11 15 4 0
14 11 14 4 0
14 11 13 4 0
14 11 12 4 0
14 11 11 4 0
14 11 10 3 66
14 12 75 3 108
14 12 69 16 32
14 12 68 4 0
14 12 67 4 0
14 12 66 4 0
14 12 65 4 0
14 12 64 4 0
14 12 63 4 0
14 12 62 4 0
14 12 61 4 0
14 12 60 4 0
14 12 59 4 0
14 12 58 4 0
14 12 57 4 64
14 12 36 9 104
14 12 34 9 126
14 12 32 9 104
14 12 29 10 40
14 12 28 4 8
14 12 27 10 8
14 12 26 4 0
14 12 25 4 0
14 12 24 4 0
14 12 23 4 0
14 12 22 4 0
14 12 21 4 0
14 12 20 4 0
14 12 19 4 0
14 12 18 4 0
14 12 17 4 0
14 12 16 4 0
14 12 15 4 0
14 12 14 4 0
14 12 13 4 0
14 12 12 4 0
14 12 11 4 0
14 12 10 3 66
14 13 69 16 32
14 13 68 11 8
14 13 67 11 8
14 13 66 11 8
14 13 65 11 8
14 13 64 11 8
14 13 63 12 8
14 13 62 11 8
14 13 61 11 8
14 13 60 12 8
14 13 59 11 8
14 13 58 11 8
14 13 57 4 64
14 13 26 11 32
14 13 25 4 0
14 13 24 4 0
14 13 23 4 0
14 13 22 4 0
14 13 21 4 0
14 13 20 4 0
14 13 19 15 0
14 13 18 15 0
14 13 17 15 0
14 13 16 15 0
14 13 15 15 0
14 13 14 15 0
14 13 13 15 0
14 13 12 15 0
14 13 11 15 0
14 13 10 3 66
14 14 69 13 96
14 14 57 19 102
14 14 26 11 32
14 14 25 4 0
14 14 24 4 0
14 14 23 4 0
14 14 22 4 0
14 14 21 4 0
14 14 20 4 0
14 14 19 15 0
14 14 18 15 0
14 14 17 15 0
14 14 16 15 0
14 14 15 15 0
14 14 14 15 0
14 14 13 15 0
14 14 12 15 0
14 14 11 15 0
14 14 10 3 66
14 15 69 13 96
14 15 57 8 104
14 15 26 11 32
14 15 25 4 0
14 15 24 4 0
14 15 23 4 0
14 15 22 4 0
14 15 21 4 0
14 15 20 4 0
14 15 19 15 0
14 15 18 15 0
14 15 17 15 0
14 15 16 15 0
14 15 15 15 0
14 15 14 15 0
14 15 13 15 0
14 15 12 15 0
14 15 11 15 0
14 15 10 15 0
14 15 9 13 80
14 16 69 3 104
14 16 26 8 40
14 16 25 8 8
14 16 24 8 0
14 16 23 8 0
14 16 22 8 0
14 16 21 8 0
14 16 20 8 0
14 16 19 8 0
14 16 18 8 0
14 16 17 8 0
14 16 16 8 0
14 16 15 8 0
14 16 14 8 0
14 16 13 8 0
14 16 12 8 0
14 16 11 8 0
14 16 10 8 0
14 16 9 3 64
14 17 24 8 32
14 17 23 10 8
14 17 22 12 8
14 17 21 12 8
14 17 20 12 8
14 17 19 12 8
14 17 18 12 8
14 17 17 12 8
14 17 16 12 8
14 17 15 12 8
14 17 14 12 8
14 17 13 10 8
14 17 12 10 8
14 17 11 8 0
14 17 10 8 0
14 17 9 3 72
14 18 24 8 104
14 18 11 8 40
14 18 10 8 72
15 1 52 7 48
15 1 51 7 16
15 1 50 7 16
15 1 49 7 16
15 1 48 7 16
15 1 47 7 16
15 1 46 7 16
15 1 45 7 16
15 1 44 7 16
15 1 43 7 16
15 1 42 7 16
15 1 41 7 16
15 1 40 7 16
15 1 39 7 16
15 1 38 7 16
15 1 37 7 16
15 1 36 7 16
15 1 35 7 16
15 1 34 7 16
15 1 33 7 16
15 1 32 7 16
15 1 31 7 16
15 1 30 7 16
15 1 29 7 16
15 1 28 7 16
15 1 27 7 16
15 1 26 7 16
15 1 25 7 16
15 1 24 7 16
15 1 23 7 16
15 1 22 7 22
15 1 21 7 86
15 2 56 7 48
15 2 55 7 16
15 2 54 7 16
15 2 53 7 16
15 2 52 7 0
15 2 51 7 0
15 2 50 7 0
15 2 49 7 0
15 2 48 7 0
15 2 47 7 0
15 2 46 7 0
15 2 45 7 0
15 2 44 7 0
15 2 43 7 0
15 2 42 7 0
15 2 41 7 0
15 2 40 7 0
15 2 39 7 0
15 2 38 7 0
15 2 37 7 0
15 2 36 7 0
15 2 35 7 0
15 2 34 7 0
15 2 33 7 0
15 2 32 7 0
15 2 31 7 0
15 2 30 7 0
15 2 29 7 0
15 2 28 7 0
15 2 27 7 0
15 2 26 7 0
15 2 25 7 0
15 2 24 7 0
15 2 23 7 0
15 2 22 7 0
15 2 21 7 0
15 2 20 7 16
15 2 19 7 86
15 3 60 7 48
15 3 59 7 16
15 3 58 7 16
15 3 57 7 16
15 3 56 4 0
15 3 55 4 0
15 3 54 4 0
15 3 53 4 0
15 3 52 4 0
15 3 51 10 0
15 3 50 10 0
15 3 49 10 0
15 3 48 10 0
15 3 47 10 0
15 3 46 10 0
15 3 45 10 0
15 3 44 10 0
15 3 43 10 0
15 3 42 10 0
15 3 41 10 0
15 3 40 10 0
15 3 39 10 0
15 3 38 10 0
15 3 37 10 0
15 3 36 10 0
15 3 35 10 0
15 3 34 10 0
15 3 33 10 0
15 3 32 10 0
15 3 31 10 0
15 3 30 10 0
15 3 29 4 0
15 3 28 4 0
15 3 27 4 0
15 3 26 4 0
15 3 25 4 0
15 3 24 4 0
15 3 23 4 0
15 3 22 4 0
15 3 21 4 0
15 3 20 4 0
15 3 19 4 0
15 3 18 7 16
15 3 17 7 86
15 4 62 7 48
15 4 61 7 16
15 4 60 4 0
15 4 59 4 0
15 4 58 4 0
15 4 57 4 0
15 4 56 4 0
15 4 55 4 0
15 4 54 4 0
15 4 53 4 0
15 4 52 10 0
15 4 51 10 0
15 4 50 10 0
15 4 49 10 0
15 4 48 10 0
15 4 47 10 0
15 4 46 10 0
15 4 45 10 0
15 4 44 10 0
15 4 43 10 0
15 4 42 10 0
15 4 41 10 0
15 4 40 10 0
15 4 39 10 0
15 4 38 10 0
15 4 37 10 0
15 4 36 10 0
15 4 35 10 0
15 4 34 10 0
15 4 33 10 0
15 4 32 10 0
15 4 31 10 0
15 4 30 10 0
15 4 29 4 0
15 4 28 4 0
15 4 27 4 0
15 4 26 4 0
15 4 25 4 0
15 4 24 4 0
15 4 23 4 0
15 4 22 4 0
15 4 21 4 0
15 4 20 4 0
15 4 19 4 0
15 4 18 4 0
15 4 17 4 0
15 4 16 7 80
15 5 65 7 48
15 5 64 7 16
15 5 63 7 16
15 5 62 4 0
15 5 61 4 0
15 5 60 4 0
15 5 59 4 0
15 5 58 4 0
15 5 57 4 0
15 5 56 4 0
15 5 55 4 0
15 5 54 4 0
15 5 53 4 0
15 5 52 10 0
15 5 51 10 0
15 5 50 10 0
15 5 49 10 0
15 5 48 10 0
15 5 47 10 0
15 5 46 10 0
15 5 45 10 0
15 5 44 10 0
15 5 43 10 0
15 5 42 10 0
15 5 41 10 0
15 5 40 10 0
15 5 39 10 0
15 5 38 10 0
15 5 37 10 0
15 5 36 10 0
15 5 35 10 0
15 5 34 10 0
15 5 33 10 0
15 5 32 10 0
15 5 31 10 0
15 5 30 10 0
15 5 29 4 0
15 5 28 4 0
15 5 27 4 0
15 5 26 4 0
15 5 25 4 0
15 5 24 4 0
15 5 23 4 0
15 5 22 4 0
15 5 21 4 0
15 5 20 4 0
15 5 19 4 0
15 5 18 4 0
15 5 17 4 0
15 5 16 7 64
15 6 68 7 54
15 6 67 7 16
15 6 66 7 16
15 6 65 4 0
15 6 64 4 0
15 6 63 4 0
15 6 62 4 0
15 6 61 4 0
15 6 60 4 0
15 6 59 4 0
15 6 58 4 0
15 6 57 4 0
15 6 56 4 0
15 6 55 4 0
15 6 54 4 0
15 6 53 4 0
15 6 52 10 0
15 6 51 10 0
15 6 50 10 0
15 6 49 10 0
15 6 48 10 0
15 6 47 10 0
15 6 46 10 0
15 6 45 10 0
15 6 44 10 0
15 6 43 10 0
15 6 42 10 0
15 6 41 10 0
15 6 40 10 0
15 6 39 10 0
15 6 38 10 0
15 6 37 10 0
15 6 36 10 0
15 6 35 10 0
15 6 34 10 0
15 6 33 10 0
15 6 32 10 0
15 6 31 10 0
15 6 30 10 0
15 6 29 4 0
15 6 28 4 0
15 6 27 4 0
15 6 26 4 0
15 6 25 4 0
15 6 24 4 0
15 6 23 4 0
15 6 22 4 0
15 6 21 4 0
15 6 20 4 0
15 6 19 4 0
15 6 18 4 0
15 6 17 4 0
15 6 16 4 0
15 6 15 3 80
15 7 70 3 54
15 7 69 4 16
15 7 68 4 0
15 7 67 4 0
15 7 66 4 0
15 7 65 4 0
15 7 64 4 0
15 7 63 4 0
15 7 62 4 0
15 7 61 4 0
15 7 60 4 0
15 7 59 4 0
15 7 58 4 0
15 7 57 4 0
15 7 56 4 0
15 7 55 4 0
15 7 54 4 0
15 7 53 4 0
15 7 52 10 0
15 7 51 10 0
15 7 50 10 0
15 7 49 10 0
15 7 48 10 0
15 7 47 10 0
15 7 46 10 0
15 7 45 10 0
15 7 44 10 0
15 7 43 10 0
15 7 42 10 0
15 7 41 10 0
15 7 40 10 0
15 7 39 10 0
15 7 38 10 0
15 7 37 10 0
15 7 36 10 0
15 7 35 10 0
15 7 34 10 0
15 7 33 10 0
15 7 32 10 0
15 7 31 10 0
15 7 30 10 0
15 7 29 4 0
15 7 28 4 0
15 7 27 4 0
15 7 26 4 0
15 7 25 4 0
15 7 24 4 0
15 7 23 4 0
15 7 22 4 0
15 7 21 4 0
15 7 20 4 0
15 7 19 4 0
15 7 18 4 0
15 7 17 4 0
15 7 16 4 0
15 7 15 4 0
15 7 14 3 80
15 8 72 3 54
15 8 71 3 16
15 8 70 4 0
15 8 69 4 0
15 8 68 4 0
15 8 67 4 0
15 8 66 4 0
15 8 65 4 0
15 8 64 4 0
15 8 63 4 0
15 8 62 4 0
15 8 61 4 0
15 8 60 4 0
15 8 59 4 0
15 8 58 4 0
15 8 57 4 0
15 8 56 4 0
15 8 55 4 0
15 8 54 4 0
15 8 53 14 0
15 8 52 10 0
15 8 51 10 0
15 8 50 10 0
15 8 49 10 0
15 8 48 10 0
15 8 47 10 0
15 8 46 10 0
15 8 45 10 0
15 8 44 10 0
15 8 43 10 0
15 8 42 10 0
15 8 41 10 0
15 8 40 10 0
15 8 39 10 0
15 8 38 10 0
15 8 37 10 0
15 8 36 10 0
15 8 35 10 0
15 8 34 10 0
15 8 33 10 0
15 8 32 10 0
15 8 31 10 0
15 8 30 10 0
15 8 29 4 0
15 8 28 4 0
15 8 27 4 0
15 8 26 4 0
15 8 25 4 0
15 8 24 4 0
15 8 23 4 0
15 8 22 4 0
15 8 21 4 0
15 8 20 4 0
15 8 19 4 0
15 8 18 4 0
15 8 17 4 0
15 8 16 4 0
15 8 15 4 0
15 8 14 4 0
15 8 13 13 80
15 9 74 3 54
15 9 73 3 16
15 9 72 4 0
15 9 71 4 0
15 9 70 4 0
15 9 69 4 0
15 9 68 4 0
15 9 67 4 0
15 9 66 4 0
15 9 65 4 0
15 9 64 4 0
15 9 63 4 0
15 9 62 4 0
15 9 61 4 0
15 9 60 4 0
15 9 59 4 0
15 9 58 4 0
15 9 57 4 0
15 9 56 4 0
15 9 55 4 0
15 9 54 4 0
15 9 53 14 0
15 9 52 10 0
15 9 51 10 0
15 9 50 10 0
15 9 49 10 0
15 9 48 10 0
15 9 47 10 0
15 9 46 10 0
15 9 45 10 0
15 9 44 10 0
15 9 43 10 0
15 9 42 10 0
15 9 41 10 0
15 9 40 10 0
15 9 39 10 0
15 9 38 10 0
15 9 37 10 0
15 9 36 10 0
15 9 35 3 8
15 9 34 3 8
15 9 33 3 8
15 9 32 10 0
15 9 31 10 0
15 9 30 10 0
15 9 29 4 0
15 9 28 4 0
15 9 27 4 0
15 9 26 4 0
15 9 25 4 0
15 9 24 4 0
15 9 23 4 0
15 9 22 4 0
15 9 21 4 0
15 9 20 4 0
15 9 19 4 0
15 9 18 4 0
15 9 17 4 0
15 9 16 4 0
15 9 15 4 0
15 9 14 4 0
15 9 13 4 0
15 9 12 13 16
15 9 11 13 80
15 10 75 3 48
15 10 74 13 8
15 10 73 13 8
15 10 72 13 8
15 10 71 13 8
15 10 70 13 8
15 10 69 4 0
15 10 68 4 0
15 10 67 4 0
15 10 66 4 0
15 10 65 4 0
15 10 64 4 0
15 10 63 4 0
15 10 62 4 0
15 10 61 4 0
15 10 60 4 0
15 10 59 4 0
15 10 58 4 0
15 10 57 4 0
15 10 56 4 0
15 10 55 4 0
15 10 54 4 0
15 10 53 14 0
15 10 52 10 0
15 10 51 10 0
15 10 50 10 0
15 10 49 10 0
15 10 48 10 0
15 10 47 10 0
15 10 46 10 0
15 10 45 10 0
15 10 44 10 0
15 10 43 10 0
15 10 42 10 0
15 10 41 10 0
15 10 40 10 0
15 10 39 10 0
15 10 38 10 0
15 10 37 10 0
15 10 36 10 64
15 10 32 10 32
15 10 31 10 0
15 10 30 10 0
15 10 29 4 0
15 10 28 4 0
15 10 27 4 0
15 10 26 4 0
15 10 25 4 0
15 10 24 4 0
15 10 23 4 0
15 10 22 4 0
15 10 21 4 0
15 10 20 4 0
15 10 19 4 0
15 10 18 4 0
15 10 17 4 0
15 10 16 4 0
15 10 15 4 0
15 10 14 4 0
15 10 13 4 0
15 10 12 4 0
15 10 11 13 64
15 11 76 3 54
15 11 75 4 64
15 11 69 13 32
15 11 68 4 0
15 11 67 4 0
15 11 66 4 0
15 11 65 4 0
15 11 64 4 0
15 11 63 4 0
15 11 62 4 0
15 11 61 4 0
15 11 60 4 0
15 11 59 4 0
15 11 58 4 0
15 11 57 4 0
15 11 56 10 8
15 11 55 10 8
15 11 54 10 8
15 11 53 10 8
15 11 52 10 8
15 11 51 10 8
15 11 50 10 8
15 11 49 10 8
15 11 48 10 8
15 11 47 10 8
15 11 46 10 8
15 11 45 10 8
15 11 44 10 8
15 11 43 10 8
15 11 42 10 8
15 11 41 10 8
15 11 40 10 8
15 11 39 10 8
15 11 38 10 8
15 11 37 10 8
15 11 36 10 64
15 11 32 10 32
15 11 31 10 8
15 11 30 10 8
15 11 29 4 0
15 11 28 4 0
15 11 27 4 0
15 11 26 4 0
15 11 25 4 0
15 11 24 4 0
15 11 23 4 0
15 11 22 4 0
15 11 21 4 0
15 11 20 4 0
15 11 19 4 0
15 11 18 4 0
15 11 17 4 0
15 11 16 4 0
15 11 15 4 0
15 11 14 4 0
15 11 13 4 0
15 11 12 4 0
15 11 11 13 64
15 12 76 3 46
15 12 75 3 72
15 12 69 16 32
15 12 68 4 0
15 12 67 4 0
15 12 66 4 0
15 12 65 4 0
15 12 64 4 0
15 12 63 4 0
15 12 62 4 0
15 12 61 4 0
15 12 60 4 0
15 12 59 4 0
15 12 58 4 0
15 12 57 11 64
15 12 36 9 40
15 12 35 9 94
15 12 33 9 62
15 12 32 9 72
15 12 29 4 40
15 12 28 10 8
15 12 27 4 8
15 12 26 4 0
15 12 25 4 0
15 12 24 4 0
15 12 23 4 0
15 12 22 4 0
15 12 21 4 0
15 12 20 4 0
15 12 19 4 0
15 12 18 4 0
15 12 17 4 0
15 12 16 4 0
15 12 15 4 0
15 12 14 4 0
15 12 13 4 0
15 12 12 4 0
15 12 11 13 64
15 13 69 16 32
15 13 68 11 8
15 13 67 11 8
15 13 66 11 8
15 13 65 11 8
15 13 64 11 8
15 13 63 12 8
15 13 62 11 8
15 13 61 11 8
15 13 60 12 8
15 13 59 11 8
15 13 58 11 8
15 13 57 11 72
15 13 26 11 32
15 13 25 4 0
15 13 24 4 0
15 13 23 4 0
15 13 22 4 0
15 13 21 4 0
15 13 20 4 0
15 13 19 15 0
15 13 18 15 0
15 13 17 15 0
15 13 16 15 0
15 13 15 15 0
15 13 14 15 0
15 13 13 15 0
15 13 12 15 0
15 13 11 13 64
15 14 69 13 96
15 14 26 11 32
15 14 25 4 0
15 14 24 4 0
15 14 23 4 0
15 14 22 4 0
15 14 21 4 0
15 14 20 4 0
15 14 19 15 0
15 14 18 15 0
15 14 17 15 0
15 14 16 15 0
15 14 15 15 0
15 14 14 15 0
15 14 13 15 0
15 14 12 15 0
15 14 11 13 64
15 15 69 13 96
15 15 57 8 120
15 15 26 11 32
15 15 25 4 0
15 15 24 4 0
15 15 23 4 0
15 15 22 4 0
15 15 21 4 0
15 15 20 4 0
15 15 19 15 0
15 15 18 15 0
15 15 17 15 0
15 15 16 15 0
15 15 15 15 0
15 15 14 15 0
15 15 13 15 0
15 15 12 15 0
15 15 11 15 0
15 15 10 13 16
15 15 9 13 80
15 16 69 3 104
15 16 26 8 40
15 16 25 8 8
15 16 24 8 0
15 16 23 8 0
15 16 22 8 0
15 16 21 8 0
15 16 20 8 0
15 16 19 8 0
15 16 18 8 0
15 16 17 8 0
15 16 16 8 0
15 16 15 8 0
15 16 14 8 0
15 16 13 8 0
15 16 12 8 0
15 16 11 8 0
15 16 10 8 0
15 16 9 3 64
15 17 24 8 32
15 17 23 10 8
15 17 22 10 8
15 17 21 10 8
15 17 20 10 8
15 17 19 10 8
15 17 18 10 8
15 17 17 10 8
15 17 16 10 8
15 17 15 10 8
15 17 14 10 8
15 17 13 10 8
15 17 12 10 8
15 17 11 8 0
15 17 10 8 0
15 17 9 3 72
15 18 24 8 104
15 18 11 8 40
15 18 10 8 72
16 1 52 7 50
16 1 51 7 18
16 1 50 7 18
16 1 49 7 18
16 1 48 7 18
16 1 47 7 18
16 1 46 7 18
16 1 45 7 18
16 1 44 7 18
16 1 43 7 18
16 1 42 7 18
16 1 41 7 18
16 1 40 7 18
16 1 39 7 18
16 1 38 7 18
16 1 37 7 18
16 1 36 7 18
16 1 35 7 18
16 1 34 7 18
16 1 33 7 18
16 1 32 7 18
16 1 31 7 18
16 1 30 7 18
16 1 29 7 18
16 1 28 7 18
16 1 27 7 18
16 1 26 7 18
16 1 25 7 18
16 1 24 7 18
16 1 23 7 82
16 2 56 7 48
16 2 55 7 16
16 2 54 7 16
16 2 53 7 16
16 2 52 7 0
16 2 51 7 0
16 2 50 7 0
16 2 49 7 0
16 2 48 7 0
16 2 47 7 0
16 2 46 7 0
16 2 45 7 0
16 2 44 7 0
16 2 43 7 0
16 2 42 7 0
16 2 41 7 0
16 2 40 7 0
16 2 39 7 0
16 2 38 7 0
16 2 37 7 0
16 2 36 7 0
16 2 35 7 0
16 2 34 7 0
16 2 33 7 0
16 2 32 7 0
16 2 31 7 0
16 2 30 7 0
16 2 29 7 0
16 2 28 7 0
16 2 27 7 0
16 2 26 7 0
16 2 25 7 0
16 2 24 7 0
16 2 23 7 0
16 2 22 7 16
16 2 21 7 16
16 2 20 7 82
16 3 60 7 50
16 3 59 7 16
16 3 58 7 16
16 3 57 7 16
16 3 56 4 0
16 3 55 4 0
16 3 54 4 0
16 3 53 4 0
16 3 52 4 0
16 3 51 10 0
16 3 50 10 0
16 3 49 10 0
16 3 48 10 0
16 3 47 10 0
16 3 46 10 0
16 3 45 10 0
16 3 44 10 0
16 3 43 10 0
16 3 42 10 0
16 3 41 10 0
16 3 40 10 0
16 3 39 10 0
16 3 38 10 0
16 3 37 10 0
16 3 36 10 0
16 3 35 10 0
16 3 34 10 0
16 3 33 10 0
16 3 32 10 0
16 3 31 10 0
16 3 30 10 0
16 3 29 4 0
16 3 28 4 0
16 3 27 4 0
16 3 26 4 0
16 3 25 4 0
16 3 24 4 0
16 3 23 4 0
16 3 22 4 0
16 3 21 4 0
16 3 20 4 0
16 3 19 7 16
16 3 18 7 82
16 4 62 7 50
16 4 61 7 16
16 4 60 4 0
16 4 59 4 0
16 4 58 4 0
16 4 57 4 0
16 4 56 4 0
16 4 55 4 0
16 4 54 4 0
16 4 53 4 0
16 4 52 10 0
16 4 51 10 0
16 4 50 10 0
16 4 49 10 0
16 4 48 10 0
16 4 47 10 0
16 4 46 10 0
16 4 45 10 0
16 4 44 10 0
16 4 43 10 0
16 4 42 10 0
16 4 41 10 0
16 4 40 10 0
16 4 39 10 0
16 4 38 10 0
16 4 37 10 0
16 4 36 10 0
16 4 35 10 0
16 4 34 10 0
16 4 33 10 0
16 4 32 10 0
16 4 31 10 0
16 4 30 10 0
16 4 29 4 0
16 4 28 4 0
16 4 27 4 0
16 4 26 4 0
16 4 25 4 0
16 4 24 4 0
16 4 23 4 0
16 4 22 4 0
16 4 21 4 0
16 4 20 4 0
16 4 19 4 0
16 4 18 4 0
16 4 17 7 16
16 4 16 7 82
16 5 65 7 50
16 5 64 7 16
16 5 63 7 16
16 5 62 4 0
16 5 61 4 0
16 5 60 4 0
16 5 59 4 0
16 5 58 4 0
16 5 57 4 0
16 5 56 4 0
16 5 55 4 0
16 5 54 4 0
16 5 53 4 0
16 5 52 10 0
16 5 51 10 0
16 5 50 10 0
16 5 49 10 0
16 5 48 10 0
16 5 47 10 0
16 5 46 10 0
16 5 45 10 0
16 5 44 10 0
16 5 43 10 0
16 5 42 10 0
16 5 41 10 0
16 5 40 10 0
16 5 39 10 0
16 5 38 10 0
16 5 37 10 0
16 5 36 10 0
16 5 35 10 0
16 5 34 10 0
16 5 33 10 0
16 5 32 10 0
16 5 31 10 0
16 5 30 10 0
16 5 29 4 0
16 5 28 4 0
16 5 27 4 0
16 5 26 4 0
16 5 25 4 0
16 5 24 4 0
16 5 23 4 0
16 5 22 4 0
16 5 21 4 0
16 5 20 4 0
16 5 19 4 0
16 5 18 4 0
16 5 17 4 0
16 5 16 7 64
16 6 67 7 50
16 6 66 7 16
16 6 65 4 0
16 6 64 4 0
16 6 63 4 0
16 6 62 4 0
16 6 61 4 0
16 6 60 4 0
16 6 59 4 0
16 6 58 4 0
16 6 57 4 0
16 6 56 4 0
16 6 55 4 0
16 6 54 4 0
16 6 53 4 0
16 6 52 10 0
16 6 51 10 0
16 6 50 10 0
16 6 49 10 0
16 6 48 10 0
16 6 47 10 0
16 6 46 10 0
16 6 45 10 0
16 6 44 10 0
16 6 43 10 0
16 6 42 10 0
16 6 41 10 0
16 6 40 10 0
16 6 39 10 0
16 6 38 10 0
16 6 37 10 0
16 6 36 10 0
16 6 35 10 0
16 6 34 10 0
16 6 33 10 0
16 6 32 10 0
16 6 31 10 0
16 6 30 10 0
16 6 29 4 0
16 6 28 4 0
16 6 27 4 0
16 6 26 4 0
16 6 25 4 0
16 6 24 4 0
16 6 23 4 0
16 6 22 4 0
16 6 21 4 0
16 6 20 4 0
16 6 19 4 0
16 6 18 4 0
16 6 17 4 0
16 6 16 4 0
16 6 15 3 80
16 7 69 3 50
16 7 68 4 16
16 7 67 4 0
16 7 66 4 0
16 7 65 4 0
16 7 64 4 0
16 7 63 4 0
16 7 62 4 0
16 7 61 4 0
16 7 60 4 0
16 7 59 4 0
16 7 58 4 0
16 7 57 4 0
16 7 56 4 0
16 7 55 4 0
16 7 54 4 0
16 7 53 4 0
16 7 52 10 0
16 7 51 10 0
16 7 50 10 0
16 7 49 10 0
16 7 48 10 0
16 7 47 10 0
16 7 46 10 0
16 7 45 10 0
16 7 44 10 0
16 7 43 10 0
16 7 42 10 0
16 7 41 10 0
16 7 40 10 0
16 7 39 10 0
16 7 38 10 0
16 7 37 10 0
16 7 36 10 0
16 7 35 10 0
16 7 34 10 0
16 7 33 10 0
16 7 32 10 0
16 7 31 10 0
16 7 30 10 0
16 7 29 4 0
16 7 28 4 0
16 7 27 4 0
16 7 26 4 0
16 7 25 4 0
16 7 24 4 0
16 7 23 4 0
16 7 22 4 0
16 7 21 4 0
16 7 20 4 0
16 7 19 4 0
16 7 18 4 0
16 7 17 4 0
16 7 16 4 0
16 7 15 4 0
16 7 14 3 80
16 8 71 3 50
16 8 70 3 18
16 8 69 4 0
16 8 68 4 0
16 8 67 4 0
16 8 66 4 0
16 8 65 4 0
16 8 64 4 0
16 8 63 4 0
16 8 62 4 0
16 8 61 4 0
16 8 60 4 0
16 8 59 4 0
16 8 58 4 0
16 8 57 4 0
16 8 56 4 0
16 8 55 4 0
16 8 54 4 0
16 8 53 14 0
16 8 52 10 0
16 8 51 10 0
16 8 50 10 0
16 8 49 10 0
16 8 48 10 0
16 8 47 10 0
16 8 46 10 0
16 8 45 10 0
16 8 44 10 0
16 8 43 10 0
16 8 42 10 0
16 8 41 10 0
16 8 40 10 0
16 8 39 10 0
16 8 38 10 0
16 8 37 10 0
16 8 36 10 0
16 8 35 10 0
16 8 34 10 0
16 8 33 10 0
16 8 32 10 0
16 8 31 10 0
16 8 30 10 0
16 8 29 4 0
16 8 28 4 0
16 8 27 4 0
16 8 26 4 0
16 8 25 4 0
16 8 24 4 0
16 8 23 4 0
16 8 22 4 0
16 8 21 4 0
16 8 20 4 0
16 8 19 4 0
16 8 18 4 0
16 8 17 4 0
16 8 16 4 0
16 8 15 4 0
16 8 14 4 0
16 8 13 13 80
16 9 73 3 50
16 9 72 3 16
16 9 71 4 0
16 9 70 4 0
16 9 69 4 0
16 9 68 4 0
16 9 67 4 0
16 9 66 4 0
16 9 65 4 0
16 9 64 4 0
16 9 63 4 0
16 9 62 4 0
16 9 61 4 0
16 9 60 4 0
16 9 59 4 0
16 9 58 4 0
16 9 57 4 0
16 9 56 4 0
16 9 55 4 0
16 9 54 4 0
16 9 53 14 0
16 9 52 10 0
16 9 51 10 0
16 9 50 10 0
16 9 49 10 0
16 9 48 10 0
16 9 47 10 0
16 9 46 10 0
16 9 45 10 0
16 9 44 10 0
16 9 43 10 0
16 9 42 10 0
16 9 41 10 0
16 9 40 10 0
16 9 39 10 0
16 9 38 10 0
16 9 37 10 0
16 9 36 10 0
16 9 35 3 8
16 9 34 3 10
16 9 33 3 8
16 9 32 10 0
16 9 31 10 0
16 9 30 10 0
16 9 29 4 0
16 9 28 4 0
16 9 27 4 0
16 9 26 4 0
16 9 25 4 0
16 9 24 4 0
16 9 23 4 0
16 9 22 4 0
16 9 21 4 0
16 9 20 4 0
16 9 19 4 0
16 9 18 4 0
16 9 17 4 0
16 9 16 4 0
16 9 15 4 0
16 9 14 4 0
16 9 13 4 0
16 9 12 13 16
16 9 11 13 80
16 10 75 3 50
16 10 74 3 26
16 10 73 13 8
16 10 72 13 8
16 10 71 13 8
16 10 70 13 8
16 10 69 4 0
16 10 68 4 0
16 10 67 4 0
16 10 66 4 0
16 10 65 4 0
16 10 64 4 0
16 10 63 4 0
16 10 62 4 0
16 10 61 4 0
16 10 60 4 0
16 10 59 4 0
16 10 58 4 0
16 10 57 4 0
16 10 56 4 0
16 10 55 4 0
16 10 54 4 0
16 10 53 14 0
16 10 52 10 0
16 10 51 10 0
16 10 50 10 0
16 10 49 10 0
16 10 48 10 0
16 10 47 10 0
16 10 46 10 0
16 10 45 10 0
16 10 44 10 0
16 10 43 10 0
16 10 42 10 0
16 10 41 10 0
16 10 40 10 0
16 10 39 10 0
16 10 38 10 0
16 10 37 10 0
16 10 36 10 64
16 10 32 10 32
16 10 31 10 0
16 10 30 17 0
16 10 29 4 0
16 10 28 4 0
16 10 27 4 0
16 10 26 4 0
16 10 25 4 0
16 10 24 4 0
16 10 23 4 0
16 10 22 4 0
16 10 21 4 0
16 10 20 4 0
16 10 19 4 0
16 10 18 4 0
16 10 17 4 0
16 10 16 4 0
16 10 15 4 0
16 10 14 4 0
16 10 13 4 0
16 10 12 4 0
16 10 11 4 0
16 10 10 3 84
16 11 75 3 98
16 11 69 13 32
16 11 68 4 0
16 11 67 4 0
16 11 66 4 0
16 11 65 4 0
16 11 64 4 0
16 11 63 4 0
16 11 62 4 0
16 11 61 4 0
16 11 60 4 0
16 11 59 4 0
16 11 58 4 0
16 11 57 4 0
16 11 56 12 8
16 11 55 12 8
16 11 54 12 8
16 11 53 12 8
16 11 52 12 8
16 11 51 12 8
16 11 50 12 8
16 11 49 12 8
16 11 48 12 8
16 11 47 12 8
16 11 46 10 8
16 11 45 10 8
16 11 44 10 8
16 11 43 10 8
16 11 42 10 8
16 11 41 12 8
16 11 40 12 8
16 11 39 12 8
16 11 38 12 8
16 11 37 12 8
16 11 36 12 64
16 11 32 10 32
16 11 31 10 8
16 11 30 10 8
16 11 29 4 0
16 11 28 4 0
16 11 27 4 0
16 11 26 4 0
16 11 25 4 0
16 11 24 4 0
16 11 23 4 0
16 11 22 4 0
16 11 21 4 0
16 11 20 4 0
16 11 19 4 0
16 11 18 4 0
16 11 17 4 0
16 11 16 4 0
16 11 15 4 0
16 11 14 4 0
16 11 13 4 0
16 11 12 4 0
16 11 11 4 0
16 11 10 3 68
16 12 75 3 106
16 12 69 16 32
16 12 68 4 0
16 12 67 4 0
16 12 66 4 0
16 12 65 4 0
16 12 64 4 0
16 12 63 4 0
16 12 62 4 0
16 12 61 4 0
16 12 60 4 0
16 12 59 4 0
16 12 58 4 0
16 12 57 4 64
16 12 36 9 104
16 12 34 9 126
16 12 32 9 104
16 12 29 10 40
16 12 28 4 8
16 12 27 10 8
16 12 26 4 0
16 12 25 4 0
16 12 24 4 0
16 12 23 4 0
16 12 22 4 0
16 12 21 4 0
16 12 20 4 0
16 12 19 4 0
16 12 18 4 0
16 12 17 4 0
16 12 16 4 0
16 12 15 4 0
16 12 14 4 0
16 12 13 4 0
16 12 12 4 0
16 12 11 4 0
16 12 10 3 68
16 13 69 16 32
16 13 68 11 8
16 13 67 11 8
16 13 66 11 8
16 13 65 11 8
16 13 64 11 8
16 13 63 12 8
16 13 62 11 8
16 13 61 11 8
16 13 60 12 8
16 13 59 11 8
16 13 58 11 8
16 13 57 4 64
16 13 26 11 32
16 13 25 4 0
16 13 24 4 0
16 13 23 4 0
16 13 22 4 0
16 13 21 4 0
16 13 20 4 0
16 13 19 15 0
16 13 18 15 0
16 13 17 15 0
16 13 16 15 0
16 13 15 15 0
16 13 14 15 0
16 13 13 15 0
16 13 12 15 0
16 13 11 15 0
16 13 10 3 68
16 14 69 13 96
16 14 57 19 102
16 14 26 11 32
16 14 25 4 0
16 14 24 4 0
16 14 23 4 0
16 14 22 4 0
16 14 21 4 0
16 14 20 4 0
16 14 19 15 0
16 14 18 15 0
16 14 17 15 0
16 14 16 15 0
16 14 15 15 0
16 14 14 15 0
16 14 13 15 0
16 14 12 15 0
16 14 11 15 0
16 14 10 3 68
16 15 69 13 96
16 15 57 8 104
16 15 26 11 32
16 15 25 4 0
16 15 24 4 0
16 15 23 4 0
16 15 22 4 0
16 15 21 4 0
16 15 20 4 0
16 15 19 15 0
16 15 18 15 0
16 15 17 15 0
16 15 16 15 0
16 15 15 15 0
16 15 14 15 0
16 15 13 15 0
16 15 12 15 0
16 15 11 15 0
16 15 10 15 0
16 15 9 13 80
16 16 69 3 104
16 16 26 8 40
16 16 25 8 8
16 16 24 8 0
16 16 23 8 0
16 16 22 8 0
16 16 21 8 0
16 16 20 8 0
16 16 19 8 0
16 16 18 8 0
16 16 17 8 0
16 16 16 8 0
16 16 15 8 0
16 16 14 8 0
16 16 13 8 0
16 16 12 8 0
16 16 11 8 0
16 16 10 8 0
16 16 9 3 64
16 17 24 8 32
16 17 23 10 8
16 17 22 12 8
16 17 21 12 8
16 17 20 12 8
16 17 19 12 8
16 17 18 12 8
16 17 17 12 8
16 17 16 12 8
16 17 15 12 8
16 17 14 12 8
16 17 13 10 8
16 17 12 10 8
16 17 11 8 0
16 17 10 8 0
16 17 9 3 72
16 18 24 8 104
16 18 11 8 40
16 18 10 8 72
17 2 56 7 48
17 2 55 7 16
17 2 54 7 16
17 2 53 7 16
17 2 52 7 16
17 2 51 7 16
17 2 50 7 16
17 2 49 7 16
17 2 48 7 16
17 2 47 7 16
17 2 46 7 16
17 2 45 7 16
17 2 44 7 16
17 2 43 7 16
17 2 42 7 16
17 2 41 7 16
17 2 40 7 16
17 2 39 7 16
17 2 38 7 16
17 2 37 7 16
17 2 36 7 16
17 2 35 7 16
17 2 34 7 16
17 2 33 7 16
17 2 32 7 16
17 2 31 7 16
17 2 30 7 16
17 2 29 7 16
17 2 28 7 16
17 2 27 7 16
17 2 26 7 16
17 2 25 7 16
17 2 24 7 16
17 2 23 7 16
17 2 22 7 16
17 2 21 7 82
17 3 59 7 50
17 3 58 7 16
17 3 57 7 16
17 3 56 4 0
17 3 55 4 0
17 3 54 4 0
17 3 53 4 0
17 3 52 4 0
17 3 51 10 0
17 3 50 10 0
17 3 49 10 0
17 3 48 10 0
17 3 47 10 0
17 3 46 10 0
17 3 45 10 0
17 3 44 10 0
17 3 43 10 0
17 3 42 10 0
17 3 41 10 0
17 3 40 10 0
17 3 39 10 0
17 3 38 10 0
17 3 37 10 0
17 3 36 10 0
17 3 35 10 0
17 3 34 10 0
17 3 33 10 0
17 3 32 10 0
17 3 31 10 0
17 3 30 10 0
17 3 29 4 0
17 3 28 4 0
17 3 27 4 0
17 3 26 4 0
17 3 25 4 0
17 3 24 4 0
17 3 23 4 0
17 3 22 4 0
17 3 21 4 0
17 3 20 7 16
17 3 19 7 82
17 4 61 7 50
17 4 60 7 16
17 4 59 4 0
17 4 58 4 0
17 4 57 4 0
17 4 56 4 0
17 4 55 4 0
17 4 54 4 0
17 4 53 4 0
17 4 52 4 0
17 4 51 10 0
17 4 50 10 0
17 4 49 10 0
17 4 48 10 0
17 4 47 10 0
17 4 46 10 0
17 4 45 10 0
17 4 44 10 0
17 4 43 10 0
17 4 42 10 0
17 4 41 10 0
17 4 40 10 0
17 4 39 10 0
17 4 38 10 0
17 4 37 10 0
17 4 36 10 0
17 4 35 10 0
17 4 34 10 0
17 4 33 10 0
17 4 32 10 0
17 4 31 10 0
17 4 30 10 0
17 4 29 4 0
17 4 28 4 0
17 4 27 4 0
17 4 26 4 0
17 4 25 4 0
17 4 24 4 0
17 4 23 4 0
17 4 22 4 0
17 4 21 4 0
17 4 20 4 0
17 4 19 4 0
17 4 18 7 16
17 4 17 7 82
17 5 64 7 50
17 5 63 7 16
17 5 62 7 16
17 5 61 4 0
17 5 60 4 0
17 5 59 4 0
17 5 58 4 0
17 5 57 4 0
17 5 56 4 0
17 5 55 4 0
17 5 54 4 0
17 5 53 4 0
17 5 52 10 0
17 5 51 10 0
17 5 50 10 0
17 5 49 10 0
17 5 48 10 0
17 5 47 10 0
17 5 46 10 0
17 5 45 10 0
17 5 44 10 0
17 5 43 10 0
17 5 42 10 0
17 5 41 10 0
17 5 40 10 0
17 5 39 10 0
17 5 38 10 0
17 5 37 10 0
17 5 36 10 0
17 5 35 10 0
17 5 34 10 0
17 5 33 10 0
17 5 32 10 0
17 5 31 10 0
17 5 30 10 0
17 5 29 4 0
17 5 28 4 0
17 5 27 4 0
17 5 26 4 0
17 5 25 4 0
17 5 24 4 0
17 5 23 4 0
17 5 22 4 0
17 5 21 4 0
17 5 20 4 0
17 5 19 4 0
17 5 18 4 0
17 5 17 4 0
17 5 16 7 82
17 6 66 7 50
17 6 65 7 16
17 6 64 4 0
17 6 63 4 0
17 6 62 4 0
17 6 61 4 0
17 6 60 4 0
17 6 59 4 0
17 6 58 4 0
17 6 57 4 0
17 6 56 4 0
17 6 55 4 0
17 6 54 4 0
17 6 53 4 0
17 6 52 10 0
17 6 51 10 0
17 6 50 10 0
17 6 49 10 0
17 6 48 10 0
17 6 47 10 0
17 6 46 10 0
17 6 45 10 0
17 6 44 10 0
17 6 43 10 0
17 6 42 10 0
17 6 41 10 0
17 6 40 10 0
17 6 39 10 0
17 6 38 10 0
17 6 37 10 0
17 6 36 10 0
17 6 35 10 0
17 6 34 10 0
17 6 33 10 0
17 6 32 10 0
17 6 31 10 0
17 6 30 10 0
17 6 29 4 0
17 6 28 4 0
17 6 27 4 0
17 6 26 4 0
17 6 25 4 0
17 6 24 4 0
17 6 23 4 0
17 6 22 4 0
17 6 21 4 0
17 6 20 4 0
17 6 19 4 0
17 6 18 4 0
17 6 17 4 0
17 6 16 4 0
17 6 15 3 82
17 7 68 3 50
17 7 67 4 16
17 7 66 4 0
17 7 65 4 0
17 7 64 4 0
17 7 63 4 0
17 7 62 4 0
17 7 61 4 0
17 7 60 4 0
17 7 59 4 0
17 7 58 4 0
17 7 57 4 0
17 7 56 4 0
17 7 55 4 0
17 7 54 4 0
17 7 53 4 0
17 7 52 10 0
17 7 51 10 0
17 7 50 10 0
17 7 49 10 0
17 7 48 10 0
17 7 47 10 0
17 7 46 10 0
17 7 45 10 0
17 7 44 10 0
17 7 43 10 0
17 7 42 10 0
17 7 41 10 0
17 7 40 10 0
17 7 39 10 0
17 7 38 10 0
17 7 37 10 0
17 7 36 10 0
17 7 35 10 0
17 7 34 0 2
17 7 33 0 2
17 7 32 10 0
17 7 31 10 0
17 7 30 10 0
17 7 29 4 0
17 7 28 4 0
17 7 27 4 0
17 7 26 4 0
17 7 25 4 0
17 7 24 4 0
17 7 23 4 0
17 7 22 4 0
17 7 21 4 0
17 7 20 4 0
17 7 19 4 0
17 7 18 4 0
17 7 17 4 0
17 7 16 4 0
17 7 15 3 0
17 7 14 3 80
17 8 69 3 50
17 8 68 3 2
17 8 67 3 0
17 8 66 4 0
17 8 65 4 0
17 8 64 4 0
17 8 63 4 0
17 8 62 4 0
17 8 61 4 0
17 8 60 4 0
17 8 59 4 0
17 8 58 4 0
17 8 57 4 0
17 8 56 4 0
17 8 55 4 0
17 8 54 4 0
17 8 53 14 0
17 8 52 10 0
17 8 51 10 0
17 8 50 10 0
17 8 49 10 0
17 8 48 10 0
17 8 47 10 0
17 8 46 10 0
17 8 45 10 0
17 8 44 10 0
17 8 43 10 0
17 8 42 10 0
17 8 41 10 0
17 8 40 10 0
17 8 39 10 0
17 8 38 10 0
17 8 37 10 0
17 8 36 10 0
17 8 35 10 0
17 8 34 3 10
17 8 33 0 2
17 8 32 10 0
17 8 31 10 0
17 8 30 10 0
17 8 29 4 0
17 8 28 4 0
17 8 27 4 0
17 8 26 4 0
17 8 25 4 0
17 8 24 4 0
17 8 23 4 0
17 8 22 4 0
17 8 21 4 0
17 8 20 4 0
17 8 19 4 0
17 8 18 4 0
17 8 17 4 0
17 8 16 4 0
17 8 15 4 0
17 8 14 4 0
17 8 13 13 80
17 9 72 3 50
17 9 71 3 18
17 9 70 3 18
17 9 69 4 0
17 9 68 4 0
17 9 67 4 0
17 9 66 4 0
17 9 65 4 0
17 9 64 4 0
17 9 63 4 0
17 9 62 4 0
17 9 61 4 0
17 9 60 4 0
17 9 59 4 0
17 9 58 4 0
17 9 57 4 0
17 9 56 4 0
17 9 55 4 0
17 9 54 4 0
17 9 53 14 0
17 9 52 10 0
17 9 51 10 0
17 9 50 10 0
17 9 49 10 0
17 9 48 10 0
17 9 47 10 0
17 9 46 10 0
17 9 45 10 0
17 9 44 10 0
17 9 43 10 0
17 9 42 10 0
17 9 41 10 0
17 9 40 10 0
17 9 39 10 0
17 9 38 10 0
17 9 37 10 0
17 9 36 10 0
17 9 35 3 72
17 9 33 3 40
17 9 32 10 0
17 9 31 10 0
17 9 30 10 0
17 9 29 4 0
17 9 28 4 0
17 9 27 4 0
17 9 26 4 0
17 9 25 4 0
17 9 24 4 0
17 9 23 4 0
17 9 22 4 0
17 9 21 4 0
17 9 20 4 0
17 9 19 4 0
17 9 18 4 0
17 9 17 4 0
17 9 16 4 0
17 9 15 4 0
17 9 14 4 0
17 9 13 4 0
17 9 12 13 16
17 9 11 13 80
17 10 73 3 58
17 10 72 3 10
17 10 71 13 8
17 10 70 13 8
17 10 69 4 0
17 10 68 4 0
17 10 67 4 0
17 10 66 4 0
17 10 65 4 0
17 10 64 4 0
17 10 63 4 0
17 10 62 4 0
17 10 61 4 0
17 10 60 4 0
17 10 59 4 0
17 10 58 4 0
17 10 57 4 0
17 10 56 4 0
17 10 55 4 0
17 10 54 4 0
17 10 53 14 0
17 10 52 10 0
17 10 51 10 0
17 10 50 10 0
17 10 49 10 0
17 10 48 10 0
17 10 47 10 0
17 10 46 10 0
17 10 45 10 0
17 10 44 10 0
17 10 43 10 0
17 10 42 10 0
17 10 41 10 0
17 10 40 10 0
17 10 39 10 0
17 10 38 10 0
17 10 37 10 0
17 10 36 10 64
17 10 32 10 32
17 10 31 10 0
17 10 30 10 0
17 10 29 4 0
17 10 28 4 0
17 10 27 4 0
17 10 26 4 0
17 10 25 4 0
17 10 24 4 0
17 10 23 4 0
17 10 22 4 0
17 10 21 4 0
17 10 20 4 0
17 10 19 4 0
17 10 18 4 0
17 10 17 4 0
17 10 16 4 0
17 10 15 4 0
17 10 14 4 0
17 10 13 4 0
17 10 12 4 0
17 10 11 4 0
17 10 10 3 80
17 11 74 3 126
17 11 69 13 34
17 11 68 4 0
17 11 67 4 0
17 11 66 4 0
17 11 65 4 0
17 11 64 4 0
17 11 63 4 0
17 11 62 4 0
17 11 61 4 0
17 11 60 4 0
17 11 59 4 0
17 11 58 4 0
17 11 57 4 0
17 11 56 10 8
17 11 55 10 8
17 11 54 10 8
17 11 53 10 8
17 11 52 10 8
17 11 51 10 8
17 11 50 10 8
17 11 49 10 8
17 11 48 10 8
17 11 47 10 8
17 11 46 10 8
17 11 45 10 8
17 11 44 10 8
17 11 43 10 8
17 11 42 10 8
17 11 41 10 8
17 11 40 10 8
17 11 39 10 8
17 11 38 10 8
17 11 37 10 8
17 11 36 10 64
17 11 32 10 32
17 11 31 10 8
17 11 30 10 8
17 11 29 4 0
17 11 28 4 0
17 11 27 4 0
17 11 26 4 0
17 11 25 4 0
17 11 24 4 0
17 11 23 4 0
17 11 22 4 0
17 11 21 4 0
17 11 20 4 0
17 11 19 4 0
17 11 18 4 0
17 11 17 4 0
17 11 16 4 0
17 11 15 4 0
17 11 14 4 0
17 11 13 4 0
17 11 12 4 0
17 11 11 4 0
17 11 10 20 64
17 12 69 13 34
17 12 68 4 0
17 12 67 4 0
17 12 66 4 0
17 12 65 4 0
17 12 64 4 0
17 12 63 4 0
17 12 62 4 0
17 12 61 4 0
17 12 60 4 0
17 12 59 4 0
17 12 58 4 0
17 12 57 11 64
17 12 36 9 40
17 12 35 9 94
17 12 33 9 62
17 12 32 9 72
17 12 29 4 40
17 12 28 10 8
17 12 27 4 8
17 12 26 4 0
17 12 25 4 0
17 12 24 4 0
17 12 23 4 0
17 12 22 4 0
17 12 21 4 0
17 12 20 4 0
17 12 19 4 0
17 12 18 4 0
17 12 17 4 0
17 12 16 4 0
17 12 15 4 0
17 12 14 4 0
17 12 13 4 0
17 12 12 4 0
17 12 11 4 0
17 12 10 20 64
17 13 69 13 34
17 13 68 11 0
17 13 67 11 8
17 13 66 11 8
17 13 65 11 8
17 13 64 11 8
17 13 63 12 8
17 13 62 11 8
17 13 61 11 8
17 13 60 12 8
17 13 59 11 8
17 13 58 11 8
17 13 57 11 72
17 13 26 4 32
17 13 25 4 0
17 13 24 4 0
17 13 23 4 0
17 13 22 4 0
17 13 21 4 0
17 13 20 4 0
17 13 19 15 0
17 13 18 15 0
17 13 17 15 0
17 13 16 15 0
17 13 15 15 0
17 13 14 15 0
17 13 13 15 0
17 13 12 15 0
17 13 11 15 0
17 13 10 20 64
17 14 69 13 34
17 14 68 13 76
17 14 26 4 32
17 14 25 4 0
17 14 24 4 0
17 14 23 4 0
17 14 22 4 0
17 14 21 4 0
17 14 20 4 0
17 14 19 15 0
17 14 18 15 0
17 14 17 15 0
17 14 16 15 0
17 14 15 15 0
17 14 14 15 0
17 14 13 15 0
17 14 12 15 0
17 14 11 15 0
17 14 10 20 64
17 15 69 13 98
17 15 57 8 120
17 15 26 4 32
17 15 25 4 0
17 15 24 4 0
17 15 23 4 0
17 15 22 4 0
17 15 21 4 0
17 15 20 4 0
17 15 19 15 0
17 15 18 15 0
17 15 17 15 0
17 15 16 15 0
17 15 15 15 0
17 15 14 15 0
17 15 13 15 0
17 15 12 15 0
17 15 11 15 0
17 15 10 15 0
17 15 9 13 80
17 16 69 3 106
17 16 26 8 40
17 16 25 8 8
17 16 24 8 0
17 16 23 8 0
17 16 22 8 0
17 16 21 8 0
17 16 20 8 0
17 16 19 8 0
17 16 18 8 0
17 16 17 8 0
17 16 16 8 0
17 16 15 8 0
17 16 14 8 0
17 16 13 8 0
17 16 12 8 0
17 16 11 8 0
17 16 10 8 0
17 16 9 3 64
17 17 24 8 32
17 17 23 10 8
17 17 22 10 8
17 17 21 10 8
17 17 20 10 8
17 17 19 10 8
17 17 18 10 8
17 17 17 10 8
17 17 16 10 8
17 17 15 10 8
17 17 14 10 8
17 17 13 10 8
17 17 12 10 8
17 17 11 8 0
17 17 10 8 0
17 17 9 3 72
17 18 24 8 104
17 18 11 8 40
17 18 10 8 72
18 2 56 7 50
18 2 55 7 18
18 2 54 7 18
18 2 53 7 18
18 2 52 7 18
18 2 51 7 18
18 2 50 7 18
18 2 49 7 18
18 2 48 7 18
18 2 47 7 18
18 2 46 7 18
18 2 45 7 18
18 2 44 7 18
18 2 43 7 18
18 2 42 7 18
18 2 41 7 18
18 2 40 7 18
18 2 39 7 18
18 2 38 7 18
18 2 37 7 18
18 2 36 7 18
18 2 35 7 18
18 2 34 7 18
18 2 33 7 18
18 2 32 7 18
18 2 31 7 18
18 2 30 7 18
18 2 29 7 18
18 2 28 7 18
18 2 27 7 18
18 2 26 7 18
18 2 25 7 18
18 2 24 7 18
18 2 23 7 18
18 2 22 7 82
18 3 58 7 50
18 3 57 7 18
18 3 56 4 0
18 3 55 4 0
18 3 54 4 0
18 3 53 4 0
18 3 52 4 0
18 3 51 10 0
18 3 50 10 0
18 3 49 10 0
18 3 48 10 0
18 3 47 10 0
18 3 46 10 0
18 3 45 10 0
18 3 44 10 0
18 3 43 10 0
18 3 42 10 0
18 3 41 10 0
18 3 40 10 0
18 3 39 10 0
18 3 38 10 0
18 3 37 10 0
18 3 36 10 0
18 3 35 10 0
18 3 34 10 0
18 3 33 10 0
18 3 32 10 0
18 3 31 10 0
18 3 30 10 0
18 3 29 4 0
18 3 28 4 0
18 3 27 4 0
18 3 26 4 0
18 3 25 4 0
18 3 24 4 0
18 3 23 4 0
18 3 22 4 0
18 3 21 7 16
18 3 20 7 82
18 4 60 7 50
18 4 59 7 16
18 4 58 4 0
18 4 57 4 0
18 4 56 4 0
18 4 55 4 0
18 4 54 4 0
18 4 53 4 0
18 4 52 4 0
18 4 51 10 0
18 4 50 10 0
18 4 49 10 0
18 4 48 10 0
18 4 47 10 0
18 4 46 10 0
18 4 45 10 0
18 4 44 10 0
18 4 43 10 0
18 4 42 10 0
18 4 41 10 0
18 4 40 10 0
18 4 39 10 0
18 4 38 10 0
18 4 37 10 0
18 4 36 10 0
18 4 35 10 0
18 4 34 10 0
18 4 33 10 0
18 4 32 10 0
18 4 31 10 0
18 4 30 10 0
18 4 29 4 0
18 4 28 4 0
18 4 27 4 0
18 4 26 4 0
18 4 25 4 0
18 4 24 4 0
18 4 23 4 0
18 4 22 4 0
18 4 21 4 0
18 4 20 4 0
18 4 19 7 18
18 4 18 7 82
18 5 63 7 50
18 5 62 7 16
18 5 61 7 16
18 5 60 4 0
18 5 59 4 0
18 5 58 4 0
18 5 57 4 0
18 5 56 4 0
18 5 55 4 0
18 5 54 4 0
18 5 53 4 0
18 5 52 4 0
18 5 51 10 0
18 5 50 10 0
18 5 49 10 0
18 5 48 10 0
18 5 47 10 0
18 5 46 10 0
18 5 45 10 0
18 5 44 10 0
18 5 43 10 0
18 5 42 10 0
18 5 41 10 0
18 5 40 10 0
18 5 39 10 0
18 5 38 10 0
18 5 37 10 0
